Workbook

Sheet Лист1

Sheet Биаксплен Новосибирск
A1: =T37 -> 406065.26
A2: ="Отчет по хранению товара за " & TEXT(B5,"ММММ ГГГГ") -> Отчет по хранению товара за Ноябрь 2025
A3: № | B3: дата | D3: Выгрузка кол-во | E3: Загрузка кол-во | F3: Хранение | G3: Резервирование 70 т | H3: Мин. Суточный резерв 0 т | I3: переконсолидация (тонн) | J3: Паллетирование | K3: Ночная загруска выгрузка | L3: стоимость ночной загруски | M3: стоимость выгрузки | N3: стоимость загрузки | O3: стоимость хранения | P3: Стоимость резервирования | Q3: Стоимость мин.суточной бработки | R3: стоимость переконс. | S3: Стоимость паллетирования | T3: итого
A5: 1 | B5: 45962 | F5: =124.81618+D5-E5 -> 124.81618 | G5: =IF(OR(B5="",NOT(ISERROR(SEARCH("KPI",$A$2))),NOT(ISERROR(SEARCH("Полиом",$A$2)))),0,IF(70-F5<=0,0,70-F5)) -> 0 | L5: =SUM(K5*240) -> 0 | M5: =SUM(D5*120) -> 0 | N5: =SUM(E5*120) -> 0 | O5: =SUM(F5*54) -> 6740.0737 | P5: =SUM(G5*54) -> 0 | Q5: =SUM(H5*120) -> 0 | R5: =SUM(I5*1000) -> 0 | S5: =SUM(J5*140) -> 0 | T5: =SUM(L5:S5) -> 6740.0737
A6: 2 | B6: 45963 | F6: =F5-E6+D6 -> 124.81618 | G6: =IF(OR(B6="",NOT(ISERROR(SEARCH("KPI",$A$2))),NOT(ISERROR(SEARCH("Полиом",$A$2)))),0,IF(70-F6<=0,0,70-F6)) -> 0 | L6: =SUM(K6*240) -> 0 | M6: =SUM(D6*120) -> 0 | N6: =SUM(E6*120) -> 0 | O6: =SUM(F6*54) -> 6740.0737 | P6: =SUM(G6*54) -> 0 | Q6: =SUM(H6*120) -> 0 | R6: =SUM(I6*1000) -> 0 | S6: =SUM(J6*140) -> 0 | T6: =SUM(L6:S6) -> 6740.0737
A7: 3 | B7: 45964 | F7: =F6-E7+D7 -> 124.81618 | G7: =IF(OR(B7="",NOT(ISERROR(SEARCH("KPI",$A$2))),NOT(ISERROR(SEARCH("Полиом",$A$2)))),0,IF(70-F7<=0,0,70-F7)) -> 0 | L7: =SUM(K7*240) -> 0 | M7: =SUM(D7*120) -> 0 | N7: =SUM(E7*120) -> 0 | O7: =SUM(F7*54) -> 6740.0737 | P7: =SUM(G7*54) -> 0 | Q7: =SUM(H7*120) -> 0 | R7: =SUM(I7*1000) -> 0 | S7: =SUM(J7*140) -> 0 | T7: =SUM(L7:S7) -> 6740.0737
A8: 4 | B8: 45965 | F8: =F7-E8+D8 -> 124.81618 | G8: =IF(OR(B8="",NOT(ISERROR(SEARCH("KPI",$A$2))),NOT(ISERROR(SEARCH("Полиом",$A$2)))),0,IF(70-F8<=0,0,70-F8)) -> 0 | L8: =SUM(K8*240) -> 0 | M8: =SUM(D8*120) -> 0 | N8: =SUM(E8*120) -> 0 | O8: =SUM(F8*54) -> 6740.0737 | P8: =SUM(G8*54) -> 0 | Q8: =SUM(H8*120) -> 0 | R8: =SUM(I8*1000) -> 0 | S8: =SUM(J8*140) -> 0 | T8: =SUM(L8:S8) -> 6740.0737
A9: 5 | B9: 45966 | D9: 18.0268 | F9: =F8-E9+D9 -> 142.84298 | G9: =IF(OR(B9="",NOT(ISERROR(SEARCH("KPI",$A$2))),NOT(ISERROR(SEARCH("Полиом",$A$2)))),0,IF(70-F9<=0,0,70-F9)) -> 0 | L9: =SUM(K9*240) -> 0 | M9: =SUM(D9*120) -> 2163.216 | N9: =SUM(E9*120) -> 0 | O9: =SUM(F9*54) -> 7713.5209 | P9: =SUM(G9*54) -> 0 | Q9: =SUM(H9*120) -> 0 | R9: =SUM(I9*1000) -> 0 | S9: =SUM(J9*140) -> 0 | T9: =SUM(L9:S9) -> 9876.7369
A10: 6 | B10: 45967 | F10: =F9-E10+D10 -> 142.84298 | G10: =IF(OR(B10="",NOT(ISERROR(SEARCH("KPI",$A$2))),NOT(ISERROR(SEARCH("Полиом",$A$2)))),0,IF(70-F10<=0,0,70-F10)) -> 0 | L10: =SUM(K10*240) -> 0 | M10: =SUM(D10*120) -> 0 | N10: =SUM(E10*120) -> 0 | O10: =SUM(F10*54) -> 7713.5209 | P10: =SUM(G10*54) -> 0 | Q10: =SUM(H10*120) -> 0 | R10: =SUM(I10*1000) -> 0 | S10: =SUM(J10*140) -> 0 | T10: =SUM(L10:S10) -> 7713.5209
A11: 7 | B11: 45968 | F11: =F10-E11+D11 -> 142.84298 | G11: =IF(OR(B11="",NOT(ISERROR(SEARCH("KPI",$A$2))),NOT(ISERROR(SEARCH("Полиом",$A$2)))),0,IF(70-F11<=0,0,70-F11)) -> 0 | L11: =SUM(K11*240) -> 0 | M11: =SUM(D11*120) -> 0 | N11: =SUM(E11*120) -> 0 | O11: =SUM(F11*54) -> 7713.5209 | P11: =SUM(G11*54) -> 0 | Q11: =SUM(H11*120) -> 0 | R11: =SUM(I11*1000) -> 0 | S11: =SUM(J11*140) -> 0 | T11: =SUM(L11:S11) -> 7713.5209
A12: 8 | B12: 45969 | F12: =F11-E12+D12 -> 142.84298 | G12: =IF(OR(B12="",NOT(ISERROR(SEARCH("KPI",$A$2))),NOT(ISERROR(SEARCH("Полиом",$A$2)))),0,IF(70-F12<=0,0,70-F12)) -> 0 | L12: =SUM(K12*240) -> 0 | M12: =SUM(D12*120) -> 0 | N12: =SUM(E12*120) -> 0 | O12: =SUM(F12*54) -> 7713.5209 | P12: =SUM(G12*54) -> 0 | Q12: =SUM(H12*120) -> 0 | R12: =SUM(I12*1000) -> 0 | S12: =SUM(J12*140) -> 0 | T12: =SUM(L12:S12) -> 7713.5209
A13: 9 | B13: 45970 | F13: =F12-E13+D13 -> 142.84298 | G13: =IF(OR(B13="",NOT(ISERROR(SEARCH("KPI",$A$2))),NOT(ISERROR(SEARCH("Полиом",$A$2)))),0,IF(70-F13<=0,0,70-F13)) -> 0 | L13: =SUM(K13*240) -> 0 | M13: =SUM(D13*120) -> 0 | N13: =SUM(E13*120) -> 0 | O13: =SUM(F13*54) -> 7713.5209 | P13: =SUM(G13*54) -> 0 | Q13: =SUM(H13*120) -> 0 | R13: =SUM(I13*1000) -> 0 | S13: =SUM(J13*140) -> 0 | T13: =SUM(L13:S13) -> 7713.5209
A14: 10 | B14: 45971 | D14: 70.4946 | F14: =F13-E14+D14 -> 213.33758 | G14: =IF(OR(B14="",NOT(ISERROR(SEARCH("KPI",$A$2))),NOT(ISERROR(SEARCH("Полиом",$A$2)))),0,IF(70-F14<=0,0,70-F14)) -> 0 | L14: =SUM(K14*240) -> 0 | M14: =SUM(D14*120) -> 8459.352 | N14: =SUM(E14*120) -> 0 | O14: =SUM(F14*54) -> 11520.229 | P14: =SUM(G14*54) -> 0 | Q14: =SUM(H14*120) -> 0 | R14: =SUM(I14*1000) -> 0 | S14: =SUM(J14*140) -> 0 | T14: =SUM(L14:S14) -> 19979.581
A15: 11 | B15: 45972 | E15: 20.9834 | F15: =F14-E15+D15 -> 192.35418 | G15: =IF(OR(B15="",NOT(ISERROR(SEARCH("KPI",$A$2))),NOT(ISERROR(SEARCH("Полиом",$A$2)))),0,IF(70-F15<=0,0,70-F15)) -> 0 | L15: =SUM(K15*240) -> 0 | M15: =SUM(D15*120) -> 0 | N15: =SUM(E15*120) -> 2518.008 | O15: =SUM(F15*54) -> 10387.126 | P15: =SUM(G15*54) -> 0 | Q15: =SUM(H15*120) -> 0 | R15: =SUM(I15*1000) -> 0 | S15: =SUM(J15*140) -> 0 | T15: =SUM(L15:S15) -> 12905.134
A16: 12 | B16: 45973 | E16: 20.5248 | F16: =F15-E16+D16 -> 171.82938 | G16: =IF(OR(B16="",NOT(ISERROR(SEARCH("KPI",$A$2))),NOT(ISERROR(SEARCH("Полиом",$A$2)))),0,IF(70-F16<=0,0,70-F16)) -> 0 | L16: =SUM(K16*240) -> 0 | M16: =SUM(D16*120) -> 0 | N16: =SUM(E16*120) -> 2462.976 | O16: =SUM(F16*54) -> 9278.7865 | P16: =SUM(G16*54) -> 0 | Q16: =SUM(H16*120) -> 0 | R16: =SUM(I16*1000) -> 0 | S16: =SUM(J16*140) -> 0 | T16: =SUM(L16:S16) -> 11741.763
A17: 13 | B17: 45974 | D17: 17.9925 | E17: 19.7894 | F17: =F16-E17+D17 -> 170.03248 | G17: =IF(OR(B17="",NOT(ISERROR(SEARCH("KPI",$A$2))),NOT(ISERROR(SEARCH("Полиом",$A$2)))),0,IF(70-F17<=0,0,70-F17)) -> 0 | L17: =SUM(K17*240) -> 0 | M17: =SUM(D17*120) -> 2159.1 | N17: =SUM(E17*120) -> 2374.728 | O17: =SUM(F17*54) -> 9181.7539 | P17: =SUM(G17*54) -> 0 | Q17: =SUM(H17*120) -> 0 | R17: =SUM(I17*1000) -> 0 | S17: =SUM(J17*140) -> 0 | T17: =SUM(L17:S17) -> 13715.582
A18: 14 | B18: 45975 | F18: =F17-E18+D18 -> 170.03248 | G18: =IF(OR(B18="",NOT(ISERROR(SEARCH("KPI",$A$2))),NOT(ISERROR(SEARCH("Полиом",$A$2)))),0,IF(70-F18<=0,0,70-F18)) -> 0 | L18: =SUM(K18*240) -> 0 | M18: =SUM(D18*120) -> 0 | N18: =SUM(E18*120) -> 0 | O18: =SUM(F18*54) -> 9181.7539 | P18: =SUM(G18*54) -> 0 | Q18: =SUM(H18*120) -> 0 | R18: =SUM(I18*1000) -> 0 | S18: =SUM(J18*140) -> 0 | T18: =SUM(L18:S18) -> 9181.7539
A19: 15 | B19: 45976 | F19: =F18-E19+D19 -> 170.03248 | G19: =IF(OR(B19="",NOT(ISERROR(SEARCH("KPI",$A$2))),NOT(ISERROR(SEARCH("Полиом",$A$2)))),0,IF(70-F19<=0,0,70-F19)) -> 0 | L19: =SUM(K19*240) -> 0 | M19: =SUM(D19*120) -> 0 | N19: =SUM(E19*120) -> 0 | O19: =SUM(F19*54) -> 9181.7539 | P19: =SUM(G19*54) -> 0 | Q19: =SUM(H19*120) -> 0 | R19: =SUM(I19*1000) -> 0 | S19: =SUM(J19*140) -> 0 | T19: =SUM(L19:S19) -> 9181.7539
A20: 16 | B20: 45977 | F20: =F19-E20+D20 -> 170.03248 | G20: =IF(OR(B20="",NOT(ISERROR(SEARCH("KPI",$A$2))),NOT(ISERROR(SEARCH("Полиом",$A$2)))),0,IF(70-F20<=0,0,70-F20)) -> 0 | L20: =SUM(K20*240) -> 0 | M20: =SUM(D20*120) -> 0 | N20: =SUM(E20*120) -> 0 | O20: =SUM(F20*54) -> 9181.7539 | P20: =SUM(G20*54) -> 0 | Q20: =SUM(H20*120) -> 0 | R20: =SUM(I20*1000) -> 0 | S20: =SUM(J20*140) -> 0 | T20: =SUM(L20:S20) -> 9181.7539
A21: 17 | B21: 45978 | E21: 3.2094 | F21: =F20-E21+D21 -> 166.82308 | G21: =IF(OR(B21="",NOT(ISERROR(SEARCH("KPI",$A$2))),NOT(ISERROR(SEARCH("Полиом",$A$2)))),0,IF(70-F21<=0,0,70-F21)) -> 0 | L21: =SUM(K21*240) -> 0 | M21: =SUM(D21*120) -> 0 | N21: =SUM(E21*120) -> 385.128 | O21: =SUM(F21*54) -> 9008.4463 | P21: =SUM(G21*54) -> 0 | Q21: =SUM(H21*120) -> 0 | R21: =SUM(I21*1000) -> 0 | S21: =SUM(J21*140) -> 0 | T21: =SUM(L21:S21) -> 9393.5743
A22: 18 | B22: 45979 | E22: 8.65788 | F22: =F21-E22+D22 -> 158.1652 | G22: =IF(OR(B22="",NOT(ISERROR(SEARCH("KPI",$A$2))),NOT(ISERROR(SEARCH("Полиом",$A$2)))),0,IF(70-F22<=0,0,70-F22)) -> 0 | L22: =SUM(K22*240) -> 0 | M22: =SUM(D22*120) -> 0 | N22: =SUM(E22*120) -> 1038.9456 | O22: =SUM(F22*54) -> 8540.9208 | P22: =SUM(G22*54) -> 0 | Q22: =SUM(H22*120) -> 0 | R22: =SUM(I22*1000) -> 0 | S22: =SUM(J22*140) -> 0 | T22: =SUM(L22:S22) -> 9579.8664
A23: 19 | B23: 45980 | E23: 3.9537 | F23: =F22-E23+D23 -> 154.2115 | G23: =IF(OR(B23="",NOT(ISERROR(SEARCH("KPI",$A$2))),NOT(ISERROR(SEARCH("Полиом",$A$2)))),0,IF(70-F23<=0,0,70-F23)) -> 0 | L23: =SUM(K23*240) -> 0 | M23: =SUM(D23*120) -> 0 | N23: =SUM(E23*120) -> 474.444 | O23: =SUM(F23*54) -> 8327.421 | P23: =SUM(G23*54) -> 0 | Q23: =SUM(H23*120) -> 0 | R23: =SUM(I23*1000) -> 0 | S23: =SUM(J23*140) -> 0 | T23: =SUM(L23:S23) -> 8801.865
A24: 20 | B24: 45981 | D24: 17.4615 | E24: 3.6718 | F24: =F23-E24+D24 -> 168.0012 | G24: =IF(OR(B24="",NOT(ISERROR(SEARCH("KPI",$A$2))),NOT(ISERROR(SEARCH("Полиом",$A$2)))),0,IF(70-F24<=0,0,70-F24)) -> 0 | L24: =SUM(K24*240) -> 0 | M24: =SUM(D24*120) -> 2095.38 | N24: =SUM(E24*120) -> 440.616 | O24: =SUM(F24*54) -> 9072.0648 | P24: =SUM(G24*54) -> 0 | Q24: =SUM(H24*120) -> 0 | R24: =SUM(I24*1000) -> 0 | S24: =SUM(J24*140) -> 0 | T24: =SUM(L24:S24) -> 11608.061
A25: 21 | B25: 45982 | D25: 70.9234 | E25: 21.7115 | F25: =F24-E25+D25 -> 217.2131 | G25: =IF(OR(B25="",NOT(ISERROR(SEARCH("KPI",$A$2))),NOT(ISERROR(SEARCH("Полиом",$A$2)))),0,IF(70-F25<=0,0,70-F25)) -> 0 | L25: =SUM(K25*240) -> 0 | M25: =SUM(D25*120) -> 8510.808 | N25: =SUM(E25*120) -> 2605.38 | O25: =SUM(F25*54) -> 11729.507 | P25: =SUM(G25*54) -> 0 | Q25: =SUM(H25*120) -> 0 | R25: =SUM(I25*1000) -> 0 | S25: =SUM(J25*140) -> 0 | T25: =SUM(L25:S25) -> 22845.695
A26: 22 | B26: 45983 | F26: =F25-E26+D26 -> 217.2131 | G26: =IF(OR(B26="",NOT(ISERROR(SEARCH("KPI",$A$2))),NOT(ISERROR(SEARCH("Полиом",$A$2)))),0,IF(70-F26<=0,0,70-F26)) -> 0 | L26: =SUM(K26*240) -> 0 | M26: =SUM(D26*120) -> 0 | N26: =SUM(E26*120) -> 0 | O26: =SUM(F26*54) -> 11729.507 | P26: =SUM(G26*54) -> 0 | Q26: =SUM(H26*120) -> 0 | R26: =SUM(I26*1000) -> 0 | S26: =SUM(J26*140) -> 0 | T26: =SUM(L26:S26) -> 11729.507
A27: 23 | B27: 45984 | F27: =F26-E27+D27 -> 217.2131 | G27: =IF(OR(B27="",NOT(ISERROR(SEARCH("KPI",$A$2))),NOT(ISERROR(SEARCH("Полиом",$A$2)))),0,IF(70-F27<=0,0,70-F27)) -> 0 | L27: =SUM(K27*240) -> 0 | M27: =SUM(D27*120) -> 0 | N27: =SUM(E27*120) -> 0 | O27: =SUM(F27*54) -> 11729.507 | P27: =SUM(G27*54) -> 0 | Q27: =SUM(H27*120) -> 0 | R27: =SUM(I27*1000) -> 0 | S27: =SUM(J27*140) -> 0 | T27: =SUM(L27:S27) -> 11729.507
A28: 24 | B28: 45985 | D28: 34.9712 | E28: 4.0396 | F28: =F27-E28+D28 -> 248.1447 | G28: =IF(OR(B28="",NOT(ISERROR(SEARCH("KPI",$A$2))),NOT(ISERROR(SEARCH("Полиом",$A$2)))),0,IF(70-F28<=0,0,70-F28)) -> 0 | L28: =SUM(K28*240) -> 0 | M28: =SUM(D28*120) -> 4196.544 | N28: =SUM(E28*120) -> 484.752 | O28: =SUM(F28*54) -> 13399.814 | P28: =SUM(G28*54) -> 0 | Q28: =SUM(H28*120) -> 0 | R28: =SUM(I28*1000) -> 0 | S28: =SUM(J28*140) -> 0 | T28: =SUM(L28:S28) -> 18081.11
A29: 25 | B29: 45986 | E29: 21.7725 | F29: =F28-E29+D29 -> 226.3722 | G29: =IF(OR(B29="",NOT(ISERROR(SEARCH("KPI",$A$2))),NOT(ISERROR(SEARCH("Полиом",$A$2)))),0,IF(70-F29<=0,0,70-F29)) -> 0 | L29: =SUM(K29*240) -> 0 | M29: =SUM(D29*120) -> 0 | N29: =SUM(E29*120) -> 2612.7 | O29: =SUM(F29*54) -> 12224.099 | P29: =SUM(G29*54) -> 0 | Q29: =SUM(H29*120) -> 0 | R29: =SUM(I29*1000) -> 0 | S29: =SUM(J29*140) -> 0 | T29: =SUM(L29:S29) -> 14836.799
A30: 26 | B30: 45987 | D30: 17.7885 | E30: 23.4968 | F30: =F29-E30+D30 -> 220.6639 | G30: =IF(OR(B30="",NOT(ISERROR(SEARCH("KPI",$A$2))),NOT(ISERROR(SEARCH("Полиом",$A$2)))),0,IF(70-F30<=0,0,70-F30)) -> 0 | L30: =SUM(K30*240) -> 0 | M30: =SUM(D30*120) -> 2134.62 | N30: =SUM(E30*120) -> 2819.616 | O30: =SUM(F30*54) -> 11915.851 | P30: =SUM(G30*54) -> 0 | Q30: =SUM(H30*120) -> 0 | R30: =SUM(I30*1000) -> 0 | S30: =SUM(J30*140) -> 0 | T30: =SUM(L30:S30) -> 16870.087
A31: 27 | B31: 45988 | E31: 28.4518 | F31: =F30-E31+D31 -> 192.2121 | G31: =IF(OR(B31="",NOT(ISERROR(SEARCH("KPI",$A$2))),NOT(ISERROR(SEARCH("Полиом",$A$2)))),0,IF(70-F31<=0,0,70-F31)) -> 0 | L31: =SUM(K31*240) -> 0 | M31: =SUM(D31*120) -> 0 | N31: =SUM(E31*120) -> 3414.216 | O31: =SUM(F31*54) -> 10379.453 | P31: =SUM(G31*54) -> 0 | Q31: =SUM(H31*120) -> 0 | R31: =SUM(I31*1000) -> 0 | S31: =SUM(J31*140) -> 0 | T31: =SUM(L31:S31) -> 13793.669
A32: 28 | B32: 45989 | D32: 17.9406 | E32: 15.6684 | F32: =F31-E32+D32 -> 194.4843 | G32: =IF(OR(B32="",NOT(ISERROR(SEARCH("KPI",$A$2))),NOT(ISERROR(SEARCH("Полиом",$A$2)))),0,IF(70-F32<=0,0,70-F32)) -> 0 | L32: =SUM(K32*240) -> 0 | M32: =SUM(D32*120) -> 2152.872 | N32: =SUM(E32*120) -> 1880.208 | O32: =SUM(F32*54) -> 10502.152 | P32: =SUM(G32*54) -> 0 | Q32: =SUM(H32*120) -> 0 | R32: =SUM(I32*1000) -> 0 | S32: =SUM(J32*140) -> 0 | T32: =SUM(L32:S32) -> 14535.232
A33: 29 | B33: 45990 | F33: =F32-E33+D33 -> 194.4843 | G33: =IF(OR(B33="",NOT(ISERROR(SEARCH("KPI",$A$2))),NOT(ISERROR(SEARCH("Полиом",$A$2)))),0,IF(70-F33<=0,0,70-F33)) -> 0 | L33: =SUM(K33*240) -> 0 | M33: =SUM(D33*120) -> 0 | N33: =SUM(E33*120) -> 0 | O33: =SUM(F33*54) -> 10502.152 | P33: =SUM(G33*54) -> 0 | Q33: =SUM(H33*120) -> 0 | R33: =SUM(I33*1000) -> 0 | S33: =SUM(J33*140) -> 0 | T33: =SUM(L33:S33) -> 10502.152
A34: 30 | B34: 45991 | F34: =F33-E34+D34 -> 194.4843 | G34: =IF(OR(B34="",NOT(ISERROR(SEARCH("KPI",$A$2))),NOT(ISERROR(SEARCH("Полиом",$A$2)))),0,IF(70-F34<=0,0,70-F34)) -> 0 | L34: =SUM(K34*240) -> 0 | M34: =SUM(D34*120) -> 0 | N34: =SUM(E34*120) -> 0 | O34: =SUM(F34*54) -> 10502.152 | P34: =SUM(G34*54) -> 0 | Q34: =SUM(H34*120) -> 0 | R34: =SUM(I34*1000) -> 0 | S34: =SUM(J34*140) -> 0 | T34: =SUM(L34:S34) -> 10502.152
G35: =IF(OR(B35="",NOT(ISERROR(SEARCH("KPI",$A$2))),NOT(ISERROR(SEARCH("Полиом",$A$2)))),0,IF(70-F35<=0,0,70-F35)) -> 0 | L35: =SUM(K35*240) -> 0 | M35: =SUM(D35*120) -> 0 | N35: =SUM(E35*120) -> 0 | O35: =SUM(F35*54) -> 0 | P35: =SUM(G35*54) -> 0 | Q35: =SUM(H35*120) -> 0 | R35: =SUM(I35*1000) -> 0 | S35: =SUM(J35*140) -> 0 | T35: =SUM(L35:S35) -> 0
D36: =SUM(D5:D35) -> 265.5991 | E36: =SUM(E5:E35) -> 195.93098 | F36: =SUM(F5:F35) -> 5240.8168 | G36: =SUM(G5:G35) -> 0 | H36: =SUM(H5:H35) -> 0 | I36: =SUM(I5:I35) -> 0 | J36: =SUM(J5:J35) -> 0 | K36: =SUM(K5:K35) -> 0 | ... T36: =SUM(T5:T35) -> 338387.71
T37: =T36*1.2 -> 406065.26

Sheet ИТОГО
A1: =G16 -> 1.2249274e+08
I2: ТОП
A3: Склад | B3: Сибур | C3: Завод | D3: Русвинил | E3: Клиенты сибура | F3: Остальные | G3: Итого | I3: Казань_Автосервисная | J3: 23143268
A4: Баумана | B4: =INDEX($M$44:$M$53,MATCH(A4,$A$44:$A$53,0),1) -> 8924080 | C4: 0 | D4: =INDEX($B$56:$B$72,MATCH(A4,$A$56:$A$72,0),1) -> 774895.05 | E4: =SUMIF($F$19:$F$41,A4,$G$19:$G$41) -> 0 | F4: =SUMIF($B$19:$B$27,A4,$C$19:$C$27) -> 73217.6 | G4: =SUM(B4:F4) -> 9772192.6 | I4: Нижнекамск завод | J4: 19482962
A5: Новикова-Прибоя | B5: =INDEX($M$44:$M$53,MATCH(A5,$A$44:$A$53,0),1) -> 11956020 | C5: 0 | D5: =INDEX($B$56:$B$72,MATCH(A5,$A$56:$A$72,0),1) -> 187151.94 | E5: =SUMIF($F$19:$F$41,A5,$G$19:$G$41) -> 0 | F5: =SUMIF($B$19:$B$27,A5,$C$19:$C$27) -> 7920 | G5: =SUM(B5:F5) -> 12151092 | I5: Новикова-Прибоя | J5: 14483152
A6: Екатеринбург | B6: =INDEX($M$44:$M$53,MATCH(A6,$A$44:$A$53,0),1) -> 10380689 | C6: 0 | D6: =INDEX($B$56:$B$72,MATCH(A6,$A$56:$A$72,0),1) -> 0 | E6: =SUMIF($F$19:$F$41,A6,$G$19:$G$41) -> 0 | F6: =SUMIF($B$19:$B$27,A6,$C$19:$C$27) -> 0 | G6: =SUM(B6:F6) -> 10380689 | I6: Екатеринбург | J6: 11908609
A7: Новосибирск | B7: =INDEX($M$44:$M$53,MATCH(A7,$A$44:$A$53,0),1) -> 7819161.9 | C7: 0 | D7: =INDEX($B$56:$B$72,MATCH(A7,$A$56:$A$72,0),1) -> 0 | E7: =SUMIF($F$19:$F$41,A7,$G$19:$G$41) -> 406065.26 | F7: =SUMIF($B$19:$B$27,A7,$C$19:$C$27) -> 0 | G7: =SUM(B7:F7) -> 8225227.1 | I7: Баумана | J7: 11544503
A8: Новосибирск_Пасечная | B8: =INDEX($M$44:$M$53,MATCH(A8,$A$44:$A$53,0),1) -> 4797371.4 | C8: 0 | D8: =INDEX($B$56:$B$72,MATCH(A8,$A$56:$A$72,0),1) -> 0 | E8: =SUMIF($F$19:$F$41,A8,$G$19:$G$41) -> 0 | F8: =SUMIF($B$19:$B$27,A8,$C$19:$C$27) -> 0 | G8: =SUM(B8:F8) -> 4797371.4
A9: Казань_Автосервисная | B9: =INDEX($M$44:$M$53,MATCH(A9,$A$44:$A$53,0),1) -> 23025567 | C9: 0 | D9: =INDEX($B$56:$B$72,MATCH(A9,$A$56:$A$72,0),1) -> 0 | E9: =SUMIF($F$19:$F$41,A9,$G$19:$G$41) -> 0 | F9: =SUMIF($B$19:$B$27,A9,$C$19:$C$27) -> 0 | G9: =SUM(B9:F9) -> 23025567 | I9: Казань_Приволжская | J9: 9900926.9
A10: Казань_Приволжская | B10: =INDEX($M$44:$M$53,MATCH(A10,$A$44:$A$53,0),1) -> 9548916.4 | C10: 0 | D10: =INDEX($B$56:$B$72,MATCH(A10,$A$56:$A$72,0),1) -> 0 | E10: =SUMIF($F$19:$F$41,A10,$G$19:$G$41) -> 0 | F10: =SUMIF($B$19:$B$27,A10,$C$19:$C$27) -> 0 | G10: =SUM(B10:F10) -> 9548916.4 | I10: Зеленодольск | J10: 9082789.1
A11: Зеленодольск | B11: =INDEX($M$44:$M$53,MATCH(A11,$A$44:$A$53,0),1) -> 8845863.3 | C11: 0 | D11: =INDEX($B$56:$B$72,MATCH(A11,$A$56:$A$72,0),1) -> 0 | E11: =SUMIF($F$19:$F$41,A11,$G$19:$G$41) -> 360241.3 | F11: =SUMIF($B$19:$B$27,A11,$C$19:$C$27) -> 0 | G11: =SUM(B11:F11) -> 9206104.6 | I11: Новосибирск | J11: 7932975.6
A12: Нижнекамск | B12: =INDEX($M$44:$M$53,MATCH(A12,$A$44:$A$53,0),1) -> 4418904.4 | C12: 0 | D12: =INDEX($B$56:$B$72,MATCH(A12,$A$56:$A$72,0),1) -> 0 | E12: =SUMIF($F$19:$F$41,A12,$G$19:$G$41) -> 0 | F12: =SUMIF($B$19:$B$27,A12,$C$19:$C$27) -> 0 | G12: =SUM(B12:F12) -> 4418904.4 | I12: Нижнекамск | J12: 7580244.6
A13: Нижнекамск завод | B13: 0 | C13: =C29+C36 -> 30820063 | D13: =INDEX($B$56:$B$72,MATCH(A13,$A$56:$A$72,0),1) -> 0 | E13: =SUMIF($F$19:$F$41,A13,$G$19:$G$41) -> 0 | F13: =SUMIF($B$19:$B$27,A13,$C$19:$C$27) -> 0 | G13: =SUM(B13:F13) -> 30820063 | I13: ГАЗ | J13: 6720000
A14: Монастырка | B14: 0 | C14: 0 | D14: =INDEX($B$56:$B$72,MATCH(A14,$A$56:$A$72,0),1) -> 0 | E14: =SUMIF($F$19:$F$41,A14,$G$19:$G$41) -> 0 | F14: =SUMIF($B$19:$B$27,A14,$C$19:$C$27) -> 0 | G14: =SUM(B14:F14) -> 0 | I14: Монастырка | J14: 2464921.6
A15: ГАЗ | B15: =INDEX($M$44:$M$53,MATCH(A15,$A$44:$A$53,0),1) -> 0 | C15: 0 | D15: =INDEX($B$56:$B$72,MATCH(A15,$A$56:$A$72,0),1) -> 146608.11 | E15: =SUMIF($F$19:$F$41,A15,$G$19:$G$41) -> 0 | F15: =SUMIF($B$19:$B$27,A15,$C$19:$C$27) -> 0 | G15: =SUM(B15:F15) -> 146608.11
B16: =SUM(B4:B15) -> 89716573 | C16: =SUM(C4:C15) -> 30820063 | D16: =SUM(D4:D15) -> 1108655.1 | E16: =SUM(E4:E15) -> 766306.56 | F16: =SUM(F4:F15) -> 81137.6 | G16: =SUM(G4:G15) -> 1.2249274e+08
A18: Остальные клиенты | C18: =SUM(C19:C27) -> 81137.6 | E18: Клиенты сибура | G18: =SUM(G19:G40) -> 766306.56
A19: Стройтех | B19: Баумана | C19: {=IFERROR(INDIRECT("'" & A19 & "'!A1"),)} -> 23948 | E19: Приоритет | F19: Баумана | G19: {=IFERROR(INDIRECT("'" & E19 & " " & F19 & "'!A1"),0)} -> 0
A20: Ергарда | B20: Баумана | C20: {=IFERROR(INDIRECT("'" & A20 & "'!A1"),)} -> 8640 | E20: Фармпласт | F20: Баумана | G20: {=IFERROR(INDIRECT("'" & E20 & " " & F20 & "'!A1"),0)} -> 0
A21: Литейные решения | B21: Баумана | C21: {=IFERROR(INDIRECT("'" & A21 & "'!A1"),)} -> 16675.2 | E21: Юг Полимер | F21: Баумана | G21: {=IFERROR(INDIRECT("'" & E21 & " " & F21 & "'!A1"),0)} -> 0
A22: Сандекс | B22: Баумана | C22: {=IFERROR(INDIRECT("'" & A22 & "'!A1"),)} -> 21823.2 | E22: Центрополимер | F22: Екатеринбург | G22: {=IFERROR(INDIRECT("'" & E22 & " " & F22 & "'!A1"),0)} -> 0
A23: ЛС-Техномет | B23: Баумана | C23: {=IFERROR(INDIRECT("'" & A23 & "'!A1"),)} -> 2131.2 | E23: Приоритет | F23: Екатеринбург | G23: {=IFERROR(INDIRECT("'" & E23 & " " & F23 & "'!A1"),0)} -> 0
A24: РусДжам | B24: ГАЗ | C24: {=IFERROR(INDIRECT("'" & A24 & "'!A1"),)} -> 0 | E24: Фармпласт | F24: Екатеринбург | G24: {=IFERROR(INDIRECT("'" & E24 & " " & F24 & "'!A1"),0)} -> 0
A25: Виго | B25: Новикова-Прибоя | C25: {=IFERROR(INDIRECT("'" & A25 & "'!A1"),)} -> 0 | E25: Приоритет | F25: Зеленодольск | G25: {=IFERROR(INDIRECT("'" & E25 & " " & F25 & "'!A1"),0)} -> 0
A26: Доктор Франк | B26: Новикова-Прибоя | C26: {=IFERROR(INDIRECT("'" & A26 & "'!A1"),)} -> 7920 | E26: Данафлекс | F26: Зеленодольск | G26: {=IFERROR(INDIRECT("'" & E26 & " " & F26 & "'!t37"),0)} -> 360241.3
A27: Нефтезол | B27: Новикова-Прибоя | C27: {=IFERROR(INDIRECT("'" & A27 & "'!A1"),)} -> 0 | E27: ИП Ксендз | F27: Нижнекамск | G27: {=IFERROR(INDIRECT("'" & E27 & " " & F27 & "'!A1"),0)} -> 0
E28: Фармпласт | F28: Новикова-Прибоя | G28: {=IFERROR(INDIRECT("'" & E28 & " " & F28 & "'!A1"),0)} -> 0
A29: Нижнекамск завод | C29: =SUM(C30:C34) -> 19155890 | E29: Центрополимер | F29: Новикова-Прибоя | G29: {=IFERROR(INDIRECT("'" & E29 & " " & F29 & "'!A1"),0)} -> 0
A30: ПРР | C30: {=INDIRECT("'" & A29 & "'!F17")} -> 15902450 | E30: Юг Полимер | F30: Новикова-Прибоя | G30: {=IFERROR(INDIRECT("'" & E30 & " " & F30 & "'!A1"),0)} -> 0
A31: Кладовки | C31: {=INDIRECT("'" & A29 & "'!F16")} -> 0 | E31: Приоритет | F31: Новикова-Прибоя | G31: {=IFERROR(INDIRECT("'" & E31 & " " & F31 & "'!A1"),0)} -> 0 | J31: 16297524
A32: Стропальщики | C32: {=INDIRECT("'" & A29 & "'!F18")} -> 804000 | E32: Биаксплен | F32: Новосибирск | G32: {=IFERROR(INDIRECT("'" & E32 & " " & F32 & "'!A1"),0)} -> 406065.26 | J32: 71775903
A33: Мойка контейнеров | C33: {=INDIRECT("'" & A29 & "'!F19")} -> 2449440 | E33: Центрополимер | F33: Новосибирск | G33: {=IFERROR(INDIRECT("'" & E33 & " " & F33 & "'!A1"),0)} -> 0 | J33: =J31+J32-78062.4 -> 87995365
A34: Комитаус | C34: {=INDIRECT("'" & A29 & "'!F20")} -> 0 | E34: Фармпласт | F34: Новосибирск | G34: {=IFERROR(INDIRECT("'" & E34 & " " & F34 & "'!A1"),0)} -> 0
E35: Юг Полимер | F35: Зеленодольск | G35: {=IFERROR(INDIRECT("'" & E35 & " " & F35 & "'!A1"),0)} -> 0
A36: Контейнерные площадки | C36: =SUM(C37:C41) -> 11664173 | E36: Фармпласт | F36: Казань_Автосервисная | G36: {=IFERROR(INDIRECT("'" & E36 & " " & F36 & "'!A1"),0)} -> 0 | I36: =K42-J33 -> 1721208.3
A37: КОС | C37: 4715760.6 | E37: Приоритет | F37: Казань_Приволжская | G37: {=IFERROR(INDIRECT("'" & E37 & " " & F37 & "'!A1"),0)} -> 0
A38: Нижнекамск | C38: 6948412.8 | E38: Центрополимер | F38: Баумана | G38: {=IFERROR(INDIRECT("'" & E38 & " " & F38 & "'!A1"),0)} -> 0
E39: Приоритет | F39: Казань_Автосервисная | G39: {=IFERROR(INDIRECT("'" & E39 & " " & F39 & "'!A1"),0)} -> 0
E40: Оникс | F40: Нижнекамск | G40: {=IFERROR(INDIRECT("'" & E40 & " " & F40 & "'!A1"),0)} -> 0
A42: СИБУР | K42: =SUM(M44:M53) -> 89716573
...

Sheet Другое

Sheet Нижнекамск завод
A9: № | B9: Наименование услуг (работ) | C9: Ед. изм. | D9: Количество | E9: Цена | F9: Сумма
A14: Итого: | F14: =SUM(F10:F13) -> 0
A15: Без налога (НДС) | F15: =SUM(F14) -> 0
A16: Всего (с учетом НДС) | F16: =SUM(F15)*1.2 -> 0
A17: Вышеперечисленные услуги (работы) выполнены полностью. | E17: ПРР | F17: 15902450
A18: ПОКЛАЖЕДАТЕЛЬ претензий по объему, качеству и срокам оказания услуг претензий не имеет. | E18: Стропальщики | F18: 804000
E19: Контейнеры | F19: 2449440
E20: Комитаус | F20: 0
A21: ООО "ДТМ" | D21: ПАО "Нижнекамскнефтехим"
A23: ____________________Молькова Т.Ю. | B23: Расстегаев Д.О. | D23: ____________________

Sheet РВ Баумана
R1: Выходной | S1: Рабочий
Q2: Выгрузка | R2: =SUMIF($P$6:$P$36,R$1,$C6:$C36) -> 0 | S2: =SUMIF($P$6:$P$36,S$1,$C6:$C36) -> 0
A3: ="Отчет по хранению товара РВ " & TEXT(A6,"ММММ ") & YEAR(A6) & " Баумана" -> Отчет по хранению товара РВ Ноябрь 2025 Баумана | Q3: Отгрузка | R3: =SUMIF($P$6:$P$36,R$1,$D6:$D36) -> 19.35 | S3: =SUMIF($P$6:$P$36,S$1,$D6:$D36) -> 208.97
A4: дата | C4: Выгрузка кол-во тонн | D4: Загрузка кол-во тонн | E4: Выгрузка после 20:00 | F4: Загрузка после 20:00 | G4: Хранение | H4: переконсолидация (тонн) | I4: стоимость выгрузки | J4: стоимость загрузки | K4: Стоимость выгрузки после 20:00 | L4: Стоимость загрузки после 20:00 | M4: стоимость хранения | N4: стоимость переконс. | O4: итого
G5: (кол-во тонн)
A6: 45962 | C6: 0 | D6: 40.85 | G6: 1448.615 | I6: =IF(P6="Выходной",SUM(C6*150)*1.5,SUM(C6*150)) -> 0 | J6: =IF(P6="Выходной",SUM(D6*150)*1.5,SUM(D6*150)) -> 6127.5 | K6: =IF(OR(WEEKDAY(A6)=1,WEEKDAY(A6)=7,NOT(ISERROR(MATCH(A6,[1]Праздники!A:A,0)))),SUM(E6*225)*1.5,SUM(E6*225)) -> 0 | L6: =IF(OR(WEEKDAY(A6)=1,WEEKDAY(A6)=7,NOT(ISERROR(MATCH(A6,[1]Праздники!A:A,0)))),SUM(F6*225)*1.5,SUM(F6*225)) -> 0 | M6: =SUM(G6*15) -> 21729.225 | N6: =SUM(H6)*750 -> 0 | O6: =SUM(I6:N6) -> 27856.725 | P6: Рабочий
A7: 45963 | C7: 0 | D7: 0 | G7: =IF(A7 ="",0,G6+C7+E7-D6-F6) -> 1407.765 | I7: =IF(P7="Выходной",SUM(C7*150)*1.5,SUM(C7*150)) -> 0 | J7: =IF(P7="Выходной",SUM(D7*150)*1.5,SUM(D7*150)) -> 0 | K7: =IF(OR(WEEKDAY(A7)=1,WEEKDAY(A7)=7,NOT(ISERROR(MATCH(A7,[1]Праздники!A:A,0)))),SUM(E7*225)*1.5,SUM(E7*225)) -> 0 | L7: =IF(OR(WEEKDAY(A7)=1,WEEKDAY(A7)=7,NOT(ISERROR(MATCH(A7,[1]Праздники!A:A,0)))),SUM(F7*225)*1.5,SUM(F7*225)) -> 0 | M7: =SUM(G7*15) -> 21116.475 | N7: =SUM(H7)*750 -> 0 | O7: =SUM(I7:N7) -> 21116.475 | P7: =IF(OR(WEEKDAY(A7)=1,WEEKDAY(A7)=7,NOT(ISERROR(MATCH(A7,[1]Праздники!A:A,0)))),"Выходной","Рабочий") -> Выходной
A8: 45964 | C8: 0 | D8: 18 | G8: =IF(A8 ="",0,G7+C8+E8-D7-F7) -> 1407.765 | I8: =IF(P8="Выходной",SUM(C8*150)*1.5,SUM(C8*150)) -> 0 | J8: =IF(P8="Выходной",SUM(D8*150)*1.5,SUM(D8*150)) -> 4050 | K8: =IF(OR(WEEKDAY(A8)=1,WEEKDAY(A8)=7,NOT(ISERROR(MATCH(A8,[1]Праздники!A:A,0)))),SUM(E8*225)*1.5,SUM(E8*225)) -> 0 | L8: =IF(OR(WEEKDAY(A8)=1,WEEKDAY(A8)=7,NOT(ISERROR(MATCH(A8,[1]Праздники!A:A,0)))),SUM(F8*225)*1.5,SUM(F8*225)) -> 0 | M8: =SUM(G8*15) -> 21116.475 | N8: =SUM(H8)*750 -> 0 | O8: =SUM(I8:N8) -> 25166.475 | P8: =IF(OR(WEEKDAY(A8)=1,WEEKDAY(A8)=7,NOT(ISERROR(MATCH(A8,[1]Праздники!A:A,0)))),"Выходной","Рабочий") -> Выходной
A9: 45965 | C9: 0 | D9: 0 | G9: =IF(A9 ="",0,G8+C9+E9-D8-F8) -> 1389.765 | I9: =IF(P9="Выходной",SUM(C9*150)*1.5,SUM(C9*150)) -> 0 | J9: =IF(P9="Выходной",SUM(D9*150)*1.5,SUM(D9*150)) -> 0 | K9: =IF(OR(WEEKDAY(A9)=1,WEEKDAY(A9)=7,NOT(ISERROR(MATCH(A9,[1]Праздники!A:A,0)))),SUM(E9*225)*1.5,SUM(E9*225)) -> 0 | L9: =IF(OR(WEEKDAY(A9)=1,WEEKDAY(A9)=7,NOT(ISERROR(MATCH(A9,[1]Праздники!A:A,0)))),SUM(F9*225)*1.5,SUM(F9*225)) -> 0 | M9: =SUM(G9*15) -> 20846.475 | N9: =SUM(H9)*750 -> 0 | O9: =SUM(I9:N9) -> 20846.475 | P9: =IF(OR(WEEKDAY(A9)=1,WEEKDAY(A9)=7,NOT(ISERROR(MATCH(A9,[1]Праздники!A:A,0)))),"Выходной","Рабочий") -> Выходной
A10: 45966 | C10: 0 | D10: 8.575 | G10: =IF(A10 ="",0,G9+C10+E10-D9-F9) -> 1389.765 | I10: =IF(P10="Выходной",SUM(C10*150)*1.5,SUM(C10*150)) -> 0 | J10: =IF(P10="Выходной",SUM(D10*150)*1.5,SUM(D10*150)) -> 1286.25 | K10: =IF(OR(WEEKDAY(A10)=1,WEEKDAY(A10)=7,NOT(ISERROR(MATCH(A10,[1]Праздники!A:A,0)))),SUM(E10*225)*1.5,SUM(E10*225)) -> 0 | L10: =IF(OR(WEEKDAY(A10)=1,WEEKDAY(A10)=7,NOT(ISERROR(MATCH(A10,[1]Праздники!A:A,0)))),SUM(F10*225)*1.5,SUM(F10*225)) -> 0 | M10: =SUM(G10*15) -> 20846.475 | N10: =SUM(H10)*750 -> 0 | O10: =SUM(I10:N10) -> 22132.725 | P10: =IF(OR(WEEKDAY(A10)=1,WEEKDAY(A10)=7,NOT(ISERROR(MATCH(A10,[1]Праздники!A:A,0)))),"Выходной","Рабочий") -> Рабочий
A11: 45967 | C11: 0 | D11: 0 | G11: =IF(A11 ="",0,G10+C11+E11-D10-F10) -> 1381.19 | I11: =IF(P11="Выходной",SUM(C11*150)*1.5,SUM(C11*150)) -> 0 | J11: =IF(P11="Выходной",SUM(D11*150)*1.5,SUM(D11*150)) -> 0 | K11: =IF(OR(WEEKDAY(A11)=1,WEEKDAY(A11)=7,NOT(ISERROR(MATCH(A11,[1]Праздники!A:A,0)))),SUM(E11*225)*1.5,SUM(E11*225)) -> 0 | L11: =IF(OR(WEEKDAY(A11)=1,WEEKDAY(A11)=7,NOT(ISERROR(MATCH(A11,[1]Праздники!A:A,0)))),SUM(F11*225)*1.5,SUM(F11*225)) -> 0 | M11: =SUM(G11*15) -> 20717.85 | N11: =SUM(H11)*750 -> 0 | O11: =SUM(I11:N11) -> 20717.85 | P11: =IF(OR(WEEKDAY(A11)=1,WEEKDAY(A11)=7,NOT(ISERROR(MATCH(A11,[1]Праздники!A:A,0)))),"Выходной","Рабочий") -> Рабочий
A12: 45968 | C12: 0 | D12: 0 | G12: =IF(A12 ="",0,G11+C12+E12-D11-F11) -> 1381.19 | I12: =IF(P12="Выходной",SUM(C12*150)*1.5,SUM(C12*150)) -> 0 | J12: =IF(P12="Выходной",SUM(D12*150)*1.5,SUM(D12*150)) -> 0 | K12: =IF(OR(WEEKDAY(A12)=1,WEEKDAY(A12)=7,NOT(ISERROR(MATCH(A12,[1]Праздники!A:A,0)))),SUM(E12*225)*1.5,SUM(E12*225)) -> 0 | L12: =IF(OR(WEEKDAY(A12)=1,WEEKDAY(A12)=7,NOT(ISERROR(MATCH(A12,[1]Праздники!A:A,0)))),SUM(F12*225)*1.5,SUM(F12*225)) -> 0 | M12: =SUM(G12*15) -> 20717.85 | N12: =SUM(H12)*750 -> 0 | O12: =SUM(I12:N12) -> 20717.85 | P12: =IF(OR(WEEKDAY(A12)=1,WEEKDAY(A12)=7,NOT(ISERROR(MATCH(A12,[1]Праздники!A:A,0)))),"Выходной","Рабочий") -> Рабочий
A13: 45969 | C13: 0 | D13: 0 | G13: =IF(A13 ="",0,G12+C13+E13-D12-F12) -> 1381.19 | I13: =IF(P13="Выходной",SUM(C13*150)*1.5,SUM(C13*150)) -> 0 | J13: =IF(P13="Выходной",SUM(D13*150)*1.5,SUM(D13*150)) -> 0 | K13: =IF(OR(WEEKDAY(A13)=1,WEEKDAY(A13)=7,NOT(ISERROR(MATCH(A13,[1]Праздники!A:A,0)))),SUM(E13*225)*1.5,SUM(E13*225)) -> 0 | L13: =IF(OR(WEEKDAY(A13)=1,WEEKDAY(A13)=7,NOT(ISERROR(MATCH(A13,[1]Праздники!A:A,0)))),SUM(F13*225)*1.5,SUM(F13*225)) -> 0 | M13: =SUM(G13*15) -> 20717.85 | N13: =SUM(H13)*750 -> 0 | O13: =SUM(I13:N13) -> 20717.85 | P13: =IF(OR(WEEKDAY(A13)=1,WEEKDAY(A13)=7,NOT(ISERROR(MATCH(A13,[1]Праздники!A:A,0)))),"Выходной","Рабочий") -> Выходной
A14: 45970 | C14: 0 | D14: 0 | G14: =IF(A14 ="",0,G13+C14+E14-D13-F13) -> 1381.19 | I14: =IF(P14="Выходной",SUM(C14*150)*1.5,SUM(C14*150)) -> 0 | J14: =IF(P14="Выходной",SUM(D14*150)*1.5,SUM(D14*150)) -> 0 | K14: =IF(OR(WEEKDAY(A14)=1,WEEKDAY(A14)=7,NOT(ISERROR(MATCH(A14,[1]Праздники!A:A,0)))),SUM(E14*225)*1.5,SUM(E14*225)) -> 0 | L14: =IF(OR(WEEKDAY(A14)=1,WEEKDAY(A14)=7,NOT(ISERROR(MATCH(A14,[1]Праздники!A:A,0)))),SUM(F14*225)*1.5,SUM(F14*225)) -> 0 | M14: =SUM(G14*15) -> 20717.85 | N14: =SUM(H14)*750 -> 0 | O14: =SUM(I14:N14) -> 20717.85 | P14: =IF(OR(WEEKDAY(A14)=1,WEEKDAY(A14)=7,NOT(ISERROR(MATCH(A14,[1]Праздники!A:A,0)))),"Выходной","Рабочий") -> Выходной
A15: 45971 | C15: 0 | D15: 12.375 | G15: =IF(A15 ="",0,G14+C15+E15-D14-F14) -> 1381.19 | I15: =IF(P15="Выходной",SUM(C15*150)*1.5,SUM(C15*150)) -> 0 | J15: =IF(P15="Выходной",SUM(D15*150)*1.5,SUM(D15*150)) -> 1856.25 | K15: =IF(OR(WEEKDAY(A15)=1,WEEKDAY(A15)=7,NOT(ISERROR(MATCH(A15,[1]Праздники!A:A,0)))),SUM(E15*225)*1.5,SUM(E15*225)) -> 0 | L15: =IF(OR(WEEKDAY(A15)=1,WEEKDAY(A15)=7,NOT(ISERROR(MATCH(A15,[1]Праздники!A:A,0)))),SUM(F15*225)*1.5,SUM(F15*225)) -> 0 | M15: =SUM(G15*15) -> 20717.85 | N15: =SUM(H15)*750 -> 0 | O15: =SUM(I15:N15) -> 22574.1 | P15: =IF(OR(WEEKDAY(A15)=1,WEEKDAY(A15)=7,NOT(ISERROR(MATCH(A15,[1]Праздники!A:A,0)))),"Выходной","Рабочий") -> Рабочий
A16: 45972 | C16: 0 | D16: 34.875 | G16: =IF(A16 ="",0,G15+C16+E16-D15-F15) -> 1368.815 | I16: =IF(P16="Выходной",SUM(C16*150)*1.5,SUM(C16*150)) -> 0 | J16: =IF(P16="Выходной",SUM(D16*150)*1.5,SUM(D16*150)) -> 5231.25 | K16: =IF(OR(WEEKDAY(A16)=1,WEEKDAY(A16)=7,NOT(ISERROR(MATCH(A16,[1]Праздники!A:A,0)))),SUM(E16*225)*1.5,SUM(E16*225)) -> 0 | L16: =IF(OR(WEEKDAY(A16)=1,WEEKDAY(A16)=7,NOT(ISERROR(MATCH(A16,[1]Праздники!A:A,0)))),SUM(F16*225)*1.5,SUM(F16*225)) -> 0 | M16: =SUM(G16*15) -> 20532.225 | N16: =SUM(H16)*750 -> 0 | O16: =SUM(I16:N16) -> 25763.475 | P16: =IF(OR(WEEKDAY(A16)=1,WEEKDAY(A16)=7,NOT(ISERROR(MATCH(A16,[1]Праздники!A:A,0)))),"Выходной","Рабочий") -> Рабочий
A17: 45973 | C17: 0 | D17: 0 | G17: =IF(A17 ="",0,G16+C17+E17-D16-F16) -> 1333.94 | I17: =IF(P17="Выходной",SUM(C17*150)*1.5,SUM(C17*150)) -> 0 | J17: =IF(P17="Выходной",SUM(D17*150)*1.5,SUM(D17*150)) -> 0 | K17: =IF(OR(WEEKDAY(A17)=1,WEEKDAY(A17)=7,NOT(ISERROR(MATCH(A17,[1]Праздники!A:A,0)))),SUM(E17*225)*1.5,SUM(E17*225)) -> 0 | L17: =IF(OR(WEEKDAY(A17)=1,WEEKDAY(A17)=7,NOT(ISERROR(MATCH(A17,[1]Праздники!A:A,0)))),SUM(F17*225)*1.5,SUM(F17*225)) -> 0 | M17: =SUM(G17*15) -> 20009.1 | N17: =SUM(H17)*750 -> 0 | O17: =SUM(I17:N17) -> 20009.1 | P17: =IF(OR(WEEKDAY(A17)=1,WEEKDAY(A17)=7,NOT(ISERROR(MATCH(A17,[1]Праздники!A:A,0)))),"Выходной","Рабочий") -> Рабочий
A18: 45974 | C18: 0 | D18: 37.125 | G18: =IF(A18 ="",0,G17+C18+E18-D17-F17) -> 1333.94 | I18: =IF(P18="Выходной",SUM(C18*150)*1.5,SUM(C18*150)) -> 0 | J18: =IF(P18="Выходной",SUM(D18*150)*1.5,SUM(D18*150)) -> 5568.75 | K18: =IF(OR(WEEKDAY(A18)=1,WEEKDAY(A18)=7,NOT(ISERROR(MATCH(A18,[1]Праздники!A:A,0)))),SUM(E18*225)*1.5,SUM(E18*225)) -> 0 | L18: =IF(OR(WEEKDAY(A18)=1,WEEKDAY(A18)=7,NOT(ISERROR(MATCH(A18,[1]Праздники!A:A,0)))),SUM(F18*225)*1.5,SUM(F18*225)) -> 0 | M18: =SUM(G18*15) -> 20009.1 | N18: =SUM(H18)*750 -> 0 | O18: =SUM(I18:N18) -> 25577.85 | P18: =IF(OR(WEEKDAY(A18)=1,WEEKDAY(A18)=7,NOT(ISERROR(MATCH(A18,[1]Праздники!A:A,0)))),"Выходной","Рабочий") -> Рабочий
... A24: 45980 | C24: 0 | D24: 0 | G24: =IF(A24 ="",0,G23+C24+E24-D23-F23) -> 1296.815 | I24: =IF(P24="Выходной",SUM(C24*150)*1.5,SUM(C24*150)) -> 0 | J24: =IF(P24="Выходной",SUM(D24*150)*1.5,SUM(D24*150)) -> 0 | K24: =IF(OR(WEEKDAY(A24)=1,WEEKDAY(A24)=7,NOT(ISERROR(MATCH(A24,[1]Праздники!A:A,0)))),SUM(E24*225)*1.5,SUM(E24*225)) -> 0 | L24: =IF(OR(WEEKDAY(A24)=1,WEEKDAY(A24)=7,NOT(ISERROR(MATCH(A24,[1]Праздники!A:A,0)))),SUM(F24*225)*1.5,SUM(F24*225)) -> 0 | M24: =SUM(G24*15) -> 19452.225 | N24: =SUM(H24)*750 -> 0 | O24: =SUM(I24:N24) -> 19452.225 | P24: =IF(OR(WEEKDAY(A24)=1,WEEKDAY(A24)=7,NOT(ISERROR(MATCH(A24,[1]Праздники!A:A,0)))),"Выходной","Рабочий") -> Рабочий
A25: 45981 | C25: 0 | D25: 17.17 | G25: =IF(A25 ="",0,G24+C25+E25-D24-F24) -> 1296.815 | I25: =IF(P25="Выходной",SUM(C25*150)*1.5,SUM(C25*150)) -> 0 | J25: =IF(P25="Выходной",SUM(D25*150)*1.5,SUM(D25*150))-7.17*150 -> 1500 | K25: =IF(OR(WEEKDAY(A25)=1,WEEKDAY(A25)=7,NOT(ISERROR(MATCH(A25,[1]Праздники!A:A,0)))),SUM(E25*225)*1.5,SUM(E25*225)) -> 0 | L25: =IF(OR(WEEKDAY(A25)=1,WEEKDAY(A25)=7,NOT(ISERROR(MATCH(A25,[1]Праздники!A:A,0)))),SUM(F25*225)*1.5,SUM(F25*225)) -> 0 | M25: =SUM(G25*15) -> 19452.225 | N25: =SUM(H25)*750 -> 0 | O25: =SUM(I25:N25) -> 20952.225 | P25: =IF(OR(WEEKDAY(A25)=1,WEEKDAY(A25)=7,NOT(ISERROR(MATCH(A25,[1]Праздники!A:A,0)))),"Выходной","Рабочий") -> Рабочий
A26: 45982 | C26: 0 | D26: 22 | G26: =IF(A26 ="",0,G25+C26+E26-D25-F25) -> 1279.645 | I26: =IF(P26="Выходной",SUM(C26*150)*1.5,SUM(C26*150)) -> 0 | J26: =IF(P26="Выходной",SUM(D26*150)*1.5,SUM(D26*150)) -> 3300 | K26: =IF(OR(WEEKDAY(A26)=1,WEEKDAY(A26)=7,NOT(ISERROR(MATCH(A26,[1]Праздники!A:A,0)))),SUM(E26*225)*1.5,SUM(E26*225)) -> 0 | L26: =IF(OR(WEEKDAY(A26)=1,WEEKDAY(A26)=7,NOT(ISERROR(MATCH(A26,[1]Праздники!A:A,0)))),SUM(F26*225)*1.5,SUM(F26*225)) -> 0 | M26: =SUM(G26*15) -> 19194.675 | N26: =SUM(H26)*750 -> 0 | O26: =SUM(I26:N26) -> 22494.675 | P26: =IF(OR(WEEKDAY(A26)=1,WEEKDAY(A26)=7,NOT(ISERROR(MATCH(A26,[1]Праздники!A:A,0)))),"Выходной","Рабочий") -> Рабочий
A27: 45983 | C27: 0 | D27: 0 | G27: =IF(A27 ="",0,G26+C27+E27-D26-F26) -> 1257.645 | I27: =IF(P27="Выходной",SUM(C27*150)*1.5,SUM(C27*150)) -> 0 | J27: =IF(P27="Выходной",SUM(D27*150)*1.5,SUM(D27*150)) -> 0 | K27: =IF(OR(WEEKDAY(A27)=1,WEEKDAY(A27)=7,NOT(ISERROR(MATCH(A27,[1]Праздники!A:A,0)))),SUM(E27*225)*1.5,SUM(E27*225)) -> 0 | L27: =IF(OR(WEEKDAY(A27)=1,WEEKDAY(A27)=7,NOT(ISERROR(MATCH(A27,[1]Праздники!A:A,0)))),SUM(F27*225)*1.5,SUM(F27*225)) -> 0 | M27: =SUM(G27*15) -> 18864.675 | N27: =SUM(H27)*750 -> 0 | O27: =SUM(I27:N27) -> 18864.675 | P27: =IF(OR(WEEKDAY(A27)=1,WEEKDAY(A27)=7,NOT(ISERROR(MATCH(A27,[1]Праздники!A:A,0)))),"Выходной","Рабочий") -> Выходной
A28: 45984 | C28: 0 | D28: 0 | G28: =IF(A28 ="",0,G27+C28+E28-D27-F27) -> 1257.645 | I28: =IF(P28="Выходной",SUM(C28*150)*1.5,SUM(C28*150)) -> 0 | J28: =IF(P28="Выходной",SUM(D28*150)*1.5,SUM(D28*150)) -> 0 | K28: =IF(OR(WEEKDAY(A28)=1,WEEKDAY(A28)=7,NOT(ISERROR(MATCH(A28,[1]Праздники!A:A,0)))),SUM(E28*225)*1.5,SUM(E28*225)) -> 0 | L28: =IF(OR(WEEKDAY(A28)=1,WEEKDAY(A28)=7,NOT(ISERROR(MATCH(A28,[1]Праздники!A:A,0)))),SUM(F28*225)*1.5,SUM(F28*225)) -> 0 | M28: =SUM(G28*15) -> 18864.675 | N28: =SUM(H28)*750 -> 0 | O28: =SUM(I28:N28) -> 18864.675 | P28: =IF(OR(WEEKDAY(A28)=1,WEEKDAY(A28)=7,NOT(ISERROR(MATCH(A28,[1]Праздники!A:A,0)))),"Выходной","Рабочий") -> Выходной
A29: 45985 | C29: 0 | D29: 0 | G29: =IF(A29 ="",0,G28+C29+E29-D28-F28)+129 -> 1386.645 | I29: =IF(P29="Выходной",SUM(C29*150)*1.5,SUM(C29*150)) -> 0 | J29: =IF(P29="Выходной",SUM(D29*150)*1.5,SUM(D29*150)) -> 0 | K29: =IF(OR(WEEKDAY(A29)=1,WEEKDAY(A29)=7,NOT(ISERROR(MATCH(A29,[1]Праздники!A:A,0)))),SUM(E29*225)*1.5,SUM(E29*225)) -> 0 | L29: =IF(OR(WEEKDAY(A29)=1,WEEKDAY(A29)=7,NOT(ISERROR(MATCH(A29,[1]Праздники!A:A,0)))),SUM(F29*225)*1.5,SUM(F29*225)) -> 0 | M29: =SUM(G29*15) -> 20799.675 | N29: =SUM(H29)*750 -> 0 | O29: =SUM(I29:N29) -> 20799.675 | P29: =IF(OR(WEEKDAY(A29)=1,WEEKDAY(A29)=7,NOT(ISERROR(MATCH(A29,[1]Праздники!A:A,0)))),"Выходной","Рабочий") -> Рабочий
A30: 45986 | C30: 0 | D30: 0 | G30: =IF(A30 ="",0,G29+C30+E30-D29-F29)+45 -> 1431.645 | I30: =IF(P30="Выходной",SUM(C30*150)*1.5,SUM(C30*150)) -> 0 | J30: =IF(P30="Выходной",SUM(D30*150)*1.5,SUM(D30*150)) -> 0 | K30: =IF(OR(WEEKDAY(A30)=1,WEEKDAY(A30)=7,NOT(ISERROR(MATCH(A30,[1]Праздники!A:A,0)))),SUM(E30*225)*1.5,SUM(E30*225)) -> 0 | L30: =IF(OR(WEEKDAY(A30)=1,WEEKDAY(A30)=7,NOT(ISERROR(MATCH(A30,[1]Праздники!A:A,0)))),SUM(F30*225)*1.5,SUM(F30*225)) -> 0 | M30: =SUM(G30*15) -> 21474.675 | N30: =SUM(H30)*750 -> 0 | O30: =SUM(I30:N30) -> 21474.675 | P30: =IF(OR(WEEKDAY(A30)=1,WEEKDAY(A30)=7,NOT(ISERROR(MATCH(A30,[1]Праздники!A:A,0)))),"Выходной","Рабочий") -> Рабочий
A31: 45987 | C31: 0 | D31: 11 | G31: =IF(A31 ="",0,G30+C31+E31-D30-F30) -> 1431.645 | I31: =IF(P31="Выходной",SUM(C31*150)*1.5,SUM(C31*150)) -> 0 | J31: =IF(P31="Выходной",SUM(D31*150)*1.5,SUM(D31*150)) -> 1650 | K31: =IF(OR(WEEKDAY(A31)=1,WEEKDAY(A31)=7,NOT(ISERROR(MATCH(A31,[1]Праздники!A:A,0)))),SUM(E31*225)*1.5,SUM(E31*225)) -> 0 | L31: =IF(OR(WEEKDAY(A31)=1,WEEKDAY(A31)=7,NOT(ISERROR(MATCH(A31,[1]Праздники!A:A,0)))),SUM(F31*225)*1.5,SUM(F31*225)) -> 0 | M31: =SUM(G31*15) -> 21474.675 | N31: =SUM(H31)*750 -> 0 | O31: =SUM(I31:N31) -> 23124.675 | P31: =IF(OR(WEEKDAY(A31)=1,WEEKDAY(A31)=7,NOT(ISERROR(MATCH(A31,[1]Праздники!A:A,0)))),"Выходной","Рабочий") -> Рабочий
A32: 45988 | C32: 0 | D32: 0 | G32: =IF(A32 ="",0,G31+C32+E32-D31-F31) -> 1420.645 | I32: =IF(P32="Выходной",SUM(C32*150)*1.5,SUM(C32*150)) -> 0 | J32: =IF(P32="Выходной",SUM(D32*150)*1.5,SUM(D32*150)) -> 0 | K32: =IF(OR(WEEKDAY(A32)=1,WEEKDAY(A32)=7,NOT(ISERROR(MATCH(A32,[1]Праздники!A:A,0)))),SUM(E32*225)*1.5,SUM(E32*225)) -> 0 | L32: =IF(OR(WEEKDAY(A32)=1,WEEKDAY(A32)=7,NOT(ISERROR(MATCH(A32,[1]Праздники!A:A,0)))),SUM(F32*225)*1.5,SUM(F32*225)) -> 0 | M32: =SUM(G32*15) -> 21309.675 | N32: =SUM(H32)*750 -> 0 | O32: =SUM(I32:N32) -> 21309.675 | P32: =IF(OR(WEEKDAY(A32)=1,WEEKDAY(A32)=7,NOT(ISERROR(MATCH(A32,[1]Праздники!A:A,0)))),"Выходной","Рабочий") -> Рабочий
A33: 45989 | C33: 0 | D33: 25 | G33: =IF(A33 ="",0,G32+C33+E33-D32-F32) -> 1420.645 | I33: =IF(P33="Выходной",SUM(C33*150)*1.5,SUM(C33*150)) -> 0 | J33: =IF(P33="Выходной",SUM(D33*150)*1.5,SUM(D33*150)) -> 3750 | K33: =IF(OR(WEEKDAY(A33)=1,WEEKDAY(A33)=7,NOT(ISERROR(MATCH(A33,[1]Праздники!A:A,0)))),SUM(E33*225)*1.5,SUM(E33*225)) -> 0 | L33: =IF(OR(WEEKDAY(A33)=1,WEEKDAY(A33)=7,NOT(ISERROR(MATCH(A33,[1]Праздники!A:A,0)))),SUM(F33*225)*1.5,SUM(F33*225)) -> 0 | M33: =SUM(G33*15) -> 21309.675 | N33: =SUM(H33)*750 -> 0 | O33: =SUM(I33:N33) -> 25059.675 | P33: =IF(OR(WEEKDAY(A33)=1,WEEKDAY(A33)=7,NOT(ISERROR(MATCH(A33,[1]Праздники!A:A,0)))),"Выходной","Рабочий") -> Рабочий
A34: 45990 | C34: 0 | D34: 0 | G34: =IF(A34 ="",0,G33+C34+E34-D33-F33) -> 1395.645 | I34: =IF(P34="Выходной",SUM(C34*150)*1.5,SUM(C34*150)) -> 0 | J34: =IF(P34="Выходной",SUM(D34*150)*1.5,SUM(D34*150)) -> 0 | K34: =IF(OR(WEEKDAY(A34)=1,WEEKDAY(A34)=7,NOT(ISERROR(MATCH(A34,[1]Праздники!A:A,0)))),SUM(E34*225)*1.5,SUM(E34*225)) -> 0 | L34: =IF(OR(WEEKDAY(A34)=1,WEEKDAY(A34)=7,NOT(ISERROR(MATCH(A34,[1]Праздники!A:A,0)))),SUM(F34*225)*1.5,SUM(F34*225)) -> 0 | M34: =SUM(G34*15) -> 20934.675 | N34: =SUM(H34)*750 -> 0 | O34: =SUM(I34:N34) -> 20934.675 | P34: =IF(OR(WEEKDAY(A34)=1,WEEKDAY(A34)=7,NOT(ISERROR(MATCH(A34,[1]Праздники!A:A,0)))),"Выходной","Рабочий") -> Выходной
A35: 45991 | C35: 0 | D35: 1.35 | G35: =IF(A35 ="",0,G34+C35+E35-D34-F34) -> 1395.645 | I35: =IF(P35="Выходной",SUM(C35*150)*1.5,SUM(C35*150)) -> 0 | J35: =IF(P35="Выходной",SUM(D35*150)*1.5,SUM(D35*150)) -> 303.75 | K35: =IF(OR(WEEKDAY(A35)=1,WEEKDAY(A35)=7,NOT(ISERROR(MATCH(A35,[1]Праздники!A:A,0)))),SUM(E35*225)*1.5,SUM(E35*225)) -> 0 | L35: =IF(OR(WEEKDAY(A35)=1,WEEKDAY(A35)=7,NOT(ISERROR(MATCH(A35,[1]Праздники!A:A,0)))),SUM(F35*225)*1.5,SUM(F35*225)) -> 0 | M35: =SUM(G35*15) -> 20934.675 | N35: =SUM(H35)*750 -> 0 | O35: =SUM(I35:N35) -> 21238.425 | P35: =IF(OR(WEEKDAY(A35)=1,WEEKDAY(A35)=7,NOT(ISERROR(MATCH(A35,[1]Праздники!A:A,0)))),"Выходной","Рабочий") -> Выходной
C36: 0 | D36: 0 | G36: =IF(A36 ="",0,G35+C36+E36-D35-F35) -> 0 | I36: =IF(P36="Выходной",SUM(C36*150)*1.5,SUM(C36*150)) -> 0 | J36: =IF(P36="Выходной",SUM(D36*150)*1.5,SUM(D36*150)) -> 0 | K36: =IF(OR(WEEKDAY(A36)=1,WEEKDAY(A36)=7,NOT(ISERROR(MATCH(A36,[1]Праздники!A:A,0)))),SUM(E36*225)*1.5,SUM(E36*225)) -> 0 | L36: =IF(OR(WEEKDAY(A36)=1,WEEKDAY(A36)=7,NOT(ISERROR(MATCH(A36,[1]Праздники!A:A,0)))),SUM(F36*225)*1.5,SUM(F36*225)) -> 0 | M36: =SUM(G36*15) -> 0 | N36: =SUM(H36)*750 -> 0 | O36: =SUM(I36:N36) -> 0 | P36: =IF(OR(WEEKDAY(A36)=1,WEEKDAY(A36)=7,NOT(ISERROR(MATCH(A36,[1]Праздники!A:A,0)))),"Выходной","Рабочий") -> Выходной
C37: =SUM(C6:C36) -> 0 | D37: =SUM(D6:D36) -> 228.32 | E37: =SUM(E6:E36) -> 0 | F37: =SUM(F6:F36) -> 0 | G37: =SUM(G6:G36) -> 40741.475 | H37: =SUM(H6:H36) -> 0 | I37: =SUM(I6:I36) -> 0 | J37: =SUM(J6:J36) -> 34623.75 | ... O37: =SUM(O6:O36) -> 645745.88
N38: С НДС; | O38: =O37*1.2 -> 774895.05

Sheet РВ ГАЗ
R1: Выходной | S1: Рабочий
Q2: Выгрузка | R2: =SUMIF($P$6:$P$36,R$1,$C6:$C36) -> 0 | S2: =SUMIF($P$6:$P$36,S$1,$C6:$C36) -> 0
A3: ="Отчет по хранению товара РВ " & TEXT(A6,"ММММ ") & YEAR(A6) & " Ленина 88" -> Отчет по хранению товара РВ Ноябрь 2025 Ленина 88 | Q3: Отгрузка | R3: =SUMIF($P$6:$P$36,R$1,$D6:$D36) -> 42.75 | S3: =SUMIF($P$6:$P$36,S$1,$D6:$D36) -> 160.855
A4: дата | C4: Выгрузка кол-во тонн | D4: Загрузка кол-во тонн | E4: Выгрузка после 20:00 | F4: Загрузка после 20:00 | G4: Хранение | H4: переконсолидация (тонн) | I4: стоимость выгрузки | J4: стоимость загрузки | K4: Стоимость выгрузки после 20:00 | L4: Стоимость загрузки после 20:00 | M4: стоимость хранения | N4: стоимость переконс. | O4: итого
G5: (кол-во тонн)
A6: 45962 | C6: 0 | D6: 44 | G6: 377.605 | I6: =IF(P6="Выходной",SUM(C6*150)*1.5,SUM(C6*150)) -> 0 | J6: =IF(P6="Выходной",SUM(D6*150)*1.5,SUM(D6*150)) -> 6600 | K6: =IF(OR(WEEKDAY(A6)=1,WEEKDAY(A6)=7,NOT(ISERROR(MATCH(A6,[1]Праздники!A:A,0)))),SUM(E6*225)*1.5,SUM(E6*225)) -> 0 | L6: =IF(OR(WEEKDAY(A6)=1,WEEKDAY(A6)=7,NOT(ISERROR(MATCH(A6,[1]Праздники!A:A,0)))),SUM(F6*225)*1.5,SUM(F6*225)) -> 0 | M6: =SUM(G6*15) -> 5664.075 | N6: =SUM(H6)*750 -> 0 | O6: =SUM(I6:N6) -> 12264.075 | P6: Рабочий
A7: 45963 | C7: 0 | D7: 0 | G7: =IF(A7 ="",0,G6+C7+E7-D6-F6) -> 333.605 | I7: =IF(P7="Выходной",SUM(C7*150)*1.5,SUM(C7*150)) -> 0 | J7: =IF(P7="Выходной",SUM(D7*150)*1.5,SUM(D7*150)) -> 0 | K7: =IF(OR(WEEKDAY(A7)=1,WEEKDAY(A7)=7,NOT(ISERROR(MATCH(A7,[1]Праздники!A:A,0)))),SUM(E7*225)*1.5,SUM(E7*225)) -> 0 | L7: =IF(OR(WEEKDAY(A7)=1,WEEKDAY(A7)=7,NOT(ISERROR(MATCH(A7,[1]Праздники!A:A,0)))),SUM(F7*225)*1.5,SUM(F7*225)) -> 0 | M7: =SUM(G7*15) -> 5004.075 | N7: =SUM(H7)*750 -> 0 | O7: =SUM(I7:N7) -> 5004.075 | P7: =IF(OR(WEEKDAY(A7)=1,WEEKDAY(A7)=7,NOT(ISERROR(MATCH(A7,[1]Праздники!A:A,0)))),"Выходной","Рабочий") -> Выходной
A8: 45964 | C8: 0 | D8: 0 | G8: =IF(A8 ="",0,G7+C8+E8-D7-F7) -> 333.605 | I8: =IF(P8="Выходной",SUM(C8*150)*1.5,SUM(C8*150)) -> 0 | J8: =IF(P8="Выходной",SUM(D8*150)*1.5,SUM(D8*150)) -> 0 | K8: =IF(OR(WEEKDAY(A8)=1,WEEKDAY(A8)=7,NOT(ISERROR(MATCH(A8,[1]Праздники!A:A,0)))),SUM(E8*225)*1.5,SUM(E8*225)) -> 0 | L8: =IF(OR(WEEKDAY(A8)=1,WEEKDAY(A8)=7,NOT(ISERROR(MATCH(A8,[1]Праздники!A:A,0)))),SUM(F8*225)*1.5,SUM(F8*225)) -> 0 | M8: =SUM(G8*15) -> 5004.075 | N8: =SUM(H8)*750 -> 0 | O8: =SUM(I8:N8) -> 5004.075 | P8: =IF(OR(WEEKDAY(A8)=1,WEEKDAY(A8)=7,NOT(ISERROR(MATCH(A8,[1]Праздники!A:A,0)))),"Выходной","Рабочий") -> Выходной
A9: 45965 | C9: 0 | D9: 0 | G9: =IF(A9 ="",0,G8+C9+E9-D8-F8) -> 333.605 | I9: =IF(P9="Выходной",SUM(C9*150)*1.5,SUM(C9*150)) -> 0 | J9: =IF(P9="Выходной",SUM(D9*150)*1.5,SUM(D9*150)) -> 0 | K9: =IF(OR(WEEKDAY(A9)=1,WEEKDAY(A9)=7,NOT(ISERROR(MATCH(A9,[1]Праздники!A:A,0)))),SUM(E9*225)*1.5,SUM(E9*225)) -> 0 | L9: =IF(OR(WEEKDAY(A9)=1,WEEKDAY(A9)=7,NOT(ISERROR(MATCH(A9,[1]Праздники!A:A,0)))),SUM(F9*225)*1.5,SUM(F9*225)) -> 0 | M9: =SUM(G9*15) -> 5004.075 | N9: =SUM(H9)*750 -> 0 | O9: =SUM(I9:N9) -> 5004.075 | P9: =IF(OR(WEEKDAY(A9)=1,WEEKDAY(A9)=7,NOT(ISERROR(MATCH(A9,[1]Праздники!A:A,0)))),"Выходной","Рабочий") -> Выходной
A10: 45966 | C10: 0 | D10: 0 | G10: =IF(A10 ="",0,G9+C10+E10-D9-F9) -> 333.605 | I10: =IF(P10="Выходной",SUM(C10*150)*1.5,SUM(C10*150)) -> 0 | J10: =IF(P10="Выходной",SUM(D10*150)*1.5,SUM(D10*150)) -> 0 | K10: =IF(OR(WEEKDAY(A10)=1,WEEKDAY(A10)=7,NOT(ISERROR(MATCH(A10,[1]Праздники!A:A,0)))),SUM(E10*225)*1.5,SUM(E10*225)) -> 0 | L10: =IF(OR(WEEKDAY(A10)=1,WEEKDAY(A10)=7,NOT(ISERROR(MATCH(A10,[1]Праздники!A:A,0)))),SUM(F10*225)*1.5,SUM(F10*225)) -> 0 | M10: =SUM(G10*15) -> 5004.075 | N10: =SUM(H10)*750 -> 0 | O10: =SUM(I10:N10) -> 5004.075 | P10: =IF(OR(WEEKDAY(A10)=1,WEEKDAY(A10)=7,NOT(ISERROR(MATCH(A10,[1]Праздники!A:A,0)))),"Выходной","Рабочий") -> Рабочий
A11: 45967 | C11: 0 | D11: 0 | G11: =IF(A11 ="",0,G10+C11+E11-D10-F10) -> 333.605 | I11: =IF(P11="Выходной",SUM(C11*150)*1.5,SUM(C11*150)) -> 0 | J11: =IF(P11="Выходной",SUM(D11*150)*1.5,SUM(D11*150)) -> 0 | K11: =IF(OR(WEEKDAY(A11)=1,WEEKDAY(A11)=7,NOT(ISERROR(MATCH(A11,[1]Праздники!A:A,0)))),SUM(E11*225)*1.5,SUM(E11*225)) -> 0 | L11: =IF(OR(WEEKDAY(A11)=1,WEEKDAY(A11)=7,NOT(ISERROR(MATCH(A11,[1]Праздники!A:A,0)))),SUM(F11*225)*1.5,SUM(F11*225)) -> 0 | M11: =SUM(G11*15) -> 5004.075 | N11: =SUM(H11)*750 -> 0 | O11: =SUM(I11:N11) -> 5004.075 | P11: =IF(OR(WEEKDAY(A11)=1,WEEKDAY(A11)=7,NOT(ISERROR(MATCH(A11,[1]Праздники!A:A,0)))),"Выходной","Рабочий") -> Рабочий
A12: 45968 | C12: 0 | D12: 0 | G12: =IF(A12 ="",0,G11+C12+E12-D11-F11) -> 333.605 | I12: =IF(P12="Выходной",SUM(C12*150)*1.5,SUM(C12*150)) -> 0 | J12: =IF(P12="Выходной",SUM(D12*150)*1.5,SUM(D12*150)) -> 0 | K12: =IF(OR(WEEKDAY(A12)=1,WEEKDAY(A12)=7,NOT(ISERROR(MATCH(A12,[1]Праздники!A:A,0)))),SUM(E12*225)*1.5,SUM(E12*225)) -> 0 | L12: =IF(OR(WEEKDAY(A12)=1,WEEKDAY(A12)=7,NOT(ISERROR(MATCH(A12,[1]Праздники!A:A,0)))),SUM(F12*225)*1.5,SUM(F12*225)) -> 0 | M12: =SUM(G12*15) -> 5004.075 | N12: =SUM(H12)*750 -> 0 | O12: =SUM(I12:N12) -> 5004.075 | P12: =IF(OR(WEEKDAY(A12)=1,WEEKDAY(A12)=7,NOT(ISERROR(MATCH(A12,[1]Праздники!A:A,0)))),"Выходной","Рабочий") -> Рабочий
A13: 45969 | C13: 0 | D13: 0 | G13: =IF(A13 ="",0,G12+C13+E13-D12-F12) -> 333.605 | I13: =IF(P13="Выходной",SUM(C13*150)*1.5,SUM(C13*150)) -> 0 | J13: =IF(P13="Выходной",SUM(D13*150)*1.5,SUM(D13*150)) -> 0 | K13: =IF(OR(WEEKDAY(A13)=1,WEEKDAY(A13)=7,NOT(ISERROR(MATCH(A13,[1]Праздники!A:A,0)))),SUM(E13*225)*1.5,SUM(E13*225)) -> 0 | L13: =IF(OR(WEEKDAY(A13)=1,WEEKDAY(A13)=7,NOT(ISERROR(MATCH(A13,[1]Праздники!A:A,0)))),SUM(F13*225)*1.5,SUM(F13*225)) -> 0 | M13: =SUM(G13*15) -> 5004.075 | N13: =SUM(H13)*750 -> 0 | O13: =SUM(I13:N13) -> 5004.075 | P13: =IF(OR(WEEKDAY(A13)=1,WEEKDAY(A13)=7,NOT(ISERROR(MATCH(A13,[1]Праздники!A:A,0)))),"Выходной","Рабочий") -> Выходной
A14: 45970 | C14: 0 | D14: 42.75 | G14: =IF(A14 ="",0,G13+C14+E14-D13-F13) -> 333.605 | I14: =IF(P14="Выходной",SUM(C14*150)*1.5,SUM(C14*150)) -> 0 | J14: =IF(P14="Выходной",SUM(D14*150)*1.5,SUM(D14*150)) -> 9618.75 | K14: =IF(OR(WEEKDAY(A14)=1,WEEKDAY(A14)=7,NOT(ISERROR(MATCH(A14,[1]Праздники!A:A,0)))),SUM(E14*225)*1.5,SUM(E14*225)) -> 0 | L14: =IF(OR(WEEKDAY(A14)=1,WEEKDAY(A14)=7,NOT(ISERROR(MATCH(A14,[1]Праздники!A:A,0)))),SUM(F14*225)*1.5,SUM(F14*225)) -> 0 | M14: =SUM(G14*15) -> 5004.075 | N14: =SUM(H14)*750 -> 0 | O14: =SUM(I14:N14) -> 14622.825 | P14: =IF(OR(WEEKDAY(A14)=1,WEEKDAY(A14)=7,NOT(ISERROR(MATCH(A14,[1]Праздники!A:A,0)))),"Выходной","Рабочий") -> Выходной
A15: 45971 | C15: 0 | D15: 64.75 | G15: =IF(A15 ="",0,G14+C15+E15-D14-F14) -> 290.855 | I15: =IF(P15="Выходной",SUM(C15*150)*1.5,SUM(C15*150)) -> 0 | J15: =IF(P15="Выходной",SUM(D15*150)*1.5,SUM(D15*150)) -> 9712.5 | K15: =IF(OR(WEEKDAY(A15)=1,WEEKDAY(A15)=7,NOT(ISERROR(MATCH(A15,[1]Праздники!A:A,0)))),SUM(E15*225)*1.5,SUM(E15*225)) -> 0 | L15: =IF(OR(WEEKDAY(A15)=1,WEEKDAY(A15)=7,NOT(ISERROR(MATCH(A15,[1]Праздники!A:A,0)))),SUM(F15*225)*1.5,SUM(F15*225)) -> 0 | M15: =SUM(G15*15) -> 4362.825 | N15: =SUM(H15)*750 -> 0 | O15: =SUM(I15:N15) -> 14075.325 | P15: =IF(OR(WEEKDAY(A15)=1,WEEKDAY(A15)=7,NOT(ISERROR(MATCH(A15,[1]Праздники!A:A,0)))),"Выходной","Рабочий") -> Рабочий
A16: 45972 | C16: 0 | D16: 7.875 | G16: =IF(A16 ="",0,G15+C16+E16-D15-F15) -> 226.105 | I16: =IF(P16="Выходной",SUM(C16*150)*1.5,SUM(C16*150)) -> 0 | J16: =IF(P16="Выходной",SUM(D16*150)*1.5,SUM(D16*150)) -> 1181.25 | K16: =IF(OR(WEEKDAY(A16)=1,WEEKDAY(A16)=7,NOT(ISERROR(MATCH(A16,[1]Праздники!A:A,0)))),SUM(E16*225)*1.5,SUM(E16*225)) -> 0 | L16: =IF(OR(WEEKDAY(A16)=1,WEEKDAY(A16)=7,NOT(ISERROR(MATCH(A16,[1]Праздники!A:A,0)))),SUM(F16*225)*1.5,SUM(F16*225)) -> 0 | M16: =SUM(G16*15) -> 3391.575 | N16: =SUM(H16)*750 -> 0 | O16: =SUM(I16:N16) -> 4572.825 | P16: =IF(OR(WEEKDAY(A16)=1,WEEKDAY(A16)=7,NOT(ISERROR(MATCH(A16,[1]Праздники!A:A,0)))),"Выходной","Рабочий") -> Рабочий
A17: 45973 | C17: 0 | D17: 0 | G17: =IF(A17 ="",0,G16+C17+E17-D16-F16) -> 218.23 | I17: =IF(P17="Выходной",SUM(C17*150)*1.5,SUM(C17*150)) -> 0 | J17: =IF(P17="Выходной",SUM(D17*150)*1.5,SUM(D17*150)) -> 0 | K17: =IF(OR(WEEKDAY(A17)=1,WEEKDAY(A17)=7,NOT(ISERROR(MATCH(A17,[1]Праздники!A:A,0)))),SUM(E17*225)*1.5,SUM(E17*225)) -> 0 | L17: =IF(OR(WEEKDAY(A17)=1,WEEKDAY(A17)=7,NOT(ISERROR(MATCH(A17,[1]Праздники!A:A,0)))),SUM(F17*225)*1.5,SUM(F17*225)) -> 0 | M17: =SUM(G17*15) -> 3273.45 | N17: =SUM(H17)*750 -> 0 | O17: =SUM(I17:N17) -> 3273.45 | P17: =IF(OR(WEEKDAY(A17)=1,WEEKDAY(A17)=7,NOT(ISERROR(MATCH(A17,[1]Праздники!A:A,0)))),"Выходной","Рабочий") -> Рабочий
A18: 45974 | C18: 0 | D18: 0 | G18: =IF(A18 ="",0,G17+C18+E18-D17-F17) -> 218.23 | I18: =IF(P18="Выходной",SUM(C18*150)*1.5,SUM(C18*150)) -> 0 | J18: =IF(P18="Выходной",SUM(D18*150)*1.5,SUM(D18*150)) -> 0 | K18: =IF(OR(WEEKDAY(A18)=1,WEEKDAY(A18)=7,NOT(ISERROR(MATCH(A18,[1]Праздники!A:A,0)))),SUM(E18*225)*1.5,SUM(E18*225)) -> 0 | L18: =IF(OR(WEEKDAY(A18)=1,WEEKDAY(A18)=7,NOT(ISERROR(MATCH(A18,[1]Праздники!A:A,0)))),SUM(F18*225)*1.5,SUM(F18*225)) -> 0 | M18: =SUM(G18*15) -> 3273.45 | N18: =SUM(H18)*750 -> 0 | O18: =SUM(I18:N18) -> 3273.45 | P18: =IF(OR(WEEKDAY(A18)=1,WEEKDAY(A18)=7,NOT(ISERROR(MATCH(A18,[1]Праздники!A:A,0)))),"Выходной","Рабочий") -> Рабочий
... A28: 45984 | C28: 0 | D28: 0 | G28: =IF(A28 ="",0,G27+C28+E28-D27-F27) -> 174 | I28: =IF(P28="Выходной",SUM(C28*150)*1.5,SUM(C28*150)) -> 0 | J28: =IF(P28="Выходной",SUM(D28*150)*1.5,SUM(D28*150)) -> 0 | K28: =IF(OR(WEEKDAY(A28)=1,WEEKDAY(A28)=7,NOT(ISERROR(MATCH(A28,[1]Праздники!A:A,0)))),SUM(E28*225)*1.5,SUM(E28*225)) -> 0 | L28: =IF(OR(WEEKDAY(A28)=1,WEEKDAY(A28)=7,NOT(ISERROR(MATCH(A28,[1]Праздники!A:A,0)))),SUM(F28*225)*1.5,SUM(F28*225)) -> 0 | M28: =SUM(G28*15) -> 2610 | N28: =SUM(H28)*750 -> 0 | O28: =SUM(I28:N28) -> 2610 | P28: =IF(OR(WEEKDAY(A28)=1,WEEKDAY(A28)=7,NOT(ISERROR(MATCH(A28,[1]Праздники!A:A,0)))),"Выходной","Рабочий") -> Выходной
A29: 45985 | C29: 0 | D29: 0 | G29: =IF(A29 ="",0,G28+C29+E29-D28-F28)-129 -> 45 | I29: =IF(P29="Выходной",SUM(C29*150)*1.5,SUM(C29*150)) -> 0 | J29: =IF(P29="Выходной",SUM(D29*150)*1.5,SUM(D29*150)) -> 0 | K29: =IF(OR(WEEKDAY(A29)=1,WEEKDAY(A29)=7,NOT(ISERROR(MATCH(A29,[1]Праздники!A:A,0)))),SUM(E29*225)*1.5,SUM(E29*225)) -> 0 | L29: =IF(OR(WEEKDAY(A29)=1,WEEKDAY(A29)=7,NOT(ISERROR(MATCH(A29,[1]Праздники!A:A,0)))),SUM(F29*225)*1.5,SUM(F29*225)) -> 0 | M29: =SUM(G29*15) -> 675 | N29: =SUM(H29)*750 -> 0 | O29: =SUM(I29:N29) -> 675 | P29: =IF(OR(WEEKDAY(A29)=1,WEEKDAY(A29)=7,NOT(ISERROR(MATCH(A29,[1]Праздники!A:A,0)))),"Выходной","Рабочий") -> Рабочий
A30: 45986 | C30: 0 | D30: 0 | G30: =IF(A30 ="",0,G29+C30+E30-D29-F29)-45 -> 0 | I30: =IF(P30="Выходной",SUM(C30*150)*1.5,SUM(C30*150)) -> 0 | J30: =IF(P30="Выходной",SUM(D30*150)*1.5,SUM(D30*150)) -> 0 | K30: =IF(OR(WEEKDAY(A30)=1,WEEKDAY(A30)=7,NOT(ISERROR(MATCH(A30,[1]Праздники!A:A,0)))),SUM(E30*225)*1.5,SUM(E30*225)) -> 0 | L30: =IF(OR(WEEKDAY(A30)=1,WEEKDAY(A30)=7,NOT(ISERROR(MATCH(A30,[1]Праздники!A:A,0)))),SUM(F30*225)*1.5,SUM(F30*225)) -> 0 | M30: =SUM(G30*15) -> 0 | N30: =SUM(H30)*750 -> 0 | O30: =SUM(I30:N30) -> 0 | P30: =IF(OR(WEEKDAY(A30)=1,WEEKDAY(A30)=7,NOT(ISERROR(MATCH(A30,[1]Праздники!A:A,0)))),"Выходной","Рабочий") -> Рабочий
A31: 45987 | C31: 0 | D31: 0 | G31: =IF(A31 ="",0,G30+C31+E31-D30-F30) -> 0 | I31: =IF(P31="Выходной",SUM(C31*150)*1.5,SUM(C31*150)) -> 0 | J31: =IF(P31="Выходной",SUM(D31*150)*1.5,SUM(D31*150)) -> 0 | K31: =IF(OR(WEEKDAY(A31)=1,WEEKDAY(A31)=7,NOT(ISERROR(MATCH(A31,[1]Праздники!A:A,0)))),SUM(E31*225)*1.5,SUM(E31*225)) -> 0 | L31: =IF(OR(WEEKDAY(A31)=1,WEEKDAY(A31)=7,NOT(ISERROR(MATCH(A31,[1]Праздники!A:A,0)))),SUM(F31*225)*1.5,SUM(F31*225)) -> 0 | M31: =SUM(G31*15) -> 0 | N31: =SUM(H31)*750 -> 0 | O31: =SUM(I31:N31) -> 0 | P31: =IF(OR(WEEKDAY(A31)=1,WEEKDAY(A31)=7,NOT(ISERROR(MATCH(A31,[1]Праздники!A:A,0)))),"Выходной","Рабочий") -> Рабочий
A32: 45988 | C32: 0 | D32: 0 | G32: =IF(A32 ="",0,G31+C32+E32-D31-F31) -> 0 | I32: =IF(P32="Выходной",SUM(C32*150)*1.5,SUM(C32*150)) -> 0 | J32: =IF(P32="Выходной",SUM(D32*150)*1.5,SUM(D32*150)) -> 0 | K32: =IF(OR(WEEKDAY(A32)=1,WEEKDAY(A32)=7,NOT(ISERROR(MATCH(A32,[1]Праздники!A:A,0)))),SUM(E32*225)*1.5,SUM(E32*225)) -> 0 | L32: =IF(OR(WEEKDAY(A32)=1,WEEKDAY(A32)=7,NOT(ISERROR(MATCH(A32,[1]Праздники!A:A,0)))),SUM(F32*225)*1.5,SUM(F32*225)) -> 0 | M32: =SUM(G32*15) -> 0 | N32: =SUM(H32)*750 -> 0 | O32: =SUM(I32:N32) -> 0 | P32: =IF(OR(WEEKDAY(A32)=1,WEEKDAY(A32)=7,NOT(ISERROR(MATCH(A32,[1]Праздники!A:A,0)))),"Выходной","Рабочий") -> Рабочий
A33: 45989 | C33: 0 | D33: 0 | G33: =IF(A33 ="",0,G32+C33+E33-D32-F32) -> 0 | I33: =IF(P33="Выходной",SUM(C33*150)*1.5,SUM(C33*150)) -> 0 | J33: =IF(P33="Выходной",SUM(D33*150)*1.5,SUM(D33*150)) -> 0 | K33: =IF(OR(WEEKDAY(A33)=1,WEEKDAY(A33)=7,NOT(ISERROR(MATCH(A33,[1]Праздники!A:A,0)))),SUM(E33*225)*1.5,SUM(E33*225)) -> 0 | L33: =IF(OR(WEEKDAY(A33)=1,WEEKDAY(A33)=7,NOT(ISERROR(MATCH(A33,[1]Праздники!A:A,0)))),SUM(F33*225)*1.5,SUM(F33*225)) -> 0 | M33: =SUM(G33*15) -> 0 | N33: =SUM(H33)*750 -> 0 | O33: =SUM(I33:N33) -> 0 | P33: =IF(OR(WEEKDAY(A33)=1,WEEKDAY(A33)=7,NOT(ISERROR(MATCH(A33,[1]Праздники!A:A,0)))),"Выходной","Рабочий") -> Рабочий
A34: 45990 | C34: 0 | D34: 0 | G34: =IF(A34 ="",0,G33+C34+E34-D33-F33) -> 0 | I34: =IF(P34="Выходной",SUM(C34*150)*1.5,SUM(C34*150)) -> 0 | J34: =IF(P34="Выходной",SUM(D34*150)*1.5,SUM(D34*150)) -> 0 | K34: =IF(OR(WEEKDAY(A34)=1,WEEKDAY(A34)=7,NOT(ISERROR(MATCH(A34,[1]Праздники!A:A,0)))),SUM(E34*225)*1.5,SUM(E34*225)) -> 0 | L34: =IF(OR(WEEKDAY(A34)=1,WEEKDAY(A34)=7,NOT(ISERROR(MATCH(A34,[1]Праздники!A:A,0)))),SUM(F34*225)*1.5,SUM(F34*225)) -> 0 | M34: =SUM(G34*15) -> 0 | N34: =SUM(H34)*750 -> 0 | O34: =SUM(I34:N34) -> 0 | P34: =IF(OR(WEEKDAY(A34)=1,WEEKDAY(A34)=7,NOT(ISERROR(MATCH(A34,[1]Праздники!A:A,0)))),"Выходной","Рабочий") -> Выходной
A35: 45991 | C35: 0 | D35: 0 | G35: =IF(A35 ="",0,G34+C35+E35-D34-F34) -> 0 | I35: =IF(P35="Выходной",SUM(C35*150)*1.5,SUM(C35*150)) -> 0 | J35: =IF(P35="Выходной",SUM(D35*150)*1.5,SUM(D35*150)) -> 0 | K35: =IF(OR(WEEKDAY(A35)=1,WEEKDAY(A35)=7,NOT(ISERROR(MATCH(A35,[1]Праздники!A:A,0)))),SUM(E35*225)*1.5,SUM(E35*225)) -> 0 | L35: =IF(OR(WEEKDAY(A35)=1,WEEKDAY(A35)=7,NOT(ISERROR(MATCH(A35,[1]Праздники!A:A,0)))),SUM(F35*225)*1.5,SUM(F35*225)) -> 0 | M35: =SUM(G35*15) -> 0 | N35: =SUM(H35)*750 -> 0 | O35: =SUM(I35:N35) -> 0 | P35: =IF(OR(WEEKDAY(A35)=1,WEEKDAY(A35)=7,NOT(ISERROR(MATCH(A35,[1]Праздники!A:A,0)))),"Выходной","Рабочий") -> Выходной
C36: 0 | D36: 0 | G36: =IF(A36 ="",0,G35+C36+E36-D35-F35) -> 0 | I36: =IF(P36="Выходной",SUM(C36*150)*1.5,SUM(C36*150)) -> 0 | J36: =IF(P36="Выходной",SUM(D36*150)*1.5,SUM(D36*150)) -> 0 | K36: =IF(OR(WEEKDAY(A36)=1,WEEKDAY(A36)=7,NOT(ISERROR(MATCH(A36,[1]Праздники!A:A,0)))),SUM(E36*225)*1.5,SUM(E36*225)) -> 0 | L36: =IF(OR(WEEKDAY(A36)=1,WEEKDAY(A36)=7,NOT(ISERROR(MATCH(A36,[1]Праздники!A:A,0)))),SUM(F36*225)*1.5,SUM(F36*225)) -> 0 | M36: =SUM(G36*15) -> 0 | N36: =SUM(H36)*750 -> 0 | O36: =SUM(I36:N36) -> 0 | P36: =IF(OR(WEEKDAY(A36)=1,WEEKDAY(A36)=7,NOT(ISERROR(MATCH(A36,[1]Праздники!A:A,0)))),"Выходной","Рабочий") -> Выходной
C37: =SUM(C6:C36) -> 0 | D37: =SUM(D6:D36) -> 203.605 | E37: =SUM(E6:E36) -> 0 | F37: =SUM(F6:F36) -> 0 | G37: =SUM(G6:G36) -> 5895.095 | H37: =SUM(H6:H36) -> 0 | I37: =SUM(I6:I36) -> 0 | J37: =SUM(J6:J36) -> 33747 | ... O37: =SUM(O6:O36) -> 122173.42
N38: С НДС; | O38: =O37*1.2 -> 146608.11

Sheet РВ Новикова-Прибоя
R1: Выходной | S1: Рабочий
Q2: Выгрузка | R2: =SUMIF($P$6:$P$36,R$1,$C6:$C36) -> 42 | S2: =SUMIF($P$6:$P$36,S$1,$C6:$C36) -> 21
A3: ="Отчет по хранению товара РВ " & TEXT(A6,"ММММ ") & YEAR(A6) & " Новикова" -> Отчет по хранению товара РВ Ноябрь 2025 Новикова | Q3: Отгрузка | R3: =SUMIF($P$6:$P$36,R$1,$D6:$D36) -> 16.38 | S3: =SUMIF($P$6:$P$36,S$1,$D6:$D36) -> 67.62
A4: дата | C4: Выгрузка кол-во тонн | D4: Загрузка кол-во тонн | E4: Выгрузка после 20:00 | F4: Загрузка после 20:00 | G4: Хранение | H4: переконсолидация (тонн) | I4: стоимость выгрузки | J4: стоимость загрузки | K4: Стоимость выгрузки после 20:00 | L4: Стоимость загрузки после 20:00 | M4: стоимость хранения | N4: стоимость переконс. | O4: итого
G5: (кол-во тонн)
A6: 45962 | C6: 0 | D6: 7.825 | G6: 320.145 | I6: =IF(P6="Выходной",SUM(C6*150)*1.5,SUM(C6*150)) -> 0 | J6: =IF(P6="Выходной",SUM(D6*150)*1.5,SUM(D6*150)) -> 1173.75 | K6: =IF(OR(WEEKDAY(A6)=1,WEEKDAY(A6)=7,NOT(ISERROR(MATCH(A6,[1]Праздники!A:A,0)))),SUM(E6*225)*1.5,SUM(E6*225)) -> 0 | L6: =IF(OR(WEEKDAY(A6)=1,WEEKDAY(A6)=7,NOT(ISERROR(MATCH(A6,[1]Праздники!A:A,0)))),SUM(F6*225)*1.5,SUM(F6*225)) -> 0 | M6: =SUM(G6*15) -> 4802.175 | N6: =SUM(H6)*750 -> 0 | O6: =SUM(I6:N6) -> 5975.925 | P6: Рабочий
A7: 45963 | C7: 0 | D7: 0 | G7: =IF(A7 ="",0,G6+C7+E7-D6-F6) -> 312.32 | I7: =IF(P7="Выходной",SUM(C7*150)*1.5,SUM(C7*150)) -> 0 | J7: =IF(P7="Выходной",SUM(D7*150)*1.5,SUM(D7*150)) -> 0 | K7: =IF(OR(WEEKDAY(A7)=1,WEEKDAY(A7)=7,NOT(ISERROR(MATCH(A7,[1]Праздники!A:A,0)))),SUM(E7*225)*1.5,SUM(E7*225)) -> 0 | L7: =IF(OR(WEEKDAY(A7)=1,WEEKDAY(A7)=7,NOT(ISERROR(MATCH(A7,[1]Праздники!A:A,0)))),SUM(F7*225)*1.5,SUM(F7*225)) -> 0 | M7: =SUM(G7*15) -> 4684.8 | N7: =SUM(H7)*750 -> 0 | O7: =SUM(I7:N7) -> 4684.8 | P7: =IF(OR(WEEKDAY(A7)=1,WEEKDAY(A7)=7,NOT(ISERROR(MATCH(A7,[1]Праздники!A:A,0)))),"Выходной","Рабочий") -> Выходной
A8: 45964 | C8: 0 | D8: 0 | G8: =IF(A8 ="",0,G7+C8+E8-D7-F7) -> 312.32 | I8: =IF(P8="Выходной",SUM(C8*150)*1.5,SUM(C8*150)) -> 0 | J8: =IF(P8="Выходной",SUM(D8*150)*1.5,SUM(D8*150)) -> 0 | K8: =IF(OR(WEEKDAY(A8)=1,WEEKDAY(A8)=7,NOT(ISERROR(MATCH(A8,[1]Праздники!A:A,0)))),SUM(E8*225)*1.5,SUM(E8*225)) -> 0 | L8: =IF(OR(WEEKDAY(A8)=1,WEEKDAY(A8)=7,NOT(ISERROR(MATCH(A8,[1]Праздники!A:A,0)))),SUM(F8*225)*1.5,SUM(F8*225)) -> 0 | M8: =SUM(G8*15) -> 4684.8 | N8: =SUM(H8)*750 -> 0 | O8: =SUM(I8:N8) -> 4684.8 | P8: =IF(OR(WEEKDAY(A8)=1,WEEKDAY(A8)=7,NOT(ISERROR(MATCH(A8,[1]Праздники!A:A,0)))),"Выходной","Рабочий") -> Выходной
A9: 45965 | C9: 0 | D9: 0 | G9: =IF(A9 ="",0,G8+C9+E9-D8-F8) -> 312.32 | I9: =IF(P9="Выходной",SUM(C9*150)*1.5,SUM(C9*150)) -> 0 | J9: =IF(P9="Выходной",SUM(D9*150)*1.5,SUM(D9*150)) -> 0 | K9: =IF(OR(WEEKDAY(A9)=1,WEEKDAY(A9)=7,NOT(ISERROR(MATCH(A9,[1]Праздники!A:A,0)))),SUM(E9*225)*1.5,SUM(E9*225)) -> 0 | L9: =IF(OR(WEEKDAY(A9)=1,WEEKDAY(A9)=7,NOT(ISERROR(MATCH(A9,[1]Праздники!A:A,0)))),SUM(F9*225)*1.5,SUM(F9*225)) -> 0 | M9: =SUM(G9*15) -> 4684.8 | N9: =SUM(H9)*750 -> 0 | O9: =SUM(I9:N9) -> 4684.8 | P9: =IF(OR(WEEKDAY(A9)=1,WEEKDAY(A9)=7,NOT(ISERROR(MATCH(A9,[1]Праздники!A:A,0)))),"Выходной","Рабочий") -> Выходной
