Workbook

Sheet Лист1

Sheet Биаксплен Новосибирск
A1: =T37 -> 312363.26
A2: ="Отчет по хранению товара за " & TEXT(B5,"ММММ ГГГГ") -> Отчет по хранению товара за Декабрь 2025
A3: № | B3: дата | D3: Выгрузка кол-во | E3: Загрузка кол-во | F3: Хранение | G3: Резервирование 70 т | H3: Мин. Суточный резерв 0 т | I3: переконсолидация (тонн) | J3: Паллетирование | K3: Ночная загруска выгрузка | L3: стоимость ночной загруски | M3: стоимость выгрузки | N3: стоимость загрузки | O3: стоимость хранения | P3: Стоимость резервирования | Q3: Стоимость мин.суточной бработки | R3: стоимость переконс. | S3: Стоимость паллетирования | T3: итого
A5: 1 | B5: 45992 | F5: =194.4843+D5-E5 -> 194.4843 | G5: =IF(OR(B5="",NOT(ISERROR(SEARCH("KPI",$A$2))),NOT(ISERROR(SEARCH("Полиом",$A$2)))),0,IF(70-F5<=0,0,70-F5)) -> 0 | L5: =SUM(K5*240) -> 0 | M5: =SUM(D5*120) -> 0 | N5: =SUM(E5*120) -> 0 | O5: =SUM(F5*54) -> 10502.152 | P5: =SUM(G5*54) -> 0 | Q5: =SUM(H5*120) -> 0 | R5: =SUM(I5*1000) -> 0 | S5: =SUM(J5*140) -> 0 | T5: =SUM(L5:S5) -> 10502.152
A6: 2 | B6: 45993 | E6: 4.032 | F6: =F5-E6+D6 -> 190.4523 | G6: =IF(OR(B6="",NOT(ISERROR(SEARCH("KPI",$A$2))),NOT(ISERROR(SEARCH("Полиом",$A$2)))),0,IF(70-F6<=0,0,70-F6)) -> 0 | L6: =SUM(K6*240) -> 0 | M6: =SUM(D6*120) -> 0 | N6: =SUM(E6*120) -> 483.84 | O6: =SUM(F6*54) -> 10284.424 | P6: =SUM(G6*54) -> 0 | Q6: =SUM(H6*120) -> 0 | R6: =SUM(I6*1000) -> 0 | S6: =SUM(J6*140) -> 0 | T6: =SUM(L6:S6) -> 10768.264
A7: 3 | B7: 45994 | F7: =F6-E7+D7 -> 190.4523 | G7: =IF(OR(B7="",NOT(ISERROR(SEARCH("KPI",$A$2))),NOT(ISERROR(SEARCH("Полиом",$A$2)))),0,IF(70-F7<=0,0,70-F7)) -> 0 | L7: =SUM(K7*240) -> 0 | M7: =SUM(D7*120) -> 0 | N7: =SUM(E7*120) -> 0 | O7: =SUM(F7*54) -> 10284.424 | P7: =SUM(G7*54) -> 0 | Q7: =SUM(H7*120) -> 0 | R7: =SUM(I7*1000) -> 0 | S7: =SUM(J7*140) -> 0 | T7: =SUM(L7:S7) -> 10284.424
A8: 4 | B8: 45995 | E8: 6.7292 | F8: =F7-E8+D8 -> 183.7231 | G8: =IF(OR(B8="",NOT(ISERROR(SEARCH("KPI",$A$2))),NOT(ISERROR(SEARCH("Полиом",$A$2)))),0,IF(70-F8<=0,0,70-F8)) -> 0 | L8: =SUM(K8*240) -> 0 | M8: =SUM(D8*120) -> 0 | N8: =SUM(E8*120) -> 807.504 | O8: =SUM(F8*54) -> 9921.0474 | P8: =SUM(G8*54) -> 0 | Q8: =SUM(H8*120) -> 0 | R8: =SUM(I8*1000) -> 0 | S8: =SUM(J8*140) -> 0 | T8: =SUM(L8:S8) -> 10728.551
A9: 5 | B9: 45996 | F9: =F8-E9+D9 -> 183.7231 | G9: =IF(OR(B9="",NOT(ISERROR(SEARCH("KPI",$A$2))),NOT(ISERROR(SEARCH("Полиом",$A$2)))),0,IF(70-F9<=0,0,70-F9)) -> 0 | L9: =SUM(K9*240) -> 0 | M9: =SUM(D9*120) -> 0 | N9: =SUM(E9*120) -> 0 | O9: =SUM(F9*54) -> 9921.0474 | P9: =SUM(G9*54) -> 0 | Q9: =SUM(H9*120) -> 0 | R9: =SUM(I9*1000) -> 0 | S9: =SUM(J9*140) -> 0 | T9: =SUM(L9:S9) -> 9921.0474
A10: 6 | B10: 45997 | E10: 7.2236 | F10: =F9-E10+D10 -> 176.4995 | G10: =IF(OR(B10="",NOT(ISERROR(SEARCH("KPI",$A$2))),NOT(ISERROR(SEARCH("Полиом",$A$2)))),0,IF(70-F10<=0,0,70-F10)) -> 0 | L10: =SUM(K10*240) -> 0 | M10: =SUM(D10*120) -> 0 | N10: =SUM(E10*120) -> 866.832 | O10: =SUM(F10*54) -> 9530.973 | P10: =SUM(G10*54) -> 0 | Q10: =SUM(H10*120) -> 0 | R10: =SUM(I10*1000) -> 0 | S10: =SUM(J10*140) -> 0 | T10: =SUM(L10:S10) -> 10397.805
A11: 7 | B11: 45998 | F11: =F10-E11+D11 -> 176.4995 | G11: =IF(OR(B11="",NOT(ISERROR(SEARCH("KPI",$A$2))),NOT(ISERROR(SEARCH("Полиом",$A$2)))),0,IF(70-F11<=0,0,70-F11)) -> 0 | L11: =SUM(K11*240) -> 0 | M11: =SUM(D11*120) -> 0 | N11: =SUM(E11*120) -> 0 | O11: =SUM(F11*54) -> 9530.973 | P11: =SUM(G11*54) -> 0 | Q11: =SUM(H11*120) -> 0 | R11: =SUM(I11*1000) -> 0 | S11: =SUM(J11*140) -> 0 | T11: =SUM(L11:S11) -> 9530.973
A12: 8 | B12: 45999 | F12: =F11-E12+D12 -> 176.4995 | G12: =IF(OR(B12="",NOT(ISERROR(SEARCH("KPI",$A$2))),NOT(ISERROR(SEARCH("Полиом",$A$2)))),0,IF(70-F12<=0,0,70-F12)) -> 0 | L12: =SUM(K12*240) -> 0 | M12: =SUM(D12*120) -> 0 | N12: =SUM(E12*120) -> 0 | O12: =SUM(F12*54) -> 9530.973 | P12: =SUM(G12*54) -> 0 | Q12: =SUM(H12*120) -> 0 | R12: =SUM(I12*1000) -> 0 | S12: =SUM(J12*140) -> 0 | T12: =SUM(L12:S12) -> 9530.973
A13: 9 | B13: 46000 | E13: 4.1532 | F13: =F12-E13+D13 -> 172.3463 | G13: =IF(OR(B13="",NOT(ISERROR(SEARCH("KPI",$A$2))),NOT(ISERROR(SEARCH("Полиом",$A$2)))),0,IF(70-F13<=0,0,70-F13)) -> 0 | L13: =SUM(K13*240) -> 0 | M13: =SUM(D13*120) -> 0 | N13: =SUM(E13*120) -> 498.384 | O13: =SUM(F13*54) -> 9306.7002 | P13: =SUM(G13*54) -> 0 | Q13: =SUM(H13*120) -> 0 | R13: =SUM(I13*1000) -> 0 | S13: =SUM(J13*140) -> 0 | T13: =SUM(L13:S13) -> 9805.0842
A14: 10 | B14: 46001 | F14: =F13-E14+D14 -> 172.3463 | G14: =IF(OR(B14="",NOT(ISERROR(SEARCH("KPI",$A$2))),NOT(ISERROR(SEARCH("Полиом",$A$2)))),0,IF(70-F14<=0,0,70-F14)) -> 0 | L14: =SUM(K14*240) -> 0 | M14: =SUM(D14*120) -> 0 | N14: =SUM(E14*120) -> 0 | O14: =SUM(F14*54) -> 9306.7002 | P14: =SUM(G14*54) -> 0 | Q14: =SUM(H14*120) -> 0 | R14: =SUM(I14*1000) -> 0 | S14: =SUM(J14*140) -> 0 | T14: =SUM(L14:S14) -> 9306.7002
A15: 11 | B15: 46002 | E15: 4.4745 | F15: =F14-E15+D15 -> 167.8718 | G15: =IF(OR(B15="",NOT(ISERROR(SEARCH("KPI",$A$2))),NOT(ISERROR(SEARCH("Полиом",$A$2)))),0,IF(70-F15<=0,0,70-F15)) -> 0 | L15: =SUM(K15*240) -> 0 | M15: =SUM(D15*120) -> 0 | N15: =SUM(E15*120) -> 536.94 | O15: =SUM(F15*54) -> 9065.0772 | P15: =SUM(G15*54) -> 0 | Q15: =SUM(H15*120) -> 0 | R15: =SUM(I15*1000) -> 0 | S15: =SUM(J15*140) -> 0 | T15: =SUM(L15:S15) -> 9602.0172
A16: 12 | B16: 46003 | F16: =F15-E16+D16 -> 167.8718 | G16: =IF(OR(B16="",NOT(ISERROR(SEARCH("KPI",$A$2))),NOT(ISERROR(SEARCH("Полиом",$A$2)))),0,IF(70-F16<=0,0,70-F16)) -> 0 | L16: =SUM(K16*240) -> 0 | M16: =SUM(D16*120) -> 0 | N16: =SUM(E16*120) -> 0 | O16: =SUM(F16*54) -> 9065.0772 | P16: =SUM(G16*54) -> 0 | Q16: =SUM(H16*120) -> 0 | R16: =SUM(I16*1000) -> 0 | S16: =SUM(J16*140) -> 0 | T16: =SUM(L16:S16) -> 9065.0772
A17: 13 | B17: 46004 | F17: =F16-E17+D17 -> 167.8718 | G17: =IF(OR(B17="",NOT(ISERROR(SEARCH("KPI",$A$2))),NOT(ISERROR(SEARCH("Полиом",$A$2)))),0,IF(70-F17<=0,0,70-F17)) -> 0 | L17: =SUM(K17*240) -> 0 | M17: =SUM(D17*120) -> 0 | N17: =SUM(E17*120) -> 0 | O17: =SUM(F17*54) -> 9065.0772 | P17: =SUM(G17*54) -> 0 | Q17: =SUM(H17*120) -> 0 | R17: =SUM(I17*1000) -> 0 | S17: =SUM(J17*140) -> 0 | T17: =SUM(L17:S17) -> 9065.0772
A18: 14 | B18: 46005 | F18: =F17-E18+D18 -> 167.8718 | G18: =IF(OR(B18="",NOT(ISERROR(SEARCH("KPI",$A$2))),NOT(ISERROR(SEARCH("Полиом",$A$2)))),0,IF(70-F18<=0,0,70-F18)) -> 0 | L18: =SUM(K18*240) -> 0 | M18: =SUM(D18*120) -> 0 | N18: =SUM(E18*120) -> 0 | O18: =SUM(F18*54) -> 9065.0772 | P18: =SUM(G18*54) -> 0 | Q18: =SUM(H18*120) -> 0 | R18: =SUM(I18*1000) -> 0 | S18: =SUM(J18*140) -> 0 | T18: =SUM(L18:S18) -> 9065.0772
A19: 15 | B19: 46006 | F19: =F18-E19+D19 -> 167.8718 | G19: =IF(OR(B19="",NOT(ISERROR(SEARCH("KPI",$A$2))),NOT(ISERROR(SEARCH("Полиом",$A$2)))),0,IF(70-F19<=0,0,70-F19)) -> 0 | L19: =SUM(K19*240) -> 0 | M19: =SUM(D19*120) -> 0 | N19: =SUM(E19*120) -> 0 | O19: =SUM(F19*54) -> 9065.0772 | P19: =SUM(G19*54) -> 0 | Q19: =SUM(H19*120) -> 0 | R19: =SUM(I19*1000) -> 0 | S19: =SUM(J19*140) -> 0 | T19: =SUM(L19:S19) -> 9065.0772
A20: 16 | B20: 46007 | E20: 21.3403 | F20: =F19-E20+D20 -> 146.5315 | G20: =IF(OR(B20="",NOT(ISERROR(SEARCH("KPI",$A$2))),NOT(ISERROR(SEARCH("Полиом",$A$2)))),0,IF(70-F20<=0,0,70-F20)) -> 0 | L20: =SUM(K20*240) -> 0 | M20: =SUM(D20*120) -> 0 | N20: =SUM(E20*120) -> 2560.836 | O20: =SUM(F20*54) -> 7912.701 | P20: =SUM(G20*54) -> 0 | Q20: =SUM(H20*120) -> 0 | R20: =SUM(I20*1000) -> 0 | S20: =SUM(J20*140) -> 0 | T20: =SUM(L20:S20) -> 10473.537
A21: 17 | B21: 46008 | F21: =F20-E21+D21 -> 146.5315 | G21: =IF(OR(B21="",NOT(ISERROR(SEARCH("KPI",$A$2))),NOT(ISERROR(SEARCH("Полиом",$A$2)))),0,IF(70-F21<=0,0,70-F21)) -> 0 | L21: =SUM(K21*240) -> 0 | M21: =SUM(D21*120) -> 0 | N21: =SUM(E21*120) -> 0 | O21: =SUM(F21*54) -> 7912.701 | P21: =SUM(G21*54) -> 0 | Q21: =SUM(H21*120) -> 0 | R21: =SUM(I21*1000) -> 0 | S21: =SUM(J21*140) -> 0 | T21: =SUM(L21:S21) -> 7912.701
A22: 18 | B22: 46009 | E22: 20.3277 | F22: =F21-E22+D22 -> 126.2038 | G22: =IF(OR(B22="",NOT(ISERROR(SEARCH("KPI",$A$2))),NOT(ISERROR(SEARCH("Полиом",$A$2)))),0,IF(70-F22<=0,0,70-F22)) -> 0 | L22: =SUM(K22*240) -> 0 | M22: =SUM(D22*120) -> 0 | N22: =SUM(E22*120) -> 2439.324 | O22: =SUM(F22*54) -> 6815.0052 | P22: =SUM(G22*54) -> 0 | Q22: =SUM(H22*120) -> 0 | R22: =SUM(I22*1000) -> 0 | S22: =SUM(J22*140) -> 0 | T22: =SUM(L22:S22) -> 9254.3292
A23: 19 | B23: 46010 | F23: =F22-E23+D23 -> 126.2038 | G23: =IF(OR(B23="",NOT(ISERROR(SEARCH("KPI",$A$2))),NOT(ISERROR(SEARCH("Полиом",$A$2)))),0,IF(70-F23<=0,0,70-F23)) -> 0 | L23: =SUM(K23*240) -> 0 | M23: =SUM(D23*120) -> 0 | N23: =SUM(E23*120) -> 0 | O23: =SUM(F23*54) -> 6815.0052 | P23: =SUM(G23*54) -> 0 | Q23: =SUM(H23*120) -> 0 | R23: =SUM(I23*1000) -> 0 | S23: =SUM(J23*140) -> 0 | T23: =SUM(L23:S23) -> 6815.0052
A24: 20 | B24: 46011 | E24: 5.0472 | F24: =F23-E24+D24 -> 121.1566 | G24: =IF(OR(B24="",NOT(ISERROR(SEARCH("KPI",$A$2))),NOT(ISERROR(SEARCH("Полиом",$A$2)))),0,IF(70-F24<=0,0,70-F24)) -> 0 | L24: =SUM(K24*240) -> 0 | M24: =SUM(D24*120) -> 0 | N24: =SUM(E24*120) -> 605.664 | O24: =SUM(F24*54) -> 6542.4564 | P24: =SUM(G24*54) -> 0 | Q24: =SUM(H24*120) -> 0 | R24: =SUM(I24*1000) -> 0 | S24: =SUM(J24*140) -> 0 | T24: =SUM(L24:S24) -> 7148.1204
A25: 21 | B25: 46012 | F25: =F24-E25+D25 -> 121.1566 | G25: =IF(OR(B25="",NOT(ISERROR(SEARCH("KPI",$A$2))),NOT(ISERROR(SEARCH("Полиом",$A$2)))),0,IF(70-F25<=0,0,70-F25)) -> 0 | L25: =SUM(K25*240) -> 0 | M25: =SUM(D25*120) -> 0 | N25: =SUM(E25*120) -> 0 | O25: =SUM(F25*54) -> 6542.4564 | P25: =SUM(G25*54) -> 0 | Q25: =SUM(H25*120) -> 0 | R25: =SUM(I25*1000) -> 0 | S25: =SUM(J25*140) -> 0 | T25: =SUM(L25:S25) -> 6542.4564
A26: 22 | B26: 46013 | F26: =F25-E26+D26 -> 121.1566 | G26: =IF(OR(B26="",NOT(ISERROR(SEARCH("KPI",$A$2))),NOT(ISERROR(SEARCH("Полиом",$A$2)))),0,IF(70-F26<=0,0,70-F26)) -> 0 | L26: =SUM(K26*240) -> 0 | M26: =SUM(D26*120) -> 0 | N26: =SUM(E26*120) -> 0 | O26: =SUM(F26*54) -> 6542.4564 | P26: =SUM(G26*54) -> 0 | Q26: =SUM(H26*120) -> 0 | R26: =SUM(I26*1000) -> 0 | S26: =SUM(J26*140) -> 0 | T26: =SUM(L26:S26) -> 6542.4564
A27: 23 | B27: 46014 | E27: 20.1362 | F27: =F26-E27+D27 -> 101.0204 | G27: =IF(OR(B27="",NOT(ISERROR(SEARCH("KPI",$A$2))),NOT(ISERROR(SEARCH("Полиом",$A$2)))),0,IF(70-F27<=0,0,70-F27)) -> 0 | L27: =SUM(K27*240) -> 0 | M27: =SUM(D27*120) -> 0 | N27: =SUM(E27*120) -> 2416.344 | O27: =SUM(F27*54) -> 5455.1016 | P27: =SUM(G27*54) -> 0 | Q27: =SUM(H27*120) -> 0 | R27: =SUM(I27*1000) -> 0 | S27: =SUM(J27*140) -> 0 | T27: =SUM(L27:S27) -> 7871.4456
A28: 24 | B28: 46015 | F28: =F27-E28+D28 -> 101.0204 | G28: =IF(OR(B28="",NOT(ISERROR(SEARCH("KPI",$A$2))),NOT(ISERROR(SEARCH("Полиом",$A$2)))),0,IF(70-F28<=0,0,70-F28)) -> 0 | L28: =SUM(K28*240) -> 0 | M28: =SUM(D28*120) -> 0 | N28: =SUM(E28*120) -> 0 | O28: =SUM(F28*54) -> 5455.1016 | P28: =SUM(G28*54) -> 0 | Q28: =SUM(H28*120) -> 0 | R28: =SUM(I28*1000) -> 0 | S28: =SUM(J28*140) -> 0 | T28: =SUM(L28:S28) -> 5455.1016
A29: 25 | B29: 46016 | E29: 30.345 | F29: =F28-E29+D29 -> 70.6754 | G29: =IF(OR(B29="",NOT(ISERROR(SEARCH("KPI",$A$2))),NOT(ISERROR(SEARCH("Полиом",$A$2)))),0,IF(70-F29<=0,0,70-F29)) -> 0 | L29: =SUM(K29*240) -> 0 | M29: =SUM(D29*120) -> 0 | N29: =SUM(E29*120) -> 3641.4 | O29: =SUM(F29*54) -> 3816.4716 | P29: =SUM(G29*54) -> 0 | Q29: =SUM(H29*120) -> 0 | R29: =SUM(I29*1000) -> 0 | S29: =SUM(J29*140) -> 0 | T29: =SUM(L29:S29) -> 7457.8716
A30: 26 | B30: 46017 | D30: 35.7441 | E30: 3.8177 | F30: =F29-E30+D30 -> 102.6018 | G30: =IF(OR(B30="",NOT(ISERROR(SEARCH("KPI",$A$2))),NOT(ISERROR(SEARCH("Полиом",$A$2)))),0,IF(70-F30<=0,0,70-F30)) -> 0 | L30: =SUM(K30*240) -> 0 | M30: =SUM(D30*120) -> 4289.292 | N30: =SUM(E30*120) -> 458.124 | O30: =SUM(F30*54) -> 5540.4972 | P30: =SUM(G30*54) -> 0 | Q30: =SUM(H30*120) -> 0 | R30: =SUM(I30*1000) -> 0 | S30: =SUM(J30*140) -> 0 | T30: =SUM(L30:S30) -> 10287.913
A31: 27 | B31: 46018 | E31: 1.6954 | F31: =F30-E31+D31 -> 100.9064 | G31: =IF(OR(B31="",NOT(ISERROR(SEARCH("KPI",$A$2))),NOT(ISERROR(SEARCH("Полиом",$A$2)))),0,IF(70-F31<=0,0,70-F31)) -> 0 | L31: =SUM(K31*240) -> 0 | M31: =SUM(D31*120) -> 0 | N31: =SUM(E31*120) -> 203.448 | O31: =SUM(F31*54) -> 5448.9456 | P31: =SUM(G31*54) -> 0 | Q31: =SUM(H31*120) -> 0 | R31: =SUM(I31*1000) -> 0 | S31: =SUM(J31*140) -> 0 | T31: =SUM(L31:S31) -> 5652.3936
A32: 28 | B32: 46019 | F32: =F31-E32+D32 -> 100.9064 | G32: =IF(OR(B32="",NOT(ISERROR(SEARCH("KPI",$A$2))),NOT(ISERROR(SEARCH("Полиом",$A$2)))),0,IF(70-F32<=0,0,70-F32)) -> 0 | L32: =SUM(K32*240) -> 0 | M32: =SUM(D32*120) -> 0 | N32: =SUM(E32*120) -> 0 | O32: =SUM(F32*54) -> 5448.9456 | P32: =SUM(G32*54) -> 0 | Q32: =SUM(H32*120) -> 0 | R32: =SUM(I32*1000) -> 0 | S32: =SUM(J32*140) -> 0 | T32: =SUM(L32:S32) -> 5448.9456
A33: 29 | B33: 46020 | F33: =F32-E33+D33 -> 100.9064 | G33: =IF(OR(B33="",NOT(ISERROR(SEARCH("KPI",$A$2))),NOT(ISERROR(SEARCH("Полиом",$A$2)))),0,IF(70-F33<=0,0,70-F33)) -> 0 | L33: =SUM(K33*240) -> 0 | M33: =SUM(D33*120) -> 0 | N33: =SUM(E33*120) -> 0 | O33: =SUM(F33*54) -> 5448.9456 | P33: =SUM(G33*54) -> 0 | Q33: =SUM(H33*120) -> 0 | R33: =SUM(I33*1000) -> 0 | S33: =SUM(J33*140) -> 0 | T33: =SUM(L33:S33) -> 5448.9456
A34: 30 | B34: 46021 | E34: 19.0464 | F34: =F33-E34+D34 -> 81.86 | G34: =IF(OR(B34="",NOT(ISERROR(SEARCH("KPI",$A$2))),NOT(ISERROR(SEARCH("Полиом",$A$2)))),0,IF(70-F34<=0,0,70-F34)) -> 0 | L34: =SUM(K34*240) -> 0 | M34: =SUM(D34*120) -> 0 | N34: =SUM(E34*120) -> 2285.568 | O34: =SUM(F34*54) -> 4420.44 | P34: =SUM(G34*54) -> 0 | Q34: =SUM(H34*120) -> 0 | R34: =SUM(I34*1000) -> 0 | S34: =SUM(J34*140) -> 0 | T34: =SUM(L34:S34) -> 6706.008
B35: 46022 | E35: 3.4355 | F35: =F34-E35+D35 -> 78.4245 | G35: =IF(OR(B35="",NOT(ISERROR(SEARCH("KPI",$A$2))),NOT(ISERROR(SEARCH("Полиом",$A$2)))),0,IF(70-F35<=0,0,70-F35)) -> 0 | L35: =SUM(K35*240) -> 0 | M35: =SUM(D35*120) -> 0 | N35: =SUM(E35*120) -> 412.26 | O35: =SUM(F35*54) -> 4234.923 | P35: =SUM(G35*54) -> 0 | Q35: =SUM(H35*120) -> 0 | R35: =SUM(I35*1000) -> 0 | S35: =SUM(J35*140) -> 0 | T35: =SUM(L35:S35) -> 4647.183
F36: =SUM(F5:F35) -> 4403.6473 | G36: =SUM(G5:G35) -> 0 | H36: =SUM(H5:H35) -> 0 | I36: =SUM(I5:I35) -> 0 | J36: =SUM(J5:J35) -> 0 | K36: =SUM(K5:K35) -> 0 | L36: =SUM(L5:L35) -> 0 | M36: =SUM(M5:M35) -> 4289.292 | ... T36: =SUM(T5:T35) -> 260302.71
T37: =T36*1.2 -> 312363.26

Sheet ИТОГО
A1: =G16 -> 1.3262589e+08
I2: ТОП
A3: Склад | B3: Сибур | C3: Завод | D3: Русвинил | E3: Клиенты сибура | F3: Остальные | G3: Итого | I3: Нижнекамск завод | J3: 41304976
A4: Баумана | B4: =INDEX($M$44:$M$53,MATCH(A4,$A$44:$A$53,0),1) -> 9146660.3 | C4: 0 | D4: =INDEX($B$56:$B$72,MATCH(A4,$A$56:$A$72,0),1) -> 808299.63 | E4: =SUMIF($F$19:$F$41,A4,$G$19:$G$41) -> 0 | F4: =SUMIF($B$19:$B$27,A4,$C$19:$C$27) -> 75482.2 | G4: =SUM(B4:F4) -> 10030442 | I4: Казань_Автосервисная | J4: 20240007
A5: Новикова-Прибоя | B5: =INDEX($M$44:$M$53,MATCH(A5,$A$44:$A$53,0),1) -> 11632297 | C5: 0 | D5: =INDEX($B$56:$B$72,MATCH(A5,$A$56:$A$72,0),1) -> 175179.96 | E5: =SUMIF($F$19:$F$41,A5,$G$19:$G$41) -> 0 | F5: =SUMIF($B$19:$B$27,A5,$C$19:$C$27) -> 8184 | G5: =SUM(B5:F5) -> 11815661 | I5: Новикова-Прибоя | J5: 11815661
A6: Екатеринбург | B6: =INDEX($M$44:$M$53,MATCH(A6,$A$44:$A$53,0),1) -> 10552487 | C6: 0 | D6: =INDEX($B$56:$B$72,MATCH(A6,$A$56:$A$72,0),1) -> 0 | E6: =SUMIF($F$19:$F$41,A6,$G$19:$G$41) -> 0 | F6: =SUMIF($B$19:$B$27,A6,$C$19:$C$27) -> 0 | G6: =SUM(B6:F6) -> 10552487 | I6: Екатеринбург | J6: 10552487
A7: Новосибирск | B7: =INDEX($M$44:$M$53,MATCH(A7,$A$44:$A$53,0),1) -> 8021379.2 | C7: 0 | D7: =INDEX($B$56:$B$72,MATCH(A7,$A$56:$A$72,0),1) -> 0 | E7: =SUMIF($F$19:$F$41,A7,$G$19:$G$41) -> 312363.26 | F7: =SUMIF($B$19:$B$27,A7,$C$19:$C$27) -> 0 | G7: =SUM(B7:F7) -> 8333742.4 | I7: Баумана | J7: 10030442
A8: Новосибирск_Пасечная | B8: =INDEX($M$44:$M$53,MATCH(A8,$A$44:$A$53,0),1) -> 5576686.6 | C8: 0 | D8: =INDEX($B$56:$B$72,MATCH(A8,$A$56:$A$72,0),1) -> 0 | E8: =SUMIF($F$19:$F$41,A8,$G$19:$G$41) -> 0 | F8: =SUMIF($B$19:$B$27,A8,$C$19:$C$27) -> 0 | G8: =SUM(B8:F8) -> 5576686.6 | I8: Казань_Приволжская | J8: 8933435.8
A9: Казань_Автосервисная | B9: =INDEX($M$44:$M$53,MATCH(A9,$A$44:$A$53,0),1) -> 20240007 | C9: 0 | D9: =INDEX($B$56:$B$72,MATCH(A9,$A$56:$A$72,0),1) -> 0 | E9: =SUMIF($F$19:$F$41,A9,$G$19:$G$41) -> 0 | F9: =SUMIF($B$19:$B$27,A9,$C$19:$C$27) -> 0 | G9: =SUM(B9:F9) -> 20240007 | I9: Новосибирск | J9: 8333742.4
A10: Казань_Приволжская | B10: =INDEX($M$44:$M$53,MATCH(A10,$A$44:$A$53,0),1) -> 8933435.8 | C10: 0 | D10: =INDEX($B$56:$B$72,MATCH(A10,$A$56:$A$72,0),1) -> 0 | E10: =SUMIF($F$19:$F$41,A10,$G$19:$G$41) -> 0 | F10: =SUMIF($B$19:$B$27,A10,$C$19:$C$27) -> 0 | G10: =SUM(B10:F10) -> 8933435.8 | I10: Зеленодольск | J10: 7871512.5
A11: Зеленодольск | B11: =INDEX($M$44:$M$53,MATCH(A11,$A$44:$A$53,0),1) -> 7252070.3 | C11: 0 | D11: =INDEX($B$56:$B$72,MATCH(A11,$A$56:$A$72,0),1) -> 0 | E11: =SUMIF($F$19:$F$41,A11,$G$19:$G$41) -> 619442.22 | F11: =SUMIF($B$19:$B$27,A11,$C$19:$C$27) -> 0 | G11: =SUM(B11:F11) -> 7871512.5 | I11: Новосибирск_Пасечная | J11: 5576686.6
A12: Нижнекамск | B12: =INDEX($M$44:$M$53,MATCH(A12,$A$44:$A$53,0),1) -> 3908030.8 | C12: 0 | D12: =INDEX($B$56:$B$72,MATCH(A12,$A$56:$A$72,0),1) -> 0 | E12: =SUMIF($F$19:$F$41,A12,$G$19:$G$41) -> 28252.224 | F12: =SUMIF($B$19:$B$27,A12,$C$19:$C$27) -> 0 | G12: =SUM(B12:F12) -> 3936283 | I12: Березовая Пойма | J12: 4030657.1
A13: Нижнекамск завод | B13: 0 | C13: =C29+C36 -> 41304976 | D13: =INDEX($B$56:$B$72,MATCH(A13,$A$56:$A$72,0),1) -> 0 | E13: =SUMIF($F$19:$F$41,A13,$G$19:$G$41) -> 0 | F13: =SUMIF($B$19:$B$27,A13,$C$19:$C$27) -> 0 | G13: =SUM(B13:F13) -> 41304976 | I13: Нижнекамск | J13: 3936283
A14: Монастырка | B14: 0 | C14: 0 | D14: =INDEX($B$56:$B$72,MATCH(A14,$A$56:$A$72,0),1) -> 0 | E14: =SUMIF($F$19:$F$41,A14,$G$19:$G$41) -> 0 | F14: =SUMIF($B$19:$B$27,A14,$C$19:$C$27) -> 0 | G14: =SUM(B14:F14) -> 0 | I14: Монастырка | J14: 0
A15: Березовая Пойма | B15: =INDEX($M$44:$M$53,MATCH(A15,$A$44:$A$53,0),1) -> 0 | C15: 0 | D15: =INDEX($B$56:$B$72,MATCH(A15,$A$56:$A$72,0),1) -> 4030657.1 | E15: =SUMIF($F$19:$F$41,A15,$G$19:$G$41) -> 0 | F15: =SUMIF($B$19:$B$27,A15,$C$19:$C$27) -> 0 | G15: =SUM(B15:F15) -> 4030657.1
B16: =SUM(B4:B15) -> 85263054 | C16: =SUM(C4:C15) -> 41304976 | D16: =SUM(D4:D15) -> 5014136.7 | E16: =SUM(E4:E15) -> 960057.7 | F16: =SUM(F4:F15) -> 83666.2 | G16: =SUM(G4:G15) -> 1.3262589e+08
A18: Остальные клиенты | C18: =SUM(C19:C27) -> 83666.2 | E18: Клиенты сибура | G18: =SUM(G19:G40) -> 960057.7
A19: Стройтех | B19: Баумана | C19: {=IFERROR(INDIRECT("'" & A19 & "'!A1"),)} -> 22627 | E19: Приоритет | F19: Баумана | G19: {=IFERROR(INDIRECT("'" & E19 & " " & F19 & "'!A1"),0)} -> 0
A20: Ергарда | B20: Баумана | C20: {=IFERROR(INDIRECT("'" & A20 & "'!A1"),)} -> 8928 | E20: Фармпласт | F20: Баумана | G20: {=IFERROR(INDIRECT("'" & E20 & " " & F20 & "'!A1"),0)} -> 0
A21: Литейные решения | B21: Баумана | C21: {=IFERROR(INDIRECT("'" & A21 & "'!A1"),)} -> 18648 | E21: Юг Полимер | F21: Баумана | G21: {=IFERROR(INDIRECT("'" & E21 & " " & F21 & "'!A1"),0)} -> 0
A22: Сандекс | B22: Баумана | C22: {=IFERROR(INDIRECT("'" & A22 & "'!A1"),)} -> 24609.6 | E22: Центрополимер | F22: Екатеринбург | G22: {=IFERROR(INDIRECT("'" & E22 & " " & F22 & "'!A1"),0)} -> 0
A23: ЛС-Техномет | B23: Баумана | C23: {=IFERROR(INDIRECT("'" & A23 & "'!A1"),)} -> 669.6 | E23: Приоритет | F23: Екатеринбург | G23: {=IFERROR(INDIRECT("'" & E23 & " " & F23 & "'!A1"),0)} -> 0
A24: РусДжам | B24: ГАЗ | C24: {=IFERROR(INDIRECT("'" & A24 & "'!A1"),)} -> 0 | E24: Фармпласт | F24: Екатеринбург | G24: {=IFERROR(INDIRECT("'" & E24 & " " & F24 & "'!A1"),0)} -> 0
A25: Виго | B25: Новикова-Прибоя | C25: {=IFERROR(INDIRECT("'" & A25 & "'!A1"),)} -> 0 | E25: Приоритет | F25: Зеленодольск | G25: {=IFERROR(INDIRECT("'" & E25 & " " & F25 & "'!A1"),0)} -> 0
A26: Доктор Франк | B26: Новикова-Прибоя | C26: {=IFERROR(INDIRECT("'" & A26 & "'!A1"),)} -> 8184 | E26: Данафлекс | F26: Зеленодольск | G26: {=IFERROR(INDIRECT("'" & E26 & " " & F26 & "'!t37"),0)} -> 619442.22
A27: Нефтезол | B27: Новикова-Прибоя | C27: {=IFERROR(INDIRECT("'" & A27 & "'!A1"),)} -> 0 | E27: ИП Ксендз | F27: Нижнекамск | G27: {=IFERROR(INDIRECT("'" & E27 & " " & F27 & "'!A1"),0)} -> 28252.224
E28: Фармпласт | F28: Новикова-Прибоя | G28: {=IFERROR(INDIRECT("'" & E28 & " " & F28 & "'!A1"),0)} -> 0
A29: Нижнекамск завод | C29: =SUM(C30:C34) -> 29349092 | E29: Центрополимер | F29: Новикова-Прибоя | G29: {=IFERROR(INDIRECT("'" & E29 & " " & F29 & "'!A1"),0)} -> 0
A30: ПРР | C30: {=INDIRECT("'" & A29 & "'!F17")} -> 15902450 | E30: Юг Полимер | F30: Новикова-Прибоя | G30: {=IFERROR(INDIRECT("'" & E30 & " " & F30 & "'!A1"),0)} -> 0
A31: Кладовки | C31: {=INDIRECT("'" & A29 & "'!F16")} -> 0 | E31: Приоритет | F31: Новикова-Прибоя | G31: {=IFERROR(INDIRECT("'" & E31 & " " & F31 & "'!A1"),0)} -> 0
A32: Стропальщики | C32: {=INDIRECT("'" & A29 & "'!F18")} -> 744000 | E32: Биаксплен | F32: Новосибирск | G32: {=IFERROR(INDIRECT("'" & E32 & " " & F32 & "'!A1"),0)} -> 312363.26
A33: Мойка контейнеров | C33: {=INDIRECT("'" & A29 & "'!F19")} -> 2313504 | E33: Центрополимер | F33: Новосибирск | G33: {=IFERROR(INDIRECT("'" & E33 & " " & F33 & "'!A1"),0)} -> 0
A34: МТО | C34: {=INDIRECT("'" & A29 & "'!F20")} -> 10389138 | E34: Фармпласт | F34: Новосибирск | G34: {=IFERROR(INDIRECT("'" & E34 & " " & F34 & "'!A1"),0)} -> 0
E35: Юг Полимер | F35: Зеленодольск | G35: {=IFERROR(INDIRECT("'" & E35 & " " & F35 & "'!A1"),0)} -> 0
A36: Контейнерные площадки | C36: =SUM(C37:C41) -> 11955884 | E36: Фармпласт | F36: Казань_Автосервисная | G36: {=IFERROR(INDIRECT("'" & E36 & " " & F36 & "'!A1"),0)} -> 0
A37: КОС | C37: =3998250+1009221.6 -> 5007471.6 | E37: Приоритет | F37: Казань_Приволжская | G37: {=IFERROR(INDIRECT("'" & E37 & " " & F37 & "'!A1"),0)} -> 0
A38: Нижнекамск | C38: 6948412.8 | E38: Центрополимер | F38: Баумана | G38: {=IFERROR(INDIRECT("'" & E38 & " " & F38 & "'!A1"),0)} -> 0
E39: Приоритет | F39: Казань_Автосервисная | G39: {=IFERROR(INDIRECT("'" & E39 & " " & F39 & "'!A1"),0)} -> 0
E40: Оникс | F40: Нижнекамск | G40: {=IFERROR(INDIRECT("'" & E40 & " " & F40 & "'!A1"),0)} -> 0
A42: СИБУР | K42: =SUM(M44:M53) -> 85263054
...

Sheet Другое

Sheet Нижнекамск завод
A9: № | B9: Наименование услуг (работ) | C9: Ед. изм. | D9: Количество | E9: Цена | F9: Сумма
A14: Итого: | F14: =SUM(F10:F13) -> 0
A15: Без налога (НДС) | F15: =SUM(F14) -> 0
A16: Всего (с учетом НДС) | F16: =SUM(F15)*1.2 -> 0
A17: Вышеперечисленные услуги (работы) выполнены полностью. | E17: ПРР | F17: 15902450
A18: ПОКЛАЖЕДАТЕЛЬ претензий по объему, качеству и срокам оказания услуг претензий не имеет. | E18: Стропальщики | F18: 744000
E19: Контейнеры | F19: 2313504
E20: МТО | F20: 10389138
A21: ООО "ДТМ" | D21: ПАО "Нижнекамскнефтехим"
A23: ____________________Молькова Т.Ю. | B23: Расстегаев Д.О. | D23: ____________________

Sheet Резерв
A3: ="Отчет по резерву хранению товара РВ " & TEXT(A6,"ММММ ") & YEAR(A6) & "" -> Отчет по резерву хранению товара РВ Декабрь 2025
A4: дата | C4: Хранение Баумана | D4: Хранение Новикова | E4: Хранение Березовая Пойма | F4: Общее хранение | G4: Резерв 8000 т | H4: стоимость резерва | I4: итого
A6: 45992 | C6: ='[1]РВ Баумана'!G6 -> 1394.295 | D6: ='[1]РВ Новикова-Прибоя'!G6 -> 299.145 | E6: ='[1]РВ Березовая Пойма'!G6 -> 0 | F6: =SUM(C6:E6) -> 1693.44 | G6: =8000-F6 -> 6306.56 | H6: =G6*15 -> 94598.4 | I6: =SUM(H6:H6) -> 94598.4 | J6: =IF(OR(WEEKDAY(A6)=1,WEEKDAY(A6)=7,NOT(ISERROR(MATCH(A6,[1]Праздники!A:A,0)))),"Выходной","Рабочий") -> Рабочий
A7: 45993 | C7: ='[1]РВ Баумана'!G7 -> 1394.295 | D7: ='[1]РВ Новикова-Прибоя'!G7 -> 299.145 | E7: ='[1]РВ Березовая Пойма'!G7 -> 21 | F7: =SUM(C7:E7) -> 1714.44 | G7: =8000-F7 -> 6285.56 | H7: =G7*15 -> 94283.4 | I7: =SUM(H7:H7) -> 94283.4 | J7: =IF(OR(WEEKDAY(A7)=1,WEEKDAY(A7)=7,NOT(ISERROR(MATCH(A7,[1]Праздники!A:A,0)))),"Выходной","Рабочий") -> Рабочий
A8: 45994 | C8: ='[1]РВ Баумана'!G8 -> 1394.295 | D8: ='[1]РВ Новикова-Прибоя'!G8 -> 299.145 | E8: ='[1]РВ Березовая Пойма'!G8 -> 42 | F8: =SUM(C8:E8) -> 1735.44 | G8: =8000-F8 -> 6264.56 | H8: =G8*15 -> 93968.4 | I8: =SUM(H8:H8) -> 93968.4 | J8: =IF(OR(WEEKDAY(A8)=1,WEEKDAY(A8)=7,NOT(ISERROR(MATCH(A8,[1]Праздники!A:A,0)))),"Выходной","Рабочий") -> Рабочий
A9: 45995 | C9: ='[1]РВ Баумана'!G9 -> 1393.125 | D9: ='[1]РВ Новикова-Прибоя'!G9 -> 299.145 | E9: ='[1]РВ Березовая Пойма'!G9 -> 367 | F9: =SUM(C9:E9) -> 2059.27 | G9: =8000-F9 -> 5940.73 | H9: =G9*15 -> 89110.95 | I9: =SUM(H9:H9) -> 89110.95 | J9: =IF(OR(WEEKDAY(A9)=1,WEEKDAY(A9)=7,NOT(ISERROR(MATCH(A9,[1]Праздники!A:A,0)))),"Выходной","Рабочий") -> Рабочий
A10: 45996 | C10: ='[1]РВ Баумана'!G10 -> 1393.125 | D10: ='[1]РВ Новикова-Прибоя'!G10 -> 299.145 | E10: ='[1]РВ Березовая Пойма'!G10 -> 563 | F10: =SUM(C10:E10) -> 2255.27 | G10: =8000-F10 -> 5744.73 | H10: =G10*15 -> 86170.95 | I10: =SUM(H10:H10) -> 86170.95 | J10: =IF(OR(WEEKDAY(A10)=1,WEEKDAY(A10)=7,NOT(ISERROR(MATCH(A10,[1]Праздники!A:A,0)))),"Выходной","Рабочий") -> Рабочий
A11: 45997 | C11: ='[1]РВ Баумана'!G11 -> 1393.125 | D11: ='[1]РВ Новикова-Прибоя'!G11 -> 297.77 | E11: ='[1]РВ Березовая Пойма'!G11 -> 629 | F11: =SUM(C11:E11) -> 2319.895 | G11: =8000-F11 -> 5680.105 | H11: =G11*15 -> 85201.575 | I11: =SUM(H11:H11) -> 85201.575 | J11: =IF(OR(WEEKDAY(A11)=1,WEEKDAY(A11)=7,NOT(ISERROR(MATCH(A11,[1]Праздники!A:A,0)))),"Выходной","Рабочий") -> Выходной
A12: 45998 | C12: ='[1]РВ Баумана'!G12 -> 1393.125 | D12: ='[1]РВ Новикова-Прибоя'!G12 -> 297.77 | E12: ='[1]РВ Березовая Пойма'!G12 -> 650 | F12: =SUM(C12:E12) -> 2340.895 | G12: =8000-F12 -> 5659.105 | H12: =G12*15 -> 84886.575 | I12: =SUM(H12:H12) -> 84886.575 | J12: =IF(OR(WEEKDAY(A12)=1,WEEKDAY(A12)=7,NOT(ISERROR(MATCH(A12,[1]Праздники!A:A,0)))),"Выходной","Рабочий") -> Выходной
A13: 45999 | C13: ='[1]РВ Баумана'!G13 -> 1393.125 | D13: ='[1]РВ Новикова-Прибоя'!G13 -> 297.77 | E13: ='[1]РВ Березовая Пойма'!G13 -> 650 | F13: =SUM(C13:E13) -> 2340.895 | G13: =8000-F13 -> 5659.105 | H13: =G13*15 -> 84886.575 | I13: =SUM(H13:H13) -> 84886.575 | J13: =IF(OR(WEEKDAY(A13)=1,WEEKDAY(A13)=7,NOT(ISERROR(MATCH(A13,[1]Праздники!A:A,0)))),"Выходной","Рабочий") -> Рабочий
A14: 46000 | C14: ='[1]РВ Баумана'!G14 -> 1379.85 | D14: ='[1]РВ Новикова-Прибоя'!G14 -> 289.645 | E14: ='[1]РВ Березовая Пойма'!G14 -> 650 | F14: =SUM(C14:E14) -> 2319.495 | G14: =8000-F14 -> 5680.505 | H14: =G14*15 -> 85207.575 | I14: =SUM(H14:H14) -> 85207.575 | J14: =IF(OR(WEEKDAY(A14)=1,WEEKDAY(A14)=7,NOT(ISERROR(MATCH(A14,[1]Праздники!A:A,0)))),"Выходной","Рабочий") -> Рабочий
A15: 46001 | C15: ='[1]РВ Баумана'!G15 -> 1379.85 | D15: ='[1]РВ Новикова-Прибоя'!G15 -> 289.645 | E15: ='[1]РВ Березовая Пойма'!G15 -> 739 | F15: =SUM(C15:E15) -> 2408.495 | G15: =8000-F15 -> 5591.505 | H15: =G15*15 -> 83872.575 | I15: =SUM(H15:H15) -> 83872.575 | J15: =IF(OR(WEEKDAY(A15)=1,WEEKDAY(A15)=7,NOT(ISERROR(MATCH(A15,[1]Праздники!A:A,0)))),"Выходной","Рабочий") -> Рабочий
A16: 46002 | C16: ='[1]РВ Баумана'!G16 -> 1379.85 | D16: ='[1]РВ Новикова-Прибоя'!G16 -> 288.27 | E16: ='[1]РВ Березовая Пойма'!G16 -> 739 | F16: =SUM(C16:E16) -> 2407.12 | G16: =8000-F16 -> 5592.88 | H16: =G16*15 -> 83893.2 | I16: =SUM(H16:H16) -> 83893.2 | J16: =IF(OR(WEEKDAY(A16)=1,WEEKDAY(A16)=7,NOT(ISERROR(MATCH(A16,[1]Праздники!A:A,0)))),"Выходной","Рабочий") -> Рабочий
A17: 46003 | C17: ='[1]РВ Баумана'!G17 -> 1362.5 | D17: ='[1]РВ Новикова-Прибоя'!G17 -> 288.27 | E17: ='[1]РВ Березовая Пойма'!G17 -> 739 | F17: =SUM(C17:E17) -> 2389.77 | G17: =8000-F17 -> 5610.23 | H17: =G17*15 -> 84153.45 | I17: =SUM(H17:H17) -> 84153.45 | J17: =IF(OR(WEEKDAY(A17)=1,WEEKDAY(A17)=7,NOT(ISERROR(MATCH(A17,[1]Праздники!A:A,0)))),"Выходной","Рабочий") -> Рабочий
... A36: 46022 | C36: ='[1]РВ Баумана'!G36 -> 883.225 | D36: ='[1]РВ Новикова-Прибоя'!G36 -> 190.67 | E36: ='[1]РВ Березовая Пойма'!G36 -> 808.23 | F36: =SUM(C36:E36) -> 1882.125 | G36: =8000-F36 -> 6117.875 | H36: =G36*15 -> 91768.125 | I36: =SUM(H36:H36) -> 91768.125 | J36: =IF(OR(WEEKDAY(A36)=1,WEEKDAY(A36)=7,NOT(ISERROR(MATCH(A36,[1]Праздники!A:A,0)))),"Выходной","Рабочий") -> Выходной
C37: =SUM(C6:C36) -> 39341.71 | D37: =SUM(D6:D36) -> 8346.345 | E37: =SUM(E6:E36) -> 22165.23 | G37: =SUM(G6:G36) -> 178146.71 | H37: =SUM(H6:H36) -> 2672200.7 | I37: =SUM(I6:I36) -> 2672200.7
I38: =I37*1.2 -> 3206640.9

Sheet РВ Баумана
R1: Выходной | S1: Рабочий
Q2: Выгрузка | R2: =SUMIF($P$6:$P$36,R$1,$C6:$C36) -> 0 | S2: =SUMIF($P$6:$P$36,S$1,$C6:$C36) -> 0
A3: ="Отчет по хранению товара РВ " & TEXT(A6,"ММММ ") & YEAR(A6) & " Баумана" -> Отчет по хранению товара РВ Декабрь 2025 Баумана | Q3: Отгрузка | R3: =SUMIF($P$6:$P$36,R$1,$D6:$D36) -> 90.625 | S3: =SUMIF($P$6:$P$36,S$1,$D6:$D36) -> 420.445
A4: дата | C4: Выгрузка кол-во тонн | D4: Загрузка кол-во тонн | E4: Выгрузка после 20:00 | F4: Загрузка после 20:00 | G4: Хранение | H4: переконсолидация (тонн) | I4: стоимость выгрузки | J4: стоимость загрузки | K4: Стоимость выгрузки после 20:00 | L4: Стоимость загрузки после 20:00 | M4: стоимость хранения | N4: стоимость переконс. | O4: итого
G5: (кол-во тонн)
A6: 45992 | C6: 0 | D6: 0 | G6: 1394.295 | I6: =IF(P6="Выходной",SUM(C6*150)*1.5,SUM(C6*150)) -> 0 | J6: =IF(P6="Выходной",SUM(D6*150)*1.5,SUM(D6*150)) -> 0 | K6: =IF(OR(WEEKDAY(A6)=1,WEEKDAY(A6)=7,NOT(ISERROR(MATCH(A6,[1]Праздники!A:A,0)))),SUM(E6*225)*1.5,SUM(E6*225)) -> 0 | L6: =IF(OR(WEEKDAY(A6)=1,WEEKDAY(A6)=7,NOT(ISERROR(MATCH(A6,[1]Праздники!A:A,0)))),SUM(F6*225)*1.5,SUM(F6*225)) -> 0 | M6: =SUM(G6*15) -> 20914.425 | N6: =SUM(H6)*750 -> 0 | O6: =SUM(I6:N6) -> 20914.425 | P6: =IF(OR(WEEKDAY(A6)=1,WEEKDAY(A6)=7,NOT(ISERROR(MATCH(A6,[1]Праздники!A:A,0)))),"Выходной","Рабочий") -> Рабочий
A7: 45993 | C7: 0 | D7: 0 | G7: =IF(A7 ="",0,G6+C7+E7-D6-F6) -> 1394.295 | I7: =IF(P7="Выходной",SUM(C7*150)*1.5,SUM(C7*150)) -> 0 | J7: =IF(P7="Выходной",SUM(D7*150)*1.5,SUM(D7*150)) -> 0 | K7: =IF(OR(WEEKDAY(A7)=1,WEEKDAY(A7)=7,NOT(ISERROR(MATCH(A7,[1]Праздники!A:A,0)))),SUM(E7*225)*1.5,SUM(E7*225)) -> 0 | L7: =IF(OR(WEEKDAY(A7)=1,WEEKDAY(A7)=7,NOT(ISERROR(MATCH(A7,[1]Праздники!A:A,0)))),SUM(F7*225)*1.5,SUM(F7*225)) -> 0 | M7: =SUM(G7*15) -> 20914.425 | N7: =SUM(H7)*750 -> 0 | O7: =SUM(I7:N7) -> 20914.425 | P7: =IF(OR(WEEKDAY(A7)=1,WEEKDAY(A7)=7,NOT(ISERROR(MATCH(A7,[1]Праздники!A:A,0)))),"Выходной","Рабочий") -> Рабочий
A8: 45994 | C8: 0 | D8: 1.17 | G8: =IF(A8 ="",0,G7+C8+E8-D7-F7) -> 1394.295 | I8: =IF(P8="Выходной",SUM(C8*150)*1.5,SUM(C8*150)) -> 0 | J8: =IF(P8="Выходной",SUM(D8*150)*1.5,SUM(D8*150)) -> 175.5 | K8: =IF(OR(WEEKDAY(A8)=1,WEEKDAY(A8)=7,NOT(ISERROR(MATCH(A8,[1]Праздники!A:A,0)))),SUM(E8*225)*1.5,SUM(E8*225)) -> 0 | L8: =IF(OR(WEEKDAY(A8)=1,WEEKDAY(A8)=7,NOT(ISERROR(MATCH(A8,[1]Праздники!A:A,0)))),SUM(F8*225)*1.5,SUM(F8*225)) -> 0 | M8: =SUM(G8*15) -> 20914.425 | N8: =SUM(H8)*750 -> 0 | O8: =SUM(I8:N8) -> 21089.925 | P8: =IF(OR(WEEKDAY(A8)=1,WEEKDAY(A8)=7,NOT(ISERROR(MATCH(A8,[1]Праздники!A:A,0)))),"Выходной","Рабочий") -> Рабочий
A9: 45995 | C9: 0 | D9: 0 | G9: =IF(A9 ="",0,G8+C9+E9-D8-F8) -> 1393.125 | I9: =IF(P9="Выходной",SUM(C9*150)*1.5,SUM(C9*150)) -> 0 | J9: =IF(P9="Выходной",SUM(D9*150)*1.5,SUM(D9*150)) -> 0 | K9: =IF(OR(WEEKDAY(A9)=1,WEEKDAY(A9)=7,NOT(ISERROR(MATCH(A9,[1]Праздники!A:A,0)))),SUM(E9*225)*1.5,SUM(E9*225)) -> 0 | L9: =IF(OR(WEEKDAY(A9)=1,WEEKDAY(A9)=7,NOT(ISERROR(MATCH(A9,[1]Праздники!A:A,0)))),SUM(F9*225)*1.5,SUM(F9*225)) -> 0 | M9: =SUM(G9*15) -> 20896.875 | N9: =SUM(H9)*750 -> 0 | O9: =SUM(I9:N9) -> 20896.875 | P9: =IF(OR(WEEKDAY(A9)=1,WEEKDAY(A9)=7,NOT(ISERROR(MATCH(A9,[1]Праздники!A:A,0)))),"Выходной","Рабочий") -> Рабочий
A10: 45996 | C10: 0 | D10: 0 | G10: =IF(A10 ="",0,G9+C10+E10-D9-F9) -> 1393.125 | I10: =IF(P10="Выходной",SUM(C10*150)*1.5,SUM(C10*150)) -> 0 | J10: =IF(P10="Выходной",SUM(D10*150)*1.5,SUM(D10*150)) -> 0 | K10: =IF(OR(WEEKDAY(A10)=1,WEEKDAY(A10)=7,NOT(ISERROR(MATCH(A10,[1]Праздники!A:A,0)))),SUM(E10*225)*1.5,SUM(E10*225)) -> 0 | L10: =IF(OR(WEEKDAY(A10)=1,WEEKDAY(A10)=7,NOT(ISERROR(MATCH(A10,[1]Праздники!A:A,0)))),SUM(F10*225)*1.5,SUM(F10*225)) -> 0 | M10: =SUM(G10*15) -> 20896.875 | N10: =SUM(H10)*750 -> 0 | O10: =SUM(I10:N10) -> 20896.875 | P10: =IF(OR(WEEKDAY(A10)=1,WEEKDAY(A10)=7,NOT(ISERROR(MATCH(A10,[1]Праздники!A:A,0)))),"Выходной","Рабочий") -> Рабочий
A11: 45997 | C11: 0 | D11: 0 | G11: =IF(A11 ="",0,G10+C11+E11-D10-F10) -> 1393.125 | I11: =IF(P11="Выходной",SUM(C11*150)*1.5,SUM(C11*150)) -> 0 | J11: =IF(P11="Выходной",SUM(D11*150)*1.5,SUM(D11*150)) -> 0 | K11: =IF(OR(WEEKDAY(A11)=1,WEEKDAY(A11)=7,NOT(ISERROR(MATCH(A11,[1]Праздники!A:A,0)))),SUM(E11*225)*1.5,SUM(E11*225)) -> 0 | L11: =IF(OR(WEEKDAY(A11)=1,WEEKDAY(A11)=7,NOT(ISERROR(MATCH(A11,[1]Праздники!A:A,0)))),SUM(F11*225)*1.5,SUM(F11*225)) -> 0 | M11: =SUM(G11*15) -> 20896.875 | N11: =SUM(H11)*750 -> 0 | O11: =SUM(I11:N11) -> 20896.875 | P11: =IF(OR(WEEKDAY(A11)=1,WEEKDAY(A11)=7,NOT(ISERROR(MATCH(A11,[1]Праздники!A:A,0)))),"Выходной","Рабочий") -> Выходной
A12: 45998 | C12: 0 | D12: 0 | G12: =IF(A12 ="",0,G11+C12+E12-D11-F11) -> 1393.125 | I12: =IF(P12="Выходной",SUM(C12*150)*1.5,SUM(C12*150)) -> 0 | J12: =IF(P12="Выходной",SUM(D12*150)*1.5,SUM(D12*150)) -> 0 | K12: =IF(OR(WEEKDAY(A12)=1,WEEKDAY(A12)=7,NOT(ISERROR(MATCH(A12,[1]Праздники!A:A,0)))),SUM(E12*225)*1.5,SUM(E12*225)) -> 0 | L12: =IF(OR(WEEKDAY(A12)=1,WEEKDAY(A12)=7,NOT(ISERROR(MATCH(A12,[1]Праздники!A:A,0)))),SUM(F12*225)*1.5,SUM(F12*225)) -> 0 | M12: =SUM(G12*15) -> 20896.875 | N12: =SUM(H12)*750 -> 0 | O12: =SUM(I12:N12) -> 20896.875 | P12: =IF(OR(WEEKDAY(A12)=1,WEEKDAY(A12)=7,NOT(ISERROR(MATCH(A12,[1]Праздники!A:A,0)))),"Выходной","Рабочий") -> Выходной
A13: 45999 | C13: 0 | D13: 13.275 | G13: =IF(A13 ="",0,G12+C13+E13-D12-F12) -> 1393.125 | I13: =IF(P13="Выходной",SUM(C13*150)*1.5,SUM(C13*150)) -> 0 | J13: =IF(P13="Выходной",SUM(D13*150)*1.5,SUM(D13*150)) -> 1991.25 | K13: =IF(OR(WEEKDAY(A13)=1,WEEKDAY(A13)=7,NOT(ISERROR(MATCH(A13,[1]Праздники!A:A,0)))),SUM(E13*225)*1.5,SUM(E13*225)) -> 0 | L13: =IF(OR(WEEKDAY(A13)=1,WEEKDAY(A13)=7,NOT(ISERROR(MATCH(A13,[1]Праздники!A:A,0)))),SUM(F13*225)*1.5,SUM(F13*225)) -> 0 | M13: =SUM(G13*15) -> 20896.875 | N13: =SUM(H13)*750 -> 0 | O13: =SUM(I13:N13) -> 22888.125 | P13: =IF(OR(WEEKDAY(A13)=1,WEEKDAY(A13)=7,NOT(ISERROR(MATCH(A13,[1]Праздники!A:A,0)))),"Выходной","Рабочий") -> Рабочий
A14: 46000 | C14: 0 | D14: 0 | G14: =IF(A14 ="",0,G13+C14+E14-D13-F13) -> 1379.85 | I14: =IF(P14="Выходной",SUM(C14*150)*1.5,SUM(C14*150)) -> 0 | J14: =IF(P14="Выходной",SUM(D14*150)*1.5,SUM(D14*150)) -> 0 | K14: =IF(OR(WEEKDAY(A14)=1,WEEKDAY(A14)=7,NOT(ISERROR(MATCH(A14,[1]Праздники!A:A,0)))),SUM(E14*225)*1.5,SUM(E14*225)) -> 0 | L14: =IF(OR(WEEKDAY(A14)=1,WEEKDAY(A14)=7,NOT(ISERROR(MATCH(A14,[1]Праздники!A:A,0)))),SUM(F14*225)*1.5,SUM(F14*225)) -> 0 | M14: =SUM(G14*15) -> 20697.75 | N14: =SUM(H14)*750 -> 0 | O14: =SUM(I14:N14) -> 20697.75 | P14: =IF(OR(WEEKDAY(A14)=1,WEEKDAY(A14)=7,NOT(ISERROR(MATCH(A14,[1]Праздники!A:A,0)))),"Выходной","Рабочий") -> Рабочий
A15: 46001 | C15: 0 | D15: 0 | G15: =IF(A15 ="",0,G14+C15+E15-D14-F14) -> 1379.85 | I15: =IF(P15="Выходной",SUM(C15*150)*1.5,SUM(C15*150)) -> 0 | J15: =IF(P15="Выходной",SUM(D15*150)*1.5,SUM(D15*150)) -> 0 | K15: =IF(OR(WEEKDAY(A15)=1,WEEKDAY(A15)=7,NOT(ISERROR(MATCH(A15,[1]Праздники!A:A,0)))),SUM(E15*225)*1.5,SUM(E15*225)) -> 0 | L15: =IF(OR(WEEKDAY(A15)=1,WEEKDAY(A15)=7,NOT(ISERROR(MATCH(A15,[1]Праздники!A:A,0)))),SUM(F15*225)*1.5,SUM(F15*225)) -> 0 | M15: =SUM(G15*15) -> 20697.75 | N15: =SUM(H15)*750 -> 0 | O15: =SUM(I15:N15) -> 20697.75 | P15: =IF(OR(WEEKDAY(A15)=1,WEEKDAY(A15)=7,NOT(ISERROR(MATCH(A15,[1]Праздники!A:A,0)))),"Выходной","Рабочий") -> Рабочий
A16: 46002 | C16: 0 | D16: 17.35 | G16: =IF(A16 ="",0,G15+C16+E16-D15-F15) -> 1379.85 | I16: =IF(P16="Выходной",SUM(C16*150)*1.5,SUM(C16*150)) -> 0 | J16: =IF(P16="Выходной",SUM(D16*150)*1.5,SUM(D16*150)) -> 2602.5 | K16: =IF(OR(WEEKDAY(A16)=1,WEEKDAY(A16)=7,NOT(ISERROR(MATCH(A16,[1]Праздники!A:A,0)))),SUM(E16*225)*1.5,SUM(E16*225)) -> 0 | L16: =IF(OR(WEEKDAY(A16)=1,WEEKDAY(A16)=7,NOT(ISERROR(MATCH(A16,[1]Праздники!A:A,0)))),SUM(F16*225)*1.5,SUM(F16*225)) -> 0 | M16: =SUM(G16*15) -> 20697.75 | N16: =SUM(H16)*750 -> 0 | O16: =SUM(I16:N16) -> 23300.25 | P16: =IF(OR(WEEKDAY(A16)=1,WEEKDAY(A16)=7,NOT(ISERROR(MATCH(A16,[1]Праздники!A:A,0)))),"Выходной","Рабочий") -> Рабочий
A17: 46003 | C17: 0 | D17: 0 | G17: =IF(A17 ="",0,G16+C17+E17-D16-F16) -> 1362.5 | I17: =IF(P17="Выходной",SUM(C17*150)*1.5,SUM(C17*150)) -> 0 | J17: =IF(P17="Выходной",SUM(D17*150)*1.5,SUM(D17*150)) -> 0 | K17: =IF(OR(WEEKDAY(A17)=1,WEEKDAY(A17)=7,NOT(ISERROR(MATCH(A17,[1]Праздники!A:A,0)))),SUM(E17*225)*1.5,SUM(E17*225)) -> 0 | L17: =IF(OR(WEEKDAY(A17)=1,WEEKDAY(A17)=7,NOT(ISERROR(MATCH(A17,[1]Праздники!A:A,0)))),SUM(F17*225)*1.5,SUM(F17*225)) -> 0 | M17: =SUM(G17*15) -> 20437.5 | N17: =SUM(H17)*750 -> 0 | O17: =SUM(I17:N17) -> 20437.5 | P17: =IF(OR(WEEKDAY(A17)=1,WEEKDAY(A17)=7,NOT(ISERROR(MATCH(A17,[1]Праздники!A:A,0)))),"Выходной","Рабочий") -> Рабочий
A18: 46004 | C18: 0 | D18: 0 | G18: =IF(A18 ="",0,G17+C18+E18-D17-F17) -> 1362.5 | I18: =IF(P18="Выходной",SUM(C18*150)*1.5,SUM(C18*150)) -> 0 | J18: =IF(P18="Выходной",SUM(D18*150)*1.5,SUM(D18*150)) -> 0 | K18: =IF(OR(WEEKDAY(A18)=1,WEEKDAY(A18)=7,NOT(ISERROR(MATCH(A18,[1]Праздники!A:A,0)))),SUM(E18*225)*1.5,SUM(E18*225)) -> 0 | L18: =IF(OR(WEEKDAY(A18)=1,WEEKDAY(A18)=7,NOT(ISERROR(MATCH(A18,[1]Праздники!A:A,0)))),SUM(F18*225)*1.5,SUM(F18*225)) -> 0 | M18: =SUM(G18*15) -> 20437.5 | N18: =SUM(H18)*750 -> 0 | O18: =SUM(I18:N18) -> 20437.5 | P18: =IF(OR(WEEKDAY(A18)=1,WEEKDAY(A18)=7,NOT(ISERROR(MATCH(A18,[1]Праздники!A:A,0)))),"Выходной","Рабочий") -> Выходной
... A36: 46022 | C36: 0 | D36: 0 | G36: =IF(A36 ="",0,G35+C36+E36-D35-F35) -> 883.225 | I36: =IF(P36="Выходной",SUM(C36*150)*1.5,SUM(C36*150)) -> 0 | J36: =IF(P36="Выходной",SUM(D36*150)*1.5,SUM(D36*150)) -> 0 | K36: =IF(OR(WEEKDAY(A36)=1,WEEKDAY(A36)=7,NOT(ISERROR(MATCH(A36,[1]Праздники!A:A,0)))),SUM(E36*225)*1.5,SUM(E36*225)) -> 0 | L36: =IF(OR(WEEKDAY(A36)=1,WEEKDAY(A36)=7,NOT(ISERROR(MATCH(A36,[1]Праздники!A:A,0)))),SUM(F36*225)*1.5,SUM(F36*225)) -> 0 | M36: =SUM(G36*15) -> 13248.375 | N36: =SUM(H36)*750 -> 0 | O36: =SUM(I36:N36) -> 13248.375 | P36: =IF(OR(WEEKDAY(A36)=1,WEEKDAY(A36)=7,NOT(ISERROR(MATCH(A36,[1]Праздники!A:A,0)))),"Выходной","Рабочий") -> Выходной
C37: =SUM(C6:C36) -> 0 | D37: =SUM(D6:D36) -> 511.07 | E37: =SUM(E6:E36) -> 0 | F37: =SUM(F6:F36) -> 0 | G37: =SUM(G6:G36) -> 39341.71 | H37: =SUM(H6:H36) -> 0 | I37: =SUM(I6:I36) -> 0 | J37: =SUM(J6:J36) -> 83457.375 | ... O37: =SUM(O6:O36) -> 673583.03
N38: С НДС; | O38: =O37*1.2 -> 808299.63

Sheet РВ Березовая Пойма
R1: Выходной | S1: Рабочий
Q2: Выгрузка | R2: =SUMIF($P$6:$P$36,R$1,$C6:$C36) -> 676.23 | S2: =SUMIF($P$6:$P$36,S$1,$C6:$C36) -> 723
A3: ="Отчет по хранению товара РВ " & TEXT(A6,"ММММ ") & YEAR(A6) & " Березовая Пойма" -> Отчет по хранению товара РВ Май 2025 Березовая Пойма | Q3: Отгрузка | R3: =SUMIF($P$6:$P$36,R$1,$D6:$D36) -> 22 | S3: =SUMIF($P$6:$P$36,S$1,$D6:$D36) -> 591
A4: дата | C4: Выгрузка кол-во тонн | D4: Загрузка кол-во тонн | E4: Выгрузка после 20:00 | F4: Загрузка после 20:00 | G4: Хранение | H4: переконсолидация (тонн) | I4: стоимость выгрузки | J4: стоимость загрузки | K4: Стоимость выгрузки после 20:00 | L4: Стоимость загрузки после 20:00 | M4: стоимость хранения | N4: стоимость переконс. | O4: итого
G5: (кол-во тонн)
A6: 45778 | C6: 0 | D6: 0 | G6: 0 | I6: =IF(P6="Выходной",SUM(C6*150)*1.5,SUM(C6*150)) -> 0 | J6: =IF(P6="Выходной",SUM(D6*150)*1.5,SUM(D6*150)) -> 0 | K6: =IF(OR(WEEKDAY(A6)=1,WEEKDAY(A6)=7,NOT(ISERROR(MATCH(A6,[1]Праздники!A:A,0)))),SUM(E6*225)*1.5,SUM(E6*225)) -> 0 | L6: =IF(OR(WEEKDAY(A6)=1,WEEKDAY(A6)=7,NOT(ISERROR(MATCH(A6,[1]Праздники!A:A,0)))),SUM(F6*225)*1.5,SUM(F6*225)) -> 0 | M6: =SUM(G6*15) -> 0 | N6: =SUM(H6)*750 -> 0 | O6: =SUM(I6:N6) -> 0 | P6: =IF(OR(WEEKDAY(A6)=1,WEEKDAY(A6)=7,NOT(ISERROR(MATCH(A6,[1]Праздники!A:A,0)))),"Выходной","Рабочий") -> Выходной
A7: 45779 | C7: 21 | D7: 0 | G7: =IF(A7 ="",0,G6+C7+E7-D6-F6) -> 21 | I7: =IF(P7="Выходной",SUM(C7*150)*1.5,SUM(C7*150)) -> 4725 | J7: =IF(P7="Выходной",SUM(D7*150)*1.5,SUM(D7*150)) -> 0 | K7: =IF(OR(WEEKDAY(A7)=1,WEEKDAY(A7)=7,NOT(ISERROR(MATCH(A7,[1]Праздники!A:A,0)))),SUM(E7*225)*1.5,SUM(E7*225)) -> 0 | L7: =IF(OR(WEEKDAY(A7)=1,WEEKDAY(A7)=7,NOT(ISERROR(MATCH(A7,[1]Праздники!A:A,0)))),SUM(F7*225)*1.5,SUM(F7*225)) -> 0 | M7: =SUM(G7*15) -> 315 | N7: =SUM(H7)*750 -> 0 | O7: =SUM(I7:N7) -> 5040 | P7: =IF(OR(WEEKDAY(A7)=1,WEEKDAY(A7)=7,NOT(ISERROR(MATCH(A7,[1]Праздники!A:A,0)))),"Выходной","Рабочий") -> Выходной
A8: 45780 | C8: 21 | D8: 0 | G8: =IF(A8 ="",0,G7+C8+E8-D7-F7) -> 42 | I8: =IF(P8="Выходной",SUM(C8*150)*1.5,SUM(C8*150)) -> 4725 | J8: =IF(P8="Выходной",SUM(D8*150)*1.5,SUM(D8*150)) -> 0 | K8: =IF(OR(WEEKDAY(A8)=1,WEEKDAY(A8)=7,NOT(ISERROR(MATCH(A8,[1]Праздники!A:A,0)))),SUM(E8*225)*1.5,SUM(E8*225)) -> 0 | L8: =IF(OR(WEEKDAY(A8)=1,WEEKDAY(A8)=7,NOT(ISERROR(MATCH(A8,[1]Праздники!A:A,0)))),SUM(F8*225)*1.5,SUM(F8*225)) -> 0 | M8: =SUM(G8*15) -> 630 | N8: =SUM(H8)*750 -> 0 | O8: =SUM(I8:N8) -> 5355 | P8: =IF(OR(WEEKDAY(A8)=1,WEEKDAY(A8)=7,NOT(ISERROR(MATCH(A8,[1]Праздники!A:A,0)))),"Выходной","Рабочий") -> Выходной
A9: 45781 | C9: 325 | D9: 0 | G9: =IF(A9 ="",0,G8+C9+E9-D8-F8) -> 367 | I9: =IF(P9="Выходной",SUM(C9*150)*1.5,SUM(C9*150)) -> 73125 | J9: =IF(P9="Выходной",SUM(D9*150)*1.5,SUM(D9*150)) -> 0 | K9: =IF(OR(WEEKDAY(A9)=1,WEEKDAY(A9)=7,NOT(ISERROR(MATCH(A9,[1]Праздники!A:A,0)))),SUM(E9*225)*1.5,SUM(E9*225)) -> 0 | L9: =IF(OR(WEEKDAY(A9)=1,WEEKDAY(A9)=7,NOT(ISERROR(MATCH(A9,[1]Праздники!A:A,0)))),SUM(F9*225)*1.5,SUM(F9*225)) -> 0 | M9: =SUM(G9*15) -> 5505 | N9: =SUM(H9)*750 -> 0 | O9: =SUM(I9:N9) -> 78630 | P9: =IF(OR(WEEKDAY(A9)=1,WEEKDAY(A9)=7,NOT(ISERROR(MATCH(A9,[1]Праздники!A:A,0)))),"Выходной","Рабочий") -> Выходной
A10: 45782 | C10: 196 | D10: 0 | G10: =IF(A10 ="",0,G9+C10+E10-D9-F9) -> 563 | I10: =IF(P10="Выходной",SUM(C10*150)*1.5,SUM(C10*150)) -> 29400 | J10: =IF(P10="Выходной",SUM(D10*150)*1.5,SUM(D10*150)) -> 0 | K10: =IF(OR(WEEKDAY(A10)=1,WEEKDAY(A10)=7,NOT(ISERROR(MATCH(A10,[1]Праздники!A:A,0)))),SUM(E10*225)*1.5,SUM(E10*225)) -> 0 | L10: =IF(OR(WEEKDAY(A10)=1,WEEKDAY(A10)=7,NOT(ISERROR(MATCH(A10,[1]Праздники!A:A,0)))),SUM(F10*225)*1.5,SUM(F10*225)) -> 0 | M10: =SUM(G10*15) -> 8445 | N10: =SUM(H10)*750 -> 0 | O10: =SUM(I10:N10) -> 37845 | P10: =IF(OR(WEEKDAY(A10)=1,WEEKDAY(A10)=7,NOT(ISERROR(MATCH(A10,[1]Праздники!A:A,0)))),"Выходной","Рабочий") -> Рабочий
A11: 45783 | C11: 66 | D11: 0 | G11: =IF(A11 ="",0,G10+C11+E11-D10-F10) -> 629 | I11: =IF(P11="Выходной",SUM(C11*150)*1.5,SUM(C11*150)) -> 9900 | J11: =IF(P11="Выходной",SUM(D11*150)*1.5,SUM(D11*150)) -> 0 | K11: =IF(OR(WEEKDAY(A11)=1,WEEKDAY(A11)=7,NOT(ISERROR(MATCH(A11,[1]Праздники!A:A,0)))),SUM(E11*225)*1.5,SUM(E11*225)) -> 0 | L11: =IF(OR(WEEKDAY(A11)=1,WEEKDAY(A11)=7,NOT(ISERROR(MATCH(A11,[1]Праздники!A:A,0)))),SUM(F11*225)*1.5,SUM(F11*225)) -> 0 | M11: =SUM(G11*15) -> 9435 | N11: =SUM(H11)*750 -> 0 | O11: =SUM(I11:N11) -> 19335 | P11: =IF(OR(WEEKDAY(A11)=1,WEEKDAY(A11)=7,NOT(ISERROR(MATCH(A11,[1]Праздники!A:A,0)))),"Выходной","Рабочий") -> Рабочий
A12: 45784 | C12: 21 | D12: 0 | G12: =IF(A12 ="",0,G11+C12+E12-D11-F11) -> 650 | I12: =IF(P12="Выходной",SUM(C12*150)*1.5,SUM(C12*150)) -> 3150 | J12: =IF(P12="Выходной",SUM(D12*150)*1.5,SUM(D12*150)) -> 0 | K12: =IF(OR(WEEKDAY(A12)=1,WEEKDAY(A12)=7,NOT(ISERROR(MATCH(A12,[1]Праздники!A:A,0)))),SUM(E12*225)*1.5,SUM(E12*225)) -> 0 | L12: =IF(OR(WEEKDAY(A12)=1,WEEKDAY(A12)=7,NOT(ISERROR(MATCH(A12,[1]Праздники!A:A,0)))),SUM(F12*225)*1.5,SUM(F12*225)) -> 0 | M12: =SUM(G12*15) -> 9750 | N12: =SUM(H12)*750 -> 0 | O12: =SUM(I12:N12) -> 12900 | P12: =IF(OR(WEEKDAY(A12)=1,WEEKDAY(A12)=7,NOT(ISERROR(MATCH(A12,[1]Праздники!A:A,0)))),"Выходной","Рабочий") -> Рабочий
A13: 45785 | C13: 0 | D13: 0 | G13: =IF(A13 ="",0,G12+C13+E13-D12-F12) -> 650 | I13: =IF(P13="Выходной",SUM(C13*150)*1.5,SUM(C13*150)) -> 0 | J13: =IF(P13="Выходной",SUM(D13*150)*1.5,SUM(D13*150)) -> 0 | K13: =IF(OR(WEEKDAY(A13)=1,WEEKDAY(A13)=7,NOT(ISERROR(MATCH(A13,[1]Праздники!A:A,0)))),SUM(E13*225)*1.5,SUM(E13*225)) -> 0 | L13: =IF(OR(WEEKDAY(A13)=1,WEEKDAY(A13)=7,NOT(ISERROR(MATCH(A13,[1]Праздники!A:A,0)))),SUM(F13*225)*1.5,SUM(F13*225)) -> 0 | M13: =SUM(G13*15) -> 9750 | N13: =SUM(H13)*750 -> 0 | O13: =SUM(I13:N13) -> 9750 | P13: =IF(OR(WEEKDAY(A13)=1,WEEKDAY(A13)=7,NOT(ISERROR(MATCH(A13,[1]Праздники!A:A,0)))),"Выходной","Рабочий") -> Выходной
A14: 45786 | C14: 0 | D14: 0 | G14: =IF(A14 ="",0,G13+C14+E14-D13-F13) -> 650 | I14: =IF(P14="Выходной",SUM(C14*150)*1.5,SUM(C14*150)) -> 0 | J14: =IF(P14="Выходной",SUM(D14*150)*1.5,SUM(D14*150)) -> 0 | K14: =IF(OR(WEEKDAY(A14)=1,WEEKDAY(A14)=7,NOT(ISERROR(MATCH(A14,[1]Праздники!A:A,0)))),SUM(E14*225)*1.5,SUM(E14*225)) -> 0 | L14: =IF(OR(WEEKDAY(A14)=1,WEEKDAY(A14)=7,NOT(ISERROR(MATCH(A14,[1]Праздники!A:A,0)))),SUM(F14*225)*1.5,SUM(F14*225)) -> 0 | M14: =SUM(G14*15) -> 9750 | N14: =SUM(H14)*750 -> 0 | O14: =SUM(I14:N14) -> 9750 | P14: =IF(OR(WEEKDAY(A14)=1,WEEKDAY(A14)=7,NOT(ISERROR(MATCH(A14,[1]Праздники!A:A,0)))),"Выходной","Рабочий") -> Выходной
A15: 45787 | C15: 89 | D15: 0 | G15: =IF(A15 ="",0,G14+C15+E15-D14-F14) -> 739 | I15: =IF(P15="Выходной",SUM(C15*150)*1.5,SUM(C15*150)) -> 20025 | J15: =IF(P15="Выходной",SUM(D15*150)*1.5,SUM(D15*150)) -> 0 | K15: =IF(OR(WEEKDAY(A15)=1,WEEKDAY(A15)=7,NOT(ISERROR(MATCH(A15,[1]Праздники!A:A,0)))),SUM(E15*225)*1.5,SUM(E15*225)) -> 0 | L15: =IF(OR(WEEKDAY(A15)=1,WEEKDAY(A15)=7,NOT(ISERROR(MATCH(A15,[1]Праздники!A:A,0)))),SUM(F15*225)*1.5,SUM(F15*225)) -> 0 | M15: =SUM(G15*15) -> 11085 | N15: =SUM(H15)*750 -> 0 | O15: =SUM(I15:N15) -> 31110 | P15: =IF(OR(WEEKDAY(A15)=1,WEEKDAY(A15)=7,NOT(ISERROR(MATCH(A15,[1]Праздники!A:A,0)))),"Выходной","Рабочий") -> Выходной
A16: 45788 | C16: 0 | D16: 0 | G16: =IF(A16 ="",0,G15+C16+E16-D15-F15) -> 739 | I16: =IF(P16="Выходной",SUM(C16*150)*1.5,SUM(C16*150)) -> 0 | J16: =IF(P16="Выходной",SUM(D16*150)*1.5,SUM(D16*150)) -> 0 | K16: =IF(OR(WEEKDAY(A16)=1,WEEKDAY(A16)=7,NOT(ISERROR(MATCH(A16,[1]Праздники!A:A,0)))),SUM(E16*225)*1.5,SUM(E16*225)) -> 0 | L16: =IF(OR(WEEKDAY(A16)=1,WEEKDAY(A16)=7,NOT(ISERROR(MATCH(A16,[1]Праздники!A:A,0)))),SUM(F16*225)*1.5,SUM(F16*225)) -> 0 | M16: =SUM(G16*15) -> 11085 | N16: =SUM(H16)*750 -> 0 | O16: =SUM(I16:N16) -> 11085 | P16: =IF(OR(WEEKDAY(A16)=1,WEEKDAY(A16)=7,NOT(ISERROR(MATCH(A16,[1]Праздники!A:A,0)))),"Выходной","Рабочий") -> Выходной
A17: 45789 | C17: 0 | D17: 0 | G17: =IF(A17 ="",0,G16+C17+E17-D16-F16) -> 739 | I17: =IF(P17="Выходной",SUM(C17*150)*1.5,SUM(C17*150)) -> 0 | J17: =IF(P17="Выходной",SUM(D17*150)*1.5,SUM(D17*150)) -> 0 | K17: =IF(OR(WEEKDAY(A17)=1,WEEKDAY(A17)=7,NOT(ISERROR(MATCH(A17,[1]Праздники!A:A,0)))),SUM(E17*225)*1.5,SUM(E17*225)) -> 0 | L17: =IF(OR(WEEKDAY(A17)=1,WEEKDAY(A17)=7,NOT(ISERROR(MATCH(A17,[1]Праздники!A:A,0)))),SUM(F17*225)*1.5,SUM(F17*225)) -> 0 | M17: =SUM(G17*15) -> 11085 | N17: =SUM(H17)*750 -> 0 | O17: =SUM(I17:N17) -> 11085 | P17: =IF(OR(WEEKDAY(A17)=1,WEEKDAY(A17)=7,NOT(ISERROR(MATCH(A17,[1]Праздники!A:A,0)))),"Выходной","Рабочий") -> Рабочий
A18: 45790 | C18: 0 | D18: 0 | G18: =IF(A18 ="",0,G17+C18+E18-D17-F17) -> 739 | I18: =IF(P18="Выходной",SUM(C18*150)*1.5,SUM(C18*150)) -> 0 | J18: =IF(P18="Выходной",SUM(D18*150)*1.5,SUM(D18*150)) -> 0 | K18: =IF(OR(WEEKDAY(A18)=1,WEEKDAY(A18)=7,NOT(ISERROR(MATCH(A18,[1]Праздники!A:A,0)))),SUM(E18*225)*1.5,SUM(E18*225)) -> 0 | L18: =IF(OR(WEEKDAY(A18)=1,WEEKDAY(A18)=7,NOT(ISERROR(MATCH(A18,[1]Праздники!A:A,0)))),SUM(F18*225)*1.5,SUM(F18*225)) -> 0 | M18: =SUM(G18*15) -> 11085 | N18: =SUM(H18)*750 -> 0 | O18: =SUM(I18:N18) -> 11085 | P18: =IF(OR(WEEKDAY(A18)=1,WEEKDAY(A18)=7,NOT(ISERROR(MATCH(A18,[1]Праздники!A:A,0)))),"Выходной","Рабочий") -> Рабочий
... A36: 45808 | C36: 220.23 | D36: 22 | G36: =IF(A36 ="",0,G35+C36+E36-D35-F35) -> 808.23 | I36: =IF(P36="Выходной",SUM(C36*150)*1.5,SUM(C36*150)) -> 49551.75 | J36: =IF(P36="Выходной",SUM(D36*150)*1.5,SUM(D36*150)) -> 4950 | K36: =IF(OR(WEEKDAY(A36)=1,WEEKDAY(A36)=7,NOT(ISERROR(MATCH(A36,[1]Праздники!A:A,0)))),SUM(E36*225)*1.5,SUM(E36*225)) -> 0 | L36: =IF(OR(WEEKDAY(A36)=1,WEEKDAY(A36)=7,NOT(ISERROR(MATCH(A36,[1]Праздники!A:A,0)))),SUM(F36*225)*1.5,SUM(F36*225)) -> 0 | M36: =SUM(G36*15) -> 12123.45 | N36: =SUM(H36)*750 -> 0 | O36: =SUM(I36:N36) -> 66625.2 | P36: =IF(OR(WEEKDAY(A36)=1,WEEKDAY(A36)=7,NOT(ISERROR(MATCH(A36,[1]Праздники!A:A,0)))),"Выходной","Рабочий") -> Выходной
C37: =SUM(C6:C36) -> 1399.23 | D37: =SUM(D6:D36) -> 613 | E37: =SUM(E6:E36) -> 0 | F37: =SUM(F6:F36) -> 0 | G37: =SUM(G6:G36) -> 22165.23 | H37: =SUM(H6:H36) -> 0 | I37: =SUM(I6:I36) -> 260601.75 | J37: =SUM(J6:J36) -> 93600 | ... O37: =SUM(O6:O36) -> 686680.2
N38: С НДС; | O38: =O37*1.2 -> 824016.24

Sheet РВ Новикова-Прибоя
R1: Выходной | S1: Рабочий
Q2: Выгрузка | R2: =SUMIF($P$6:$P$36,R$1,$C6:$C36) -> 0 | S2: =SUMIF($P$6:$P$36,S$1,$C6:$C36) -> 0
A3: ="Отчет по хранению товара РВ " & TEXT(A6,"ММММ ") & YEAR(A6) & " Новикова" -> Отчет по хранению товара РВ Май 2025 Новикова | Q3: Отгрузка | R3: =SUMIF($P$6:$P$36,R$1,$D6:$D36) -> 60.225 | S3: =SUMIF($P$6:$P$36,S$1,$D6:$D36) -> 48.25
A4: дата | C4: Выгрузка кол-во тонн | D4: Загрузка кол-во тонн | E4: Выгрузка после 20:00 | F4: Загрузка после 20:00 | G4: Хранение | H4: переконсолидация (тонн) | I4: стоимость выгрузки | J4: стоимость загрузки | K4: Стоимость выгрузки после 20:00 | L4: Стоимость загрузки после 20:00 | M4: стоимость хранения | N4: стоимость переконс. | O4: итого
G5: (кол-во тонн)
A6: 45778 | C6: 0 | D6: 0 | G6: 299.145 | I6: =IF(P6="Выходной",SUM(C6*150)*1.5,SUM(C6*150)) -> 0 | J6: =IF(P6="Выходной",SUM(D6*150)*1.5,SUM(D6*150)) -> 0 | K6: =IF(OR(WEEKDAY(A6)=1,WEEKDAY(A6)=7,NOT(ISERROR(MATCH(A6,[1]Праздники!A:A,0)))),SUM(E6*225)*1.5,SUM(E6*225)) -> 0 | L6: =IF(OR(WEEKDAY(A6)=1,WEEKDAY(A6)=7,NOT(ISERROR(MATCH(A6,[1]Праздники!A:A,0)))),SUM(F6*225)*1.5,SUM(F6*225)) -> 0 | M6: =SUM(G6*15) -> 4487.175 | N6: =SUM(H6)*750 -> 0 | O6: =SUM(I6:N6) -> 4487.175 | P6: =IF(OR(WEEKDAY(A6)=1,WEEKDAY(A6)=7,NOT(ISERROR(MATCH(A6,[1]Праздники!A:A,0)))),"Выходной","Рабочий") -> Выходной
A7: 45779 | C7: 0 | D7: 0 | G7: =IF(A7 ="",0,G6+C7+E7-D6-F6) -> 299.145 | I7: =IF(P7="Выходной",SUM(C7*150)*1.5,SUM(C7*150)) -> 0 | J7: =IF(P7="Выходной",SUM(D7*150)*1.5,SUM(D7*150)) -> 0 | K7: =IF(OR(WEEKDAY(A7)=1,WEEKDAY(A7)=7,NOT(ISERROR(MATCH(A7,[1]Праздники!A:A,0)))),SUM(E7*225)*1.5,SUM(E7*225)) -> 0 | L7: =IF(OR(WEEKDAY(A7)=1,WEEKDAY(A7)=7,NOT(ISERROR(MATCH(A7,[1]Праздники!A:A,0)))),SUM(F7*225)*1.5,SUM(F7*225)) -> 0 | M7: =SUM(G7*15) -> 4487.175 | N7: =SUM(H7)*750 -> 0 | O7: =SUM(I7:N7) -> 4487.175 | P7: =IF(OR(WEEKDAY(A7)=1,WEEKDAY(A7)=7,NOT(ISERROR(MATCH(A7,[1]Праздники!A:A,0)))),"Выходной","Рабочий") -> Выходной
A8: 45780 | C8: 0 | D8: 0 | G8: =IF(A8 ="",0,G7+C8+E8-D7-F7) -> 299.145 | I8: =IF(P8="Выходной",SUM(C8*150)*1.5,SUM(C8*150)) -> 0 | J8: =IF(P8="Выходной",SUM(D8*150)*1.5,SUM(D8*150)) -> 0 | K8: =IF(OR(WEEKDAY(A8)=1,WEEKDAY(A8)=7,NOT(ISERROR(MATCH(A8,[1]Праздники!A:A,0)))),SUM(E8*225)*1.5,SUM(E8*225)) -> 0 | L8: =IF(OR(WEEKDAY(A8)=1,WEEKDAY(A8)=7,NOT(ISERROR(MATCH(A8,[1]Праздники!A:A,0)))),SUM(F8*225)*1.5,SUM(F8*225)) -> 0 | M8: =SUM(G8*15) -> 4487.175 | N8: =SUM(H8)*750 -> 0 | O8: =SUM(I8:N8) -> 4487.175 | P8: =IF(OR(WEEKDAY(A8)=1,WEEKDAY(A8)=7,NOT(ISERROR(MATCH(A8,[1]Праздники!A:A,0)))),"Выходной","Рабочий") -> Выходной
A9: 45781 | C9: 0 | D9: 0 | G9: =IF(A9 ="",0,G8+C9+E9-D8-F8) -> 299.145 | I9: =IF(P9="Выходной",SUM(C9*150)*1.5,SUM(C9*150)) -> 0 | J9: =IF(P9="Выходной",SUM(D9*150)*1.5,SUM(D9*150)) -> 0 | K9: =IF(OR(WEEKDAY(A9)=1,WEEKDAY(A9)=7,NOT(ISERROR(MATCH(A9,[1]Праздники!A:A,0)))),SUM(E9*225)*1.5,SUM(E9*225)) -> 0 | L9: =IF(OR(WEEKDAY(A9)=1,WEEKDAY(A9)=7,NOT(ISERROR(MATCH(A9,[1]Праздники!A:A,0)))),SUM(F9*225)*1.5,SUM(F9*225)) -> 0 | M9: =SUM(G9*15) -> 4487.175 | N9: =SUM(H9)*750 -> 0 | O9: =SUM(I9:N9) -> 4487.175 | P9: =IF(OR(WEEKDAY(A9)=1,WEEKDAY(A9)=7,NOT(ISERROR(MATCH(A9,[1]Праздники!A:A,0)))),"Выходной","Рабочий") -> Выходной
A10: 45782 | C10: 0 | D10: 1.375 | G10: =IF(A10 ="",0,G9+C10+E10-D9-F9) -> 299.145 | I10: =IF(P10="Выходной",SUM(C10*150)*1.5,SUM(C10*150)) -> 0 | J10: =IF(P10="Выходной",SUM(D10*150)*1.5,SUM(D10*150)) -> 206.25 | K10: =IF(OR(WEEKDAY(A10)=1,WEEKDAY(A10)=7,NOT(ISERROR(MATCH(A10,[1]Праздники!A:A,0)))),SUM(E10*225)*1.5,SUM(E10*225)) -> 0 | L10: =IF(OR(WEEKDAY(A10)=1,WEEKDAY(A10)=7,NOT(ISERROR(MATCH(A10,[1]Праздники!A:A,0)))),SUM(F10*225)*1.5,SUM(F10*225)) -> 0 | M10: =SUM(G10*15) -> 4487.175 | N10: =SUM(H10)*750 -> 0 | O10: =SUM(I10:N10) -> 4693.425 | P10: =IF(OR(WEEKDAY(A10)=1,WEEKDAY(A10)=7,NOT(ISERROR(MATCH(A10,[1]Праздники!A:A,0)))),"Выходной","Рабочий") -> Рабочий
A11: 45783 | C11: 0 | D11: 0 | G11: =IF(A11 ="",0,G10+C11+E11-D10-F10) -> 297.77 | I11: =IF(P11="Выходной",SUM(C11*150)*1.5,SUM(C11*150)) -> 0 | J11: =IF(P11="Выходной",SUM(D11*150)*1.5,SUM(D11*150)) -> 0 | K11: =IF(OR(WEEKDAY(A11)=1,WEEKDAY(A11)=7,NOT(ISERROR(MATCH(A11,[1]Праздники!A:A,0)))),SUM(E11*225)*1.5,SUM(E11*225)) -> 0 | L11: =IF(OR(WEEKDAY(A11)=1,WEEKDAY(A11)=7,NOT(ISERROR(MATCH(A11,[1]Праздники!A:A,0)))),SUM(F11*225)*1.5,SUM(F11*225)) -> 0 | M11: =SUM(G11*15) -> 4466.55 | N11: =SUM(H11)*750 -> 0 | O11: =SUM(I11:N11) -> 4466.55 | P11: =IF(OR(WEEKDAY(A11)=1,WEEKDAY(A11)=7,NOT(ISERROR(MATCH(A11,[1]Праздники!A:A,0)))),"Выходной","Рабочий") -> Рабочий
A12: 45784 | C12: 0 | D12: 0 | G12: =IF(A12 ="",0,G11+C12+E12-D11-F11) -> 297.77 | I12: =IF(P12="Выходной",SUM(C12*150)*1.5,SUM(C12*150)) -> 0 | J12: =IF(P12="Выходной",SUM(D12*150)*1.5,SUM(D12*150)) -> 0 | K12: =IF(OR(WEEKDAY(A12)=1,WEEKDAY(A12)=7,NOT(ISERROR(MATCH(A12,[1]Праздники!A:A,0)))),SUM(E12*225)*1.5,SUM(E12*225)) -> 0 | L12: =IF(OR(WEEKDAY(A12)=1,WEEKDAY(A12)=7,NOT(ISERROR(MATCH(A12,[1]Праздники!A:A,0)))),SUM(F12*225)*1.5,SUM(F12*225)) -> 0 | M12: =SUM(G12*15) -> 4466.55 | N12: =SUM(H12)*750 -> 0 | O12: =SUM(I12:N12) -> 4466.55 | P12: =IF(OR(WEEKDAY(A12)=1,WEEKDAY(A12)=7,NOT(ISERROR(MATCH(A12,[1]Праздники!A:A,0)))),"Выходной","Рабочий") -> Рабочий
A13: 45785 | C13: 0 | D13: 8.125 | G13: =IF(A13 ="",0,G12+C13+E13-D12-F12) -> 297.77 | I13: =IF(P13="Выходной",SUM(C13*150)*1.5,SUM(C13*150)) -> 0 | J13: =IF(P13="Выходной",SUM(D13*150)*1.5,SUM(D13*150)) -> 1828.125 | K13: =IF(OR(WEEKDAY(A13)=1,WEEKDAY(A13)=7,NOT(ISERROR(MATCH(A13,[1]Праздники!A:A,0)))),SUM(E13*225)*1.5,SUM(E13*225)) -> 0 | L13: =IF(OR(WEEKDAY(A13)=1,WEEKDAY(A13)=7,NOT(ISERROR(MATCH(A13,[1]Праздники!A:A,0)))),SUM(F13*225)*1.5,SUM(F13*225)) -> 0 | M13: =SUM(G13*15) -> 4466.55 | N13: =SUM(H13)*750 -> 0 | O13: =SUM(I13:N13) -> 6294.675 | P13: =IF(OR(WEEKDAY(A13)=1,WEEKDAY(A13)=7,NOT(ISERROR(MATCH(A13,[1]Праздники!A:A,0)))),"Выходной","Рабочий") -> Выходной
A14: 45786 | C14: 0 | D14: 0 | G14: =IF(A14 ="",0,G13+C14+E14-D13-F13) -> 289.645 | I14: =IF(P14="Выходной",SUM(C14*150)*1.5,SUM(C14*150)) -> 0 | J14: =IF(P14="Выходной",SUM(D14*150)*1.5,SUM(D14*150)) -> 0 | K14: =IF(OR(WEEKDAY(A14)=1,WEEKDAY(A14)=7,NOT(ISERROR(MATCH(A14,[1]Праздники!A:A,0)))),SUM(E14*225)*1.5,SUM(E14*225)) -> 0 | L14: =IF(OR(WEEKDAY(A14)=1,WEEKDAY(A14)=7,NOT(ISERROR(MATCH(A14,[1]Праздники!A:A,0)))),SUM(F14*225)*1.5,SUM(F14*225)) -> 0 | M14: =SUM(G14*15) -> 4344.675 | N14: =SUM(H14)*750 -> 0 | O14: =SUM(I14:N14) -> 4344.675 | P14: =IF(OR(WEEKDAY(A14)=1,WEEKDAY(A14)=7,NOT(ISERROR(MATCH(A14,[1]Праздники!A:A,0)))),"Выходной","Рабочий") -> Выходной
A15: 45787 | C15: 0 | D15: 1.375 | G15: =IF(A15 ="",0,G14+C15+E15-D14-F14) -> 289.645 | I15: =IF(P15="Выходной",SUM(C15*150)*1.5,SUM(C15*150)) -> 0 | J15: =IF(P15="Выходной",SUM(D15*150)*1.5,SUM(D15*150)) -> 309.375 | K15: =IF(OR(WEEKDAY(A15)=1,WEEKDAY(A15)=7,NOT(ISERROR(MATCH(A15,[1]Праздники!A:A,0)))),SUM(E15*225)*1.5,SUM(E15*225)) -> 0 | L15: =IF(OR(WEEKDAY(A15)=1,WEEKDAY(A15)=7,NOT(ISERROR(MATCH(A15,[1]Праздники!A:A,0)))),SUM(F15*225)*1.5,SUM(F15*225)) -> 0 | M15: =SUM(G15*15) -> 4344.675 | N15: =SUM(H15)*750 -> 0 | O15: =SUM(I15:N15) -> 4654.05 | P15: =IF(OR(WEEKDAY(A15)=1,WEEKDAY(A15)=7,NOT(ISERROR(MATCH(A15,[1]Праздники!A:A,0)))),"Выходной","Рабочий") -> Выходной
A16: 45788 | C16: 0 | D16: 0 | G16: =IF(A16 ="",0,G15+C16+E16-D15-F15) -> 288.27 | I16: =IF(P16="Выходной",SUM(C16*150)*1.5,SUM(C16*150)) -> 0 | J16: =IF(P16="Выходной",SUM(D16*150)*1.5,SUM(D16*150)) -> 0 | K16: =IF(OR(WEEKDAY(A16)=1,WEEKDAY(A16)=7,NOT(ISERROR(MATCH(A16,[1]Праздники!A:A,0)))),SUM(E16*225)*1.5,SUM(E16*225)) -> 0 | L16: =IF(OR(WEEKDAY(A16)=1,WEEKDAY(A16)=7,NOT(ISERROR(MATCH(A16,[1]Праздники!A:A,0)))),SUM(F16*225)*1.5,SUM(F16*225)) -> 0 | M16: =SUM(G16*15) -> 4324.05 | N16: =SUM(H16)*750 -> 0 | O16: =SUM(I16:N16) -> 4324.05 | P16: =IF(OR(WEEKDAY(A16)=1,WEEKDAY(A16)=7,NOT(ISERROR(MATCH(A16,[1]Праздники!A:A,0)))),"Выходной","Рабочий") -> Выходной
A17: 45789 | C17: 0 | D17: 0 | G17: =IF(A17 ="",0,G16+C17+E17-D16-F16) -> 288.27 | I17: =IF(P17="Выходной",SUM(C17*150)*1.5,SUM(C17*150)) -> 0 | J17: =IF(P17="Выходной",SUM(D17*150)*1.5,SUM(D17*150)) -> 0 | K17: =IF(OR(WEEKDAY(A17)=1,WEEKDAY(A17)=7,NOT(ISERROR(MATCH(A17,[1]Праздники!A:A,0)))),SUM(E17*225)*1.5,SUM(E17*225)) -> 0 | L17: =IF(OR(WEEKDAY(A17)=1,WEEKDAY(A17)=7,NOT(ISERROR(MATCH(A17,[1]Праздники!A:A,0)))),SUM(F17*225)*1.5,SUM(F17*225)) -> 0 | M17: =SUM(G17*15) -> 4324.05 | N17: =SUM(H17)*750 -> 0 | O17: =SUM(I17:N17) -> 4324.05 | P17: =IF(OR(WEEKDAY(A17)=1,WEEKDAY(A17)=7,NOT(ISERROR(MATCH(A17,[1]Праздники!A:A,0)))),"Выходной","Рабочий") -> Рабочий
A18: 45790 | C18: 0 | D18: 0 | G18: =IF(A18 ="",0,G17+C18+E18-D17-F17) -> 288.27 | I18: =IF(P18="Выходной",SUM(C18*150)*1.5,SUM(C18*150)) -> 0 | J18: =IF(P18="Выходной",SUM(D18*150)*1.5,SUM(D18*150)) -> 0 | K18: =IF(OR(WEEKDAY(A18)=1,WEEKDAY(A18)=7,NOT(ISERROR(MATCH(A18,[1]Праздники!A:A,0)))),SUM(E18*225)*1.5,SUM(E18*225)) -> 0 | L18: =IF(OR(WEEKDAY(A18)=1,WEEKDAY(A18)=7,NOT(ISERROR(MATCH(A18,[1]Праздники!A:A,0)))),SUM(F18*225)*1.5,SUM(F18*225)) -> 0 | M18: =SUM(G18*15) -> 4324.05 | N18: =SUM(H18)*750 -> 0 | O18: =SUM(I18:N18) -> 4324.05 | P18: =IF(OR(WEEKDAY(A18)=1,WEEKDAY(A18)=7,NOT(ISERROR(MATCH(A18,[1]Праздники!A:A,0)))),"Выходной","Рабочий") -> Рабочий
... A36: 45808 | C36: 0 | D36: 0 | G36: =IF(A36 ="",0,G35+C36+E36-D35-F35) -> 190.67 | I36: =IF(P36="Выходной",SUM(C36*150)*1.5,SUM(C36*150)) -> 0 | J36: =IF(P36="Выходной",SUM(D36*150)*1.5,SUM(D36*150)) -> 0 | K36: =IF(OR(WEEKDAY(A36)=1,WEEKDAY(A36)=7,NOT(ISERROR(MATCH(A36,[1]Праздники!A:A,0)))),SUM(E36*225)*1.5,SUM(E36*225)) -> 0 | L36: =IF(OR(WEEKDAY(A36)=1,WEEKDAY(A36)=7,NOT(ISERROR(MATCH(A36,[1]Праздники!A:A,0)))),SUM(F36*225)*1.5,SUM(F36*225)) -> 0 | M36: =SUM(G36*15) -> 2860.05 | N36: =SUM(H36)*750 -> 0 | O36: =SUM(I36:N36) -> 2860.05 | P36: =IF(OR(WEEKDAY(A36)=1,WEEKDAY(A36)=7,NOT(ISERROR(MATCH(A36,[1]Праздники!A:A,0)))),"Выходной","Рабочий") -> Выходной
C37: =SUM(C6:C36) -> 0 | D37: =SUM(D6:D36) -> 108.475 | E37: =SUM(E6:E36) -> 0 | F37: =SUM(F6:F36) -> 0 | G37: =SUM(G6:G36) -> 8346.345 | H37: =SUM(H6:H36) -> 0 | I37: =SUM(I6:I36) -> 0 | J37: =SUM(J6:J36) -> 20788.125 | ... O37: =SUM(O6:O36) -> 145983.3
N38: С НДС; | O38: =O37*1.2 -> 175179.96

Sheet Нижнекамск экспорт
A3: =IF(DAY(TODAY())>27,"Акт № от " & TEXT(TODAY(),"ДД ММММ ГГГГ"),"Акт № от " & TEXT(TODAY()-DAY(TODAY()),"ДД ММММ ГГГГ")) -> Акт № от 31 Декабрь 2025
A4: =IF(DAY(TODAY()) > 27, "выполненных работ (оказанных услуг) за " & TEXT(TODAY(),"ММММ ГГГГ"),"выполненных работ (оказанных услуг) за " & TEXT(TODAY()-DAY(TODAY()),"ММММ ГГГГ")) -> выполненных работ (оказанных услуг) за Декабрь 2025
A5: по Договору хранения № СХ.47103 от «10» апреля 2025 г.
A7: =IF(DAY(TODAY()) > 27,"Во исполнение Договора в период с " & TEXT(TODAY()-DAY(TODAY()-DAY(TODAY())),"ДД ММММ ГГГГ") & " г. По " & TEXT(TODAY(),"ДД ММММ ГГГГ") & " г. ХРАНИТЕЛЬ оказал ПОКЛАЖЕДАТЕЛЮ следующие услуги (работы):"," Во исполнение Договора в период с " & TEXT(TODAY()-DAY(TODAY())-DAY(TODAY()-DAY(TODAY()))+1,"ДД ММММ ГГГГ") & " г. По " & TEXT(TODAY()-DAY(TODAY()),"ДД ММММ ГГГГ") & " г. ХРАНИТЕЛЬ оказал ПОКЛАЖЕДАТЕЛЮ следующие услуги (работы):") -> Во исполнение Договора в период с 01 Декабрь 2025 г. По 31 Декабрь 2025 г. ХРАНИТЕЛЬ оказал ПОКЛАЖЕДАТЕЛЮ следующие услуги (работы):
A9: № | B9: Наименование услуг (работ) | C9: Ед. изм. | D9: Количество | E9: Цена | F9: Сумма без НДС | G9: Сумма с НДС
