Workbook

Sheet Лист1

Sheet Биаксплен Новосибирск
A1: =T37 -> 138348
A2: ="Отчет по хранению товара за " & TEXT(B5,"ММММ ГГГГ") -> Отчет по хранению товара за Июнь 2026
A3: № | B3: дата | D3: Выгрузка кол-во | E3: Загрузка кол-во | F3: Хранение | G3: Резервирование 70 т | H3: Мин. Суточный резерв 0 т | I3: переконсолидация (тонн) | J3: Паллетирование | K3: Ночная загруска выгрузка | L3: стоимость ночной загруски | M3: стоимость выгрузки | N3: стоимость загрузки | O3: стоимость хранения | P3: Стоимость резервирования | Q3: Стоимость мин.суточной бработки | R3: стоимость переконс. | S3: Стоимость паллетирования | T3: итого
A5: 1 | B5: 46174 | F5: 0 | G5: =IF(OR(B5="",NOT(ISERROR(SEARCH("KPI",$A$2))),NOT(ISERROR(SEARCH("Полиом",$A$2)))),0,IF(70-F5<=0,0,70-F5)) -> 70 | L5: =SUM(K5*240) -> 0 | M5: =SUM(D5*120) -> 0 | N5: =SUM(E5*120) -> 0 | O5: =SUM(F5*54) -> 0 | P5: =SUM(G5*54) -> 3780 | Q5: =SUM(H5*120) -> 0 | R5: =SUM(I5*1000) -> 0 | S5: =SUM(J5*140) -> 0 | T5: =SUM(L5:S5) -> 3780
A6: 2 | B6: 46175 | F6: =F5-E6+D6 -> 0 | G6: =IF(OR(B6="",NOT(ISERROR(SEARCH("KPI",$A$2))),NOT(ISERROR(SEARCH("Полиом",$A$2)))),0,IF(70-F6<=0,0,70-F6)) -> 70 | L6: =SUM(K6*240) -> 0 | M6: =SUM(D6*120) -> 0 | N6: =SUM(E6*120) -> 0 | O6: =SUM(F6*54) -> 0 | P6: =SUM(G6*54) -> 3780 | Q6: =SUM(H6*120) -> 0 | R6: =SUM(I6*1000) -> 0 | S6: =SUM(J6*140) -> 0 | T6: =SUM(L6:S6) -> 3780
A7: 3 | B7: 46176 | F7: =F6-E7+D7 -> 0 | G7: =IF(OR(B7="",NOT(ISERROR(SEARCH("KPI",$A$2))),NOT(ISERROR(SEARCH("Полиом",$A$2)))),0,IF(70-F7<=0,0,70-F7)) -> 70 | L7: =SUM(K7*240) -> 0 | M7: =SUM(D7*120) -> 0 | N7: =SUM(E7*120) -> 0 | O7: =SUM(F7*54) -> 0 | P7: =SUM(G7*54) -> 3780 | Q7: =SUM(H7*120) -> 0 | R7: =SUM(I7*1000) -> 0 | S7: =SUM(J7*140) -> 0 | T7: =SUM(L7:S7) -> 3780
A8: 4 | B8: 46177 | F8: =F7-E8+D8 -> 0 | G8: =IF(OR(B8="",NOT(ISERROR(SEARCH("KPI",$A$2))),NOT(ISERROR(SEARCH("Полиом",$A$2)))),0,IF(70-F8<=0,0,70-F8)) -> 70 | L8: =SUM(K8*240) -> 0 | M8: =SUM(D8*120) -> 0 | N8: =SUM(E8*120) -> 0 | O8: =SUM(F8*54) -> 0 | P8: =SUM(G8*54) -> 3780 | Q8: =SUM(H8*120) -> 0 | R8: =SUM(I8*1000) -> 0 | S8: =SUM(J8*140) -> 0 | T8: =SUM(L8:S8) -> 3780
A9: 5 | B9: 46178 | F9: =F8-E9+D9 -> 0 | G9: =IF(OR(B9="",NOT(ISERROR(SEARCH("KPI",$A$2))),NOT(ISERROR(SEARCH("Полиом",$A$2)))),0,IF(70-F9<=0,0,70-F9)) -> 70 | L9: =SUM(K9*240) -> 0 | M9: =SUM(D9*120) -> 0 | N9: =SUM(E9*120) -> 0 | O9: =SUM(F9*54) -> 0 | P9: =SUM(G9*54) -> 3780 | Q9: =SUM(H9*120) -> 0 | R9: =SUM(I9*1000) -> 0 | S9: =SUM(J9*140) -> 0 | T9: =SUM(L9:S9) -> 3780
A10: 6 | B10: 46179 | F10: =F9-E10+D10 -> 0 | G10: =IF(OR(B10="",NOT(ISERROR(SEARCH("KPI",$A$2))),NOT(ISERROR(SEARCH("Полиом",$A$2)))),0,IF(70-F10<=0,0,70-F10)) -> 70 | L10: =SUM(K10*240) -> 0 | M10: =SUM(D10*120) -> 0 | N10: =SUM(E10*120) -> 0 | O10: =SUM(F10*54) -> 0 | P10: =SUM(G10*54) -> 3780 | Q10: =SUM(H10*120) -> 0 | R10: =SUM(I10*1000) -> 0 | S10: =SUM(J10*140) -> 0 | T10: =SUM(L10:S10) -> 3780
A11: 7 | B11: 46180 | F11: =F10-E11+D11 -> 0 | G11: =IF(OR(B11="",NOT(ISERROR(SEARCH("KPI",$A$2))),NOT(ISERROR(SEARCH("Полиом",$A$2)))),0,IF(70-F11<=0,0,70-F11)) -> 70 | L11: =SUM(K11*240) -> 0 | M11: =SUM(D11*120) -> 0 | N11: =SUM(E11*120) -> 0 | O11: =SUM(F11*54) -> 0 | P11: =SUM(G11*54) -> 3780 | Q11: =SUM(H11*120) -> 0 | R11: =SUM(I11*1000) -> 0 | S11: =SUM(J11*140) -> 0 | T11: =SUM(L11:S11) -> 3780
A12: 8 | B12: 46181 | F12: =F11-E12+D12 -> 0 | G12: =IF(OR(B12="",NOT(ISERROR(SEARCH("KPI",$A$2))),NOT(ISERROR(SEARCH("Полиом",$A$2)))),0,IF(70-F12<=0,0,70-F12)) -> 70 | L12: =SUM(K12*240) -> 0 | M12: =SUM(D12*120) -> 0 | N12: =SUM(E12*120) -> 0 | O12: =SUM(F12*54) -> 0 | P12: =SUM(G12*54) -> 3780 | Q12: =SUM(H12*120) -> 0 | R12: =SUM(I12*1000) -> 0 | S12: =SUM(J12*140) -> 0 | T12: =SUM(L12:S12) -> 3780
A13: 9 | B13: 46182 | F13: =F12-E13+D13 -> 0 | G13: =IF(OR(B13="",NOT(ISERROR(SEARCH("KPI",$A$2))),NOT(ISERROR(SEARCH("Полиом",$A$2)))),0,IF(70-F13<=0,0,70-F13)) -> 70 | L13: =SUM(K13*240) -> 0 | M13: =SUM(D13*120) -> 0 | N13: =SUM(E13*120) -> 0 | O13: =SUM(F13*54) -> 0 | P13: =SUM(G13*54) -> 3780 | Q13: =SUM(H13*120) -> 0 | R13: =SUM(I13*1000) -> 0 | S13: =SUM(J13*140) -> 0 | T13: =SUM(L13:S13) -> 3780
A14: 10 | B14: 46183 | F14: =F13-E14+D14 -> 0 | G14: =IF(OR(B14="",NOT(ISERROR(SEARCH("KPI",$A$2))),NOT(ISERROR(SEARCH("Полиом",$A$2)))),0,IF(70-F14<=0,0,70-F14)) -> 70 | L14: =SUM(K14*240) -> 0 | M14: =SUM(D14*120) -> 0 | N14: =SUM(E14*120) -> 0 | O14: =SUM(F14*54) -> 0 | P14: =SUM(G14*54) -> 3780 | Q14: =SUM(H14*120) -> 0 | R14: =SUM(I14*1000) -> 0 | S14: =SUM(J14*140) -> 0 | T14: =SUM(L14:S14) -> 3780
A15: 11 | B15: 46184 | F15: =F14-E15+D15 -> 0 | G15: =IF(OR(B15="",NOT(ISERROR(SEARCH("KPI",$A$2))),NOT(ISERROR(SEARCH("Полиом",$A$2)))),0,IF(70-F15<=0,0,70-F15)) -> 70 | L15: =SUM(K15*240) -> 0 | M15: =SUM(D15*120) -> 0 | N15: =SUM(E15*120) -> 0 | O15: =SUM(F15*54) -> 0 | P15: =SUM(G15*54) -> 3780 | Q15: =SUM(H15*120) -> 0 | R15: =SUM(I15*1000) -> 0 | S15: =SUM(J15*140) -> 0 | T15: =SUM(L15:S15) -> 3780
A16: 12 | B16: 46185 | F16: =F15-E16+D16 -> 0 | G16: =IF(OR(B16="",NOT(ISERROR(SEARCH("KPI",$A$2))),NOT(ISERROR(SEARCH("Полиом",$A$2)))),0,IF(70-F16<=0,0,70-F16)) -> 70 | L16: =SUM(K16*240) -> 0 | M16: =SUM(D16*120) -> 0 | N16: =SUM(E16*120) -> 0 | O16: =SUM(F16*54) -> 0 | P16: =SUM(G16*54) -> 3780 | Q16: =SUM(H16*120) -> 0 | R16: =SUM(I16*1000) -> 0 | S16: =SUM(J16*140) -> 0 | T16: =SUM(L16:S16) -> 3780
A17: 13 | B17: 46186 | F17: =F16-E17+D17 -> 0 | G17: =IF(OR(B17="",NOT(ISERROR(SEARCH("KPI",$A$2))),NOT(ISERROR(SEARCH("Полиом",$A$2)))),0,IF(70-F17<=0,0,70-F17)) -> 70 | L17: =SUM(K17*240) -> 0 | M17: =SUM(D17*120) -> 0 | N17: =SUM(E17*120) -> 0 | O17: =SUM(F17*54) -> 0 | P17: =SUM(G17*54) -> 3780 | Q17: =SUM(H17*120) -> 0 | R17: =SUM(I17*1000) -> 0 | S17: =SUM(J17*140) -> 0 | T17: =SUM(L17:S17) -> 3780
... A34: 30 | B34: 46203 | F34: =F33-E34+D34 -> 0 | G34: =IF(OR(B34="",NOT(ISERROR(SEARCH("KPI",$A$2))),NOT(ISERROR(SEARCH("Полиом",$A$2)))),0,IF(70-F34<=0,0,70-F34)) -> 70 | L34: =SUM(K34*240) -> 0 | M34: =SUM(D34*120) -> 0 | N34: =SUM(E34*120) -> 0 | O34: =SUM(F34*54) -> 0 | P34: =SUM(G34*54) -> 3780 | Q34: =SUM(H34*120) -> 0 | R34: =SUM(I34*1000) -> 0 | S34: =SUM(J34*140) -> 0 | T34: =SUM(L34:S34) -> 3780
L35: =SUM(K35*240) -> 0 | M35: =SUM(D35*120) -> 0 | N35: =SUM(E35*120) -> 0 | O35: =SUM(F35*54) -> 0 | P35: =SUM(G35*54) -> 0 | Q35: =SUM(H35*120) -> 0 | R35: =SUM(I35*1000) -> 0 | S35: =SUM(J35*140) -> 0 | T35: =SUM(L35:S35) -> 0
F36: =SUM(F5:F35) -> 0 | G36: =SUM(G5:G35) -> 2100 | H36: =SUM(H5:H35) -> 0 | I36: =SUM(I5:I35) -> 0 | J36: =SUM(J5:J35) -> 0 | K36: =SUM(K5:K35) -> 0 | L36: =SUM(L5:L35) -> 0 | M36: =SUM(M5:M35) -> 0 | ... T36: =SUM(T5:T35) -> 113400
T37: =T36*1.22 -> 138348

Sheet ИТОГО
A1: =G16 -> 1.4416318e+08
I2: ТОП
A3: Склад | B3: Сибур | C3: Завод | D3: Русвинил | E3: Клиенты сибура | F3: Остальные | G3: Итого | I3: Казань_Автосервисная | J3: 23143268
A4: Баумана | B4: =INDEX($M$45:$M$54,MATCH(A4,$A$45:$A$54,0),1) -> 9308583.3 | C4: 0 | D4: =INDEX($B$57:$B$73,MATCH(A4,$A$57:$A$73,0),1) -> 0 | E4: =SUMIF($F$19:$F$42,A4,$G$19:$G$42) -> 42887.88 | F4: =SUMIF($B$19:$B$27,A4,$C$19:$C$27) -> 159387 | G4: =SUM(B4:F4) -> 9510858.2 | I4: Нижнекамск завод | J4: 19482962
A5: Новикова-Прибоя | B5: =INDEX($M$45:$M$54,MATCH(A5,$A$45:$A$54,0),1) -> 10585418 | C5: 0 | D5: =INDEX($B$57:$B$73,MATCH(A5,$A$57:$A$73,0),1) -> 0 | E5: =SUMIF($F$19:$F$42,A5,$G$19:$G$42) -> 6423.3 | F5: =SUMIF($B$19:$B$27,A5,$C$19:$C$27) -> 0 | G5: =SUM(B5:F5) -> 10591842 | I5: Новикова-Прибоя | J5: 14483152
A6: Екатеринбург | B6: =INDEX($M$45:$M$54,MATCH(A6,$A$45:$A$54,0),1) -> 12664184 | C6: 0 | D6: =INDEX($B$57:$B$73,MATCH(A6,$A$57:$A$73,0),1) -> 0 | E6: =SUMIF($F$19:$F$42,A6,$G$19:$G$42) -> 0 | F6: =SUMIF($B$19:$B$27,A6,$C$19:$C$27) -> 0 | G6: =SUM(B6:F6) -> 12664184 | I6: Екатеринбург | J6: 11908609
A7: Новосибирск | B7: =INDEX($M$45:$M$54,MATCH(A7,$A$45:$A$54,0),1) -> 6041240.2 | C7: 0 | D7: =INDEX($B$57:$B$73,MATCH(A7,$A$57:$A$73,0),1) -> 0 | E7: =SUMIF($F$19:$F$42,A7,$G$19:$G$42) -> 138348 | F7: =SUMIF($B$19:$B$27,A7,$C$19:$C$27) -> 0 | G7: =SUM(B7:F7) -> 6179588.2 | I7: Баумана | J7: 11544503
A8: Новосибирск_Пасечная | B8: =INDEX($M$45:$M$54,MATCH(A8,$A$45:$A$54,0),1) -> 5883745 | C8: 0 | D8: =INDEX($B$57:$B$73,MATCH(A8,$A$57:$A$73,0),1) -> 0 | E8: =SUMIF($F$19:$F$42,A8,$G$19:$G$42) -> 0 | F8: =SUMIF($B$19:$B$27,A8,$C$19:$C$27) -> 0 | G8: =SUM(B8:F8) -> 5883745
A9: Казань_Автосервисная | B9: =INDEX($M$45:$M$54,MATCH(A9,$A$45:$A$54,0),1) -> 18643995 | C9: 0 | D9: =INDEX($B$57:$B$73,MATCH(A9,$A$57:$A$73,0),1) -> 0 | E9: =SUMIF($F$19:$F$42,A9,$G$19:$G$42) -> 0 | F9: =SUMIF($B$19:$B$27,A9,$C$19:$C$27) -> 0 | G9: =SUM(B9:F9) -> 18643995 | I9: Казань_Приволжская | J9: 9900926.9
A10: Казань_Приволжская | B10: =INDEX($M$45:$M$54,MATCH(A10,$A$45:$A$54,0),1) -> 9551913.8 | C10: 0 | D10: =INDEX($B$57:$B$73,MATCH(A10,$A$57:$A$73,0),1) -> 0 | E10: =SUMIF($F$19:$F$42,A10,$G$19:$G$42) -> 0 | F10: =SUMIF($B$19:$B$27,A10,$C$19:$C$27) -> 0 | G10: =SUM(B10:F10) -> 9551913.8 | I10: Зеленодольск | J10: 9082789.1
A11: Зеленодольск | B11: =INDEX($M$45:$M$54,MATCH(A11,$A$45:$A$54,0),1) -> 8737018.6 | C11: 0 | D11: =INDEX($B$57:$B$73,MATCH(A11,$A$57:$A$73,0),1) -> 0 | E11: =SUMIF($F$19:$F$42,A11,$G$19:$G$42) -> 3294 | F11: =SUMIF($B$19:$B$27,A11,$C$19:$C$27) -> 0 | G11: =SUM(B11:F11) -> 8740312.6 | I11: Новосибирск | J11: 7932975.6
A12: Нижнекамск | B12: =INDEX($M$45:$M$54,MATCH(A12,$A$45:$A$54,0),1) -> 0 | C12: 0 | D12: =INDEX($B$57:$B$73,MATCH(A12,$A$57:$A$73,0),1) -> 0 | E12: =SUMIF($F$19:$F$42,A12,$G$19:$G$42) -> 0 | F12: =SUMIF($B$19:$B$27,A12,$C$19:$C$27) -> 0 | G12: =SUM(B12:F12) -> 0 | I12: Нижнекамск | J12: 7580244.6
A13: Нижнекамск завод | B13: 0 | C13: =C29+C37 -> 55347989 | D13: =INDEX($B$57:$B$73,MATCH(A13,$A$57:$A$73,0),1) -> 0 | E13: =SUMIF($F$19:$F$42,A13,$G$19:$G$42) -> 0 | F13: =SUMIF($B$19:$B$27,A13,$C$19:$C$27) -> 0 | G13: =SUM(B13:F13) -> 55347989 | I13: ГАЗ | J13: 6720000
A14: ЕкатеринбургЧкаловский | B14: =INDEX($M$45:$M$54,MATCH(A14,$A$45:$A$54,0),1) -> 7048755.2 | C14: 0 | D14: =INDEX($B$57:$B$73,MATCH(A14,$A$57:$A$73,0),1) -> 0 | E14: =SUMIF($F$19:$F$42,A14,$G$19:$G$42) -> 0 | F14: =SUMIF($B$19:$B$27,A14,$C$19:$C$27) -> 0 | G14: =SUM(B14:F14) -> 7048755.2 | I14: Монастырка | J14: 2464921.6
A15: Березовая Пойма | B15: 0 | C15: 0 | D15: =INDEX($B$57:$B$73,MATCH(A15,$A$57:$A$73,0),1) -> 0 | E15: =SUMIF($F$19:$F$42,A15,$G$19:$G$42) -> 0 | F15: =SUMIF($B$19:$B$27,A15,$C$19:$C$27) -> 0 | G15: =SUM(B15:F15) -> 0
B16: =SUM(B4:B15) -> 88464854 | C16: =SUM(C4:C15) -> 55347989 | D16: =SUM(D4:D15) -> 0 | E16: =SUM(E4:E15) -> 190953.18 | F16: =SUM(F4:F15) -> 159387 | G16: =SUM(G4:G15) -> 1.4416318e+08
A18: Остальные клиенты | C18: =SUM(C19:C27) -> 159387 | E18: Клиенты сибура | G18: =SUM(G19:G41) -> 190953.18
A19: Стройтех | B19: Баумана | C19: {=IFERROR(INDIRECT("'" & A19 & "'!A1"),)} -> 42893 | E19: Приоритет | F19: Баумана | G19: {=IFERROR(INDIRECT("'" & E19 & " " & F19 & "'!A1"),0)} -> 4446.9
A20: Ергарда | B20: Баумана | C20: {=IFERROR(INDIRECT("'" & A20 & "'!A1"),)} -> 8640 | E20: Фармпласт | F20: Баумана | G20: {=IFERROR(INDIRECT("'" & E20 & " " & F20 & "'!A1"),0)} -> 15712.38
A21: Литейные решения | B21: Баумана | C21: {=IFERROR(INDIRECT("'" & A21 & "'!A1"),)} -> 85642 | E21: Юг Полимер | F21: Баумана | G21: {=IFERROR(INDIRECT("'" & E21 & " " & F21 & "'!A1"),0)} -> 12846.6
A22: Сандекс | B22: Баумана | C22: {=IFERROR(INDIRECT("'" & A22 & "'!A1"),)} -> 18700.8 | E22: Центрополимер | F22: Екатеринбург | G22: {=IFERROR(INDIRECT("'" & E22 & " " & F22 & "'!A1"),0)} -> 0
A23: ЛС-Техномет | B23: Баумана | C23: {=IFERROR(INDIRECT("'" & A23 & "'!A1"),)} -> 3511.2 | E23: Приоритет | F23: Екатеринбург | G23: {=IFERROR(INDIRECT("'" & E23 & " " & F23 & "'!A1"),0)} -> 0
A24: РусДжам | B24: ГАЗ | C24: {=IFERROR(INDIRECT("'" & A24 & "'!A1"),)} -> 0 | E24: Фармпласт | F24: Екатеринбург | G24: {=IFERROR(INDIRECT("'" & E24 & " " & F24 & "'!A1"),0)} -> 0
A25: Виго | B25: Новикова-Прибоя | C25: {=IFERROR(INDIRECT("'" & A25 & "'!A1"),)} -> 0 | E25: Приоритет | F25: Зеленодольск | G25: {=IFERROR(INDIRECT("'" & E25 & " " & F25 & "'!A1"),0)} -> 0
A26: Доктор Франк | B26: Новикова-Прибоя | C26: {=IFERROR(INDIRECT("'" & A26 & "'!A1"),)} -> 0 | E26: Данафлекс | F26: Зеленодольск | G26: {=IFERROR(INDIRECT("'" & E26 & " " & F26 & "'!t37"),0)} -> 0
A27: Нефтезол | B27: Новикова-Прибоя | C27: {=IFERROR(INDIRECT("'" & A27 & "'!A1"),)} -> 0 | E27: ИП Ксендз | F27: Нижнекамск | G27: {=IFERROR(INDIRECT("'" & E27 & " " & F27 & "'!A1"),0)} -> 0
E28: Фармпласт | F28: Новикова-Прибоя | G28: {=IFERROR(INDIRECT("'" & E28 & " " & F28 & "'!A1"),0)} -> 3952.8
A29: Нижнекамск завод | C29: =SUM(C30:C35) -> 44749043 | E29: Центрополимер | F29: Новикова-Прибоя | G29: {=IFERROR(INDIRECT("'" & E29 & " " & F29 & "'!A1"),0)} -> 0
A30: ПРР | C30: {=INDIRECT("'" & A29 & "'!F17")} -> 16167490 | E30: Юг Полимер | F30: Новикова-Прибоя | G30: {=IFERROR(INDIRECT("'" & E30 & " " & F30 & "'!A1"),0)} -> 0
A31: Кладовки | C31: {=INDIRECT("'" & A29 & "'!F16")} -> 0 | E31: Приоритет | F31: Новикова-Прибоя | G31: {=IFERROR(INDIRECT("'" & E31 & " " & F31 & "'!A1"),0)} -> 2470.5
A32: Стропальщики | C32: {=INDIRECT("'" & A29 & "'!F18")} -> 872300 | E32: Биаксплен | F32: Новосибирск | G32: {=IFERROR(INDIRECT("'" & E32 & " " & F32 & "'!A1"),0)} -> 138348
A33: Мойка контейнеров | C33: {=INDIRECT("'" & A29 & "'!F19")} -> 2242921 | E33: Центрополимер | F33: Новосибирск | G33: {=IFERROR(INDIRECT("'" & E33 & " " & F33 & "'!A1"),0)} -> 0
A34: МТО | C34: {=INDIRECT("'" & A29 & "'!F20")} -> 20121277 | E34: Фармпласт | F34: Новосибирск | G34: {=IFERROR(INDIRECT("'" & E34 & " " & F34 & "'!A1"),0)} -> 0
A35: МТО 2520 | C35: {=INDIRECT("'" & A29 & "'!F21")} -> 5345055 | E35: Центрополимер | F35: Зеленодольск | G35: {=IFERROR(INDIRECT("'" & E35 & " " & F35 & "'!A1"),0)} -> 3294
E36: Юг Полимер | F36: Зеленодольск | G36: {=IFERROR(INDIRECT("'" & E36 & " " & F36 & "'!A1"),0)} -> 0
A37: Контейнерные площадки | C37: =SUM(C38:C42) -> 10598946 | E37: Фармпласт | F37: Казань_Автосервисная | G37: {=IFERROR(INDIRECT("'" & E37 & " " & F37 & "'!A1"),0)} -> 0
A38: КОС | C38: 3534726 | E38: Приоритет | F38: Казань_Приволжская | G38: {=IFERROR(INDIRECT("'" & E38 & " " & F38 & "'!A1"),0)} -> 0
A39: Нижнекамск | C39: 7064220 | E39: Центрополимер | F39: Баумана | G39: {=IFERROR(INDIRECT("'" & E39 & " " & F39 & "'!A1"),0)} -> 9882
E40: Приоритет | F40: Казань_Автосервисная | G40: {=IFERROR(INDIRECT("'" & E40 & " " & F40 & "'!A1"),0)} -> 0
E41: Оникс | F41: Нижнекамск | G41: {=IFERROR(INDIRECT("'" & E41 & " " & F41 & "'!A1"),0)} -> 0
...

Sheet Другое

Sheet Нижнекамск завод
A9: № | B9: Наименование услуг (работ) | C9: Ед. изм. | D9: Количество | E9: Цена | F9: Сумма
A14: Итого: | F14: =SUM(F10:F13) -> 0
A15: Без налога (НДС) | F15: =SUM(F14) -> 0
A16: Всего (с учетом НДС) | F16: =SUM(F15)*1.2 -> 0
A17: Вышеперечисленные услуги (работы) выполнены полностью. | E17: ПРР | F17: 16167490
A18: ПОКЛАЖЕДАТЕЛЬ претензий по объему, качеству и срокам оказания услуг претензий не имеет. | E18: Стропальщики | F18: 872300
E19: Контейнеры | F19: 2242921
E20: МТО | F20: =19736977+315000*1.22 -> 20121277
E21: МТО 2520 | F21: 5345055
A22: ООО "ДТМ" | D22: ПАО "Нижнекамскнефтехим"
A24: ____________________Молькова Т.Ю. | B24: Расстегаев Д.О. | D24: ____________________

Sheet Сводка
A1: KPI | B1: Баумана | C1: =INDEX(INDIRECT("ИТОГО!$B$45:$L$54"),MATCH(Сводка!B1,INDIRECT("ИТОГО!$A$45:$A$54"),0),MATCH(Сводка!A1,INDIRECT("ИТОГО!$B$44:$L$44"),0)) -> 1178.04
A2: Полиом | B2: Баумана | C2: =INDEX(INDIRECT("ИТОГО!$B$45:$L$54"),MATCH(Сводка!B2,INDIRECT("ИТОГО!$A$45:$A$54"),0),MATCH(Сводка!A2,INDIRECT("ИТОГО!$B$44:$L$44"),0)) -> 198644.54
A3: Полимеры | B3: Баумана | C3: =INDEX(INDIRECT("ИТОГО!$B$45:$L$54"),MATCH(Сводка!B3,INDIRECT("ИТОГО!$A$45:$A$54"),0),MATCH(Сводка!A3,INDIRECT("ИТОГО!$B$44:$L$44"),0)) -> 9108760.8
A4: Каучук | B4: Баумана | C4: =INDEX(INDIRECT("ИТОГО!$B$45:$L$54"),MATCH(Сводка!B4,INDIRECT("ИТОГО!$A$45:$A$54"),0),MATCH(Сводка!A4,INDIRECT("ИТОГО!$B$44:$L$44"),0)) -> 0
A5: ПСОН | B5: Баумана | C5: =INDEX(INDIRECT("ИТОГО!$B$45:$L$54"),MATCH(Сводка!B5,INDIRECT("ИТОГО!$A$45:$A$54"),0),MATCH(Сводка!A5,INDIRECT("ИТОГО!$B$44:$L$44"),0)) -> 0
A6: Данафлекс | B6: Баумана | C6: =INDEX(INDIRECT("ИТОГО!$B$45:$L$54"),MATCH(Сводка!B6,INDIRECT("ИТОГО!$A$45:$A$54"),0),MATCH(Сводка!A6,INDIRECT("ИТОГО!$B$44:$L$44"),0)) -> 0
A7: СБС | B7: Баумана | C7: =INDEX(INDIRECT("ИТОГО!$B$45:$L$54"),MATCH(Сводка!B7,INDIRECT("ИТОГО!$A$45:$A$54"),0),MATCH(Сводка!A7,INDIRECT("ИТОГО!$B$44:$L$44"),0)) -> 0
A8: Порошок | B8: Баумана | C8: =INDEX(INDIRECT("ИТОГО!$B$45:$L$54"),MATCH(Сводка!B8,INDIRECT("ИТОГО!$A$45:$A$54"),0),MATCH(Сводка!A8,INDIRECT("ИТОГО!$B$44:$L$44"),0)) -> 0
A9: НПЭГ | B9: Баумана | C9: =INDEX(INDIRECT("ИТОГО!$B$45:$L$54"),MATCH(Сводка!B9,INDIRECT("ИТОГО!$A$45:$A$54"),0),MATCH(Сводка!A9,INDIRECT("ИТОГО!$B$44:$L$44"),0)) -> 0
A10: Экспорт | B10: Баумана | C10: =INDEX(INDIRECT("ИТОГО!$B$45:$L$54"),MATCH(Сводка!B10,INDIRECT("ИТОГО!$A$45:$A$54"),0),MATCH(Сводка!A10,INDIRECT("ИТОГО!$B$44:$L$44"),0)) -> 0
A11: Доп услуги | B11: Баумана | C11: =INDEX(INDIRECT("ИТОГО!$B$45:$L$54"),MATCH(Сводка!B11,INDIRECT("ИТОГО!$A$45:$A$54"),0),MATCH(Сводка!A11,INDIRECT("ИТОГО!$B$44:$L$44"),0)) -> 0
A12: KPI | B12: Новикова-Прибоя | C12: =INDEX(INDIRECT("ИТОГО!$B$45:$L$54"),MATCH(Сводка!B12,INDIRECT("ИТОГО!$A$45:$A$54"),0),MATCH(Сводка!A12,INDIRECT("ИТОГО!$B$44:$L$44"),0)) -> 15008.31
... A99: Доп услуги | B99: Казань_Приволжская | C99: =INDEX(INDIRECT("ИТОГО!$B$45:$L$54"),MATCH(Сводка!B99,INDIRECT("ИТОГО!$A$45:$A$54"),0),MATCH(Сводка!A99,INDIRECT("ИТОГО!$B$44:$L$44"),0)) -> 0
A100: Русвинил | B100: Баумана | C100: {=INDIRECT("ИТОГО!B57")} -> 0
A101: Русвинил | B101: Новикова-Прибоя | C101: {=INDIRECT("ИТОГО!B58")} -> 0
A102: Русвинил | B102: Березовая Пойма | C102: {=INDIRECT("ИТОГО!B67")} -> 0
A103: ПРР | B103: Нижнекамск завод | C103: {=INDIRECT("ИТОГО!C30")} -> 16167490
A104: Кладовки | B104: Нижнекамск завод | C104: {=INDIRECT("ИТОГО!C31")} -> 0
A105: Стропальщики | B105: Нижнекамск завод | C105: {=INDIRECT("ИТОГО!C32")} -> 872300
A106: Мойка контейнеров | B106: Нижнекамск завод | C106: {=INDIRECT("ИТОГО!C33")} -> 2242921
A107: МТО | B107: Нижнекамск завод | C107: {=INDIRECT("ИТОГО!C34")} -> 20121277
A108: МТО 2520 | B108: Нижнекамск завод | C108: {=INDIRECT("ИТОГО!C35")} -> 5345055
A109: КП КОС | B109: Нижнекамск завод | C109: {=INDIRECT("ИТОГО!C38")} -> 3534726
A110: КП Нижнекамск | B110: Нижнекамск завод | C110: {=INDIRECT("ИТОГО!C39")} -> 7064220
A111: Стройтех | B111: Баумана | C111: {=INDIRECT("ИТОГО!C19")} -> 42893
A112: Ергарда | B112: Баумана | C112: {=INDIRECT("ИТОГО!C20")} -> 8640
A113: Литейные решения | B113: Баумана | C113: {=INDIRECT("ИТОГО!C21")} -> 85642
A114: Сандекс | B114: Баумана | C114: {=INDIRECT("ИТОГО!C22")} -> 18700.8
A115: ЛС-Техномет | B115: Баумана | C115: {=INDIRECT("ИТОГО!C23")} -> 3511.2
A116: Приоритет | B116: Баумана | C116: {=INDIRECT("ИТОГО!G19")} -> 4446.9
A117: Фармпласт | B117: Баумана | C117: {=INDIRECT("ИТОГО!G20")} -> 15712.38
A118: Юг Полимер | B118: Баумана | C118: {=INDIRECT("ИТОГО!G21")} -> 12846.6
A119: Центрополимер | B119: Екатеринбург | C119: {=INDIRECT("ИТОГО!G22")} -> 0
A120: Приоритет | B120: Екатеринбург | C120: {=INDIRECT("ИТОГО!G23")} -> 0
A121: Фармпласт | B121: Екатеринбург | C121: {=INDIRECT("ИТОГО!G24")} -> 0
A122: Приоритет | B122: Зеленодольск | C122: {=INDIRECT("ИТОГО!G25")} -> 0
A123: Данафлекс | B123: Зеленодольск | C123: {=INDIRECT("ИТОГО!G26")} -> 0
A124: ИП Ксендз | B124: Нижнекамск | C124: {=INDIRECT("ИТОГО!G27")} -> 0
A125: Фармпласт | B125: Новикова-Прибоя | C125: {=INDIRECT("ИТОГО!G28")} -> 3952.8
A126: Центрополимер | B126: Новикова-Прибоя | C126: {=INDIRECT("ИТОГО!G29")} -> 0
...

Sheet Центрополимер Зеленодольск
A1: =N37 -> 3294
A2: ="Отчет по хранению товара за " & TEXT(B5,"ММММ ГГГГ") -> Отчет по хранению товара за Июнь 2026
A3: № | B3: дата | D3: Выгрузка кол-во | E3: Загрузка кол-во | F3: Хранение | G3: переконсолидация (тонн) | H3: Паллетирование | I3: стоимость выгрузки | J3: стоимость загрузки | K3: стоимость хранения | L3: стоимость переконс. | M3: Стоимость паллетирования | N3: итого | Q3: Цены
Q4: Выгрузка | R4: 180
A5: 1 | B5: 46174 | F5: 0 | G5: 0 | H5: 0 | I5: =SUM(D5*$R$4) -> 0 | J5: =SUM(E5*$R$5) -> 0 | K5: =F5*$R$6 -> 0 | L5: =SUM(G5*$R$7) -> 0 | M5: =SUM(H5*$R$8) -> 0 | N5: =SUM(I5:M5) -> 0 | Q5: Загрузка | R5: 180
A6: 2 | B6: 46175 | F6: =F5-E5+D6 -> 0 | G6: 0 | H6: 0 | I6: =SUM(D6*$R$4) -> 0 | J6: =SUM(E6*$R$5) -> 0 | K6: =F6*$R$6 -> 0 | L6: =SUM(G6*$R$7) -> 0 | M6: =SUM(H6*$R$8) -> 0 | N6: =SUM(I6:M6) -> 0 | Q6: Хранение | R6: 24
A7: 3 | B7: 46176 | F7: =F6-E6+D7 -> 0 | G7: 0 | H7: 0 | I7: =SUM(D7*$R$4) -> 0 | J7: =SUM(E7*$R$5) -> 0 | K7: =F7*$R$6 -> 0 | L7: =SUM(G7*$R$7) -> 0 | M7: =SUM(H7*$R$8) -> 0 | N7: =SUM(I7:M7) -> 0 | Q7: Переконсолидация | R7: 1200
A8: 4 | B8: 46177 | F8: =F7-E7+D8 -> 0 | G8: 0 | H8: 0 | I8: =SUM(D8*$R$4) -> 0 | J8: =SUM(E8*$R$5) -> 0 | K8: =F8*$R$6 -> 0 | L8: =SUM(G8*$R$7) -> 0 | M8: =SUM(H8*$R$8) -> 0 | N8: =SUM(I8:M8) -> 0 | Q8: Паллетирование | R8: 240
A9: 5 | B9: 46178 | F9: =F8-E8+D9 -> 0 | G9: 0 | H9: 0 | I9: =SUM(D9*$R$4) -> 0 | J9: =SUM(E9*$R$5) -> 0 | K9: =F9*$R$6 -> 0 | L9: =SUM(G9*$R$7) -> 0 | M9: =SUM(H9*$R$8) -> 0 | N9: =SUM(I9:M9) -> 0
A10: 6 | B10: 46179 | F10: =F9-E9+D10 -> 0 | G10: 0 | H10: 0 | I10: =SUM(D10*$R$4) -> 0 | J10: =SUM(E10*$R$5) -> 0 | K10: =F10*$R$6 -> 0 | L10: =SUM(G10*$R$7) -> 0 | M10: =SUM(H10*$R$8) -> 0 | N10: =SUM(I10:M10) -> 0
A11: 7 | B11: 46180 | F11: =F10-E10+D11 -> 0 | G11: 0 | H11: 0 | I11: =SUM(D11*$R$4) -> 0 | J11: =SUM(E11*$R$5) -> 0 | K11: =F11*$R$6 -> 0 | L11: =SUM(G11*$R$7) -> 0 | M11: =SUM(H11*$R$8) -> 0 | N11: =SUM(I11:M11) -> 0
A12: 8 | B12: 46181 | F12: =F11-E11+D12 -> 0 | G12: 0 | H12: 0 | I12: =SUM(D12*$R$4) -> 0 | J12: =SUM(E12*$R$5) -> 0 | K12: =F12*$R$6 -> 0 | L12: =SUM(G12*$R$7) -> 0 | M12: =SUM(H12*$R$8) -> 0 | N12: =SUM(I12:M12) -> 0
A13: 9 | B13: 46182 | F13: =F12-E12+D13 -> 0 | G13: 0 | H13: 0 | I13: =SUM(D13*$R$4) -> 0 | J13: =SUM(E13*$R$5) -> 0 | K13: =F13*$R$6 -> 0 | L13: =SUM(G13*$R$7) -> 0 | M13: =SUM(H13*$R$8) -> 0 | N13: =SUM(I13:M13) -> 0
A14: 10 | B14: 46183 | F14: =F13-E13+D14 -> 0 | G14: 0 | H14: 0 | I14: =SUM(D14*$R$4) -> 0 | J14: =SUM(E14*$R$5) -> 0 | K14: =F14*$R$6 -> 0 | L14: =SUM(G14*$R$7) -> 0 | M14: =SUM(H14*$R$8) -> 0 | N14: =SUM(I14:M14) -> 0
A15: 11 | B15: 46184 | F15: =F14-E14+D15 -> 0 | G15: 0 | H15: 0 | I15: =SUM(D15*$R$4) -> 0 | J15: =SUM(E15*$R$5) -> 0 | K15: =F15*$R$6 -> 0 | L15: =SUM(G15*$R$7) -> 0 | M15: =SUM(H15*$R$8) -> 0 | N15: =SUM(I15:M15) -> 0
A16: 12 | B16: 46185 | F16: =F15-E15+D16 -> 0 | G16: 0 | H16: 0 | I16: =SUM(D16*$R$4) -> 0 | J16: =SUM(E16*$R$5) -> 0 | K16: =F16*$R$6 -> 0 | L16: =SUM(G16*$R$7) -> 0 | M16: =SUM(H16*$R$8) -> 0 | N16: =SUM(I16:M16) -> 0
A17: 13 | B17: 46186 | F17: =F16-E16+D17 -> 0 | G17: 0 | H17: 0 | I17: =SUM(D17*$R$4) -> 0 | J17: =SUM(E17*$R$5) -> 0 | K17: =F17*$R$6 -> 0 | L17: =SUM(G17*$R$7) -> 0 | M17: =SUM(H17*$R$8) -> 0 | N17: =SUM(I17:M17) -> 0
A18: 14 | B18: 46187 | F18: =F17-E17+D18 -> 0 | G18: 0 | H18: 0 | I18: =SUM(D18*$R$4) -> 0 | J18: =SUM(E18*$R$5) -> 0 | K18: =F18*$R$6 -> 0 | L18: =SUM(G18*$R$7) -> 0 | M18: =SUM(H18*$R$8) -> 0 | N18: =SUM(I18:M18) -> 0
A19: 15 | B19: 46188 | F19: =F18-E18+D19 -> 0 | G19: 0 | H19: 0 | I19: =SUM(D19*$R$4) -> 0 | J19: =SUM(E19*$R$5) -> 0 | K19: =F19*$R$6 -> 0 | L19: =SUM(G19*$R$7) -> 0 | M19: =SUM(H19*$R$8) -> 0 | N19: =SUM(I19:M19) -> 0
A20: 16 | B20: 46189 | F20: =F19-E19+D20 -> 0 | G20: 0 | H20: 0 | I20: =SUM(D20*$R$4) -> 0 | J20: =SUM(E20*$R$5) -> 0 | K20: =F20*$R$6 -> 0 | L20: =SUM(G20*$R$7) -> 0 | M20: =SUM(H20*$R$8) -> 0 | N20: =SUM(I20:M20) -> 0
... A33: 29 | B33: 46202 | F33: =F32-E32+D33 -> 0 | G33: 0 | H33: 0 | I33: =SUM(D33*$R$4) -> 0 | J33: =SUM(E33*$R$5) -> 0 | K33: =F33*$R$6 -> 0 | L33: =SUM(G33*$R$7) -> 0 | M33: =SUM(H33*$R$8) -> 0 | N33: =SUM(I33:M33) -> 0
A34: 30 | B34: 46203 | F34: 112.5 | G34: 0 | H34: 0 | I34: =SUM(D34*$R$4) -> 0 | J34: =SUM(E34*$R$5) -> 0 | K34: =F34*$R$6 -> 2700 | L34: =SUM(G34*$R$7) -> 0 | M34: =SUM(H34*$R$8) -> 0 | N34: =SUM(I34:M34) -> 2700
I35: =SUM(D35*$R$4) -> 0 | J35: =SUM(E35*$R$5) -> 0 | K35: =F35*$R$6 -> 0 | L35: =SUM(G35*$R$7) -> 0 | M35: =SUM(H35*$R$8) -> 0 | N35: =SUM(I35:M35) -> 0
D36: =SUM(D5:D35) -> 0 | E36: =SUM(E5:E35) -> 0 | F36: =SUM(F5:F35) -> 112.5 | G36: =SUM(G5:G35) -> 0 | H36: =SUM(H5:H35) -> 0 | I36: =SUM(I5:I35) -> 0 | J36: =SUM(J5:J35) -> 0 | K36: =SUM(K5:K35) -> 2700 | ... N36: =SUM(N5:N35) -> 2700
N37: =N36*1.22 -> 3294

Sheet Центрополимер Баумана
A1: =N37 -> 9882
A2: ="Отчет по хранению товара за " & TEXT(B5,"ММММ ГГГГ") -> Отчет по хранению товара за Июнь 2026
A3: № | B3: дата | D3: Выгрузка кол-во | E3: Загрузка кол-во | F3: Хранение | G3: переконсолидация (тонн) | H3: Паллетирование | I3: стоимость выгрузки | J3: стоимость загрузки | K3: стоимость хранения | L3: стоимость переконс. | M3: Стоимость паллетирования | N3: итого | Q3: Цены
Q4: Выгрузка | R4: 180
A5: 1 | B5: 46174 | F5: 0 | G5: 0 | H5: 0 | I5: =SUM(D5*$R$4) -> 0 | J5: =SUM(E5*$R$5) -> 0 | K5: =F5*$R$6 -> 0 | L5: =SUM(G5*$R$7) -> 0 | M5: =SUM(H5*$R$8) -> 0 | N5: =SUM(I5:M5) -> 0 | Q5: Загрузка | R5: 180
A6: 2 | B6: 46175 | F6: =F5-E5+D6 -> 0 | G6: 0 | H6: 0 | I6: =SUM(D6*$R$4) -> 0 | J6: =SUM(E6*$R$5) -> 0 | K6: =F6*$R$6 -> 0 | L6: =SUM(G6*$R$7) -> 0 | M6: =SUM(H6*$R$8) -> 0 | N6: =SUM(I6:M6) -> 0 | Q6: Хранение | R6: 24
A7: 3 | B7: 46176 | F7: =F6-E6+D7 -> 0 | G7: 0 | H7: 0 | I7: =SUM(D7*$R$4) -> 0 | J7: =SUM(E7*$R$5) -> 0 | K7: =F7*$R$6 -> 0 | L7: =SUM(G7*$R$7) -> 0 | M7: =SUM(H7*$R$8) -> 0 | N7: =SUM(I7:M7) -> 0 | Q7: Переконсолидация | R7: 1200
A8: 4 | B8: 46177 | F8: =F7-E7+D8 -> 0 | G8: 0 | H8: 0 | I8: =SUM(D8*$R$4) -> 0 | J8: =SUM(E8*$R$5) -> 0 | K8: =F8*$R$6 -> 0 | L8: =SUM(G8*$R$7) -> 0 | M8: =SUM(H8*$R$8) -> 0 | N8: =SUM(I8:M8) -> 0 | Q8: Паллетирование | R8: 240
A9: 5 | B9: 46178 | F9: =F8-E8+D9 -> 0 | G9: 0 | H9: 0 | I9: =SUM(D9*$R$4) -> 0 | J9: =SUM(E9*$R$5) -> 0 | K9: =F9*$R$6 -> 0 | L9: =SUM(G9*$R$7) -> 0 | M9: =SUM(H9*$R$8) -> 0 | N9: =SUM(I9:M9) -> 0
A10: 6 | B10: 46179 | F10: =F9-E9+D10 -> 0 | G10: 0 | H10: 0 | I10: =SUM(D10*$R$4) -> 0 | J10: =SUM(E10*$R$5) -> 0 | K10: =F10*$R$6 -> 0 | L10: =SUM(G10*$R$7) -> 0 | M10: =SUM(H10*$R$8) -> 0 | N10: =SUM(I10:M10) -> 0
A11: 7 | B11: 46180 | F11: =F10-E10+D11 -> 0 | G11: 0 | H11: 0 | I11: =SUM(D11*$R$4) -> 0 | J11: =SUM(E11*$R$5) -> 0 | K11: =F11*$R$6 -> 0 | L11: =SUM(G11*$R$7) -> 0 | M11: =SUM(H11*$R$8) -> 0 | N11: =SUM(I11:M11) -> 0
A12: 8 | B12: 46181 | F12: =F11-E11+D12 -> 0 | G12: 0 | H12: 0 | I12: =SUM(D12*$R$4) -> 0 | J12: =SUM(E12*$R$5) -> 0 | K12: =F12*$R$6 -> 0 | L12: =SUM(G12*$R$7) -> 0 | M12: =SUM(H12*$R$8) -> 0 | N12: =SUM(I12:M12) -> 0
A13: 9 | B13: 46182 | F13: =F12-E12+D13 -> 0 | G13: 0 | H13: 0 | I13: =SUM(D13*$R$4) -> 0 | J13: =SUM(E13*$R$5) -> 0 | K13: =F13*$R$6 -> 0 | L13: =SUM(G13*$R$7) -> 0 | M13: =SUM(H13*$R$8) -> 0 | N13: =SUM(I13:M13) -> 0
A14: 10 | B14: 46183 | F14: =F13-E13+D14 -> 0 | G14: 0 | H14: 0 | I14: =SUM(D14*$R$4) -> 0 | J14: =SUM(E14*$R$5) -> 0 | K14: =F14*$R$6 -> 0 | L14: =SUM(G14*$R$7) -> 0 | M14: =SUM(H14*$R$8) -> 0 | N14: =SUM(I14:M14) -> 0
A15: 11 | B15: 46184 | F15: =F14-E14+D15 -> 0 | G15: 0 | H15: 0 | I15: =SUM(D15*$R$4) -> 0 | J15: =SUM(E15*$R$5) -> 0 | K15: =F15*$R$6 -> 0 | L15: =SUM(G15*$R$7) -> 0 | M15: =SUM(H15*$R$8) -> 0 | N15: =SUM(I15:M15) -> 0
A16: 12 | B16: 46185 | F16: =F15-E15+D16 -> 0 | G16: 0 | H16: 0 | I16: =SUM(D16*$R$4) -> 0 | J16: =SUM(E16*$R$5) -> 0 | K16: =F16*$R$6 -> 0 | L16: =SUM(G16*$R$7) -> 0 | M16: =SUM(H16*$R$8) -> 0 | N16: =SUM(I16:M16) -> 0
A17: 13 | B17: 46186 | F17: =F16-E16+D17 -> 0 | G17: 0 | H17: 0 | I17: =SUM(D17*$R$4) -> 0 | J17: =SUM(E17*$R$5) -> 0 | K17: =F17*$R$6 -> 0 | L17: =SUM(G17*$R$7) -> 0 | M17: =SUM(H17*$R$8) -> 0 | N17: =SUM(I17:M17) -> 0
A18: 14 | B18: 46187 | F18: =F17-E17+D18 -> 0 | G18: 0 | H18: 0 | I18: =SUM(D18*$R$4) -> 0 | J18: =SUM(E18*$R$5) -> 0 | K18: =F18*$R$6 -> 0 | L18: =SUM(G18*$R$7) -> 0 | M18: =SUM(H18*$R$8) -> 0 | N18: =SUM(I18:M18) -> 0
A19: 15 | B19: 46188 | F19: =F18-E18+D19 -> 0 | G19: 0 | H19: 0 | I19: =SUM(D19*$R$4) -> 0 | J19: =SUM(E19*$R$5) -> 0 | K19: =F19*$R$6 -> 0 | L19: =SUM(G19*$R$7) -> 0 | M19: =SUM(H19*$R$8) -> 0 | N19: =SUM(I19:M19) -> 0
A20: 16 | B20: 46189 | F20: =F19-E19+D20 -> 0 | G20: 0 | H20: 0 | I20: =SUM(D20*$R$4) -> 0 | J20: =SUM(E20*$R$5) -> 0 | K20: =F20*$R$6 -> 0 | L20: =SUM(G20*$R$7) -> 0 | M20: =SUM(H20*$R$8) -> 0 | N20: =SUM(I20:M20) -> 0
... A33: 29 | B33: 46202 | F33: =F32-E32+D33 -> 0 | G33: 0 | H33: 0 | I33: =SUM(D33*$R$4) -> 0 | J33: =SUM(E33*$R$5) -> 0 | K33: =F33*$R$6 -> 0 | L33: =SUM(G33*$R$7) -> 0 | M33: =SUM(H33*$R$8) -> 0 | N33: =SUM(I33:M33) -> 0
A34: 30 | B34: 46203 | F34: 337.5 | G34: 0 | H34: 0 | I34: =SUM(D34*$R$4) -> 0 | J34: =SUM(E34*$R$5) -> 0 | K34: =F34*$R$6 -> 8100 | L34: =SUM(G34*$R$7) -> 0 | M34: =SUM(H34*$R$8) -> 0 | N34: =SUM(I34:M34) -> 8100
I35: =SUM(D35*$R$4) -> 0 | J35: =SUM(E35*$R$5) -> 0 | K35: =F35*$R$6 -> 0 | L35: =SUM(G35*$R$7) -> 0 | M35: =SUM(H35*$R$8) -> 0 | N35: =SUM(I35:M35) -> 0
D36: =SUM(D5:D35) -> 0 | E36: =SUM(E5:E35) -> 0 | F36: =SUM(F5:F35) -> 337.5 | G36: =SUM(G5:G35) -> 0 | H36: =SUM(H5:H35) -> 0 | I36: =SUM(I5:I35) -> 0 | J36: =SUM(J5:J35) -> 0 | K36: =SUM(K5:K35) -> 8100 | ... N36: =SUM(N5:N35) -> 8100
N37: =N36*1.22 -> 9882

Sheet Центрополимер Новикова-Прибоя
A1: =N37 -> 0
A2: ="Отчет по хранению товара за " & TEXT(B5,"ММММ ГГГГ") -> Отчет по хранению товара за Июнь 2026
A3: № | B3: дата | D3: Выгрузка кол-во | E3: Загрузка кол-во | F3: Хранение | G3: переконсолидация (тонн) | H3: Паллетирование | I3: стоимость выгрузки | J3: стоимость загрузки | K3: стоимость хранения | L3: стоимость переконс. | M3: Стоимость паллетирования | N3: итого | Q3: Цены
Q4: Выгрузка | R4: 120
A5: 1 | B5: 46174 | F5: 0 | G5: 0 | H5: 0 | I5: =SUM(D5*R4) -> 0 | J5: =SUM(E5*$R$5) -> 0 | K5: =SUM(F5*$R$6) -> 0 | L5: =SUM(G5*$R$7) -> 0 | M5: =SUM(H5*$R$8) -> 0 | N5: =SUM(I5:M5) -> 0 | Q5: Загрузка | R5: 120
A6: 2 | B6: 46175 | F6: =F5-E5+D6 -> 0 | G6: 0 | H6: 0 | I6: =SUM(D6*R5) -> 0 | J6: =SUM(E6*$R$5) -> 0 | K6: =SUM(F6*$R$6) -> 0 | L6: =SUM(G6*$R$7) -> 0 | M6: =SUM(H6*$R$8) -> 0 | N6: =SUM(I6:M6) -> 0 | Q6: Хранение | R6: 18
A7: 3 | B7: 46176 | F7: =F6-E6+D7 -> 0 | G7: 0 | H7: 0 | I7: =SUM(D7*R6) -> 0 | J7: =SUM(E7*$R$5) -> 0 | K7: =SUM(F7*$R$6) -> 0 | L7: =SUM(G7*$R$7) -> 0 | M7: =SUM(H7*$R$8) -> 0 | N7: =SUM(I7:M7) -> 0 | Q7: Переконсолидация | R7: 950
A8: 4 | B8: 46177 | F8: =F7-E7+D8 -> 0 | G8: 0 | H8: 0 | I8: =SUM(D8*R7) -> 0 | J8: =SUM(E8*$R$5) -> 0 | K8: =SUM(F8*$R$6) -> 0 | L8: =SUM(G8*$R$7) -> 0 | M8: =SUM(H8*$R$8) -> 0 | N8: =SUM(I8:M8) -> 0 | Q8: Паллетирование | R8: 120
A9: 5 | B9: 46178 | F9: =F8-E8+D9 -> 0 | G9: 0 | H9: 0 | I9: =SUM(D9*R8) -> 0 | J9: =SUM(E9*$R$5) -> 0 | K9: =SUM(F9*$R$6) -> 0 | L9: =SUM(G9*$R$7) -> 0 | M9: =SUM(H9*$R$8) -> 0 | N9: =SUM(I9:M9) -> 0
A10: 6 | B10: 46179 | F10: =F9-E9+D10 -> 0 | G10: 0 | H10: 0 | I10: =SUM(D10*R9) -> 0 | J10: =SUM(E10*$R$5) -> 0 | K10: =SUM(F10*$R$6) -> 0 | L10: =SUM(G10*$R$7) -> 0 | M10: =SUM(H10*$R$8) -> 0 | N10: =SUM(I10:M10) -> 0
A11: 7 | B11: 46180 | F11: =F10-E10+D11 -> 0 | G11: 0 | H11: 0 | I11: =SUM(D11*R10) -> 0 | J11: =SUM(E11*$R$5) -> 0 | K11: =SUM(F11*$R$6) -> 0 | L11: =SUM(G11*$R$7) -> 0 | M11: =SUM(H11*$R$8) -> 0 | N11: =SUM(I11:M11) -> 0
A12: 8 | B12: 46181 | F12: =F11-E11+D12 -> 0 | G12: 0 | H12: 0 | I12: =SUM(D12*R11) -> 0 | J12: =SUM(E12*$R$5) -> 0 | K12: =SUM(F12*$R$6) -> 0 | L12: =SUM(G12*$R$7) -> 0 | M12: =SUM(H12*$R$8) -> 0 | N12: =SUM(I12:M12) -> 0
A13: 9 | B13: 46182 | F13: =F12-E12+D13 -> 0 | G13: 0 | H13: 0 | I13: =SUM(D13*R12) -> 0 | J13: =SUM(E13*$R$5) -> 0 | K13: =SUM(F13*$R$6) -> 0 | L13: =SUM(G13*$R$7) -> 0 | M13: =SUM(H13*$R$8) -> 0 | N13: =SUM(I13:M13) -> 0
A14: 10 | B14: 46183 | F14: =F13-E13+D14 -> 0 | G14: 0 | H14: 0 | I14: =SUM(D14*R13) -> 0 | J14: =SUM(E14*$R$5) -> 0 | K14: =SUM(F14*$R$6) -> 0 | L14: =SUM(G14*$R$7) -> 0 | M14: =SUM(H14*$R$8) -> 0 | N14: =SUM(I14:M14) -> 0
A15: 11 | B15: 46184 | F15: =F14-E14+D15 -> 0 | G15: 0 | H15: 0 | I15: =SUM(D15*R14) -> 0 | J15: =SUM(E15*$R$5) -> 0 | K15: =SUM(F15*$R$6) -> 0 | L15: =SUM(G15*$R$7) -> 0 | M15: =SUM(H15*$R$8) -> 0 | N15: =SUM(I15:M15) -> 0
A16: 12 | B16: 46185 | F16: =F15-E15+D16 -> 0 | G16: 0 | H16: 0 | I16: =SUM(D16*R15) -> 0 | J16: =SUM(E16*$R$5) -> 0 | K16: =SUM(F16*$R$6) -> 0 | L16: =SUM(G16*$R$7) -> 0 | M16: =SUM(H16*$R$8) -> 0 | N16: =SUM(I16:M16) -> 0
A17: 13 | B17: 46186 | F17: =F16-E16+D17 -> 0 | G17: 0 | H17: 0 | I17: =SUM(D17*R16) -> 0 | J17: =SUM(E17*$R$5) -> 0 | K17: =SUM(F17*$R$6) -> 0 | L17: =SUM(G17*$R$7) -> 0 | M17: =SUM(H17*$R$8) -> 0 | N17: =SUM(I17:M17) -> 0
A18: 14 | B18: 46187 | F18: =F17-E17+D18 -> 0 | G18: 0 | H18: 0 | I18: =SUM(D18*R17) -> 0 | J18: =SUM(E18*$R$5) -> 0 | K18: =SUM(F18*$R$6) -> 0 | L18: =SUM(G18*$R$7) -> 0 | M18: =SUM(H18*$R$8) -> 0 | N18: =SUM(I18:M18) -> 0
A19: 15 | B19: 46188 | F19: =F18-E18+D19 -> 0 | G19: 0 | H19: 0 | I19: =SUM(D19*R18) -> 0 | J19: =SUM(E19*$R$5) -> 0 | K19: =SUM(F19*$R$6) -> 0 | L19: =SUM(G19*$R$7) -> 0 | M19: =SUM(H19*$R$8) -> 0 | N19: =SUM(I19:M19) -> 0
A20: 16 | B20: 46189 | F20: =F19-E19+D20 -> 0 | G20: 0 | H20: 0 | I20: =SUM(D20*R19) -> 0 | J20: =SUM(E20*$R$5) -> 0 | K20: =SUM(F20*$R$6) -> 0 | L20: =SUM(G20*$R$7) -> 0 | M20: =SUM(H20*$R$8) -> 0 | N20: =SUM(I20:M20) -> 0
... A34: 30 | B34: 46203 | F34: =F33-E33+D34 -> 0 | G34: 0 | H34: 0 | I34: =SUM(D34*R33) -> 0 | J34: =SUM(E34*$R$5) -> 0 | K34: =SUM(F34*$R$6) -> 0 | L34: =SUM(G34*$R$7) -> 0 | M34: =SUM(H34*$R$8) -> 0 | N34: =SUM(I34:M34) -> 0
F35: =F34-E34+D35 -> 0 | G35: 0 | H35: 0 | I35: =SUM(D35*R34) -> 0 | J35: =SUM(E35*$R$5) -> 0 | K35: =SUM(F35*$R$6) -> 0 | L35: =SUM(G35*$R$7) -> 0 | M35: =SUM(H35*$R$8) -> 0 | N35: =SUM(I35:M35) -> 0
D36: =SUM(D5:D35) -> 0 | E36: =SUM(E5:E35) -> 0 | F36: =SUM(F5:F35) -> 0 | G36: =SUM(G5:G35) -> 0 | H36: =SUM(H5:H35) -> 0 | I36: =SUM(I5:I35) -> 0 | J36: =SUM(J5:J35) -> 0 | K36: =SUM(K5:K35) -> 0 | ... N36: =SUM(N5:N35) -> 0
N37: =N36*1.22 -> 0

Sheet Центрополимер Екатеринбург
A1: =N37 -> 0
A2: ="Отчет по хранению товара за " & TEXT(B5,"ММММ ГГГГ") -> Отчет по хранению товара за Июнь 2026
A3: № | B3: дата | D3: Выгрузка кол-во | E3: Загрузка кол-во | F3: Хранение | G3: переконсолидация (тонн) | H3: Паллетирование | I3: стоимость выгрузки | J3: стоимость загрузки | K3: стоимость хранения | L3: стоимость переконс. | M3: Стоимость паллетирования | N3: итого | Q3: Цены
Q4: Выгрузка | R4: 140
A5: 1 | B5: 46174 | F5: 0 | G5: 0 | H5: 0 | I5: =SUM(D5*$R$4) -> 0 | J5: =SUM(E5*$R$5) -> 0 | K5: =SUM(F5*$R$6) -> 0 | L5: =SUM(G5*$R$7) -> 0 | M5: =SUM(H5*$R$8) -> 0 | N5: =SUM(I5:M5) -> 0 | Q5: Загрузка | R5: 140
A6: 2 | B6: 46175 | F6: =F5-E5+D6 -> 0 | G6: 0 | H6: 0 | I6: =SUM(D6*$R$4) -> 0 | J6: =SUM(E6*$R$5) -> 0 | K6: =SUM(F6*$R$6) -> 0 | L6: =SUM(G6*$R$7) -> 0 | M6: =SUM(H6*$R$8) -> 0 | N6: =SUM(I6:M6) -> 0 | Q6: Хранение | R6: 20
A7: 3 | B7: 46176 | F7: =F6-E6+D7 -> 0 | G7: 0 | H7: 0 | I7: =SUM(D7*$R$4) -> 0 | J7: =SUM(E7*$R$5) -> 0 | K7: =SUM(F7*$R$6) -> 0 | L7: =SUM(G7*$R$7) -> 0 | M7: =SUM(H7*$R$8) -> 0 | N7: =SUM(I7:M7) -> 0 | Q7: Переконсолидация | R7: 950
A8: 4 | B8: 46177 | F8: =F7-E7+D8 -> 0 | G8: 0 | H8: 0 | I8: =SUM(D8*$R$4) -> 0 | J8: =SUM(E8*$R$5) -> 0 | K8: =SUM(F8*$R$6) -> 0 | L8: =SUM(G8*$R$7) -> 0 | M8: =SUM(H8*$R$8) -> 0 | N8: =SUM(I8:M8) -> 0 | Q8: Паллетирование | R8: 120
A9: 5 | B9: 46178 | F9: =F8-E8+D9 -> 0 | G9: 0 | H9: 0 | I9: =SUM(D9*$R$4) -> 0 | J9: =SUM(E9*$R$5) -> 0 | K9: =SUM(F9*$R$6) -> 0 | L9: =SUM(G9*$R$7) -> 0 | M9: =SUM(H9*$R$8) -> 0 | N9: =SUM(I9:M9) -> 0
A10: 6 | B10: 46179 | F10: =F9-E9+D10 -> 0 | G10: 0 | H10: 0 | I10: =SUM(D10*$R$4) -> 0 | J10: =SUM(E10*$R$5) -> 0 | K10: =SUM(F10*$R$6) -> 0 | L10: =SUM(G10*$R$7) -> 0 | M10: =SUM(H10*$R$8) -> 0 | N10: =SUM(I10:M10) -> 0
A11: 7 | B11: 46180 | F11: =F10-E10+D11 -> 0 | G11: 0 | H11: 0 | I11: =SUM(D11*$R$4) -> 0 | J11: =SUM(E11*$R$5) -> 0 | K11: =SUM(F11*$R$6) -> 0 | L11: =SUM(G11*$R$7) -> 0 | M11: =SUM(H11*$R$8) -> 0 | N11: =SUM(I11:M11) -> 0
A12: 8 | B12: 46181 | F12: =F11-E11+D12 -> 0 | G12: 0 | H12: 0 | I12: =SUM(D12*$R$4) -> 0 | J12: =SUM(E12*$R$5) -> 0 | K12: =SUM(F12*$R$6) -> 0 | L12: =SUM(G12*$R$7) -> 0 | M12: =SUM(H12*$R$8) -> 0 | N12: =SUM(I12:M12) -> 0
A13: 9 | B13: 46182 | F13: =F12-E12+D13 -> 0 | G13: 0 | H13: 0 | I13: =SUM(D13*$R$4) -> 0 | J13: =SUM(E13*$R$5) -> 0 | K13: =SUM(F13*$R$6) -> 0 | L13: =SUM(G13*$R$7) -> 0 | M13: =SUM(H13*$R$8) -> 0 | N13: =SUM(I13:M13) -> 0
A14: 10 | B14: 46183 | F14: =F13-E13+D14 -> 0 | G14: 0 | H14: 0 | I14: =SUM(D14*$R$4) -> 0 | J14: =SUM(E14*$R$5) -> 0 | K14: =SUM(F14*$R$6) -> 0 | L14: =SUM(G14*$R$7) -> 0 | M14: =SUM(H14*$R$8) -> 0 | N14: =SUM(I14:M14) -> 0
A15: 11 | B15: 46184 | F15: =F14-E14+D15 -> 0 | G15: 0 | H15: 0 | I15: =SUM(D15*$R$4) -> 0 | J15: =SUM(E15*$R$5) -> 0 | K15: =SUM(F15*$R$6) -> 0 | L15: =SUM(G15*$R$7) -> 0 | M15: =SUM(H15*$R$8) -> 0 | N15: =SUM(I15:M15) -> 0
A16: 12 | B16: 46185 | F16: =F15-E15+D16 -> 0 | G16: 0 | H16: 0 | I16: =SUM(D16*$R$4) -> 0 | J16: =SUM(E16*$R$5) -> 0 | K16: =SUM(F16*$R$6) -> 0 | L16: =SUM(G16*$R$7) -> 0 | M16: =SUM(H16*$R$8) -> 0 | N16: =SUM(I16:M16) -> 0
A17: 13 | B17: 46186 | F17: =F16-E16+D17 -> 0 | G17: 0 | H17: 0 | I17: =SUM(D17*$R$4) -> 0 | J17: =SUM(E17*$R$5) -> 0 | K17: =SUM(F17*$R$6) -> 0 | L17: =SUM(G17*$R$7) -> 0 | M17: =SUM(H17*$R$8) -> 0 | N17: =SUM(I17:M17) -> 0
A18: 14 | B18: 46187 | F18: =F17-E17+D18 -> 0 | G18: 0 | H18: 0 | I18: =SUM(D18*$R$4) -> 0 | J18: =SUM(E18*$R$5) -> 0 | K18: =SUM(F18*$R$6) -> 0 | L18: =SUM(G18*$R$7) -> 0 | M18: =SUM(H18*$R$8) -> 0 | N18: =SUM(I18:M18) -> 0
A19: 15 | B19: 46188 | F19: =F18-E18+D19 -> 0 | G19: 0 | H19: 0 | I19: =SUM(D19*$R$4) -> 0 | J19: =SUM(E19*$R$5) -> 0 | K19: =SUM(F19*$R$6) -> 0 | L19: =SUM(G19*$R$7) -> 0 | M19: =SUM(H19*$R$8) -> 0 | N19: =SUM(I19:M19) -> 0
A20: 16 | B20: 46189 | F20: =F19-E19+D20 -> 0 | G20: 0 | H20: 0 | I20: =SUM(D20*$R$4) -> 0 | J20: =SUM(E20*$R$5) -> 0 | K20: =SUM(F20*$R$6) -> 0 | L20: =SUM(G20*$R$7) -> 0 | M20: =SUM(H20*$R$8) -> 0 | N20: =SUM(I20:M20) -> 0
... A34: 30 | B34: 46203 | F34: =F33-E33+D34 -> 0 | G34: 0 | H34: 0 | I34: =SUM(D34*$R$4) -> 0 | J34: =SUM(E34*$R$5) -> 0 | K34: =SUM(F34*$R$6) -> 0 | L34: =SUM(G34*$R$7) -> 0 | M34: =SUM(H34*$R$8) -> 0 | N34: =SUM(I34:M34) -> 0
G35: 0 | H35: 0 | I35: =SUM(D35*$R$4) -> 0 | J35: =SUM(E35*$R$5) -> 0 | K35: =SUM(F35*$R$6) -> 0 | L35: =SUM(G35*$R$7) -> 0 | M35: =SUM(H35*$R$8) -> 0 | N35: =SUM(I35:M35) -> 0
D36: =SUM(D5:D35) -> 0 | E36: =SUM(E5:E35) -> 0 | F36: =SUM(F5:F35) -> 0 | G36: =SUM(G5:G35) -> 0 | H36: =SUM(H5:H35) -> 0 | I36: =SUM(I5:I35) -> 0 | J36: =SUM(J5:J35) -> 0 | K36: =SUM(K5:K35) -> 0 | ... N36: =SUM(N5:N35) -> 0
N37: =N36*1.22 -> 0

Sheet Центрополимер Новосибирск
A1: =N37 -> 0
A2: ="Отчет по хранению товара за " & TEXT(B5,"ММММ ГГГГ") -> Отчет по хранению товара за Июнь 2026
A3: № | B3: дата | D3: Выгрузка кол-во | E3: Загрузка кол-во | F3: Хранение | G3: переконсолидация (тонн) | H3: Паллетирование | I3: стоимость выгрузки | J3: стоимость загрузки | K3: стоимость хранения | L3: стоимость переконс. | M3: Стоимость паллетирования | N3: итого | Q3: Цены
Q4: Выгрузка | R4: 140
A5: 1 | B5: 46174 | D5: 0 | E5: 0 | F5: 0 | G5: 0 | H5: 0 | I5: =SUM(D5*$R$4) -> 0 | J5: =SUM(E5*$R$5) -> 0 | K5: =SUM(F5*$R$6) -> 0 | L5: =SUM(G5*$R$7) -> 0 | M5: =SUM(H5*$R$8) -> 0 | N5: =SUM(I5:M5) -> 0 | Q5: Загрузка | R5: 140
A6: 2 | B6: 46175 | D6: 0 | E6: 0 | F6: =F5-E5+D6 -> 0 | G6: 0 | H6: 0 | I6: =SUM(D6*$R$4) -> 0 | J6: =SUM(E6*$R$5) -> 0 | K6: =SUM(F6*$R$6) -> 0 | L6: =SUM(G6*$R$7) -> 0 | M6: =SUM(H6*$R$8) -> 0 | N6: =SUM(I6:M6) -> 0 | Q6: Хранение | R6: 26
A7: 3 | B7: 46176 | D7: 0 | E7: 0 | F7: =F6-E6+D7 -> 0 | G7: 0 | H7: 0 | I7: =SUM(D7*$R$4) -> 0 | J7: =SUM(E7*$R$5) -> 0 | K7: =SUM(F7*$R$6) -> 0 | L7: =SUM(G7*$R$7) -> 0 | M7: =SUM(H7*$R$8) -> 0 | N7: =SUM(I7:M7) -> 0 | Q7: Переконсолидация | R7: 950
A8: 4 | B8: 46177 | D8: 0 | E8: 0 | F8: =F7-E7+D8 -> 0 | G8: 0 | H8: 0 | I8: =SUM(D8*$R$4) -> 0 | J8: =SUM(E8*$R$5) -> 0 | K8: =SUM(F8*$R$6) -> 0 | L8: =SUM(G8*$R$7) -> 0 | M8: =SUM(H8*$R$8) -> 0 | N8: =SUM(I8:M8) -> 0 | Q8: Паллетирование | R8: 120
A9: 5 | B9: 46178 | D9: 0 | E9: 0 | F9: =F8-E8+D9 -> 0 | G9: 0 | H9: 0 | I9: =SUM(D9*$R$4) -> 0 | J9: =SUM(E9*$R$5) -> 0 | K9: =SUM(F9*$R$6) -> 0 | L9: =SUM(G9*$R$7) -> 0 | M9: =SUM(H9*$R$8) -> 0 | N9: =SUM(I9:M9) -> 0
A10: 6 | B10: 46179 | D10: 0 | E10: 0 | F10: =F9-E9+D10 -> 0 | G10: 0 | H10: 0 | I10: =SUM(D10*$R$4) -> 0 | J10: =SUM(E10*$R$5) -> 0 | K10: =SUM(F10*$R$6) -> 0 | L10: =SUM(G10*$R$7) -> 0 | M10: =SUM(H10*$R$8) -> 0 | N10: =SUM(I10:M10) -> 0
A11: 7 | B11: 46180 | D11: 0 | E11: 0 | F11: =F10-E10+D11 -> 0 | G11: 0 | H11: 0 | I11: =SUM(D11*$R$4) -> 0 | J11: =SUM(E11*$R$5) -> 0 | K11: =SUM(F11*$R$6) -> 0 | L11: =SUM(G11*$R$7) -> 0 | M11: =SUM(H11*$R$8) -> 0 | N11: =SUM(I11:M11) -> 0
A12: 8 | B12: 46181 | D12: 0 | E12: 0 | F12: =F11-E11+D12 -> 0 | G12: 0 | H12: 0 | I12: =SUM(D12*$R$4) -> 0 | J12: =SUM(E12*$R$5) -> 0 | K12: =SUM(F12*$R$6) -> 0 | L12: =SUM(G12*$R$7) -> 0 | M12: =SUM(H12*$R$8) -> 0 | N12: =SUM(I12:M12) -> 0
A13: 9 | B13: 46182 | D13: 0 | E13: 0 | F13: =F12-E12+D13 -> 0 | G13: 0 | H13: 0 | I13: =SUM(D13*$R$4) -> 0 | J13: =SUM(E13*$R$5) -> 0 | K13: =SUM(F13*$R$6) -> 0 | L13: =SUM(G13*$R$7) -> 0 | M13: =SUM(H13*$R$8) -> 0 | N13: =SUM(I13:M13) -> 0
A14: 10 | B14: 46183 | D14: 0 | E14: 0 | F14: =F13-E13+D14 -> 0 | G14: 0 | H14: 0 | I14: =SUM(D14*$R$4) -> 0 | J14: =SUM(E14*$R$5) -> 0 | K14: =SUM(F14*$R$6) -> 0 | L14: =SUM(G14*$R$7) -> 0 | M14: =SUM(H14*$R$8) -> 0 | N14: =SUM(I14:M14) -> 0
A15: 11 | B15: 46184 | D15: 0 | E15: 0 | F15: =F14-E14+D15 -> 0 | G15: 0 | H15: 0 | I15: =SUM(D15*$R$4) -> 0 | J15: =SUM(E15*$R$5) -> 0 | K15: =SUM(F15*$R$6) -> 0 | L15: =SUM(G15*$R$7) -> 0 | M15: =SUM(H15*$R$8) -> 0 | N15: =SUM(I15:M15) -> 0
A16: 12 | B16: 46185 | D16: 0 | E16: 0 | F16: =F15-E15+D16 -> 0 | G16: 0 | H16: 0 | I16: =SUM(D16*$R$4) -> 0 | J16: =SUM(E16*$R$5) -> 0 | K16: =SUM(F16*$R$6) -> 0 | L16: =SUM(G16*$R$7) -> 0 | M16: =SUM(H16*$R$8) -> 0 | N16: =SUM(I16:M16) -> 0
A17: 13 | B17: 46186 | D17: 0 | E17: 0 | F17: =F16-E16+D17 -> 0 | G17: 0 | H17: 0 | I17: =SUM(D17*$R$4) -> 0 | J17: =SUM(E17*$R$5) -> 0 | K17: =SUM(F17*$R$6) -> 0 | L17: =SUM(G17*$R$7) -> 0 | M17: =SUM(H17*$R$8) -> 0 | N17: =SUM(I17:M17) -> 0
A18: 14 | B18: 46187 | D18: 0 | E18: 0 | F18: =F17-E17+D18 -> 0 | G18: 0 | H18: 0 | I18: =SUM(D18*$R$4) -> 0 | J18: =SUM(E18*$R$5) -> 0 | K18: =SUM(F18*$R$6) -> 0 | L18: =SUM(G18*$R$7) -> 0 | M18: =SUM(H18*$R$8) -> 0 | N18: =SUM(I18:M18) -> 0
A19: 15 | B19: 46188 | D19: 0 | E19: 0 | F19: =F18-E18+D19 -> 0 | G19: 0 | H19: 0 | I19: =SUM(D19*$R$4) -> 0 | J19: =SUM(E19*$R$5) -> 0 | K19: =SUM(F19*$R$6) -> 0 | L19: =SUM(G19*$R$7) -> 0 | M19: =SUM(H19*$R$8) -> 0 | N19: =SUM(I19:M19) -> 0
A20: 16 | B20: 46189 | D20: 0 | E20: 0 | F20: =F19-E19+D20 -> 0 | G20: 0 | H20: 0 | I20: =SUM(D20*$R$4) -> 0 | J20: =SUM(E20*$R$5) -> 0 | K20: =SUM(F20*$R$6) -> 0 | L20: =SUM(G20*$R$7) -> 0 | M20: =SUM(H20*$R$8) -> 0 | N20: =SUM(I20:M20) -> 0
... A34: 30 | B34: 46203 | D34: 0 | E34: 0 | F34: =F33-E33+D34 -> 0 | G34: 0 | H34: 0 | I34: =SUM(D34*$R$4) -> 0 | J34: =SUM(E34*$R$5) -> 0 | K34: =SUM(F34*$R$6) -> 0 | L34: =SUM(G34*$R$7) -> 0 | M34: =SUM(H34*$R$8) -> 0 | N34: =SUM(I34:M34) -> 0
B35: 31.06.2026 | D35: 0 | E35: 0 | F35: =F34-E34+D35 -> 0 | G35: 0 | H35: 0 | I35: =SUM(D35*$R$4) -> 0 | J35: =SUM(E35*$R$5) -> 0 | K35: =SUM(F35*$R$6) -> 0 | L35: =SUM(G35*$R$7) -> 0 | M35: =SUM(H35*$R$8) -> 0 | N35: =SUM(I35:M35) -> 0
D36: =SUM(D5:D35) -> 0 | E36: =SUM(E5:E35) -> 0 | F36: =SUM(F5:F35) -> 0 | G36: =SUM(G5:G35) -> 0 | H36: =SUM(H5:H35) -> 0 | I36: =SUM(I5:I35) -> 0 | J36: =SUM(J5:J35) -> 0 | K36: =SUM(K5:K35) -> 0 | ... N36: =SUM(N5:N35) -> 0
N37: =N36*1.22 -> 0

Sheet Юг Полимер Зеленодольск
A1: =N37 -> 0
A2: ="Отчет по хранению товара за " & TEXT(B5,"ММММ ГГГГ") -> Отчет по хранению товара за Июнь 2026 | I2: Зеленодольск
A3: № | B3: дата | D3: Выгрузка кол-во | E3: Загрузка кол-во | F3: Хранение | G3: переконсолидация (тонн) | H3: Паллетирование | I3: стоимость выгрузки | J3: стоимость загрузки | K3: стоимость хранения | L3: стоимость переконс. | M3: Стоимость паллетирования | N3: итого | Q3: Цены
Q4: Выгрузка | R4: 140
A5: 1 | B5: 46174 | F5: 0 | G5: 0 | H5: 0 | I5: =SUM(D5*$R$4) -> 0 | J5: =SUM(E5*$R$5) -> 0 | K5: =SUM(F5*$R$6) -> 0 | L5: =SUM(G5*$R$7) -> 0 | M5: =SUM(H5*$R$8) -> 0 | N5: =SUM(I5:M5) -> 0 | Q5: Загрузка | R5: 140
A6: 2 | B6: 46175 | F6: =F5-E5+D6 -> 0 | G6: 0 | H6: 0 | I6: =SUM(D6*$R$4) -> 0 | J6: =SUM(E6*$R$5) -> 0 | K6: =SUM(F6*$R$6) -> 0 | L6: =SUM(G6*$R$7) -> 0 | M6: =SUM(H6*$R$8) -> 0 | N6: =SUM(I6:M6) -> 0 | Q6: Хранение | R6: 15
A7: 3 | B7: 46176 | F7: =F6-E6+D7 -> 0 | G7: 0 | H7: 0 | I7: =SUM(D7*$R$4) -> 0 | J7: =SUM(E7*$R$5) -> 0 | K7: =SUM(F7*$R$6) -> 0 | L7: =SUM(G7*$R$7) -> 0 | M7: =SUM(H7*$R$8) -> 0 | N7: =SUM(I7:M7) -> 0 | Q7: Переконсолидация | R7: 120
A8: 4 | B8: 46177 | F8: =F7-E7+D8 -> 0 | G8: 0 | H8: 0 | I8: =SUM(D8*$R$4) -> 0 | J8: =SUM(E8*$R$5) -> 0 | K8: =SUM(F8*$R$6) -> 0 | L8: =SUM(G8*$R$7) -> 0 | M8: =SUM(H8*$R$8) -> 0 | N8: =SUM(I8:M8) -> 0 | Q8: Паллетирование | R8: 150
A9: 5 | B9: 46178 | F9: =F8-E8+D9 -> 0 | G9: 0 | H9: 0 | I9: =SUM(D9*$R$4) -> 0 | J9: =SUM(E9*$R$5) -> 0 | K9: =SUM(F9*$R$6) -> 0 | L9: =SUM(G9*$R$7) -> 0 | M9: =SUM(H9*$R$8) -> 0 | N9: =SUM(I9:M9) -> 0
A10: 6 | B10: 46179 | F10: =F9-E9+D10 -> 0 | G10: 0 | H10: 0 | I10: =SUM(D10*$R$4) -> 0 | J10: =SUM(E10*$R$5) -> 0 | K10: =SUM(F10*$R$6) -> 0 | L10: =SUM(G10*$R$7) -> 0 | M10: =SUM(H10*$R$8) -> 0 | N10: =SUM(I10:M10) -> 0
A11: 7 | B11: 46180 | F11: =F10-E10+D11 -> 0 | G11: 0 | H11: 0 | I11: =SUM(D11*$R$4) -> 0 | J11: =SUM(E11*$R$5) -> 0 | K11: =SUM(F11*$R$6) -> 0 | L11: =SUM(G11*$R$7) -> 0 | M11: =SUM(H11*$R$8) -> 0 | N11: =SUM(I11:M11) -> 0
A12: 8 | B12: 46181 | F12: =F11-E11+D12 -> 0 | G12: 0 | H12: 0 | I12: =SUM(D12*$R$4) -> 0 | J12: =SUM(E12*$R$5) -> 0 | K12: =SUM(F12*$R$6) -> 0 | L12: =SUM(G12*$R$7) -> 0 | M12: =SUM(H12*$R$8) -> 0 | N12: =SUM(I12:M12) -> 0
A13: 9 | B13: 46182 | F13: =F12-E12+D13 -> 0 | G13: 0 | H13: 0 | I13: =SUM(D13*$R$4) -> 0 | J13: =SUM(E13*$R$5) -> 0 | K13: =SUM(F13*$R$6) -> 0 | L13: =SUM(G13*$R$7) -> 0 | M13: =SUM(H13*$R$8) -> 0 | N13: =SUM(I13:M13) -> 0
A14: 10 | B14: 46183 | F14: =F13-E13+D14 -> 0 | G14: 0 | H14: 0 | I14: =SUM(D14*$R$4) -> 0 | J14: =SUM(E14*$R$5) -> 0 | K14: =SUM(F14*$R$6) -> 0 | L14: =SUM(G14*$R$7) -> 0 | M14: =SUM(H14*$R$8) -> 0 | N14: =SUM(I14:M14) -> 0
A15: 11 | B15: 46184 | F15: =F14-E14+D15 -> 0 | G15: 0 | H15: 0 | I15: =SUM(D15*$R$4) -> 0 | J15: =SUM(E15*$R$5) -> 0 | K15: =SUM(F15*$R$6) -> 0 | L15: =SUM(G15*$R$7) -> 0 | M15: =SUM(H15*$R$8) -> 0 | N15: =SUM(I15:M15) -> 0
A16: 12 | B16: 46185 | F16: =F15-E15+D16 -> 0 | G16: 0 | H16: 0 | I16: =SUM(D16*$R$4) -> 0 | J16: =SUM(E16*$R$5) -> 0 | K16: =SUM(F16*$R$6) -> 0 | L16: =SUM(G16*$R$7) -> 0 | M16: =SUM(H16*$R$8) -> 0 | N16: =SUM(I16:M16) -> 0
A17: 13 | B17: 46186 | F17: =F16-E16+D17 -> 0 | G17: 0 | H17: 0 | I17: =SUM(D17*$R$4) -> 0 | J17: =SUM(E17*$R$5) -> 0 | K17: =SUM(F17*$R$6) -> 0 | L17: =SUM(G17*$R$7) -> 0 | M17: =SUM(H17*$R$8) -> 0 | N17: =SUM(I17:M17) -> 0
A18: 14 | B18: 46187 | F18: =F17-E17+D18 -> 0 | G18: 0 | H18: 0 | I18: =SUM(D18*$R$4) -> 0 | J18: =SUM(E18*$R$5) -> 0 | K18: =SUM(F18*$R$6) -> 0 | L18: =SUM(G18*$R$7) -> 0 | M18: =SUM(H18*$R$8) -> 0 | N18: =SUM(I18:M18) -> 0
A19: 15 | B19: 46188 | F19: =F18-E18+D19 -> 0 | G19: 0 | H19: 0 | I19: =SUM(D19*$R$4) -> 0 | J19: =SUM(E19*$R$5) -> 0 | K19: =SUM(F19*$R$6) -> 0 | L19: =SUM(G19*$R$7) -> 0 | M19: =SUM(H19*$R$8) -> 0 | N19: =SUM(I19:M19) -> 0
A20: 16 | B20: 46189 | F20: =F19-E19+D20 -> 0 | G20: 0 | H20: 0 | I20: =SUM(D20*$R$4) -> 0 | J20: =SUM(E20*$R$5) -> 0 | K20: =SUM(F20*$R$6) -> 0 | L20: =SUM(G20*$R$7) -> 0 | M20: =SUM(H20*$R$8) -> 0 | N20: =SUM(I20:M20) -> 0
... A34: 30 | B34: 46203 | F34: =F33-E33+D34 -> 0 | G34: 0 | H34: 0 | I34: =SUM(D34*$R$4) -> 0 | J34: =SUM(E34*$R$5) -> 0 | K34: =SUM(F34*$R$6) -> 0 | L34: =SUM(G34*$R$7) -> 0 | M34: =SUM(H34*$R$8) -> 0 | N34: =SUM(I34:M34) -> 0
G35: 0 | H35: 0 | I35: =SUM(D35*$R$4) -> 0 | J35: =SUM(E35*$R$5) -> 0 | K35: =SUM(F35*$R$6) -> 0 | L35: =SUM(G35*$R$7) -> 0 | M35: =SUM(H35*$R$8) -> 0 | N35: =SUM(I35:M35) -> 0
D36: =SUM(D5:D35) -> 0 | E36: =SUM(E5:E35) -> 0 | F36: =SUM(F5:F35) -> 0 | G36: =SUM(G5:G35) -> 0 | H36: =SUM(H5:H35) -> 0 | I36: =SUM(I5:I35) -> 0 | J36: =SUM(J5:J35) -> 0 | K36: =SUM(K5:K35) -> 0 | ... N36: =SUM(N5:N35) -> 0
N37: =N36*1.22 -> 0

Sheet Юг Полимер Новикова-Прибоя
A1: =N37 -> 0
A2: ="Отчет по хранению товара за " & TEXT(B5,"ММММ ГГГГ") -> Отчет по хранению товара за Июнь 2026 | I2: Новикова
A3: № | B3: дата | D3: Выгрузка кол-во | E3: Загрузка кол-во | F3: Хранение | G3: переконсолидация (тонн) | H3: Паллетирование | I3: стоимость выгрузки | J3: стоимость загрузки | K3: стоимость хранения | L3: стоимость переконс. | M3: Стоимость паллетирования | N3: итого | Q3: Цены
Q4: Выгрузка | R4: 120
A5: 1 | B5: 46174 | F5: 0 | G5: 0 | H5: 0 | I5: =SUM(D5*$R$4) -> 0 | J5: =SUM(E5*$R$5) -> 0 | K5: =SUM(F5*$R$6) -> 0 | L5: =SUM(G5*$R$7) -> 0 | M5: =SUM(H5*$R$8) -> 0 | N5: =SUM(I5:M5) -> 0 | Q5: Загрузка | R5: 120
A6: 2 | B6: 46175 | F6: =F5-E5+D6 -> 0 | G6: 0 | H6: 0 | I6: =SUM(D6*$R$4) -> 0 | J6: =SUM(E6*$R$5) -> 0 | K6: =SUM(F6*$R$6) -> 0 | L6: =SUM(G6*$R$7) -> 0 | M6: =SUM(H6*$R$8) -> 0 | N6: =SUM(I6:M6) -> 0 | Q6: Хранение | R6: 18
A7: 3 | B7: 46176 | F7: =F6-E6+D7 -> 0 | G7: 0 | H7: 0 | I7: =SUM(D7*$R$4) -> 0 | J7: =SUM(E7*$R$5) -> 0 | K7: =SUM(F7*$R$6) -> 0 | L7: =SUM(G7*$R$7) -> 0 | M7: =SUM(H7*$R$8) -> 0 | N7: =SUM(I7:M7) -> 0 | Q7: Переконсолидация | R7: 950
A8: 4 | B8: 46177 | F8: =F7-E7+D8 -> 0 | G8: 0 | H8: 0 | I8: =SUM(D8*$R$4) -> 0 | J8: =SUM(E8*$R$5) -> 0 | K8: =SUM(F8*$R$6) -> 0 | L8: =SUM(G8*$R$7) -> 0 | M8: =SUM(H8*$R$8) -> 0 | N8: =SUM(I8:M8) -> 0 | Q8: Паллетирование | R8: 120
A9: 5 | B9: 46178 | F9: =F8-E8+D9 -> 0 | G9: 0 | H9: 0 | I9: =SUM(D9*$R$4) -> 0 | J9: =SUM(E9*$R$5) -> 0 | K9: =SUM(F9*$R$6) -> 0 | L9: =SUM(G9*$R$7) -> 0 | M9: =SUM(H9*$R$8) -> 0 | N9: =SUM(I9:M9) -> 0
A10: 6 | B10: 46179 | F10: =F9-E9+D10 -> 0 | G10: 0 | H10: 0 | I10: =SUM(D10*$R$4) -> 0 | J10: =SUM(E10*$R$5) -> 0 | K10: =SUM(F10*$R$6) -> 0 | L10: =SUM(G10*$R$7) -> 0 | M10: =SUM(H10*$R$8) -> 0 | N10: =SUM(I10:M10) -> 0
A11: 7 | B11: 46180 | F11: =F10-E10+D11 -> 0 | G11: 0 | H11: 0 | I11: =SUM(D11*$R$4) -> 0 | J11: =SUM(E11*$R$5) -> 0 | K11: =SUM(F11*$R$6) -> 0 | L11: =SUM(G11*$R$7) -> 0 | M11: =SUM(H11*$R$8) -> 0 | N11: =SUM(I11:M11) -> 0
A12: 8 | B12: 46181 | F12: =F11-E11+D12 -> 0 | G12: 0 | H12: 0 | I12: =SUM(D12*$R$4) -> 0 | J12: =SUM(E12*$R$5) -> 0 | K12: =SUM(F12*$R$6) -> 0 | L12: =SUM(G12*$R$7) -> 0 | M12: =SUM(H12*$R$8) -> 0 | N12: =SUM(I12:M12) -> 0
A13: 9 | B13: 46182 | F13: =F12-E12+D13 -> 0 | G13: 0 | H13: 0 | I13: =SUM(D13*$R$4) -> 0 | J13: =SUM(E13*$R$5) -> 0 | K13: =SUM(F13*$R$6) -> 0 | L13: =SUM(G13*$R$7) -> 0 | M13: =SUM(H13*$R$8) -> 0 | N13: =SUM(I13:M13) -> 0
A14: 10 | B14: 46183 | F14: =F13-E13+D14 -> 0 | G14: 0 | H14: 0 | I14: =SUM(D14*$R$4) -> 0 | J14: =SUM(E14*$R$5) -> 0 | K14: =SUM(F14*$R$6) -> 0 | L14: =SUM(G14*$R$7) -> 0 | M14: =SUM(H14*$R$8) -> 0 | N14: =SUM(I14:M14) -> 0
A15: 11 | B15: 46184 | F15: =F14-E14+D15 -> 0 | G15: 0 | H15: 0 | I15: =SUM(D15*$R$4) -> 0 | J15: =SUM(E15*$R$5) -> 0 | K15: =SUM(F15*$R$6) -> 0 | L15: =SUM(G15*$R$7) -> 0 | M15: =SUM(H15*$R$8) -> 0 | N15: =SUM(I15:M15) -> 0
A16: 12 | B16: 46185 | F16: =F15-E15+D16 -> 0 | G16: 0 | H16: 0 | I16: =SUM(D16*$R$4) -> 0 | J16: =SUM(E16*$R$5) -> 0 | K16: =SUM(F16*$R$6) -> 0 | L16: =SUM(G16*$R$7) -> 0 | M16: =SUM(H16*$R$8) -> 0 | N16: =SUM(I16:M16) -> 0
A17: 13 | B17: 46186 | F17: =F16-E16+D17 -> 0 | G17: 0 | H17: 0 | I17: =SUM(D17*$R$4) -> 0 | J17: =SUM(E17*$R$5) -> 0 | K17: =SUM(F17*$R$6) -> 0 | L17: =SUM(G17*$R$7) -> 0 | M17: =SUM(H17*$R$8) -> 0 | N17: =SUM(I17:M17) -> 0
A18: 14 | B18: 46187 | F18: =F17-E17+D18 -> 0 | G18: 0 | H18: 0 | I18: =SUM(D18*$R$4) -> 0 | J18: =SUM(E18*$R$5) -> 0 | K18: =SUM(F18*$R$6) -> 0 | L18: =SUM(G18*$R$7) -> 0 | M18: =SUM(H18*$R$8) -> 0 | N18: =SUM(I18:M18) -> 0
A19: 15 | B19: 46188 | F19: =F18-E18+D19 -> 0 | G19: 0 | H19: 0 | I19: =SUM(D19*$R$4) -> 0 | J19: =SUM(E19*$R$5) -> 0 | K19: =SUM(F19*$R$6) -> 0 | L19: =SUM(G19*$R$7) -> 0 | M19: =SUM(H19*$R$8) -> 0 | N19: =SUM(I19:M19) -> 0
A20: 16 | B20: 46189 | F20: =F19-E19+D20 -> 0 | G20: 0 | H20: 0 | I20: =SUM(D20*$R$4) -> 0 | J20: =SUM(E20*$R$5) -> 0 | K20: =SUM(F20*$R$6) -> 0 | L20: =SUM(G20*$R$7) -> 0 | M20: =SUM(H20*$R$8) -> 0 | N20: =SUM(I20:M20) -> 0
... A34: 30 | B34: 46203 | F34: =F33-E33+D34 -> 0 | G34: 0 | H34: 0 | I34: =SUM(D34*$R$4) -> 0 | J34: =SUM(E34*$R$5) -> 0 | K34: =SUM(F34*$R$6) -> 0 | L34: =SUM(G34*$R$7) -> 0 | M34: =SUM(H34*$R$8) -> 0 | N34: =SUM(I34:M34) -> 0
G35: 0 | H35: 0 | I35: =SUM(D35*$R$4) -> 0 | J35: =SUM(E35*$R$5) -> 0 | K35: =SUM(F35*$R$6) -> 0 | L35: =SUM(G35*$R$7) -> 0 | M35: =SUM(H35*$R$8) -> 0 | N35: =SUM(I35:M35) -> 0
D36: =SUM(D5:D35) -> 0 | E36: =SUM(E5:E35) -> 0 | F36: =SUM(F5:F35) -> 0 | G36: =SUM(G5:G35) -> 0 | H36: =SUM(H5:H35) -> 0 | I36: =SUM(I5:I35) -> 0 | J36: =SUM(J5:J35) -> 0 | K36: =SUM(K5:K35) -> 0 | ... N36: =SUM(N5:N35) -> 0
N37: =N36*1.22 -> 0

Sheet Юг Полимер Баумана
A1: =N37 -> 12846.6
A2: ="Отчет по хранению товара за " & TEXT(B5,"ММММ ГГГГ") -> Отчет по хранению товара за Июнь 2026 | I2: Баумана
A3: № | B3: дата | D3: Выгрузка кол-во | E3: Загрузка кол-во | F3: Хранение | G3: переконсолидация (тонн) | H3: Паллетирование | I3: стоимость выгрузки | J3: стоимость загрузки | K3: стоимость хранения | L3: стоимость переконс. | M3: Стоимость паллетирования | N3: итого | Q3: Цены
Q4: Выгрузка | R4: 140
A5: 1 | B5: 46174 | D5: 0 | E5: 0 | F5: 0 | G5: 0 | H5: 0 | I5: =SUM(D5*$R$4) -> 0 | J5: =SUM(E5*$R$5) -> 0 | K5: =SUM(F5*$R$6) -> 0 | L5: =SUM(G5*$R$7) -> 0 | M5: =SUM(H5*$R$8) -> 0 | N5: =SUM(I5:M5) -> 0 | Q5: Загрузка | R5: 140
A6: 2 | B6: 46175 | D6: 0 | E6: 0 | F6: =F5-E5+D6 -> 0 | G6: 0 | H6: 0 | I6: =SUM(D6*$R$4) -> 0 | J6: =SUM(E6*$R$5) -> 0 | K6: =SUM(F6*$R$6) -> 0 | L6: =SUM(G6*$R$7) -> 0 | M6: =SUM(H6*$R$8) -> 0 | N6: =SUM(I6:M6) -> 0 | Q6: Хранение | R6: 26
A7: 3 | B7: 46176 | D7: 0 | E7: 0 | F7: =F6-E6+D7 -> 0 | G7: 0 | H7: 0 | I7: =SUM(D7*$R$4) -> 0 | J7: =SUM(E7*$R$5) -> 0 | K7: =SUM(F7*$R$6) -> 0 | L7: =SUM(G7*$R$7) -> 0 | M7: =SUM(H7*$R$8) -> 0 | N7: =SUM(I7:M7) -> 0 | Q7: Переконсолидация | R7: 950
A8: 4 | B8: 46177 | D8: 0 | E8: 0 | F8: =F7-E7+D8 -> 0 | G8: 0 | H8: 0 | I8: =SUM(D8*$R$4) -> 0 | J8: =SUM(E8*$R$5) -> 0 | K8: =SUM(F8*$R$6) -> 0 | L8: =SUM(G8*$R$7) -> 0 | M8: =SUM(H8*$R$8) -> 0 | N8: =SUM(I8:M8) -> 0 | Q8: Паллетирование | R8: 120
A9: 5 | B9: 46178 | D9: 0 | E9: 0 | F9: =F8-E8+D9 -> 0 | G9: 0 | H9: 0 | I9: =SUM(D9*$R$4) -> 0 | J9: =SUM(E9*$R$5) -> 0 | K9: =SUM(F9*$R$6) -> 0 | L9: =SUM(G9*$R$7) -> 0 | M9: =SUM(H9*$R$8) -> 0 | N9: =SUM(I9:M9) -> 0
A10: 6 | B10: 46179 | D10: 0 | E10: 0 | F10: =F9-E9+D10 -> 0 | G10: 0 | H10: 0 | I10: =SUM(D10*$R$4) -> 0 | J10: =SUM(E10*$R$5) -> 0 | K10: =SUM(F10*$R$6) -> 0 | L10: =SUM(G10*$R$7) -> 0 | M10: =SUM(H10*$R$8) -> 0 | N10: =SUM(I10:M10) -> 0
A11: 7 | B11: 46180 | D11: 0 | E11: 0 | F11: =F10-E10+D11 -> 0 | G11: 0 | H11: 0 | I11: =SUM(D11*$R$4) -> 0 | J11: =SUM(E11*$R$5) -> 0 | K11: =SUM(F11*$R$6) -> 0 | L11: =SUM(G11*$R$7) -> 0 | M11: =SUM(H11*$R$8) -> 0 | N11: =SUM(I11:M11) -> 0
A12: 8 | B12: 46181 | D12: 0 | E12: 0 | F12: =F11-E11+D12 -> 0 | G12: 0 | H12: 0 | I12: =SUM(D12*$R$4) -> 0 | J12: =SUM(E12*$R$5) -> 0 | K12: =SUM(F12*$R$6) -> 0 | L12: =SUM(G12*$R$7) -> 0 | M12: =SUM(H12*$R$8) -> 0 | N12: =SUM(I12:M12) -> 0
A13: 9 | B13: 46182 | D13: 0 | E13: 0 | F13: =F12-E12+D13 -> 0 | G13: 0 | H13: 0 | I13: =SUM(D13*$R$4) -> 0 | J13: =SUM(E13*$R$5) -> 0 | K13: =SUM(F13*$R$6) -> 0 | L13: =SUM(G13*$R$7) -> 0 | M13: =SUM(H13*$R$8) -> 0 | N13: =SUM(I13:M13) -> 0
A14: 10 | B14: 46183 | D14: 0 | E14: 0 | F14: =F13-E13+D14 -> 0 | G14: 0 | H14: 0 | I14: =SUM(D14*$R$4) -> 0 | J14: =SUM(E14*$R$5) -> 0 | K14: =SUM(F14*$R$6) -> 0 | L14: =SUM(G14*$R$7) -> 0 | M14: =SUM(H14*$R$8) -> 0 | N14: =SUM(I14:M14) -> 0
A15: 11 | B15: 46184 | D15: 0 | E15: 0 | F15: =F14-E14+D15 -> 0 | G15: 0 | H15: 0 | I15: =SUM(D15*$R$4) -> 0 | J15: =SUM(E15*$R$5) -> 0 | K15: =SUM(F15*$R$6) -> 0 | L15: =SUM(G15*$R$7) -> 0 | M15: =SUM(H15*$R$8) -> 0 | N15: =SUM(I15:M15) -> 0
A16: 12 | B16: 46185 | D16: 0 | E16: 0 | F16: =F15-E15+D16 -> 0 | G16: 0 | H16: 0 | I16: =SUM(D16*$R$4) -> 0 | J16: =SUM(E16*$R$5) -> 0 | K16: =SUM(F16*$R$6) -> 0 | L16: =SUM(G16*$R$7) -> 0 | M16: =SUM(H16*$R$8) -> 0 | N16: =SUM(I16:M16) -> 0
A17: 13 | B17: 46186 | D17: 0 | E17: 0 | F17: =F16-E16+D17 -> 0 | G17: 0 | H17: 0 | I17: =SUM(D17*$R$4) -> 0 | J17: =SUM(E17*$R$5) -> 0 | K17: =SUM(F17*$R$6) -> 0 | L17: =SUM(G17*$R$7) -> 0 | M17: =SUM(H17*$R$8) -> 0 | N17: =SUM(I17:M17) -> 0
A18: 14 | B18: 46187 | D18: 0 | E18: 0 | F18: =F17-E17+D18 -> 0 | G18: 0 | H18: 0 | I18: =SUM(D18*$R$4) -> 0 | J18: =SUM(E18*$R$5) -> 0 | K18: =SUM(F18*$R$6) -> 0 | L18: =SUM(G18*$R$7) -> 0 | M18: =SUM(H18*$R$8) -> 0 | N18: =SUM(I18:M18) -> 0
A19: 15 | B19: 46188 | D19: 0 | E19: 0 | F19: =F18-E18+D19 -> 0 | G19: 0 | H19: 0 | I19: =SUM(D19*$R$4) -> 0 | J19: =SUM(E19*$R$5) -> 0 | K19: =SUM(F19*$R$6) -> 0 | L19: =SUM(G19*$R$7) -> 0 | M19: =SUM(H19*$R$8) -> 0 | N19: =SUM(I19:M19) -> 0
A20: 16 | B20: 46189 | D20: 0 | E20: 0 | F20: =F19-E19+D20 -> 0 | G20: 0 | H20: 0 | I20: =SUM(D20*$R$4) -> 0 | J20: =SUM(E20*$R$5) -> 0 | K20: =SUM(F20*$R$6) -> 0 | L20: =SUM(G20*$R$7) -> 0 | M20: =SUM(H20*$R$8) -> 0 | N20: =SUM(I20:M20) -> 0
... A33: 29 | B33: 46202 | D33: 0 | E33: 0 | F33: =F32-E32+D33 -> 0 | G33: 0 | H33: 0 | I33: =SUM(D33*$R$4) -> 0 | J33: =SUM(E33*$R$5) -> 0 | K33: =SUM(F33*$R$6) -> 0 | L33: =SUM(G33*$R$7) -> 0 | M33: =SUM(H33*$R$8) -> 0 | N33: =SUM(I33:M33) -> 0
A34: 30 | B34: 46203 | D34: 0 | E34: 0 | F34: 405 | G34: 0 | H34: 0 | I34: =SUM(D34*$R$4) -> 0 | J34: =SUM(E34*$R$5) -> 0 | K34: =SUM(F34*$R$6) -> 10530 | L34: =SUM(G34*$R$7) -> 0 | M34: =SUM(H34*$R$8) -> 0 | N34: =SUM(I34:M34) -> 10530
G35: 0 | H35: 0 | I35: =SUM(D35*$R$4) -> 0 | J35: =SUM(E35*$R$5) -> 0 | K35: =SUM(F35*$R$6) -> 0 | L35: =SUM(G35*$R$7) -> 0 | M35: =SUM(H35*$R$8) -> 0 | N35: =SUM(I35:M35) -> 0
D36: =SUM(D5:D35) -> 0 | E36: =SUM(E5:E35) -> 0 | F36: =SUM(F5:F35) -> 405 | G36: =SUM(G5:G35) -> 0 | H36: =SUM(H5:H35) -> 0 | I36: =SUM(I5:I35) -> 0 | J36: =SUM(J5:J35) -> 0 | K36: =SUM(K5:K35) -> 10530 | ... N36: =SUM(N5:N35) -> 10530
N37: =N36*1.22 -> 12846.6

Sheet Приоритет Казань_Автосервисная
A1: =N37 -> 0
A2: ="Отчет по хранению товара за " & TEXT(B5,"ММММ ГГГГ") -> Отчет по хранению товара за Июнь 2026 | I2: Казань_Автосервисная
A3: № | B3: дата | D3: Выгрузка кол-во | E3: Загрузка кол-во | F3: Хранение | G3: переконсолидация (тонн) | H3: Паллетирование | I3: стоимость выгрузки | J3: стоимость загрузки | K3: стоимость хранения | L3: стоимость переконс. | M3: Стоимость паллетирования | N3: итого | Q3: Цены
Q4: Выгрузка | R4: 144
A5: 1 | B5: 46174 | F5: 0 | G5: 0 | H5: 0 | I5: =SUM(D5*$R$4) -> 0 | J5: =SUM(E5*$R$5) -> 0 | K5: =SUM(F5*$R$6) -> 0 | L5: =SUM(G5*$R$7) -> 0 | M5: =SUM(H5*$R$8) -> 0 | N5: =SUM(I5:M5) -> 0 | Q5: Загрузка | R5: 144
A6: 2 | B6: 46175 | F6: =F5+D6-E5 -> 0 | G6: 0 | H6: 0 | I6: =SUM(D6*$R$4) -> 0 | J6: =SUM(E6*$R$5) -> 0 | K6: =SUM(F6*$R$6) -> 0 | L6: =SUM(G6*$R$7) -> 0 | M6: =SUM(H6*$R$8) -> 0 | N6: =SUM(I6:M6) -> 0 | Q6: Хранение | R6: 42
A7: 3 | B7: 46176 | F7: =F6+D7-E6 -> 0 | G7: 0 | H7: 0 | I7: =SUM(D7*$R$4) -> 0 | J7: =SUM(E7*$R$5) -> 0 | K7: =SUM(F7*$R$6) -> 0 | L7: =SUM(G7*$R$7) -> 0 | M7: =SUM(H7*$R$8) -> 0 | N7: =SUM(I7:M7) -> 0 | Q7: Переконсолидация | R7: 1200
A8: 4 | B8: 46177 | F8: =F7+D8-E7 -> 0 | G8: 0 | H8: 0 | I8: =SUM(D8*$R$4) -> 0 | J8: =SUM(E8*$R$5) -> 0 | K8: =SUM(F8*$R$6) -> 0 | L8: =SUM(G8*$R$7) -> 0 | M8: =SUM(H8*$R$8) -> 0 | N8: =SUM(I8:M8) -> 0 | Q8: Паллетирование | R8: 240
