Workbook

Sheet Лист1

Sheet Биаксплен Новосибирск
A1: =T37 -> 461628.96
A2: ="Отчет по хранению товара за " & TEXT(B5,"ММММ ГГГГ") -> Отчет по хранению товара за Январь 2026
A3: № | B3: дата | D3: Выгрузка кол-во | E3: Загрузка кол-во | F3: Хранение | G3: Резервирование 70 т | H3: Мин. Суточный резерв 0 т | I3: переконсолидация (тонн) | J3: Паллетирование | K3: Ночная загруска выгрузка | L3: стоимость ночной загруски | M3: стоимость выгрузки | N3: стоимость загрузки | O3: стоимость хранения | P3: Стоимость резервирования | Q3: Стоимость мин.суточной бработки | R3: стоимость переконс. | S3: Стоимость паллетирования | T3: итого
A5: 1 | B5: 46023 | F5: =78.4245+D5-E5 -> 78.4245 | G5: =IF(OR(B5="",NOT(ISERROR(SEARCH("KPI",$A$2))),NOT(ISERROR(SEARCH("Полиом",$A$2)))),0,IF(70-F5<=0,0,70-F5)) -> 0 | L5: =SUM(K5*240) -> 0 | M5: =SUM(D5*120) -> 0 | N5: =SUM(E5*120) -> 0 | O5: =SUM(F5*54) -> 4234.923 | P5: =SUM(G5*54) -> 0 | Q5: =SUM(H5*120) -> 0 | R5: =SUM(I5*1000) -> 0 | S5: =SUM(J5*140) -> 0 | T5: =SUM(L5:S5) -> 4234.923
A6: 2 | B6: 46024 | F6: =F5-E6+D6 -> 78.4245 | G6: =IF(OR(B6="",NOT(ISERROR(SEARCH("KPI",$A$2))),NOT(ISERROR(SEARCH("Полиом",$A$2)))),0,IF(70-F6<=0,0,70-F6)) -> 0 | L6: =SUM(K6*240) -> 0 | M6: =SUM(D6*120) -> 0 | N6: =SUM(E6*120) -> 0 | O6: =SUM(F6*54) -> 4234.923 | P6: =SUM(G6*54) -> 0 | Q6: =SUM(H6*120) -> 0 | R6: =SUM(I6*1000) -> 0 | S6: =SUM(J6*140) -> 0 | T6: =SUM(L6:S6) -> 4234.923
A7: 3 | B7: 46025 | F7: =F6-E7+D7 -> 78.4245 | G7: =IF(OR(B7="",NOT(ISERROR(SEARCH("KPI",$A$2))),NOT(ISERROR(SEARCH("Полиом",$A$2)))),0,IF(70-F7<=0,0,70-F7)) -> 0 | L7: =SUM(K7*240) -> 0 | M7: =SUM(D7*120) -> 0 | N7: =SUM(E7*120) -> 0 | O7: =SUM(F7*54) -> 4234.923 | P7: =SUM(G7*54) -> 0 | Q7: =SUM(H7*120) -> 0 | R7: =SUM(I7*1000) -> 0 | S7: =SUM(J7*140) -> 0 | T7: =SUM(L7:S7) -> 4234.923
A8: 4 | B8: 46026 | F8: =F7-E8+D8 -> 78.4245 | G8: =IF(OR(B8="",NOT(ISERROR(SEARCH("KPI",$A$2))),NOT(ISERROR(SEARCH("Полиом",$A$2)))),0,IF(70-F8<=0,0,70-F8)) -> 0 | L8: =SUM(K8*240) -> 0 | M8: =SUM(D8*120) -> 0 | N8: =SUM(E8*120) -> 0 | O8: =SUM(F8*54) -> 4234.923 | P8: =SUM(G8*54) -> 0 | Q8: =SUM(H8*120) -> 0 | R8: =SUM(I8*1000) -> 0 | S8: =SUM(J8*140) -> 0 | T8: =SUM(L8:S8) -> 4234.923
A9: 5 | B9: 46027 | F9: =F8-E9+D9 -> 78.4245 | G9: =IF(OR(B9="",NOT(ISERROR(SEARCH("KPI",$A$2))),NOT(ISERROR(SEARCH("Полиом",$A$2)))),0,IF(70-F9<=0,0,70-F9)) -> 0 | L9: =SUM(K9*240) -> 0 | M9: =SUM(D9*120) -> 0 | N9: =SUM(E9*120) -> 0 | O9: =SUM(F9*54) -> 4234.923 | P9: =SUM(G9*54) -> 0 | Q9: =SUM(H9*120) -> 0 | R9: =SUM(I9*1000) -> 0 | S9: =SUM(J9*140) -> 0 | T9: =SUM(L9:S9) -> 4234.923
A10: 6 | B10: 46028 | D10: 71.7454 | F10: =F9-E10+D10 -> 150.1699 | G10: =IF(OR(B10="",NOT(ISERROR(SEARCH("KPI",$A$2))),NOT(ISERROR(SEARCH("Полиом",$A$2)))),0,IF(70-F10<=0,0,70-F10)) -> 0 | L10: =SUM(K10*240) -> 0 | M10: =SUM(D10*120) -> 8609.448 | N10: =SUM(E10*120) -> 0 | O10: =SUM(F10*54) -> 8109.1746 | P10: =SUM(G10*54) -> 0 | Q10: =SUM(H10*120) -> 0 | R10: =SUM(I10*1000) -> 0 | S10: =SUM(J10*140) -> 0 | T10: =SUM(L10:S10) -> 16718.623
A11: 7 | B11: 46029 | D11: 71.5785 | F11: =F10-E11+D11 -> 221.7484 | G11: =IF(OR(B11="",NOT(ISERROR(SEARCH("KPI",$A$2))),NOT(ISERROR(SEARCH("Полиом",$A$2)))),0,IF(70-F11<=0,0,70-F11)) -> 0 | L11: =SUM(K11*240) -> 0 | M11: =SUM(D11*120) -> 8589.42 | N11: =SUM(E11*120) -> 0 | O11: =SUM(F11*54) -> 11974.414 | P11: =SUM(G11*54) -> 0 | Q11: =SUM(H11*120) -> 0 | R11: =SUM(I11*1000) -> 0 | S11: =SUM(J11*140) -> 0 | T11: =SUM(L11:S11) -> 20563.834
A12: 8 | B12: 46030 | D12: 35.6269 | F12: =F11-E12+D12 -> 257.3753 | G12: =IF(OR(B12="",NOT(ISERROR(SEARCH("KPI",$A$2))),NOT(ISERROR(SEARCH("Полиом",$A$2)))),0,IF(70-F12<=0,0,70-F12)) -> 0 | L12: =SUM(K12*240) -> 0 | M12: =SUM(D12*120) -> 4275.228 | N12: =SUM(E12*120) -> 0 | O12: =SUM(F12*54) -> 13898.266 | P12: =SUM(G12*54) -> 0 | Q12: =SUM(H12*120) -> 0 | R12: =SUM(I12*1000) -> 0 | S12: =SUM(J12*140) -> 0 | T12: =SUM(L12:S12) -> 18173.494
A13: 9 | B13: 46031 | F13: =F12-E13+D13 -> 257.3753 | G13: =IF(OR(B13="",NOT(ISERROR(SEARCH("KPI",$A$2))),NOT(ISERROR(SEARCH("Полиом",$A$2)))),0,IF(70-F13<=0,0,70-F13)) -> 0 | L13: =SUM(K13*240) -> 0 | M13: =SUM(D13*120) -> 0 | N13: =SUM(E13*120) -> 0 | O13: =SUM(F13*54) -> 13898.266 | P13: =SUM(G13*54) -> 0 | Q13: =SUM(H13*120) -> 0 | R13: =SUM(I13*1000) -> 0 | S13: =SUM(J13*140) -> 0 | T13: =SUM(L13:S13) -> 13898.266
A14: 10 | B14: 46032 | F14: =F13-E14+D14 -> 257.3753 | G14: =IF(OR(B14="",NOT(ISERROR(SEARCH("KPI",$A$2))),NOT(ISERROR(SEARCH("Полиом",$A$2)))),0,IF(70-F14<=0,0,70-F14)) -> 0 | L14: =SUM(K14*240) -> 0 | M14: =SUM(D14*120) -> 0 | N14: =SUM(E14*120) -> 0 | O14: =SUM(F14*54) -> 13898.266 | P14: =SUM(G14*54) -> 0 | Q14: =SUM(H14*120) -> 0 | R14: =SUM(I14*1000) -> 0 | S14: =SUM(J14*140) -> 0 | T14: =SUM(L14:S14) -> 13898.266
A15: 11 | B15: 46033 | F15: =F14-E15+D15 -> 257.3753 | G15: =IF(OR(B15="",NOT(ISERROR(SEARCH("KPI",$A$2))),NOT(ISERROR(SEARCH("Полиом",$A$2)))),0,IF(70-F15<=0,0,70-F15)) -> 0 | L15: =SUM(K15*240) -> 0 | M15: =SUM(D15*120) -> 0 | N15: =SUM(E15*120) -> 0 | O15: =SUM(F15*54) -> 13898.266 | P15: =SUM(G15*54) -> 0 | Q15: =SUM(H15*120) -> 0 | R15: =SUM(I15*1000) -> 0 | S15: =SUM(J15*140) -> 0 | T15: =SUM(L15:S15) -> 13898.266
A16: 12 | B16: 46034 | D16: 18.3508 | F16: =F15-E16+D16 -> 275.7261 | G16: =IF(OR(B16="",NOT(ISERROR(SEARCH("KPI",$A$2))),NOT(ISERROR(SEARCH("Полиом",$A$2)))),0,IF(70-F16<=0,0,70-F16)) -> 0 | L16: =SUM(K16*240) -> 0 | M16: =SUM(D16*120) -> 2202.096 | N16: =SUM(E16*120) -> 0 | O16: =SUM(F16*54) -> 14889.209 | P16: =SUM(G16*54) -> 0 | Q16: =SUM(H16*120) -> 0 | R16: =SUM(I16*1000) -> 0 | S16: =SUM(J16*140) -> 0 | T16: =SUM(L16:S16) -> 17091.305
A17: 13 | B17: 46035 | D17: 36.7334 | F17: =F16-E17+D17 -> 312.4595 | G17: =IF(OR(B17="",NOT(ISERROR(SEARCH("KPI",$A$2))),NOT(ISERROR(SEARCH("Полиом",$A$2)))),0,IF(70-F17<=0,0,70-F17)) -> 0 | L17: =SUM(K17*240) -> 0 | M17: =SUM(D17*120) -> 4408.008 | N17: =SUM(E17*120) -> 0 | O17: =SUM(F17*54) -> 16872.813 | P17: =SUM(G17*54) -> 0 | Q17: =SUM(H17*120) -> 0 | R17: =SUM(I17*1000) -> 0 | S17: =SUM(J17*140) -> 0 | T17: =SUM(L17:S17) -> 21280.821
A18: 14 | B18: 46036 | E18: 17.6792 | F18: =F17-E18+D18 -> 294.7803 | G18: =IF(OR(B18="",NOT(ISERROR(SEARCH("KPI",$A$2))),NOT(ISERROR(SEARCH("Полиом",$A$2)))),0,IF(70-F18<=0,0,70-F18)) -> 0 | L18: =SUM(K18*240) -> 0 | M18: =SUM(D18*120) -> 0 | N18: =SUM(E18*120) -> 2121.504 | O18: =SUM(F18*54) -> 15918.136 | P18: =SUM(G18*54) -> 0 | Q18: =SUM(H18*120) -> 0 | R18: =SUM(I18*1000) -> 0 | S18: =SUM(J18*140) -> 0 | T18: =SUM(L18:S18) -> 18039.64
A19: 15 | B19: 46037 | E19: 9.3882 | F19: =F18-E19+D19 -> 285.3921 | G19: =IF(OR(B19="",NOT(ISERROR(SEARCH("KPI",$A$2))),NOT(ISERROR(SEARCH("Полиом",$A$2)))),0,IF(70-F19<=0,0,70-F19)) -> 0 | L19: =SUM(K19*240) -> 0 | M19: =SUM(D19*120) -> 0 | N19: =SUM(E19*120) -> 1126.584 | O19: =SUM(F19*54) -> 15411.173 | P19: =SUM(G19*54) -> 0 | Q19: =SUM(H19*120) -> 0 | R19: =SUM(I19*1000) -> 0 | S19: =SUM(J19*140) -> 0 | T19: =SUM(L19:S19) -> 16537.757
A20: 16 | B20: 46038 | E20: 12.4938 | F20: =F19-E20+D20 -> 272.8983 | G20: =IF(OR(B20="",NOT(ISERROR(SEARCH("KPI",$A$2))),NOT(ISERROR(SEARCH("Полиом",$A$2)))),0,IF(70-F20<=0,0,70-F20)) -> 0 | L20: =SUM(K20*240) -> 0 | M20: =SUM(D20*120) -> 0 | N20: =SUM(E20*120) -> 1499.256 | O20: =SUM(F20*54) -> 14736.508 | P20: =SUM(G20*54) -> 0 | Q20: =SUM(H20*120) -> 0 | R20: =SUM(I20*1000) -> 0 | S20: =SUM(J20*140) -> 0 | T20: =SUM(L20:S20) -> 16235.764
A21: 17 | B21: 46039 | F21: =F20-E21+D21 -> 272.8983 | G21: =IF(OR(B21="",NOT(ISERROR(SEARCH("KPI",$A$2))),NOT(ISERROR(SEARCH("Полиом",$A$2)))),0,IF(70-F21<=0,0,70-F21)) -> 0 | L21: =SUM(K21*240) -> 0 | M21: =SUM(D21*120) -> 0 | N21: =SUM(E21*120) -> 0 | O21: =SUM(F21*54) -> 14736.508 | P21: =SUM(G21*54) -> 0 | Q21: =SUM(H21*120) -> 0 | R21: =SUM(I21*1000) -> 0 | S21: =SUM(J21*140) -> 0 | T21: =SUM(L21:S21) -> 14736.508
A22: 18 | B22: 46040 | F22: =F21-E22+D22 -> 272.8983 | G22: =IF(OR(B22="",NOT(ISERROR(SEARCH("KPI",$A$2))),NOT(ISERROR(SEARCH("Полиом",$A$2)))),0,IF(70-F22<=0,0,70-F22)) -> 0 | L22: =SUM(K22*240) -> 0 | M22: =SUM(D22*120) -> 0 | N22: =SUM(E22*120) -> 0 | O22: =SUM(F22*54) -> 14736.508 | P22: =SUM(G22*54) -> 0 | Q22: =SUM(H22*120) -> 0 | R22: =SUM(I22*1000) -> 0 | S22: =SUM(J22*140) -> 0 | T22: =SUM(L22:S22) -> 14736.508
A23: 19 | B23: 46041 | E23: 22.3138 | F23: =F22-E23+D23 -> 250.5845 | G23: =IF(OR(B23="",NOT(ISERROR(SEARCH("KPI",$A$2))),NOT(ISERROR(SEARCH("Полиом",$A$2)))),0,IF(70-F23<=0,0,70-F23)) -> 0 | L23: =SUM(K23*240) -> 0 | M23: =SUM(D23*120) -> 0 | N23: =SUM(E23*120) -> 2677.656 | O23: =SUM(F23*54) -> 13531.563 | P23: =SUM(G23*54) -> 0 | Q23: =SUM(H23*120) -> 0 | R23: =SUM(I23*1000) -> 0 | S23: =SUM(J23*140) -> 0 | T23: =SUM(L23:S23) -> 16209.219
A24: 20 | B24: 46042 | F24: =F23-E24+D24 -> 250.5845 | G24: =IF(OR(B24="",NOT(ISERROR(SEARCH("KPI",$A$2))),NOT(ISERROR(SEARCH("Полиом",$A$2)))),0,IF(70-F24<=0,0,70-F24)) -> 0 | L24: =SUM(K24*240) -> 0 | M24: =SUM(D24*120) -> 0 | N24: =SUM(E24*120) -> 0 | O24: =SUM(F24*54) -> 13531.563 | P24: =SUM(G24*54) -> 0 | Q24: =SUM(H24*120) -> 0 | R24: =SUM(I24*1000) -> 0 | S24: =SUM(J24*140) -> 0 | T24: =SUM(L24:S24) -> 13531.563
A25: 21 | B25: 46043 | E25: 22.0059 | F25: =F24-E25+D25 -> 228.5786 | G25: =IF(OR(B25="",NOT(ISERROR(SEARCH("KPI",$A$2))),NOT(ISERROR(SEARCH("Полиом",$A$2)))),0,IF(70-F25<=0,0,70-F25)) -> 0 | L25: =SUM(K25*240) -> 0 | M25: =SUM(D25*120) -> 0 | N25: =SUM(E25*120) -> 2640.708 | O25: =SUM(F25*54) -> 12343.244 | P25: =SUM(G25*54) -> 0 | Q25: =SUM(H25*120) -> 0 | R25: =SUM(I25*1000) -> 0 | S25: =SUM(J25*140) -> 0 | T25: =SUM(L25:S25) -> 14983.952
A26: 22 | B26: 46044 | E26: 40.7457 | F26: =F25-E26+D26 -> 187.8329 | G26: =IF(OR(B26="",NOT(ISERROR(SEARCH("KPI",$A$2))),NOT(ISERROR(SEARCH("Полиом",$A$2)))),0,IF(70-F26<=0,0,70-F26)) -> 0 | L26: =SUM(K26*240) -> 0 | M26: =SUM(D26*120) -> 0 | N26: =SUM(E26*120) -> 4889.484 | O26: =SUM(F26*54) -> 10142.977 | P26: =SUM(G26*54) -> 0 | Q26: =SUM(H26*120) -> 0 | R26: =SUM(I26*1000) -> 0 | S26: =SUM(J26*140) -> 0 | T26: =SUM(L26:S26) -> 15032.461
A27: 23 | B27: 46045 | E27: 18.148 | F27: =F26-E27+D27 -> 169.6849 | G27: =IF(OR(B27="",NOT(ISERROR(SEARCH("KPI",$A$2))),NOT(ISERROR(SEARCH("Полиом",$A$2)))),0,IF(70-F27<=0,0,70-F27)) -> 0 | L27: =SUM(K27*240) -> 0 | M27: =SUM(D27*120) -> 0 | N27: =SUM(E27*120) -> 2177.76 | O27: =SUM(F27*54) -> 9162.9846 | P27: =SUM(G27*54) -> 0 | Q27: =SUM(H27*120) -> 0 | R27: =SUM(I27*1000) -> 0 | S27: =SUM(J27*140) -> 0 | T27: =SUM(L27:S27) -> 11340.745
A28: 24 | B28: 46046 | F28: =F27-E28+D28 -> 169.6849 | G28: =IF(OR(B28="",NOT(ISERROR(SEARCH("KPI",$A$2))),NOT(ISERROR(SEARCH("Полиом",$A$2)))),0,IF(70-F28<=0,0,70-F28)) -> 0 | L28: =SUM(K28*240) -> 0 | M28: =SUM(D28*120) -> 0 | N28: =SUM(E28*120) -> 0 | O28: =SUM(F28*54) -> 9162.9846 | P28: =SUM(G28*54) -> 0 | Q28: =SUM(H28*120) -> 0 | R28: =SUM(I28*1000) -> 0 | S28: =SUM(J28*140) -> 0 | T28: =SUM(L28:S28) -> 9162.9846
A29: 25 | B29: 46047 | F29: =F28-E29+D29 -> 169.6849 | G29: =IF(OR(B29="",NOT(ISERROR(SEARCH("KPI",$A$2))),NOT(ISERROR(SEARCH("Полиом",$A$2)))),0,IF(70-F29<=0,0,70-F29)) -> 0 | L29: =SUM(K29*240) -> 0 | M29: =SUM(D29*120) -> 0 | N29: =SUM(E29*120) -> 0 | O29: =SUM(F29*54) -> 9162.9846 | P29: =SUM(G29*54) -> 0 | Q29: =SUM(H29*120) -> 0 | R29: =SUM(I29*1000) -> 0 | S29: =SUM(J29*140) -> 0 | T29: =SUM(L29:S29) -> 9162.9846
A30: 26 | B30: 46048 | E30: 9.3003 | F30: =F29-E30+D30 -> 160.3846 | G30: =IF(OR(B30="",NOT(ISERROR(SEARCH("KPI",$A$2))),NOT(ISERROR(SEARCH("Полиом",$A$2)))),0,IF(70-F30<=0,0,70-F30)) -> 0 | L30: =SUM(K30*240) -> 0 | M30: =SUM(D30*120) -> 0 | N30: =SUM(E30*120) -> 1116.036 | O30: =SUM(F30*54) -> 8660.7684 | P30: =SUM(G30*54) -> 0 | Q30: =SUM(H30*120) -> 0 | R30: =SUM(I30*1000) -> 0 | S30: =SUM(J30*140) -> 0 | T30: =SUM(L30:S30) -> 9776.8044
A31: 27 | B31: 46049 | E31: 3.8719 | F31: =F30-E31+D31 -> 156.5127 | G31: =IF(OR(B31="",NOT(ISERROR(SEARCH("KPI",$A$2))),NOT(ISERROR(SEARCH("Полиом",$A$2)))),0,IF(70-F31<=0,0,70-F31)) -> 0 | L31: =SUM(K31*240) -> 0 | M31: =SUM(D31*120) -> 0 | N31: =SUM(E31*120) -> 464.628 | O31: =SUM(F31*54) -> 8451.6858 | P31: =SUM(G31*54) -> 0 | Q31: =SUM(H31*120) -> 0 | R31: =SUM(I31*1000) -> 0 | S31: =SUM(J31*140) -> 0 | T31: =SUM(L31:S31) -> 8916.3138
A32: 28 | B32: 46050 | F32: =F31-E32+D32 -> 156.5127 | G32: =IF(OR(B32="",NOT(ISERROR(SEARCH("KPI",$A$2))),NOT(ISERROR(SEARCH("Полиом",$A$2)))),0,IF(70-F32<=0,0,70-F32)) -> 0 | L32: =SUM(K32*240) -> 0 | M32: =SUM(D32*120) -> 0 | N32: =SUM(E32*120) -> 0 | O32: =SUM(F32*54) -> 8451.6858 | P32: =SUM(G32*54) -> 0 | Q32: =SUM(H32*120) -> 0 | R32: =SUM(I32*1000) -> 0 | S32: =SUM(J32*140) -> 0 | T32: =SUM(L32:S32) -> 8451.6858
A33: 29 | B33: 46051 | E33: 17.5018 | F33: =F32-E33+D33 -> 139.0109 | G33: =IF(OR(B33="",NOT(ISERROR(SEARCH("KPI",$A$2))),NOT(ISERROR(SEARCH("Полиом",$A$2)))),0,IF(70-F33<=0,0,70-F33)) -> 0 | L33: =SUM(K33*240) -> 0 | M33: =SUM(D33*120) -> 0 | N33: =SUM(E33*120) -> 2100.216 | O33: =SUM(F33*54) -> 7506.5886 | P33: =SUM(G33*54) -> 0 | Q33: =SUM(H33*120) -> 0 | R33: =SUM(I33*1000) -> 0 | S33: =SUM(J33*140) -> 0 | T33: =SUM(L33:S33) -> 9606.8046
A34: 30 | B34: 46052 | E34: 17.6692 | F34: =F33-E34+D34 -> 121.3417 | G34: =IF(OR(B34="",NOT(ISERROR(SEARCH("KPI",$A$2))),NOT(ISERROR(SEARCH("Полиом",$A$2)))),0,IF(70-F34<=0,0,70-F34)) -> 0 | L34: =SUM(K34*240) -> 0 | M34: =SUM(D34*120) -> 0 | N34: =SUM(E34*120) -> 2120.304 | O34: =SUM(F34*54) -> 6552.4518 | P34: =SUM(G34*54) -> 0 | Q34: =SUM(H34*120) -> 0 | R34: =SUM(I34*1000) -> 0 | S34: =SUM(J34*140) -> 0 | T34: =SUM(L34:S34) -> 8672.7558
B35: 46053 | F35: =F34-E35+D35 -> 121.3417 | G35: =IF(OR(B35="",NOT(ISERROR(SEARCH("KPI",$A$2))),NOT(ISERROR(SEARCH("Полиом",$A$2)))),0,IF(70-F35<=0,0,70-F35)) -> 0 | L35: =SUM(K35*240) -> 0 | M35: =SUM(D35*120) -> 0 | N35: =SUM(E35*120) -> 0 | O35: =SUM(F35*54) -> 6552.4518 | P35: =SUM(G35*54) -> 0 | Q35: =SUM(H35*120) -> 0 | R35: =SUM(I35*1000) -> 0 | S35: =SUM(J35*140) -> 0 | T35: =SUM(L35:S35) -> 6552.4518
F36: =SUM(F5:F35) -> 6062.3344 | G36: =SUM(G5:G35) -> 0 | H36: =SUM(H5:H35) -> 0 | I36: =SUM(I5:I35) -> 0 | J36: =SUM(J5:J35) -> 0 | K36: =SUM(K5:K35) -> 0 | L36: =SUM(L5:L35) -> 0 | M36: =SUM(M5:M35) -> 28084.2 | ... T36: =SUM(T5:T35) -> 378384.39
T37: =T36*1.22 -> 461628.96

Sheet ИТОГО
A1: =G16 -> 1.34992e+08
I2: ТОП
A3: Склад | B3: Сибур | C3: Завод | D3: Русвинил | E3: Клиенты сибура | F3: Остальные | G3: Итого | I3: Казань_Автосервисная | J3: 23143268
A4: Баумана | B4: =INDEX($N$44:$N$53,MATCH(A4,$A$44:$A$53,0),1) -> 7891101.9 | C4: 0 | D4: =INDEX($B$56:$B$72,MATCH(A4,$A$56:$A$72,0),1) -> 507717.03 | E4: =SUMIF($F$19:$F$41,A4,$G$19:$G$41) -> 0 | F4: =SUMIF($B$19:$B$27,A4,$C$19:$C$27) -> 48184.2 | G4: =SUM(B4:F4) -> 8447003.1 | I4: Нижнекамск завод | J4: 19482962
A5: Новикова-Прибоя | B5: =INDEX($N$44:$N$53,MATCH(A5,$A$44:$A$53,0),1) -> 10750834 | C5: 0 | D5: =INDEX($B$56:$B$72,MATCH(A5,$A$56:$A$72,0),1) -> 809022.23 | E5: =SUMIF($F$19:$F$41,A5,$G$19:$G$41) -> 0 | F5: =SUMIF($B$19:$B$27,A5,$C$19:$C$27) -> 8184 | G5: =SUM(B5:F5) -> 11568040 | I5: Новикова-Прибоя | J5: 14483152
A6: Екатеринбург | B6: =INDEX($N$44:$N$53,MATCH(A6,$A$44:$A$53,0),1) -> 11243241 | C6: 0 | D6: =INDEX($B$56:$B$72,MATCH(A6,$A$56:$A$72,0),1) -> 0 | E6: =SUMIF($F$19:$F$41,A6,$G$19:$G$41) -> 0 | F6: =SUMIF($B$19:$B$27,A6,$C$19:$C$27) -> 0 | G6: =SUM(B6:F6) -> 11243241 | I6: Екатеринбург | J6: 11908609
A7: Новосибирск | B7: =INDEX($N$44:$N$53,MATCH(A7,$A$44:$A$53,0),1) -> 8139705.4 | C7: 0 | D7: =INDEX($B$56:$B$72,MATCH(A7,$A$56:$A$72,0),1) -> 0 | E7: =SUMIF($F$19:$F$41,A7,$G$19:$G$41) -> 461628.96 | F7: =SUMIF($B$19:$B$27,A7,$C$19:$C$27) -> 0 | G7: =SUM(B7:F7) -> 8601334.4 | I7: Баумана | J7: 11544503
A8: Новосибирск_Пасечная | B8: =INDEX($N$44:$N$53,MATCH(A8,$A$44:$A$53,0),1) -> 6161036.8 | C8: 0 | D8: =INDEX($B$56:$B$72,MATCH(A8,$A$56:$A$72,0),1) -> 0 | E8: =SUMIF($F$19:$F$41,A8,$G$19:$G$41) -> 0 | F8: =SUMIF($B$19:$B$27,A8,$C$19:$C$27) -> 0 | G8: =SUM(B8:F8) -> 6161036.8
A9: Казань_Автосервисная | B9: =INDEX($N$44:$N$53,MATCH(A9,$A$44:$A$53,0),1) -> 18468887 | C9: 0 | D9: =INDEX($B$56:$B$72,MATCH(A9,$A$56:$A$72,0),1) -> 0 | E9: =SUMIF($F$19:$F$41,A9,$G$19:$G$41) -> 0 | F9: =SUMIF($B$19:$B$27,A9,$C$19:$C$27) -> 0 | G9: =SUM(B9:F9) -> 18468887 | I9: Казань_Приволжская | J9: 9900926.9
A10: Казань_Приволжская | B10: =INDEX($N$44:$N$53,MATCH(A10,$A$44:$A$53,0),1) -> 9663965.4 | C10: 0 | D10: =INDEX($B$56:$B$72,MATCH(A10,$A$56:$A$72,0),1) -> 0 | E10: =SUMIF($F$19:$F$41,A10,$G$19:$G$41) -> 0 | F10: =SUMIF($B$19:$B$27,A10,$C$19:$C$27) -> 0 | G10: =SUM(B10:F10) -> 9663965.4 | I10: Зеленодольск | J10: 9082789.1
A11: Зеленодольск | B11: =INDEX($N$44:$N$53,MATCH(A11,$A$44:$A$53,0),1) -> 8550347 | C11: 0 | D11: =INDEX($B$56:$B$72,MATCH(A11,$A$56:$A$72,0),1) -> 0 | E11: =SUMIF($F$19:$F$41,A11,$G$19:$G$41) -> 615525.55 | F11: =SUMIF($B$19:$B$27,A11,$C$19:$C$27) -> 0 | G11: =SUM(B11:F11) -> 9165872.6 | I11: Новосибирск | J11: 7932975.6
A12: Нижнекамск | B12: =INDEX($N$44:$N$53,MATCH(A12,$A$44:$A$53,0),1) -> 4807181.1 | C12: 0 | D12: =INDEX($B$56:$B$72,MATCH(A12,$A$56:$A$72,0),1) -> 0 | E12: =SUMIF($F$19:$F$41,A12,$G$19:$G$41) -> 96099.595 | F12: =SUMIF($B$19:$B$27,A12,$C$19:$C$27) -> 0 | G12: =SUM(B12:F12) -> 4903280.7 | I12: Нижнекамск | J12: 7580244.6
A13: Нижнекамск завод | B13: 0 | C13: =C29+C36 -> 41076517 | D13: =INDEX($B$56:$B$72,MATCH(A13,$A$56:$A$72,0),1) -> 0 | E13: =SUMIF($F$19:$F$41,A13,$G$19:$G$41) -> 0 | F13: =SUMIF($B$19:$B$27,A13,$C$19:$C$27) -> 0 | G13: =SUM(B13:F13) -> 41076517 | I13: ГАЗ | J13: 6720000
A14: Монастырка | B14: 0 | C14: 0 | D14: =INDEX($B$56:$B$72,MATCH(A14,$A$56:$A$72,0),1) -> 0 | E14: =SUMIF($F$19:$F$41,A14,$G$19:$G$41) -> 0 | F14: =SUMIF($B$19:$B$27,A14,$C$19:$C$27) -> 0 | G14: =SUM(B14:F14) -> 0 | I14: Монастырка | J14: 2464921.6
A15: Березовая Пойма | B15: =INDEX($N$44:$N$53,MATCH(A15,$A$44:$A$53,0),1) -> 0 | C15: 0 | D15: =INDEX($B$56:$B$72,MATCH(A15,$A$56:$A$72,0),1) -> 5692817.6 | E15: =SUMIF($F$19:$F$41,A15,$G$19:$G$41) -> 0 | F15: =SUMIF($B$19:$B$27,A15,$C$19:$C$27) -> 0 | G15: =SUM(B15:F15) -> 5692817.6
B16: =SUM(B4:B15) -> 85676299 | C16: =SUM(C4:C15) -> 41076517 | D16: =SUM(D4:D15) -> 7009556.9 | E16: =SUM(E4:E15) -> 1173254.1 | F16: =SUM(F4:F15) -> 56368.2 | G16: =SUM(G4:G15) -> 1.34992e+08
A18: Остальные клиенты | C18: =SUM(C19:C27) -> 56368.2 | E18: Клиенты сибура | G18: =SUM(G19:G40) -> 1173254.1
A19: Стройтех | B19: Баумана | C19: {=IFERROR(INDIRECT("'" & A19 & "'!A1"),)} -> 21000 | E19: Приоритет | F19: Баумана | G19: {=IFERROR(INDIRECT("'" & E19 & " " & F19 & "'!A1"),0)} -> 0
A20: Ергарда | B20: Баумана | C20: {=IFERROR(INDIRECT("'" & A20 & "'!A1"),)} -> 8928 | E20: Фармпласт | F20: Баумана | G20: {=IFERROR(INDIRECT("'" & E20 & " " & F20 & "'!A1"),0)} -> 0
A21: Литейные решения | B21: Баумана | C21: {=IFERROR(INDIRECT("'" & A21 & "'!A1"),)} -> 15573 | E21: Юг Полимер | F21: Баумана | G21: {=IFERROR(INDIRECT("'" & E21 & " " & F21 & "'!A1"),0)} -> 0
A22: Сандекс | B22: Баумана | C22: {=IFERROR(INDIRECT("'" & A22 & "'!A1"),)} -> 2013.6 | E22: Центрополимер | F22: Екатеринбург | G22: {=IFERROR(INDIRECT("'" & E22 & " " & F22 & "'!A1"),0)} -> 0
A23: ЛС-Техномет | B23: Баумана | C23: {=IFERROR(INDIRECT("'" & A23 & "'!A1"),)} -> 669.6 | E23: Приоритет | F23: Екатеринбург | G23: {=IFERROR(INDIRECT("'" & E23 & " " & F23 & "'!A1"),0)} -> 0
A24: РусДжам | B24: ГАЗ | C24: {=IFERROR(INDIRECT("'" & A24 & "'!A1"),)} -> 0 | E24: Фармпласт | F24: Екатеринбург | G24: {=IFERROR(INDIRECT("'" & E24 & " " & F24 & "'!A1"),0)} -> 0
A25: Виго | B25: Новикова-Прибоя | C25: {=IFERROR(INDIRECT("'" & A25 & "'!A1"),)} -> 0 | E25: Приоритет | F25: Зеленодольск | G25: {=IFERROR(INDIRECT("'" & E25 & " " & F25 & "'!A1"),0)} -> 0
A26: Доктор Франк | B26: Новикова-Прибоя | C26: {=IFERROR(INDIRECT("'" & A26 & "'!A1"),)} -> 8184 | E26: Данафлекс | F26: Зеленодольск | G26: {=IFERROR(INDIRECT("'" & E26 & " " & F26 & "'!t37"),0)} -> 615525.55
A27: Нефтезол | B27: Новикова-Прибоя | C27: {=IFERROR(INDIRECT("'" & A27 & "'!A1"),)} -> 0 | E27: ИП Ксендз | F27: Нижнекамск | G27: {=IFERROR(INDIRECT("'" & E27 & " " & F27 & "'!A1"),0)} -> 96099.595
E28: Фармпласт | F28: Новикова-Прибоя | G28: {=IFERROR(INDIRECT("'" & E28 & " " & F28 & "'!A1"),0)} -> 0
A29: Нижнекамск завод | C29: =SUM(C30:C34) -> 30944856 | E29: Центрополимер | F29: Новикова-Прибоя | G29: {=IFERROR(INDIRECT("'" & E29 & " " & F29 & "'!A1"),0)} -> 0
A30: ПРР | C30: {=INDIRECT("'" & A29 & "'!F17")} -> 15902450 | E30: Юг Полимер | F30: Новикова-Прибоя | G30: {=IFERROR(INDIRECT("'" & E30 & " " & F30 & "'!A1"),0)} -> 0
A31: Кладовки | C31: {=INDIRECT("'" & A29 & "'!F16")} -> 0 | E31: Приоритет | F31: Новикова-Прибоя | G31: {=IFERROR(INDIRECT("'" & E31 & " " & F31 & "'!A1"),0)} -> 0
A32: Стропальщики | C32: {=INDIRECT("'" & A29 & "'!F18")} -> 744000 | E32: Биаксплен | F32: Новосибирск | G32: {=IFERROR(INDIRECT("'" & E32 & " " & F32 & "'!A1"),0)} -> 461628.96
A33: Мойка контейнеров | C33: {=INDIRECT("'" & A29 & "'!F19")} -> 1831976 | E33: Центрополимер | F33: Новосибирск | G33: {=IFERROR(INDIRECT("'" & E33 & " " & F33 & "'!A1"),0)} -> 0
A34: МТО | C34: {=INDIRECT("'" & A29 & "'!F20")} -> 12466430 | E34: Фармпласт | F34: Новосибирск | G34: {=IFERROR(INDIRECT("'" & E34 & " " & F34 & "'!A1"),0)} -> 0
E35: Юг Полимер | F35: Зеленодольск | G35: {=IFERROR(INDIRECT("'" & E35 & " " & F35 & "'!A1"),0)} -> 0
A36: Контейнерные площадки | C36: =SUM(C37:C41) -> 10131661 | E36: Фармпласт | F36: Казань_Автосервисная | G36: {=IFERROR(INDIRECT("'" & E36 & " " & F36 & "'!A1"),0)} -> 0
A37: КОС | C37: =3067441 -> 3067441 | E37: Приоритет | F37: Казань_Приволжская | G37: {=IFERROR(INDIRECT("'" & E37 & " " & F37 & "'!A1"),0)} -> 0
A38: Нижнекамск | C38: 7064220 | E38: Центрополимер | F38: Баумана | G38: {=IFERROR(INDIRECT("'" & E38 & " " & F38 & "'!A1"),0)} -> 0
E39: Приоритет | F39: Казань_Автосервисная | G39: {=IFERROR(INDIRECT("'" & E39 & " " & F39 & "'!A1"),0)} -> 0
E40: Оникс | F40: Нижнекамск | G40: {=IFERROR(INDIRECT("'" & E40 & " " & F40 & "'!A1"),0)} -> 0
A42: СИБУР | K42: =SUM(N44:N53) -> 85676299
...

Sheet Другое

Sheet Нижнекамск завод
A9: № | B9: Наименование услуг (работ) | C9: Ед. изм. | D9: Количество | E9: Цена | F9: Сумма
A14: Итого: | F14: =SUM(F10:F13) -> 0
A15: Без налога (НДС) | F15: =SUM(F14) -> 0
A16: Всего (с учетом НДС) | F16: =SUM(F15)*1.2 -> 0
A17: Вышеперечисленные услуги (работы) выполнены полностью. | E17: ПРР | F17: 15902450
A18: ПОКЛАЖЕДАТЕЛЬ претензий по объему, качеству и срокам оказания услуг претензий не имеет. | E18: Стропальщики | F18: 744000
E19: Контейнеры | F19: 1831976
E20: МТО | F20: 12466430
A21: ООО "ДТМ" | D21: ПАО "Нижнекамскнефтехим"
A23: ____________________Молькова Т.Ю. | B23: Расстегаев Д.О. | D23: ____________________

Sheet Резерв
A3: ="Отчет по резерву хранению товара РВ " & TEXT(A6,"ММММ ") & YEAR(A6) & "" -> Отчет по резерву хранению товара РВ Январь 2026
A4: дата | C4: Хранение Баумана | D4: Хранение Новикова | E4: Хранение Березовая Пойма | F4: Общее хранение | G4: Резерв 8000 т | H4: стоимость резерва | I4: итого
A6: 46023 | C6: ='[1]РВ Баумана'!G6 -> 883.225 | D6: ='[1]РВ Новикова-Прибоя'!G6 -> 190.67 | E6: ='[1]РВ Березовая Пойма'!G6 -> 786.23 | F6: =SUM(C6:E6) -> 1860.125 | G6: =IF(8000-F6<0,0,8000-F6) -> 6139.875 | H6: =G6*15 -> 92098.125 | I6: =SUM(H6:H6) -> 92098.125 | J6: =IF(OR(WEEKDAY(A6)=1,WEEKDAY(A6)=7,NOT(ISERROR(MATCH(A6,[1]Праздники!A:A,0)))),"Выходной","Рабочий") -> Выходной
A7: 46024 | C7: ='[1]РВ Баумана'!G7 -> 883.225 | D7: ='[1]РВ Новикова-Прибоя'!G7 -> 190.67 | E7: ='[1]РВ Березовая Пойма'!G7 -> 786.23 | F7: =SUM(C7:E7) -> 1860.125 | G7: =IF(8000-F7<0,0,8000-F7) -> 6139.875 | H7: =G7*15 -> 92098.125 | I7: =SUM(H7:H7) -> 92098.125 | J7: =IF(OR(WEEKDAY(A7)=1,WEEKDAY(A7)=7,NOT(ISERROR(MATCH(A7,[1]Праздники!A:A,0)))),"Выходной","Рабочий") -> Выходной
A8: 46025 | C8: ='[1]РВ Баумана'!G8 -> 883.225 | D8: ='[1]РВ Новикова-Прибоя'!G8 -> 190.67 | E8: ='[1]РВ Березовая Пойма'!G8 -> 1516.35 | F8: =SUM(C8:E8) -> 2590.245 | G8: =IF(8000-F8<0,0,8000-F8) -> 5409.755 | H8: =G8*15 -> 81146.325 | I8: =SUM(H8:H8) -> 81146.325 | J8: =IF(OR(WEEKDAY(A8)=1,WEEKDAY(A8)=7,NOT(ISERROR(MATCH(A8,[1]Праздники!A:A,0)))),"Выходной","Рабочий") -> Выходной
A9: 46026 | C9: ='[1]РВ Баумана'!G9 -> 883.225 | D9: ='[1]РВ Новикова-Прибоя'!G9 -> 190.67 | E9: ='[1]РВ Березовая Пойма'!G9 -> 1869.04 | F9: =SUM(C9:E9) -> 2942.935 | G9: =IF(8000-F9<0,0,8000-F9) -> 5057.065 | H9: =G9*15 -> 75855.975 | I9: =SUM(H9:H9) -> 75855.975 | J9: =IF(OR(WEEKDAY(A9)=1,WEEKDAY(A9)=7,NOT(ISERROR(MATCH(A9,[1]Праздники!A:A,0)))),"Выходной","Рабочий") -> Выходной
A10: 46027 | C10: ='[1]РВ Баумана'!G10 -> 883.225 | D10: ='[1]РВ Новикова-Прибоя'!G10 -> 190.67 | E10: ='[1]РВ Березовая Пойма'!G10 -> 2376.19 | F10: =SUM(C10:E10) -> 3450.085 | G10: =IF(8000-F10<0,0,8000-F10) -> 4549.915 | H10: =G10*15 -> 68248.725 | I10: =SUM(H10:H10) -> 68248.725 | J10: =IF(OR(WEEKDAY(A10)=1,WEEKDAY(A10)=7,NOT(ISERROR(MATCH(A10,[1]Праздники!A:A,0)))),"Выходной","Рабочий") -> Выходной
A11: 46028 | C11: ='[1]РВ Баумана'!G11 -> 883.225 | D11: ='[1]РВ Новикова-Прибоя'!G11 -> 190.67 | E11: ='[1]РВ Березовая Пойма'!G11 -> 3235.57 | F11: =SUM(C11:E11) -> 4309.465 | G11: =IF(8000-F11<0,0,8000-F11) -> 3690.535 | H11: =G11*15 -> 55358.025 | I11: =SUM(H11:H11) -> 55358.025 | J11: =IF(OR(WEEKDAY(A11)=1,WEEKDAY(A11)=7,NOT(ISERROR(MATCH(A11,[1]Праздники!A:A,0)))),"Выходной","Рабочий") -> Выходной
A12: 46029 | C12: ='[1]РВ Баумана'!G12 -> 883.225 | D12: ='[1]РВ Новикова-Прибоя'!G12 -> 190.67 | E12: ='[1]РВ Березовая Пойма'!G12 -> 3985.18 | F12: =SUM(C12:E12) -> 5059.075 | G12: =IF(8000-F12<0,0,8000-F12) -> 2940.925 | H12: =G12*15 -> 44113.875 | I12: =SUM(H12:H12) -> 44113.875 | J12: =IF(OR(WEEKDAY(A12)=1,WEEKDAY(A12)=7,NOT(ISERROR(MATCH(A12,[1]Праздники!A:A,0)))),"Выходной","Рабочий") -> Выходной
A13: 46030 | C13: ='[1]РВ Баумана'!G13 -> 883.225 | D13: ='[1]РВ Новикова-Прибоя'!G13 -> 190.67 | E13: ='[1]РВ Березовая Пойма'!G13 -> 4560.4 | F13: =SUM(C13:E13) -> 5634.295 | G13: =IF(8000-F13<0,0,8000-F13) -> 2365.705 | H13: =G13*15 -> 35485.575 | I13: =SUM(H13:H13) -> 35485.575 | J13: =IF(OR(WEEKDAY(A13)=1,WEEKDAY(A13)=7,NOT(ISERROR(MATCH(A13,[1]Праздники!A:A,0)))),"Выходной","Рабочий") -> Выходной
A14: 46031 | C14: ='[1]РВ Баумана'!G14 -> 883.225 | D14: ='[1]РВ Новикова-Прибоя'!G14 -> 190.67 | E14: ='[1]РВ Березовая Пойма'!G14 -> 4974.05 | F14: =SUM(C14:E14) -> 6047.945 | G14: =IF(8000-F14<0,0,8000-F14) -> 1952.055 | H14: =G14*15 -> 29280.825 | I14: =SUM(H14:H14) -> 29280.825 | J14: =IF(OR(WEEKDAY(A14)=1,WEEKDAY(A14)=7,NOT(ISERROR(MATCH(A14,[1]Праздники!A:A,0)))),"Выходной","Рабочий") -> Выходной
A15: 46032 | C15: ='[1]РВ Баумана'!G15 -> 883.225 | D15: ='[1]РВ Новикова-Прибоя'!G15 -> 190.67 | E15: ='[1]РВ Березовая Пойма'!G15 -> 5238.74 | F15: =SUM(C15:E15) -> 6312.635 | G15: =IF(8000-F15<0,0,8000-F15) -> 1687.365 | H15: =G15*15 -> 25310.475 | I15: =SUM(H15:H15) -> 25310.475 | J15: =IF(OR(WEEKDAY(A15)=1,WEEKDAY(A15)=7,NOT(ISERROR(MATCH(A15,[1]Праздники!A:A,0)))),"Выходной","Рабочий") -> Выходной
A16: 46033 | C16: ='[1]РВ Баумана'!G16 -> 883.225 | D16: ='[1]РВ Новикова-Прибоя'!G16 -> 190.67 | E16: ='[1]РВ Березовая Пойма'!G16 -> 5439.16 | F16: =SUM(C16:E16) -> 6513.055 | G16: =IF(8000-F16<0,0,8000-F16) -> 1486.945 | H16: =G16*15 -> 22304.175 | I16: =SUM(H16:H16) -> 22304.175 | J16: =IF(OR(WEEKDAY(A16)=1,WEEKDAY(A16)=7,NOT(ISERROR(MATCH(A16,[1]Праздники!A:A,0)))),"Выходной","Рабочий") -> Выходной
A17: 46034 | C17: ='[1]РВ Баумана'!G17 -> 883.225 | D17: ='[1]РВ Новикова-Прибоя'!G17 -> 193.215 | E17: ='[1]РВ Березовая Пойма'!G17 -> 6429.67 | F17: =SUM(C17:E17) -> 7506.11 | G17: =IF(8000-F17<0,0,8000-F17) -> 493.89 | H17: =G17*15 -> 7408.35 | I17: =SUM(H17:H17) -> 7408.35 | J17: =IF(OR(WEEKDAY(A17)=1,WEEKDAY(A17)=7,NOT(ISERROR(MATCH(A17,[1]Праздники!A:A,0)))),"Выходной","Рабочий") -> Рабочий
... A36: 46053 | C36: ='[1]РВ Баумана'!G36 -> 812.35 | D36: ='[1]РВ Новикова-Прибоя'!G36 -> 1411.04 | E36: ='[1]РВ Березовая Пойма'!G36 -> 4829.68 | F36: =SUM(C36:E36) -> 7053.07 | G36: =IF(8000-F36<0,0,8000-F36) -> 946.93 | H36: =G36*15 -> 14203.95 | I36: =SUM(H36:H36) -> 14203.95 | J36: =IF(OR(WEEKDAY(A36)=1,WEEKDAY(A36)=7,NOT(ISERROR(MATCH(A36,[1]Праздники!A:A,0)))),"Выходной","Рабочий") -> Выходной
C37: =SUM(C6:C36) -> 26622.85 | D37: =SUM(D6:D36) -> 28317.59 | E37: =SUM(E6:E36) -> 143700.66 | G37: =SUM(G6:G36) -> 51605.745 | H37: =SUM(H6:H36) -> 774086.17 | I37: =SUM(I6:I36) -> 774086.17
I38: =I37*1.22 -> 944385.13

Sheet РВ Баумана
R1: Выходной | S1: Рабочий
Q2: Выгрузка | R2: =SUMIF($P$6:$P$36,R$1,$C6:$C36) -> 0 | S2: =SUMIF($P$6:$P$36,S$1,$C6:$C36) -> 0
A3: ="Отчет по хранению товара РВ " & TEXT(A6,"ММММ ") & YEAR(A6) & " Баумана" -> Отчет по хранению товара РВ Январь 2026 Баумана | Q3: Отгрузка | R3: =SUMIF($P$6:$P$36,R$1,$D6:$D36) -> 60.5 | S3: =SUMIF($P$6:$P$36,S$1,$D6:$D36) -> 21.375
A4: дата | C4: Выгрузка кол-во тонн | D4: Загрузка кол-во тонн | E4: Выгрузка после 20:00 | F4: Загрузка после 20:00 | G4: Хранение | H4: переконсолидация (тонн) | I4: стоимость выгрузки | J4: стоимость загрузки | K4: Стоимость выгрузки после 20:00 | L4: Стоимость загрузки после 20:00 | M4: стоимость хранения | N4: стоимость переконс. | O4: итого
G5: (кол-во тонн)
A6: 46023 | C6: 0 | D6: 0 | G6: 883.225 | I6: =IF(P6="Выходной",SUM(C6*150)*1.5,SUM(C6*150)) -> 0 | J6: =IF(P6="Выходной",SUM(D6*150)*1.5,SUM(D6*150)) -> 0 | K6: =IF(OR(WEEKDAY(A6)=1,WEEKDAY(A6)=7,NOT(ISERROR(MATCH(A6,[1]Праздники!A:A,0)))),SUM(E6*225)*1.5,SUM(E6*225)) -> 0 | L6: =IF(OR(WEEKDAY(A6)=1,WEEKDAY(A6)=7,NOT(ISERROR(MATCH(A6,[1]Праздники!A:A,0)))),SUM(F6*225)*1.5,SUM(F6*225)) -> 0 | M6: =SUM(G6*15) -> 13248.375 | N6: =SUM(H6)*750 -> 0 | O6: =SUM(I6:N6) -> 13248.375 | P6: =IF(OR(WEEKDAY(A6)=1,WEEKDAY(A6)=7,NOT(ISERROR(MATCH(A6,[1]Праздники!A:A,0)))),"Выходной","Рабочий") -> Выходной
A7: 46024 | C7: 0 | D7: 0 | G7: =IF(A7 ="",0,G6+C7+E7-D6-F6) -> 883.225 | I7: =IF(P7="Выходной",SUM(C7*150)*1.5,SUM(C7*150)) -> 0 | J7: =IF(P7="Выходной",SUM(D7*150)*1.5,SUM(D7*150)) -> 0 | K7: =IF(OR(WEEKDAY(A7)=1,WEEKDAY(A7)=7,NOT(ISERROR(MATCH(A7,[1]Праздники!A:A,0)))),SUM(E7*225)*1.5,SUM(E7*225)) -> 0 | L7: =IF(OR(WEEKDAY(A7)=1,WEEKDAY(A7)=7,NOT(ISERROR(MATCH(A7,[1]Праздники!A:A,0)))),SUM(F7*225)*1.5,SUM(F7*225)) -> 0 | M7: =SUM(G7*15) -> 13248.375 | N7: =SUM(H7)*750 -> 0 | O7: =SUM(I7:N7) -> 13248.375 | P7: =IF(OR(WEEKDAY(A7)=1,WEEKDAY(A7)=7,NOT(ISERROR(MATCH(A7,[1]Праздники!A:A,0)))),"Выходной","Рабочий") -> Выходной
A8: 46025 | C8: 0 | D8: 0 | G8: =IF(A8 ="",0,G7+C8+E8-D7-F7) -> 883.225 | I8: =IF(P8="Выходной",SUM(C8*150)*1.5,SUM(C8*150)) -> 0 | J8: =IF(P8="Выходной",SUM(D8*150)*1.5,SUM(D8*150)) -> 0 | K8: =IF(OR(WEEKDAY(A8)=1,WEEKDAY(A8)=7,NOT(ISERROR(MATCH(A8,[1]Праздники!A:A,0)))),SUM(E8*225)*1.5,SUM(E8*225)) -> 0 | L8: =IF(OR(WEEKDAY(A8)=1,WEEKDAY(A8)=7,NOT(ISERROR(MATCH(A8,[1]Праздники!A:A,0)))),SUM(F8*225)*1.5,SUM(F8*225)) -> 0 | M8: =SUM(G8*15) -> 13248.375 | N8: =SUM(H8)*750 -> 0 | O8: =SUM(I8:N8) -> 13248.375 | P8: =IF(OR(WEEKDAY(A8)=1,WEEKDAY(A8)=7,NOT(ISERROR(MATCH(A8,[1]Праздники!A:A,0)))),"Выходной","Рабочий") -> Выходной
A9: 46026 | C9: 0 | D9: 0 | G9: =IF(A9 ="",0,G8+C9+E9-D8-F8) -> 883.225 | I9: =IF(P9="Выходной",SUM(C9*150)*1.5,SUM(C9*150)) -> 0 | J9: =IF(P9="Выходной",SUM(D9*150)*1.5,SUM(D9*150)) -> 0 | K9: =IF(OR(WEEKDAY(A9)=1,WEEKDAY(A9)=7,NOT(ISERROR(MATCH(A9,[1]Праздники!A:A,0)))),SUM(E9*225)*1.5,SUM(E9*225)) -> 0 | L9: =IF(OR(WEEKDAY(A9)=1,WEEKDAY(A9)=7,NOT(ISERROR(MATCH(A9,[1]Праздники!A:A,0)))),SUM(F9*225)*1.5,SUM(F9*225)) -> 0 | M9: =SUM(G9*15) -> 13248.375 | N9: =SUM(H9)*750 -> 0 | O9: =SUM(I9:N9) -> 13248.375 | P9: =IF(OR(WEEKDAY(A9)=1,WEEKDAY(A9)=7,NOT(ISERROR(MATCH(A9,[1]Праздники!A:A,0)))),"Выходной","Рабочий") -> Выходной
A10: 46027 | C10: 0 | D10: 0 | G10: =IF(A10 ="",0,G9+C10+E10-D9-F9) -> 883.225 | I10: =IF(P10="Выходной",SUM(C10*150)*1.5,SUM(C10*150)) -> 0 | J10: =IF(P10="Выходной",SUM(D10*150)*1.5,SUM(D10*150)) -> 0 | K10: =IF(OR(WEEKDAY(A10)=1,WEEKDAY(A10)=7,NOT(ISERROR(MATCH(A10,[1]Праздники!A:A,0)))),SUM(E10*225)*1.5,SUM(E10*225)) -> 0 | L10: =IF(OR(WEEKDAY(A10)=1,WEEKDAY(A10)=7,NOT(ISERROR(MATCH(A10,[1]Праздники!A:A,0)))),SUM(F10*225)*1.5,SUM(F10*225)) -> 0 | M10: =SUM(G10*15) -> 13248.375 | N10: =SUM(H10)*750 -> 0 | O10: =SUM(I10:N10) -> 13248.375 | P10: =IF(OR(WEEKDAY(A10)=1,WEEKDAY(A10)=7,NOT(ISERROR(MATCH(A10,[1]Праздники!A:A,0)))),"Выходной","Рабочий") -> Выходной
A11: 46028 | C11: 0 | D11: 0 | G11: =IF(A11 ="",0,G10+C11+E11-D10-F10) -> 883.225 | I11: =IF(P11="Выходной",SUM(C11*150)*1.5,SUM(C11*150)) -> 0 | J11: =IF(P11="Выходной",SUM(D11*150)*1.5,SUM(D11*150)) -> 0 | K11: =IF(OR(WEEKDAY(A11)=1,WEEKDAY(A11)=7,NOT(ISERROR(MATCH(A11,[1]Праздники!A:A,0)))),SUM(E11*225)*1.5,SUM(E11*225)) -> 0 | L11: =IF(OR(WEEKDAY(A11)=1,WEEKDAY(A11)=7,NOT(ISERROR(MATCH(A11,[1]Праздники!A:A,0)))),SUM(F11*225)*1.5,SUM(F11*225)) -> 0 | M11: =SUM(G11*15) -> 13248.375 | N11: =SUM(H11)*750 -> 0 | O11: =SUM(I11:N11) -> 13248.375 | P11: =IF(OR(WEEKDAY(A11)=1,WEEKDAY(A11)=7,NOT(ISERROR(MATCH(A11,[1]Праздники!A:A,0)))),"Выходной","Рабочий") -> Выходной
A12: 46029 | C12: 0 | D12: 0 | G12: =IF(A12 ="",0,G11+C12+E12-D11-F11) -> 883.225 | I12: =IF(P12="Выходной",SUM(C12*150)*1.5,SUM(C12*150)) -> 0 | J12: =IF(P12="Выходной",SUM(D12*150)*1.5,SUM(D12*150)) -> 0 | K12: =IF(OR(WEEKDAY(A12)=1,WEEKDAY(A12)=7,NOT(ISERROR(MATCH(A12,[1]Праздники!A:A,0)))),SUM(E12*225)*1.5,SUM(E12*225)) -> 0 | L12: =IF(OR(WEEKDAY(A12)=1,WEEKDAY(A12)=7,NOT(ISERROR(MATCH(A12,[1]Праздники!A:A,0)))),SUM(F12*225)*1.5,SUM(F12*225)) -> 0 | M12: =SUM(G12*15) -> 13248.375 | N12: =SUM(H12)*750 -> 0 | O12: =SUM(I12:N12) -> 13248.375 | P12: =IF(OR(WEEKDAY(A12)=1,WEEKDAY(A12)=7,NOT(ISERROR(MATCH(A12,[1]Праздники!A:A,0)))),"Выходной","Рабочий") -> Выходной
A13: 46030 | C13: 0 | D13: 0 | G13: =IF(A13 ="",0,G12+C13+E13-D12-F12) -> 883.225 | I13: =IF(P13="Выходной",SUM(C13*150)*1.5,SUM(C13*150)) -> 0 | J13: =IF(P13="Выходной",SUM(D13*150)*1.5,SUM(D13*150)) -> 0 | K13: =IF(OR(WEEKDAY(A13)=1,WEEKDAY(A13)=7,NOT(ISERROR(MATCH(A13,[1]Праздники!A:A,0)))),SUM(E13*225)*1.5,SUM(E13*225)) -> 0 | L13: =IF(OR(WEEKDAY(A13)=1,WEEKDAY(A13)=7,NOT(ISERROR(MATCH(A13,[1]Праздники!A:A,0)))),SUM(F13*225)*1.5,SUM(F13*225)) -> 0 | M13: =SUM(G13*15) -> 13248.375 | N13: =SUM(H13)*750 -> 0 | O13: =SUM(I13:N13) -> 13248.375 | P13: =IF(OR(WEEKDAY(A13)=1,WEEKDAY(A13)=7,NOT(ISERROR(MATCH(A13,[1]Праздники!A:A,0)))),"Выходной","Рабочий") -> Выходной
A14: 46031 | C14: 0 | D14: 0 | G14: =IF(A14 ="",0,G13+C14+E14-D13-F13) -> 883.225 | I14: =IF(P14="Выходной",SUM(C14*150)*1.5,SUM(C14*150)) -> 0 | J14: =IF(P14="Выходной",SUM(D14*150)*1.5,SUM(D14*150)) -> 0 | K14: =IF(OR(WEEKDAY(A14)=1,WEEKDAY(A14)=7,NOT(ISERROR(MATCH(A14,[1]Праздники!A:A,0)))),SUM(E14*225)*1.5,SUM(E14*225)) -> 0 | L14: =IF(OR(WEEKDAY(A14)=1,WEEKDAY(A14)=7,NOT(ISERROR(MATCH(A14,[1]Праздники!A:A,0)))),SUM(F14*225)*1.5,SUM(F14*225)) -> 0 | M14: =SUM(G14*15) -> 13248.375 | N14: =SUM(H14)*750 -> 0 | O14: =SUM(I14:N14) -> 13248.375 | P14: =IF(OR(WEEKDAY(A14)=1,WEEKDAY(A14)=7,NOT(ISERROR(MATCH(A14,[1]Праздники!A:A,0)))),"Выходной","Рабочий") -> Выходной
A15: 46032 | C15: 0 | D15: 0 | G15: =IF(A15 ="",0,G14+C15+E15-D14-F14) -> 883.225 | I15: =IF(P15="Выходной",SUM(C15*150)*1.5,SUM(C15*150)) -> 0 | J15: =IF(P15="Выходной",SUM(D15*150)*1.5,SUM(D15*150)) -> 0 | K15: =IF(OR(WEEKDAY(A15)=1,WEEKDAY(A15)=7,NOT(ISERROR(MATCH(A15,[1]Праздники!A:A,0)))),SUM(E15*225)*1.5,SUM(E15*225)) -> 0 | L15: =IF(OR(WEEKDAY(A15)=1,WEEKDAY(A15)=7,NOT(ISERROR(MATCH(A15,[1]Праздники!A:A,0)))),SUM(F15*225)*1.5,SUM(F15*225)) -> 0 | M15: =SUM(G15*15) -> 13248.375 | N15: =SUM(H15)*750 -> 0 | O15: =SUM(I15:N15) -> 13248.375 | P15: =IF(OR(WEEKDAY(A15)=1,WEEKDAY(A15)=7,NOT(ISERROR(MATCH(A15,[1]Праздники!A:A,0)))),"Выходной","Рабочий") -> Выходной
A16: 46033 | C16: 0 | D16: 0 | G16: =IF(A16 ="",0,G15+C16+E16-D15-F15) -> 883.225 | I16: =IF(P16="Выходной",SUM(C16*150)*1.5,SUM(C16*150)) -> 0 | J16: =IF(P16="Выходной",SUM(D16*150)*1.5,SUM(D16*150)) -> 0 | K16: =IF(OR(WEEKDAY(A16)=1,WEEKDAY(A16)=7,NOT(ISERROR(MATCH(A16,[1]Праздники!A:A,0)))),SUM(E16*225)*1.5,SUM(E16*225)) -> 0 | L16: =IF(OR(WEEKDAY(A16)=1,WEEKDAY(A16)=7,NOT(ISERROR(MATCH(A16,[1]Праздники!A:A,0)))),SUM(F16*225)*1.5,SUM(F16*225)) -> 0 | M16: =SUM(G16*15) -> 13248.375 | N16: =SUM(H16)*750 -> 0 | O16: =SUM(I16:N16) -> 13248.375 | P16: =IF(OR(WEEKDAY(A16)=1,WEEKDAY(A16)=7,NOT(ISERROR(MATCH(A16,[1]Праздники!A:A,0)))),"Выходной","Рабочий") -> Выходной
A17: 46034 | C17: 0 | D17: 0 | G17: =IF(A17 ="",0,G16+C17+E17-D16-F16) -> 883.225 | I17: =IF(P17="Выходной",SUM(C17*150)*1.5,SUM(C17*150)) -> 0 | J17: =IF(P17="Выходной",SUM(D17*150)*1.5,SUM(D17*150)) -> 0 | K17: =IF(OR(WEEKDAY(A17)=1,WEEKDAY(A17)=7,NOT(ISERROR(MATCH(A17,[1]Праздники!A:A,0)))),SUM(E17*225)*1.5,SUM(E17*225)) -> 0 | L17: =IF(OR(WEEKDAY(A17)=1,WEEKDAY(A17)=7,NOT(ISERROR(MATCH(A17,[1]Праздники!A:A,0)))),SUM(F17*225)*1.5,SUM(F17*225)) -> 0 | M17: =SUM(G17*15) -> 13248.375 | N17: =SUM(H17)*750 -> 0 | O17: =SUM(I17:N17) -> 13248.375 | P17: =IF(OR(WEEKDAY(A17)=1,WEEKDAY(A17)=7,NOT(ISERROR(MATCH(A17,[1]Праздники!A:A,0)))),"Выходной","Рабочий") -> Рабочий
A18: 46035 | C18: 0 | D18: 0 | G18: =IF(A18 ="",0,G17+C18+E18-D17-F17) -> 883.225 | I18: =IF(P18="Выходной",SUM(C18*150)*1.5,SUM(C18*150)) -> 0 | J18: =IF(P18="Выходной",SUM(D18*150)*1.5,SUM(D18*150)) -> 0 | K18: =IF(OR(WEEKDAY(A18)=1,WEEKDAY(A18)=7,NOT(ISERROR(MATCH(A18,[1]Праздники!A:A,0)))),SUM(E18*225)*1.5,SUM(E18*225)) -> 0 | L18: =IF(OR(WEEKDAY(A18)=1,WEEKDAY(A18)=7,NOT(ISERROR(MATCH(A18,[1]Праздники!A:A,0)))),SUM(F18*225)*1.5,SUM(F18*225)) -> 0 | M18: =SUM(G18*15) -> 13248.375 | N18: =SUM(H18)*750 -> 0 | O18: =SUM(I18:N18) -> 13248.375 | P18: =IF(OR(WEEKDAY(A18)=1,WEEKDAY(A18)=7,NOT(ISERROR(MATCH(A18,[1]Праздники!A:A,0)))),"Выходной","Рабочий") -> Рабочий
... A36: 46053 | C36: 0 | D36: 11 | G36: =IF(A36 ="",0,G35+C36+E36-D35-F35) -> 812.35 | I36: =IF(P36="Выходной",SUM(C36*150)*1.5,SUM(C36*150)) -> 0 | J36: =IF(P36="Выходной",SUM(D36*150)*1.5,SUM(D36*150)) -> 2475 | K36: =IF(OR(WEEKDAY(A36)=1,WEEKDAY(A36)=7,NOT(ISERROR(MATCH(A36,[1]Праздники!A:A,0)))),SUM(E36*225)*1.5,SUM(E36*225)) -> 0 | L36: =IF(OR(WEEKDAY(A36)=1,WEEKDAY(A36)=7,NOT(ISERROR(MATCH(A36,[1]Праздники!A:A,0)))),SUM(F36*225)*1.5,SUM(F36*225)) -> 0 | M36: =SUM(G36*15) -> 12185.25 | N36: =SUM(H36)*750 -> 0 | O36: =SUM(I36:N36) -> 14660.25 | P36: =IF(OR(WEEKDAY(A36)=1,WEEKDAY(A36)=7,NOT(ISERROR(MATCH(A36,[1]Праздники!A:A,0)))),"Выходной","Рабочий") -> Выходной
C37: =SUM(C6:C36) -> 0 | D37: =SUM(D6:D36) -> 81.875 | E37: =SUM(E6:E36) -> 0 | F37: =SUM(F6:F36) -> 0 | G37: =SUM(G6:G36) -> 26622.85 | H37: =SUM(H6:H36) -> 0 | I37: =SUM(I6:I36) -> 0 | J37: =SUM(J6:J36) -> 16818.75 | ... O37: =SUM(O6:O36) -> 416161.5
N38: С НДС; | O38: =O37*1.22 -> 507717.03

Sheet РВ Березовая Пойма
R1: Выходной | S1: Рабочий
Q2: Выгрузка | R2: =SUMIF($P$6:$P$36,R$1,$C6:$C36) -> 4919.69 | S2: =SUMIF($P$6:$P$36,S$1,$C6:$C36) -> 1279.04
A3: ="Отчет по хранению товара РВ " & TEXT(A6,"ММММ ") & YEAR(A6) & " Березовая Пойма" -> Отчет по хранению товара РВ Январь 2026 Березовая Пойма | Q3: Отгрузка | R3: =SUMIF($P$6:$P$36,R$1,$D6:$D36) -> 1020.665 | S3: =SUMIF($P$6:$P$36,S$1,$D6:$D36) -> 1388.08
A4: дата | C4: Выгрузка кол-во тонн | D4: Загрузка кол-во тонн | E4: Выгрузка после 20:00 | F4: Загрузка после 20:00 | G4: Хранение | H4: переконсолидация (тонн) | I4: стоимость выгрузки | J4: стоимость загрузки | K4: Стоимость выгрузки после 20:00 | L4: Стоимость загрузки после 20:00 | M4: стоимость хранения | N4: стоимость переконс. | O4: итого
G5: (кол-во тонн)
A6: 46023 | C6: 0 | D6: 0 | G6: 786.23 | I6: =IF(P6="Выходной",SUM(C6*150)*1.5,SUM(C6*150)) -> 0 | J6: =IF(P6="Выходной",SUM(D6*150)*1.5,SUM(D6*150)) -> 0 | K6: =IF(OR(WEEKDAY(A6)=1,WEEKDAY(A6)=7,NOT(ISERROR(MATCH(A6,[1]Праздники!A:A,0)))),SUM(E6*225)*1.5,SUM(E6*225)) -> 0 | L6: =IF(OR(WEEKDAY(A6)=1,WEEKDAY(A6)=7,NOT(ISERROR(MATCH(A6,[1]Праздники!A:A,0)))),SUM(F6*225)*1.5,SUM(F6*225)) -> 0 | M6: =SUM(G6*15) -> 11793.45 | N6: =SUM(H6)*750 -> 0 | O6: =SUM(I6:N6) -> 11793.45 | P6: =IF(OR(WEEKDAY(A6)=1,WEEKDAY(A6)=7,NOT(ISERROR(MATCH(A6,[1]Праздники!A:A,0)))),"Выходной","Рабочий") -> Выходной
A7: 46024 | C7: 0 | D7: 0 | G7: =IF(A7 ="",0,G6+C7+E7-D6-F6) -> 786.23 | I7: =IF(P7="Выходной",SUM(C7*150)*1.5,SUM(C7*150)) -> 0 | J7: =IF(P7="Выходной",SUM(D7*150)*1.5,SUM(D7*150)) -> 0 | K7: =IF(OR(WEEKDAY(A7)=1,WEEKDAY(A7)=7,NOT(ISERROR(MATCH(A7,[1]Праздники!A:A,0)))),SUM(E7*225)*1.5,SUM(E7*225)) -> 0 | L7: =IF(OR(WEEKDAY(A7)=1,WEEKDAY(A7)=7,NOT(ISERROR(MATCH(A7,[1]Праздники!A:A,0)))),SUM(F7*225)*1.5,SUM(F7*225)) -> 0 | M7: =SUM(G7*15) -> 11793.45 | N7: =SUM(H7)*750 -> 0 | O7: =SUM(I7:N7) -> 11793.45 | P7: =IF(OR(WEEKDAY(A7)=1,WEEKDAY(A7)=7,NOT(ISERROR(MATCH(A7,[1]Праздники!A:A,0)))),"Выходной","Рабочий") -> Выходной
A8: 46025 | C8: 730.12 | D8: 0 | G8: =IF(A8 ="",0,G7+C8+E8-D7-F7) -> 1516.35 | I8: =IF(P8="Выходной",SUM(C8*150)*1.5,SUM(C8*150)) -> 164277 | J8: =IF(P8="Выходной",SUM(D8*150)*1.5,SUM(D8*150)) -> 0 | K8: =IF(OR(WEEKDAY(A8)=1,WEEKDAY(A8)=7,NOT(ISERROR(MATCH(A8,[1]Праздники!A:A,0)))),SUM(E8*225)*1.5,SUM(E8*225)) -> 0 | L8: =IF(OR(WEEKDAY(A8)=1,WEEKDAY(A8)=7,NOT(ISERROR(MATCH(A8,[1]Праздники!A:A,0)))),SUM(F8*225)*1.5,SUM(F8*225)) -> 0 | M8: =SUM(G8*15) -> 22745.25 | N8: =SUM(H8)*750 -> 0 | O8: =SUM(I8:N8) -> 187022.25 | P8: =IF(OR(WEEKDAY(A8)=1,WEEKDAY(A8)=7,NOT(ISERROR(MATCH(A8,[1]Праздники!A:A,0)))),"Выходной","Рабочий") -> Выходной
A9: 46026 | C9: 352.69 | D9: 0 | G9: =IF(A9 ="",0,G8+C9+E9-D8-F8) -> 1869.04 | I9: =IF(P9="Выходной",SUM(C9*150)*1.5,SUM(C9*150)) -> 79355.25 | J9: =IF(P9="Выходной",SUM(D9*150)*1.5,SUM(D9*150)) -> 0 | K9: =IF(OR(WEEKDAY(A9)=1,WEEKDAY(A9)=7,NOT(ISERROR(MATCH(A9,[1]Праздники!A:A,0)))),SUM(E9*225)*1.5,SUM(E9*225)) -> 0 | L9: =IF(OR(WEEKDAY(A9)=1,WEEKDAY(A9)=7,NOT(ISERROR(MATCH(A9,[1]Праздники!A:A,0)))),SUM(F9*225)*1.5,SUM(F9*225)) -> 0 | M9: =SUM(G9*15) -> 28035.6 | N9: =SUM(H9)*750 -> 0 | O9: =SUM(I9:N9) -> 107390.85 | P9: =IF(OR(WEEKDAY(A9)=1,WEEKDAY(A9)=7,NOT(ISERROR(MATCH(A9,[1]Праздники!A:A,0)))),"Выходной","Рабочий") -> Выходной
A10: 46027 | C10: 507.15 | D10: 0 | G10: =IF(A10 ="",0,G9+C10+E10-D9-F9) -> 2376.19 | I10: =IF(P10="Выходной",SUM(C10*150)*1.5,SUM(C10*150)) -> 114108.75 | J10: =IF(P10="Выходной",SUM(D10*150)*1.5,SUM(D10*150)) -> 0 | K10: =IF(OR(WEEKDAY(A10)=1,WEEKDAY(A10)=7,NOT(ISERROR(MATCH(A10,[1]Праздники!A:A,0)))),SUM(E10*225)*1.5,SUM(E10*225)) -> 0 | L10: =IF(OR(WEEKDAY(A10)=1,WEEKDAY(A10)=7,NOT(ISERROR(MATCH(A10,[1]Праздники!A:A,0)))),SUM(F10*225)*1.5,SUM(F10*225)) -> 0 | M10: =SUM(G10*15) -> 35642.85 | N10: =SUM(H10)*750 -> 0 | O10: =SUM(I10:N10) -> 149751.6 | P10: =IF(OR(WEEKDAY(A10)=1,WEEKDAY(A10)=7,NOT(ISERROR(MATCH(A10,[1]Праздники!A:A,0)))),"Выходной","Рабочий") -> Выходной
A11: 46028 | C11: 859.38 | D11: 0 | G11: =IF(A11 ="",0,G10+C11+E11-D10-F10) -> 3235.57 | I11: =IF(P11="Выходной",SUM(C11*150)*1.5,SUM(C11*150)) -> 193360.5 | J11: =IF(P11="Выходной",SUM(D11*150)*1.5,SUM(D11*150)) -> 0 | K11: =IF(OR(WEEKDAY(A11)=1,WEEKDAY(A11)=7,NOT(ISERROR(MATCH(A11,[1]Праздники!A:A,0)))),SUM(E11*225)*1.5,SUM(E11*225)) -> 0 | L11: =IF(OR(WEEKDAY(A11)=1,WEEKDAY(A11)=7,NOT(ISERROR(MATCH(A11,[1]Праздники!A:A,0)))),SUM(F11*225)*1.5,SUM(F11*225)) -> 0 | M11: =SUM(G11*15) -> 48533.55 | N11: =SUM(H11)*750 -> 0 | O11: =SUM(I11:N11) -> 241894.05 | P11: =IF(OR(WEEKDAY(A11)=1,WEEKDAY(A11)=7,NOT(ISERROR(MATCH(A11,[1]Праздники!A:A,0)))),"Выходной","Рабочий") -> Выходной
A12: 46029 | C12: 749.61 | D12: 0 | G12: =IF(A12 ="",0,G11+C12+E12-D11-F11) -> 3985.18 | I12: =IF(P12="Выходной",SUM(C12*150)*1.5,SUM(C12*150)) -> 168662.25 | J12: =IF(P12="Выходной",SUM(D12*150)*1.5,SUM(D12*150)) -> 0 | K12: =IF(OR(WEEKDAY(A12)=1,WEEKDAY(A12)=7,NOT(ISERROR(MATCH(A12,[1]Праздники!A:A,0)))),SUM(E12*225)*1.5,SUM(E12*225)) -> 0 | L12: =IF(OR(WEEKDAY(A12)=1,WEEKDAY(A12)=7,NOT(ISERROR(MATCH(A12,[1]Праздники!A:A,0)))),SUM(F12*225)*1.5,SUM(F12*225)) -> 0 | M12: =SUM(G12*15) -> 59777.7 | N12: =SUM(H12)*750 -> 0 | O12: =SUM(I12:N12) -> 228439.95 | P12: =IF(OR(WEEKDAY(A12)=1,WEEKDAY(A12)=7,NOT(ISERROR(MATCH(A12,[1]Праздники!A:A,0)))),"Выходной","Рабочий") -> Выходной
A13: 46030 | C13: 575.22 | D13: 0 | G13: =IF(A13 ="",0,G12+C13+E13-D12-F12) -> 4560.4 | I13: =IF(P13="Выходной",SUM(C13*150)*1.5,SUM(C13*150)) -> 129424.5 | J13: =IF(P13="Выходной",SUM(D13*150)*1.5,SUM(D13*150)) -> 0 | K13: =IF(OR(WEEKDAY(A13)=1,WEEKDAY(A13)=7,NOT(ISERROR(MATCH(A13,[1]Праздники!A:A,0)))),SUM(E13*225)*1.5,SUM(E13*225)) -> 0 | L13: =IF(OR(WEEKDAY(A13)=1,WEEKDAY(A13)=7,NOT(ISERROR(MATCH(A13,[1]Праздники!A:A,0)))),SUM(F13*225)*1.5,SUM(F13*225)) -> 0 | M13: =SUM(G13*15) -> 68406 | N13: =SUM(H13)*750 -> 0 | O13: =SUM(I13:N13) -> 197830.5 | P13: =IF(OR(WEEKDAY(A13)=1,WEEKDAY(A13)=7,NOT(ISERROR(MATCH(A13,[1]Праздники!A:A,0)))),"Выходной","Рабочий") -> Выходной
A14: 46031 | C14: 413.65 | D14: 0 | G14: =IF(A14 ="",0,G13+C14+E14-D13-F13) -> 4974.05 | I14: =IF(P14="Выходной",SUM(C14*150)*1.5,SUM(C14*150)) -> 93071.25 | J14: =IF(P14="Выходной",SUM(D14*150)*1.5,SUM(D14*150)) -> 0 | K14: =IF(OR(WEEKDAY(A14)=1,WEEKDAY(A14)=7,NOT(ISERROR(MATCH(A14,[1]Праздники!A:A,0)))),SUM(E14*225)*1.5,SUM(E14*225)) -> 0 | L14: =IF(OR(WEEKDAY(A14)=1,WEEKDAY(A14)=7,NOT(ISERROR(MATCH(A14,[1]Праздники!A:A,0)))),SUM(F14*225)*1.5,SUM(F14*225)) -> 0 | M14: =SUM(G14*15) -> 74610.75 | N14: =SUM(H14)*750 -> 0 | O14: =SUM(I14:N14) -> 167682 | P14: =IF(OR(WEEKDAY(A14)=1,WEEKDAY(A14)=7,NOT(ISERROR(MATCH(A14,[1]Праздники!A:A,0)))),"Выходной","Рабочий") -> Выходной
A15: 46032 | C15: 264.69 | D15: 0 | G15: =IF(A15 ="",0,G14+C15+E15-D14-F14) -> 5238.74 | I15: =IF(P15="Выходной",SUM(C15*150)*1.5,SUM(C15*150)) -> 59555.25 | J15: =IF(P15="Выходной",SUM(D15*150)*1.5,SUM(D15*150)) -> 0 | K15: =IF(OR(WEEKDAY(A15)=1,WEEKDAY(A15)=7,NOT(ISERROR(MATCH(A15,[1]Праздники!A:A,0)))),SUM(E15*225)*1.5,SUM(E15*225)) -> 0 | L15: =IF(OR(WEEKDAY(A15)=1,WEEKDAY(A15)=7,NOT(ISERROR(MATCH(A15,[1]Праздники!A:A,0)))),SUM(F15*225)*1.5,SUM(F15*225)) -> 0 | M15: =SUM(G15*15) -> 78581.1 | N15: =SUM(H15)*750 -> 0 | O15: =SUM(I15:N15) -> 138136.35 | P15: =IF(OR(WEEKDAY(A15)=1,WEEKDAY(A15)=7,NOT(ISERROR(MATCH(A15,[1]Праздники!A:A,0)))),"Выходной","Рабочий") -> Выходной
A16: 46033 | C16: 200.42 | D16: 0 | G16: =IF(A16 ="",0,G15+C16+E16-D15-F15) -> 5439.16 | I16: =IF(P16="Выходной",SUM(C16*150)*1.5,SUM(C16*150)) -> 45094.5 | J16: =IF(P16="Выходной",SUM(D16*150)*1.5,SUM(D16*150)) -> 0 | K16: =IF(OR(WEEKDAY(A16)=1,WEEKDAY(A16)=7,NOT(ISERROR(MATCH(A16,[1]Праздники!A:A,0)))),SUM(E16*225)*1.5,SUM(E16*225)) -> 0 | L16: =IF(OR(WEEKDAY(A16)=1,WEEKDAY(A16)=7,NOT(ISERROR(MATCH(A16,[1]Праздники!A:A,0)))),SUM(F16*225)*1.5,SUM(F16*225)) -> 0 | M16: =SUM(G16*15) -> 81587.4 | N16: =SUM(H16)*750 -> 0 | O16: =SUM(I16:N16) -> 126681.9 | P16: =IF(OR(WEEKDAY(A16)=1,WEEKDAY(A16)=7,NOT(ISERROR(MATCH(A16,[1]Праздники!A:A,0)))),"Выходной","Рабочий") -> Выходной
A17: 46034 | C17: 990.51 | D17: 0 | G17: =IF(A17 ="",0,G16+C17+E17-D16-F16) -> 6429.67 | I17: =IF(P17="Выходной",SUM(C17*150)*1.5,SUM(C17*150)) -> 148576.5 | J17: =IF(P17="Выходной",SUM(D17*150)*1.5,SUM(D17*150)) -> 0 | K17: =IF(OR(WEEKDAY(A17)=1,WEEKDAY(A17)=7,NOT(ISERROR(MATCH(A17,[1]Праздники!A:A,0)))),SUM(E17*225)*1.5,SUM(E17*225)) -> 0 | L17: =IF(OR(WEEKDAY(A17)=1,WEEKDAY(A17)=7,NOT(ISERROR(MATCH(A17,[1]Праздники!A:A,0)))),SUM(F17*225)*1.5,SUM(F17*225)) -> 0 | M17: =SUM(G17*15) -> 96445.05 | N17: =SUM(H17)*750 -> 0 | O17: =SUM(I17:N17) -> 245021.55 | P17: =IF(OR(WEEKDAY(A17)=1,WEEKDAY(A17)=7,NOT(ISERROR(MATCH(A17,[1]Праздники!A:A,0)))),"Выходной","Рабочий") -> Рабочий
A18: 46035 | C18: 110.69 | D18: 22 | G18: =IF(A18 ="",0,G17+C18+E18-D17-F17) -> 6540.36 | I18: =IF(P18="Выходной",SUM(C18*150)*1.5,SUM(C18*150)) -> 16603.5 | J18: =IF(P18="Выходной",SUM(D18*150)*1.5,SUM(D18*150)) -> 3300 | K18: =IF(OR(WEEKDAY(A18)=1,WEEKDAY(A18)=7,NOT(ISERROR(MATCH(A18,[1]Праздники!A:A,0)))),SUM(E18*225)*1.5,SUM(E18*225)) -> 0 | L18: =IF(OR(WEEKDAY(A18)=1,WEEKDAY(A18)=7,NOT(ISERROR(MATCH(A18,[1]Праздники!A:A,0)))),SUM(F18*225)*1.5,SUM(F18*225)) -> 0 | M18: =SUM(G18*15) -> 98105.4 | N18: =SUM(H18)*750 -> 0 | O18: =SUM(I18:N18) -> 118008.9 | P18: =IF(OR(WEEKDAY(A18)=1,WEEKDAY(A18)=7,NOT(ISERROR(MATCH(A18,[1]Праздники!A:A,0)))),"Выходной","Рабочий") -> Рабочий
... A36: 46053 | C36: 266.76 | D36: 253.465 | G36: =IF(A36 ="",0,G35+C36+E36-D35-F35) -> 4829.68 | I36: =IF(P36="Выходной",SUM(C36*150)*1.5,SUM(C36*150)) -> 60021 | J36: =IF(P36="Выходной",SUM(D36*150)*1.5,SUM(D36*150)) -> 57029.625 | K36: =IF(OR(WEEKDAY(A36)=1,WEEKDAY(A36)=7,NOT(ISERROR(MATCH(A36,[1]Праздники!A:A,0)))),SUM(E36*225)*1.5,SUM(E36*225)) -> 0 | L36: =IF(OR(WEEKDAY(A36)=1,WEEKDAY(A36)=7,NOT(ISERROR(MATCH(A36,[1]Праздники!A:A,0)))),SUM(F36*225)*1.5,SUM(F36*225)) -> 0 | M36: =SUM(G36*15) -> 72445.2 | N36: =SUM(H36)*750 -> 0 | O36: =SUM(I36:N36) -> 189495.83 | P36: =IF(OR(WEEKDAY(A36)=1,WEEKDAY(A36)=7,NOT(ISERROR(MATCH(A36,[1]Праздники!A:A,0)))),"Выходной","Рабочий") -> Выходной
C37: =SUM(C6:C36) -> 6198.73 | D37: =SUM(D6:D36) -> 2408.745 | E37: =SUM(E6:E36) -> 0 | F37: =SUM(F6:F36) -> 0 | G37: =SUM(G6:G36) -> 143700.66 | H37: =SUM(H6:H36) -> 0 | I37: =SUM(I6:I36) -> 1298786.2 | J37: =SUM(J6:J36) -> 437861.62 | ... O37: =SUM(O6:O36) -> 3892157.8
N38: С НДС; | O38: =O37*1.22 -> 4748432.5

Sheet РВ Новикова-Прибоя
R1: Выходной | S1: Рабочий
Q2: Выгрузка | R2: =SUMIF($P$6:$P$36,R$1,$C6:$C36) -> 110.23 | S2: =SUMIF($P$6:$P$36,S$1,$C6:$C36) -> 1212.07
A3: ="Отчет по хранению товара РВ " & TEXT(A6,"ММММ ") & YEAR(A6) & " Новикова" -> Отчет по хранению товара РВ Январь 2026 Новикова | Q3: Отгрузка | R3: =SUMIF($P$6:$P$36,R$1,$D6:$D36) -> 82.475 | S3: =SUMIF($P$6:$P$36,S$1,$D6:$D36) -> 88
A4: дата | C4: Выгрузка кол-во тонн | D4: Загрузка кол-во тонн | E4: Выгрузка после 20:00 | F4: Загрузка после 20:00 | G4: Хранение | H4: переконсолидация (тонн) | I4: стоимость выгрузки | J4: стоимость загрузки | K4: Стоимость выгрузки после 20:00 | L4: Стоимость загрузки после 20:00 | M4: стоимость хранения | N4: стоимость переконс. | O4: итого
G5: (кол-во тонн)
A6: 46023 | C6: 0 | D6: 0 | G6: 190.67 | I6: =IF(P6="Выходной",SUM(C6*150)*1.5,SUM(C6*150)) -> 0 | J6: =IF(P6="Выходной",SUM(D6*150)*1.5,SUM(D6*150)) -> 0 | K6: =IF(OR(WEEKDAY(A6)=1,WEEKDAY(A6)=7,NOT(ISERROR(MATCH(A6,[1]Праздники!A:A,0)))),SUM(E6*225)*1.5,SUM(E6*225)) -> 0 | L6: =IF(OR(WEEKDAY(A6)=1,WEEKDAY(A6)=7,NOT(ISERROR(MATCH(A6,[1]Праздники!A:A,0)))),SUM(F6*225)*1.5,SUM(F6*225)) -> 0 | M6: =SUM(G6*15) -> 2860.05 | N6: =SUM(H6)*750 -> 0 | O6: =SUM(I6:N6) -> 2860.05 | P6: =IF(OR(WEEKDAY(A6)=1,WEEKDAY(A6)=7,NOT(ISERROR(MATCH(A6,[1]Праздники!A:A,0)))),"Выходной","Рабочий") -> Выходной
A7: 46024 | C7: 0 | D7: 0 | G7: =IF(A7 ="",0,G6+C7+E7-D6-F6) -> 190.67 | I7: =IF(P7="Выходной",SUM(C7*150)*1.5,SUM(C7*150)) -> 0 | J7: =IF(P7="Выходной",SUM(D7*150)*1.5,SUM(D7*150)) -> 0 | K7: =IF(OR(WEEKDAY(A7)=1,WEEKDAY(A7)=7,NOT(ISERROR(MATCH(A7,[1]Праздники!A:A,0)))),SUM(E7*225)*1.5,SUM(E7*225)) -> 0 | L7: =IF(OR(WEEKDAY(A7)=1,WEEKDAY(A7)=7,NOT(ISERROR(MATCH(A7,[1]Праздники!A:A,0)))),SUM(F7*225)*1.5,SUM(F7*225)) -> 0 | M7: =SUM(G7*15) -> 2860.05 | N7: =SUM(H7)*750 -> 0 | O7: =SUM(I7:N7) -> 2860.05 | P7: =IF(OR(WEEKDAY(A7)=1,WEEKDAY(A7)=7,NOT(ISERROR(MATCH(A7,[1]Праздники!A:A,0)))),"Выходной","Рабочий") -> Выходной
A8: 46025 | C8: 0 | D8: 0 | G8: =IF(A8 ="",0,G7+C8+E8-D7-F7) -> 190.67 | I8: =IF(P8="Выходной",SUM(C8*150)*1.5,SUM(C8*150)) -> 0 | J8: =IF(P8="Выходной",SUM(D8*150)*1.5,SUM(D8*150)) -> 0 | K8: =IF(OR(WEEKDAY(A8)=1,WEEKDAY(A8)=7,NOT(ISERROR(MATCH(A8,[1]Праздники!A:A,0)))),SUM(E8*225)*1.5,SUM(E8*225)) -> 0 | L8: =IF(OR(WEEKDAY(A8)=1,WEEKDAY(A8)=7,NOT(ISERROR(MATCH(A8,[1]Праздники!A:A,0)))),SUM(F8*225)*1.5,SUM(F8*225)) -> 0 | M8: =SUM(G8*15) -> 2860.05 | N8: =SUM(H8)*750 -> 0 | O8: =SUM(I8:N8) -> 2860.05 | P8: =IF(OR(WEEKDAY(A8)=1,WEEKDAY(A8)=7,NOT(ISERROR(MATCH(A8,[1]Праздники!A:A,0)))),"Выходной","Рабочий") -> Выходной
A9: 46026 | C9: 0 | D9: 0 | G9: =IF(A9 ="",0,G8+C9+E9-D8-F8) -> 190.67 | I9: =IF(P9="Выходной",SUM(C9*150)*1.5,SUM(C9*150)) -> 0 | J9: =IF(P9="Выходной",SUM(D9*150)*1.5,SUM(D9*150)) -> 0 | K9: =IF(OR(WEEKDAY(A9)=1,WEEKDAY(A9)=7,NOT(ISERROR(MATCH(A9,[1]Праздники!A:A,0)))),SUM(E9*225)*1.5,SUM(E9*225)) -> 0 | L9: =IF(OR(WEEKDAY(A9)=1,WEEKDAY(A9)=7,NOT(ISERROR(MATCH(A9,[1]Праздники!A:A,0)))),SUM(F9*225)*1.5,SUM(F9*225)) -> 0 | M9: =SUM(G9*15) -> 2860.05 | N9: =SUM(H9)*750 -> 0 | O9: =SUM(I9:N9) -> 2860.05 | P9: =IF(OR(WEEKDAY(A9)=1,WEEKDAY(A9)=7,NOT(ISERROR(MATCH(A9,[1]Праздники!A:A,0)))),"Выходной","Рабочий") -> Выходной
A10: 46027 | C10: 0 | D10: 0 | G10: =IF(A10 ="",0,G9+C10+E10-D9-F9) -> 190.67 | I10: =IF(P10="Выходной",SUM(C10*150)*1.5,SUM(C10*150)) -> 0 | J10: =IF(P10="Выходной",SUM(D10*150)*1.5,SUM(D10*150)) -> 0 | K10: =IF(OR(WEEKDAY(A10)=1,WEEKDAY(A10)=7,NOT(ISERROR(MATCH(A10,[1]Праздники!A:A,0)))),SUM(E10*225)*1.5,SUM(E10*225)) -> 0 | L10: =IF(OR(WEEKDAY(A10)=1,WEEKDAY(A10)=7,NOT(ISERROR(MATCH(A10,[1]Праздники!A:A,0)))),SUM(F10*225)*1.5,SUM(F10*225)) -> 0 | M10: =SUM(G10*15) -> 2860.05 | N10: =SUM(H10)*750 -> 0 | O10: =SUM(I10:N10) -> 2860.05 | P10: =IF(OR(WEEKDAY(A10)=1,WEEKDAY(A10)=7,NOT(ISERROR(MATCH(A10,[1]Праздники!A:A,0)))),"Выходной","Рабочий") -> Выходной
A11: 46028 | C11: 0 | D11: 0 | G11: =IF(A11 ="",0,G10+C11+E11-D10-F10) -> 190.67 | I11: =IF(P11="Выходной",SUM(C11*150)*1.5,SUM(C11*150)) -> 0 | J11: =IF(P11="Выходной",SUM(D11*150)*1.5,SUM(D11*150)) -> 0 | K11: =IF(OR(WEEKDAY(A11)=1,WEEKDAY(A11)=7,NOT(ISERROR(MATCH(A11,[1]Праздники!A:A,0)))),SUM(E11*225)*1.5,SUM(E11*225)) -> 0 | L11: =IF(OR(WEEKDAY(A11)=1,WEEKDAY(A11)=7,NOT(ISERROR(MATCH(A11,[1]Праздники!A:A,0)))),SUM(F11*225)*1.5,SUM(F11*225)) -> 0 | M11: =SUM(G11*15) -> 2860.05 | N11: =SUM(H11)*750 -> 0 | O11: =SUM(I11:N11) -> 2860.05 | P11: =IF(OR(WEEKDAY(A11)=1,WEEKDAY(A11)=7,NOT(ISERROR(MATCH(A11,[1]Праздники!A:A,0)))),"Выходной","Рабочий") -> Выходной
A12: 46029 | C12: 0 | D12: 0 | G12: =IF(A12 ="",0,G11+C12+E12-D11-F11) -> 190.67 | I12: =IF(P12="Выходной",SUM(C12*150)*1.5,SUM(C12*150)) -> 0 | J12: =IF(P12="Выходной",SUM(D12*150)*1.5,SUM(D12*150)) -> 0 | K12: =IF(OR(WEEKDAY(A12)=1,WEEKDAY(A12)=7,NOT(ISERROR(MATCH(A12,[1]Праздники!A:A,0)))),SUM(E12*225)*1.5,SUM(E12*225)) -> 0 | L12: =IF(OR(WEEKDAY(A12)=1,WEEKDAY(A12)=7,NOT(ISERROR(MATCH(A12,[1]Праздники!A:A,0)))),SUM(F12*225)*1.5,SUM(F12*225)) -> 0 | M12: =SUM(G12*15) -> 2860.05 | N12: =SUM(H12)*750 -> 0 | O12: =SUM(I12:N12) -> 2860.05 | P12: =IF(OR(WEEKDAY(A12)=1,WEEKDAY(A12)=7,NOT(ISERROR(MATCH(A12,[1]Праздники!A:A,0)))),"Выходной","Рабочий") -> Выходной
A13: 46030 | C13: 0 | D13: 0 | G13: =IF(A13 ="",0,G12+C13+E13-D12-F12) -> 190.67 | I13: =IF(P13="Выходной",SUM(C13*150)*1.5,SUM(C13*150)) -> 0 | J13: =IF(P13="Выходной",SUM(D13*150)*1.5,SUM(D13*150)) -> 0 | K13: =IF(OR(WEEKDAY(A13)=1,WEEKDAY(A13)=7,NOT(ISERROR(MATCH(A13,[1]Праздники!A:A,0)))),SUM(E13*225)*1.5,SUM(E13*225)) -> 0 | L13: =IF(OR(WEEKDAY(A13)=1,WEEKDAY(A13)=7,NOT(ISERROR(MATCH(A13,[1]Праздники!A:A,0)))),SUM(F13*225)*1.5,SUM(F13*225)) -> 0 | M13: =SUM(G13*15) -> 2860.05 | N13: =SUM(H13)*750 -> 0 | O13: =SUM(I13:N13) -> 2860.05 | P13: =IF(OR(WEEKDAY(A13)=1,WEEKDAY(A13)=7,NOT(ISERROR(MATCH(A13,[1]Праздники!A:A,0)))),"Выходной","Рабочий") -> Выходной
A14: 46031 | C14: 0 | D14: 0 | G14: =IF(A14 ="",0,G13+C14+E14-D13-F13) -> 190.67 | I14: =IF(P14="Выходной",SUM(C14*150)*1.5,SUM(C14*150)) -> 0 | J14: =IF(P14="Выходной",SUM(D14*150)*1.5,SUM(D14*150)) -> 0 | K14: =IF(OR(WEEKDAY(A14)=1,WEEKDAY(A14)=7,NOT(ISERROR(MATCH(A14,[1]Праздники!A:A,0)))),SUM(E14*225)*1.5,SUM(E14*225)) -> 0 | L14: =IF(OR(WEEKDAY(A14)=1,WEEKDAY(A14)=7,NOT(ISERROR(MATCH(A14,[1]Праздники!A:A,0)))),SUM(F14*225)*1.5,SUM(F14*225)) -> 0 | M14: =SUM(G14*15) -> 2860.05 | N14: =SUM(H14)*750 -> 0 | O14: =SUM(I14:N14) -> 2860.05 | P14: =IF(OR(WEEKDAY(A14)=1,WEEKDAY(A14)=7,NOT(ISERROR(MATCH(A14,[1]Праздники!A:A,0)))),"Выходной","Рабочий") -> Выходной
A15: 46032 | C15: 0 | D15: 0 | G15: =IF(A15 ="",0,G14+C15+E15-D14-F14) -> 190.67 | I15: =IF(P15="Выходной",SUM(C15*150)*1.5,SUM(C15*150)) -> 0 | J15: =IF(P15="Выходной",SUM(D15*150)*1.5,SUM(D15*150)) -> 0 | K15: =IF(OR(WEEKDAY(A15)=1,WEEKDAY(A15)=7,NOT(ISERROR(MATCH(A15,[1]Праздники!A:A,0)))),SUM(E15*225)*1.5,SUM(E15*225)) -> 0 | L15: =IF(OR(WEEKDAY(A15)=1,WEEKDAY(A15)=7,NOT(ISERROR(MATCH(A15,[1]Праздники!A:A,0)))),SUM(F15*225)*1.5,SUM(F15*225)) -> 0 | M15: =SUM(G15*15) -> 2860.05 | N15: =SUM(H15)*750 -> 0 | O15: =SUM(I15:N15) -> 2860.05 | P15: =IF(OR(WEEKDAY(A15)=1,WEEKDAY(A15)=7,NOT(ISERROR(MATCH(A15,[1]Праздники!A:A,0)))),"Выходной","Рабочий") -> Выходной
A16: 46033 | C16: 0 | D16: 0 | G16: =IF(A16 ="",0,G15+C16+E16-D15-F15) -> 190.67 | I16: =IF(P16="Выходной",SUM(C16*150)*1.5,SUM(C16*150)) -> 0 | J16: =IF(P16="Выходной",SUM(D16*150)*1.5,SUM(D16*150)) -> 0 | K16: =IF(OR(WEEKDAY(A16)=1,WEEKDAY(A16)=7,NOT(ISERROR(MATCH(A16,[1]Праздники!A:A,0)))),SUM(E16*225)*1.5,SUM(E16*225)) -> 0 | L16: =IF(OR(WEEKDAY(A16)=1,WEEKDAY(A16)=7,NOT(ISERROR(MATCH(A16,[1]Праздники!A:A,0)))),SUM(F16*225)*1.5,SUM(F16*225)) -> 0 | M16: =SUM(G16*15) -> 2860.05 | N16: =SUM(H16)*750 -> 0 | O16: =SUM(I16:N16) -> 2860.05 | P16: =IF(OR(WEEKDAY(A16)=1,WEEKDAY(A16)=7,NOT(ISERROR(MATCH(A16,[1]Праздники!A:A,0)))),"Выходной","Рабочий") -> Выходной
A17: 46034 | C17: 0 | D17: 0 | G17: =IF(A17 ="",0,G16+C17+E17-D16-F16)+2.545 -> 193.215 | I17: =IF(P17="Выходной",SUM(C17*150)*1.5,SUM(C17*150)) -> 0 | J17: =IF(P17="Выходной",SUM(D17*150)*1.5,SUM(D17*150)) -> 0 | K17: =IF(OR(WEEKDAY(A17)=1,WEEKDAY(A17)=7,NOT(ISERROR(MATCH(A17,[1]Праздники!A:A,0)))),SUM(E17*225)*1.5,SUM(E17*225)) -> 0 | L17: =IF(OR(WEEKDAY(A17)=1,WEEKDAY(A17)=7,NOT(ISERROR(MATCH(A17,[1]Праздники!A:A,0)))),SUM(F17*225)*1.5,SUM(F17*225)) -> 0 | M17: =SUM(G17*15) -> 2898.225 | N17: =SUM(H17)*750 -> 0 | O17: =SUM(I17:N17) -> 2898.225 | P17: =IF(OR(WEEKDAY(A17)=1,WEEKDAY(A17)=7,NOT(ISERROR(MATCH(A17,[1]Праздники!A:A,0)))),"Выходной","Рабочий") -> Рабочий
A18: 46035 | C18: 264 | D18: 0 | G18: =IF(A18 ="",0,G17+C18+E18-D17-F17) -> 457.215 | I18: =IF(P18="Выходной",SUM(C18*150)*1.5,SUM(C18*150)) -> 39600 | J18: =IF(P18="Выходной",SUM(D18*150)*1.5,SUM(D18*150)) -> 0 | K18: =IF(OR(WEEKDAY(A18)=1,WEEKDAY(A18)=7,NOT(ISERROR(MATCH(A18,[1]Праздники!A:A,0)))),SUM(E18*225)*1.5,SUM(E18*225)) -> 0 | L18: =IF(OR(WEEKDAY(A18)=1,WEEKDAY(A18)=7,NOT(ISERROR(MATCH(A18,[1]Праздники!A:A,0)))),SUM(F18*225)*1.5,SUM(F18*225)) -> 0 | M18: =SUM(G18*15) -> 6858.225 | N18: =SUM(H18)*750 -> 0 | O18: =SUM(I18:N18) -> 46458.225 | P18: =IF(OR(WEEKDAY(A18)=1,WEEKDAY(A18)=7,NOT(ISERROR(MATCH(A18,[1]Праздники!A:A,0)))),"Выходной","Рабочий") -> Рабочий
A19: 46036 | C19: 330 | D19: 0 | G19: =IF(A19 ="",0,G18+C19+E19-D18-F18) -> 787.215 | I19: =IF(P19="Выходной",SUM(C19*150)*1.5,SUM(C19*150)) -> 49500 | J19: =IF(P19="Выходной",SUM(D19*150)*1.5,SUM(D19*150)) -> 0 | K19: =IF(OR(WEEKDAY(A19)=1,WEEKDAY(A19)=7,NOT(ISERROR(MATCH(A19,[1]Праздники!A:A,0)))),SUM(E19*225)*1.5,SUM(E19*225)) -> 0 | L19: =IF(OR(WEEKDAY(A19)=1,WEEKDAY(A19)=7,NOT(ISERROR(MATCH(A19,[1]Праздники!A:A,0)))),SUM(F19*225)*1.5,SUM(F19*225)) -> 0 | M19: =SUM(G19*15) -> 11808.225 | N19: =SUM(H19)*750 -> 0 | O19: =SUM(I19:N19) -> 61308.225 | P19: =IF(OR(WEEKDAY(A19)=1,WEEKDAY(A19)=7,NOT(ISERROR(MATCH(A19,[1]Праздники!A:A,0)))),"Выходной","Рабочий") -> Рабочий
A20: 46037 | C20: 242 | D20: 0 | G20: =IF(A20 ="",0,G19+C20+E20-D19-F19) -> 1029.215 | I20: =IF(P20="Выходной",SUM(C20*150)*1.5,SUM(C20*150)) -> 36300 | J20: =IF(P20="Выходной",SUM(D20*150)*1.5,SUM(D20*150)) -> 0 | K20: =IF(OR(WEEKDAY(A20)=1,WEEKDAY(A20)=7,NOT(ISERROR(MATCH(A20,[1]Праздники!A:A,0)))),SUM(E20*225)*1.5,SUM(E20*225)) -> 0 | L20: =IF(OR(WEEKDAY(A20)=1,WEEKDAY(A20)=7,NOT(ISERROR(MATCH(A20,[1]Праздники!A:A,0)))),SUM(F20*225)*1.5,SUM(F20*225)) -> 0 | M20: =SUM(G20*15) -> 15438.225 | N20: =SUM(H20)*750 -> 0 | O20: =SUM(I20:N20) -> 51738.225 | P20: =IF(OR(WEEKDAY(A20)=1,WEEKDAY(A20)=7,NOT(ISERROR(MATCH(A20,[1]Праздники!A:A,0)))),"Выходной","Рабочий") -> Рабочий
