Workbook

Sheet Лист1

Sheet Биаксплен Новосибирск
A1: =T37 -> 143189.07
A2: ="Отчет по хранению товара за " & TEXT(B5,"ММММ ГГГГ") -> Отчет по хранению товара за Май 2026
A3: № | B3: дата | D3: Выгрузка кол-во | E3: Загрузка кол-во | F3: Хранение | G3: Резервирование 70 т | H3: Мин. Суточный резерв 0 т | I3: переконсолидация (тонн) | J3: Паллетирование | K3: Ночная загруска выгрузка | L3: стоимость ночной загруски | M3: стоимость выгрузки | N3: стоимость загрузки | O3: стоимость хранения | P3: Стоимость резервирования | Q3: Стоимость мин.суточной бработки | R3: стоимость переконс. | S3: Стоимость паллетирования | T3: итого
A5: 1 | B5: 46143 | F5: =1.5674+D5-E5 -> 1.5674 | G5: =IF(OR(B5="",NOT(ISERROR(SEARCH("KPI",$A$2))),NOT(ISERROR(SEARCH("Полиом",$A$2)))),0,IF(70-F5<=0,0,70-F5)) -> 68.4326 | L5: =SUM(K5*240) -> 0 | M5: =SUM(D5*120) -> 0 | N5: =SUM(E5*120) -> 0 | O5: =SUM(F5*54) -> 84.6396 | P5: =SUM(G5*54) -> 3695.3604 | Q5: =SUM(H5*120) -> 0 | R5: =SUM(I5*1000) -> 0 | S5: =SUM(J5*140) -> 0 | T5: =SUM(L5:S5) -> 3780
A6: 2 | B6: 46144 | F6: =F5-E6+D6 -> 1.5674 | G6: =IF(OR(B6="",NOT(ISERROR(SEARCH("KPI",$A$2))),NOT(ISERROR(SEARCH("Полиом",$A$2)))),0,IF(70-F6<=0,0,70-F6)) -> 68.4326 | L6: =SUM(K6*240) -> 0 | M6: =SUM(D6*120) -> 0 | N6: =SUM(E6*120) -> 0 | O6: =SUM(F6*54) -> 84.6396 | P6: =SUM(G6*54) -> 3695.3604 | Q6: =SUM(H6*120) -> 0 | R6: =SUM(I6*1000) -> 0 | S6: =SUM(J6*140) -> 0 | T6: =SUM(L6:S6) -> 3780
A7: 3 | B7: 46145 | F7: =F6-E7+D7 -> 1.5674 | G7: =IF(OR(B7="",NOT(ISERROR(SEARCH("KPI",$A$2))),NOT(ISERROR(SEARCH("Полиом",$A$2)))),0,IF(70-F7<=0,0,70-F7)) -> 68.4326 | L7: =SUM(K7*240) -> 0 | M7: =SUM(D7*120) -> 0 | N7: =SUM(E7*120) -> 0 | O7: =SUM(F7*54) -> 84.6396 | P7: =SUM(G7*54) -> 3695.3604 | Q7: =SUM(H7*120) -> 0 | R7: =SUM(I7*1000) -> 0 | S7: =SUM(J7*140) -> 0 | T7: =SUM(L7:S7) -> 3780
A8: 4 | B8: 46146 | F8: =F7-E8+D8 -> 1.5674 | G8: =IF(OR(B8="",NOT(ISERROR(SEARCH("KPI",$A$2))),NOT(ISERROR(SEARCH("Полиом",$A$2)))),0,IF(70-F8<=0,0,70-F8)) -> 68.4326 | L8: =SUM(K8*240) -> 0 | M8: =SUM(D8*120) -> 0 | N8: =SUM(E8*120) -> 0 | O8: =SUM(F8*54) -> 84.6396 | P8: =SUM(G8*54) -> 3695.3604 | Q8: =SUM(H8*120) -> 0 | R8: =SUM(I8*1000) -> 0 | S8: =SUM(J8*140) -> 0 | T8: =SUM(L8:S8) -> 3780
A9: 5 | B9: 46147 | F9: =F8-E9+D9 -> 1.5674 | G9: =IF(OR(B9="",NOT(ISERROR(SEARCH("KPI",$A$2))),NOT(ISERROR(SEARCH("Полиом",$A$2)))),0,IF(70-F9<=0,0,70-F9)) -> 68.4326 | L9: =SUM(K9*240) -> 0 | M9: =SUM(D9*120) -> 0 | N9: =SUM(E9*120) -> 0 | O9: =SUM(F9*54) -> 84.6396 | P9: =SUM(G9*54) -> 3695.3604 | Q9: =SUM(H9*120) -> 0 | R9: =SUM(I9*1000) -> 0 | S9: =SUM(J9*140) -> 0 | T9: =SUM(L9:S9) -> 3780
A10: 6 | B10: 46148 | F10: =F9-E10+D10 -> 1.5674 | G10: =IF(OR(B10="",NOT(ISERROR(SEARCH("KPI",$A$2))),NOT(ISERROR(SEARCH("Полиом",$A$2)))),0,IF(70-F10<=0,0,70-F10)) -> 68.4326 | L10: =SUM(K10*240) -> 0 | M10: =SUM(D10*120) -> 0 | N10: =SUM(E10*120) -> 0 | O10: =SUM(F10*54) -> 84.6396 | P10: =SUM(G10*54) -> 3695.3604 | Q10: =SUM(H10*120) -> 0 | R10: =SUM(I10*1000) -> 0 | S10: =SUM(J10*140) -> 0 | T10: =SUM(L10:S10) -> 3780
A11: 7 | B11: 46149 | F11: =F10-E11+D11 -> 1.5674 | G11: =IF(OR(B11="",NOT(ISERROR(SEARCH("KPI",$A$2))),NOT(ISERROR(SEARCH("Полиом",$A$2)))),0,IF(70-F11<=0,0,70-F11)) -> 68.4326 | L11: =SUM(K11*240) -> 0 | M11: =SUM(D11*120) -> 0 | N11: =SUM(E11*120) -> 0 | O11: =SUM(F11*54) -> 84.6396 | P11: =SUM(G11*54) -> 3695.3604 | Q11: =SUM(H11*120) -> 0 | R11: =SUM(I11*1000) -> 0 | S11: =SUM(J11*140) -> 0 | T11: =SUM(L11:S11) -> 3780
A12: 8 | B12: 46150 | F12: =F11-E12+D12 -> 1.5674 | G12: =IF(OR(B12="",NOT(ISERROR(SEARCH("KPI",$A$2))),NOT(ISERROR(SEARCH("Полиом",$A$2)))),0,IF(70-F12<=0,0,70-F12)) -> 68.4326 | L12: =SUM(K12*240) -> 0 | M12: =SUM(D12*120) -> 0 | N12: =SUM(E12*120) -> 0 | O12: =SUM(F12*54) -> 84.6396 | P12: =SUM(G12*54) -> 3695.3604 | Q12: =SUM(H12*120) -> 0 | R12: =SUM(I12*1000) -> 0 | S12: =SUM(J12*140) -> 0 | T12: =SUM(L12:S12) -> 3780
A13: 9 | B13: 46151 | F13: =F12-E13+D13 -> 1.5674 | G13: =IF(OR(B13="",NOT(ISERROR(SEARCH("KPI",$A$2))),NOT(ISERROR(SEARCH("Полиом",$A$2)))),0,IF(70-F13<=0,0,70-F13)) -> 68.4326 | L13: =SUM(K13*240) -> 0 | M13: =SUM(D13*120) -> 0 | N13: =SUM(E13*120) -> 0 | O13: =SUM(F13*54) -> 84.6396 | P13: =SUM(G13*54) -> 3695.3604 | Q13: =SUM(H13*120) -> 0 | R13: =SUM(I13*1000) -> 0 | S13: =SUM(J13*140) -> 0 | T13: =SUM(L13:S13) -> 3780
A14: 10 | B14: 46152 | F14: =F13-E14+D14 -> 1.5674 | G14: =IF(OR(B14="",NOT(ISERROR(SEARCH("KPI",$A$2))),NOT(ISERROR(SEARCH("Полиом",$A$2)))),0,IF(70-F14<=0,0,70-F14)) -> 68.4326 | L14: =SUM(K14*240) -> 0 | M14: =SUM(D14*120) -> 0 | N14: =SUM(E14*120) -> 0 | O14: =SUM(F14*54) -> 84.6396 | P14: =SUM(G14*54) -> 3695.3604 | Q14: =SUM(H14*120) -> 0 | R14: =SUM(I14*1000) -> 0 | S14: =SUM(J14*140) -> 0 | T14: =SUM(L14:S14) -> 3780
A15: 11 | B15: 46153 | F15: =F14-E15+D15 -> 1.5674 | G15: =IF(OR(B15="",NOT(ISERROR(SEARCH("KPI",$A$2))),NOT(ISERROR(SEARCH("Полиом",$A$2)))),0,IF(70-F15<=0,0,70-F15)) -> 68.4326 | L15: =SUM(K15*240) -> 0 | M15: =SUM(D15*120) -> 0 | N15: =SUM(E15*120) -> 0 | O15: =SUM(F15*54) -> 84.6396 | P15: =SUM(G15*54) -> 3695.3604 | Q15: =SUM(H15*120) -> 0 | R15: =SUM(I15*1000) -> 0 | S15: =SUM(J15*140) -> 0 | T15: =SUM(L15:S15) -> 3780
A16: 12 | B16: 46154 | F16: =F15-E16+D16 -> 1.5674 | G16: =IF(OR(B16="",NOT(ISERROR(SEARCH("KPI",$A$2))),NOT(ISERROR(SEARCH("Полиом",$A$2)))),0,IF(70-F16<=0,0,70-F16)) -> 68.4326 | L16: =SUM(K16*240) -> 0 | M16: =SUM(D16*120) -> 0 | N16: =SUM(E16*120) -> 0 | O16: =SUM(F16*54) -> 84.6396 | P16: =SUM(G16*54) -> 3695.3604 | Q16: =SUM(H16*120) -> 0 | R16: =SUM(I16*1000) -> 0 | S16: =SUM(J16*140) -> 0 | T16: =SUM(L16:S16) -> 3780
A17: 13 | B17: 46155 | F17: =F16-E17+D17 -> 1.5674 | G17: =IF(OR(B17="",NOT(ISERROR(SEARCH("KPI",$A$2))),NOT(ISERROR(SEARCH("Полиом",$A$2)))),0,IF(70-F17<=0,0,70-F17)) -> 68.4326 | L17: =SUM(K17*240) -> 0 | M17: =SUM(D17*120) -> 0 | N17: =SUM(E17*120) -> 0 | O17: =SUM(F17*54) -> 84.6396 | P17: =SUM(G17*54) -> 3695.3604 | Q17: =SUM(H17*120) -> 0 | R17: =SUM(I17*1000) -> 0 | S17: =SUM(J17*140) -> 0 | T17: =SUM(L17:S17) -> 3780
A18: 14 | B18: 46156 | E18: 1.5674 | F18: =F17-E18+D18 -> 0 | G18: =IF(OR(B18="",NOT(ISERROR(SEARCH("KPI",$A$2))),NOT(ISERROR(SEARCH("Полиом",$A$2)))),0,IF(70-F18<=0,0,70-F18)) -> 70 | L18: =SUM(K18*240) -> 0 | M18: =SUM(D18*120) -> 0 | N18: =SUM(E18*120) -> 188.088 | O18: =SUM(F18*54) -> 0 | P18: =SUM(G18*54) -> 3780 | Q18: =SUM(H18*120) -> 0 | R18: =SUM(I18*1000) -> 0 | S18: =SUM(J18*140) -> 0 | T18: =SUM(L18:S18) -> 3968.088
A19: 15 | B19: 46157 | F19: =F18-E19+D19 -> 0 | G19: =IF(OR(B19="",NOT(ISERROR(SEARCH("KPI",$A$2))),NOT(ISERROR(SEARCH("Полиом",$A$2)))),0,IF(70-F19<=0,0,70-F19)) -> 70 | L19: =SUM(K19*240) -> 0 | M19: =SUM(D19*120) -> 0 | N19: =SUM(E19*120) -> 0 | O19: =SUM(F19*54) -> 0 | P19: =SUM(G19*54) -> 3780 | Q19: =SUM(H19*120) -> 0 | R19: =SUM(I19*1000) -> 0 | S19: =SUM(J19*140) -> 0 | T19: =SUM(L19:S19) -> 3780
A20: 16 | B20: 46158 | F20: =F19-E20+D20 -> 0 | G20: =IF(OR(B20="",NOT(ISERROR(SEARCH("KPI",$A$2))),NOT(ISERROR(SEARCH("Полиом",$A$2)))),0,IF(70-F20<=0,0,70-F20)) -> 70 | L20: =SUM(K20*240) -> 0 | M20: =SUM(D20*120) -> 0 | N20: =SUM(E20*120) -> 0 | O20: =SUM(F20*54) -> 0 | P20: =SUM(G20*54) -> 3780 | Q20: =SUM(H20*120) -> 0 | R20: =SUM(I20*1000) -> 0 | S20: =SUM(J20*140) -> 0 | T20: =SUM(L20:S20) -> 3780
A21: 17 | B21: 46159 | F21: =F20-E21+D21 -> 0 | G21: =IF(OR(B21="",NOT(ISERROR(SEARCH("KPI",$A$2))),NOT(ISERROR(SEARCH("Полиом",$A$2)))),0,IF(70-F21<=0,0,70-F21)) -> 70 | L21: =SUM(K21*240) -> 0 | M21: =SUM(D21*120) -> 0 | N21: =SUM(E21*120) -> 0 | O21: =SUM(F21*54) -> 0 | P21: =SUM(G21*54) -> 3780 | Q21: =SUM(H21*120) -> 0 | R21: =SUM(I21*1000) -> 0 | S21: =SUM(J21*140) -> 0 | T21: =SUM(L21:S21) -> 3780
A22: 18 | B22: 46160 | F22: =F21-E22+D22 -> 0 | G22: =IF(OR(B22="",NOT(ISERROR(SEARCH("KPI",$A$2))),NOT(ISERROR(SEARCH("Полиом",$A$2)))),0,IF(70-F22<=0,0,70-F22)) -> 70 | L22: =SUM(K22*240) -> 0 | M22: =SUM(D22*120) -> 0 | N22: =SUM(E22*120) -> 0 | O22: =SUM(F22*54) -> 0 | P22: =SUM(G22*54) -> 3780 | Q22: =SUM(H22*120) -> 0 | R22: =SUM(I22*1000) -> 0 | S22: =SUM(J22*140) -> 0 | T22: =SUM(L22:S22) -> 3780
A23: 19 | B23: 46161 | F23: =F22-E23+D23 -> 0 | G23: =IF(OR(B23="",NOT(ISERROR(SEARCH("KPI",$A$2))),NOT(ISERROR(SEARCH("Полиом",$A$2)))),0,IF(70-F23<=0,0,70-F23)) -> 70 | L23: =SUM(K23*240) -> 0 | M23: =SUM(D23*120) -> 0 | N23: =SUM(E23*120) -> 0 | O23: =SUM(F23*54) -> 0 | P23: =SUM(G23*54) -> 3780 | Q23: =SUM(H23*120) -> 0 | R23: =SUM(I23*1000) -> 0 | S23: =SUM(J23*140) -> 0 | T23: =SUM(L23:S23) -> 3780
A24: 20 | B24: 46162 | F24: =F23-E24+D24 -> 0 | G24: =IF(OR(B24="",NOT(ISERROR(SEARCH("KPI",$A$2))),NOT(ISERROR(SEARCH("Полиом",$A$2)))),0,IF(70-F24<=0,0,70-F24)) -> 70 | L24: =SUM(K24*240) -> 0 | M24: =SUM(D24*120) -> 0 | N24: =SUM(E24*120) -> 0 | O24: =SUM(F24*54) -> 0 | P24: =SUM(G24*54) -> 3780 | Q24: =SUM(H24*120) -> 0 | R24: =SUM(I24*1000) -> 0 | S24: =SUM(J24*140) -> 0 | T24: =SUM(L24:S24) -> 3780
A25: 21 | B25: 46163 | F25: =F24-E25+D25 -> 0 | G25: =IF(OR(B25="",NOT(ISERROR(SEARCH("KPI",$A$2))),NOT(ISERROR(SEARCH("Полиом",$A$2)))),0,IF(70-F25<=0,0,70-F25)) -> 70 | L25: =SUM(K25*240) -> 0 | M25: =SUM(D25*120) -> 0 | N25: =SUM(E25*120) -> 0 | O25: =SUM(F25*54) -> 0 | P25: =SUM(G25*54) -> 3780 | Q25: =SUM(H25*120) -> 0 | R25: =SUM(I25*1000) -> 0 | S25: =SUM(J25*140) -> 0 | T25: =SUM(L25:S25) -> 3780
A26: 22 | B26: 46164 | F26: =F25-E26+D26 -> 0 | G26: =IF(OR(B26="",NOT(ISERROR(SEARCH("KPI",$A$2))),NOT(ISERROR(SEARCH("Полиом",$A$2)))),0,IF(70-F26<=0,0,70-F26)) -> 70 | L26: =SUM(K26*240) -> 0 | M26: =SUM(D26*120) -> 0 | N26: =SUM(E26*120) -> 0 | O26: =SUM(F26*54) -> 0 | P26: =SUM(G26*54) -> 3780 | Q26: =SUM(H26*120) -> 0 | R26: =SUM(I26*1000) -> 0 | S26: =SUM(J26*140) -> 0 | T26: =SUM(L26:S26) -> 3780
A27: 23 | B27: 46165 | F27: =F26-E27+D27 -> 0 | G27: =IF(OR(B27="",NOT(ISERROR(SEARCH("KPI",$A$2))),NOT(ISERROR(SEARCH("Полиом",$A$2)))),0,IF(70-F27<=0,0,70-F27)) -> 70 | L27: =SUM(K27*240) -> 0 | M27: =SUM(D27*120) -> 0 | N27: =SUM(E27*120) -> 0 | O27: =SUM(F27*54) -> 0 | P27: =SUM(G27*54) -> 3780 | Q27: =SUM(H27*120) -> 0 | R27: =SUM(I27*1000) -> 0 | S27: =SUM(J27*140) -> 0 | T27: =SUM(L27:S27) -> 3780
A28: 24 | B28: 46166 | F28: =F27-E28+D28 -> 0 | G28: =IF(OR(B28="",NOT(ISERROR(SEARCH("KPI",$A$2))),NOT(ISERROR(SEARCH("Полиом",$A$2)))),0,IF(70-F28<=0,0,70-F28)) -> 70 | L28: =SUM(K28*240) -> 0 | M28: =SUM(D28*120) -> 0 | N28: =SUM(E28*120) -> 0 | O28: =SUM(F28*54) -> 0 | P28: =SUM(G28*54) -> 3780 | Q28: =SUM(H28*120) -> 0 | R28: =SUM(I28*1000) -> 0 | S28: =SUM(J28*140) -> 0 | T28: =SUM(L28:S28) -> 3780
A29: 25 | B29: 46167 | F29: =F28-E29+D29 -> 0 | G29: =IF(OR(B29="",NOT(ISERROR(SEARCH("KPI",$A$2))),NOT(ISERROR(SEARCH("Полиом",$A$2)))),0,IF(70-F29<=0,0,70-F29)) -> 70 | L29: =SUM(K29*240) -> 0 | M29: =SUM(D29*120) -> 0 | N29: =SUM(E29*120) -> 0 | O29: =SUM(F29*54) -> 0 | P29: =SUM(G29*54) -> 3780 | Q29: =SUM(H29*120) -> 0 | R29: =SUM(I29*1000) -> 0 | S29: =SUM(J29*140) -> 0 | T29: =SUM(L29:S29) -> 3780
A30: 26 | B30: 46168 | F30: =F29-E30+D30 -> 0 | G30: =IF(OR(B30="",NOT(ISERROR(SEARCH("KPI",$A$2))),NOT(ISERROR(SEARCH("Полиом",$A$2)))),0,IF(70-F30<=0,0,70-F30)) -> 70 | L30: =SUM(K30*240) -> 0 | M30: =SUM(D30*120) -> 0 | N30: =SUM(E30*120) -> 0 | O30: =SUM(F30*54) -> 0 | P30: =SUM(G30*54) -> 3780 | Q30: =SUM(H30*120) -> 0 | R30: =SUM(I30*1000) -> 0 | S30: =SUM(J30*140) -> 0 | T30: =SUM(L30:S30) -> 3780
... A34: 30 | B34: 46172 | F34: =F33-E34+D34 -> 0 | G34: =IF(OR(B34="",NOT(ISERROR(SEARCH("KPI",$A$2))),NOT(ISERROR(SEARCH("Полиом",$A$2)))),0,IF(70-F34<=0,0,70-F34)) -> 70 | L34: =SUM(K34*240) -> 0 | M34: =SUM(D34*120) -> 0 | N34: =SUM(E34*120) -> 0 | O34: =SUM(F34*54) -> 0 | P34: =SUM(G34*54) -> 3780 | Q34: =SUM(H34*120) -> 0 | R34: =SUM(I34*1000) -> 0 | S34: =SUM(J34*140) -> 0 | T34: =SUM(L34:S34) -> 3780
B35: 46173 | F35: =F34-E35+D35 -> 0 | G35: =IF(OR(B35="",NOT(ISERROR(SEARCH("KPI",$A$2))),NOT(ISERROR(SEARCH("Полиом",$A$2)))),0,IF(70-F35<=0,0,70-F35)) -> 70 | L35: =SUM(K35*240) -> 0 | M35: =SUM(D35*120) -> 0 | N35: =SUM(E35*120) -> 0 | O35: =SUM(F35*54) -> 0 | P35: =SUM(G35*54) -> 3780 | Q35: =SUM(H35*120) -> 0 | R35: =SUM(I35*1000) -> 0 | S35: =SUM(J35*140) -> 0 | T35: =SUM(L35:S35) -> 3780
F36: =SUM(F5:F35) -> 20.3762 | G36: =SUM(G5:G35) -> 2149.6238 | H36: =SUM(H5:H35) -> 0 | I36: =SUM(I5:I35) -> 0 | J36: =SUM(J5:J35) -> 0 | K36: =SUM(K5:K35) -> 0 | L36: =SUM(L5:L35) -> 0 | M36: =SUM(M5:M35) -> 0 | ... T36: =SUM(T5:T35) -> 117368.09
T37: =T36*1.22 -> 143189.07

Sheet ИТОГО
A1: =G16 -> 1.2924404e+08
I2: ТОП
A3: Склад | B3: Сибур | C3: Завод | D3: Русвинил | E3: Клиенты сибура | F3: Остальные | G3: Итого | I3: Казань_Автосервисная | J3: 23143268
A4: Баумана | B4: =INDEX($M$45:$M$54,MATCH(A4,$A$45:$A$54,0),1) -> 8383542 | C4: 0 | D4: =INDEX($B$57:$B$73,MATCH(A4,$A$57:$A$73,0),1) -> 0 | E4: =SUMIF($F$19:$F$42,A4,$G$19:$G$42) -> 0 | F4: =SUMIF($B$19:$B$27,A4,$C$19:$C$27) -> 88704 | G4: =SUM(B4:F4) -> 8472246 | I4: Нижнекамск завод | J4: 19482962
A5: Новикова-Прибоя | B5: =INDEX($M$45:$M$54,MATCH(A5,$A$45:$A$54,0),1) -> 10573996 | C5: 0 | D5: =INDEX($B$57:$B$73,MATCH(A5,$A$57:$A$73,0),1) -> 0 | E5: =SUMIF($F$19:$F$42,A5,$G$19:$G$42) -> 0 | F5: =SUMIF($B$19:$B$27,A5,$C$19:$C$27) -> 0 | G5: =SUM(B5:F5) -> 10573996 | I5: Новикова-Прибоя | J5: 14483152
A6: Екатеринбург | B6: =INDEX($M$45:$M$54,MATCH(A6,$A$45:$A$54,0),1) -> 12268825 | C6: 0 | D6: =INDEX($B$57:$B$73,MATCH(A6,$A$57:$A$73,0),1) -> 0 | E6: =SUMIF($F$19:$F$42,A6,$G$19:$G$42) -> 0 | F6: =SUMIF($B$19:$B$27,A6,$C$19:$C$27) -> 0 | G6: =SUM(B6:F6) -> 12268825 | I6: Екатеринбург | J6: 11908609
A7: Новосибирск | B7: =INDEX($M$45:$M$54,MATCH(A7,$A$45:$A$54,0),1) -> 6118133.7 | C7: 0 | D7: =INDEX($B$57:$B$73,MATCH(A7,$A$57:$A$73,0),1) -> 0 | E7: =SUMIF($F$19:$F$42,A7,$G$19:$G$42) -> 143189.07 | F7: =SUMIF($B$19:$B$27,A7,$C$19:$C$27) -> 0 | G7: =SUM(B7:F7) -> 6261322.7 | I7: Баумана | J7: 11544503
A8: Новосибирск_Пасечная | B8: =INDEX($M$45:$M$54,MATCH(A8,$A$45:$A$54,0),1) -> 5137648.6 | C8: 0 | D8: =INDEX($B$57:$B$73,MATCH(A8,$A$57:$A$73,0),1) -> 0 | E8: =SUMIF($F$19:$F$42,A8,$G$19:$G$42) -> 0 | F8: =SUMIF($B$19:$B$27,A8,$C$19:$C$27) -> 0 | G8: =SUM(B8:F8) -> 5137648.6
A9: Казань_Автосервисная | B9: =INDEX($M$45:$M$54,MATCH(A9,$A$45:$A$54,0),1) -> 18487985 | C9: 0 | D9: =INDEX($B$57:$B$73,MATCH(A9,$A$57:$A$73,0),1) -> 0 | E9: =SUMIF($F$19:$F$42,A9,$G$19:$G$42) -> 0 | F9: =SUMIF($B$19:$B$27,A9,$C$19:$C$27) -> 0 | G9: =SUM(B9:F9) -> 18487985 | I9: Казань_Приволжская | J9: 9900926.9
A10: Казань_Приволжская | B10: =INDEX($M$45:$M$54,MATCH(A10,$A$45:$A$54,0),1) -> 9559792.9 | C10: 0 | D10: =INDEX($B$57:$B$73,MATCH(A10,$A$57:$A$73,0),1) -> 0 | E10: =SUMIF($F$19:$F$42,A10,$G$19:$G$42) -> 0 | F10: =SUMIF($B$19:$B$27,A10,$C$19:$C$27) -> 0 | G10: =SUM(B10:F10) -> 9559792.9 | I10: Зеленодольск | J10: 9082789.1
A11: Зеленодольск | B11: =INDEX($M$45:$M$54,MATCH(A11,$A$45:$A$54,0),1) -> 8659496.7 | C11: 0 | D11: =INDEX($B$57:$B$73,MATCH(A11,$A$57:$A$73,0),1) -> 0 | E11: =SUMIF($F$19:$F$42,A11,$G$19:$G$42) -> 0 | F11: =SUMIF($B$19:$B$27,A11,$C$19:$C$27) -> 0 | G11: =SUM(B11:F11) -> 8659496.7 | I11: Новосибирск | J11: 7932975.6
A12: Нижнекамск | B12: =INDEX($M$45:$M$54,MATCH(A12,$A$45:$A$54,0),1) -> 0 | C12: 0 | D12: =INDEX($B$57:$B$73,MATCH(A12,$A$57:$A$73,0),1) -> 0 | E12: =SUMIF($F$19:$F$42,A12,$G$19:$G$42) -> 0 | F12: =SUMIF($B$19:$B$27,A12,$C$19:$C$27) -> 0 | G12: =SUM(B12:F12) -> 0 | I12: Нижнекамск | J12: 7580244.6
A13: Нижнекамск завод | B13: 0 | C13: =C29+C37 -> 49822732 | D13: =INDEX($B$57:$B$73,MATCH(A13,$A$57:$A$73,0),1) -> 0 | E13: =SUMIF($F$19:$F$42,A13,$G$19:$G$42) -> 0 | F13: =SUMIF($B$19:$B$27,A13,$C$19:$C$27) -> 0 | G13: =SUM(B13:F13) -> 49822732 | I13: ГАЗ | J13: 6720000
A14: Монастырка | B14: 0 | C14: 0 | D14: =INDEX($B$57:$B$73,MATCH(A14,$A$57:$A$73,0),1) -> 0 | E14: =SUMIF($F$19:$F$42,A14,$G$19:$G$42) -> 0 | F14: =SUMIF($B$19:$B$27,A14,$C$19:$C$27) -> 0 | G14: =SUM(B14:F14) -> 0 | I14: Монастырка | J14: 2464921.6
A15: Березовая Пойма | B15: =INDEX($M$45:$M$54,MATCH(A15,$A$45:$A$54,0),1) -> 0 | C15: 0 | D15: =INDEX($B$57:$B$73,MATCH(A15,$A$57:$A$73,0),1) -> 0 | E15: =SUMIF($F$19:$F$42,A15,$G$19:$G$42) -> 0 | F15: =SUMIF($B$19:$B$27,A15,$C$19:$C$27) -> 0 | G15: =SUM(B15:F15) -> 0
B16: =SUM(B4:B15) -> 79189419 | C16: =SUM(C4:C15) -> 49822732 | D16: =SUM(D4:D15) -> 0 | E16: =SUM(E4:E15) -> 143189.07 | F16: =SUM(F4:F15) -> 88704 | G16: =SUM(G4:G15) -> 1.2924404e+08
A18: Остальные клиенты | C18: =SUM(C19:C27) -> 88704 | E18: Клиенты сибура | G18: =SUM(G19:G41) -> 143189.07
A19: Стройтех | B19: Баумана | C19: {=IFERROR(INDIRECT("'" & A19 & "'!A1"),)} -> 26403 | E19: Приоритет | F19: Баумана | G19: {=IFERROR(INDIRECT("'" & E19 & " " & F19 & "'!A1"),0)} -> 0
A20: Ергарда | B20: Баумана | C20: {=IFERROR(INDIRECT("'" & A20 & "'!A1"),)} -> 8928 | E20: Фармпласт | F20: Баумана | G20: {=IFERROR(INDIRECT("'" & E20 & " " & F20 & "'!A1"),0)} -> 0
A21: Литейные решения | B21: Баумана | C21: {=IFERROR(INDIRECT("'" & A21 & "'!A1"),)} -> 27921 | E21: Юг Полимер | F21: Баумана | G21: {=IFERROR(INDIRECT("'" & E21 & " " & F21 & "'!A1"),0)} -> 0
A22: Сандекс | B22: Баумана | C22: {=IFERROR(INDIRECT("'" & A22 & "'!A1"),)} -> 20640 | E22: Центрополимер | F22: Екатеринбург | G22: {=IFERROR(INDIRECT("'" & E22 & " " & F22 & "'!A1"),0)} -> 0
A23: ЛС-Техномет | B23: Баумана | C23: {=IFERROR(INDIRECT("'" & A23 & "'!A1"),)} -> 4812 | E23: Приоритет | F23: Екатеринбург | G23: {=IFERROR(INDIRECT("'" & E23 & " " & F23 & "'!A1"),0)} -> 0
A24: РусДжам | B24: ГАЗ | C24: {=IFERROR(INDIRECT("'" & A24 & "'!A1"),)} -> 0 | E24: Фармпласт | F24: Екатеринбург | G24: {=IFERROR(INDIRECT("'" & E24 & " " & F24 & "'!A1"),0)} -> 0
A25: Виго | B25: Новикова-Прибоя | C25: {=IFERROR(INDIRECT("'" & A25 & "'!A1"),)} -> 0 | E25: Приоритет | F25: Зеленодольск | G25: {=IFERROR(INDIRECT("'" & E25 & " " & F25 & "'!A1"),0)} -> 0
A26: Доктор Франк | B26: Новикова-Прибоя | C26: {=IFERROR(INDIRECT("'" & A26 & "'!A1"),)} -> 0 | E26: Данафлекс | F26: Зеленодольск | G26: {=IFERROR(INDIRECT("'" & E26 & " " & F26 & "'!t37"),0)} -> 0
A27: Нефтезол | B27: Новикова-Прибоя | C27: {=IFERROR(INDIRECT("'" & A27 & "'!A1"),)} -> 0 | E27: ИП Ксендз | F27: Нижнекамск | G27: {=IFERROR(INDIRECT("'" & E27 & " " & F27 & "'!A1"),0)} -> 0
E28: Фармпласт | F28: Новикова-Прибоя | G28: {=IFERROR(INDIRECT("'" & E28 & " " & F28 & "'!A1"),0)} -> 0
A29: Нижнекамск завод | C29: =SUM(C30:C35) -> 39955133 | E29: Центрополимер | F29: Новикова-Прибоя | G29: {=IFERROR(INDIRECT("'" & E29 & " " & F29 & "'!A1"),0)} -> 0
A30: ПРР | C30: {=INDIRECT("'" & A29 & "'!F17")+80377} -> 16247867 | E30: Юг Полимер | F30: Новикова-Прибоя | G30: {=IFERROR(INDIRECT("'" & E30 & " " & F30 & "'!A1"),0)} -> 0
A31: Кладовки | C31: {=INDIRECT("'" & A29 & "'!F16")} -> 0 | E31: Приоритет | F31: Новикова-Прибоя | G31: {=IFERROR(INDIRECT("'" & E31 & " " & F31 & "'!A1"),0)} -> 0
A32: Стропальщики | C32: {=INDIRECT("'" & A29 & "'!F18")} -> 799100 | E32: Биаксплен | F32: Новосибирск | G32: {=IFERROR(INDIRECT("'" & E32 & " " & F32 & "'!A1"),0)} -> 143189.07
A33: Мойка контейнеров | C33: {=INDIRECT("'" & A29 & "'!F19")} -> 1217379 | E33: Центрополимер | F33: Новосибирск | G33: {=IFERROR(INDIRECT("'" & E33 & " " & F33 & "'!A1"),0)} -> 0
A34: МТО | C34: {=INDIRECT("'" & A29 & "'!F20")} -> 17003203 | E34: Фармпласт | F34: Новосибирск | G34: {=IFERROR(INDIRECT("'" & E34 & " " & F34 & "'!A1"),0)} -> 0
A35: МТО 2520 | C35: {=INDIRECT("'" & A29 & "'!F21")} -> 4687584
E36: Юг Полимер | F36: Зеленодольск | G36: {=IFERROR(INDIRECT("'" & E36 & " " & F36 & "'!A1"),0)} -> 0
A37: Контейнерные площадки | C37: =SUM(C38:C42) -> 9867599 | E37: Фармпласт | F37: Казань_Автосервисная | G37: {=IFERROR(INDIRECT("'" & E37 & " " & F37 & "'!A1"),0)} -> 0
A38: КОС | C38: 2803379 | E38: Приоритет | F38: Казань_Приволжская | G38: {=IFERROR(INDIRECT("'" & E38 & " " & F38 & "'!A1"),0)} -> 0
A39: Нижнекамск | C39: 7064220 | E39: Центрополимер | F39: Баумана | G39: {=IFERROR(INDIRECT("'" & E39 & " " & F39 & "'!A1"),0)} -> 0
E40: Приоритет | F40: Казань_Автосервисная | G40: {=IFERROR(INDIRECT("'" & E40 & " " & F40 & "'!A1"),0)} -> 0
E41: Оникс | F41: Нижнекамск | G41: {=IFERROR(INDIRECT("'" & E41 & " " & F41 & "'!A1"),0)} -> 0
...

Sheet Другое

Sheet Нижнекамск завод
A9: № | B9: Наименование услуг (работ) | C9: Ед. изм. | D9: Количество | E9: Цена | F9: Сумма
A14: Итого: | F14: =SUM(F10:F13) -> 0
A15: Без налога (НДС) | F15: =SUM(F14) -> 0
A16: Всего (с учетом НДС) | F16: =SUM(F15)*1.2 -> 0
A17: Вышеперечисленные услуги (работы) выполнены полностью. | E17: ПРР | F17: 16167490
A18: ПОКЛАЖЕДАТЕЛЬ претензий по объему, качеству и срокам оказания услуг претензий не имеет. | E18: Стропальщики | F18: 799100
E19: Контейнеры | F19: 1217379
E20: МТО | F20: =17003203 -> 17003203
E21: МТО 2520 | F21: 4687584
A22: ООО "ДТМ" | D22: ПАО "Нижнекамскнефтехим"
A24: ____________________Молькова Т.Ю. | B24: Расстегаев Д.О. | D24: ____________________

Sheet Сводка
A1: KPI | B1: Баумана | C1: =INDEX(INDIRECT("ИТОГО!$B$45:$L$54"),MATCH(Сводка!B1,INDIRECT("ИТОГО!$A$45:$A$54"),0),MATCH(Сводка!A1,INDIRECT("ИТОГО!$B$44:$L$44"),0)) -> 3096.29
A2: Полиом | B2: Баумана | C2: =INDEX(INDIRECT("ИТОГО!$B$45:$L$54"),MATCH(Сводка!B2,INDIRECT("ИТОГО!$A$45:$A$54"),0),MATCH(Сводка!A2,INDIRECT("ИТОГО!$B$44:$L$44"),0)) -> 537086.71
A3: Полимеры | B3: Баумана | C3: =INDEX(INDIRECT("ИТОГО!$B$45:$L$54"),MATCH(Сводка!B3,INDIRECT("ИТОГО!$A$45:$A$54"),0),MATCH(Сводка!A3,INDIRECT("ИТОГО!$B$44:$L$44"),0)) -> 7843359
A4: Каучук | B4: Баумана | C4: =INDEX(INDIRECT("ИТОГО!$B$45:$L$54"),MATCH(Сводка!B4,INDIRECT("ИТОГО!$A$45:$A$54"),0),MATCH(Сводка!A4,INDIRECT("ИТОГО!$B$44:$L$44"),0)) -> 0
A5: ПСОН | B5: Баумана | C5: =INDEX(INDIRECT("ИТОГО!$B$45:$L$54"),MATCH(Сводка!B5,INDIRECT("ИТОГО!$A$45:$A$54"),0),MATCH(Сводка!A5,INDIRECT("ИТОГО!$B$44:$L$44"),0)) -> 0
A6: Данафлекс | B6: Баумана | C6: =INDEX(INDIRECT("ИТОГО!$B$45:$L$54"),MATCH(Сводка!B6,INDIRECT("ИТОГО!$A$45:$A$54"),0),MATCH(Сводка!A6,INDIRECT("ИТОГО!$B$44:$L$44"),0)) -> 0
A7: СБС | B7: Баумана | C7: =INDEX(INDIRECT("ИТОГО!$B$45:$L$54"),MATCH(Сводка!B7,INDIRECT("ИТОГО!$A$45:$A$54"),0),MATCH(Сводка!A7,INDIRECT("ИТОГО!$B$44:$L$44"),0)) -> 0
A8: Порошок | B8: Баумана | C8: =INDEX(INDIRECT("ИТОГО!$B$45:$L$54"),MATCH(Сводка!B8,INDIRECT("ИТОГО!$A$45:$A$54"),0),MATCH(Сводка!A8,INDIRECT("ИТОГО!$B$44:$L$44"),0)) -> 0
A9: НПЭГ | B9: Баумана | C9: =INDEX(INDIRECT("ИТОГО!$B$45:$L$54"),MATCH(Сводка!B9,INDIRECT("ИТОГО!$A$45:$A$54"),0),MATCH(Сводка!A9,INDIRECT("ИТОГО!$B$44:$L$44"),0)) -> 0
A10: Экспорт | B10: Баумана | C10: =INDEX(INDIRECT("ИТОГО!$B$45:$L$54"),MATCH(Сводка!B10,INDIRECT("ИТОГО!$A$45:$A$54"),0),MATCH(Сводка!A10,INDIRECT("ИТОГО!$B$44:$L$44"),0)) -> 0
A11: Доп услуги | B11: Баумана | C11: =INDEX(INDIRECT("ИТОГО!$B$45:$L$54"),MATCH(Сводка!B11,INDIRECT("ИТОГО!$A$45:$A$54"),0),MATCH(Сводка!A11,INDIRECT("ИТОГО!$B$44:$L$44"),0)) -> 0
A12: KPI | B12: Новикова-Прибоя | C12: =INDEX(INDIRECT("ИТОГО!$B$45:$L$54"),MATCH(Сводка!B12,INDIRECT("ИТОГО!$A$45:$A$54"),0),MATCH(Сводка!A12,INDIRECT("ИТОГО!$B$44:$L$44"),0)) -> 21861.83
... A99: Доп услуги | B99: Казань_Приволжская | C99: =INDEX(INDIRECT("ИТОГО!$B$45:$L$54"),MATCH(Сводка!B99,INDIRECT("ИТОГО!$A$45:$A$54"),0),MATCH(Сводка!A99,INDIRECT("ИТОГО!$B$44:$L$44"),0)) -> 0
A100: Русвинил | B100: Баумана | C100: {=INDIRECT("ИТОГО!B57")} -> 0
A101: Русвинил | B101: Новикова-Прибоя | C101: {=INDIRECT("ИТОГО!B58")} -> 0
A102: Русвинил | B102: Березовая Пойма | C102: {=INDIRECT("ИТОГО!B67")} -> 0
A103: ПРР | B103: Нижнекамск завод | C103: {=INDIRECT("ИТОГО!C30")} -> 16247867
A104: Кладовки | B104: Нижнекамск завод | C104: {=INDIRECT("ИТОГО!C31")} -> 0
A105: Стропальщики | B105: Нижнекамск завод | C105: {=INDIRECT("ИТОГО!C32")} -> 799100
A106: Мойка контейнеров | B106: Нижнекамск завод | C106: {=INDIRECT("ИТОГО!C33")} -> 1217379
A107: МТО | B107: Нижнекамск завод | C107: {=INDIRECT("ИТОГО!C34")} -> 17003203
A108: МТО 2520 | B108: Нижнекамск завод | C108: {=INDIRECT("ИТОГО!C35")} -> 4687584
A109: КП КОС | B109: Нижнекамск завод | C109: {=INDIRECT("ИТОГО!C38")} -> 2803379
A110: КП Нижнекамск | B110: Нижнекамск завод | C110: {=INDIRECT("ИТОГО!C39")} -> 7064220
A111: Стройтех | B111: Баумана | C111: {=INDIRECT("ИТОГО!C19")} -> 26403
A112: Ергарда | B112: Баумана | C112: {=INDIRECT("ИТОГО!C20")} -> 8928
A113: Литейные решения | B113: Баумана | C113: {=INDIRECT("ИТОГО!C21")} -> 27921
A114: Сандекс | B114: Баумана | C114: {=INDIRECT("ИТОГО!C22")} -> 20640
A115: ЛС-Техномет | B115: Баумана | C115: {=INDIRECT("ИТОГО!C23")} -> 4812
A116: Приоритет | B116: Баумана | C116: {=INDIRECT("ИТОГО!G19")} -> 0
A117: Фармпласт | B117: Баумана | C117: {=INDIRECT("ИТОГО!G20")} -> 0
A118: Юг Полимер | B118: Баумана | C118: {=INDIRECT("ИТОГО!G21")} -> 0
A119: Центрополимер | B119: Екатеринбург | C119: {=INDIRECT("ИТОГО!G22")} -> 0
A120: Приоритет | B120: Екатеринбург | C120: {=INDIRECT("ИТОГО!G23")} -> 0
A121: Фармпласт | B121: Екатеринбург | C121: {=INDIRECT("ИТОГО!G24")} -> 0
A122: Приоритет | B122: Зеленодольск | C122: {=INDIRECT("ИТОГО!G25")} -> 0
A123: Данафлекс | B123: Зеленодольск | C123: {=INDIRECT("ИТОГО!G26")} -> 0
A124: ИП Ксендз | B124: Нижнекамск | C124: {=INDIRECT("ИТОГО!G27")} -> 0
A125: Фармпласт | B125: Новикова-Прибоя | C125: {=INDIRECT("ИТОГО!G28")} -> 0
A126: Центрополимер | B126: Новикова-Прибоя | C126: {=INDIRECT("ИТОГО!G29")} -> 0
...

Sheet Литейные решения
A1: =R36 -> 27921
B2: Отчет по хранению товара за Май
A3: № | B3: дата | D3: Выгрузка кол-во паллет | E3: Загрузка кол-во паллет | F3: Ручная загрузка | G3: Ручная выгрузка | H3: Хранение | I3: предоставление паллеты | J3: Фильмаж (паллет) | K3: стоимость выгрузки | L3: стоимость загрузки | M3: Стоимость ручной загрузки | N3: Стоимость ручной выгрузки | O3: стоимость хранения | P3: Стоимость предоставления паллета | Q3: стоимость услуги фильмаж | R3: итого
H4: (кол-во паллет)
A5: 1 | B5: 46143 | H5: 27 | K5: =SUM(D5*171) -> 0 | L5: =SUM(E5*171) -> 0 | M5: =F5*1018 -> 0 | N5: =G5*1018 -> 0 | O5: =SUM(H5*22) -> 594 | P5: =I5*509 -> 0 | Q5: =SUM(J5)*610 -> 0 | R5: =SUM(K5:Q5) -> 594
A6: 2 | B6: 46144 | H6: =H5+D6-E5 -> 27 | K6: =SUM(D6*171) -> 0 | L6: =SUM(E6*171) -> 0 | M6: =F6*1018 -> 0 | N6: =G6*1018 -> 0 | O6: =SUM(H6*22) -> 594 | P6: =I6*509 -> 0 | Q6: =SUM(J6)*610 -> 0 | R6: =SUM(K6:Q6) -> 594
A7: 3 | B7: 46145 | H7: =H6+D7-E6 -> 27 | K7: =SUM(D7*171) -> 0 | L7: =SUM(E7*171) -> 0 | M7: =F7*1018 -> 0 | N7: =G7*1018 -> 0 | O7: =SUM(H7*22) -> 594 | P7: =I7*509 -> 0 | Q7: =SUM(J7)*610 -> 0 | R7: =SUM(K7:Q7) -> 594
A8: 4 | B8: 46146 | H8: =H7+D8-E7 -> 27 | K8: =SUM(D8*171) -> 0 | L8: =SUM(E8*171) -> 0 | M8: =F8*1018 -> 0 | N8: =G8*1018 -> 0 | O8: =SUM(H8*22) -> 594 | P8: =I8*509 -> 0 | Q8: =SUM(J8)*610 -> 0 | R8: =SUM(K8:Q8) -> 594
A9: 5 | B9: 46147 | H9: =H8+D9-E8 -> 27 | K9: =SUM(D9*171) -> 0 | L9: =SUM(E9*171) -> 0 | M9: =F9*1018 -> 0 | N9: =G9*1018 -> 0 | O9: =SUM(H9*22) -> 594 | P9: =I9*509 -> 0 | Q9: =SUM(J9)*610 -> 0 | R9: =SUM(K9:Q9) -> 594
A10: 6 | B10: 46148 | D10: 1 | E10: 2 | H10: =H9+D10-E9 -> 28 | K10: =SUM(D10*171) -> 171 | L10: =SUM(E10*171) -> 342 | M10: =F10*1018 -> 0 | N10: =G10*1018 -> 0 | O10: =SUM(H10*22) -> 616 | P10: =I10*509 -> 0 | Q10: =SUM(J10)*610 -> 0 | R10: =SUM(K10:Q10) -> 1129
A11: 7 | B11: 46149 | H11: =H10+D11-E10 -> 26 | K11: =SUM(D11*171) -> 0 | L11: =SUM(E11*171) -> 0 | M11: =F11*1018 -> 0 | N11: =G11*1018 -> 0 | O11: =SUM(H11*22) -> 572 | P11: =I11*509 -> 0 | Q11: =SUM(J11)*610 -> 0 | R11: =SUM(K11:Q11) -> 572
A12: 8 | B12: 46150 | H12: =H11+D12-E11 -> 26 | K12: =SUM(D12*171) -> 0 | L12: =SUM(E12*171) -> 0 | M12: =F12*1018 -> 0 | N12: =G12*1018 -> 0 | O12: =SUM(H12*22) -> 572 | P12: =I12*509 -> 0 | Q12: =SUM(J12)*610 -> 0 | R12: =SUM(K12:Q12) -> 572
A13: 9 | B13: 46151 | H13: =H12+D13-E12 -> 26 | K13: =SUM(D13*171) -> 0 | L13: =SUM(E13*171) -> 0 | M13: =F13*1018 -> 0 | N13: =G13*1018 -> 0 | O13: =SUM(H13*22) -> 572 | P13: =I13*509 -> 0 | Q13: =SUM(J13)*610 -> 0 | R13: =SUM(K13:Q13) -> 572
A14: 10 | B14: 46152 | H14: =H13+D14-E13 -> 26 | K14: =SUM(D14*171) -> 0 | L14: =SUM(E14*171) -> 0 | M14: =F14*1018 -> 0 | N14: =G14*1018 -> 0 | O14: =SUM(H14*22) -> 572 | P14: =I14*509 -> 0 | Q14: =SUM(J14)*610 -> 0 | R14: =SUM(K14:Q14) -> 572
A15: 11 | B15: 46153 | H15: =H14+D15-E14 -> 26 | K15: =SUM(D15*171) -> 0 | L15: =SUM(E15*171) -> 0 | M15: =F15*1018 -> 0 | N15: =G15*1018 -> 0 | O15: =SUM(H15*22) -> 572 | P15: =I15*509 -> 0 | Q15: =SUM(J15)*610 -> 0 | R15: =SUM(K15:Q15) -> 572
A16: 12 | B16: 46154 | E16: 2 | H16: =H15+D16-E15 -> 26 | K16: =SUM(D16*171) -> 0 | L16: =SUM(E16*171) -> 342 | M16: =F16*1018 -> 0 | N16: =G16*1018 -> 0 | O16: =SUM(H16*22) -> 572 | P16: =I16*509 -> 0 | Q16: =SUM(J16)*610 -> 0 | R16: =SUM(K16:Q16) -> 914
A17: 13 | B17: 46155 | H17: =H16+D17-E16 -> 24 | K17: =SUM(D17*171) -> 0 | L17: =SUM(E17*171) -> 0 | M17: =F17*1018 -> 0 | N17: =G17*1018 -> 0 | O17: =SUM(H17*22) -> 528 | P17: =I17*509 -> 0 | Q17: =SUM(J17)*610 -> 0 | R17: =SUM(K17:Q17) -> 528
A18: 14 | B18: 46156 | H18: =H17+D18-E17 -> 24 | K18: =SUM(D18*171) -> 0 | L18: =SUM(E18*171) -> 0 | M18: =F18*1018 -> 0 | N18: =G18*1018 -> 0 | O18: =SUM(H18*22) -> 528 | P18: =I18*509 -> 0 | Q18: =SUM(J18)*610 -> 0 | R18: =SUM(K18:Q18) -> 528
A19: 15 | B19: 46157 | H19: =H18+D19-E18 -> 24 | K19: =SUM(D19*171) -> 0 | L19: =SUM(E19*171) -> 0 | M19: =F19*1018 -> 0 | N19: =G19*1018 -> 0 | O19: =SUM(H19*22) -> 528 | P19: =I19*509 -> 0 | Q19: =SUM(J19)*610 -> 0 | R19: =SUM(K19:Q19) -> 528
A20: 16 | B20: 46158 | H20: =H19+D20-E19 -> 24 | K20: =SUM(D20*171) -> 0 | L20: =SUM(E20*171) -> 0 | M20: =F20*1018 -> 0 | N20: =G20*1018 -> 0 | O20: =SUM(H20*22) -> 528 | P20: =I20*509 -> 0 | Q20: =SUM(J20)*610 -> 0 | R20: =SUM(K20:Q20) -> 528
A21: 17 | B21: 46159 | H21: =H20+D21-E20 -> 24 | K21: =SUM(D21*171) -> 0 | L21: =SUM(E21*171) -> 0 | M21: =F21*1018 -> 0 | N21: =G21*1018 -> 0 | O21: =SUM(H21*22) -> 528 | P21: =I21*509 -> 0 | Q21: =SUM(J21)*610 -> 0 | R21: =SUM(K21:Q21) -> 528
A22: 18 | B22: 46160 | D22: 3 | E22: 3 | H22: =H21+D22-E21 -> 27 | K22: =SUM(D22*171) -> 513 | L22: =SUM(E22*171) -> 513 | M22: =F22*1018 -> 0 | N22: =G22*1018 -> 0 | O22: =SUM(H22*22) -> 594 | P22: =I22*509 -> 0 | Q22: =SUM(J22)*610 -> 0 | R22: =SUM(K22:Q22) -> 1620
A23: 19 | B23: 46161 | H23: =H22+D23-E22 -> 24 | K23: =SUM(D23*171) -> 0 | L23: =SUM(E23*171) -> 0 | M23: =F23*1018 -> 0 | N23: =G23*1018 -> 0 | O23: =SUM(H23*22) -> 528 | P23: =I23*509 -> 0 | Q23: =SUM(J23)*610 -> 0 | R23: =SUM(K23:Q23) -> 528
A24: 20 | B24: 46162 | H24: =H23+D24-E23 -> 24 | K24: =SUM(D24*171) -> 0 | L24: =SUM(E24*171) -> 0 | M24: =F24*1018 -> 0 | N24: =G24*1018 -> 0 | O24: =SUM(H24*22) -> 528 | P24: =I24*509 -> 0 | Q24: =SUM(J24)*610 -> 0 | R24: =SUM(K24:Q24) -> 528
A25: 21 | B25: 46163 | D25: 20 | H25: =H24+D25-E24 -> 44 | K25: =SUM(D25*171) -> 3420 | L25: =SUM(E25*171) -> 0 | M25: =F25*1018 -> 0 | N25: =G25*1018 -> 0 | O25: =SUM(H25*22) -> 968 | P25: =I25*509 -> 0 | Q25: =SUM(J25)*610 -> 0 | R25: =SUM(K25:Q25) -> 4388
A26: 22 | B26: 46164 | H26: =H25+D26-E25 -> 44 | K26: =SUM(D26*171) -> 0 | L26: =SUM(E26*171) -> 0 | M26: =F26*1018 -> 0 | N26: =G26*1018 -> 0 | O26: =SUM(H26*22) -> 968 | P26: =I26*509 -> 0 | Q26: =SUM(J26)*610 -> 0 | R26: =SUM(K26:Q26) -> 968
A27: 23 | B27: 46165 | H27: =H26+D27-E26 -> 44 | K27: =SUM(D27*171) -> 0 | L27: =SUM(E27*171) -> 0 | M27: =F27*1018 -> 0 | N27: =G27*1018 -> 0 | O27: =SUM(H27*22) -> 968 | P27: =I27*509 -> 0 | Q27: =SUM(J27)*610 -> 0 | R27: =SUM(K27:Q27) -> 968
A28: 24 | B28: 46166 | H28: =H27+D28-E27 -> 44 | K28: =SUM(D28*171) -> 0 | L28: =SUM(E28*171) -> 0 | M28: =F28*1018 -> 0 | N28: =G28*1018 -> 0 | O28: =SUM(H28*22) -> 968 | P28: =I28*509 -> 0 | Q28: =SUM(J28)*610 -> 0 | R28: =SUM(K28:Q28) -> 968
A29: 25 | B29: 46167 | H29: =H28+D29-E28 -> 44 | K29: =SUM(D29*171) -> 0 | L29: =SUM(E29*171) -> 0 | M29: =F29*1018 -> 0 | N29: =G29*1018 -> 0 | O29: =SUM(H29*22) -> 968 | P29: =I29*509 -> 0 | Q29: =SUM(J29)*610 -> 0 | R29: =SUM(K29:Q29) -> 968
A30: 26 | B30: 46168 | H30: =H29+D30-E29 -> 44 | K30: =SUM(D30*171) -> 0 | L30: =SUM(E30*171) -> 0 | M30: =F30*1018 -> 0 | N30: =G30*1018 -> 0 | O30: =SUM(H30*22) -> 968 | P30: =I30*509 -> 0 | Q30: =SUM(J30)*610 -> 0 | R30: =SUM(K30:Q30) -> 968
A31: 27 | B31: 46169 | E31: 8 | H31: =H30+D31-E30 -> 44 | K31: =SUM(D31*171) -> 0 | L31: =SUM(E31*171) -> 1368 | M31: =F31*1018 -> 0 | N31: =G31*1018 -> 0 | O31: =SUM(H31*22) -> 968 | P31: =I31*509 -> 0 | Q31: =SUM(J31)*610 -> 0 | R31: =SUM(K31:Q31) -> 2336
A32: 28 | B32: 46170 | H32: =H31+D32-E31 -> 36 | K32: =SUM(D32*171) -> 0 | L32: =SUM(E32*171) -> 0 | M32: =F32*1018 -> 0 | N32: =G32*1018 -> 0 | O32: =SUM(H32*22) -> 792 | P32: =I32*509 -> 0 | Q32: =SUM(J32)*610 -> 0 | R32: =SUM(K32:Q32) -> 792
A33: 29 | B33: 46171 | H33: =H32+D33-E32 -> 36 | K33: =SUM(D33*171) -> 0 | L33: =SUM(E33*171) -> 0 | M33: =F33*1018 -> 0 | N33: =G33*1018 -> 0 | O33: =SUM(H33*22) -> 792 | P33: =I33*509 -> 0 | Q33: =SUM(J33)*610 -> 0 | R33: =SUM(K33:Q33) -> 792
A34: 30 | B34: 46172 | H34: =H33+D34-E33 -> 36 | K34: =SUM(D34*171) -> 0 | L34: =SUM(E34*171) -> 0 | M34: =F34*1018 -> 0 | N34: =G34*1018 -> 0 | O34: =SUM(H34*22) -> 792 | P34: =I34*509 -> 0 | Q34: =SUM(J34)*610 -> 0 | R34: =SUM(K34:Q34) -> 792
A35: 31 | B35: 46173 | H35: =H34+D35-E34 -> 36 | K35: =SUM(D35*171) -> 0 | L35: =SUM(E35*171) -> 0 | M35: =F35*1018 -> 0 | N35: =G35*1018 -> 0 | O35: =SUM(H35*22) -> 792 | P35: =I35*509 -> 0 | Q35: =SUM(J35)*610 -> 0 | R35: =SUM(K35:Q35) -> 792
D36: =SUM(D5:D35) -> 24 | E36: =SUM(E5:E35) -> 15 | F36: =SUM(F5:F35) -> 0 | H36: =SUM(H5:H35) -> 966 | K36: =SUM(K5:K35) -> 4104 | L36: =SUM(L5:L35) -> 2565 | M36: =SUM(M5:M35) -> 0 | N36: =SUM(N5:N35) -> 0 | O36: =SUM(O5:O35) -> 21252 | P36: =SUM(P5:P35) -> 0 | Q36: =SUM(Q5:Q35) -> 0 | R36: =SUM(R5:R35) -> 27921

Sheet ЛС-Техномет
A1: =R36 -> 4812
B2: Отчет по хранению товара за Май
A3: № | B3: дата | D3: Выгрузка кол-во паллет | E3: Загрузка кол-во паллет | F3: Ручная загрузка | G3: Ручная выгрузка | H3: Хранение | I3: предоставление паллеты | J3: Фильмаж (паллет) | K3: стоимость выгрузки | L3: стоимость загрузки | M3: Стоимость ручной загрузки | N3: Стоимость ручной выгрузки | O3: стоимость хранения | P3: Стоимость предоставления паллета | Q3: стоимость услуги фильмаж | R3: итого
H4: (кол-во паллет)
A5: 1 | B5: 46143 | H5: 7 | K5: =SUM(D5*168) -> 0 | L5: =SUM(E5*168) -> 0 | M5: =F5*1000 -> 0 | N5: =G5*1000 -> 0 | O5: =SUM(H5*21.6) -> 151.2 | P5: =I5*500 -> 0 | Q5: =SUM(J5)*600 -> 0 | R5: =SUM(K5:Q5) -> 151.2
A6: 2 | B6: 46144 | H6: 7 | K6: =SUM(D6*168) -> 0 | L6: =SUM(E6*168) -> 0 | M6: =F6*1000 -> 0 | N6: =G6*1000 -> 0 | O6: =SUM(H6*21.6) -> 151.2 | P6: =I6*500 -> 0 | Q6: =SUM(J6)*600 -> 0 | R6: =SUM(K6:Q6) -> 151.2
A7: 3 | B7: 46145 | H7: 7 | K7: =SUM(D7*168) -> 0 | L7: =SUM(E7*168) -> 0 | M7: =F7*1000 -> 0 | N7: =G7*1000 -> 0 | O7: =SUM(H7*21.6) -> 151.2 | P7: =I7*500 -> 0 | Q7: =SUM(J7)*600 -> 0 | R7: =SUM(K7:Q7) -> 151.2
A8: 4 | B8: 46146 | H8: 7 | K8: =SUM(D8*168) -> 0 | L8: =SUM(E8*168) -> 0 | M8: =F8*1000 -> 0 | N8: =G8*1000 -> 0 | O8: =SUM(H8*21.6) -> 151.2 | P8: =I8*500 -> 0 | Q8: =SUM(J8)*600 -> 0 | R8: =SUM(K8:Q8) -> 151.2
A9: 5 | B9: 46147 | H9: 7 | K9: =SUM(D9*168) -> 0 | L9: =SUM(E9*168) -> 0 | M9: =F9*1000 -> 0 | N9: =G9*1000 -> 0 | O9: =SUM(H9*21.6) -> 151.2 | P9: =I9*500 -> 0 | Q9: =SUM(J9)*600 -> 0 | R9: =SUM(K9:Q9) -> 151.2
A10: 6 | B10: 46148 | H10: 7 | K10: =SUM(D10*168) -> 0 | L10: =SUM(E10*168) -> 0 | M10: =F10*1000 -> 0 | N10: =G10*1000 -> 0 | O10: =SUM(H10*21.6) -> 151.2 | P10: =I10*500 -> 0 | Q10: =SUM(J10)*600 -> 0 | R10: =SUM(K10:Q10) -> 151.2
A11: 7 | B11: 46149 | H11: 7 | K11: =SUM(D11*168) -> 0 | L11: =SUM(E11*168) -> 0 | M11: =F11*1000 -> 0 | N11: =G11*1000 -> 0 | O11: =SUM(H11*21.6) -> 151.2 | P11: =I11*500 -> 0 | Q11: =SUM(J11)*600 -> 0 | R11: =SUM(K11:Q11) -> 151.2
A12: 8 | B12: 46150 | H12: 7 | K12: =SUM(D12*168) -> 0 | L12: =SUM(E12*168) -> 0 | M12: =F12*1000 -> 0 | N12: =G12*1000 -> 0 | O12: =SUM(H12*21.6) -> 151.2 | P12: =I12*500 -> 0 | Q12: =SUM(J12)*600 -> 0 | R12: =SUM(K12:Q12) -> 151.2
A13: 9 | B13: 46151 | H13: 7 | K13: =SUM(D13*168) -> 0 | L13: =SUM(E13*168) -> 0 | M13: =F13*1000 -> 0 | N13: =G13*1000 -> 0 | O13: =SUM(H13*21.6) -> 151.2 | P13: =I13*500 -> 0 | Q13: =SUM(J13)*600 -> 0 | R13: =SUM(K13:Q13) -> 151.2
A14: 10 | B14: 46152 | H14: 7 | K14: =SUM(D14*168) -> 0 | L14: =SUM(E14*168) -> 0 | M14: =F14*1000 -> 0 | N14: =G14*1000 -> 0 | O14: =SUM(H14*21.6) -> 151.2 | P14: =I14*500 -> 0 | Q14: =SUM(J14)*600 -> 0 | R14: =SUM(K14:Q14) -> 151.2
A15: 11 | B15: 46153 | H15: 7 | K15: =SUM(D15*168) -> 0 | L15: =SUM(E15*168) -> 0 | M15: =F15*1000 -> 0 | N15: =G15*1000 -> 0 | O15: =SUM(H15*21.6) -> 151.2 | P15: =I15*500 -> 0 | Q15: =SUM(J15)*600 -> 0 | R15: =SUM(K15:Q15) -> 151.2
A16: 12 | B16: 46154 | H16: 7 | K16: =SUM(D16*168) -> 0 | L16: =SUM(E16*168) -> 0 | M16: =F16*1000 -> 0 | N16: =G16*1000 -> 0 | O16: =SUM(H16*21.6) -> 151.2 | P16: =I16*500 -> 0 | Q16: =SUM(J16)*600 -> 0 | R16: =SUM(K16:Q16) -> 151.2
... A32: 28 | B32: 46170 | H32: 7 | K32: =SUM(D32*168) -> 0 | L32: =SUM(E32*168) -> 0 | M32: =F32*1000 -> 0 | N32: =G32*1000 -> 0 | O32: =SUM(H32*21.6) -> 151.2 | P32: =I32*500 -> 0 | Q32: =SUM(J32)*600 -> 0 | R32: =SUM(K32:Q32) -> 151.2
A33: 29 | B33: 46171 | E33: 1 | H33: 7 | K33: =SUM(D33*168) -> 0 | L33: =SUM(E33*168) -> 168 | M33: =F33*1000 -> 0 | N33: =G33*1000 -> 0 | O33: =SUM(H33*21.6) -> 151.2 | P33: =I33*500 -> 0 | Q33: =SUM(J33)*600 -> 0 | R33: =SUM(K33:Q33) -> 319.2
A34: 30 | B34: 46172 | H34: 6 | K34: =SUM(D34*168) -> 0 | L34: =SUM(E34*168) -> 0 | M34: =F34*1000 -> 0 | N34: =G34*1000 -> 0 | O34: =SUM(H34*21.6) -> 129.6 | P34: =I34*500 -> 0 | Q34: =SUM(J34)*600 -> 0 | R34: =SUM(K34:Q34) -> 129.6
B35: 46173 | H35: 6 | K35: =SUM(D35*168) -> 0 | L35: =SUM(E35*168) -> 0 | M35: =F35*1000 -> 0 | N35: =G35*1000 -> 0 | O35: =SUM(H35*21.6) -> 129.6 | P35: =I35*500 -> 0 | Q35: =SUM(J35)*600 -> 0 | R35: =SUM(K35:Q35) -> 129.6
D36: =SUM(D5:D35) -> 0 | E36: =SUM(E5:E35) -> 1 | F36: =SUM(F5:F35) -> 0 | H36: =SUM(H5:H35) -> 215 | K36: =SUM(K5:K35) -> 0 | L36: =SUM(L5:L35) -> 168 | M36: =SUM(M5:M35) -> 0 | N36: =SUM(N5:N35) -> 0 | O36: =SUM(O5:O35) -> 4644 | P36: =SUM(P5:P35) -> 0 | Q36: =SUM(Q5:Q35) -> 0 | R36: =SUM(R5:R35) -> 4812

Sheet Сандекс
A1: =S39 -> 20640
A4: Отчет "Сандекс" Май 2025 | L4: Стоимость
A5: дата | C5: Выгрузка паллет | D5: Выгрузка короб | E5: Загрузка паллет | F5: Загрузка короб | G5: Наборка короб | J5: Палетирование | K5: Хранение | L5: Выгрузка палллет | M5: Выгрузка короб | N5: Загрузка паллет | O5: Загрузка короб | P5: Наборка | Q5: Паллетирование | R5: Хранение | S5: итого
K6: 38
A7: 46143 | J7: 0 | K7: 30 | L7: =C7*168 -> 0 | M7: =D7*4 -> 0 | N7: =E7*168 -> 0 | O7: =F7*4 -> 0 | P7: =G7*4 -> 0 | Q7: =J7*600 -> 0 | R7: =K7*21.6 -> 648 | S7: =SUM(L7:R7) -> 648
A8: 46144 | J8: 0 | K8: 30 | L8: =C8*168 -> 0 | M8: =D8*4 -> 0 | N8: =E8*168 -> 0 | O8: =F8*4 -> 0 | P8: =G8*4 -> 0 | Q8: =J8*600 -> 0 | R8: =K8*21.6 -> 648 | S8: =SUM(L8:R8) -> 648
A9: 46145 | J9: 0 | K9: 30 | L9: =C9*168 -> 0 | M9: =D9*4 -> 0 | N9: =E9*168 -> 0 | O9: =F9*4 -> 0 | P9: =G9*4 -> 0 | Q9: =J9*600 -> 0 | R9: =K9*21.6 -> 648 | S9: =SUM(L9:R9) -> 648
A10: 46146 | J10: 0 | K10: 30 | L10: =C10*168 -> 0 | M10: =D10*4 -> 0 | N10: =E10*168 -> 0 | O10: =F10*4 -> 0 | P10: =G10*4 -> 0 | Q10: =J10*600 -> 0 | R10: =K10*21.6 -> 648 | S10: =SUM(L10:R10) -> 648
A11: 46147 | J11: 0 | K11: 30 | L11: =C11*168 -> 0 | M11: =D11*4 -> 0 | N11: =E11*168 -> 0 | O11: =F11*4 -> 0 | P11: =G11*4 -> 0 | Q11: =J11*600 -> 0 | R11: =K11*21.6 -> 648 | S11: =SUM(L11:R11) -> 648
A12: 46148 | J12: 0 | K12: 30 | L12: =C12*168 -> 0 | M12: =D12*4 -> 0 | N12: =E12*168 -> 0 | O12: =F12*4 -> 0 | P12: =G12*4 -> 0 | Q12: =J12*600 -> 0 | R12: =K12*21.6 -> 648 | S12: =SUM(L12:R12) -> 648
A13: 46149 | J13: 0 | K13: 30 | L13: =C13*168 -> 0 | M13: =D13*4 -> 0 | N13: =E13*168 -> 0 | O13: =F13*4 -> 0 | P13: =G13*4 -> 0 | Q13: =J13*600 -> 0 | R13: =K13*21.6 -> 648 | S13: =SUM(L13:R13) -> 648
A14: 46150 | J14: 0 | K14: 30 | L14: =C14*168 -> 0 | M14: =D14*4 -> 0 | N14: =E14*168 -> 0 | O14: =F14*4 -> 0 | P14: =G14*4 -> 0 | Q14: =J14*600 -> 0 | R14: =K14*21.6 -> 648 | S14: =SUM(L14:R14) -> 648
A15: 46151 | J15: 0 | K15: 30 | L15: =C15*168 -> 0 | M15: =D15*4 -> 0 | N15: =E15*168 -> 0 | O15: =F15*4 -> 0 | P15: =G15*4 -> 0 | Q15: =J15*600 -> 0 | R15: =K15*21.6 -> 648 | S15: =SUM(L15:R15) -> 648
A16: 46152 | J16: 0 | K16: 30 | L16: =C16*168 -> 0 | M16: =D16*4 -> 0 | N16: =E16*168 -> 0 | O16: =F16*4 -> 0 | P16: =G16*4 -> 0 | Q16: =J16*600 -> 0 | R16: =K16*21.6 -> 648 | S16: =SUM(L16:R16) -> 648
A17: 46153 | J17: 0 | K17: 30 | L17: =C17*168 -> 0 | M17: =D17*4 -> 0 | N17: =E17*168 -> 0 | O17: =F17*4 -> 0 | P17: =G17*4 -> 0 | Q17: =J17*600 -> 0 | R17: =K17*21.6 -> 648 | S17: =SUM(L17:R17) -> 648
A18: 46154 | J18: 0 | K18: 30 | L18: =C18*168 -> 0 | M18: =D18*4 -> 0 | N18: =E18*168 -> 0 | O18: =F18*4 -> 0 | P18: =G18*4 -> 0 | Q18: =J18*600 -> 0 | R18: =K18*21.6 -> 648 | S18: =SUM(L18:R18) -> 648
... A32: 46168 | J32: 0 | K32: 30 | L32: =C32*168 -> 0 | M32: =D32*4 -> 0 | N32: =E32*168 -> 0 | O32: =F32*4 -> 0 | P32: =G32*4 -> 0 | Q32: =J32*600 -> 0 | R32: =K32*21.6 -> 648 | S32: =SUM(L32:R32) -> 648
A33: 46169 | C33: 2 | J33: 0 | K33: 32 | L33: =C33*168 -> 336 | M33: =D33*4 -> 0 | N33: =E33*168 -> 0 | O33: =F33*4 -> 0 | P33: =G33*4 -> 0 | Q33: =J33*600 -> 0 | R33: =K33*21.6 -> 691.2 | S33: =SUM(L33:R33) -> 1027.2
A34: 46170 | J34: 0 | K34: 32 | L34: =C34*168 -> 0 | M34: =D34*4 -> 0 | N34: =E34*168 -> 0 | O34: =F34*4 -> 0 | P34: =G34*4 -> 0 | Q34: =J34*600 -> 0 | R34: =K34*21.6 -> 691.2 | S34: =SUM(L34:R34) -> 691.2
A35: 46171 | K35: 32 | L35: =C35*168 -> 0 | M35: =D35*4 -> 0 | N35: =E35*168 -> 0 | O35: =F35*4 -> 0 | P35: =G35*4 -> 0 | Q35: =J35*600 -> 0 | R35: =K35*21.6 -> 691.2 | S35: =SUM(L35:R35) -> 691.2
A36: 46172 | K36: 32 | L36: =C36*168 -> 0 | M36: =D36*4 -> 0 | N36: =E36*168 -> 0 | O36: =F36*4 -> 0 | P36: =G36*4 -> 0 | Q36: =J36*600 -> 0 | R36: =K36*21.6 -> 691.2 | S36: =SUM(L36:R36) -> 691.2
A37: 46173 | K37: 32 | L37: =C37*168 -> 0 | M37: =D37*4 -> 0 | N37: =E37*168 -> 0 | O37: =F37*4 -> 0 | P37: =G37*4 -> 0 | Q37: =J37*600 -> 0 | R37: =K37*21.6 -> 691.2 | S37: =SUM(L37:R37) -> 691.2
A38: Итого | C38: =SUM(C7:C37) -> 2 | D38: =SUM(D7:D37) -> 0 | E38: =SUM(E7:E37) -> 0 | F38: =SUM(F7:F37) -> 0 | G38: =SUM(G7:G37) -> 0 | H38: =SUM(H7:H37) -> 0 | I38: =SUM(I7:I37) -> 0 | J38: =SUM(J7:J37) -> 0 | ... S38: =SUM(S7:S37) -> 20640
R39: Итого | S39: =S38 -> 20640

Sheet СтройТех
A1: =K36 -> 26403
A2: Отчет по хранению товара СтройТех за Май
A3: № | B3: дата | D3: Выгрузка кол-во паллет | E3: ручная загрузка | G3: Хранение | H3: стоимость выгрузки | I3: стоимость загр.. Работ | J3: стоимость хранения | K3: итого
E4: мультипак | F4: шт,. | G4: (кол-во паллет)
A5: 1 | B5: 46143 | G5: 45 | H5: =SUM(D5*60) -> 0 | I5: =SUM(E5*25+F5*7) -> 0 | J5: =SUM(G5*15) -> 675 | K5: =SUM(H5:J5) -> 675
A6: 2 | B6: 46144 | G6: 45 | H6: =SUM(D6*60) -> 0 | I6: =SUM(E6*25+F6*7) -> 0 | J6: =SUM(G6*15) -> 675 | K6: =SUM(H6:J6) -> 675
A7: 3 | B7: 46145 | G7: 45 | H7: =SUM(D7*60) -> 0 | I7: =SUM(E7*25+F7*7) -> 0 | J7: =SUM(G7*15) -> 675 | K7: =SUM(H7:J7) -> 675
A8: 4 | B8: 46146 | G8: 45 | H8: =SUM(D8*60) -> 0 | I8: =SUM(E8*25+F8*7) -> 0 | J8: =SUM(G8*15) -> 675 | K8: =SUM(H8:J8) -> 675
A9: 5 | B9: 46147 | G9: 45 | H9: =SUM(D9*60) -> 0 | I9: =SUM(E9*25+F9*7) -> 0 | J9: =SUM(G9*15) -> 675 | K9: =SUM(H9:J9) -> 675
A10: 6 | B10: 46148 | G10: 45 | H10: =SUM(D10*60) -> 0 | I10: =SUM(E10*25+F10*7) -> 0 | J10: =SUM(G10*15) -> 675 | K10: =SUM(H10:J10) -> 675
A11: 7 | B11: 46149 | G11: 45 | H11: =SUM(D11*60) -> 0 | I11: =SUM(E11*25+F11*7) -> 0 | J11: =SUM(G11*15) -> 675 | K11: =SUM(H11:J11) -> 675
A12: 8 | B12: 46150 | G12: 45 | H12: =SUM(D12*60) -> 0 | I12: =SUM(E12*25+F12*7) -> 0 | J12: =SUM(G12*15) -> 675 | K12: =SUM(H12:J12) -> 675
A13: 9 | B13: 46151 | G13: 45 | H13: =SUM(D13*60) -> 0 | I13: =SUM(E13*25+F13*7) -> 0 | J13: =SUM(G13*15) -> 675 | K13: =SUM(H13:J13) -> 675
A14: 10 | B14: 46152 | G14: 45 | H14: =SUM(D14*60) -> 0 | I14: =SUM(E14*25+F14*7) -> 0 | J14: =SUM(G14*15) -> 675 | K14: =SUM(H14:J14) -> 675
A15: 11 | B15: 46153 | G15: 45 | H15: =SUM(D15*60) -> 0 | I15: =SUM(E15*25+F15*7) -> 0 | J15: =SUM(G15*15) -> 675 | K15: =SUM(H15:J15) -> 675
A16: 12 | B16: 46154 | G16: 45 | H16: =SUM(D16*60) -> 0 | I16: =SUM(E16*25+F16*7) -> 0 | J16: =SUM(G16*15) -> 675 | K16: =SUM(H16:J16) -> 675
... A21: 17 | B21: 46159 | G21: 45 | H21: =SUM(D21*60) -> 0 | I21: =SUM(E21*25+F21*7) -> 0 | J21: =SUM(G21*15) -> 675 | K21: =SUM(H21:J21) -> 675
A22: 18 | B22: 46160 | D22: 20 | G22: 65 | H22: =SUM(D22*60) -> 1200 | I22: =SUM(E22*25+F22*7) -> 0 | J22: =SUM(G22*15) -> 975 | K22: =SUM(H22:J22) -> 2175
A23: 19 | B23: 46161 | G23: 65 | H23: =SUM(D23*60) -> 0 | I23: =SUM(E23*25+F23*7) -> 0 | J23: =SUM(G23*15) -> 975 | K23: =SUM(H23:J23) -> 975
A24: 20 | B24: 46162 | G24: 65 | H24: =SUM(D24*60) -> 0 | I24: =SUM(E24*25+F24*7) -> 0 | J24: =SUM(G24*15) -> 975 | K24: =SUM(H24:J24) -> 975
A25: 21 | B25: 46163 | G25: 65 | H25: =SUM(D25*60) -> 0 | I25: =SUM(E25*25+F25*7) -> 0 | J25: =SUM(G25*15) -> 975 | K25: =SUM(H25:J25) -> 975
A26: 22 | B26: 46164 | E26: 1 | F26: 5 | G26: 65 | H26: =SUM(D26*60) -> 0 | I26: =SUM(E26*25+F26*7) -> 60 | J26: =SUM(G26*15) -> 975 | K26: =SUM(H26:J26) -> 1035
A27: 23 | B27: 46165 | G27: 65 | H27: =SUM(D27*60) -> 0 | I27: =SUM(E27*25+F27*7) -> 0 | J27: =SUM(G27*15) -> 975 | K27: =SUM(H27:J27) -> 975
A28: 24 | B28: 46166 | G28: 65 | H28: =SUM(D28*60) -> 0 | I28: =SUM(E28*25+F28*7) -> 0 | J28: =SUM(G28*15) -> 975 | K28: =SUM(H28:J28) -> 975
A29: 25 | B29: 46167 | G29: 65 | H29: =SUM(D29*60) -> 0 | I29: =SUM(E29*25+F29*7) -> 0 | J29: =SUM(G29*15) -> 975 | K29: =SUM(H29:J29) -> 975
A30: 26 | B30: 46168 | G30: 65 | H30: =SUM(D30*60) -> 0 | I30: =SUM(E30*25+F30*7) -> 0 | J30: =SUM(G30*15) -> 975 | K30: =SUM(H30:J30) -> 975
A31: 27 | B31: 46169 | G31: 65 | H31: =SUM(D31*60) -> 0 | I31: =SUM(E31*25+F31*7) -> 0 | J31: =SUM(G31*15) -> 975 | K31: =SUM(H31:J31) -> 975
A32: 28 | B32: 46170 | F32: 9 | G32: 65 | H32: =SUM(D32*60) -> 0 | I32: =SUM(E32*25+F32*7) -> 63 | J32: =SUM(G32*15) -> 975 | K32: =SUM(H32:J32) -> 1038
A33: 29 | B33: 46171 | G33: 64 | H33: =SUM(D33*60) -> 0 | I33: =SUM(E33*25+F33*7) -> 0 | J33: =SUM(G33*15) -> 960 | K33: =SUM(H33:J33) -> 960
A34: 30 | B34: 46172 | G34: 64 | H34: =SUM(D34*60) -> 0 | I34: =SUM(E34*25+F34*7) -> 0 | J34: =SUM(G34*15) -> 960 | K34: =SUM(H34:J34) -> 960
B35: 46173 | G35: 64 | H35: =SUM(D35*60) -> 0 | I35: =SUM(E35*25+F35*7) -> 0 | J35: =SUM(G35*15) -> 960 | K35: =SUM(H35:J35) -> 960
G36: =SUM(G5:G35) -> 1672 | H36: =SUM(H5:H35) -> 1200 | I36: =SUM(I5:I35) -> 123 | J36: =SUM(J5:J35) -> 25080 | K36: =SUM(K5:K35) -> 26403

Sheet Ергарда
A1: =J35 -> 8928 | B1: Отчет по хранению товара Ергарда за Май
A2: № | B2: дата | D2: Выгрузка кол-во паллет | E2: Загрузка кол-во паллет | F2: Хранение | G2: стоимость выгрузки | H2: стоимость загрузки | I2: стоимость хранения | J2: итого
F3: (кол-во паллет)
A4: 1 | B4: 46143 | F4: 24 | G4: =SUM(D4*120) -> 0 | H4: =SUM(E4*120) -> 0 | I4: =SUM(F4*12) -> 288 | J4: =SUM(G4:I4) -> 288
A5: 2 | B5: 46144 | F5: 24 | G5: =SUM(D5*120) -> 0 | H5: =SUM(E5*120) -> 0 | I5: =SUM(F5*12) -> 288 | J5: =SUM(G5:I5) -> 288
A6: 3 | B6: 46145 | F6: 24 | G6: =SUM(D6*120) -> 0 | H6: =SUM(E6*120) -> 0 | I6: =SUM(F6*12) -> 288 | J6: =SUM(G6:I6) -> 288
A7: 4 | B7: 46146 | F7: 24 | G7: =SUM(D7*120) -> 0 | H7: =SUM(E7*120) -> 0 | I7: =SUM(F7*12) -> 288 | J7: =SUM(G7:I7) -> 288
A8: 5 | B8: 46147 | F8: 24 | G8: =SUM(D8*120) -> 0 | H8: =SUM(E8*120) -> 0 | I8: =SUM(F8*12) -> 288 | J8: =SUM(G8:I8) -> 288
A9: 6 | B9: 46148 | F9: 24 | G9: =SUM(D9*120) -> 0 | H9: =SUM(E9*120) -> 0 | I9: =SUM(F9*12) -> 288 | J9: =SUM(G9:I9) -> 288
A10: 7 | B10: 46149 | F10: 24 | G10: =SUM(D10*120) -> 0 | H10: =SUM(E10*120) -> 0 | I10: =SUM(F10*12) -> 288 | J10: =SUM(G10:I10) -> 288
A11: 8 | B11: 46150 | F11: 24 | G11: =SUM(D11*120) -> 0 | H11: =SUM(E11*120) -> 0 | I11: =SUM(F11*12) -> 288 | J11: =SUM(G11:I11) -> 288
A12: 9 | B12: 46151 | F12: 24 | G12: =SUM(D12*120) -> 0 | H12: =SUM(E12*120) -> 0 | I12: =SUM(F12*12) -> 288 | J12: =SUM(G12:I12) -> 288
A13: 10 | B13: 46152 | F13: 24 | G13: =SUM(D13*120) -> 0 | H13: =SUM(E13*120) -> 0 | I13: =SUM(F13*12) -> 288 | J13: =SUM(G13:I13) -> 288
A14: 11 | B14: 46153 | F14: 24 | G14: =SUM(D14*120) -> 0 | H14: =SUM(E14*120) -> 0 | I14: =SUM(F14*12) -> 288 | J14: =SUM(G14:I14) -> 288
A15: 12 | B15: 46154 | F15: 24 | G15: =SUM(D15*120) -> 0 | H15: =SUM(E15*120) -> 0 | I15: =SUM(F15*12) -> 288 | J15: =SUM(G15:I15) -> 288
... A34: 31 | B34: 46173 | F34: 24 | G34: =SUM(D34*120) -> 0 | H34: =SUM(E34*120) -> 0 | I34: =SUM(F34*12) -> 288 | J34: =SUM(G34:I34) -> 288
G35: =SUM(G4:G34) -> 0 | H35: =SUM(H4:H34) -> 0 | I35: =SUM(I4:I34) -> 8928 | J35: =SUM(J4:J34) -> 8928

Sheet Казань_Приволжская экспорт
A3: =IF(DAY(TODAY())>27,"Акт № от " & TEXT(TODAY(),"ДД ММММ ГГГГ"),"Акт № от " & TEXT(TODAY()-DAY(TODAY()),"ДД ММММ ГГГГ")) & "г. Казань_Приволжская" -> Акт № от 31 Май 2026г. Казань_Приволжская
A4: =IF(DAY(TODAY()) > 27, "выполненных работ (оказанных услуг) за " & TEXT(TODAY(),"ММММ ГГГГ"),"выполненных работ (оказанных услуг) за " & TEXT(TODAY()-DAY(TODAY()),"ММММ ГГГГ")) -> выполненных работ (оказанных услуг) за Май 2026
A5: по Договору хранения № СХ.47103 от «10» апреля 2025 г.
A7: =IF(DAY(TODAY()) > 27,"Во исполнение Договора в период с " & TEXT(TODAY()-DAY(TODAY()-DAY(TODAY())),"ДД ММММ ГГГГ") & " г. По " & TEXT(TODAY(),"ДД ММММ ГГГГ") & " г. ХРАНИТЕЛЬ оказал ПОКЛАЖЕДАТЕЛЮ следующие услуги (работы):"," Во исполнение Договора в период с " & TEXT(TODAY()-DAY(TODAY())-DAY(TODAY()-DAY(TODAY()))+1,"ДД ММММ ГГГГ") & " г. По " & TEXT(TODAY()-DAY(TODAY()),"ДД ММММ ГГГГ") & " г. ХРАНИТЕЛЬ оказал ПОКЛАЖЕДАТЕЛЮ следующие услуги (работы):") -> Во исполнение Договора в период с 01 Май 2026 г. По 31 Май 2026 г. ХРАНИТЕЛЬ оказал ПОКЛАЖЕДАТЕЛЮ следующие услуги (работы):
A9: № | B9: Наименование услуг (работ) | C9: Ед. изм. | D9: Количество | E9: Цена | F9: Сумма без НДС | G9: Сумма с НДС
A10: 1 | B10: оформление документов | C10: шт. | D10: 13 | E10: 2000 | F10: =SUM(D10*E10) -> 26000 | G10: =F10*1.22 -> 31720
A11: 2 | B11: Оформление сертификата | C11: шт. | F11: =SUM(D11*E11) -> 0 | G11: =F11*1.2 -> 0
F12: =SUM(F10:F11) -> 26000 | G12: =SUM(G10:G11) -> 31720
A13: Итого: | B13: двадцать шесть тысяч рублей ноль копеек
A14: Без налога (НДС): | B14: =B13 -> двадцать шесть тысяч рублей ноль копеек
A15: Всего (с учетом НДС) | B15: тридцать одна тысяча семьсот двадцать рублей ноль копеек
A16: Вышеперечисленные услуги (работы) выполнены полностью.
A17: ПОКЛАЖЕДАТЕЛЬ претензий по объему, качеству и срокам оказания услуг претензий не имеет.
A20: ООО "ДТМ" | D20: ПАО "СИБУР Холдинг"
A22: ____________________Расстегаев Д.О. | D22: ____________________

Sheet Казань_Автосервисная экспорт
A3: =IF(DAY(TODAY())>27,"Акт № от " & TEXT(TODAY(),"ДД ММММ ГГГГ"),"Акт № от " & TEXT(TODAY()-DAY(TODAY()),"ДД ММММ ГГГГ")) & " г. Казань_Автосервисная" -> Акт № от 31 Май 2026 г. Казань_Автосервисная
A4: =IF(DAY(TODAY()) > 27, "выполненных работ (оказанных услуг) за " & TEXT(TODAY(),"ММММ ГГГГ"),"выполненных работ (оказанных услуг) за " & TEXT(TODAY()-DAY(TODAY()),"ММММ ГГГГ")) -> выполненных работ (оказанных услуг) за Май 2026
A5: по Договору хранения № СХ.47103 от «10» апреля 2025 г.
A7: =IF(DAY(TODAY()) > 27,"Во исполнение Договора в период с " & TEXT(TODAY()-DAY(TODAY()-DAY(TODAY())),"ДД ММММ ГГГГ") & " г. По " & TEXT(TODAY(),"ДД ММММ ГГГГ") & " г. ХРАНИТЕЛЬ оказал ПОКЛАЖЕДАТЕЛЮ следующие услуги (работы):"," Во исполнение Договора в период с " & TEXT(TODAY()-DAY(TODAY())-DAY(TODAY()-DAY(TODAY()))+1,"ДД ММММ ГГГГ") & " г. По " & TEXT(TODAY()-DAY(TODAY()),"ДД ММММ ГГГГ") & " г. ХРАНИТЕЛЬ оказал ПОКЛАЖЕДАТЕЛЮ следующие услуги (работы):") -> Во исполнение Договора в период с 01 Май 2026 г. По 31 Май 2026 г. ХРАНИТЕЛЬ оказал ПОКЛАЖЕДАТЕЛЮ следующие услуги (работы):
A9: № | B9: Наименование услуг (работ) | C9: Ед. изм. | D9: Количество | E9: Цена | F9: Сумма без НДС | G9: Сумма с НДС
A10: 1 | B10: оформление документов | C10: шт. | D10: 13 | E10: 2000 | F10: =SUM(D10*E10) -> 26000 | G10: =F10*1.22 -> 31720
A11: 2 | B11: Оформление сертификата | C11: шт. | F11: =SUM(D11*E11) -> 0 | G11: =F11*1.2 -> 0
F12: =SUM(F10:F11) -> 26000 | G12: =SUM(G10:G11) -> 31720
A13: Итого: | B13: двадцать шесть тысяч рублей ноль копеек
A14: Без налога (НДС): | B14: =B13 -> двадцать шесть тысяч рублей ноль копеек
A15: Всего (с учетом НДС) | B15: тридцать одна тысяча семьсот двадцать рублей ноль копеек
A16: Вышеперечисленные услуги (работы) выполнены полностью.
A17: ПОКЛАЖЕДАТЕЛЬ претензий по объему, качеству и срокам оказания услуг претензий не имеет.
A20: ООО "ДТМ" | D20: ПАО "СИБУР Холдинг"
A22: ____________________Расстегаев Д.О. | D22: ____________________

Sheet Екатеринбург экспорт
A3: =IF(DAY(TODAY())>27,"Акт № от " & TEXT(TODAY(),"ДД ММММ ГГГГ"),"Акт № от " & TEXT(TODAY()-DAY(TODAY()),"ДД ММММ ГГГГ")) & " г. Екатеринбург" -> Акт № от 31 Май 2026 г. Екатеринбург
A4: =IF(DAY(TODAY()) > 27, "выполненных работ (оказанных услуг) за " & TEXT(TODAY(),"ММММ ГГГГ"),"выполненных работ (оказанных услуг) за " & TEXT(TODAY()-DAY(TODAY()),"ММММ ГГГГ")) -> выполненных работ (оказанных услуг) за Май 2026
A5: по Договору хранения № СХ.47103 от «10» апреля 2025 г.
A7: =IF(DAY(TODAY()) > 27,"Во исполнение Договора в период с " & TEXT(TODAY()-DAY(TODAY()-DAY(TODAY())),"ДД ММММ ГГГГ") & " г. По " & TEXT(TODAY(),"ДД ММММ ГГГГ") & " г. ХРАНИТЕЛЬ оказал ПОКЛАЖЕДАТЕЛЮ следующие услуги (работы):"," Во исполнение Договора в период с " & TEXT(TODAY()-DAY(TODAY())-DAY(TODAY()-DAY(TODAY()))+1,"ДД ММММ ГГГГ") & " г. По " & TEXT(TODAY()-DAY(TODAY()),"ДД ММММ ГГГГ") & " г. ХРАНИТЕЛЬ оказал ПОКЛАЖЕДАТЕЛЮ следующие услуги (работы):") -> Во исполнение Договора в период с 01 Май 2026 г. По 31 Май 2026 г. ХРАНИТЕЛЬ оказал ПОКЛАЖЕДАТЕЛЮ следующие услуги (работы):
A9: № | B9: Наименование услуг (работ) | C9: Ед. изм. | D9: Количество | E9: Цена | F9: Сумма без НДС | G9: Сумма с НДС
A10: 1 | B10: оформление документов | C10: шт. | D10: 1 | E10: 2000 | F10: =SUM(D10*E10) -> 2000 | G10: =F10*1.22 -> 2440
A11: 2 | B11: Оформление сертификата | C11: шт. | F11: =SUM(D11*E11) -> 0 | G11: =F11*1.2 -> 0
F12: =SUM(F10:F11) -> 2000 | G12: =SUM(G10:G11) -> 2440
A13: Итого: | B13: две тысячи рублей ноль копеек
A14: Без налога (НДС): | B14: =B13 -> две тысячи рублей ноль копеек
A15: Всего (с учетом НДС) | B15: две тысячи четыреста сорок рублей ноль копеек
A16: Вышеперечисленные услуги (работы) выполнены полностью.
A17: ПОКЛАЖЕДАТЕЛЬ претензий по объему, качеству и срокам оказания услуг претензий не имеет.
A20: ООО "ДТМ" | D20: ПАО "СИБУР Холдинг"
A22: ____________________Расстегаев Д.О. | D22: ____________________

Sheet Баумана KPI
A2: Отчет по хранению товара за Май 2026 Баумана KPI
A3: № | B3: дата | D3: Выгрузка кол-во | E3: Загрузка кол-во | F3: Хранение | G3: Резервирование 0 | H3: Мин. Суточный резерв 0 | I3: переконсолидация (тонн) | J3: Паллетирование | K3: Взвешивание | L3: стоимость взвешивания | M3: стоимость выгрузки за 1 месяц | N3: стоимость загрузки за 1 месяц | O3: стоимость хранения за 1 месяц | P3: Доплата за хранение за 1 месяц | Q3: Доплата за ПРР за 1 месяц | R3: стоимость переконс. | S3: Стоимость паллетирования | T3: итого
A5: 1 | B5: 01.05.2026 | D5: 0 | E5: 0 | F5: 8.225 | G5: 0 | H5: 0 | I5: 0 | J5: 0 | K5: 0 | L5: 0 | M5: 0 | N5: 0 | O5: 0 | P5: 0 | Q5: 0 | R5: 0 | S5: 0 | T5: 0
A6: 2 | B6: 02.05.2026 | D6: 0 | E6: 0 | F6: 8.225 | G6: 0 | H6: 0 | I6: 0 | J6: 0 | K6: 0 | L6: 0 | M6: 0 | N6: 0 | O6: 0 | P6: 0 | Q6: 0 | R6: 0 | S6: 0 | T6: 0
A7: 3 | B7: 03.05.2026 | D7: 0 | E7: 0 | F7: 8.225 | G7: 0 | H7: 0 | I7: 0 | J7: 0 | K7: 0 | L7: 0 | M7: 0 | N7: 0 | O7: 0 | P7: 0 | Q7: 0 | R7: 0 | S7: 0 | T7: 0
A8: 4 | B8: 04.05.2026 | D8: 0 | E8: 0 | F8: 8.225 | G8: 0 | H8: 0 | I8: 0 | J8: 0 | K8: 0 | L8: 0 | M8: 0 | N8: 0 | O8: 0 | P8: 0 | Q8: 0 | R8: 0 | S8: 0 | T8: 0
A9: 5 | B9: 05.05.2026 | D9: 0 | E9: 0 | F9: 8.225 | G9: 0 | H9: 0 | I9: 0 | J9: 0 | K9: 0 | L9: 0 | M9: 0 | N9: 0 | O9: 0 | P9: 0 | Q9: 0 | R9: 0 | S9: 0 | T9: 0
A10: 6 | B10: 06.05.2026 | D10: 0 | E10: 0 | F10: 8.225 | G10: 0 | H10: 0 | I10: 0 | J10: 0 | K10: 0 | L10: 0 | M10: 0 | N10: 0 | O10: 0 | P10: 0 | Q10: 0 | R10: 0 | S10: 0 | T10: 0
A11: 7 | B11: 07.05.2026 | D11: 0 | E11: 0 | F11: 8.225 | G11: 0 | H11: 0 | I11: 0 | J11: 0 | K11: 0 | L11: 0 | M11: 0 | N11: 0 | O11: 0 | P11: 0 | Q11: 0 | R11: 0 | S11: 0 | T11: 0
A12: 8 | B12: 08.05.2026 | D12: 0 | E12: 0 | F12: 8.225 | G12: 0 | H12: 0 | I12: 0 | J12: 0 | K12: 0 | L12: 0 | M12: 0 | N12: 0 | O12: 0 | P12: 0 | Q12: 0 | R12: 0 | S12: 0 | T12: 0
A13: 9 | B13: 09.05.2026 | D13: 0 | E13: 0 | F13: 8.225 | G13: 0 | H13: 0 | I13: 0 | J13: 0 | K13: 0 | L13: 0 | M13: 0 | N13: 0 | O13: 0 | P13: 0 | Q13: 0 | R13: 0 | S13: 0 | T13: 0
A14: 10 | B14: 10.05.2026 | D14: 0 | E14: 0 | F14: 8.225 | G14: 0 | H14: 0 | I14: 0 | J14: 0 | K14: 0 | L14: 0 | M14: 0 | N14: 0 | O14: 0 | P14: 0 | Q14: 0 | R14: 0 | S14: 0 | T14: 0
A15: 11 | B15: 11.05.2026 | D15: 0 | E15: 0 | F15: 8.225 | G15: 0 | H15: 0 | I15: 0 | J15: 0 | K15: 0 | L15: 0 | M15: 0 | N15: 0 | O15: 0 | P15: 0 | Q15: 0 | R15: 0 | S15: 0 | T15: 0
A16: 12 | B16: 12.05.2026 | D16: 0 | E16: 0 | F16: 8.225 | G16: 0 | H16: 0 | I16: 0 | J16: 0 | K16: 0 | L16: 0 | M16: 0 | N16: 0 | O16: 0 | P16: 0 | Q16: 0 | R16: 0 | S16: 0 | T16: 0
... A35: 31 | B35: 31.05.2026 | D35: 0 | E35: 0 | F35: 4.1 | G35: 0 | H35: 0 | I35: 0 | J35: 0 | K35: 0 | L35: 0 | M35: 0 | N35: 0 | O35: 0 | P35: 0 | Q35: 0 | R35: 0 | S35: 0 | T35: 0
D36: 0 | E36: 4.125 | F36: 184.85 | G36: 0 | H36: 0 | I36: 0 | J36: 0 | K36: 0 | L36: 0 | M36: 0 | N36: 861.61 | O36: 1676.33 | P36: 0 | Q36: 0 | R36: 0 | S36: 0 | T36: 2537.94
T37: 3096.29

Sheet Баумана Полимеры
A2: Отчет по хранению товара за Май 2026 Баумана Полимеры
A3: № | B3: дата | D3: Выгрузка кол-во | E3: Загрузка кол-во | F3: Хранение | G3: Резервирование 0 | H3: Мин. Суточный резерв 0 | I3: переконсолидация (тонн) | J3: Паллетирование | K3: Взвешивание | L3: стоимость взвешивания | M3: стоимость выгрузки за 1 месяц | N3: стоимость загрузки за 1 месяц | O3: стоимость хранения за 1 месяц | P3: Доплата за хранение за 1 месяц | Q3: Доплата за ПРР за 1 месяц | R3: стоимость переконс. | S3: Стоимость паллетирования | T3: итого
A5: 1 | B5: 01.05.2026 | D5: 110.5 | E5: 289 | F5: 6309.926 | G5: 0 | H5: 0 | I5: 0 | J5: 0 | K5: 0 | L5: 0 | M5: 0 | N5: 0 | O5: 0 | P5: 0 | Q5: 0 | R5: 0 | S5: 0 | T5: 0
A6: 2 | B6: 02.05.2026 | D6: 330.5 | E6: 151 | F6: 6489.426 | G6: 0 | H6: 0 | I6: 0 | J6: 0 | K6: 0 | L6: 0 | M6: 0 | N6: 0 | O6: 0 | P6: 0 | Q6: 0 | R6: 0 | S6: 0 | T6: 0
A7: 3 | B7: 03.05.2026 | D7: 287.5 | E7: 200.5 | F7: 6576.426 | G7: 0 | H7: 0 | I7: 0 | J7: 0 | K7: 0 | L7: 0 | M7: 0 | N7: 0 | O7: 0 | P7: 0 | Q7: 0 | R7: 0 | S7: 0 | T7: 0
A8: 4 | B8: 04.05.2026 | D8: 649.5 | E8: 201 | F8: 7024.926 | G8: 0 | H8: 0 | I8: 0 | J8: 0 | K8: 0 | L8: 0 | M8: 0 | N8: 0 | O8: 0 | P8: 0 | Q8: 0 | R8: 0 | S8: 0 | T8: 0
A9: 5 | B9: 05.05.2026 | D9: 445.5 | E9: 67 | F9: 7403.426 | G9: 0 | H9: 0 | I9: 1.375 | J9: 1.375 | K9: 0 | L9: 0 | M9: 0 | N9: 0 | O9: 0 | P9: 0 | Q9: 0 | R9: 343.75 | S9: 192.5 | T9: 536.25
A10: 6 | B10: 06.05.2026 | D10: 247 | E10: 120.625 | F10: 7529.801 | G10: 0 | H10: 0 | I10: 2.725 | J10: 2.725 | K10: 0 | L10: 0 | M10: 0 | N10: 0 | O10: 0 | P10: 0 | Q10: 0 | R10: 681.25 | S10: 381.5 | T10: 1062.75
A11: 7 | B11: 07.05.2026 | D11: 470 | E11: 194.375 | F11: 7805.426 | G11: 0 | H11: 0 | I11: 0 | J11: 0 | K11: 0 | L11: 0 | M11: 0 | N11: 0 | O11: 0 | P11: 0 | Q11: 0 | R11: 0 | S11: 0 | T11: 0
A12: 8 | B12: 08.05.2026 | D12: 379 | E12: 112.25 | F12: 8072.176 | G12: 0 | H12: 0 | I12: 0 | J12: 0 | K12: 0 | L12: 0 | M12: 0 | N12: 0 | O12: 0 | P12: 0 | Q12: 0 | R12: 0 | S12: 0 | T12: 0
A13: 9 | B13: 09.05.2026 | D13: 376 | E13: 22.35 | F13: 8425.826 | G13: 0 | H13: 0 | I13: 0 | J13: 0 | K13: 0 | L13: 0 | M13: 0 | N13: 0 | O13: 0 | P13: 0 | Q13: 0 | R13: 0 | S13: 0 | T13: 0
