Workbook

Sheet Лист1

Sheet Биаксплен Новосибирск
A1: =T37 -> 174135.18
A2: ="Отчет по хранению товара за " & TEXT(B5,"ММММ ГГГГ") -> Отчет по хранению товара за Март 2026
A3: № | B3: дата | D3: Выгрузка кол-во | E3: Загрузка кол-во | F3: Хранение | G3: Резервирование 70 т | H3: Мин. Суточный резерв 0 т | I3: переконсолидация (тонн) | J3: Паллетирование | K3: Ночная загруска выгрузка | L3: стоимость ночной загруски | M3: стоимость выгрузки | N3: стоимость загрузки | O3: стоимость хранения | P3: Стоимость резервирования | Q3: Стоимость мин.суточной бработки | R3: стоимость переконс. | S3: Стоимость паллетирования | T3: итого
A5: 1 | B5: 46082 | F5: =60.367+D5-E5 -> 60.367 | G5: =IF(OR(B5="",NOT(ISERROR(SEARCH("KPI",$A$2))),NOT(ISERROR(SEARCH("Полиом",$A$2)))),0,IF(70-F5<=0,0,70-F5)) -> 9.633 | L5: =SUM(K5*240) -> 0 | M5: =SUM(D5*120) -> 0 | N5: =SUM(E5*120) -> 0 | O5: =SUM(F5*54) -> 3259.818 | P5: =SUM(G5*54) -> 520.182 | Q5: =SUM(H5*120) -> 0 | R5: =SUM(I5*1000) -> 0 | S5: =SUM(J5*140) -> 0 | T5: =SUM(L5:S5) -> 3780
A6: 2 | B6: 46083 | E6: 1.5455 | F6: =F5-E6+D6 -> 58.8215 | G6: =IF(OR(B6="",NOT(ISERROR(SEARCH("KPI",$A$2))),NOT(ISERROR(SEARCH("Полиом",$A$2)))),0,IF(70-F6<=0,0,70-F6)) -> 11.1785 | L6: =SUM(K6*240) -> 0 | M6: =SUM(D6*120) -> 0 | N6: =SUM(E6*120) -> 185.46 | O6: =SUM(F6*54) -> 3176.361 | P6: =SUM(G6*54) -> 603.639 | Q6: =SUM(H6*120) -> 0 | R6: =SUM(I6*1000) -> 0 | S6: =SUM(J6*140) -> 0 | T6: =SUM(L6:S6) -> 3965.46
A7: 3 | B7: 46084 | D7: 36.0673 | F7: =F6-E7+D7 -> 94.8888 | G7: =IF(OR(B7="",NOT(ISERROR(SEARCH("KPI",$A$2))),NOT(ISERROR(SEARCH("Полиом",$A$2)))),0,IF(70-F7<=0,0,70-F7)) -> 0 | L7: =SUM(K7*240) -> 0 | M7: =SUM(D7*120) -> 4328.076 | N7: =SUM(E7*120) -> 0 | O7: =SUM(F7*54) -> 5123.9952 | P7: =SUM(G7*54) -> 0 | Q7: =SUM(H7*120) -> 0 | R7: =SUM(I7*1000) -> 0 | S7: =SUM(J7*140) -> 0 | T7: =SUM(L7:S7) -> 9452.0712
A8: 4 | B8: 46085 | F8: =F7-E8+D8 -> 94.8888 | G8: =IF(OR(B8="",NOT(ISERROR(SEARCH("KPI",$A$2))),NOT(ISERROR(SEARCH("Полиом",$A$2)))),0,IF(70-F8<=0,0,70-F8)) -> 0 | L8: =SUM(K8*240) -> 0 | M8: =SUM(D8*120) -> 0 | N8: =SUM(E8*120) -> 0 | O8: =SUM(F8*54) -> 5123.9952 | P8: =SUM(G8*54) -> 0 | Q8: =SUM(H8*120) -> 0 | R8: =SUM(I8*1000) -> 0 | S8: =SUM(J8*140) -> 0 | T8: =SUM(L8:S8) -> 5123.9952
A9: 5 | B9: 46086 | E9: 2.0196 | F9: =F8-E9+D9 -> 92.8692 | G9: =IF(OR(B9="",NOT(ISERROR(SEARCH("KPI",$A$2))),NOT(ISERROR(SEARCH("Полиом",$A$2)))),0,IF(70-F9<=0,0,70-F9)) -> 0 | L9: =SUM(K9*240) -> 0 | M9: =SUM(D9*120) -> 0 | N9: =SUM(E9*120) -> 242.352 | O9: =SUM(F9*54) -> 5014.9368 | P9: =SUM(G9*54) -> 0 | Q9: =SUM(H9*120) -> 0 | R9: =SUM(I9*1000) -> 0 | S9: =SUM(J9*140) -> 0 | T9: =SUM(L9:S9) -> 5257.2888
A10: 6 | B10: 46087 | E10: 8.3232 | F10: =F9-E10+D10 -> 84.546 | G10: =IF(OR(B10="",NOT(ISERROR(SEARCH("KPI",$A$2))),NOT(ISERROR(SEARCH("Полиом",$A$2)))),0,IF(70-F10<=0,0,70-F10)) -> 0 | L10: =SUM(K10*240) -> 0 | M10: =SUM(D10*120) -> 0 | N10: =SUM(E10*120) -> 998.784 | O10: =SUM(F10*54) -> 4565.484 | P10: =SUM(G10*54) -> 0 | Q10: =SUM(H10*120) -> 0 | R10: =SUM(I10*1000) -> 0 | S10: =SUM(J10*140) -> 0 | T10: =SUM(L10:S10) -> 5564.268
A11: 7 | B11: 46088 | F11: =F10-E11+D11 -> 84.546 | G11: =IF(OR(B11="",NOT(ISERROR(SEARCH("KPI",$A$2))),NOT(ISERROR(SEARCH("Полиом",$A$2)))),0,IF(70-F11<=0,0,70-F11)) -> 0 | L11: =SUM(K11*240) -> 0 | M11: =SUM(D11*120) -> 0 | N11: =SUM(E11*120) -> 0 | O11: =SUM(F11*54) -> 4565.484 | P11: =SUM(G11*54) -> 0 | Q11: =SUM(H11*120) -> 0 | R11: =SUM(I11*1000) -> 0 | S11: =SUM(J11*140) -> 0 | T11: =SUM(L11:S11) -> 4565.484
A12: 8 | B12: 46089 | F12: =F11-E12+D12 -> 84.546 | G12: =IF(OR(B12="",NOT(ISERROR(SEARCH("KPI",$A$2))),NOT(ISERROR(SEARCH("Полиом",$A$2)))),0,IF(70-F12<=0,0,70-F12)) -> 0 | L12: =SUM(K12*240) -> 0 | M12: =SUM(D12*120) -> 0 | N12: =SUM(E12*120) -> 0 | O12: =SUM(F12*54) -> 4565.484 | P12: =SUM(G12*54) -> 0 | Q12: =SUM(H12*120) -> 0 | R12: =SUM(I12*1000) -> 0 | S12: =SUM(J12*140) -> 0 | T12: =SUM(L12:S12) -> 4565.484
A13: 9 | B13: 46090 | F13: =F12-E13+D13 -> 84.546 | G13: =IF(OR(B13="",NOT(ISERROR(SEARCH("KPI",$A$2))),NOT(ISERROR(SEARCH("Полиом",$A$2)))),0,IF(70-F13<=0,0,70-F13)) -> 0 | L13: =SUM(K13*240) -> 0 | M13: =SUM(D13*120) -> 0 | N13: =SUM(E13*120) -> 0 | O13: =SUM(F13*54) -> 4565.484 | P13: =SUM(G13*54) -> 0 | Q13: =SUM(H13*120) -> 0 | R13: =SUM(I13*1000) -> 0 | S13: =SUM(J13*140) -> 0 | T13: =SUM(L13:S13) -> 4565.484
A14: 10 | B14: 46091 | F14: =F13-E14+D14 -> 84.546 | G14: =IF(OR(B14="",NOT(ISERROR(SEARCH("KPI",$A$2))),NOT(ISERROR(SEARCH("Полиом",$A$2)))),0,IF(70-F14<=0,0,70-F14)) -> 0 | L14: =SUM(K14*240) -> 0 | M14: =SUM(D14*120) -> 0 | N14: =SUM(E14*120) -> 0 | O14: =SUM(F14*54) -> 4565.484 | P14: =SUM(G14*54) -> 0 | Q14: =SUM(H14*120) -> 0 | R14: =SUM(I14*1000) -> 0 | S14: =SUM(J14*140) -> 0 | T14: =SUM(L14:S14) -> 4565.484
A15: 11 | B15: 46092 | E15: 11.5747 | F15: =F14-E15+D15 -> 72.9713 | G15: =IF(OR(B15="",NOT(ISERROR(SEARCH("KPI",$A$2))),NOT(ISERROR(SEARCH("Полиом",$A$2)))),0,IF(70-F15<=0,0,70-F15)) -> 0 | L15: =SUM(K15*240) -> 0 | M15: =SUM(D15*120) -> 0 | N15: =SUM(E15*120) -> 1388.964 | O15: =SUM(F15*54) -> 3940.4502 | P15: =SUM(G15*54) -> 0 | Q15: =SUM(H15*120) -> 0 | R15: =SUM(I15*1000) -> 0 | S15: =SUM(J15*140) -> 0 | T15: =SUM(L15:S15) -> 5329.4142
A16: 12 | B16: 46093 | F16: =F15-E16+D16 -> 72.9713 | G16: =IF(OR(B16="",NOT(ISERROR(SEARCH("KPI",$A$2))),NOT(ISERROR(SEARCH("Полиом",$A$2)))),0,IF(70-F16<=0,0,70-F16)) -> 0 | L16: =SUM(K16*240) -> 0 | M16: =SUM(D16*120) -> 0 | N16: =SUM(E16*120) -> 0 | O16: =SUM(F16*54) -> 3940.4502 | P16: =SUM(G16*54) -> 0 | Q16: =SUM(H16*120) -> 0 | R16: =SUM(I16*1000) -> 0 | S16: =SUM(J16*140) -> 0 | T16: =SUM(L16:S16) -> 3940.4502
A17: 13 | B17: 46094 | E17: 35.9265 | F17: =F16-E17+D17 -> 37.0448 | G17: =IF(OR(B17="",NOT(ISERROR(SEARCH("KPI",$A$2))),NOT(ISERROR(SEARCH("Полиом",$A$2)))),0,IF(70-F17<=0,0,70-F17)) -> 32.9552 | L17: =SUM(K17*240) -> 0 | M17: =SUM(D17*120) -> 0 | N17: =SUM(E17*120) -> 4311.18 | O17: =SUM(F17*54) -> 2000.4192 | P17: =SUM(G17*54) -> 1779.5808 | Q17: =SUM(H17*120) -> 0 | R17: =SUM(I17*1000) -> 0 | S17: =SUM(J17*140) -> 0 | T17: =SUM(L17:S17) -> 8091.18
A18: 14 | B18: 46095 | F18: =F17-E18+D18 -> 37.0448 | G18: =IF(OR(B18="",NOT(ISERROR(SEARCH("KPI",$A$2))),NOT(ISERROR(SEARCH("Полиом",$A$2)))),0,IF(70-F18<=0,0,70-F18)) -> 32.9552 | L18: =SUM(K18*240) -> 0 | M18: =SUM(D18*120) -> 0 | N18: =SUM(E18*120) -> 0 | O18: =SUM(F18*54) -> 2000.4192 | P18: =SUM(G18*54) -> 1779.5808 | Q18: =SUM(H18*120) -> 0 | R18: =SUM(I18*1000) -> 0 | S18: =SUM(J18*140) -> 0 | T18: =SUM(L18:S18) -> 3780
A19: 15 | B19: 46096 | F19: =F18-E19+D19 -> 37.0448 | G19: =IF(OR(B19="",NOT(ISERROR(SEARCH("KPI",$A$2))),NOT(ISERROR(SEARCH("Полиом",$A$2)))),0,IF(70-F19<=0,0,70-F19)) -> 32.9552 | L19: =SUM(K19*240) -> 0 | M19: =SUM(D19*120) -> 0 | N19: =SUM(E19*120) -> 0 | O19: =SUM(F19*54) -> 2000.4192 | P19: =SUM(G19*54) -> 1779.5808 | Q19: =SUM(H19*120) -> 0 | R19: =SUM(I19*1000) -> 0 | S19: =SUM(J19*140) -> 0 | T19: =SUM(L19:S19) -> 3780
A20: 16 | B20: 46097 | F20: =F19-E20+D20 -> 37.0448 | G20: =IF(OR(B20="",NOT(ISERROR(SEARCH("KPI",$A$2))),NOT(ISERROR(SEARCH("Полиом",$A$2)))),0,IF(70-F20<=0,0,70-F20)) -> 32.9552 | L20: =SUM(K20*240) -> 0 | M20: =SUM(D20*120) -> 0 | N20: =SUM(E20*120) -> 0 | O20: =SUM(F20*54) -> 2000.4192 | P20: =SUM(G20*54) -> 1779.5808 | Q20: =SUM(H20*120) -> 0 | R20: =SUM(I20*1000) -> 0 | S20: =SUM(J20*140) -> 0 | T20: =SUM(L20:S20) -> 3780
A21: 17 | B21: 46098 | E21: 0.9532 | F21: =F20-E21+D21 -> 36.0916 | G21: =IF(OR(B21="",NOT(ISERROR(SEARCH("KPI",$A$2))),NOT(ISERROR(SEARCH("Полиом",$A$2)))),0,IF(70-F21<=0,0,70-F21)) -> 33.9084 | L21: =SUM(K21*240) -> 0 | M21: =SUM(D21*120) -> 0 | N21: =SUM(E21*120) -> 114.384 | O21: =SUM(F21*54) -> 1948.9464 | P21: =SUM(G21*54) -> 1831.0536 | Q21: =SUM(H21*120) -> 0 | R21: =SUM(I21*1000) -> 0 | S21: =SUM(J21*140) -> 0 | T21: =SUM(L21:S21) -> 3894.384
A22: 18 | B22: 46099 | E22: 3.3398 | F22: =F21-E22+D22 -> 32.7518 | G22: =IF(OR(B22="",NOT(ISERROR(SEARCH("KPI",$A$2))),NOT(ISERROR(SEARCH("Полиом",$A$2)))),0,IF(70-F22<=0,0,70-F22)) -> 37.2482 | L22: =SUM(K22*240) -> 0 | M22: =SUM(D22*120) -> 0 | N22: =SUM(E22*120) -> 400.776 | O22: =SUM(F22*54) -> 1768.5972 | P22: =SUM(G22*54) -> 2011.4028 | Q22: =SUM(H22*120) -> 0 | R22: =SUM(I22*1000) -> 0 | S22: =SUM(J22*140) -> 0 | T22: =SUM(L22:S22) -> 4180.776
A23: 19 | B23: 46100 | F23: =F22-E23+D23 -> 32.7518 | G23: =IF(OR(B23="",NOT(ISERROR(SEARCH("KPI",$A$2))),NOT(ISERROR(SEARCH("Полиом",$A$2)))),0,IF(70-F23<=0,0,70-F23)) -> 37.2482 | L23: =SUM(K23*240) -> 0 | M23: =SUM(D23*120) -> 0 | N23: =SUM(E23*120) -> 0 | O23: =SUM(F23*54) -> 1768.5972 | P23: =SUM(G23*54) -> 2011.4028 | Q23: =SUM(H23*120) -> 0 | R23: =SUM(I23*1000) -> 0 | S23: =SUM(J23*140) -> 0 | T23: =SUM(L23:S23) -> 3780
A24: 20 | B24: 46101 | F24: =F23-E24+D24 -> 32.7518 | G24: =IF(OR(B24="",NOT(ISERROR(SEARCH("KPI",$A$2))),NOT(ISERROR(SEARCH("Полиом",$A$2)))),0,IF(70-F24<=0,0,70-F24)) -> 37.2482 | L24: =SUM(K24*240) -> 0 | M24: =SUM(D24*120) -> 0 | N24: =SUM(E24*120) -> 0 | O24: =SUM(F24*54) -> 1768.5972 | P24: =SUM(G24*54) -> 2011.4028 | Q24: =SUM(H24*120) -> 0 | R24: =SUM(I24*1000) -> 0 | S24: =SUM(J24*140) -> 0 | T24: =SUM(L24:S24) -> 3780
A25: 21 | B25: 46102 | F25: =F24-E25+D25 -> 32.7518 | G25: =IF(OR(B25="",NOT(ISERROR(SEARCH("KPI",$A$2))),NOT(ISERROR(SEARCH("Полиом",$A$2)))),0,IF(70-F25<=0,0,70-F25)) -> 37.2482 | L25: =SUM(K25*240) -> 0 | M25: =SUM(D25*120) -> 0 | N25: =SUM(E25*120) -> 0 | O25: =SUM(F25*54) -> 1768.5972 | P25: =SUM(G25*54) -> 2011.4028 | Q25: =SUM(H25*120) -> 0 | R25: =SUM(I25*1000) -> 0 | S25: =SUM(J25*140) -> 0 | T25: =SUM(L25:S25) -> 3780
A26: 22 | B26: 46103 | F26: =F25-E26+D26 -> 32.7518 | G26: =IF(OR(B26="",NOT(ISERROR(SEARCH("KPI",$A$2))),NOT(ISERROR(SEARCH("Полиом",$A$2)))),0,IF(70-F26<=0,0,70-F26)) -> 37.2482 | L26: =SUM(K26*240) -> 0 | M26: =SUM(D26*120) -> 0 | N26: =SUM(E26*120) -> 0 | O26: =SUM(F26*54) -> 1768.5972 | P26: =SUM(G26*54) -> 2011.4028 | Q26: =SUM(H26*120) -> 0 | R26: =SUM(I26*1000) -> 0 | S26: =SUM(J26*140) -> 0 | T26: =SUM(L26:S26) -> 3780
A27: 23 | B27: 46104 | F27: =F26-E27+D27 -> 32.7518 | G27: =IF(OR(B27="",NOT(ISERROR(SEARCH("KPI",$A$2))),NOT(ISERROR(SEARCH("Полиом",$A$2)))),0,IF(70-F27<=0,0,70-F27)) -> 37.2482 | L27: =SUM(K27*240) -> 0 | M27: =SUM(D27*120) -> 0 | N27: =SUM(E27*120) -> 0 | O27: =SUM(F27*54) -> 1768.5972 | P27: =SUM(G27*54) -> 2011.4028 | Q27: =SUM(H27*120) -> 0 | R27: =SUM(I27*1000) -> 0 | S27: =SUM(J27*140) -> 0 | T27: =SUM(L27:S27) -> 3780
A28: 24 | B28: 46105 | F28: =F27-E28+D28 -> 32.7518 | G28: =IF(OR(B28="",NOT(ISERROR(SEARCH("KPI",$A$2))),NOT(ISERROR(SEARCH("Полиом",$A$2)))),0,IF(70-F28<=0,0,70-F28)) -> 37.2482 | L28: =SUM(K28*240) -> 0 | M28: =SUM(D28*120) -> 0 | N28: =SUM(E28*120) -> 0 | O28: =SUM(F28*54) -> 1768.5972 | P28: =SUM(G28*54) -> 2011.4028 | Q28: =SUM(H28*120) -> 0 | R28: =SUM(I28*1000) -> 0 | S28: =SUM(J28*140) -> 0 | T28: =SUM(L28:S28) -> 3780
A29: 25 | B29: 46106 | D29: 18.424 | E29: 17.1158 | F29: =F28-E29+D29 -> 34.06 | G29: =IF(OR(B29="",NOT(ISERROR(SEARCH("KPI",$A$2))),NOT(ISERROR(SEARCH("Полиом",$A$2)))),0,IF(70-F29<=0,0,70-F29)) -> 35.94 | L29: =SUM(K29*240) -> 0 | M29: =SUM(D29*120) -> 2210.88 | N29: =SUM(E29*120) -> 2053.896 | O29: =SUM(F29*54) -> 1839.24 | P29: =SUM(G29*54) -> 1940.76 | Q29: =SUM(H29*120) -> 0 | R29: =SUM(I29*1000) -> 0 | S29: =SUM(J29*140) -> 0 | T29: =SUM(L29:S29) -> 8044.776
A30: 26 | B30: 46107 | E30: 1.6043 | F30: =F29-E30+D30 -> 32.4557 | G30: =IF(OR(B30="",NOT(ISERROR(SEARCH("KPI",$A$2))),NOT(ISERROR(SEARCH("Полиом",$A$2)))),0,IF(70-F30<=0,0,70-F30)) -> 37.5443 | L30: =SUM(K30*240) -> 0 | M30: =SUM(D30*120) -> 0 | N30: =SUM(E30*120) -> 192.516 | O30: =SUM(F30*54) -> 1752.6078 | P30: =SUM(G30*54) -> 2027.3922 | Q30: =SUM(H30*120) -> 0 | R30: =SUM(I30*1000) -> 0 | S30: =SUM(J30*140) -> 0 | T30: =SUM(L30:S30) -> 3972.516
A31: 27 | B31: 46108 | F31: =F30-E31+D31 -> 32.4557 | G31: =IF(OR(B31="",NOT(ISERROR(SEARCH("KPI",$A$2))),NOT(ISERROR(SEARCH("Полиом",$A$2)))),0,IF(70-F31<=0,0,70-F31)) -> 37.5443 | L31: =SUM(K31*240) -> 0 | M31: =SUM(D31*120) -> 0 | N31: =SUM(E31*120) -> 0 | O31: =SUM(F31*54) -> 1752.6078 | P31: =SUM(G31*54) -> 2027.3922 | Q31: =SUM(H31*120) -> 0 | R31: =SUM(I31*1000) -> 0 | S31: =SUM(J31*140) -> 0 | T31: =SUM(L31:S31) -> 3780
A32: 28 | B32: 46109 | F32: =F31-E32+D32 -> 32.4557 | G32: =IF(OR(B32="",NOT(ISERROR(SEARCH("KPI",$A$2))),NOT(ISERROR(SEARCH("Полиом",$A$2)))),0,IF(70-F32<=0,0,70-F32)) -> 37.5443 | L32: =SUM(K32*240) -> 0 | M32: =SUM(D32*120) -> 0 | N32: =SUM(E32*120) -> 0 | O32: =SUM(F32*54) -> 1752.6078 | P32: =SUM(G32*54) -> 2027.3922 | Q32: =SUM(H32*120) -> 0 | R32: =SUM(I32*1000) -> 0 | S32: =SUM(J32*140) -> 0 | T32: =SUM(L32:S32) -> 3780
A33: 29 | B33: 46110 | F33: =F32-E33+D33 -> 32.4557 | G33: =IF(OR(B33="",NOT(ISERROR(SEARCH("KPI",$A$2))),NOT(ISERROR(SEARCH("Полиом",$A$2)))),0,IF(70-F33<=0,0,70-F33)) -> 37.5443 | L33: =SUM(K33*240) -> 0 | M33: =SUM(D33*120) -> 0 | N33: =SUM(E33*120) -> 0 | O33: =SUM(F33*54) -> 1752.6078 | P33: =SUM(G33*54) -> 2027.3922 | Q33: =SUM(H33*120) -> 0 | R33: =SUM(I33*1000) -> 0 | S33: =SUM(J33*140) -> 0 | T33: =SUM(L33:S33) -> 3780
A34: 30 | B34: 46111 | F34: =F33-E34+D34 -> 32.4557 | G34: =IF(OR(B34="",NOT(ISERROR(SEARCH("KPI",$A$2))),NOT(ISERROR(SEARCH("Полиом",$A$2)))),0,IF(70-F34<=0,0,70-F34)) -> 37.5443 | L34: =SUM(K34*240) -> 0 | M34: =SUM(D34*120) -> 0 | N34: =SUM(E34*120) -> 0 | O34: =SUM(F34*54) -> 1752.6078 | P34: =SUM(G34*54) -> 2027.3922 | Q34: =SUM(H34*120) -> 0 | R34: =SUM(I34*1000) -> 0 | S34: =SUM(J34*140) -> 0 | T34: =SUM(L34:S34) -> 3780
B35: 46112 | E35: 7.9603 | F35: =F34-E35+D35 -> 24.4954 | G35: =IF(OR(B35="",NOT(ISERROR(SEARCH("KPI",$A$2))),NOT(ISERROR(SEARCH("Полиом",$A$2)))),0,IF(70-F35<=0,0,70-F35)) -> 45.5046 | L35: =SUM(K35*240) -> 0 | M35: =SUM(D35*120) -> 0 | N35: =SUM(E35*120) -> 955.236 | O35: =SUM(F35*54) -> 1322.7516 | P35: =SUM(G35*54) -> 2457.2484 | Q35: =SUM(H35*120) -> 0 | R35: =SUM(I35*1000) -> 0 | S35: =SUM(J35*140) -> 0 | T35: =SUM(L35:S35) -> 4735.236
F36: =SUM(F5:F35) -> 1604.8752 | G36: =SUM(G5:G35) -> 716.4442 | H36: =SUM(H5:H35) -> 0 | I36: =SUM(I5:I35) -> 0 | J36: =SUM(J5:J35) -> 0 | K36: =SUM(K5:K35) -> 0 | L36: =SUM(L5:L35) -> 0 | M36: =SUM(M5:M35) -> 6538.956 | ... T36: =SUM(T5:T35) -> 142733.75
T37: =T36*1.22 -> 174135.18

Sheet ИТОГО
A1: =G16 -> 1.4344448e+08
I2: ТОП
A3: Склад | B3: Сибур | C3: Завод | D3: Русвинил | E3: Клиенты сибура | F3: Остальные | G3: Итого | I3: Казань_Автосервисная | J3: 23143268
A4: Баумана | B4: =INDEX($M$45:$M$54,MATCH(A4,$A$45:$A$54,0),1) -> 7162539.1 | C4: 0 | D4: =INDEX($B$57:$B$73,MATCH(A4,$A$57:$A$73,0),1) -> 256416.4 | E4: =SUMIF($F$19:$F$42,A4,$G$19:$G$42) -> 0 | F4: =SUMIF($B$19:$B$27,A4,$C$19:$C$27) -> 86846 | G4: =SUM(B4:F4) -> 7505801.5 | I4: Нижнекамск завод | J4: 19482962
A5: Новикова-Прибоя | B5: =INDEX($M$45:$M$54,MATCH(A5,$A$45:$A$54,0),1) -> 10572038 | C5: 0 | D5: =INDEX($B$57:$B$73,MATCH(A5,$A$57:$A$73,0),1) -> 209215.3 | E5: =SUMIF($F$19:$F$42,A5,$G$19:$G$42) -> 0 | F5: =SUMIF($B$19:$B$27,A5,$C$19:$C$27) -> 0 | G5: =SUM(B5:F5) -> 10781253 | I5: Новикова-Прибоя | J5: 14483152
A6: Екатеринбург | B6: =INDEX($M$45:$M$54,MATCH(A6,$A$45:$A$54,0),1) -> 11739684 | C6: 0 | D6: =INDEX($B$57:$B$73,MATCH(A6,$A$57:$A$73,0),1) -> 0 | E6: =SUMIF($F$19:$F$42,A6,$G$19:$G$42) -> 0 | F6: =SUMIF($B$19:$B$27,A6,$C$19:$C$27) -> 0 | G6: =SUM(B6:F6) -> 11739684 | I6: Екатеринбург | J6: 11908609
A7: Новосибирск | B7: =INDEX($M$45:$M$54,MATCH(A7,$A$45:$A$54,0),1) -> 6609793.6 | C7: 0 | D7: =INDEX($B$57:$B$73,MATCH(A7,$A$57:$A$73,0),1) -> 0 | E7: =SUMIF($F$19:$F$42,A7,$G$19:$G$42) -> 174135.18 | F7: =SUMIF($B$19:$B$27,A7,$C$19:$C$27) -> 0 | G7: =SUM(B7:F7) -> 6783928.8 | I7: Баумана | J7: 11544503
A8: Новосибирск_Пасечная | B8: =INDEX($M$45:$M$54,MATCH(A8,$A$45:$A$54,0),1) -> 5803487.8 | C8: 0 | D8: =INDEX($B$57:$B$73,MATCH(A8,$A$57:$A$73,0),1) -> 0 | E8: =SUMIF($F$19:$F$42,A8,$G$19:$G$42) -> 0 | F8: =SUMIF($B$19:$B$27,A8,$C$19:$C$27) -> 0 | G8: =SUM(B8:F8) -> 5803487.8
A9: Казань_Автосервисная | B9: =INDEX($M$45:$M$54,MATCH(A9,$A$45:$A$54,0),1) -> 18498167 | C9: 0 | D9: =INDEX($B$57:$B$73,MATCH(A9,$A$57:$A$73,0),1) -> 0 | E9: =SUMIF($F$19:$F$42,A9,$G$19:$G$42) -> 0 | F9: =SUMIF($B$19:$B$27,A9,$C$19:$C$27) -> 0 | G9: =SUM(B9:F9) -> 18498167 | I9: Казань_Приволжская | J9: 9900926.9
A10: Казань_Приволжская | B10: =INDEX($M$45:$M$54,MATCH(A10,$A$45:$A$54,0),1) -> 9660016.4 | C10: 0 | D10: =INDEX($B$57:$B$73,MATCH(A10,$A$57:$A$73,0),1) -> 0 | E10: =SUMIF($F$19:$F$42,A10,$G$19:$G$42) -> 0 | F10: =SUMIF($B$19:$B$27,A10,$C$19:$C$27) -> 0 | G10: =SUM(B10:F10) -> 9660016.4 | I10: Зеленодольск | J10: 9082789.1
A11: Зеленодольск | B11: =INDEX($M$45:$M$54,MATCH(A11,$A$45:$A$54,0),1) -> 9122230.7 | C11: 0 | D11: =INDEX($B$57:$B$73,MATCH(A11,$A$57:$A$73,0),1) -> 0 | E11: =SUMIF($F$19:$F$42,A11,$G$19:$G$42) -> 0 | F11: =SUMIF($B$19:$B$27,A11,$C$19:$C$27) -> 0 | G11: =SUM(B11:F11) -> 9122230.7 | I11: Новосибирск | J11: 7932975.6
A12: Нижнекамск | B12: =INDEX($M$45:$M$54,MATCH(A12,$A$45:$A$54,0),1) -> 3200195.9 | C12: 0 | D12: =INDEX($B$57:$B$73,MATCH(A12,$A$57:$A$73,0),1) -> 0 | E12: =SUMIF($F$19:$F$42,A12,$G$19:$G$42) -> 1747.284 | F12: =SUMIF($B$19:$B$27,A12,$C$19:$C$27) -> 0 | G12: =SUM(B12:F12) -> 3201943.2 | I12: Нижнекамск | J12: 7580244.6
A13: Нижнекамск завод | B13: 0 | C13: =C29+C37 -> 54670761 | D13: =INDEX($B$57:$B$73,MATCH(A13,$A$57:$A$73,0),1) -> 0 | E13: =SUMIF($F$19:$F$42,A13,$G$19:$G$42) -> 0 | F13: =SUMIF($B$19:$B$27,A13,$C$19:$C$27) -> 0 | G13: =SUM(B13:F13) -> 54670761 | I13: ГАЗ | J13: 6720000
A14: Монастырка | B14: 0 | C14: 0 | D14: =INDEX($B$57:$B$73,MATCH(A14,$A$57:$A$73,0),1) -> 0 | E14: =SUMIF($F$19:$F$42,A14,$G$19:$G$42) -> 0 | F14: =SUMIF($B$19:$B$27,A14,$C$19:$C$27) -> 0 | G14: =SUM(B14:F14) -> 0 | I14: Монастырка | J14: 2464921.6
A15: Березовая Пойма | B15: =INDEX($M$45:$M$54,MATCH(A15,$A$45:$A$54,0),1) -> 0 | C15: 0 | D15: =INDEX($B$57:$B$73,MATCH(A15,$A$57:$A$73,0),1) -> 5677203.9 | E15: =SUMIF($F$19:$F$42,A15,$G$19:$G$42) -> 0 | F15: =SUMIF($B$19:$B$27,A15,$C$19:$C$27) -> 0 | G15: =SUM(B15:F15) -> 5677203.9
B16: =SUM(B4:B15) -> 82368153 | C16: =SUM(C4:C15) -> 54670761 | D16: =SUM(D4:D15) -> 6142835.6 | E16: =SUM(E4:E15) -> 175882.46 | F16: =SUM(F4:F15) -> 86846 | G16: =SUM(G4:G15) -> 1.4344448e+08
A18: Остальные клиенты | C18: =SUM(C19:C27) -> 86846 | E18: Клиенты сибура | G18: =SUM(G19:G41) -> 175882.46
A19: Стройтех | B19: Баумана | C19: {=IFERROR(INDIRECT("'" & A19 & "'!A1"),)} -> 24355 | E19: Приоритет | F19: Баумана | G19: {=IFERROR(INDIRECT("'" & E19 & " " & F19 & "'!A1"),0)} -> 0
A20: Ергарда | B20: Баумана | C20: {=IFERROR(INDIRECT("'" & A20 & "'!A1"),)} -> 8928 | E20: Фармпласт | F20: Баумана | G20: {=IFERROR(INDIRECT("'" & E20 & " " & F20 & "'!A1"),0)} -> 0
A21: Литейные решения | B21: Баумана | C21: {=IFERROR(INDIRECT("'" & A21 & "'!A1"),)} -> 20803 | E21: Юг Полимер | F21: Баумана | G21: {=IFERROR(INDIRECT("'" & E21 & " " & F21 & "'!A1"),0)} -> 0
A22: Сандекс | B22: Баумана | C22: {=IFERROR(INDIRECT("'" & A22 & "'!A1"),)} -> 24151.2 | E22: Центрополимер | F22: Екатеринбург | G22: {=IFERROR(INDIRECT("'" & E22 & " " & F22 & "'!A1"),0)} -> 0
A23: ЛС-Техномет | B23: Баумана | C23: {=IFERROR(INDIRECT("'" & A23 & "'!A1"),)} -> 8608.8 | E23: Приоритет | F23: Екатеринбург | G23: {=IFERROR(INDIRECT("'" & E23 & " " & F23 & "'!A1"),0)} -> 0
A24: РусДжам | B24: ГАЗ | C24: {=IFERROR(INDIRECT("'" & A24 & "'!A1"),)} -> 0 | E24: Фармпласт | F24: Екатеринбург | G24: {=IFERROR(INDIRECT("'" & E24 & " " & F24 & "'!A1"),0)} -> 0
A25: Виго | B25: Новикова-Прибоя | C25: {=IFERROR(INDIRECT("'" & A25 & "'!A1"),)} -> 0 | E25: Приоритет | F25: Зеленодольск | G25: {=IFERROR(INDIRECT("'" & E25 & " " & F25 & "'!A1"),0)} -> 0
A26: Доктор Франк | B26: Новикова-Прибоя | C26: {=IFERROR(INDIRECT("'" & A26 & "'!A1"),)} -> 0 | E26: Данафлекс | F26: Зеленодольск | G26: {=IFERROR(INDIRECT("'" & E26 & " " & F26 & "'!t37"),0)} -> 0
A27: Нефтезол | B27: Новикова-Прибоя | C27: {=IFERROR(INDIRECT("'" & A27 & "'!A1"),)} -> 0 | E27: ИП Ксендз | F27: Нижнекамск | G27: {=IFERROR(INDIRECT("'" & E27 & " " & F27 & "'!A1"),0)} -> 0
E28: Фармпласт | F28: Новикова-Прибоя | G28: {=IFERROR(INDIRECT("'" & E28 & " " & F28 & "'!A1"),0)} -> 0
A29: Нижнекамск завод | C29: =SUM(C30:C35) -> 44695725 | E29: Центрополимер | F29: Новикова-Прибоя | G29: {=IFERROR(INDIRECT("'" & E29 & " " & F29 & "'!A1"),0)} -> 0
A30: ПРР | C30: {=INDIRECT("'" & A29 & "'!F17")} -> 16167490 | E30: Юг Полимер | F30: Новикова-Прибоя | G30: {=IFERROR(INDIRECT("'" & E30 & " " & F30 & "'!A1"),0)} -> 0
A31: Кладовки | C31: {=INDIRECT("'" & A29 & "'!F16")} -> 0 | E31: Приоритет | F31: Новикова-Прибоя | G31: {=IFERROR(INDIRECT("'" & E31 & " " & F31 & "'!A1"),0)} -> 0
A32: Стропальщики | C32: {=INDIRECT("'" & A29 & "'!F18")} -> 817400 | E32: Биаксплен | F32: Новосибирск | G32: {=IFERROR(INDIRECT("'" & E32 & " " & F32 & "'!A1"),0)} -> 174135.18
A33: Мойка контейнеров | C33: {=INDIRECT("'" & A29 & "'!F19")} -> 2020076 | E33: Центрополимер | F33: Новосибирск | G33: {=IFERROR(INDIRECT("'" & E33 & " " & F33 & "'!A1"),0)} -> 0
A34: МТО | C34: {=INDIRECT("'" & A29 & "'!F20")} -> 18710159 | E34: Фармпласт | F34: Новосибирск | G34: {=IFERROR(INDIRECT("'" & E34 & " " & F34 & "'!A1"),0)} -> 0
A35: МТО 2520 | C35: {=INDIRECT("'" & A29 & "'!F21")} -> 6980600
E36: Юг Полимер | F36: Зеленодольск | G36: {=IFERROR(INDIRECT("'" & E36 & " " & F36 & "'!A1"),0)} -> 0
A37: Контейнерные площадки | C37: =SUM(C38:C42) -> 9975036 | E37: Фармпласт | F37: Казань_Автосервисная | G37: {=IFERROR(INDIRECT("'" & E37 & " " & F37 & "'!A1"),0)} -> 0
A38: КОС | C38: =2910816 -> 2910816 | E38: Приоритет | F38: Казань_Приволжская | G38: {=IFERROR(INDIRECT("'" & E38 & " " & F38 & "'!A1"),0)} -> 0
A39: Нижнекамск | C39: 7064220 | E39: Центрополимер | F39: Баумана | G39: {=IFERROR(INDIRECT("'" & E39 & " " & F39 & "'!A1"),0)} -> 0
E40: Приоритет | F40: Казань_Автосервисная | G40: {=IFERROR(INDIRECT("'" & E40 & " " & F40 & "'!A1"),0)} -> 0
E41: Оникс | F41: Нижнекамск | G41: {=IFERROR(INDIRECT("'" & E41 & " " & F41 & "'!A1"),0)} -> 1747.284
...

Sheet Другое

Sheet Нижнекамск завод
A9: № | B9: Наименование услуг (работ) | C9: Ед. изм. | D9: Количество | E9: Цена | F9: Сумма
A14: Итого: | F14: =SUM(F10:F13) -> 0
A15: Без налога (НДС) | F15: =SUM(F14) -> 0
A16: Всего (с учетом НДС) | F16: =SUM(F15)*1.2 -> 0
A17: Вышеперечисленные услуги (работы) выполнены полностью. | E17: ПРР | F17: 16167490
A18: ПОКЛАЖЕДАТЕЛЬ претензий по объему, качеству и срокам оказания услуг претензий не имеет. | E18: Стропальщики | F18: 817400
E19: Контейнеры | F19: 2020076
E20: МТО | F20: =18518570+191589 -> 18710159
E21: МТО 2520 | F21: 6980600
A22: ООО "ДТМ" | D22: ПАО "Нижнекамскнефтехим"
A24: ____________________Молькова Т.Ю. | B24: Расстегаев Д.О. | D24: ____________________

Sheet Сводка
A1: KPI | B1: Баумана | C1: =INDEX(INDIRECT("ИТОГО!$B$45:$L$54"),MATCH(Сводка!B1,INDIRECT("ИТОГО!$A$45:$A$54"),0),MATCH(Сводка!A1,INDIRECT("ИТОГО!$B$44:$L$44"),0)) -> 9054.69
A2: Полиом | B2: Баумана | C2: =INDEX(INDIRECT("ИТОГО!$B$45:$L$54"),MATCH(Сводка!B2,INDIRECT("ИТОГО!$A$45:$A$54"),0),MATCH(Сводка!A2,INDIRECT("ИТОГО!$B$44:$L$44"),0)) -> 228458.8
A3: Полимеры | B3: Баумана | C3: =INDEX(INDIRECT("ИТОГО!$B$45:$L$54"),MATCH(Сводка!B3,INDIRECT("ИТОГО!$A$45:$A$54"),0),MATCH(Сводка!A3,INDIRECT("ИТОГО!$B$44:$L$44"),0)) -> 6925025.6
A4: Каучук | B4: Баумана | C4: =INDEX(INDIRECT("ИТОГО!$B$45:$L$54"),MATCH(Сводка!B4,INDIRECT("ИТОГО!$A$45:$A$54"),0),MATCH(Сводка!A4,INDIRECT("ИТОГО!$B$44:$L$44"),0)) -> 0
A5: ПСОН | B5: Баумана | C5: =INDEX(INDIRECT("ИТОГО!$B$45:$L$54"),MATCH(Сводка!B5,INDIRECT("ИТОГО!$A$45:$A$54"),0),MATCH(Сводка!A5,INDIRECT("ИТОГО!$B$44:$L$44"),0)) -> 0
A6: Данафлекс | B6: Баумана | C6: =INDEX(INDIRECT("ИТОГО!$B$45:$L$54"),MATCH(Сводка!B6,INDIRECT("ИТОГО!$A$45:$A$54"),0),MATCH(Сводка!A6,INDIRECT("ИТОГО!$B$44:$L$44"),0)) -> 0
A7: СБС | B7: Баумана | C7: =INDEX(INDIRECT("ИТОГО!$B$45:$L$54"),MATCH(Сводка!B7,INDIRECT("ИТОГО!$A$45:$A$54"),0),MATCH(Сводка!A7,INDIRECT("ИТОГО!$B$44:$L$44"),0)) -> 0
A8: Порошок | B8: Баумана | C8: =INDEX(INDIRECT("ИТОГО!$B$45:$L$54"),MATCH(Сводка!B8,INDIRECT("ИТОГО!$A$45:$A$54"),0),MATCH(Сводка!A8,INDIRECT("ИТОГО!$B$44:$L$44"),0)) -> 0
A9: НПЭГ | B9: Баумана | C9: =INDEX(INDIRECT("ИТОГО!$B$45:$L$54"),MATCH(Сводка!B9,INDIRECT("ИТОГО!$A$45:$A$54"),0),MATCH(Сводка!A9,INDIRECT("ИТОГО!$B$44:$L$44"),0)) -> 0
A10: Экспорт | B10: Баумана | C10: =INDEX(INDIRECT("ИТОГО!$B$45:$L$54"),MATCH(Сводка!B10,INDIRECT("ИТОГО!$A$45:$A$54"),0),MATCH(Сводка!A10,INDIRECT("ИТОГО!$B$44:$L$44"),0)) -> 0
A11: Доп услуги | B11: Баумана | C11: =INDEX(INDIRECT("ИТОГО!$B$45:$L$54"),MATCH(Сводка!B11,INDIRECT("ИТОГО!$A$45:$A$54"),0),MATCH(Сводка!A11,INDIRECT("ИТОГО!$B$44:$L$44"),0)) -> 0
A12: KPI | B12: Новикова-Прибоя | C12: =INDEX(INDIRECT("ИТОГО!$B$45:$L$54"),MATCH(Сводка!B12,INDIRECT("ИТОГО!$A$45:$A$54"),0),MATCH(Сводка!A12,INDIRECT("ИТОГО!$B$44:$L$44"),0)) -> 46250.75
... A99: Доп услуги | B99: Казань_Приволжская | C99: =INDEX(INDIRECT("ИТОГО!$B$45:$L$54"),MATCH(Сводка!B99,INDIRECT("ИТОГО!$A$45:$A$54"),0),MATCH(Сводка!A99,INDIRECT("ИТОГО!$B$44:$L$44"),0)) -> 47616
A100: Русвинил | B100: Баумана | C100: {=INDIRECT("ИТОГО!B57")} -> 256416.4
A101: Русвинил | B101: Новикова-Прибоя | C101: {=INDIRECT("ИТОГО!B58")} -> 209215.3
A102: Русвинил | B102: Березовая Пойма | C102: {=INDIRECT("ИТОГО!B67")} -> 5677203.9
A103: ПРР | B103: Нижнекамск завод | C103: {=INDIRECT("ИТОГО!C30")} -> 16167490
A104: Кладовки | B104: Нижнекамск завод | C104: {=INDIRECT("ИТОГО!C31")} -> 0
A105: Стропальщики | B105: Нижнекамск завод | C105: {=INDIRECT("ИТОГО!C32")} -> 817400
A106: Мойка контейнеров | B106: Нижнекамск завод | C106: {=INDIRECT("ИТОГО!C33")} -> 2020076
A107: МТО | B107: Нижнекамск завод | C107: {=INDIRECT("ИТОГО!C34")} -> 18710159
A108: МТО 2520 | B108: Нижнекамск завод | C108: {=INDIRECT("ИТОГО!C35")} -> 6980600
A109: КП КОС | B109: Нижнекамск завод | C109: {=INDIRECT("ИТОГО!C38")} -> 2910816
A110: КП Нижнекамск | B110: Нижнекамск завод | C110: {=INDIRECT("ИТОГО!C39")} -> 7064220
A111: Стройтех | B111: Баумана | C111: {=INDIRECT("ИТОГО!C19")} -> 24355
A112: Ергарда | B112: Баумана | C112: {=INDIRECT("ИТОГО!C20")} -> 8928
A113: Литейные решения | B113: Баумана | C113: {=INDIRECT("ИТОГО!C21")} -> 20803
A114: Сандекс | B114: Баумана | C114: {=INDIRECT("ИТОГО!C22")} -> 24151.2
A115: ЛС-Техномет | B115: Баумана | C115: {=INDIRECT("ИТОГО!C23")} -> 8608.8
A116: Приоритет | B116: Баумана | C116: {=INDIRECT("ИТОГО!G19")} -> 0
A117: Фармпласт | B117: Баумана | C117: {=INDIRECT("ИТОГО!G20")} -> 0
A118: Юг Полимер | B118: Баумана | C118: {=INDIRECT("ИТОГО!G21")} -> 0
A119: Центрополимер | B119: Екатеринбург | C119: {=INDIRECT("ИТОГО!G22")} -> 0
A120: Приоритет | B120: Екатеринбург | C120: {=INDIRECT("ИТОГО!G23")} -> 0
A121: Фармпласт | B121: Екатеринбург | C121: {=INDIRECT("ИТОГО!G24")} -> 0
A122: Приоритет | B122: Зеленодольск | C122: {=INDIRECT("ИТОГО!G25")} -> 0
A123: Данафлекс | B123: Зеленодольск | C123: {=INDIRECT("ИТОГО!G26")} -> 0
A124: ИП Ксендз | B124: Нижнекамск | C124: {=INDIRECT("ИТОГО!G27")} -> 0
A125: Фармпласт | B125: Новикова-Прибоя | C125: {=INDIRECT("ИТОГО!G28")} -> 0
A126: Центрополимер | B126: Новикова-Прибоя | C126: {=INDIRECT("ИТОГО!G29")} -> 0
...

Sheet Резерв
A3: ="Отчет по резерву хранению товара РВ " & TEXT(A6,"ММММ ") & YEAR(A6) & "" -> Отчет по резерву хранению товара РВ Март 2026
A4: дата | C4: Хранение Баумана | D4: Хранение Новикова | E4: Хранение Березовая Пойма | F4: Общее хранение | G4: Резерв 8000 т | H4: стоимость резерва | I4: итого
A6: 46082 | C6: ='[1]РВ Баумана'!G6 -> 600.275 | D6: ='[1]РВ Новикова-Прибоя'!G6 -> 419.025 | E6: ='[1]РВ Березовая Пойма'!G6 -> 4011.225 | F6: =SUM(C6:E6) -> 5030.525 | G6: =IF(A6<>"",IF(8000-F6<0,0,8000-F6),0) -> 2969.475 | H6: =G6*15 -> 44542.125 | I6: =SUM(H6:H6) -> 44542.125 | J6: =IF(OR(WEEKDAY(A6)=1,WEEKDAY(A6)=7,NOT(ISERROR(MATCH(A6,[1]Праздники!A:A,0)))),"Выходной","Рабочий") -> Выходной
A7: 46083 | C7: ='[1]РВ Баумана'!G7 -> 556.275 | D7: ='[1]РВ Новикова-Прибоя'!G7 -> 374.795 | E7: ='[1]РВ Березовая Пойма'!G7 -> 3944.995 | F7: =SUM(C7:E7) -> 4876.065 | G7: =IF(A7<>"",IF(8000-F7<0,0,8000-F7),0) -> 3123.935 | H7: =G7*15 -> 46859.025 | I7: =SUM(H7:H7) -> 46859.025 | J7: =IF(OR(WEEKDAY(A7)=1,WEEKDAY(A7)=7,NOT(ISERROR(MATCH(A7,[1]Праздники!A:A,0)))),"Выходной","Рабочий") -> Рабочий
A8: 46084 | C8: ='[1]РВ Баумана'!G8 -> 556.275 | D8: ='[1]РВ Новикова-Прибоя'!G8 -> 330.565 | E8: ='[1]РВ Березовая Пойма'!G8 -> 3789.845 | F8: =SUM(C8:E8) -> 4676.685 | G8: =IF(A8<>"",IF(8000-F8<0,0,8000-F8),0) -> 3323.315 | H8: =G8*15 -> 49849.725 | I8: =SUM(H8:H8) -> 49849.725 | J8: =IF(OR(WEEKDAY(A8)=1,WEEKDAY(A8)=7,NOT(ISERROR(MATCH(A8,[1]Праздники!A:A,0)))),"Выходной","Рабочий") -> Рабочий
A9: 46085 | C9: ='[1]РВ Баумана'!G9 -> 512.325 | D9: ='[1]РВ Новикова-Прибоя'!G9 -> 308.565 | E9: ='[1]РВ Березовая Пойма'!G9 -> 3612.465 | F9: =SUM(C9:E9) -> 4433.355 | G9: =IF(A9<>"",IF(8000-F9<0,0,8000-F9),0) -> 3566.645 | H9: =G9*15 -> 53499.675 | I9: =SUM(H9:H9) -> 53499.675 | J9: =IF(OR(WEEKDAY(A9)=1,WEEKDAY(A9)=7,NOT(ISERROR(MATCH(A9,[1]Праздники!A:A,0)))),"Выходной","Рабочий") -> Рабочий
A10: 46086 | C10: ='[1]РВ Баумана'!G10 -> 468.325 | D10: ='[1]РВ Новикова-Прибоя'!G10 -> 286.565 | E10: ='[1]РВ Березовая Пойма'!G10 -> 3546.005 | F10: =SUM(C10:E10) -> 4300.895 | G10: =IF(A10<>"",IF(8000-F10<0,0,8000-F10),0) -> 3699.105 | H10: =G10*15 -> 55486.575 | I10: =SUM(H10:H10) -> 55486.575 | J10: =IF(OR(WEEKDAY(A10)=1,WEEKDAY(A10)=7,NOT(ISERROR(MATCH(A10,[1]Праздники!A:A,0)))),"Выходной","Рабочий") -> Рабочий
A11: 46087 | C11: ='[1]РВ Баумана'!G11 -> 468.325 | D11: ='[1]РВ Новикова-Прибоя'!G11 -> 286.565 | E11: ='[1]РВ Березовая Пойма'!G11 -> 3546.005 | F11: =SUM(C11:E11) -> 4300.895 | G11: =IF(A11<>"",IF(8000-F11<0,0,8000-F11),0) -> 3699.105 | H11: =G11*15 -> 55486.575 | I11: =SUM(H11:H11) -> 55486.575 | J11: =IF(OR(WEEKDAY(A11)=1,WEEKDAY(A11)=7,NOT(ISERROR(MATCH(A11,[1]Праздники!A:A,0)))),"Выходной","Рабочий") -> Рабочий
A12: 46088 | C12: ='[1]РВ Баумана'!G12 -> 468.325 | D12: ='[1]РВ Новикова-Прибоя'!G12 -> 286.565 | E12: ='[1]РВ Березовая Пойма'!G12 -> 3744.005 | F12: =SUM(C12:E12) -> 4498.895 | G12: =IF(A12<>"",IF(8000-F12<0,0,8000-F12),0) -> 3501.105 | H12: =G12*15 -> 52516.575 | I12: =SUM(H12:H12) -> 52516.575 | J12: =IF(OR(WEEKDAY(A12)=1,WEEKDAY(A12)=7,NOT(ISERROR(MATCH(A12,[1]Праздники!A:A,0)))),"Выходной","Рабочий") -> Выходной
A13: 46089 | C13: ='[1]РВ Баумана'!G13 -> 424.325 | D13: ='[1]РВ Новикова-Прибоя'!G13 -> 286.565 | E13: ='[1]РВ Березовая Пойма'!G13 -> 3722.005 | F13: =SUM(C13:E13) -> 4432.895 | G13: =IF(A13<>"",IF(8000-F13<0,0,8000-F13),0) -> 3567.105 | H13: =G13*15 -> 53506.575 | I13: =SUM(H13:H13) -> 53506.575 | J13: =IF(OR(WEEKDAY(A13)=1,WEEKDAY(A13)=7,NOT(ISERROR(MATCH(A13,[1]Праздники!A:A,0)))),"Выходной","Рабочий") -> Выходной
A14: 46090 | C14: ='[1]РВ Баумана'!G14 -> 380.325 | D14: ='[1]РВ Новикова-Прибоя'!G14 -> 286.565 | E14: ='[1]РВ Березовая Пойма'!G14 -> 3919.505 | F14: =SUM(C14:E14) -> 4586.395 | G14: =IF(A14<>"",IF(8000-F14<0,0,8000-F14),0) -> 3413.605 | H14: =G14*15 -> 51204.075 | I14: =SUM(H14:H14) -> 51204.075 | J14: =IF(OR(WEEKDAY(A14)=1,WEEKDAY(A14)=7,NOT(ISERROR(MATCH(A14,[1]Праздники!A:A,0)))),"Выходной","Рабочий") -> Выходной
A15: 46091 | C15: ='[1]РВ Баумана'!G15 -> 358.325 | D15: ='[1]РВ Новикова-Прибоя'!G15 -> 286.565 | E15: ='[1]РВ Березовая Пойма'!G15 -> 4117.505 | F15: =SUM(C15:E15) -> 4762.395 | G15: =IF(A15<>"",IF(8000-F15<0,0,8000-F15),0) -> 3237.605 | H15: =G15*15 -> 48564.075 | I15: =SUM(H15:H15) -> 48564.075 | J15: =IF(OR(WEEKDAY(A15)=1,WEEKDAY(A15)=7,NOT(ISERROR(MATCH(A15,[1]Праздники!A:A,0)))),"Выходной","Рабочий") -> Рабочий
A16: 46092 | C16: ='[1]РВ Баумана'!G16 -> 299.2 | D16: ='[1]РВ Новикова-Прибоя'!G16 -> 279.69 | E16: ='[1]РВ Березовая Пойма'!G16 -> 4117.505 | F16: =SUM(C16:E16) -> 4696.395 | G16: =IF(A16<>"",IF(8000-F16<0,0,8000-F16),0) -> 3303.605 | H16: =G16*15 -> 49554.075 | I16: =SUM(H16:H16) -> 49554.075 | J16: =IF(OR(WEEKDAY(A16)=1,WEEKDAY(A16)=7,NOT(ISERROR(MATCH(A16,[1]Праздники!A:A,0)))),"Выходной","Рабочий") -> Рабочий
A17: 46093 | C17: ='[1]РВ Баумана'!G17 -> 255.2 | D17: ='[1]РВ Новикова-Прибоя'!G17 -> 279.69 | E17: ='[1]РВ Березовая Пойма'!G17 -> 4022.485 | F17: =SUM(C17:E17) -> 4557.375 | G17: =IF(A17<>"",IF(8000-F17<0,0,8000-F17),0) -> 3442.625 | H17: =G17*15 -> 51639.375 | I17: =SUM(H17:H17) -> 51639.375 | J17: =IF(OR(WEEKDAY(A17)=1,WEEKDAY(A17)=7,NOT(ISERROR(MATCH(A17,[1]Праздники!A:A,0)))),"Выходной","Рабочий") -> Рабочий
... A36: 46112 | C36: ='[1]РВ Баумана'!G36 -> -6.8167694e-14 | D36: ='[1]РВ Новикова-Прибоя'!G36 -> 7.9936058e-15 | E36: ='[1]РВ Березовая Пойма'!G36 -> 80.21 | F36: =SUM(C36:E36) -> 80.21 | G36: =IF(A36<>"",IF(8000-F36<0,0,8000-F36),0) -> 7919.79 | H36: =G36*15 -> 118796.85 | I36: =SUM(H36:H36) -> 118796.85 | J36: =IF(OR(WEEKDAY(A36)=1,WEEKDAY(A36)=7,NOT(ISERROR(MATCH(A36,[1]Праздники!A:A,0)))),"Выходной","Рабочий") -> Рабочий
C37: =SUM(C6:C36) -> 6847.45 | D37: =SUM(D6:D36) -> 7000.63 | E37: =SUM(E6:E36) -> 94235.53 | G37: =SUM(G6:G36) -> 139916.39 | H37: =SUM(H6:H36) -> 2098745.9 | I37: =SUM(I6:I36) -> 2098745.9
I38: =I37*1.22 -> 2560469.9

Sheet РВ Баумана
R1: Выходной | S1: Рабочий
Q2: Выгрузка | R2: =SUMIF($P$6:$P$36,R$1,$C6:$C36) -> 0 | S2: =SUMIF($P$6:$P$36,S$1,$C6:$C36) -> 0
A3: ="Отчет по хранению товара РВ " & TEXT(A6,"ММММ ") & YEAR(A6) & " Баумана" -> Отчет по хранению товара РВ Март 2026 Баумана | Q3: Отгрузка | R3: =SUMIF($P$6:$P$36,R$1,$D6:$D36) -> 232.325 | S3: =SUMIF($P$6:$P$36,S$1,$D6:$D36) -> 367.95
A4: дата | C4: Выгрузка кол-во тонн | D4: Загрузка кол-во тонн | E4: Выгрузка после 20:00 | F4: Загрузка после 20:00 | G4: Хранение | H4: переконсолидация (тонн) | I4: стоимость выгрузки | J4: стоимость загрузки | K4: Стоимость выгрузки после 20:00 | L4: Стоимость загрузки после 20:00 | M4: стоимость хранения | N4: стоимость переконс. | O4: итого
G5: (кол-во тонн)
A6: 46082 | C6: 0 | D6: 44 | G6: 600.275 | I6: =IF(P6="Выходной",SUM(C6*150)*1.5,SUM(C6*150)) -> 0 | J6: =IF(P6="Выходной",SUM(D6*150)*1.5,SUM(D6*150)) -> 9900 | K6: =IF(OR(WEEKDAY(A6)=1,WEEKDAY(A6)=7,NOT(ISERROR(MATCH(A6,[1]Праздники!A:A,0)))),SUM(E6*225)*1.5,SUM(E6*225)) -> 0 | L6: =IF(OR(WEEKDAY(A6)=1,WEEKDAY(A6)=7,NOT(ISERROR(MATCH(A6,[1]Праздники!A:A,0)))),SUM(F6*225)*1.5,SUM(F6*225)) -> 0 | M6: =SUM(G6*15) -> 9004.125 | N6: =SUM(H6)*750 -> 0 | O6: =SUM(I6:N6) -> 18904.125 | P6: =IF(OR(WEEKDAY(A6)=1,WEEKDAY(A6)=7,NOT(ISERROR(MATCH(A6,[1]Праздники!A:A,0)))),"Выходной","Рабочий") -> Выходной
A7: 46083 | C7: 0 | D7: 0 | G7: =IF(A7 ="",0,G6+C7+E7-D6-F6) -> 556.275 | I7: =IF(P7="Выходной",SUM(C7*150)*1.5,SUM(C7*150)) -> 0 | J7: =IF(P7="Выходной",SUM(D7*150)*1.5,SUM(D7*150)) -> 0 | K7: =IF(OR(WEEKDAY(A7)=1,WEEKDAY(A7)=7,NOT(ISERROR(MATCH(A7,[1]Праздники!A:A,0)))),SUM(E7*225)*1.5,SUM(E7*225)) -> 0 | L7: =IF(OR(WEEKDAY(A7)=1,WEEKDAY(A7)=7,NOT(ISERROR(MATCH(A7,[1]Праздники!A:A,0)))),SUM(F7*225)*1.5,SUM(F7*225)) -> 0 | M7: =SUM(G7*15) -> 8344.125 | N7: =SUM(H7)*750 -> 0 | O7: =SUM(I7:N7) -> 8344.125 | P7: =IF(OR(WEEKDAY(A7)=1,WEEKDAY(A7)=7,NOT(ISERROR(MATCH(A7,[1]Праздники!A:A,0)))),"Выходной","Рабочий") -> Рабочий
A8: 46084 | C8: 0 | D8: 43.95 | G8: =IF(A8 ="",0,G7+C8+E8-D7-F7) -> 556.275 | I8: =IF(P8="Выходной",SUM(C8*150)*1.5,SUM(C8*150)) -> 0 | J8: =IF(P8="Выходной",SUM(D8*150)*1.5,SUM(D8*150)) -> 6592.5 | K8: =IF(OR(WEEKDAY(A8)=1,WEEKDAY(A8)=7,NOT(ISERROR(MATCH(A8,[1]Праздники!A:A,0)))),SUM(E8*225)*1.5,SUM(E8*225)) -> 0 | L8: =IF(OR(WEEKDAY(A8)=1,WEEKDAY(A8)=7,NOT(ISERROR(MATCH(A8,[1]Праздники!A:A,0)))),SUM(F8*225)*1.5,SUM(F8*225)) -> 0 | M8: =SUM(G8*15) -> 8344.125 | N8: =SUM(H8)*750 -> 0 | O8: =SUM(I8:N8) -> 14936.625 | P8: =IF(OR(WEEKDAY(A8)=1,WEEKDAY(A8)=7,NOT(ISERROR(MATCH(A8,[1]Праздники!A:A,0)))),"Выходной","Рабочий") -> Рабочий
A9: 46085 | C9: 0 | D9: 44 | G9: =IF(A9 ="",0,G8+C9+E9-D8-F8) -> 512.325 | I9: =IF(P9="Выходной",SUM(C9*150)*1.5,SUM(C9*150)) -> 0 | J9: =IF(P9="Выходной",SUM(D9*150)*1.5,SUM(D9*150)) -> 6600 | K9: =IF(OR(WEEKDAY(A9)=1,WEEKDAY(A9)=7,NOT(ISERROR(MATCH(A9,[1]Праздники!A:A,0)))),SUM(E9*225)*1.5,SUM(E9*225)) -> 0 | L9: =IF(OR(WEEKDAY(A9)=1,WEEKDAY(A9)=7,NOT(ISERROR(MATCH(A9,[1]Праздники!A:A,0)))),SUM(F9*225)*1.5,SUM(F9*225)) -> 0 | M9: =SUM(G9*15) -> 7684.875 | N9: =SUM(H9)*750 -> 0 | O9: =SUM(I9:N9) -> 14284.875 | P9: =IF(OR(WEEKDAY(A9)=1,WEEKDAY(A9)=7,NOT(ISERROR(MATCH(A9,[1]Праздники!A:A,0)))),"Выходной","Рабочий") -> Рабочий
A10: 46086 | C10: 0 | D10: 0 | G10: =IF(A10 ="",0,G9+C10+E10-D9-F9) -> 468.325 | I10: =IF(P10="Выходной",SUM(C10*150)*1.5,SUM(C10*150)) -> 0 | J10: =IF(P10="Выходной",SUM(D10*150)*1.5,SUM(D10*150)) -> 0 | K10: =IF(OR(WEEKDAY(A10)=1,WEEKDAY(A10)=7,NOT(ISERROR(MATCH(A10,[1]Праздники!A:A,0)))),SUM(E10*225)*1.5,SUM(E10*225)) -> 0 | L10: =IF(OR(WEEKDAY(A10)=1,WEEKDAY(A10)=7,NOT(ISERROR(MATCH(A10,[1]Праздники!A:A,0)))),SUM(F10*225)*1.5,SUM(F10*225)) -> 0 | M10: =SUM(G10*15) -> 7024.875 | N10: =SUM(H10)*750 -> 0 | O10: =SUM(I10:N10) -> 7024.875 | P10: =IF(OR(WEEKDAY(A10)=1,WEEKDAY(A10)=7,NOT(ISERROR(MATCH(A10,[1]Праздники!A:A,0)))),"Выходной","Рабочий") -> Рабочий
A11: 46087 | C11: 0 | D11: 0 | G11: =IF(A11 ="",0,G10+C11+E11-D10-F10) -> 468.325 | I11: =IF(P11="Выходной",SUM(C11*150)*1.5,SUM(C11*150)) -> 0 | J11: =IF(P11="Выходной",SUM(D11*150)*1.5,SUM(D11*150)) -> 0 | K11: =IF(OR(WEEKDAY(A11)=1,WEEKDAY(A11)=7,NOT(ISERROR(MATCH(A11,[1]Праздники!A:A,0)))),SUM(E11*225)*1.5,SUM(E11*225)) -> 0 | L11: =IF(OR(WEEKDAY(A11)=1,WEEKDAY(A11)=7,NOT(ISERROR(MATCH(A11,[1]Праздники!A:A,0)))),SUM(F11*225)*1.5,SUM(F11*225)) -> 0 | M11: =SUM(G11*15) -> 7024.875 | N11: =SUM(H11)*750 -> 0 | O11: =SUM(I11:N11) -> 7024.875 | P11: =IF(OR(WEEKDAY(A11)=1,WEEKDAY(A11)=7,NOT(ISERROR(MATCH(A11,[1]Праздники!A:A,0)))),"Выходной","Рабочий") -> Рабочий
A12: 46088 | C12: 0 | D12: 44 | G12: =IF(A12 ="",0,G11+C12+E12-D11-F11) -> 468.325 | I12: =IF(P12="Выходной",SUM(C12*150)*1.5,SUM(C12*150)) -> 0 | J12: =IF(P12="Выходной",SUM(D12*150)*1.5,SUM(D12*150)) -> 9900 | K12: =IF(OR(WEEKDAY(A12)=1,WEEKDAY(A12)=7,NOT(ISERROR(MATCH(A12,[1]Праздники!A:A,0)))),SUM(E12*225)*1.5,SUM(E12*225)) -> 0 | L12: =IF(OR(WEEKDAY(A12)=1,WEEKDAY(A12)=7,NOT(ISERROR(MATCH(A12,[1]Праздники!A:A,0)))),SUM(F12*225)*1.5,SUM(F12*225)) -> 0 | M12: =SUM(G12*15) -> 7024.875 | N12: =SUM(H12)*750 -> 0 | O12: =SUM(I12:N12) -> 16924.875 | P12: =IF(OR(WEEKDAY(A12)=1,WEEKDAY(A12)=7,NOT(ISERROR(MATCH(A12,[1]Праздники!A:A,0)))),"Выходной","Рабочий") -> Выходной
A13: 46089 | C13: 0 | D13: 44 | G13: =IF(A13 ="",0,G12+C13+E13-D12-F12) -> 424.325 | I13: =IF(P13="Выходной",SUM(C13*150)*1.5,SUM(C13*150)) -> 0 | J13: =IF(P13="Выходной",SUM(D13*150)*1.5,SUM(D13*150)) -> 9900 | K13: =IF(OR(WEEKDAY(A13)=1,WEEKDAY(A13)=7,NOT(ISERROR(MATCH(A13,[1]Праздники!A:A,0)))),SUM(E13*225)*1.5,SUM(E13*225)) -> 0 | L13: =IF(OR(WEEKDAY(A13)=1,WEEKDAY(A13)=7,NOT(ISERROR(MATCH(A13,[1]Праздники!A:A,0)))),SUM(F13*225)*1.5,SUM(F13*225)) -> 0 | M13: =SUM(G13*15) -> 6364.875 | N13: =SUM(H13)*750 -> 0 | O13: =SUM(I13:N13) -> 16264.875 | P13: =IF(OR(WEEKDAY(A13)=1,WEEKDAY(A13)=7,NOT(ISERROR(MATCH(A13,[1]Праздники!A:A,0)))),"Выходной","Рабочий") -> Выходной
A14: 46090 | C14: 0 | D14: 22 | G14: =IF(A14 ="",0,G13+C14+E14-D13-F13) -> 380.325 | I14: =IF(P14="Выходной",SUM(C14*150)*1.5,SUM(C14*150)) -> 0 | J14: =IF(P14="Выходной",SUM(D14*150)*1.5,SUM(D14*150)) -> 4950 | K14: =IF(OR(WEEKDAY(A14)=1,WEEKDAY(A14)=7,NOT(ISERROR(MATCH(A14,[1]Праздники!A:A,0)))),SUM(E14*225)*1.5,SUM(E14*225)) -> 0 | L14: =IF(OR(WEEKDAY(A14)=1,WEEKDAY(A14)=7,NOT(ISERROR(MATCH(A14,[1]Праздники!A:A,0)))),SUM(F14*225)*1.5,SUM(F14*225)) -> 0 | M14: =SUM(G14*15) -> 5704.875 | N14: =SUM(H14)*750 -> 0 | O14: =SUM(I14:N14) -> 10654.875 | P14: =IF(OR(WEEKDAY(A14)=1,WEEKDAY(A14)=7,NOT(ISERROR(MATCH(A14,[1]Праздники!A:A,0)))),"Выходной","Рабочий") -> Выходной
A15: 46091 | C15: 0 | D15: 59.125 | G15: =IF(A15 ="",0,G14+C15+E15-D14-F14) -> 358.325 | I15: =IF(P15="Выходной",SUM(C15*150)*1.5,SUM(C15*150)) -> 0 | J15: =IF(P15="Выходной",SUM(D15*150)*1.5,SUM(D15*150)) -> 8868.75 | K15: =IF(OR(WEEKDAY(A15)=1,WEEKDAY(A15)=7,NOT(ISERROR(MATCH(A15,[1]Праздники!A:A,0)))),SUM(E15*225)*1.5,SUM(E15*225)) -> 0 | L15: =IF(OR(WEEKDAY(A15)=1,WEEKDAY(A15)=7,NOT(ISERROR(MATCH(A15,[1]Праздники!A:A,0)))),SUM(F15*225)*1.5,SUM(F15*225)) -> 0 | M15: =SUM(G15*15) -> 5374.875 | N15: =SUM(H15)*750 -> 0 | O15: =SUM(I15:N15) -> 14243.625 | P15: =IF(OR(WEEKDAY(A15)=1,WEEKDAY(A15)=7,NOT(ISERROR(MATCH(A15,[1]Праздники!A:A,0)))),"Выходной","Рабочий") -> Рабочий
A16: 46092 | C16: 0 | D16: 44 | G16: =IF(A16 ="",0,G15+C16+E16-D15-F15) -> 299.2 | I16: =IF(P16="Выходной",SUM(C16*150)*1.5,SUM(C16*150)) -> 0 | J16: =IF(P16="Выходной",SUM(D16*150)*1.5,SUM(D16*150)) -> 6600 | K16: =IF(OR(WEEKDAY(A16)=1,WEEKDAY(A16)=7,NOT(ISERROR(MATCH(A16,[1]Праздники!A:A,0)))),SUM(E16*225)*1.5,SUM(E16*225)) -> 0 | L16: =IF(OR(WEEKDAY(A16)=1,WEEKDAY(A16)=7,NOT(ISERROR(MATCH(A16,[1]Праздники!A:A,0)))),SUM(F16*225)*1.5,SUM(F16*225)) -> 0 | M16: =SUM(G16*15) -> 4488 | N16: =SUM(H16)*750 -> 0 | O16: =SUM(I16:N16) -> 11088 | P16: =IF(OR(WEEKDAY(A16)=1,WEEKDAY(A16)=7,NOT(ISERROR(MATCH(A16,[1]Праздники!A:A,0)))),"Выходной","Рабочий") -> Рабочий
A17: 46093 | C17: 0 | D17: 44 | G17: =IF(A17 ="",0,G16+C17+E17-D16-F16) -> 255.2 | I17: =IF(P17="Выходной",SUM(C17*150)*1.5,SUM(C17*150)) -> 0 | J17: =IF(P17="Выходной",SUM(D17*150)*1.5,SUM(D17*150)) -> 6600 | K17: =IF(OR(WEEKDAY(A17)=1,WEEKDAY(A17)=7,NOT(ISERROR(MATCH(A17,[1]Праздники!A:A,0)))),SUM(E17*225)*1.5,SUM(E17*225)) -> 0 | L17: =IF(OR(WEEKDAY(A17)=1,WEEKDAY(A17)=7,NOT(ISERROR(MATCH(A17,[1]Праздники!A:A,0)))),SUM(F17*225)*1.5,SUM(F17*225)) -> 0 | M17: =SUM(G17*15) -> 3828 | N17: =SUM(H17)*750 -> 0 | O17: =SUM(I17:N17) -> 10428 | P17: =IF(OR(WEEKDAY(A17)=1,WEEKDAY(A17)=7,NOT(ISERROR(MATCH(A17,[1]Праздники!A:A,0)))),"Выходной","Рабочий") -> Рабочий
A18: 46094 | C18: 0 | D18: 22 | G18: =IF(A18 ="",0,G17+C18+E18-D17-F17) -> 211.2 | I18: =IF(P18="Выходной",SUM(C18*150)*1.5,SUM(C18*150)) -> 0 | J18: =IF(P18="Выходной",SUM(D18*150)*1.5,SUM(D18*150)) -> 3300 | K18: =IF(OR(WEEKDAY(A18)=1,WEEKDAY(A18)=7,NOT(ISERROR(MATCH(A18,[1]Праздники!A:A,0)))),SUM(E18*225)*1.5,SUM(E18*225)) -> 0 | L18: =IF(OR(WEEKDAY(A18)=1,WEEKDAY(A18)=7,NOT(ISERROR(MATCH(A18,[1]Праздники!A:A,0)))),SUM(F18*225)*1.5,SUM(F18*225)) -> 0 | M18: =SUM(G18*15) -> 3168 | N18: =SUM(H18)*750 -> 0 | O18: =SUM(I18:N18) -> 6468 | P18: =IF(OR(WEEKDAY(A18)=1,WEEKDAY(A18)=7,NOT(ISERROR(MATCH(A18,[1]Праздники!A:A,0)))),"Выходной","Рабочий") -> Рабочий
... A36: 46112 | C36: 0 | D36: 0 | G36: =IF(A36 ="",0,G35+C36+E36-D35-F35) -> -6.8167694e-14 | I36: =IF(P36="Выходной",SUM(C36*150)*1.5,SUM(C36*150)) -> 0 | J36: =IF(P36="Выходной",SUM(D36*150)*1.5,SUM(D36*150)) -> 0 | K36: =IF(OR(WEEKDAY(A36)=1,WEEKDAY(A36)=7,NOT(ISERROR(MATCH(A36,[1]Праздники!A:A,0)))),SUM(E36*225)*1.5,SUM(E36*225)) -> 0 | L36: =IF(OR(WEEKDAY(A36)=1,WEEKDAY(A36)=7,NOT(ISERROR(MATCH(A36,[1]Праздники!A:A,0)))),SUM(F36*225)*1.5,SUM(F36*225)) -> 0 | M36: =SUM(G36*15) -> -1.0225154e-12 | N36: =SUM(H36)*750 -> 0 | O36: =SUM(I36:N36) -> -1.0225154e-12 | P36: =IF(OR(WEEKDAY(A36)=1,WEEKDAY(A36)=7,NOT(ISERROR(MATCH(A36,[1]Праздники!A:A,0)))),"Выходной","Рабочий") -> Рабочий
C37: =SUM(C6:C36) -> 0 | D37: =SUM(D6:D36) -> 600.275 | E37: =SUM(E6:E36) -> 0 | F37: =SUM(F6:F36) -> 0 | G37: =SUM(G6:G36) -> 6847.45 | H37: =SUM(H6:H36) -> 0 | I37: =SUM(I6:I36) -> 0 | J37: =SUM(J6:J36) -> 107465.62 | ... O37: =SUM(O6:O36) -> 210177.38
N38: С НДС; | O38: =O37*1.22 -> 256416.4

Sheet РВ Березовая Пойма
R1: Выходной | S1: Рабочий
Q2: Выгрузка | R2: =SUMIF($P$6:$P$36,R$1,$C6:$C36) -> 658.025 | S2: =SUMIF($P$6:$P$36,S$1,$C6:$C36) -> 660
A3: ="Отчет по хранению товара РВ " & TEXT(A6,"ММММ ") & YEAR(A6) & " Березовая Пойма" -> Отчет по хранению товара РВ Март 2026 Березовая Пойма | Q3: Отгрузка | R3: =SUMIF($P$6:$P$36,R$1,$D6:$D36) -> 1262.985 | S3: =SUMIF($P$6:$P$36,S$1,$D6:$D36) -> 4066.265
A4: дата | C4: Выгрузка кол-во тонн | D4: Загрузка кол-во тонн | E4: Выгрузка после 20:00 | F4: Загрузка после 20:00 | G4: Хранение | H4: переконсолидация (тонн) | I4: стоимость выгрузки | J4: стоимость загрузки | K4: Стоимость выгрузки после 20:00 | L4: Стоимость загрузки после 20:00 | M4: стоимость хранения | N4: стоимость переконс. | O4: итого
G5: (кол-во тонн)
A6: 46082 | C6: 0 | D6: 66.23 | G6: 4011.225 | I6: =IF(P6="Выходной",SUM(C6*150)*1.5,SUM(C6*150)) -> 0 | J6: =IF(P6="Выходной",SUM(D6*150)*1.5,SUM(D6*150)) -> 14901.75 | K6: =IF(OR(WEEKDAY(A6)=1,WEEKDAY(A6)=7,NOT(ISERROR(MATCH(A6,[1]Праздники!A:A,0)))),SUM(E6*225)*1.5,SUM(E6*225)) -> 0 | L6: =IF(OR(WEEKDAY(A6)=1,WEEKDAY(A6)=7,NOT(ISERROR(MATCH(A6,[1]Праздники!A:A,0)))),SUM(F6*225)*1.5,SUM(F6*225)) -> 0 | M6: =SUM(G6*15) -> 60168.375 | N6: =SUM(H6)*750 -> 0 | O6: =SUM(I6:N6) -> 75070.125 | P6: =IF(OR(WEEKDAY(A6)=1,WEEKDAY(A6)=7,NOT(ISERROR(MATCH(A6,[1]Праздники!A:A,0)))),"Выходной","Рабочий") -> Выходной
A7: 46083 | C7: 0 | D7: 155.15 | G7: =IF(A7 ="",0,G6+C7+E7-D6-F6) -> 3944.995 | I7: =IF(P7="Выходной",SUM(C7*150)*1.5,SUM(C7*150)) -> 0 | J7: =IF(P7="Выходной",SUM(D7*150)*1.5,SUM(D7*150)) -> 23272.5 | K7: =IF(OR(WEEKDAY(A7)=1,WEEKDAY(A7)=7,NOT(ISERROR(MATCH(A7,[1]Праздники!A:A,0)))),SUM(E7*225)*1.5,SUM(E7*225)) -> 0 | L7: =IF(OR(WEEKDAY(A7)=1,WEEKDAY(A7)=7,NOT(ISERROR(MATCH(A7,[1]Праздники!A:A,0)))),SUM(F7*225)*1.5,SUM(F7*225)) -> 0 | M7: =SUM(G7*15) -> 59174.925 | N7: =SUM(H7)*750 -> 0 | O7: =SUM(I7:N7) -> 82447.425 | P7: =IF(OR(WEEKDAY(A7)=1,WEEKDAY(A7)=7,NOT(ISERROR(MATCH(A7,[1]Праздники!A:A,0)))),"Выходной","Рабочий") -> Рабочий
A8: 46084 | C8: 0 | D8: 177.38 | G8: =IF(A8 ="",0,G7+C8+E8-D7-F7) -> 3789.845 | I8: =IF(P8="Выходной",SUM(C8*150)*1.5,SUM(C8*150)) -> 0 | J8: =IF(P8="Выходной",SUM(D8*150)*1.5,SUM(D8*150)) -> 26607 | K8: =IF(OR(WEEKDAY(A8)=1,WEEKDAY(A8)=7,NOT(ISERROR(MATCH(A8,[1]Праздники!A:A,0)))),SUM(E8*225)*1.5,SUM(E8*225)) -> 0 | L8: =IF(OR(WEEKDAY(A8)=1,WEEKDAY(A8)=7,NOT(ISERROR(MATCH(A8,[1]Праздники!A:A,0)))),SUM(F8*225)*1.5,SUM(F8*225)) -> 0 | M8: =SUM(G8*15) -> 56847.675 | N8: =SUM(H8)*750 -> 0 | O8: =SUM(I8:N8) -> 83454.675 | P8: =IF(OR(WEEKDAY(A8)=1,WEEKDAY(A8)=7,NOT(ISERROR(MATCH(A8,[1]Праздники!A:A,0)))),"Выходной","Рабочий") -> Рабочий
A9: 46085 | C9: 0 | D9: 66.46 | G9: =IF(A9 ="",0,G8+C9+E9-D8-F8) -> 3612.465 | I9: =IF(P9="Выходной",SUM(C9*150)*1.5,SUM(C9*150)) -> 0 | J9: =IF(P9="Выходной",SUM(D9*150)*1.5,SUM(D9*150)) -> 9969 | K9: =IF(OR(WEEKDAY(A9)=1,WEEKDAY(A9)=7,NOT(ISERROR(MATCH(A9,[1]Праздники!A:A,0)))),SUM(E9*225)*1.5,SUM(E9*225)) -> 0 | L9: =IF(OR(WEEKDAY(A9)=1,WEEKDAY(A9)=7,NOT(ISERROR(MATCH(A9,[1]Праздники!A:A,0)))),SUM(F9*225)*1.5,SUM(F9*225)) -> 0 | M9: =SUM(G9*15) -> 54186.975 | N9: =SUM(H9)*750 -> 0 | O9: =SUM(I9:N9) -> 64155.975 | P9: =IF(OR(WEEKDAY(A9)=1,WEEKDAY(A9)=7,NOT(ISERROR(MATCH(A9,[1]Праздники!A:A,0)))),"Выходной","Рабочий") -> Рабочий
A10: 46086 | C10: 0 | D10: 0 | G10: =IF(A10 ="",0,G9+C10+E10-D9-F9) -> 3546.005 | I10: =IF(P10="Выходной",SUM(C10*150)*1.5,SUM(C10*150)) -> 0 | J10: =IF(P10="Выходной",SUM(D10*150)*1.5,SUM(D10*150)) -> 0 | K10: =IF(OR(WEEKDAY(A10)=1,WEEKDAY(A10)=7,NOT(ISERROR(MATCH(A10,[1]Праздники!A:A,0)))),SUM(E10*225)*1.5,SUM(E10*225)) -> 0 | L10: =IF(OR(WEEKDAY(A10)=1,WEEKDAY(A10)=7,NOT(ISERROR(MATCH(A10,[1]Праздники!A:A,0)))),SUM(F10*225)*1.5,SUM(F10*225)) -> 0 | M10: =SUM(G10*15) -> 53190.075 | N10: =SUM(H10)*750 -> 0 | O10: =SUM(I10:N10) -> 53190.075 | P10: =IF(OR(WEEKDAY(A10)=1,WEEKDAY(A10)=7,NOT(ISERROR(MATCH(A10,[1]Праздники!A:A,0)))),"Выходной","Рабочий") -> Рабочий
A11: 46087 | C11: 0 | D11: 22 | G11: =IF(A11 ="",0,G10+C11+E11-D10-F10) -> 3546.005 | I11: =IF(P11="Выходной",SUM(C11*150)*1.5,SUM(C11*150)) -> 0 | J11: =IF(P11="Выходной",SUM(D11*150)*1.5,SUM(D11*150)) -> 3300 | K11: =IF(OR(WEEKDAY(A11)=1,WEEKDAY(A11)=7,NOT(ISERROR(MATCH(A11,[1]Праздники!A:A,0)))),SUM(E11*225)*1.5,SUM(E11*225)) -> 0 | L11: =IF(OR(WEEKDAY(A11)=1,WEEKDAY(A11)=7,NOT(ISERROR(MATCH(A11,[1]Праздники!A:A,0)))),SUM(F11*225)*1.5,SUM(F11*225)) -> 0 | M11: =SUM(G11*15) -> 53190.075 | N11: =SUM(H11)*750 -> 0 | O11: =SUM(I11:N11) -> 56490.075 | P11: =IF(OR(WEEKDAY(A11)=1,WEEKDAY(A11)=7,NOT(ISERROR(MATCH(A11,[1]Праздники!A:A,0)))),"Выходной","Рабочий") -> Рабочий
A12: 46088 | C12: 220 | D12: 22 | G12: =IF(A12 ="",0,G11+C12+E12-D11-F11) -> 3744.005 | I12: =IF(P12="Выходной",SUM(C12*150)*1.5,SUM(C12*150)) -> 49500 | J12: =IF(P12="Выходной",SUM(D12*150)*1.5,SUM(D12*150)) -> 4950 | K12: =IF(OR(WEEKDAY(A12)=1,WEEKDAY(A12)=7,NOT(ISERROR(MATCH(A12,[1]Праздники!A:A,0)))),SUM(E12*225)*1.5,SUM(E12*225)) -> 0 | L12: =IF(OR(WEEKDAY(A12)=1,WEEKDAY(A12)=7,NOT(ISERROR(MATCH(A12,[1]Праздники!A:A,0)))),SUM(F12*225)*1.5,SUM(F12*225)) -> 0 | M12: =SUM(G12*15) -> 56160.075 | N12: =SUM(H12)*750 -> 0 | O12: =SUM(I12:N12) -> 110610.07 | P12: =IF(OR(WEEKDAY(A12)=1,WEEKDAY(A12)=7,NOT(ISERROR(MATCH(A12,[1]Праздники!A:A,0)))),"Выходной","Рабочий") -> Выходной
A13: 46089 | C13: 0 | D13: 22.5 | G13: =IF(A13 ="",0,G12+C13+E13-D12-F12) -> 3722.005 | I13: =IF(P13="Выходной",SUM(C13*150)*1.5,SUM(C13*150)) -> 0 | J13: =IF(P13="Выходной",SUM(D13*150)*1.5,SUM(D13*150)) -> 5062.5 | K13: =IF(OR(WEEKDAY(A13)=1,WEEKDAY(A13)=7,NOT(ISERROR(MATCH(A13,[1]Праздники!A:A,0)))),SUM(E13*225)*1.5,SUM(E13*225)) -> 0 | L13: =IF(OR(WEEKDAY(A13)=1,WEEKDAY(A13)=7,NOT(ISERROR(MATCH(A13,[1]Праздники!A:A,0)))),SUM(F13*225)*1.5,SUM(F13*225)) -> 0 | M13: =SUM(G13*15) -> 55830.075 | N13: =SUM(H13)*750 -> 0 | O13: =SUM(I13:N13) -> 60892.575 | P13: =IF(OR(WEEKDAY(A13)=1,WEEKDAY(A13)=7,NOT(ISERROR(MATCH(A13,[1]Праздники!A:A,0)))),"Выходной","Рабочий") -> Выходной
A14: 46090 | C14: 220 | D14: 22 | G14: =IF(A14 ="",0,G13+C14+E14-D13-F13) -> 3919.505 | I14: =IF(P14="Выходной",SUM(C14*150)*1.5,SUM(C14*150)) -> 49500 | J14: =IF(P14="Выходной",SUM(D14*150)*1.5,SUM(D14*150)) -> 4950 | K14: =IF(OR(WEEKDAY(A14)=1,WEEKDAY(A14)=7,NOT(ISERROR(MATCH(A14,[1]Праздники!A:A,0)))),SUM(E14*225)*1.5,SUM(E14*225)) -> 0 | L14: =IF(OR(WEEKDAY(A14)=1,WEEKDAY(A14)=7,NOT(ISERROR(MATCH(A14,[1]Праздники!A:A,0)))),SUM(F14*225)*1.5,SUM(F14*225)) -> 0 | M14: =SUM(G14*15) -> 58792.575 | N14: =SUM(H14)*750 -> 0 | O14: =SUM(I14:N14) -> 113242.57 | P14: =IF(OR(WEEKDAY(A14)=1,WEEKDAY(A14)=7,NOT(ISERROR(MATCH(A14,[1]Праздники!A:A,0)))),"Выходной","Рабочий") -> Выходной
A15: 46091 | C15: 220 | D15: 0 | G15: =IF(A15 ="",0,G14+C15+E15-D14-F14) -> 4117.505 | I15: =IF(P15="Выходной",SUM(C15*150)*1.5,SUM(C15*150)) -> 33000 | J15: =IF(P15="Выходной",SUM(D15*150)*1.5,SUM(D15*150)) -> 0 | K15: =IF(OR(WEEKDAY(A15)=1,WEEKDAY(A15)=7,NOT(ISERROR(MATCH(A15,[1]Праздники!A:A,0)))),SUM(E15*225)*1.5,SUM(E15*225)) -> 0 | L15: =IF(OR(WEEKDAY(A15)=1,WEEKDAY(A15)=7,NOT(ISERROR(MATCH(A15,[1]Праздники!A:A,0)))),SUM(F15*225)*1.5,SUM(F15*225)) -> 0 | M15: =SUM(G15*15) -> 61762.575 | N15: =SUM(H15)*750 -> 0 | O15: =SUM(I15:N15) -> 94762.575 | P15: =IF(OR(WEEKDAY(A15)=1,WEEKDAY(A15)=7,NOT(ISERROR(MATCH(A15,[1]Праздники!A:A,0)))),"Выходной","Рабочий") -> Рабочий
A16: 46092 | C16: 0 | D16: 95.02 | G16: =IF(A16 ="",0,G15+C16+E16-D15-F15) -> 4117.505 | I16: =IF(P16="Выходной",SUM(C16*150)*1.5,SUM(C16*150)) -> 0 | J16: =IF(P16="Выходной",SUM(D16*150)*1.5,SUM(D16*150)) -> 14253 | K16: =IF(OR(WEEKDAY(A16)=1,WEEKDAY(A16)=7,NOT(ISERROR(MATCH(A16,[1]Праздники!A:A,0)))),SUM(E16*225)*1.5,SUM(E16*225)) -> 0 | L16: =IF(OR(WEEKDAY(A16)=1,WEEKDAY(A16)=7,NOT(ISERROR(MATCH(A16,[1]Праздники!A:A,0)))),SUM(F16*225)*1.5,SUM(F16*225)) -> 0 | M16: =SUM(G16*15) -> 61762.575 | N16: =SUM(H16)*750 -> 0 | O16: =SUM(I16:N16) -> 76015.575 | P16: =IF(OR(WEEKDAY(A16)=1,WEEKDAY(A16)=7,NOT(ISERROR(MATCH(A16,[1]Праздники!A:A,0)))),"Выходной","Рабочий") -> Рабочий
A17: 46093 | C17: 0 | D17: 53.45 | G17: =IF(A17 ="",0,G16+C17+E17-D16-F16) -> 4022.485 | I17: =IF(P17="Выходной",SUM(C17*150)*1.5,SUM(C17*150)) -> 0 | J17: =IF(P17="Выходной",SUM(D17*150)*1.5,SUM(D17*150)) -> 8017.5 | K17: =IF(OR(WEEKDAY(A17)=1,WEEKDAY(A17)=7,NOT(ISERROR(MATCH(A17,[1]Праздники!A:A,0)))),SUM(E17*225)*1.5,SUM(E17*225)) -> 0 | L17: =IF(OR(WEEKDAY(A17)=1,WEEKDAY(A17)=7,NOT(ISERROR(MATCH(A17,[1]Праздники!A:A,0)))),SUM(F17*225)*1.5,SUM(F17*225)) -> 0 | M17: =SUM(G17*15) -> 60337.275 | N17: =SUM(H17)*750 -> 0 | O17: =SUM(I17:N17) -> 68354.775 | P17: =IF(OR(WEEKDAY(A17)=1,WEEKDAY(A17)=7,NOT(ISERROR(MATCH(A17,[1]Праздники!A:A,0)))),"Выходной","Рабочий") -> Рабочий
A18: 46094 | C18: 220 | D18: 37.125 | G18: =IF(A18 ="",0,G17+C18+E18-D17-F17) -> 4189.035 | I18: =IF(P18="Выходной",SUM(C18*150)*1.5,SUM(C18*150)) -> 33000 | J18: =IF(P18="Выходной",SUM(D18*150)*1.5,SUM(D18*150)) -> 5568.75 | K18: =IF(OR(WEEKDAY(A18)=1,WEEKDAY(A18)=7,NOT(ISERROR(MATCH(A18,[1]Праздники!A:A,0)))),SUM(E18*225)*1.5,SUM(E18*225)) -> 0 | L18: =IF(OR(WEEKDAY(A18)=1,WEEKDAY(A18)=7,NOT(ISERROR(MATCH(A18,[1]Праздники!A:A,0)))),SUM(F18*225)*1.5,SUM(F18*225)) -> 0 | M18: =SUM(G18*15) -> 62835.525 | N18: =SUM(H18)*750 -> 0 | O18: =SUM(I18:N18) -> 101404.27 | P18: =IF(OR(WEEKDAY(A18)=1,WEEKDAY(A18)=7,NOT(ISERROR(MATCH(A18,[1]Праздники!A:A,0)))),"Выходной","Рабочий") -> Рабочий
... A36: 46112 | C36: 0 | D36: 80.21 | G36: =IF(A36 ="",0,G35+C36+E36-D35-F35) -> 80.21 | I36: =IF(P36="Выходной",SUM(C36*150)*1.5,SUM(C36*150)) -> 0 | J36: =IF(P36="Выходной",SUM(D36*150)*1.5,SUM(D36*150)) -> 12031.5 | K36: =IF(OR(WEEKDAY(A36)=1,WEEKDAY(A36)=7,NOT(ISERROR(MATCH(A36,[1]Праздники!A:A,0)))),SUM(E36*225)*1.5,SUM(E36*225)) -> 0 | L36: =IF(OR(WEEKDAY(A36)=1,WEEKDAY(A36)=7,NOT(ISERROR(MATCH(A36,[1]Праздники!A:A,0)))),SUM(F36*225)*1.5,SUM(F36*225)) -> 0 | M36: =SUM(G36*15) -> 1203.15 | N36: =SUM(H36)*750 -> 0 | O36: =SUM(I36:N36) -> 13234.65 | P36: =IF(OR(WEEKDAY(A36)=1,WEEKDAY(A36)=7,NOT(ISERROR(MATCH(A36,[1]Праздники!A:A,0)))),"Выходной","Рабочий") -> Рабочий
C37: =SUM(C6:C36) -> 1318.025 | D37: =SUM(D6:D36) -> 5329.25 | E37: =SUM(E6:E36) -> 0 | F37: =SUM(F6:F36) -> 0 | G37: =SUM(G6:G36) -> 94235.53 | H37: =SUM(H6:H36) -> 0 | I37: =SUM(I6:I36) -> 247055.62 | J37: =SUM(J6:J36) -> 894111.38 | ... O37: =SUM(O6:O36) -> 2554699.9
N38: С НДС; | O38: =O37*1.22 -> 3116733.9

Sheet РВ Новикова-Прибоя
R1: Выходной | S1: Рабочий
Q2: Выгрузка | R2: =SUMIF($P$6:$P$36,R$1,$C6:$C36) -> 0 | S2: =SUMIF($P$6:$P$36,S$1,$C6:$C36) -> 0
A3: ="Отчет по хранению товара РВ " & TEXT(A6,"ММММ ") & YEAR(A6) & " Новикова" -> Отчет по хранению товара РВ Март 2026 Новикова | Q3: Отгрузка | R3: =SUMIF($P$6:$P$36,R$1,$D6:$D36) -> 48.33 | S3: =SUMIF($P$6:$P$36,S$1,$D6:$D36) -> 370.695
A4: дата | C4: Выгрузка кол-во тонн | D4: Загрузка кол-во тонн | E4: Выгрузка после 20:00 | F4: Загрузка после 20:00 | G4: Хранение | H4: переконсолидация (тонн) | I4: стоимость выгрузки | J4: стоимость загрузки | K4: Стоимость выгрузки после 20:00 | L4: Стоимость загрузки после 20:00 | M4: стоимость хранения | N4: стоимость переконс. | O4: итого
G5: (кол-во тонн)
A6: 46082 | C6: 0 | D6: 44.23 | G6: 419.025 | I6: =IF(P6="Выходной",SUM(C6*150)*1.5,SUM(C6*150)) -> 0 | J6: =IF(P6="Выходной",SUM(D6*150)*1.5,SUM(D6*150)) -> 9951.75 | K6: =IF(OR(WEEKDAY(A6)=1,WEEKDAY(A6)=7,NOT(ISERROR(MATCH(A6,[1]Праздники!A:A,0)))),SUM(E6*225)*1.5,SUM(E6*225)) -> 0 | L6: =IF(OR(WEEKDAY(A6)=1,WEEKDAY(A6)=7,NOT(ISERROR(MATCH(A6,[1]Праздники!A:A,0)))),SUM(F6*225)*1.5,SUM(F6*225)) -> 0 | M6: =SUM(G6*15) -> 6285.375 | N6: =SUM(H6)*750 -> 0 | O6: =SUM(I6:N6) -> 16237.125 | P6: =IF(OR(WEEKDAY(A6)=1,WEEKDAY(A6)=7,NOT(ISERROR(MATCH(A6,[1]Праздники!A:A,0)))),"Выходной","Рабочий") -> Выходной
A7: 46083 | C7: 0 | D7: 44.23 | G7: =IF(A7 ="",0,G6+C7+E7-D6-F6) -> 374.795 | I7: =IF(P7="Выходной",SUM(C7*150)*1.5,SUM(C7*150)) -> 0 | J7: =IF(P7="Выходной",SUM(D7*150)*1.5,SUM(D7*150)) -> 6634.5 | K7: =IF(OR(WEEKDAY(A7)=1,WEEKDAY(A7)=7,NOT(ISERROR(MATCH(A7,[1]Праздники!A:A,0)))),SUM(E7*225)*1.5,SUM(E7*225)) -> 0 | L7: =IF(OR(WEEKDAY(A7)=1,WEEKDAY(A7)=7,NOT(ISERROR(MATCH(A7,[1]Праздники!A:A,0)))),SUM(F7*225)*1.5,SUM(F7*225)) -> 0 | M7: =SUM(G7*15) -> 5621.925 | N7: =SUM(H7)*750 -> 0 | O7: =SUM(I7:N7) -> 12256.425 | P7: =IF(OR(WEEKDAY(A7)=1,WEEKDAY(A7)=7,NOT(ISERROR(MATCH(A7,[1]Праздники!A:A,0)))),"Выходной","Рабочий") -> Рабочий
A8: 46084 | C8: 0 | D8: 22 | G8: =IF(A8 ="",0,G7+C8+E8-D7-F7) -> 330.565 | I8: =IF(P8="Выходной",SUM(C8*150)*1.5,SUM(C8*150)) -> 0 | J8: =IF(P8="Выходной",SUM(D8*150)*1.5,SUM(D8*150)) -> 3300 | K8: =IF(OR(WEEKDAY(A8)=1,WEEKDAY(A8)=7,NOT(ISERROR(MATCH(A8,[1]Праздники!A:A,0)))),SUM(E8*225)*1.5,SUM(E8*225)) -> 0 | L8: =IF(OR(WEEKDAY(A8)=1,WEEKDAY(A8)=7,NOT(ISERROR(MATCH(A8,[1]Праздники!A:A,0)))),SUM(F8*225)*1.5,SUM(F8*225)) -> 0 | M8: =SUM(G8*15) -> 4958.475 | N8: =SUM(H8)*750 -> 0 | O8: =SUM(I8:N8) -> 8258.475 | P8: =IF(OR(WEEKDAY(A8)=1,WEEKDAY(A8)=7,NOT(ISERROR(MATCH(A8,[1]Праздники!A:A,0)))),"Выходной","Рабочий") -> Рабочий
A9: 46085 | C9: 0 | D9: 22 | G9: =IF(A9 ="",0,G8+C9+E9-D8-F8) -> 308.565 | I9: =IF(P9="Выходной",SUM(C9*150)*1.5,SUM(C9*150)) -> 0 | J9: =IF(P9="Выходной",SUM(D9*150)*1.5,SUM(D9*150)) -> 3300 | K9: =IF(OR(WEEKDAY(A9)=1,WEEKDAY(A9)=7,NOT(ISERROR(MATCH(A9,[1]Праздники!A:A,0)))),SUM(E9*225)*1.5,SUM(E9*225)) -> 0 | L9: =IF(OR(WEEKDAY(A9)=1,WEEKDAY(A9)=7,NOT(ISERROR(MATCH(A9,[1]Праздники!A:A,0)))),SUM(F9*225)*1.5,SUM(F9*225)) -> 0 | M9: =SUM(G9*15) -> 4628.475 | N9: =SUM(H9)*750 -> 0 | O9: =SUM(I9:N9) -> 7928.475 | P9: =IF(OR(WEEKDAY(A9)=1,WEEKDAY(A9)=7,NOT(ISERROR(MATCH(A9,[1]Праздники!A:A,0)))),"Выходной","Рабочий") -> Рабочий
A10: 46086 | C10: 0 | D10: 0 | G10: =IF(A10 ="",0,G9+C10+E10-D9-F9) -> 286.565 | I10: =IF(P10="Выходной",SUM(C10*150)*1.5,SUM(C10*150)) -> 0 | J10: =IF(P10="Выходной",SUM(D10*150)*1.5,SUM(D10*150)) -> 0 | K10: =IF(OR(WEEKDAY(A10)=1,WEEKDAY(A10)=7,NOT(ISERROR(MATCH(A10,[1]Праздники!A:A,0)))),SUM(E10*225)*1.5,SUM(E10*225)) -> 0 | L10: =IF(OR(WEEKDAY(A10)=1,WEEKDAY(A10)=7,NOT(ISERROR(MATCH(A10,[1]Праздники!A:A,0)))),SUM(F10*225)*1.5,SUM(F10*225)) -> 0 | M10: =SUM(G10*15) -> 4298.475 | N10: =SUM(H10)*750 -> 0 | O10: =SUM(I10:N10) -> 4298.475 | P10: =IF(OR(WEEKDAY(A10)=1,WEEKDAY(A10)=7,NOT(ISERROR(MATCH(A10,[1]Праздники!A:A,0)))),"Выходной","Рабочий") -> Рабочий
A11: 46087 | C11: 0 | D11: 0 | G11: =IF(A11 ="",0,G10+C11+E11-D10-F10) -> 286.565 | I11: =IF(P11="Выходной",SUM(C11*150)*1.5,SUM(C11*150)) -> 0 | J11: =IF(P11="Выходной",SUM(D11*150)*1.5,SUM(D11*150)) -> 0 | K11: =IF(OR(WEEKDAY(A11)=1,WEEKDAY(A11)=7,NOT(ISERROR(MATCH(A11,[1]Праздники!A:A,0)))),SUM(E11*225)*1.5,SUM(E11*225)) -> 0 | L11: =IF(OR(WEEKDAY(A11)=1,WEEKDAY(A11)=7,NOT(ISERROR(MATCH(A11,[1]Праздники!A:A,0)))),SUM(F11*225)*1.5,SUM(F11*225)) -> 0 | M11: =SUM(G11*15) -> 4298.475 | N11: =SUM(H11)*750 -> 0 | O11: =SUM(I11:N11) -> 4298.475 | P11: =IF(OR(WEEKDAY(A11)=1,WEEKDAY(A11)=7,NOT(ISERROR(MATCH(A11,[1]Праздники!A:A,0)))),"Выходной","Рабочий") -> Рабочий
A12: 46088 | C12: 0 | D12: 0 | G12: =IF(A12 ="",0,G11+C12+E12-D11-F11) -> 286.565 | I12: =IF(P12="Выходной",SUM(C12*150)*1.5,SUM(C12*150)) -> 0 | J12: =IF(P12="Выходной",SUM(D12*150)*1.5,SUM(D12*150)) -> 0 | K12: =IF(OR(WEEKDAY(A12)=1,WEEKDAY(A12)=7,NOT(ISERROR(MATCH(A12,[1]Праздники!A:A,0)))),SUM(E12*225)*1.5,SUM(E12*225)) -> 0 | L12: =IF(OR(WEEKDAY(A12)=1,WEEKDAY(A12)=7,NOT(ISERROR(MATCH(A12,[1]Праздники!A:A,0)))),SUM(F12*225)*1.5,SUM(F12*225)) -> 0 | M12: =SUM(G12*15) -> 4298.475 | N12: =SUM(H12)*750 -> 0 | O12: =SUM(I12:N12) -> 4298.475 | P12: =IF(OR(WEEKDAY(A12)=1,WEEKDAY(A12)=7,NOT(ISERROR(MATCH(A12,[1]Праздники!A:A,0)))),"Выходной","Рабочий") -> Выходной
A13: 46089 | C13: 0 | D13: 0 | G13: =IF(A13 ="",0,G12+C13+E13-D12-F12) -> 286.565 | I13: =IF(P13="Выходной",SUM(C13*150)*1.5,SUM(C13*150)) -> 0 | J13: =IF(P13="Выходной",SUM(D13*150)*1.5,SUM(D13*150)) -> 0 | K13: =IF(OR(WEEKDAY(A13)=1,WEEKDAY(A13)=7,NOT(ISERROR(MATCH(A13,[1]Праздники!A:A,0)))),SUM(E13*225)*1.5,SUM(E13*225)) -> 0 | L13: =IF(OR(WEEKDAY(A13)=1,WEEKDAY(A13)=7,NOT(ISERROR(MATCH(A13,[1]Праздники!A:A,0)))),SUM(F13*225)*1.5,SUM(F13*225)) -> 0 | M13: =SUM(G13*15) -> 4298.475 | N13: =SUM(H13)*750 -> 0 | O13: =SUM(I13:N13) -> 4298.475 | P13: =IF(OR(WEEKDAY(A13)=1,WEEKDAY(A13)=7,NOT(ISERROR(MATCH(A13,[1]Праздники!A:A,0)))),"Выходной","Рабочий") -> Выходной
