Workbook

Sheet Лист1

Sheet Биаксплен Новосибирск
A1: =T37 -> 144133.38
A2: ="Отчет по хранению товара за " & TEXT(B5,"ММММ ГГГГ") -> Отчет по хранению товара за Апрель 2026
A3: № | B3: дата | D3: Выгрузка кол-во | E3: Загрузка кол-во | F3: Хранение | G3: Резервирование 70 т | H3: Мин. Суточный резерв 0 т | I3: переконсолидация (тонн) | J3: Паллетирование | K3: Ночная загруска выгрузка | L3: стоимость ночной загруски | M3: стоимость выгрузки | N3: стоимость загрузки | O3: стоимость хранения | P3: Стоимость резервирования | Q3: Стоимость мин.суточной бработки | R3: стоимость переконс. | S3: Стоимость паллетирования | T3: итого
A5: 1 | B5: 46113 | F5: =24.4954+D5-E5 -> 24.4954 | G5: =IF(OR(B5="",NOT(ISERROR(SEARCH("KPI",$A$2))),NOT(ISERROR(SEARCH("Полиом",$A$2)))),0,IF(70-F5<=0,0,70-F5)) -> 45.5046 | L5: =SUM(K5*240) -> 0 | M5: =SUM(D5*120) -> 0 | N5: =SUM(E5*120) -> 0 | O5: =SUM(F5*54) -> 1322.7516 | P5: =SUM(G5*54) -> 2457.2484 | Q5: =SUM(H5*120) -> 0 | R5: =SUM(I5*1000) -> 0 | S5: =SUM(J5*140) -> 0 | T5: =SUM(L5:S5) -> 3780
A6: 2 | B6: 46114 | F6: =F5-E6+D6 -> 24.4954 | G6: =IF(OR(B6="",NOT(ISERROR(SEARCH("KPI",$A$2))),NOT(ISERROR(SEARCH("Полиом",$A$2)))),0,IF(70-F6<=0,0,70-F6)) -> 45.5046 | L6: =SUM(K6*240) -> 0 | M6: =SUM(D6*120) -> 0 | N6: =SUM(E6*120) -> 0 | O6: =SUM(F6*54) -> 1322.7516 | P6: =SUM(G6*54) -> 2457.2484 | Q6: =SUM(H6*120) -> 0 | R6: =SUM(I6*1000) -> 0 | S6: =SUM(J6*140) -> 0 | T6: =SUM(L6:S6) -> 3780
A7: 3 | B7: 46115 | F7: =F6-E7+D7 -> 24.4954 | G7: =IF(OR(B7="",NOT(ISERROR(SEARCH("KPI",$A$2))),NOT(ISERROR(SEARCH("Полиом",$A$2)))),0,IF(70-F7<=0,0,70-F7)) -> 45.5046 | L7: =SUM(K7*240) -> 0 | M7: =SUM(D7*120) -> 0 | N7: =SUM(E7*120) -> 0 | O7: =SUM(F7*54) -> 1322.7516 | P7: =SUM(G7*54) -> 2457.2484 | Q7: =SUM(H7*120) -> 0 | R7: =SUM(I7*1000) -> 0 | S7: =SUM(J7*140) -> 0 | T7: =SUM(L7:S7) -> 3780
A8: 4 | B8: 46116 | F8: =F7-E8+D8 -> 24.4954 | G8: =IF(OR(B8="",NOT(ISERROR(SEARCH("KPI",$A$2))),NOT(ISERROR(SEARCH("Полиом",$A$2)))),0,IF(70-F8<=0,0,70-F8)) -> 45.5046 | L8: =SUM(K8*240) -> 0 | M8: =SUM(D8*120) -> 0 | N8: =SUM(E8*120) -> 0 | O8: =SUM(F8*54) -> 1322.7516 | P8: =SUM(G8*54) -> 2457.2484 | Q8: =SUM(H8*120) -> 0 | R8: =SUM(I8*1000) -> 0 | S8: =SUM(J8*140) -> 0 | T8: =SUM(L8:S8) -> 3780
A9: 5 | B9: 46117 | F9: =F8-E9+D9 -> 24.4954 | G9: =IF(OR(B9="",NOT(ISERROR(SEARCH("KPI",$A$2))),NOT(ISERROR(SEARCH("Полиом",$A$2)))),0,IF(70-F9<=0,0,70-F9)) -> 45.5046 | L9: =SUM(K9*240) -> 0 | M9: =SUM(D9*120) -> 0 | N9: =SUM(E9*120) -> 0 | O9: =SUM(F9*54) -> 1322.7516 | P9: =SUM(G9*54) -> 2457.2484 | Q9: =SUM(H9*120) -> 0 | R9: =SUM(I9*1000) -> 0 | S9: =SUM(J9*140) -> 0 | T9: =SUM(L9:S9) -> 3780
A10: 6 | B10: 46118 | F10: =F9-E10+D10 -> 24.4954 | G10: =IF(OR(B10="",NOT(ISERROR(SEARCH("KPI",$A$2))),NOT(ISERROR(SEARCH("Полиом",$A$2)))),0,IF(70-F10<=0,0,70-F10)) -> 45.5046 | L10: =SUM(K10*240) -> 0 | M10: =SUM(D10*120) -> 0 | N10: =SUM(E10*120) -> 0 | O10: =SUM(F10*54) -> 1322.7516 | P10: =SUM(G10*54) -> 2457.2484 | Q10: =SUM(H10*120) -> 0 | R10: =SUM(I10*1000) -> 0 | S10: =SUM(J10*140) -> 0 | T10: =SUM(L10:S10) -> 3780
A11: 7 | B11: 46119 | E11: 5.3566 | F11: =F10-E11+D11 -> 19.1388 | G11: =IF(OR(B11="",NOT(ISERROR(SEARCH("KPI",$A$2))),NOT(ISERROR(SEARCH("Полиом",$A$2)))),0,IF(70-F11<=0,0,70-F11)) -> 50.8612 | L11: =SUM(K11*240) -> 0 | M11: =SUM(D11*120) -> 0 | N11: =SUM(E11*120) -> 642.792 | O11: =SUM(F11*54) -> 1033.4952 | P11: =SUM(G11*54) -> 2746.5048 | Q11: =SUM(H11*120) -> 0 | R11: =SUM(I11*1000) -> 0 | S11: =SUM(J11*140) -> 0 | T11: =SUM(L11:S11) -> 4422.792
A12: 8 | B12: 46120 | F12: =F11-E12+D12 -> 19.1388 | G12: =IF(OR(B12="",NOT(ISERROR(SEARCH("KPI",$A$2))),NOT(ISERROR(SEARCH("Полиом",$A$2)))),0,IF(70-F12<=0,0,70-F12)) -> 50.8612 | L12: =SUM(K12*240) -> 0 | M12: =SUM(D12*120) -> 0 | N12: =SUM(E12*120) -> 0 | O12: =SUM(F12*54) -> 1033.4952 | P12: =SUM(G12*54) -> 2746.5048 | Q12: =SUM(H12*120) -> 0 | R12: =SUM(I12*1000) -> 0 | S12: =SUM(J12*140) -> 0 | T12: =SUM(L12:S12) -> 3780
A13: 9 | B13: 46121 | F13: =F12-E13+D13 -> 19.1388 | G13: =IF(OR(B13="",NOT(ISERROR(SEARCH("KPI",$A$2))),NOT(ISERROR(SEARCH("Полиом",$A$2)))),0,IF(70-F13<=0,0,70-F13)) -> 50.8612 | L13: =SUM(K13*240) -> 0 | M13: =SUM(D13*120) -> 0 | N13: =SUM(E13*120) -> 0 | O13: =SUM(F13*54) -> 1033.4952 | P13: =SUM(G13*54) -> 2746.5048 | Q13: =SUM(H13*120) -> 0 | R13: =SUM(I13*1000) -> 0 | S13: =SUM(J13*140) -> 0 | T13: =SUM(L13:S13) -> 3780
A14: 10 | B14: 46122 | E14: 16.9803 | F14: =F13-E14+D14 -> 2.1585 | G14: =IF(OR(B14="",NOT(ISERROR(SEARCH("KPI",$A$2))),NOT(ISERROR(SEARCH("Полиом",$A$2)))),0,IF(70-F14<=0,0,70-F14)) -> 67.8415 | L14: =SUM(K14*240) -> 0 | M14: =SUM(D14*120) -> 0 | N14: =SUM(E14*120) -> 2037.636 | O14: =SUM(F14*54) -> 116.559 | P14: =SUM(G14*54) -> 3663.441 | Q14: =SUM(H14*120) -> 0 | R14: =SUM(I14*1000) -> 0 | S14: =SUM(J14*140) -> 0 | T14: =SUM(L14:S14) -> 5817.636
A15: 11 | B15: 46123 | F15: =F14-E15+D15 -> 2.1585 | G15: =IF(OR(B15="",NOT(ISERROR(SEARCH("KPI",$A$2))),NOT(ISERROR(SEARCH("Полиом",$A$2)))),0,IF(70-F15<=0,0,70-F15)) -> 67.8415 | L15: =SUM(K15*240) -> 0 | M15: =SUM(D15*120) -> 0 | N15: =SUM(E15*120) -> 0 | O15: =SUM(F15*54) -> 116.559 | P15: =SUM(G15*54) -> 3663.441 | Q15: =SUM(H15*120) -> 0 | R15: =SUM(I15*1000) -> 0 | S15: =SUM(J15*140) -> 0 | T15: =SUM(L15:S15) -> 3780
A16: 12 | B16: 46124 | F16: =F15-E16+D16 -> 2.1585 | G16: =IF(OR(B16="",NOT(ISERROR(SEARCH("KPI",$A$2))),NOT(ISERROR(SEARCH("Полиом",$A$2)))),0,IF(70-F16<=0,0,70-F16)) -> 67.8415 | L16: =SUM(K16*240) -> 0 | M16: =SUM(D16*120) -> 0 | N16: =SUM(E16*120) -> 0 | O16: =SUM(F16*54) -> 116.559 | P16: =SUM(G16*54) -> 3663.441 | Q16: =SUM(H16*120) -> 0 | R16: =SUM(I16*1000) -> 0 | S16: =SUM(J16*140) -> 0 | T16: =SUM(L16:S16) -> 3780
A17: 13 | B17: 46125 | F17: =F16-E17+D17 -> 2.1585 | G17: =IF(OR(B17="",NOT(ISERROR(SEARCH("KPI",$A$2))),NOT(ISERROR(SEARCH("Полиом",$A$2)))),0,IF(70-F17<=0,0,70-F17)) -> 67.8415 | L17: =SUM(K17*240) -> 0 | M17: =SUM(D17*120) -> 0 | N17: =SUM(E17*120) -> 0 | O17: =SUM(F17*54) -> 116.559 | P17: =SUM(G17*54) -> 3663.441 | Q17: =SUM(H17*120) -> 0 | R17: =SUM(I17*1000) -> 0 | S17: =SUM(J17*140) -> 0 | T17: =SUM(L17:S17) -> 3780
A18: 14 | B18: 46126 | F18: =F17-E18+D18 -> 2.1585 | G18: =IF(OR(B18="",NOT(ISERROR(SEARCH("KPI",$A$2))),NOT(ISERROR(SEARCH("Полиом",$A$2)))),0,IF(70-F18<=0,0,70-F18)) -> 67.8415 | L18: =SUM(K18*240) -> 0 | M18: =SUM(D18*120) -> 0 | N18: =SUM(E18*120) -> 0 | O18: =SUM(F18*54) -> 116.559 | P18: =SUM(G18*54) -> 3663.441 | Q18: =SUM(H18*120) -> 0 | R18: =SUM(I18*1000) -> 0 | S18: =SUM(J18*140) -> 0 | T18: =SUM(L18:S18) -> 3780
A19: 15 | B19: 46127 | F19: =F18-E19+D19 -> 2.1585 | G19: =IF(OR(B19="",NOT(ISERROR(SEARCH("KPI",$A$2))),NOT(ISERROR(SEARCH("Полиом",$A$2)))),0,IF(70-F19<=0,0,70-F19)) -> 67.8415 | L19: =SUM(K19*240) -> 0 | M19: =SUM(D19*120) -> 0 | N19: =SUM(E19*120) -> 0 | O19: =SUM(F19*54) -> 116.559 | P19: =SUM(G19*54) -> 3663.441 | Q19: =SUM(H19*120) -> 0 | R19: =SUM(I19*1000) -> 0 | S19: =SUM(J19*140) -> 0 | T19: =SUM(L19:S19) -> 3780
A20: 16 | B20: 46128 | F20: =F19-E20+D20 -> 2.1585 | G20: =IF(OR(B20="",NOT(ISERROR(SEARCH("KPI",$A$2))),NOT(ISERROR(SEARCH("Полиом",$A$2)))),0,IF(70-F20<=0,0,70-F20)) -> 67.8415 | L20: =SUM(K20*240) -> 0 | M20: =SUM(D20*120) -> 0 | N20: =SUM(E20*120) -> 0 | O20: =SUM(F20*54) -> 116.559 | P20: =SUM(G20*54) -> 3663.441 | Q20: =SUM(H20*120) -> 0 | R20: =SUM(I20*1000) -> 0 | S20: =SUM(J20*140) -> 0 | T20: =SUM(L20:S20) -> 3780
A21: 17 | B21: 46129 | F21: =F20-E21+D21 -> 2.1585 | G21: =IF(OR(B21="",NOT(ISERROR(SEARCH("KPI",$A$2))),NOT(ISERROR(SEARCH("Полиом",$A$2)))),0,IF(70-F21<=0,0,70-F21)) -> 67.8415 | L21: =SUM(K21*240) -> 0 | M21: =SUM(D21*120) -> 0 | N21: =SUM(E21*120) -> 0 | O21: =SUM(F21*54) -> 116.559 | P21: =SUM(G21*54) -> 3663.441 | Q21: =SUM(H21*120) -> 0 | R21: =SUM(I21*1000) -> 0 | S21: =SUM(J21*140) -> 0 | T21: =SUM(L21:S21) -> 3780
A22: 18 | B22: 46130 | F22: =F21-E22+D22 -> 2.1585 | G22: =IF(OR(B22="",NOT(ISERROR(SEARCH("KPI",$A$2))),NOT(ISERROR(SEARCH("Полиом",$A$2)))),0,IF(70-F22<=0,0,70-F22)) -> 67.8415 | L22: =SUM(K22*240) -> 0 | M22: =SUM(D22*120) -> 0 | N22: =SUM(E22*120) -> 0 | O22: =SUM(F22*54) -> 116.559 | P22: =SUM(G22*54) -> 3663.441 | Q22: =SUM(H22*120) -> 0 | R22: =SUM(I22*1000) -> 0 | S22: =SUM(J22*140) -> 0 | T22: =SUM(L22:S22) -> 3780
A23: 19 | B23: 46131 | F23: =F22-E23+D23 -> 2.1585 | G23: =IF(OR(B23="",NOT(ISERROR(SEARCH("KPI",$A$2))),NOT(ISERROR(SEARCH("Полиом",$A$2)))),0,IF(70-F23<=0,0,70-F23)) -> 67.8415 | L23: =SUM(K23*240) -> 0 | M23: =SUM(D23*120) -> 0 | N23: =SUM(E23*120) -> 0 | O23: =SUM(F23*54) -> 116.559 | P23: =SUM(G23*54) -> 3663.441 | Q23: =SUM(H23*120) -> 0 | R23: =SUM(I23*1000) -> 0 | S23: =SUM(J23*140) -> 0 | T23: =SUM(L23:S23) -> 3780
A24: 20 | B24: 46132 | F24: =F23-E24+D24 -> 2.1585 | G24: =IF(OR(B24="",NOT(ISERROR(SEARCH("KPI",$A$2))),NOT(ISERROR(SEARCH("Полиом",$A$2)))),0,IF(70-F24<=0,0,70-F24)) -> 67.8415 | L24: =SUM(K24*240) -> 0 | M24: =SUM(D24*120) -> 0 | N24: =SUM(E24*120) -> 0 | O24: =SUM(F24*54) -> 116.559 | P24: =SUM(G24*54) -> 3663.441 | Q24: =SUM(H24*120) -> 0 | R24: =SUM(I24*1000) -> 0 | S24: =SUM(J24*140) -> 0 | T24: =SUM(L24:S24) -> 3780
A25: 21 | B25: 46133 | F25: =F24-E25+D25 -> 2.1585 | G25: =IF(OR(B25="",NOT(ISERROR(SEARCH("KPI",$A$2))),NOT(ISERROR(SEARCH("Полиом",$A$2)))),0,IF(70-F25<=0,0,70-F25)) -> 67.8415 | L25: =SUM(K25*240) -> 0 | M25: =SUM(D25*120) -> 0 | N25: =SUM(E25*120) -> 0 | O25: =SUM(F25*54) -> 116.559 | P25: =SUM(G25*54) -> 3663.441 | Q25: =SUM(H25*120) -> 0 | R25: =SUM(I25*1000) -> 0 | S25: =SUM(J25*140) -> 0 | T25: =SUM(L25:S25) -> 3780
A26: 22 | B26: 46134 | D26: 8.2948 | F26: =F25-E26+D26 -> 10.4533 | G26: =IF(OR(B26="",NOT(ISERROR(SEARCH("KPI",$A$2))),NOT(ISERROR(SEARCH("Полиом",$A$2)))),0,IF(70-F26<=0,0,70-F26)) -> 59.5467 | L26: =SUM(K26*240) -> 0 | M26: =SUM(D26*120) -> 995.376 | N26: =SUM(E26*120) -> 0 | O26: =SUM(F26*54) -> 564.4782 | P26: =SUM(G26*54) -> 3215.5218 | Q26: =SUM(H26*120) -> 0 | R26: =SUM(I26*1000) -> 0 | S26: =SUM(J26*140) -> 0 | T26: =SUM(L26:S26) -> 4775.376
A27: 23 | B27: 46135 | E27: 4.7398 | F27: =F26-E27+D27 -> 5.7135 | G27: =IF(OR(B27="",NOT(ISERROR(SEARCH("KPI",$A$2))),NOT(ISERROR(SEARCH("Полиом",$A$2)))),0,IF(70-F27<=0,0,70-F27)) -> 64.2865 | L27: =SUM(K27*240) -> 0 | M27: =SUM(D27*120) -> 0 | N27: =SUM(E27*120) -> 568.776 | O27: =SUM(F27*54) -> 308.529 | P27: =SUM(G27*54) -> 3471.471 | Q27: =SUM(H27*120) -> 0 | R27: =SUM(I27*1000) -> 0 | S27: =SUM(J27*140) -> 0 | T27: =SUM(L27:S27) -> 4348.776
A28: 24 | B28: 46136 | E28: 4.1461 | F28: =F27-E28+D28 -> 1.5674 | G28: =IF(OR(B28="",NOT(ISERROR(SEARCH("KPI",$A$2))),NOT(ISERROR(SEARCH("Полиом",$A$2)))),0,IF(70-F28<=0,0,70-F28)) -> 68.4326 | L28: =SUM(K28*240) -> 0 | M28: =SUM(D28*120) -> 0 | N28: =SUM(E28*120) -> 497.532 | O28: =SUM(F28*54) -> 84.6396 | P28: =SUM(G28*54) -> 3695.3604 | Q28: =SUM(H28*120) -> 0 | R28: =SUM(I28*1000) -> 0 | S28: =SUM(J28*140) -> 0 | T28: =SUM(L28:S28) -> 4277.532
A29: 25 | B29: 46137 | F29: =F28-E29+D29 -> 1.5674 | G29: =IF(OR(B29="",NOT(ISERROR(SEARCH("KPI",$A$2))),NOT(ISERROR(SEARCH("Полиом",$A$2)))),0,IF(70-F29<=0,0,70-F29)) -> 68.4326 | L29: =SUM(K29*240) -> 0 | M29: =SUM(D29*120) -> 0 | N29: =SUM(E29*120) -> 0 | O29: =SUM(F29*54) -> 84.6396 | P29: =SUM(G29*54) -> 3695.3604 | Q29: =SUM(H29*120) -> 0 | R29: =SUM(I29*1000) -> 0 | S29: =SUM(J29*140) -> 0 | T29: =SUM(L29:S29) -> 3780
A30: 26 | B30: 46138 | F30: =F29-E30+D30 -> 1.5674 | G30: =IF(OR(B30="",NOT(ISERROR(SEARCH("KPI",$A$2))),NOT(ISERROR(SEARCH("Полиом",$A$2)))),0,IF(70-F30<=0,0,70-F30)) -> 68.4326 | L30: =SUM(K30*240) -> 0 | M30: =SUM(D30*120) -> 0 | N30: =SUM(E30*120) -> 0 | O30: =SUM(F30*54) -> 84.6396 | P30: =SUM(G30*54) -> 3695.3604 | Q30: =SUM(H30*120) -> 0 | R30: =SUM(I30*1000) -> 0 | S30: =SUM(J30*140) -> 0 | T30: =SUM(L30:S30) -> 3780
A31: 27 | B31: 46139 | F31: =F30-E31+D31 -> 1.5674 | G31: =IF(OR(B31="",NOT(ISERROR(SEARCH("KPI",$A$2))),NOT(ISERROR(SEARCH("Полиом",$A$2)))),0,IF(70-F31<=0,0,70-F31)) -> 68.4326 | L31: =SUM(K31*240) -> 0 | M31: =SUM(D31*120) -> 0 | N31: =SUM(E31*120) -> 0 | O31: =SUM(F31*54) -> 84.6396 | P31: =SUM(G31*54) -> 3695.3604 | Q31: =SUM(H31*120) -> 0 | R31: =SUM(I31*1000) -> 0 | S31: =SUM(J31*140) -> 0 | T31: =SUM(L31:S31) -> 3780
A32: 28 | B32: 46140 | F32: =F31-E32+D32 -> 1.5674 | G32: =IF(OR(B32="",NOT(ISERROR(SEARCH("KPI",$A$2))),NOT(ISERROR(SEARCH("Полиом",$A$2)))),0,IF(70-F32<=0,0,70-F32)) -> 68.4326 | L32: =SUM(K32*240) -> 0 | M32: =SUM(D32*120) -> 0 | N32: =SUM(E32*120) -> 0 | O32: =SUM(F32*54) -> 84.6396 | P32: =SUM(G32*54) -> 3695.3604 | Q32: =SUM(H32*120) -> 0 | R32: =SUM(I32*1000) -> 0 | S32: =SUM(J32*140) -> 0 | T32: =SUM(L32:S32) -> 3780
A33: 29 | B33: 46141 | F33: =F32-E33+D33 -> 1.5674 | G33: =IF(OR(B33="",NOT(ISERROR(SEARCH("KPI",$A$2))),NOT(ISERROR(SEARCH("Полиом",$A$2)))),0,IF(70-F33<=0,0,70-F33)) -> 68.4326 | L33: =SUM(K33*240) -> 0 | M33: =SUM(D33*120) -> 0 | N33: =SUM(E33*120) -> 0 | O33: =SUM(F33*54) -> 84.6396 | P33: =SUM(G33*54) -> 3695.3604 | Q33: =SUM(H33*120) -> 0 | R33: =SUM(I33*1000) -> 0 | S33: =SUM(J33*140) -> 0 | T33: =SUM(L33:S33) -> 3780
A34: 30 | B34: 46142 | F34: =F33-E34+D34 -> 1.5674 | G34: =IF(OR(B34="",NOT(ISERROR(SEARCH("KPI",$A$2))),NOT(ISERROR(SEARCH("Полиом",$A$2)))),0,IF(70-F34<=0,0,70-F34)) -> 68.4326 | L34: =SUM(K34*240) -> 0 | M34: =SUM(D34*120) -> 0 | N34: =SUM(E34*120) -> 0 | O34: =SUM(F34*54) -> 84.6396 | P34: =SUM(G34*54) -> 3695.3604 | Q34: =SUM(H34*120) -> 0 | R34: =SUM(I34*1000) -> 0 | S34: =SUM(J34*140) -> 0 | T34: =SUM(L34:S34) -> 3780
L35: =SUM(K35*240) -> 0 | M35: =SUM(D35*120) -> 0 | N35: =SUM(E35*120) -> 0 | O35: =SUM(F35*54) -> 0 | P35: =SUM(G35*54) -> 0 | Q35: =SUM(H35*120) -> 0 | R35: =SUM(I35*1000) -> 0 | S35: =SUM(J35*140) -> 0 | T35: =SUM(L35:S35) -> 0
F36: =SUM(F5:F35) -> 257.4294 | G36: =SUM(G5:G35) -> 1842.5706 | H36: =SUM(H5:H35) -> 0 | I36: =SUM(I5:I35) -> 0 | J36: =SUM(J5:J35) -> 0 | K36: =SUM(K5:K35) -> 0 | L36: =SUM(L5:L35) -> 0 | M36: =SUM(M5:M35) -> 995.376 | ... T36: =SUM(T5:T35) -> 118142.11
T37: =T36*1.22 -> 144133.38

Sheet ИТОГО
A1: =G16 -> 1.3540776e+08
I2: ТОП
A3: Склад | B3: Сибур | C3: Завод | D3: Русвинил | E3: Клиенты сибура | F3: Остальные | G3: Итого | I3: Казань_Автосервисная | J3: 23143268
A4: Баумана | B4: =INDEX($M$45:$M$54,MATCH(A4,$A$45:$A$54,0),1) -> 6329326.2 | C4: 0 | D4: =INDEX($B$57:$B$73,MATCH(A4,$A$57:$A$73,0),1) -> 0 | E4: =SUMIF($F$19:$F$42,A4,$G$19:$G$42) -> 0 | F4: =SUMIF($B$19:$B$27,A4,$C$19:$C$27) -> 78580 | G4: =SUM(B4:F4) -> 6407906.2 | I4: Нижнекамск завод | J4: 19482962
A5: Новикова-Прибоя | B5: =INDEX($M$45:$M$54,MATCH(A5,$A$45:$A$54,0),1) -> 10571819 | C5: 0 | D5: =INDEX($B$57:$B$73,MATCH(A5,$A$57:$A$73,0),1) -> 0 | E5: =SUMIF($F$19:$F$42,A5,$G$19:$G$42) -> 0 | F5: =SUMIF($B$19:$B$27,A5,$C$19:$C$27) -> 0 | G5: =SUM(B5:F5) -> 10571819 | I5: Новикова-Прибоя | J5: 14483152
A6: Екатеринбург | B6: =INDEX($M$45:$M$54,MATCH(A6,$A$45:$A$54,0),1) -> 12214093 | C6: 0 | D6: =INDEX($B$57:$B$73,MATCH(A6,$A$57:$A$73,0),1) -> 0 | E6: =SUMIF($F$19:$F$42,A6,$G$19:$G$42) -> 0 | F6: =SUMIF($B$19:$B$27,A6,$C$19:$C$27) -> 0 | G6: =SUM(B6:F6) -> 12214093 | I6: Екатеринбург | J6: 11908609
A7: Новосибирск | B7: =INDEX($M$45:$M$54,MATCH(A7,$A$45:$A$54,0),1) -> 6187376.9 | C7: 0 | D7: =INDEX($B$57:$B$73,MATCH(A7,$A$57:$A$73,0),1) -> 0 | E7: =SUMIF($F$19:$F$42,A7,$G$19:$G$42) -> 144133.38 | F7: =SUMIF($B$19:$B$27,A7,$C$19:$C$27) -> 0 | G7: =SUM(B7:F7) -> 6331510.3 | I7: Баумана | J7: 11544503
A8: Новосибирск_Пасечная | B8: =INDEX($M$45:$M$54,MATCH(A8,$A$45:$A$54,0),1) -> 4970334.4 | C8: 0 | D8: =INDEX($B$57:$B$73,MATCH(A8,$A$57:$A$73,0),1) -> 0 | E8: =SUMIF($F$19:$F$42,A8,$G$19:$G$42) -> 0 | F8: =SUMIF($B$19:$B$27,A8,$C$19:$C$27) -> 0 | G8: =SUM(B8:F8) -> 4970334.4
A9: Казань_Автосервисная | B9: =INDEX($M$45:$M$54,MATCH(A9,$A$45:$A$54,0),1) -> 18549407 | C9: 0 | D9: =INDEX($B$57:$B$73,MATCH(A9,$A$57:$A$73,0),1) -> 0 | E9: =SUMIF($F$19:$F$42,A9,$G$19:$G$42) -> 0 | F9: =SUMIF($B$19:$B$27,A9,$C$19:$C$27) -> 0 | G9: =SUM(B9:F9) -> 18549407 | I9: Казань_Приволжская | J9: 9900926.9
A10: Казань_Приволжская | B10: =INDEX($M$45:$M$54,MATCH(A10,$A$45:$A$54,0),1) -> 9115018.9 | C10: 0 | D10: =INDEX($B$57:$B$73,MATCH(A10,$A$57:$A$73,0),1) -> 0 | E10: =SUMIF($F$19:$F$42,A10,$G$19:$G$42) -> 0 | F10: =SUMIF($B$19:$B$27,A10,$C$19:$C$27) -> 0 | G10: =SUM(B10:F10) -> 9115018.9 | I10: Зеленодольск | J10: 9082789.1
A11: Зеленодольск | B11: =INDEX($M$45:$M$54,MATCH(A11,$A$45:$A$54,0),1) -> 8418981.2 | C11: 0 | D11: =INDEX($B$57:$B$73,MATCH(A11,$A$57:$A$73,0),1) -> 0 | E11: =SUMIF($F$19:$F$42,A11,$G$19:$G$42) -> 0 | F11: =SUMIF($B$19:$B$27,A11,$C$19:$C$27) -> 0 | G11: =SUM(B11:F11) -> 8418981.2 | I11: Новосибирск | J11: 7932975.6
A12: Нижнекамск | B12: =INDEX($M$45:$M$54,MATCH(A12,$A$45:$A$54,0),1) -> 1119397.2 | C12: 0 | D12: =INDEX($B$57:$B$73,MATCH(A12,$A$57:$A$73,0),1) -> 0 | E12: =SUMIF($F$19:$F$42,A12,$G$19:$G$42) -> 12010.656 | F12: =SUMIF($B$19:$B$27,A12,$C$19:$C$27) -> 0 | G12: =SUM(B12:F12) -> 1131407.8 | I12: Нижнекамск | J12: 7580244.6
A13: Нижнекамск завод | B13: 0 | C13: =C29+C37 -> 57697281 | D13: =INDEX($B$57:$B$73,MATCH(A13,$A$57:$A$73,0),1) -> 0 | E13: =SUMIF($F$19:$F$42,A13,$G$19:$G$42) -> 0 | F13: =SUMIF($B$19:$B$27,A13,$C$19:$C$27) -> 0 | G13: =SUM(B13:F13) -> 57697281 | I13: ГАЗ | J13: 6720000
A14: Монастырка | B14: 0 | C14: 0 | D14: =INDEX($B$57:$B$73,MATCH(A14,$A$57:$A$73,0),1) -> 0 | E14: =SUMIF($F$19:$F$42,A14,$G$19:$G$42) -> 0 | F14: =SUMIF($B$19:$B$27,A14,$C$19:$C$27) -> 0 | G14: =SUM(B14:F14) -> 0 | I14: Монастырка | J14: 2464921.6
A15: Березовая Пойма | B15: =INDEX($M$45:$M$54,MATCH(A15,$A$45:$A$54,0),1) -> 0 | C15: 0 | D15: =INDEX($B$57:$B$73,MATCH(A15,$A$57:$A$73,0),1) -> 0 | E15: =SUMIF($F$19:$F$42,A15,$G$19:$G$42) -> 0 | F15: =SUMIF($B$19:$B$27,A15,$C$19:$C$27) -> 0 | G15: =SUM(B15:F15) -> 0
B16: =SUM(B4:B15) -> 77475753 | C16: =SUM(C4:C15) -> 57697281 | D16: =SUM(D4:D15) -> 0 | E16: =SUM(E4:E15) -> 156144.03 | F16: =SUM(F4:F15) -> 78580 | G16: =SUM(G4:G15) -> 1.3540776e+08
A18: Остальные клиенты | C18: =SUM(C19:C27) -> 78580 | E18: Клиенты сибура | G18: =SUM(G19:G41) -> 156144.03
A19: Стройтех | B19: Баумана | C19: {=IFERROR(INDIRECT("'" & A19 & "'!A1"),)} -> 22125 | E19: Приоритет | F19: Баумана | G19: {=IFERROR(INDIRECT("'" & E19 & " " & F19 & "'!A1"),0)} -> 0
A20: Ергарда | B20: Баумана | C20: {=IFERROR(INDIRECT("'" & A20 & "'!A1"),)} -> 8640 | E20: Фармпласт | F20: Баумана | G20: {=IFERROR(INDIRECT("'" & E20 & " " & F20 & "'!A1"),0)} -> 0
A21: Литейные решения | B21: Баумана | C21: {=IFERROR(INDIRECT("'" & A21 & "'!A1"),)} -> 16819 | E21: Юг Полимер | F21: Баумана | G21: {=IFERROR(INDIRECT("'" & E21 & " " & F21 & "'!A1"),0)} -> 0
A22: Сандекс | B22: Баумана | C22: {=IFERROR(INDIRECT("'" & A22 & "'!A1"),)} -> 22922.4 | E22: Центрополимер | F22: Екатеринбург | G22: {=IFERROR(INDIRECT("'" & E22 & " " & F22 & "'!A1"),0)} -> 0
A23: ЛС-Техномет | B23: Баумана | C23: {=IFERROR(INDIRECT("'" & A23 & "'!A1"),)} -> 8073.6 | E23: Приоритет | F23: Екатеринбург | G23: {=IFERROR(INDIRECT("'" & E23 & " " & F23 & "'!A1"),0)} -> 0
A24: РусДжам | B24: ГАЗ | C24: {=IFERROR(INDIRECT("'" & A24 & "'!A1"),)} -> 0 | E24: Фармпласт | F24: Екатеринбург | G24: {=IFERROR(INDIRECT("'" & E24 & " " & F24 & "'!A1"),0)} -> 0
A25: Виго | B25: Новикова-Прибоя | C25: {=IFERROR(INDIRECT("'" & A25 & "'!A1"),)} -> 0 | E25: Приоритет | F25: Зеленодольск | G25: {=IFERROR(INDIRECT("'" & E25 & " " & F25 & "'!A1"),0)} -> 0
A26: Доктор Франк | B26: Новикова-Прибоя | C26: {=IFERROR(INDIRECT("'" & A26 & "'!A1"),)} -> 0 | E26: Данафлекс | F26: Зеленодольск | G26: {=IFERROR(INDIRECT("'" & E26 & " " & F26 & "'!t37"),0)} -> 0
A27: Нефтезол | B27: Новикова-Прибоя | C27: {=IFERROR(INDIRECT("'" & A27 & "'!A1"),)} -> 0 | E27: ИП Ксендз | F27: Нижнекамск | G27: {=IFERROR(INDIRECT("'" & E27 & " " & F27 & "'!A1"),0)} -> 0
E28: Фармпласт | F28: Новикова-Прибоя | G28: {=IFERROR(INDIRECT("'" & E28 & " " & F28 & "'!A1"),0)} -> 0
A29: Нижнекамск завод | C29: =SUM(C30:C35) -> 47534554 | E29: Центрополимер | F29: Новикова-Прибоя | G29: {=IFERROR(INDIRECT("'" & E29 & " " & F29 & "'!A1"),0)} -> 0
A30: ПРР | C30: {=INDIRECT("'" & A29 & "'!F17")+68919} -> 16236409 | E30: Юг Полимер | F30: Новикова-Прибоя | G30: {=IFERROR(INDIRECT("'" & E30 & " " & F30 & "'!A1"),0)} -> 0
A31: Кладовки | C31: {=INDIRECT("'" & A29 & "'!F16")} -> 0 | E31: Приоритет | F31: Новикова-Прибоя | G31: {=IFERROR(INDIRECT("'" & E31 & " " & F31 & "'!A1"),0)} -> 0
A32: Стропальщики | C32: {=INDIRECT("'" & A29 & "'!F18")} -> 732000 | E32: Биаксплен | F32: Новосибирск | G32: {=IFERROR(INDIRECT("'" & E32 & " " & F32 & "'!A1"),0)} -> 144133.38
A33: Мойка контейнеров | C33: {=INDIRECT("'" & A29 & "'!F19")} -> 2058457 | E33: Центрополимер | F33: Новосибирск | G33: {=IFERROR(INDIRECT("'" & E33 & " " & F33 & "'!A1"),0)} -> 0
A34: МТО | C34: {=INDIRECT("'" & A29 & "'!F20")} -> 21892054 | E34: Фармпласт | F34: Новосибирск | G34: {=IFERROR(INDIRECT("'" & E34 & " " & F34 & "'!A1"),0)} -> 0
A35: МТО 2520 | C35: {=INDIRECT("'" & A29 & "'!F21")} -> 6615634
E36: Юг Полимер | F36: Зеленодольск | G36: {=IFERROR(INDIRECT("'" & E36 & " " & F36 & "'!A1"),0)} -> 0
A37: Контейнерные площадки | C37: =SUM(C38:C42) -> 10162727 | E37: Фармпласт | F37: Казань_Автосервисная | G37: {=IFERROR(INDIRECT("'" & E37 & " " & F37 & "'!A1"),0)} -> 0
A38: КОС | C38: =3098507 -> 3098507 | E38: Приоритет | F38: Казань_Приволжская | G38: {=IFERROR(INDIRECT("'" & E38 & " " & F38 & "'!A1"),0)} -> 0
A39: Нижнекамск | C39: 7064220 | E39: Центрополимер | F39: Баумана | G39: {=IFERROR(INDIRECT("'" & E39 & " " & F39 & "'!A1"),0)} -> 0
E40: Приоритет | F40: Казань_Автосервисная | G40: {=IFERROR(INDIRECT("'" & E40 & " " & F40 & "'!A1"),0)} -> 0
E41: Оникс | F41: Нижнекамск | G41: {=IFERROR(INDIRECT("'" & E41 & " " & F41 & "'!A1"),0)} -> 12010.656
...

Sheet Другое

Sheet Нижнекамск завод
A9: № | B9: Наименование услуг (работ) | C9: Ед. изм. | D9: Количество | E9: Цена | F9: Сумма
A14: Итого: | F14: =SUM(F10:F13) -> 0
A15: Без налога (НДС) | F15: =SUM(F14) -> 0
A16: Всего (с учетом НДС) | F16: =SUM(F15)*1.2 -> 0
A17: Вышеперечисленные услуги (работы) выполнены полностью. | E17: ПРР | F17: 16167490
A18: ПОКЛАЖЕДАТЕЛЬ претензий по объему, качеству и срокам оказания услуг претензий не имеет. | E18: Стропальщики | F18: 732000
E19: Контейнеры | F19: 2058457
E20: МТО | F20: 21892054
E21: МТО 2520 | F21: 6615634
A22: ООО "ДТМ" | D22: ПАО "Нижнекамскнефтехим"
A24: ____________________Молькова Т.Ю. | B24: Расстегаев Д.О. | D24: ____________________

Sheet Сводка
A1: KPI | B1: Баумана | C1: =INDEX(INDIRECT("ИТОГО!$B$45:$L$54"),MATCH(Сводка!B1,INDIRECT("ИТОГО!$A$45:$A$54"),0),MATCH(Сводка!A1,INDIRECT("ИТОГО!$B$44:$L$44"),0)) -> 78394.96
A2: Полиом | B2: Баумана | C2: =INDEX(INDIRECT("ИТОГО!$B$45:$L$54"),MATCH(Сводка!B2,INDIRECT("ИТОГО!$A$45:$A$54"),0),MATCH(Сводка!A2,INDIRECT("ИТОГО!$B$44:$L$44"),0)) -> 427145.58
A3: Полимеры | B3: Баумана | C3: =INDEX(INDIRECT("ИТОГО!$B$45:$L$54"),MATCH(Сводка!B3,INDIRECT("ИТОГО!$A$45:$A$54"),0),MATCH(Сводка!A3,INDIRECT("ИТОГО!$B$44:$L$44"),0)) -> 5823785.6
A4: Каучук | B4: Баумана | C4: =INDEX(INDIRECT("ИТОГО!$B$45:$L$54"),MATCH(Сводка!B4,INDIRECT("ИТОГО!$A$45:$A$54"),0),MATCH(Сводка!A4,INDIRECT("ИТОГО!$B$44:$L$44"),0)) -> 0
A5: ПСОН | B5: Баумана | C5: =INDEX(INDIRECT("ИТОГО!$B$45:$L$54"),MATCH(Сводка!B5,INDIRECT("ИТОГО!$A$45:$A$54"),0),MATCH(Сводка!A5,INDIRECT("ИТОГО!$B$44:$L$44"),0)) -> 0
A6: Данафлекс | B6: Баумана | C6: =INDEX(INDIRECT("ИТОГО!$B$45:$L$54"),MATCH(Сводка!B6,INDIRECT("ИТОГО!$A$45:$A$54"),0),MATCH(Сводка!A6,INDIRECT("ИТОГО!$B$44:$L$44"),0)) -> 0
A7: СБС | B7: Баумана | C7: =INDEX(INDIRECT("ИТОГО!$B$45:$L$54"),MATCH(Сводка!B7,INDIRECT("ИТОГО!$A$45:$A$54"),0),MATCH(Сводка!A7,INDIRECT("ИТОГО!$B$44:$L$44"),0)) -> 0
A8: Порошок | B8: Баумана | C8: =INDEX(INDIRECT("ИТОГО!$B$45:$L$54"),MATCH(Сводка!B8,INDIRECT("ИТОГО!$A$45:$A$54"),0),MATCH(Сводка!A8,INDIRECT("ИТОГО!$B$44:$L$44"),0)) -> 0
A9: НПЭГ | B9: Баумана | C9: =INDEX(INDIRECT("ИТОГО!$B$45:$L$54"),MATCH(Сводка!B9,INDIRECT("ИТОГО!$A$45:$A$54"),0),MATCH(Сводка!A9,INDIRECT("ИТОГО!$B$44:$L$44"),0)) -> 0
A10: Экспорт | B10: Баумана | C10: =INDEX(INDIRECT("ИТОГО!$B$45:$L$54"),MATCH(Сводка!B10,INDIRECT("ИТОГО!$A$45:$A$54"),0),MATCH(Сводка!A10,INDIRECT("ИТОГО!$B$44:$L$44"),0)) -> 0
A11: Доп услуги | B11: Баумана | C11: =INDEX(INDIRECT("ИТОГО!$B$45:$L$54"),MATCH(Сводка!B11,INDIRECT("ИТОГО!$A$45:$A$54"),0),MATCH(Сводка!A11,INDIRECT("ИТОГО!$B$44:$L$44"),0)) -> 0
A12: KPI | B12: Новикова-Прибоя | C12: =INDEX(INDIRECT("ИТОГО!$B$45:$L$54"),MATCH(Сводка!B12,INDIRECT("ИТОГО!$A$45:$A$54"),0),MATCH(Сводка!A12,INDIRECT("ИТОГО!$B$44:$L$44"),0)) -> 39526.16
... A99: Доп услуги | B99: Казань_Приволжская | C99: =INDEX(INDIRECT("ИТОГО!$B$45:$L$54"),MATCH(Сводка!B99,INDIRECT("ИТОГО!$A$45:$A$54"),0),MATCH(Сводка!A99,INDIRECT("ИТОГО!$B$44:$L$44"),0)) -> 0
A100: Русвинил | B100: Баумана | C100: {=INDIRECT("ИТОГО!B57")} -> 0
A101: Русвинил | B101: Новикова-Прибоя | C101: {=INDIRECT("ИТОГО!B58")} -> 0
A102: Русвинил | B102: Березовая Пойма | C102: {=INDIRECT("ИТОГО!B67")} -> 0
A103: ПРР | B103: Нижнекамск завод | C103: {=INDIRECT("ИТОГО!C30")} -> 16236409
A104: Кладовки | B104: Нижнекамск завод | C104: {=INDIRECT("ИТОГО!C31")} -> 0
A105: Стропальщики | B105: Нижнекамск завод | C105: {=INDIRECT("ИТОГО!C32")} -> 732000
A106: Мойка контейнеров | B106: Нижнекамск завод | C106: {=INDIRECT("ИТОГО!C33")} -> 2058457
A107: МТО | B107: Нижнекамск завод | C107: {=INDIRECT("ИТОГО!C34")} -> 21892054
A108: МТО 2520 | B108: Нижнекамск завод | C108: {=INDIRECT("ИТОГО!C35")} -> 6615634
A109: КП КОС | B109: Нижнекамск завод | C109: {=INDIRECT("ИТОГО!C38")} -> 3098507
A110: КП Нижнекамск | B110: Нижнекамск завод | C110: {=INDIRECT("ИТОГО!C39")} -> 7064220
A111: Стройтех | B111: Баумана | C111: {=INDIRECT("ИТОГО!C19")} -> 22125
A112: Ергарда | B112: Баумана | C112: {=INDIRECT("ИТОГО!C20")} -> 8640
A113: Литейные решения | B113: Баумана | C113: {=INDIRECT("ИТОГО!C21")} -> 16819
A114: Сандекс | B114: Баумана | C114: {=INDIRECT("ИТОГО!C22")} -> 22922.4
A115: ЛС-Техномет | B115: Баумана | C115: {=INDIRECT("ИТОГО!C23")} -> 8073.6
A116: Приоритет | B116: Баумана | C116: {=INDIRECT("ИТОГО!G19")} -> 0
A117: Фармпласт | B117: Баумана | C117: {=INDIRECT("ИТОГО!G20")} -> 0
A118: Юг Полимер | B118: Баумана | C118: {=INDIRECT("ИТОГО!G21")} -> 0
A119: Центрополимер | B119: Екатеринбург | C119: {=INDIRECT("ИТОГО!G22")} -> 0
A120: Приоритет | B120: Екатеринбург | C120: {=INDIRECT("ИТОГО!G23")} -> 0
A121: Фармпласт | B121: Екатеринбург | C121: {=INDIRECT("ИТОГО!G24")} -> 0
A122: Приоритет | B122: Зеленодольск | C122: {=INDIRECT("ИТОГО!G25")} -> 0
A123: Данафлекс | B123: Зеленодольск | C123: {=INDIRECT("ИТОГО!G26")} -> 0
A124: ИП Ксендз | B124: Нижнекамск | C124: {=INDIRECT("ИТОГО!G27")} -> 0
A125: Фармпласт | B125: Новикова-Прибоя | C125: {=INDIRECT("ИТОГО!G28")} -> 0
A126: Центрополимер | B126: Новикова-Прибоя | C126: {=INDIRECT("ИТОГО!G29")} -> 0
...

Sheet Нижнекамск экспорт
A3: =IF(DAY(TODAY())>27,"Акт № от " & TEXT(TODAY(),"ДД ММММ ГГГГ"),"Акт № от " & TEXT(TODAY()-DAY(TODAY()),"ДД ММММ ГГГГ")) -> Акт № от 31 Май 2026
A4: =IF(DAY(TODAY()) > 22, "выполненных работ (оказанных услуг) за " & TEXT(TODAY(),"ММММ ГГГГ"),"выполненных работ (оказанных услуг) за " & TEXT(TODAY()-DAY(TODAY()),"ММММ ГГГГ")) -> выполненных работ (оказанных услуг) за Май 2026
A5: по Договору хранения № СХ.47103 от «10» апреля 2025 г.
A7: Во исполнение Договора в период с 01 Апрель 2026 г. По 30 Апрель 2026 г. ХРАНИТЕЛЬ оказал ПОКЛАЖЕДАТЕЛЮ следующие услуги (работы):
A9: № | B9: Наименование услуг (работ) | C9: Ед. изм. | D9: Количество | E9: Цена | F9: Сумма без НДС | G9: Сумма с НДС
A10: 1 | B10: оформление документов | C10: шт. | D10: 3 | E10: 2000 | F10: =SUM(D10*E10) -> 6000 | G10: =F10*1.22 -> 7320
A11: 2 | B11: Оформление сертификата | C11: шт. | F11: =SUM(D11*E11) -> 0 | G11: =F11*1.2 -> 0
F12: =SUM(F10:F11) -> 6000 | G12: =SUM(G10:G11) -> 7320
A13: Итого: | B13: шесть тысяч рублей ноль копеек
A14: Без налога (НДС): | B14: =B13 -> шесть тысяч рублей ноль копеек
A15: Всего (с учетом НДС) | B15: семь тысяч триста двадцать рублей ноль копеек
A16: Вышеперечисленные услуги (работы) выполнены полностью.
A17: ПОКЛАЖЕДАТЕЛЬ претензий по объему, качеству и срокам оказания услуг претензий не имеет.
A20: ООО "ДТМ" | D20: ПАО "СИБУР Холдинг"
A22: ____________________Расстегаев Д.О. | D22: ____________________

Sheet Зеленодольск экспорт
A3: =IF(DAY(TODAY())>27,"Акт № от " & TEXT(TODAY(),"ДД ММММ ГГГГ"),"Акт № от " & TEXT(TODAY()-DAY(TODAY()),"ДД ММММ ГГГГ")) & " г. Зеленодольск" -> Акт № от 31 Май 2026 г. Зеленодольск
A4: =IF(DAY(TODAY()) > 27, "выполненных работ (оказанных услуг) за " & TEXT(TODAY(),"ММММ ГГГГ"),"выполненных работ (оказанных услуг) за " & TEXT(TODAY()-DAY(TODAY()),"ММММ ГГГГ")) -> выполненных работ (оказанных услуг) за Май 2026
A5: по Договору хранения № СХ.47103 от «10» апреля 2025 г.
A7: =IF(DAY(TODAY()) > 27,"Во исполнение Договора в период с " & TEXT(TODAY()-DAY(TODAY()-DAY(TODAY())),"ДД ММММ ГГГГ") & " г. По " & TEXT(TODAY(),"ДД ММММ ГГГГ") & " г. ХРАНИТЕЛЬ оказал ПОКЛАЖЕДАТЕЛЮ следующие услуги (работы):"," Во исполнение Договора в период с " & TEXT(TODAY()-DAY(TODAY())-DAY(TODAY()-DAY(TODAY()))+1,"ДД ММММ ГГГГ") & " г. По " & TEXT(TODAY()-DAY(TODAY()),"ДД ММММ ГГГГ") & " г. ХРАНИТЕЛЬ оказал ПОКЛАЖЕДАТЕЛЮ следующие услуги (работы):") -> Во исполнение Договора в период с 01 Май 2026 г. По 31 Май 2026 г. ХРАНИТЕЛЬ оказал ПОКЛАЖЕДАТЕЛЮ следующие услуги (работы):
A9: № | B9: Наименование услуг (работ) | C9: Ед. изм. | D9: Количество | E9: Цена | F9: Сумма без НДС | G9: Сумма с НДС
A10: 1 | B10: оформление документов | C10: шт. | D10: 19 | E10: 2000 | F10: =SUM(D10*E10) -> 38000 | G10: =F10*1.22 -> 46360
A11: 2 | B11: Оформление сертификата | C11: шт. | F11: =SUM(D11*E11) -> 0 | G11: =F11*1.2 -> 0
F12: =SUM(F10:F11) -> 38000 | G12: =SUM(G10:G11) -> 46360
A13: Итого: | B13: тридцать восемь тысяч рублей ноль копеек
A14: Без налога (НДС): | B14: =B13 -> тридцать восемь тысяч рублей ноль копеек
A15: Всего (с учетом НДС) | B15: сорок шесть тысяч триста шестьдесят рублей ноль копеек
A16: Вышеперечисленные услуги (работы) выполнены полностью.
A17: ПОКЛАЖЕДАТЕЛЬ претензий по объему, качеству и срокам оказания услуг претензий не имеет.
A20: ООО "ДТМ" | D20: ПАО "СИБУР Холдинг"
A22: ____________________Расстегаев Д.О. | D22: ____________________

Sheet Литейные решения
A1: =R36 -> 16819
B2: Отчет по хранению товара за Апрель
A3: № | B3: дата | D3: Выгрузка кол-во паллет | E3: Загрузка кол-во паллет | F3: Ручная загрузка | G3: Ручная выгрузка | H3: Хранение | I3: предоставление паллеты | J3: Фильмаж (паллет) | K3: стоимость выгрузки | L3: стоимость загрузки | M3: Стоимость ручной загрузки | N3: Стоимость ручной выгрузки | O3: стоимость хранения | P3: Стоимость предоставления паллета | Q3: стоимость услуги фильмаж | R3: итого
H4: (кол-во паллет)
A5: 1 | B5: 46113 | H5: 20 | K5: =SUM(D5*171) -> 0 | L5: =SUM(E5*171) -> 0 | M5: =F5*1018 -> 0 | N5: =G5*1018 -> 0 | O5: =SUM(H5*22) -> 440 | P5: =I5*509 -> 0 | Q5: =SUM(J5)*610 -> 0 | R5: =SUM(K5:Q5) -> 440
A6: 2 | B6: 46114 | H6: =H5+D6-E5 -> 20 | K6: =SUM(D6*171) -> 0 | L6: =SUM(E6*171) -> 0 | M6: =F6*1018 -> 0 | N6: =G6*1018 -> 0 | O6: =SUM(H6*22) -> 440 | P6: =I6*509 -> 0 | Q6: =SUM(J6)*610 -> 0 | R6: =SUM(K6:Q6) -> 440
A7: 3 | B7: 46115 | E7: 2 | H7: =H6+D7-E6 -> 20 | K7: =SUM(D7*171) -> 0 | L7: =SUM(E7*171) -> 342 | M7: =F7*1018 -> 0 | N7: =G7*1018 -> 0 | O7: =SUM(H7*22) -> 440 | P7: =I7*509 -> 0 | Q7: =SUM(J7)*610 -> 0 | R7: =SUM(K7:Q7) -> 782
A8: 4 | B8: 46116 | H8: =H7+D8-E7 -> 18 | K8: =SUM(D8*171) -> 0 | L8: =SUM(E8*171) -> 0 | M8: =F8*1018 -> 0 | N8: =G8*1018 -> 0 | O8: =SUM(H8*22) -> 396 | P8: =I8*509 -> 0 | Q8: =SUM(J8)*610 -> 0 | R8: =SUM(K8:Q8) -> 396
A9: 5 | B9: 46117 | H9: =H8+D9-E8 -> 18 | K9: =SUM(D9*171) -> 0 | L9: =SUM(E9*171) -> 0 | M9: =F9*1018 -> 0 | N9: =G9*1018 -> 0 | O9: =SUM(H9*22) -> 396 | P9: =I9*509 -> 0 | Q9: =SUM(J9)*610 -> 0 | R9: =SUM(K9:Q9) -> 396
A10: 6 | B10: 46118 | H10: =H9+D10-E9 -> 18 | K10: =SUM(D10*171) -> 0 | L10: =SUM(E10*171) -> 0 | M10: =F10*1018 -> 0 | N10: =G10*1018 -> 0 | O10: =SUM(H10*22) -> 396 | P10: =I10*509 -> 0 | Q10: =SUM(J10)*610 -> 0 | R10: =SUM(K10:Q10) -> 396
A11: 7 | B11: 46119 | H11: =H10+D11-E10 -> 18 | K11: =SUM(D11*171) -> 0 | L11: =SUM(E11*171) -> 0 | M11: =F11*1018 -> 0 | N11: =G11*1018 -> 0 | O11: =SUM(H11*22) -> 396 | P11: =I11*509 -> 0 | Q11: =SUM(J11)*610 -> 0 | R11: =SUM(K11:Q11) -> 396
A12: 8 | B12: 46120 | H12: =H11+D12-E11 -> 18 | K12: =SUM(D12*171) -> 0 | L12: =SUM(E12*171) -> 0 | M12: =F12*1018 -> 0 | N12: =G12*1018 -> 0 | O12: =SUM(H12*22) -> 396 | P12: =I12*509 -> 0 | Q12: =SUM(J12)*610 -> 0 | R12: =SUM(K12:Q12) -> 396
A13: 9 | B13: 46121 | H13: =H12+D13-E12 -> 18 | K13: =SUM(D13*171) -> 0 | L13: =SUM(E13*171) -> 0 | M13: =F13*1018 -> 0 | N13: =G13*1018 -> 0 | O13: =SUM(H13*22) -> 396 | P13: =I13*509 -> 0 | Q13: =SUM(J13)*610 -> 0 | R13: =SUM(K13:Q13) -> 396
A14: 10 | B14: 46122 | H14: =H13+D14-E13 -> 18 | K14: =SUM(D14*171) -> 0 | L14: =SUM(E14*171) -> 0 | M14: =F14*1018 -> 0 | N14: =G14*1018 -> 0 | O14: =SUM(H14*22) -> 396 | P14: =I14*509 -> 0 | Q14: =SUM(J14)*610 -> 0 | R14: =SUM(K14:Q14) -> 396
A15: 11 | B15: 46123 | H15: =H14+D15-E14 -> 18 | K15: =SUM(D15*171) -> 0 | L15: =SUM(E15*171) -> 0 | M15: =F15*1018 -> 0 | N15: =G15*1018 -> 0 | O15: =SUM(H15*22) -> 396 | P15: =I15*509 -> 0 | Q15: =SUM(J15)*610 -> 0 | R15: =SUM(K15:Q15) -> 396
A16: 12 | B16: 46124 | H16: =H15+D16-E15 -> 18 | K16: =SUM(D16*171) -> 0 | L16: =SUM(E16*171) -> 0 | M16: =F16*1018 -> 0 | N16: =G16*1018 -> 0 | O16: =SUM(H16*22) -> 396 | P16: =I16*509 -> 0 | Q16: =SUM(J16)*610 -> 0 | R16: =SUM(K16:Q16) -> 396
A17: 13 | B17: 46125 | H17: =H16+D17-E16 -> 18 | K17: =SUM(D17*171) -> 0 | L17: =SUM(E17*171) -> 0 | M17: =F17*1018 -> 0 | N17: =G17*1018 -> 0 | O17: =SUM(H17*22) -> 396 | P17: =I17*509 -> 0 | Q17: =SUM(J17)*610 -> 0 | R17: =SUM(K17:Q17) -> 396
A18: 14 | B18: 46126 | E18: 7 | H18: =H17+D18-E17 -> 18 | K18: =SUM(D18*171) -> 0 | L18: =SUM(E18*171) -> 1197 | M18: =F18*1018 -> 0 | N18: =G18*1018 -> 0 | O18: =SUM(H18*22) -> 396 | P18: =I18*509 -> 0 | Q18: =SUM(J18)*610 -> 0 | R18: =SUM(K18:Q18) -> 1593
A19: 15 | B19: 46127 | H19: =H18+D19-E18 -> 11 | K19: =SUM(D19*171) -> 0 | L19: =SUM(E19*171) -> 0 | M19: =F19*1018 -> 0 | N19: =G19*1018 -> 0 | O19: =SUM(H19*22) -> 242 | P19: =I19*509 -> 0 | Q19: =SUM(J19)*610 -> 0 | R19: =SUM(K19:Q19) -> 242
A20: 16 | B20: 46128 | H20: =H19+D20-E19 -> 11 | K20: =SUM(D20*171) -> 0 | L20: =SUM(E20*171) -> 0 | M20: =F20*1018 -> 0 | N20: =G20*1018 -> 0 | O20: =SUM(H20*22) -> 242 | P20: =I20*509 -> 0 | Q20: =SUM(J20)*610 -> 0 | R20: =SUM(K20:Q20) -> 242
A21: 17 | B21: 46129 | H21: =H20+D21-E20 -> 11 | K21: =SUM(D21*171) -> 0 | L21: =SUM(E21*171) -> 0 | M21: =F21*1018 -> 0 | N21: =G21*1018 -> 0 | O21: =SUM(H21*22) -> 242 | P21: =I21*509 -> 0 | Q21: =SUM(J21)*610 -> 0 | R21: =SUM(K21:Q21) -> 242
A22: 18 | B22: 46130 | H22: =H21+D22-E21 -> 11 | K22: =SUM(D22*171) -> 0 | L22: =SUM(E22*171) -> 0 | M22: =F22*1018 -> 0 | N22: =G22*1018 -> 0 | O22: =SUM(H22*22) -> 242 | P22: =I22*509 -> 0 | Q22: =SUM(J22)*610 -> 0 | R22: =SUM(K22:Q22) -> 242
A23: 19 | B23: 46131 | H23: =H22+D23-E22 -> 11 | K23: =SUM(D23*171) -> 0 | L23: =SUM(E23*171) -> 0 | M23: =F23*1018 -> 0 | N23: =G23*1018 -> 0 | O23: =SUM(H23*22) -> 242 | P23: =I23*509 -> 0 | Q23: =SUM(J23)*610 -> 0 | R23: =SUM(K23:Q23) -> 242
A24: 20 | B24: 46132 | H24: =H23+D24-E23 -> 11 | K24: =SUM(D24*171) -> 0 | L24: =SUM(E24*171) -> 0 | M24: =F24*1018 -> 0 | N24: =G24*1018 -> 0 | O24: =SUM(H24*22) -> 242 | P24: =I24*509 -> 0 | Q24: =SUM(J24)*610 -> 0 | R24: =SUM(K24:Q24) -> 242
A25: 21 | B25: 46133 | H25: =H24+D25-E24 -> 11 | K25: =SUM(D25*171) -> 0 | L25: =SUM(E25*171) -> 0 | M25: =F25*1018 -> 0 | N25: =G25*1018 -> 0 | O25: =SUM(H25*22) -> 242 | P25: =I25*509 -> 0 | Q25: =SUM(J25)*610 -> 0 | R25: =SUM(K25:Q25) -> 242
A26: 22 | B26: 46134 | H26: =H25+D26-E25 -> 11 | K26: =SUM(D26*171) -> 0 | L26: =SUM(E26*171) -> 0 | M26: =F26*1018 -> 0 | N26: =G26*1018 -> 0 | O26: =SUM(H26*22) -> 242 | P26: =I26*509 -> 0 | Q26: =SUM(J26)*610 -> 0 | R26: =SUM(K26:Q26) -> 242
A27: 23 | B27: 46135 | H27: =H26+D27-E26 -> 11 | K27: =SUM(D27*171) -> 0 | L27: =SUM(E27*171) -> 0 | M27: =F27*1018 -> 0 | N27: =G27*1018 -> 0 | O27: =SUM(H27*22) -> 242 | P27: =I27*509 -> 0 | Q27: =SUM(J27)*610 -> 0 | R27: =SUM(K27:Q27) -> 242
A28: 24 | B28: 46136 | H28: =H27+D28-E27 -> 11 | K28: =SUM(D28*171) -> 0 | L28: =SUM(E28*171) -> 0 | M28: =F28*1018 -> 0 | N28: =G28*1018 -> 0 | O28: =SUM(H28*22) -> 242 | P28: =I28*509 -> 0 | Q28: =SUM(J28)*610 -> 0 | R28: =SUM(K28:Q28) -> 242
A29: 25 | B29: 46137 | H29: =H28+D29-E28 -> 11 | K29: =SUM(D29*171) -> 0 | L29: =SUM(E29*171) -> 0 | M29: =F29*1018 -> 0 | N29: =G29*1018 -> 0 | O29: =SUM(H29*22) -> 242 | P29: =I29*509 -> 0 | Q29: =SUM(J29)*610 -> 0 | R29: =SUM(K29:Q29) -> 242
A30: 26 | B30: 46138 | H30: =H29+D30-E29 -> 11 | K30: =SUM(D30*171) -> 0 | L30: =SUM(E30*171) -> 0 | M30: =F30*1018 -> 0 | N30: =G30*1018 -> 0 | O30: =SUM(H30*22) -> 242 | P30: =I30*509 -> 0 | Q30: =SUM(J30)*610 -> 0 | R30: =SUM(K30:Q30) -> 242
A31: 27 | B31: 46139 | D31: 20 | H31: =H30+D31-E30 -> 31 | K31: =SUM(D31*171) -> 3420 | L31: =SUM(E31*171) -> 0 | M31: =F31*1018 -> 0 | N31: =G31*1018 -> 0 | O31: =SUM(H31*22) -> 682 | P31: =I31*509 -> 0 | Q31: =SUM(J31)*610 -> 0 | R31: =SUM(K31:Q31) -> 4102
A32: 28 | B32: 46140 | E32: 2 | H32: =H31+D32-E31 -> 31 | K32: =SUM(D32*171) -> 0 | L32: =SUM(E32*171) -> 342 | M32: =F32*1018 -> 0 | N32: =G32*1018 -> 0 | O32: =SUM(H32*22) -> 682 | P32: =I32*509 -> 0 | Q32: =SUM(J32)*610 -> 0 | R32: =SUM(K32:Q32) -> 1024
A33: 29 | B33: 46141 | E33: 2 | H33: =H32+D33-E32 -> 29 | K33: =SUM(D33*171) -> 0 | L33: =SUM(E33*171) -> 342 | M33: =F33*1018 -> 0 | N33: =G33*1018 -> 0 | O33: =SUM(H33*22) -> 638 | P33: =I33*509 -> 0 | Q33: =SUM(J33)*610 -> 0 | R33: =SUM(K33:Q33) -> 980
A34: 30 | B34: 46142 | H34: =H33+D34-E33 -> 27 | K34: =SUM(D34*171) -> 0 | L34: =SUM(E34*171) -> 0 | M34: =F34*1018 -> 0 | N34: =G34*1018 -> 0 | O34: =SUM(H34*22) -> 594 | P34: =I34*509 -> 0 | Q34: =SUM(J34)*610 -> 0 | R34: =SUM(K34:Q34) -> 594
A35: 31 | K35: =SUM(D35*171) -> 0 | L35: =SUM(E35*171) -> 0 | M35: =F35*1018 -> 0 | N35: =G35*1018 -> 0 | O35: =SUM(H35*22) -> 0 | P35: =I35*509 -> 0 | Q35: =SUM(J35)*610 -> 0 | R35: =SUM(K35:Q35) -> 0
D36: =SUM(D5:D35) -> 20 | E36: =SUM(E5:E35) -> 13 | F36: =SUM(F5:F35) -> 0 | H36: =SUM(H5:H35) -> 508 | K36: =SUM(K5:K35) -> 3420 | L36: =SUM(L5:L35) -> 2223 | M36: =SUM(M5:M35) -> 0 | N36: =SUM(N5:N35) -> 0 | O36: =SUM(O5:O35) -> 11176 | P36: =SUM(P5:P35) -> 0 | Q36: =SUM(Q5:Q35) -> 0 | R36: =SUM(R5:R35) -> 16819

Sheet ЛС-Техномет
A1: =R36 -> 8073.6
B2: Отчет по хранению товара за Апрель
A3: № | B3: дата | D3: Выгрузка кол-во паллет | E3: Загрузка кол-во паллет | F3: Ручная загрузка | G3: Ручная выгрузка | H3: Хранение | I3: предоставление паллеты | J3: Фильмаж (паллет) | K3: стоимость выгрузки | L3: стоимость загрузки | M3: Стоимость ручной загрузки | N3: Стоимость ручной выгрузки | O3: стоимость хранения | P3: Стоимость предоставления паллета | Q3: стоимость услуги фильмаж | R3: итого
H4: (кол-во паллет)
A5: 1 | B5: 46113 | H5: 13 | K5: =SUM(D5*168) -> 0 | L5: =SUM(E5*168) -> 0 | M5: =F5*1000 -> 0 | N5: =G5*1000 -> 0 | O5: =SUM(H5*21.6) -> 280.8 | P5: =I5*500 -> 0 | Q5: =SUM(J5)*600 -> 0 | R5: =SUM(K5:Q5) -> 280.8
A6: 2 | B6: 46114 | H6: 13 | K6: =SUM(D6*168) -> 0 | L6: =SUM(E6*168) -> 0 | M6: =F6*1000 -> 0 | N6: =G6*1000 -> 0 | O6: =SUM(H6*21.6) -> 280.8 | P6: =I6*500 -> 0 | Q6: =SUM(J6)*600 -> 0 | R6: =SUM(K6:Q6) -> 280.8
A7: 3 | B7: 46115 | E7: 1 | H7: 13 | K7: =SUM(D7*168) -> 0 | L7: =SUM(E7*168) -> 168 | M7: =F7*1000 -> 0 | N7: =G7*1000 -> 0 | O7: =SUM(H7*21.6) -> 280.8 | P7: =I7*500 -> 0 | Q7: =SUM(J7)*600 -> 0 | R7: =SUM(K7:Q7) -> 448.8
A8: 4 | B8: 46116 | H8: 12 | K8: =SUM(D8*168) -> 0 | L8: =SUM(E8*168) -> 0 | M8: =F8*1000 -> 0 | N8: =G8*1000 -> 0 | O8: =SUM(H8*21.6) -> 259.2 | P8: =I8*500 -> 0 | Q8: =SUM(J8)*600 -> 0 | R8: =SUM(K8:Q8) -> 259.2
A9: 5 | B9: 46117 | H9: 12 | K9: =SUM(D9*168) -> 0 | L9: =SUM(E9*168) -> 0 | M9: =F9*1000 -> 0 | N9: =G9*1000 -> 0 | O9: =SUM(H9*21.6) -> 259.2 | P9: =I9*500 -> 0 | Q9: =SUM(J9)*600 -> 0 | R9: =SUM(K9:Q9) -> 259.2
A10: 6 | B10: 46118 | H10: 12 | K10: =SUM(D10*168) -> 0 | L10: =SUM(E10*168) -> 0 | M10: =F10*1000 -> 0 | N10: =G10*1000 -> 0 | O10: =SUM(H10*21.6) -> 259.2 | P10: =I10*500 -> 0 | Q10: =SUM(J10)*600 -> 0 | R10: =SUM(K10:Q10) -> 259.2
A11: 7 | B11: 46119 | H11: 12 | K11: =SUM(D11*168) -> 0 | L11: =SUM(E11*168) -> 0 | M11: =F11*1000 -> 0 | N11: =G11*1000 -> 0 | O11: =SUM(H11*21.6) -> 259.2 | P11: =I11*500 -> 0 | Q11: =SUM(J11)*600 -> 0 | R11: =SUM(K11:Q11) -> 259.2
A12: 8 | B12: 46120 | H12: 12 | K12: =SUM(D12*168) -> 0 | L12: =SUM(E12*168) -> 0 | M12: =F12*1000 -> 0 | N12: =G12*1000 -> 0 | O12: =SUM(H12*21.6) -> 259.2 | P12: =I12*500 -> 0 | Q12: =SUM(J12)*600 -> 0 | R12: =SUM(K12:Q12) -> 259.2
A13: 9 | B13: 46121 | H13: 12 | K13: =SUM(D13*168) -> 0 | L13: =SUM(E13*168) -> 0 | M13: =F13*1000 -> 0 | N13: =G13*1000 -> 0 | O13: =SUM(H13*21.6) -> 259.2 | P13: =I13*500 -> 0 | Q13: =SUM(J13)*600 -> 0 | R13: =SUM(K13:Q13) -> 259.2
A14: 10 | B14: 46122 | H14: 12 | K14: =SUM(D14*168) -> 0 | L14: =SUM(E14*168) -> 0 | M14: =F14*1000 -> 0 | N14: =G14*1000 -> 0 | O14: =SUM(H14*21.6) -> 259.2 | P14: =I14*500 -> 0 | Q14: =SUM(J14)*600 -> 0 | R14: =SUM(K14:Q14) -> 259.2
A15: 11 | B15: 46123 | H15: 12 | K15: =SUM(D15*168) -> 0 | L15: =SUM(E15*168) -> 0 | M15: =F15*1000 -> 0 | N15: =G15*1000 -> 0 | O15: =SUM(H15*21.6) -> 259.2 | P15: =I15*500 -> 0 | Q15: =SUM(J15)*600 -> 0 | R15: =SUM(K15:Q15) -> 259.2
A16: 12 | B16: 46124 | H16: 12 | K16: =SUM(D16*168) -> 0 | L16: =SUM(E16*168) -> 0 | M16: =F16*1000 -> 0 | N16: =G16*1000 -> 0 | O16: =SUM(H16*21.6) -> 259.2 | P16: =I16*500 -> 0 | Q16: =SUM(J16)*600 -> 0 | R16: =SUM(K16:Q16) -> 259.2
A17: 13 | B17: 46125 | D17: 2 | E17: 3 | H17: 14 | K17: =SUM(D17*168) -> 336 | L17: =SUM(E17*168) -> 504 | M17: =F17*1000 -> 0 | N17: =G17*1000 -> 0 | O17: =SUM(H17*21.6) -> 302.4 | P17: =I17*500 -> 0 | Q17: =SUM(J17)*600 -> 0 | R17: =SUM(K17:Q17) -> 1142.4
A18: 14 | B18: 46126 | E18: 1 | H18: 11 | K18: =SUM(D18*168) -> 0 | L18: =SUM(E18*168) -> 168 | M18: =F18*1000 -> 0 | N18: =G18*1000 -> 0 | O18: =SUM(H18*21.6) -> 237.6 | P18: =I18*500 -> 0 | Q18: =SUM(J18)*600 -> 0 | R18: =SUM(K18:Q18) -> 405.6
A19: 15 | B19: 46127 | H19: 10 | K19: =SUM(D19*168) -> 0 | L19: =SUM(E19*168) -> 0 | M19: =F19*1000 -> 0 | N19: =G19*1000 -> 0 | O19: =SUM(H19*21.6) -> 216 | P19: =I19*500 -> 0 | Q19: =SUM(J19)*600 -> 0 | R19: =SUM(K19:Q19) -> 216
A20: 16 | B20: 46128 | H20: 10 | K20: =SUM(D20*168) -> 0 | L20: =SUM(E20*168) -> 0 | M20: =F20*1000 -> 0 | N20: =G20*1000 -> 0 | O20: =SUM(H20*21.6) -> 216 | P20: =I20*500 -> 0 | Q20: =SUM(J20)*600 -> 0 | R20: =SUM(K20:Q20) -> 216
A21: 17 | B21: 46129 | H21: 10 | K21: =SUM(D21*168) -> 0 | L21: =SUM(E21*168) -> 0 | M21: =F21*1000 -> 0 | N21: =G21*1000 -> 0 | O21: =SUM(H21*21.6) -> 216 | P21: =I21*500 -> 0 | Q21: =SUM(J21)*600 -> 0 | R21: =SUM(K21:Q21) -> 216
A22: 18 | B22: 46130 | E22: 3 | H22: 10 | K22: =SUM(D22*168) -> 0 | L22: =SUM(E22*168) -> 504 | M22: =F22*1000 -> 0 | N22: =G22*1000 -> 0 | O22: =SUM(H22*21.6) -> 216 | P22: =I22*500 -> 0 | Q22: =SUM(J22)*600 -> 0 | R22: =SUM(K22:Q22) -> 720
A23: 19 | B23: 46131 | H23: 7 | K23: =SUM(D23*168) -> 0 | L23: =SUM(E23*168) -> 0 | M23: =F23*1000 -> 0 | N23: =G23*1000 -> 0 | O23: =SUM(H23*21.6) -> 151.2 | P23: =I23*500 -> 0 | Q23: =SUM(J23)*600 -> 0 | R23: =SUM(K23:Q23) -> 151.2
A24: 20 | B24: 46132 | H24: 7 | K24: =SUM(D24*168) -> 0 | L24: =SUM(E24*168) -> 0 | M24: =F24*1000 -> 0 | N24: =G24*1000 -> 0 | O24: =SUM(H24*21.6) -> 151.2 | P24: =I24*500 -> 0 | Q24: =SUM(J24)*600 -> 0 | R24: =SUM(K24:Q24) -> 151.2
A25: 21 | B25: 46133 | H25: 7 | K25: =SUM(D25*168) -> 0 | L25: =SUM(E25*168) -> 0 | M25: =F25*1000 -> 0 | N25: =G25*1000 -> 0 | O25: =SUM(H25*21.6) -> 151.2 | P25: =I25*500 -> 0 | Q25: =SUM(J25)*600 -> 0 | R25: =SUM(K25:Q25) -> 151.2
A26: 22 | B26: 46134 | H26: 7 | K26: =SUM(D26*168) -> 0 | L26: =SUM(E26*168) -> 0 | M26: =F26*1000 -> 0 | N26: =G26*1000 -> 0 | O26: =SUM(H26*21.6) -> 151.2 | P26: =I26*500 -> 0 | Q26: =SUM(J26)*600 -> 0 | R26: =SUM(K26:Q26) -> 151.2
A27: 23 | B27: 46135 | H27: 7 | K27: =SUM(D27*168) -> 0 | L27: =SUM(E27*168) -> 0 | M27: =F27*1000 -> 0 | N27: =G27*1000 -> 0 | O27: =SUM(H27*21.6) -> 151.2 | P27: =I27*500 -> 0 | Q27: =SUM(J27)*600 -> 0 | R27: =SUM(K27:Q27) -> 151.2
A28: 24 | B28: 46136 | H28: 7 | K28: =SUM(D28*168) -> 0 | L28: =SUM(E28*168) -> 0 | M28: =F28*1000 -> 0 | N28: =G28*1000 -> 0 | O28: =SUM(H28*21.6) -> 151.2 | P28: =I28*500 -> 0 | Q28: =SUM(J28)*600 -> 0 | R28: =SUM(K28:Q28) -> 151.2
A29: 25 | B29: 46137 | H29: 7 | K29: =SUM(D29*168) -> 0 | L29: =SUM(E29*168) -> 0 | M29: =F29*1000 -> 0 | N29: =G29*1000 -> 0 | O29: =SUM(H29*21.6) -> 151.2 | P29: =I29*500 -> 0 | Q29: =SUM(J29)*600 -> 0 | R29: =SUM(K29:Q29) -> 151.2
A30: 26 | B30: 46138 | H30: 7 | K30: =SUM(D30*168) -> 0 | L30: =SUM(E30*168) -> 0 | M30: =F30*1000 -> 0 | N30: =G30*1000 -> 0 | O30: =SUM(H30*21.6) -> 151.2 | P30: =I30*500 -> 0 | Q30: =SUM(J30)*600 -> 0 | R30: =SUM(K30:Q30) -> 151.2
A31: 27 | B31: 46139 | H31: 7 | K31: =SUM(D31*168) -> 0 | L31: =SUM(E31*168) -> 0 | M31: =F31*1000 -> 0 | N31: =G31*1000 -> 0 | O31: =SUM(H31*21.6) -> 151.2 | P31: =I31*500 -> 0 | Q31: =SUM(J31)*600 -> 0 | R31: =SUM(K31:Q31) -> 151.2
A32: 28 | B32: 46140 | H32: 7 | K32: =SUM(D32*168) -> 0 | L32: =SUM(E32*168) -> 0 | M32: =F32*1000 -> 0 | N32: =G32*1000 -> 0 | O32: =SUM(H32*21.6) -> 151.2 | P32: =I32*500 -> 0 | Q32: =SUM(J32)*600 -> 0 | R32: =SUM(K32:Q32) -> 151.2
A33: 29 | B33: 46141 | H33: 7 | K33: =SUM(D33*168) -> 0 | L33: =SUM(E33*168) -> 0 | M33: =F33*1000 -> 0 | N33: =G33*1000 -> 0 | O33: =SUM(H33*21.6) -> 151.2 | P33: =I33*500 -> 0 | Q33: =SUM(J33)*600 -> 0 | R33: =SUM(K33:Q33) -> 151.2
A34: 30 | B34: 46142 | H34: 7 | K34: =SUM(D34*168) -> 0 | L34: =SUM(E34*168) -> 0 | M34: =F34*1000 -> 0 | N34: =G34*1000 -> 0 | O34: =SUM(H34*21.6) -> 151.2 | P34: =I34*500 -> 0 | Q34: =SUM(J34)*600 -> 0 | R34: =SUM(K34:Q34) -> 151.2
K35: =SUM(D35*168) -> 0 | L35: =SUM(E35*168) -> 0 | M35: =F35*1000 -> 0 | N35: =G35*1000 -> 0 | O35: =SUM(H35*21.6) -> 0 | P35: =I35*500 -> 0 | Q35: =SUM(J35)*600 -> 0 | R35: =SUM(K35:Q35) -> 0
D36: =SUM(D5:D35) -> 2 | E36: =SUM(E5:E35) -> 8 | F36: =SUM(F5:F35) -> 0 | H36: =SUM(H5:H35) -> 296 | K36: =SUM(K5:K35) -> 336 | L36: =SUM(L5:L35) -> 1344 | M36: =SUM(M5:M35) -> 0 | N36: =SUM(N5:N35) -> 0 | O36: =SUM(O5:O35) -> 6393.6 | P36: =SUM(P5:P35) -> 0 | Q36: =SUM(Q5:Q35) -> 0 | R36: =SUM(R5:R35) -> 8073.6

Sheet Сандекс
A1: =S39 -> 22922.4
A4: Отчет "Сандекс" Апрель 2025 | L4: Стоимость
A5: дата | C5: Выгрузка паллет | D5: Выгрузка короб | E5: Загрузка паллет | F5: Загрузка короб | G5: Наборка короб | J5: Палетирование | K5: Хранение | L5: Выгрузка палллет | M5: Выгрузка короб | N5: Загрузка паллет | O5: Загрузка короб | P5: Наборка | Q5: Паллетирование | R5: Хранение | S5: итого
K6: 38
A7: 46113 | J7: 0 | K7: 38 | L7: =C7*168 -> 0 | M7: =D7*4 -> 0 | N7: =E7*168 -> 0 | O7: =F7*4 -> 0 | P7: =G7*4 -> 0 | Q7: =J7*600 -> 0 | R7: =K7*21.6 -> 820.8 | S7: =SUM(L7:R7) -> 820.8
A8: 46114 | J8: 0 | K8: 38 | L8: =C8*168 -> 0 | M8: =D8*4 -> 0 | N8: =E8*168 -> 0 | O8: =F8*4 -> 0 | P8: =G8*4 -> 0 | Q8: =J8*600 -> 0 | R8: =K8*21.6 -> 820.8 | S8: =SUM(L8:R8) -> 820.8
A9: 46115 | J9: 0 | K9: 38 | L9: =C9*168 -> 0 | M9: =D9*4 -> 0 | N9: =E9*168 -> 0 | O9: =F9*4 -> 0 | P9: =G9*4 -> 0 | Q9: =J9*600 -> 0 | R9: =K9*21.6 -> 820.8 | S9: =SUM(L9:R9) -> 820.8
A10: 46116 | J10: 0 | K10: 38 | L10: =C10*168 -> 0 | M10: =D10*4 -> 0 | N10: =E10*168 -> 0 | O10: =F10*4 -> 0 | P10: =G10*4 -> 0 | Q10: =J10*600 -> 0 | R10: =K10*21.6 -> 820.8 | S10: =SUM(L10:R10) -> 820.8
A11: 46117 | J11: 0 | K11: 38 | L11: =C11*168 -> 0 | M11: =D11*4 -> 0 | N11: =E11*168 -> 0 | O11: =F11*4 -> 0 | P11: =G11*4 -> 0 | Q11: =J11*600 -> 0 | R11: =K11*21.6 -> 820.8 | S11: =SUM(L11:R11) -> 820.8
A12: 46118 | J12: 0 | K12: 38 | L12: =C12*168 -> 0 | M12: =D12*4 -> 0 | N12: =E12*168 -> 0 | O12: =F12*4 -> 0 | P12: =G12*4 -> 0 | Q12: =J12*600 -> 0 | R12: =K12*21.6 -> 820.8 | S12: =SUM(L12:R12) -> 820.8
A13: 46119 | J13: 0 | K13: 38 | L13: =C13*168 -> 0 | M13: =D13*4 -> 0 | N13: =E13*168 -> 0 | O13: =F13*4 -> 0 | P13: =G13*4 -> 0 | Q13: =J13*600 -> 0 | R13: =K13*21.6 -> 820.8 | S13: =SUM(L13:R13) -> 820.8
A14: 46120 | E14: 6 | J14: 0 | K14: 38 | L14: =C14*168 -> 0 | M14: =D14*4 -> 0 | N14: =E14*168 -> 1008 | O14: =F14*4 -> 0 | P14: =G14*4 -> 0 | Q14: =J14*600 -> 0 | R14: =K14*21.6 -> 820.8 | S14: =SUM(L14:R14) -> 1828.8
A15: 46121 | J15: 0 | K15: 32 | L15: =C15*168 -> 0 | M15: =D15*4 -> 0 | N15: =E15*168 -> 0 | O15: =F15*4 -> 0 | P15: =G15*4 -> 0 | Q15: =J15*600 -> 0 | R15: =K15*21.6 -> 691.2 | S15: =SUM(L15:R15) -> 691.2
A16: 46122 | J16: 0 | K16: 32 | L16: =C16*168 -> 0 | M16: =D16*4 -> 0 | N16: =E16*168 -> 0 | O16: =F16*4 -> 0 | P16: =G16*4 -> 0 | Q16: =J16*600 -> 0 | R16: =K16*21.6 -> 691.2 | S16: =SUM(L16:R16) -> 691.2
A17: 46123 | J17: 0 | K17: 32 | L17: =C17*168 -> 0 | M17: =D17*4 -> 0 | N17: =E17*168 -> 0 | O17: =F17*4 -> 0 | P17: =G17*4 -> 0 | Q17: =J17*600 -> 0 | R17: =K17*21.6 -> 691.2 | S17: =SUM(L17:R17) -> 691.2
A18: 46124 | J18: 0 | K18: 32 | L18: =C18*168 -> 0 | M18: =D18*4 -> 0 | N18: =E18*168 -> 0 | O18: =F18*4 -> 0 | P18: =G18*4 -> 0 | Q18: =J18*600 -> 0 | R18: =K18*21.6 -> 691.2 | S18: =SUM(L18:R18) -> 691.2
A19: 46125 | J19: 0 | K19: 32 | L19: =C19*168 -> 0 | M19: =D19*4 -> 0 | N19: =E19*168 -> 0 | O19: =F19*4 -> 0 | P19: =G19*4 -> 0 | Q19: =J19*600 -> 0 | R19: =K19*21.6 -> 691.2 | S19: =SUM(L19:R19) -> 691.2
A20: 46126 | J20: 0 | K20: 32 | L20: =C20*168 -> 0 | M20: =D20*4 -> 0 | N20: =E20*168 -> 0 | O20: =F20*4 -> 0 | P20: =G20*4 -> 0 | Q20: =J20*600 -> 0 | R20: =K20*21.6 -> 691.2 | S20: =SUM(L20:R20) -> 691.2
A21: 46127 | J21: 0 | K21: 32 | L21: =C21*168 -> 0 | M21: =D21*4 -> 0 | N21: =E21*168 -> 0 | O21: =F21*4 -> 0 | P21: =G21*4 -> 0 | Q21: =J21*600 -> 0 | R21: =K21*21.6 -> 691.2 | S21: =SUM(L21:R21) -> 691.2
A22: 46128 | J22: 0 | K22: 32 | L22: =C22*168 -> 0 | M22: =D22*4 -> 0 | N22: =E22*168 -> 0 | O22: =F22*4 -> 0 | P22: =G22*4 -> 0 | Q22: =J22*600 -> 0 | R22: =K22*21.6 -> 691.2 | S22: =SUM(L22:R22) -> 691.2
A23: 46129 | J23: 0 | K23: 32 | L23: =C23*168 -> 0 | M23: =D23*4 -> 0 | N23: =E23*168 -> 0 | O23: =F23*4 -> 0 | P23: =G23*4 -> 0 | Q23: =J23*600 -> 0 | R23: =K23*21.6 -> 691.2 | S23: =SUM(L23:R23) -> 691.2
A24: 46130 | J24: 0 | K24: 32 | L24: =C24*168 -> 0 | M24: =D24*4 -> 0 | N24: =E24*168 -> 0 | O24: =F24*4 -> 0 | P24: =G24*4 -> 0 | Q24: =J24*600 -> 0 | R24: =K24*21.6 -> 691.2 | S24: =SUM(L24:R24) -> 691.2
A25: 46131 | J25: 0 | K25: 32 | L25: =C25*168 -> 0 | M25: =D25*4 -> 0 | N25: =E25*168 -> 0 | O25: =F25*4 -> 0 | P25: =G25*4 -> 0 | Q25: =J25*600 -> 0 | R25: =K25*21.6 -> 691.2 | S25: =SUM(L25:R25) -> 691.2
A26: 46132 | J26: 0 | K26: 32 | L26: =C26*168 -> 0 | M26: =D26*4 -> 0 | N26: =E26*168 -> 0 | O26: =F26*4 -> 0 | P26: =G26*4 -> 0 | Q26: =J26*600 -> 0 | R26: =K26*21.6 -> 691.2 | S26: =SUM(L26:R26) -> 691.2
A27: 46133 | J27: 0 | K27: 32 | L27: =C27*168 -> 0 | M27: =D27*4 -> 0 | N27: =E27*168 -> 0 | O27: =F27*4 -> 0 | P27: =G27*4 -> 0 | Q27: =J27*600 -> 0 | R27: =K27*21.6 -> 691.2 | S27: =SUM(L27:R27) -> 691.2
A28: 46134 | E28: 1 | J28: 0 | K28: 32 | L28: =C28*168 -> 0 | M28: =D28*4 -> 0 | N28: =E28*168 -> 168 | O28: =F28*4 -> 0 | P28: =G28*4 -> 0 | Q28: =J28*600 -> 0 | R28: =K28*21.6 -> 691.2 | S28: =SUM(L28:R28) -> 859.2
A29: 46135 | J29: 0 | K29: 31 | L29: =C29*168 -> 0 | M29: =D29*4 -> 0 | N29: =E29*168 -> 0 | O29: =F29*4 -> 0 | P29: =G29*4 -> 0 | Q29: =J29*600 -> 0 | R29: =K29*21.6 -> 669.6 | S29: =SUM(L29:R29) -> 669.6
A30: 46136 | J30: 0 | K30: 31 | L30: =C30*168 -> 0 | M30: =D30*4 -> 0 | N30: =E30*168 -> 0 | O30: =F30*4 -> 0 | P30: =G30*4 -> 0 | Q30: =J30*600 -> 0 | R30: =K30*21.6 -> 669.6 | S30: =SUM(L30:R30) -> 669.6
A31: 46137 | J31: 0 | K31: 31 | L31: =C31*168 -> 0 | M31: =D31*4 -> 0 | N31: =E31*168 -> 0 | O31: =F31*4 -> 0 | P31: =G31*4 -> 0 | Q31: =J31*600 -> 0 | R31: =K31*21.6 -> 669.6 | S31: =SUM(L31:R31) -> 669.6
A32: 46138 | J32: 0 | K32: 31 | L32: =C32*168 -> 0 | M32: =D32*4 -> 0 | N32: =E32*168 -> 0 | O32: =F32*4 -> 0 | P32: =G32*4 -> 0 | Q32: =J32*600 -> 0 | R32: =K32*21.6 -> 669.6 | S32: =SUM(L32:R32) -> 669.6
A33: 46139 | J33: 0 | K33: 31 | L33: =C33*168 -> 0 | M33: =D33*4 -> 0 | N33: =E33*168 -> 0 | O33: =F33*4 -> 0 | P33: =G33*4 -> 0 | Q33: =J33*600 -> 0 | R33: =K33*21.6 -> 669.6 | S33: =SUM(L33:R33) -> 669.6
A34: 46140 | J34: 0 | K34: 31 | L34: =C34*168 -> 0 | M34: =D34*4 -> 0 | N34: =E34*168 -> 0 | O34: =F34*4 -> 0 | P34: =G34*4 -> 0 | Q34: =J34*600 -> 0 | R34: =K34*21.6 -> 669.6 | S34: =SUM(L34:R34) -> 669.6
A35: 46141 | E35: 1 | K35: 31 | L35: =C35*168 -> 0 | M35: =D35*4 -> 0 | N35: =E35*168 -> 168 | O35: =F35*4 -> 0 | P35: =G35*4 -> 0 | Q35: =J35*600 -> 0 | R35: =K35*21.6 -> 669.6 | S35: =SUM(L35:R35) -> 837.6
A36: 46142 | K36: 30 | L36: =C36*168 -> 0 | M36: =D36*4 -> 0 | N36: =E36*168 -> 0 | O36: =F36*4 -> 0 | P36: =G36*4 -> 0 | Q36: =J36*600 -> 0 | R36: =K36*21.6 -> 648 | S36: =SUM(L36:R36) -> 648
L37: =C37*168 -> 0 | M37: =D37*4 -> 0 | N37: =E37*168 -> 0 | O37: =F37*4 -> 0 | P37: =G37*4 -> 0 | Q37: =J37*600 -> 0 | R37: =K37*21.6 -> 0 | S37: =SUM(L37:R37) -> 0
A38: Итого | C38: =SUM(C7:C37) -> 0 | D38: =SUM(D7:D37) -> 0 | E38: =SUM(E7:E37) -> 8 | F38: =SUM(F7:F37) -> 0 | G38: =SUM(G7:G37) -> 0 | H38: =SUM(H7:H37) -> 0 | I38: =SUM(I7:I37) -> 0 | J38: =SUM(J7:J37) -> 0 | ... S38: =SUM(S7:S37) -> 22922.4
R39: Итого | S39: =S38 -> 22922.4

Sheet СтройТех
A1: =K36 -> 22125
A2: Отчет по хранению товара СтройТех за Апрель
A3: № | B3: дата | D3: Выгрузка кол-во паллет | E3: ручная загрузка | G3: Хранение | H3: стоимость выгрузки | I3: стоимость загр.. Работ | J3: стоимость хранения | K3: итого
E4: мультипак | F4: шт,. | G4: (кол-во паллет)
A5: 1 | B5: 46113 | G5: 51 | H5: =SUM(D5*60) -> 0 | I5: =SUM(E5*25+F5*7) -> 0 | J5: =SUM(G5*15) -> 765 | K5: =SUM(H5:J5) -> 765
A6: 2 | B6: 46114 | E6: 18 | G6: 51 | H6: =SUM(D6*60) -> 0 | I6: =SUM(E6*25+F6*7) -> 450 | J6: =SUM(G6*15) -> 765 | K6: =SUM(H6:J6) -> 1215
A7: 3 | B7: 46115 | G7: 48 | H7: =SUM(D7*60) -> 0 | I7: =SUM(E7*25+F7*7) -> 0 | J7: =SUM(G7*15) -> 720 | K7: =SUM(H7:J7) -> 720
A8: 4 | B8: 46116 | G8: 48 | H8: =SUM(D8*60) -> 0 | I8: =SUM(E8*25+F8*7) -> 0 | J8: =SUM(G8*15) -> 720 | K8: =SUM(H8:J8) -> 720
A9: 5 | B9: 46117 | G9: 48 | H9: =SUM(D9*60) -> 0 | I9: =SUM(E9*25+F9*7) -> 0 | J9: =SUM(G9*15) -> 720 | K9: =SUM(H9:J9) -> 720
A10: 6 | B10: 46118 | G10: 48 | H10: =SUM(D10*60) -> 0 | I10: =SUM(E10*25+F10*7) -> 0 | J10: =SUM(G10*15) -> 720 | K10: =SUM(H10:J10) -> 720
A11: 7 | B11: 46119 | G11: 48 | H11: =SUM(D11*60) -> 0 | I11: =SUM(E11*25+F11*7) -> 0 | J11: =SUM(G11*15) -> 720 | K11: =SUM(H11:J11) -> 720
A12: 8 | B12: 46120 | G12: 48 | H12: =SUM(D12*60) -> 0 | I12: =SUM(E12*25+F12*7) -> 0 | J12: =SUM(G12*15) -> 720 | K12: =SUM(H12:J12) -> 720
A13: 9 | B13: 46121 | G13: 48 | H13: =SUM(D13*60) -> 0 | I13: =SUM(E13*25+F13*7) -> 0 | J13: =SUM(G13*15) -> 720 | K13: =SUM(H13:J13) -> 720
A14: 10 | B14: 46122 | G14: 48 | H14: =SUM(D14*60) -> 0 | I14: =SUM(E14*25+F14*7) -> 0 | J14: =SUM(G14*15) -> 720 | K14: =SUM(H14:J14) -> 720
A15: 11 | B15: 46123 | G15: 48 | H15: =SUM(D15*60) -> 0 | I15: =SUM(E15*25+F15*7) -> 0 | J15: =SUM(G15*15) -> 720 | K15: =SUM(H15:J15) -> 720
A16: 12 | B16: 46124 | G16: 48 | H16: =SUM(D16*60) -> 0 | I16: =SUM(E16*25+F16*7) -> 0 | J16: =SUM(G16*15) -> 720 | K16: =SUM(H16:J16) -> 720
A17: 13 | B17: 46125 | E17: 20 | G17: 48 | H17: =SUM(D17*60) -> 0 | I17: =SUM(E17*25+F17*7) -> 500 | J17: =SUM(G17*15) -> 720 | K17: =SUM(H17:J17) -> 1220
A18: 14 | B18: 46126 | G18: 46 | H18: =SUM(D18*60) -> 0 | I18: =SUM(E18*25+F18*7) -> 0 | J18: =SUM(G18*15) -> 690 | K18: =SUM(H18:J18) -> 690
A19: 15 | B19: 46127 | G19: 46 | H19: =SUM(D19*60) -> 0 | I19: =SUM(E19*25+F19*7) -> 0 | J19: =SUM(G19*15) -> 690 | K19: =SUM(H19:J19) -> 690
A20: 16 | B20: 46128 | G20: 46 | H20: =SUM(D20*60) -> 0 | I20: =SUM(E20*25+F20*7) -> 0 | J20: =SUM(G20*15) -> 690 | K20: =SUM(H20:J20) -> 690
A21: 17 | B21: 46129 | G21: 46 | H21: =SUM(D21*60) -> 0 | I21: =SUM(E21*25+F21*7) -> 0 | J21: =SUM(G21*15) -> 690 | K21: =SUM(H21:J21) -> 690
A22: 18 | B22: 46130 | G22: 46 | H22: =SUM(D22*60) -> 0 | I22: =SUM(E22*25+F22*7) -> 0 | J22: =SUM(G22*15) -> 690 | K22: =SUM(H22:J22) -> 690
A23: 19 | B23: 46131 | G23: 46 | H23: =SUM(D23*60) -> 0 | I23: =SUM(E23*25+F23*7) -> 0 | J23: =SUM(G23*15) -> 690 | K23: =SUM(H23:J23) -> 690
A24: 20 | B24: 46132 | G24: 46 | H24: =SUM(D24*60) -> 0 | I24: =SUM(E24*25+F24*7) -> 0 | J24: =SUM(G24*15) -> 690 | K24: =SUM(H24:J24) -> 690
A25: 21 | B25: 46133 | G25: 46 | H25: =SUM(D25*60) -> 0 | I25: =SUM(E25*25+F25*7) -> 0 | J25: =SUM(G25*15) -> 690 | K25: =SUM(H25:J25) -> 690
A26: 22 | B26: 46134 | G26: 46 | H26: =SUM(D26*60) -> 0 | I26: =SUM(E26*25+F26*7) -> 0 | J26: =SUM(G26*15) -> 690 | K26: =SUM(H26:J26) -> 690
A27: 23 | B27: 46135 | E27: 4 | G27: 46 | H27: =SUM(D27*60) -> 0 | I27: =SUM(E27*25+F27*7) -> 100 | J27: =SUM(G27*15) -> 690 | K27: =SUM(H27:J27) -> 790
A28: 24 | B28: 46136 | G28: 45 | H28: =SUM(D28*60) -> 0 | I28: =SUM(E28*25+F28*7) -> 0 | J28: =SUM(G28*15) -> 675 | K28: =SUM(H28:J28) -> 675
A29: 25 | B29: 46137 | G29: 45 | H29: =SUM(D29*60) -> 0 | I29: =SUM(E29*25+F29*7) -> 0 | J29: =SUM(G29*15) -> 675 | K29: =SUM(H29:J29) -> 675
A30: 26 | B30: 46138 | G30: 45 | H30: =SUM(D30*60) -> 0 | I30: =SUM(E30*25+F30*7) -> 0 | J30: =SUM(G30*15) -> 675 | K30: =SUM(H30:J30) -> 675
A31: 27 | B31: 46139 | G31: 45 | H31: =SUM(D31*60) -> 0 | I31: =SUM(E31*25+F31*7) -> 0 | J31: =SUM(G31*15) -> 675 | K31: =SUM(H31:J31) -> 675
A32: 28 | B32: 46140 | G32: 45 | H32: =SUM(D32*60) -> 0 | I32: =SUM(E32*25+F32*7) -> 0 | J32: =SUM(G32*15) -> 675 | K32: =SUM(H32:J32) -> 675
A33: 29 | B33: 46141 | G33: 45 | H33: =SUM(D33*60) -> 0 | I33: =SUM(E33*25+F33*7) -> 0 | J33: =SUM(G33*15) -> 675 | K33: =SUM(H33:J33) -> 675
A34: 30 | B34: 46142 | G34: 45 | H34: =SUM(D34*60) -> 0 | I34: =SUM(E34*25+F34*7) -> 0 | J34: =SUM(G34*15) -> 675 | K34: =SUM(H34:J34) -> 675
H35: =SUM(D35*60) -> 0 | I35: =SUM(E35*25+F35*7) -> 0 | J35: =SUM(G35*15) -> 0 | K35: =SUM(H35:J35) -> 0
G36: =SUM(G5:G35) -> 1405 | H36: =SUM(H5:H35) -> 0 | I36: =SUM(I5:I35) -> 1050 | J36: =SUM(J5:J35) -> 21075 | K36: =SUM(K5:K35) -> 22125

Sheet Ергарда
A1: =J35 -> 8640 | B1: Отчет по хранению товара Ергарда за Апрель
A2: № | B2: дата | D2: Выгрузка кол-во паллет | E2: Загрузка кол-во паллет | F2: Хранение | G2: стоимость выгрузки | H2: стоимость загрузки | I2: стоимость хранения | J2: итого
F3: (кол-во паллет)
A4: 1 | B4: 46113 | F4: 24 | G4: =SUM(D4*120) -> 0 | H4: =SUM(E4*120) -> 0 | I4: =SUM(F4*12) -> 288 | J4: =SUM(G4:I4) -> 288
A5: 2 | B5: 46114 | F5: 24 | G5: =SUM(D5*120) -> 0 | H5: =SUM(E5*120) -> 0 | I5: =SUM(F5*12) -> 288 | J5: =SUM(G5:I5) -> 288
A6: 3 | B6: 46115 | F6: 24 | G6: =SUM(D6*120) -> 0 | H6: =SUM(E6*120) -> 0 | I6: =SUM(F6*12) -> 288 | J6: =SUM(G6:I6) -> 288
A7: 4 | B7: 46116 | F7: 24 | G7: =SUM(D7*120) -> 0 | H7: =SUM(E7*120) -> 0 | I7: =SUM(F7*12) -> 288 | J7: =SUM(G7:I7) -> 288
A8: 5 | B8: 46117 | F8: 24 | G8: =SUM(D8*120) -> 0 | H8: =SUM(E8*120) -> 0 | I8: =SUM(F8*12) -> 288 | J8: =SUM(G8:I8) -> 288
A9: 6 | B9: 46118 | F9: 24 | G9: =SUM(D9*120) -> 0 | H9: =SUM(E9*120) -> 0 | I9: =SUM(F9*12) -> 288 | J9: =SUM(G9:I9) -> 288
A10: 7 | B10: 46119 | F10: 24 | G10: =SUM(D10*120) -> 0 | H10: =SUM(E10*120) -> 0 | I10: =SUM(F10*12) -> 288 | J10: =SUM(G10:I10) -> 288
A11: 8 | B11: 46120 | F11: 24 | G11: =SUM(D11*120) -> 0 | H11: =SUM(E11*120) -> 0 | I11: =SUM(F11*12) -> 288 | J11: =SUM(G11:I11) -> 288
A12: 9 | B12: 46121 | F12: 24 | G12: =SUM(D12*120) -> 0 | H12: =SUM(E12*120) -> 0 | I12: =SUM(F12*12) -> 288 | J12: =SUM(G12:I12) -> 288
A13: 10 | B13: 46122 | F13: 24 | G13: =SUM(D13*120) -> 0 | H13: =SUM(E13*120) -> 0 | I13: =SUM(F13*12) -> 288 | J13: =SUM(G13:I13) -> 288
