Workbook

Sheet Лист1

Sheet Биаксплен Новосибирск
A1: =T37 -> 210273.99
A2: ="Отчет по хранению товара за " & TEXT(B5,"ММММ ГГГГ") -> Отчет по хранению товара за Февраль 2026
A3: № | B3: дата | D3: Выгрузка кол-во | E3: Загрузка кол-во | F3: Хранение | G3: Резервирование 70 т | H3: Мин. Суточный резерв 0 т | I3: переконсолидация (тонн) | J3: Паллетирование | K3: Ночная загруска выгрузка | L3: стоимость ночной загруски | M3: стоимость выгрузки | N3: стоимость загрузки | O3: стоимость хранения | P3: Стоимость резервирования | Q3: Стоимость мин.суточной бработки | R3: стоимость переконс. | S3: Стоимость паллетирования | T3: итого
A5: 1 | B5: 46054 | F5: 121.3417 | G5: =IF(OR(B5="",NOT(ISERROR(SEARCH("KPI",$A$2))),NOT(ISERROR(SEARCH("Полиом",$A$2)))),0,IF(70-F5<=0,0,70-F5)) -> 0 | L5: =SUM(K5*240) -> 0 | M5: =SUM(D5*120) -> 0 | N5: =SUM(E5*120) -> 0 | O5: =SUM(F5*54) -> 6552.4518 | P5: =SUM(G5*54) -> 0 | Q5: =SUM(H5*120) -> 0 | R5: =SUM(I5*1000) -> 0 | S5: =SUM(J5*140) -> 0 | T5: =SUM(L5:S5) -> 6552.4518
A6: 2 | B6: 46055 | F6: 121.3417 | G6: =IF(OR(B6="",NOT(ISERROR(SEARCH("KPI",$A$2))),NOT(ISERROR(SEARCH("Полиом",$A$2)))),0,IF(70-F6<=0,0,70-F6)) -> 0 | L6: =SUM(K6*240) -> 0 | M6: =SUM(D6*120) -> 0 | N6: =SUM(E6*120) -> 0 | O6: =SUM(F6*54) -> 6552.4518 | P6: =SUM(G6*54) -> 0 | Q6: =SUM(H6*120) -> 0 | R6: =SUM(I6*1000) -> 0 | S6: =SUM(J6*140) -> 0 | T6: =SUM(L6:S6) -> 6552.4518
A7: 3 | B7: 46056 | F7: 121.3417 | G7: =IF(OR(B7="",NOT(ISERROR(SEARCH("KPI",$A$2))),NOT(ISERROR(SEARCH("Полиом",$A$2)))),0,IF(70-F7<=0,0,70-F7)) -> 0 | L7: =SUM(K7*240) -> 0 | M7: =SUM(D7*120) -> 0 | N7: =SUM(E7*120) -> 0 | O7: =SUM(F7*54) -> 6552.4518 | P7: =SUM(G7*54) -> 0 | Q7: =SUM(H7*120) -> 0 | R7: =SUM(I7*1000) -> 0 | S7: =SUM(J7*140) -> 0 | T7: =SUM(L7:S7) -> 6552.4518
A8: 4 | B8: 46057 | E8: 3.2091 | F8: 118.1326 | G8: =IF(OR(B8="",NOT(ISERROR(SEARCH("KPI",$A$2))),NOT(ISERROR(SEARCH("Полиом",$A$2)))),0,IF(70-F8<=0,0,70-F8)) -> 0 | L8: =SUM(K8*240) -> 0 | M8: =SUM(D8*120) -> 0 | N8: =SUM(E8*120) -> 385.092 | O8: =SUM(F8*54) -> 6379.1604 | P8: =SUM(G8*54) -> 0 | Q8: =SUM(H8*120) -> 0 | R8: =SUM(I8*1000) -> 0 | S8: =SUM(J8*140) -> 0 | T8: =SUM(L8:S8) -> 6764.2524
A9: 5 | B9: 46058 | E9: 17.5303 | F9: 100.6023 | G9: =IF(OR(B9="",NOT(ISERROR(SEARCH("KPI",$A$2))),NOT(ISERROR(SEARCH("Полиом",$A$2)))),0,IF(70-F9<=0,0,70-F9)) -> 0 | L9: =SUM(K9*240) -> 0 | M9: =SUM(D9*120) -> 0 | N9: =SUM(E9*120) -> 2103.636 | O9: =SUM(F9*54) -> 5432.5242 | P9: =SUM(G9*54) -> 0 | Q9: =SUM(H9*120) -> 0 | R9: =SUM(I9*1000) -> 0 | S9: =SUM(J9*140) -> 0 | T9: =SUM(L9:S9) -> 7536.1602
A10: 6 | B10: 46059 | D10: 17.7328 | E10: 6.7244 | F10: 111.6107 | G10: =IF(OR(B10="",NOT(ISERROR(SEARCH("KPI",$A$2))),NOT(ISERROR(SEARCH("Полиом",$A$2)))),0,IF(70-F10<=0,0,70-F10)) -> 0 | L10: =SUM(K10*240) -> 0 | M10: =SUM(D10*120) -> 2127.936 | N10: =SUM(E10*120) -> 806.928 | O10: =SUM(F10*54) -> 6026.9778 | P10: =SUM(G10*54) -> 0 | Q10: =SUM(H10*120) -> 0 | R10: =SUM(I10*1000) -> 0 | S10: =SUM(J10*140) -> 0 | T10: =SUM(L10:S10) -> 8961.8418
A11: 7 | B11: 46060 | F11: 111.6107 | G11: =IF(OR(B11="",NOT(ISERROR(SEARCH("KPI",$A$2))),NOT(ISERROR(SEARCH("Полиом",$A$2)))),0,IF(70-F11<=0,0,70-F11)) -> 0 | L11: =SUM(K11*240) -> 0 | M11: =SUM(D11*120) -> 0 | N11: =SUM(E11*120) -> 0 | O11: =SUM(F11*54) -> 6026.9778 | P11: =SUM(G11*54) -> 0 | Q11: =SUM(H11*120) -> 0 | R11: =SUM(I11*1000) -> 0 | S11: =SUM(J11*140) -> 0 | T11: =SUM(L11:S11) -> 6026.9778
A12: 8 | B12: 46061 | F12: 111.6107 | G12: =IF(OR(B12="",NOT(ISERROR(SEARCH("KPI",$A$2))),NOT(ISERROR(SEARCH("Полиом",$A$2)))),0,IF(70-F12<=0,0,70-F12)) -> 0 | L12: =SUM(K12*240) -> 0 | M12: =SUM(D12*120) -> 0 | N12: =SUM(E12*120) -> 0 | O12: =SUM(F12*54) -> 6026.9778 | P12: =SUM(G12*54) -> 0 | Q12: =SUM(H12*120) -> 0 | R12: =SUM(I12*1000) -> 0 | S12: =SUM(J12*140) -> 0 | T12: =SUM(L12:S12) -> 6026.9778
A13: 9 | B13: 46062 | F13: 111.6107 | G13: =IF(OR(B13="",NOT(ISERROR(SEARCH("KPI",$A$2))),NOT(ISERROR(SEARCH("Полиом",$A$2)))),0,IF(70-F13<=0,0,70-F13)) -> 0 | L13: =SUM(K13*240) -> 0 | M13: =SUM(D13*120) -> 0 | N13: =SUM(E13*120) -> 0 | O13: =SUM(F13*54) -> 6026.9778 | P13: =SUM(G13*54) -> 0 | Q13: =SUM(H13*120) -> 0 | R13: =SUM(I13*1000) -> 0 | S13: =SUM(J13*140) -> 0 | T13: =SUM(L13:S13) -> 6026.9778
A14: 10 | B14: 46063 | E14: 10.9311 | F14: 100.6796 | G14: =IF(OR(B14="",NOT(ISERROR(SEARCH("KPI",$A$2))),NOT(ISERROR(SEARCH("Полиом",$A$2)))),0,IF(70-F14<=0,0,70-F14)) -> 0 | L14: =SUM(K14*240) -> 0 | M14: =SUM(D14*120) -> 0 | N14: =SUM(E14*120) -> 1311.732 | O14: =SUM(F14*54) -> 5436.6984 | P14: =SUM(G14*54) -> 0 | Q14: =SUM(H14*120) -> 0 | R14: =SUM(I14*1000) -> 0 | S14: =SUM(J14*140) -> 0 | T14: =SUM(L14:S14) -> 6748.4304
A15: 11 | B15: 46064 | E15: 17.435 | F15: 83.2446 | G15: =IF(OR(B15="",NOT(ISERROR(SEARCH("KPI",$A$2))),NOT(ISERROR(SEARCH("Полиом",$A$2)))),0,IF(70-F15<=0,0,70-F15)) -> 0 | L15: =SUM(K15*240) -> 0 | M15: =SUM(D15*120) -> 0 | N15: =SUM(E15*120) -> 2092.2 | O15: =SUM(F15*54) -> 4495.2084 | P15: =SUM(G15*54) -> 0 | Q15: =SUM(H15*120) -> 0 | R15: =SUM(I15*1000) -> 0 | S15: =SUM(J15*140) -> 0 | T15: =SUM(L15:S15) -> 6587.4084
A16: 12 | B16: 46065 | F16: 83.2446 | G16: =IF(OR(B16="",NOT(ISERROR(SEARCH("KPI",$A$2))),NOT(ISERROR(SEARCH("Полиом",$A$2)))),0,IF(70-F16<=0,0,70-F16)) -> 0 | L16: =SUM(K16*240) -> 0 | M16: =SUM(D16*120) -> 0 | N16: =SUM(E16*120) -> 0 | O16: =SUM(F16*54) -> 4495.2084 | P16: =SUM(G16*54) -> 0 | Q16: =SUM(H16*120) -> 0 | R16: =SUM(I16*1000) -> 0 | S16: =SUM(J16*140) -> 0 | T16: =SUM(L16:S16) -> 4495.2084
A17: 13 | B17: 46066 | E17: 2.2995 | F17: 80.9451 | G17: =IF(OR(B17="",NOT(ISERROR(SEARCH("KPI",$A$2))),NOT(ISERROR(SEARCH("Полиом",$A$2)))),0,IF(70-F17<=0,0,70-F17)) -> 0 | L17: =SUM(K17*240) -> 0 | M17: =SUM(D17*120) -> 0 | N17: =SUM(E17*120) -> 275.94 | O17: =SUM(F17*54) -> 4371.0354 | P17: =SUM(G17*54) -> 0 | Q17: =SUM(H17*120) -> 0 | R17: =SUM(I17*1000) -> 0 | S17: =SUM(J17*140) -> 0 | T17: =SUM(L17:S17) -> 4646.9754
A18: 14 | B18: 46067 | F18: 80.9451 | G18: =IF(OR(B18="",NOT(ISERROR(SEARCH("KPI",$A$2))),NOT(ISERROR(SEARCH("Полиом",$A$2)))),0,IF(70-F18<=0,0,70-F18)) -> 0 | L18: =SUM(K18*240) -> 0 | M18: =SUM(D18*120) -> 0 | N18: =SUM(E18*120) -> 0 | O18: =SUM(F18*54) -> 4371.0354 | P18: =SUM(G18*54) -> 0 | Q18: =SUM(H18*120) -> 0 | R18: =SUM(I18*1000) -> 0 | S18: =SUM(J18*140) -> 0 | T18: =SUM(L18:S18) -> 4371.0354
A19: 15 | B19: 46068 | F19: 80.9451 | G19: =IF(OR(B19="",NOT(ISERROR(SEARCH("KPI",$A$2))),NOT(ISERROR(SEARCH("Полиом",$A$2)))),0,IF(70-F19<=0,0,70-F19)) -> 0 | L19: =SUM(K19*240) -> 0 | M19: =SUM(D19*120) -> 0 | N19: =SUM(E19*120) -> 0 | O19: =SUM(F19*54) -> 4371.0354 | P19: =SUM(G19*54) -> 0 | Q19: =SUM(H19*120) -> 0 | R19: =SUM(I19*1000) -> 0 | S19: =SUM(J19*140) -> 0 | T19: =SUM(L19:S19) -> 4371.0354
A20: 16 | B20: 46069 | D20: 51.783 | E20: 2.1034 | F20: 130.6247 | G20: =IF(OR(B20="",NOT(ISERROR(SEARCH("KPI",$A$2))),NOT(ISERROR(SEARCH("Полиом",$A$2)))),0,IF(70-F20<=0,0,70-F20)) -> 0 | L20: =SUM(K20*240) -> 0 | M20: =SUM(D20*120) -> 6213.96 | N20: =SUM(E20*120) -> 252.408 | O20: =SUM(F20*54) -> 7053.7338 | P20: =SUM(G20*54) -> 0 | Q20: =SUM(H20*120) -> 0 | R20: =SUM(I20*1000) -> 0 | S20: =SUM(J20*140) -> 0 | T20: =SUM(L20:S20) -> 13520.102
A21: 17 | B21: 46070 | E21: 2.7732 | F21: 127.8515 | G21: =IF(OR(B21="",NOT(ISERROR(SEARCH("KPI",$A$2))),NOT(ISERROR(SEARCH("Полиом",$A$2)))),0,IF(70-F21<=0,0,70-F21)) -> 0 | L21: =SUM(K21*240) -> 0 | M21: =SUM(D21*120) -> 0 | N21: =SUM(E21*120) -> 332.784 | O21: =SUM(F21*54) -> 6903.981 | P21: =SUM(G21*54) -> 0 | Q21: =SUM(H21*120) -> 0 | R21: =SUM(I21*1000) -> 0 | S21: =SUM(J21*140) -> 0 | T21: =SUM(L21:S21) -> 7236.765
A22: 18 | B22: 46071 | E22: 20.829 | F22: 107.0225 | G22: =IF(OR(B22="",NOT(ISERROR(SEARCH("KPI",$A$2))),NOT(ISERROR(SEARCH("Полиом",$A$2)))),0,IF(70-F22<=0,0,70-F22)) -> 0 | L22: =SUM(K22*240) -> 0 | M22: =SUM(D22*120) -> 0 | N22: =SUM(E22*120) -> 2499.48 | O22: =SUM(F22*54) -> 5779.215 | P22: =SUM(G22*54) -> 0 | Q22: =SUM(H22*120) -> 0 | R22: =SUM(I22*1000) -> 0 | S22: =SUM(J22*140) -> 0 | T22: =SUM(L22:S22) -> 8278.695
A23: 19 | B23: 46072 | E23: 13.2659 | F23: 93.7566 | G23: =IF(OR(B23="",NOT(ISERROR(SEARCH("KPI",$A$2))),NOT(ISERROR(SEARCH("Полиом",$A$2)))),0,IF(70-F23<=0,0,70-F23)) -> 0 | L23: =SUM(K23*240) -> 0 | M23: =SUM(D23*120) -> 0 | N23: =SUM(E23*120) -> 1591.908 | O23: =SUM(F23*54) -> 5062.8564 | P23: =SUM(G23*54) -> 0 | Q23: =SUM(H23*120) -> 0 | R23: =SUM(I23*1000) -> 0 | S23: =SUM(J23*140) -> 0 | T23: =SUM(L23:S23) -> 6654.7644
A24: 20 | B24: 46073 | E24: 2.9673 | F24: 90.7893 | G24: =IF(OR(B24="",NOT(ISERROR(SEARCH("KPI",$A$2))),NOT(ISERROR(SEARCH("Полиом",$A$2)))),0,IF(70-F24<=0,0,70-F24)) -> 0 | L24: =SUM(K24*240) -> 0 | M24: =SUM(D24*120) -> 0 | N24: =SUM(E24*120) -> 356.076 | O24: =SUM(F24*54) -> 4902.6222 | P24: =SUM(G24*54) -> 0 | Q24: =SUM(H24*120) -> 0 | R24: =SUM(I24*1000) -> 0 | S24: =SUM(J24*140) -> 0 | T24: =SUM(L24:S24) -> 5258.6982
A25: 21 | B25: 46074 | F25: 90.7893 | G25: =IF(OR(B25="",NOT(ISERROR(SEARCH("KPI",$A$2))),NOT(ISERROR(SEARCH("Полиом",$A$2)))),0,IF(70-F25<=0,0,70-F25)) -> 0 | L25: =SUM(K25*240) -> 0 | M25: =SUM(D25*120) -> 0 | N25: =SUM(E25*120) -> 0 | O25: =SUM(F25*54) -> 4902.6222 | P25: =SUM(G25*54) -> 0 | Q25: =SUM(H25*120) -> 0 | R25: =SUM(I25*1000) -> 0 | S25: =SUM(J25*140) -> 0 | T25: =SUM(L25:S25) -> 4902.6222
A26: 22 | B26: 46075 | F26: 90.7893 | G26: =IF(OR(B26="",NOT(ISERROR(SEARCH("KPI",$A$2))),NOT(ISERROR(SEARCH("Полиом",$A$2)))),0,IF(70-F26<=0,0,70-F26)) -> 0 | L26: =SUM(K26*240) -> 0 | M26: =SUM(D26*120) -> 0 | N26: =SUM(E26*120) -> 0 | O26: =SUM(F26*54) -> 4902.6222 | P26: =SUM(G26*54) -> 0 | Q26: =SUM(H26*120) -> 0 | R26: =SUM(I26*1000) -> 0 | S26: =SUM(J26*140) -> 0 | T26: =SUM(L26:S26) -> 4902.6222
A27: 23 | B27: 46076 | F27: 90.7893 | G27: =IF(OR(B27="",NOT(ISERROR(SEARCH("KPI",$A$2))),NOT(ISERROR(SEARCH("Полиом",$A$2)))),0,IF(70-F27<=0,0,70-F27)) -> 0 | L27: =SUM(K27*240) -> 0 | M27: =SUM(D27*120) -> 0 | N27: =SUM(E27*120) -> 0 | O27: =SUM(F27*54) -> 4902.6222 | P27: =SUM(G27*54) -> 0 | Q27: =SUM(H27*120) -> 0 | R27: =SUM(I27*1000) -> 0 | S27: =SUM(J27*140) -> 0 | T27: =SUM(L27:S27) -> 4902.6222
A28: 24 | B28: 46077 | F28: 90.7893 | G28: =IF(OR(B28="",NOT(ISERROR(SEARCH("KPI",$A$2))),NOT(ISERROR(SEARCH("Полиом",$A$2)))),0,IF(70-F28<=0,0,70-F28)) -> 0 | L28: =SUM(K28*240) -> 0 | M28: =SUM(D28*120) -> 0 | N28: =SUM(E28*120) -> 0 | O28: =SUM(F28*54) -> 4902.6222 | P28: =SUM(G28*54) -> 0 | Q28: =SUM(H28*120) -> 0 | R28: =SUM(I28*1000) -> 0 | S28: =SUM(J28*140) -> 0 | T28: =SUM(L28:S28) -> 4902.6222
A29: 25 | B29: 46078 | E29: 5.8836 | F29: 84.9057 | G29: =IF(OR(B29="",NOT(ISERROR(SEARCH("KPI",$A$2))),NOT(ISERROR(SEARCH("Полиом",$A$2)))),0,IF(70-F29<=0,0,70-F29)) -> 0 | L29: =SUM(K29*240) -> 0 | M29: =SUM(D29*120) -> 0 | N29: =SUM(E29*120) -> 706.032 | O29: =SUM(F29*54) -> 4584.9078 | P29: =SUM(G29*54) -> 0 | Q29: =SUM(H29*120) -> 0 | R29: =SUM(I29*1000) -> 0 | S29: =SUM(J29*140) -> 0 | T29: =SUM(L29:S29) -> 5290.9398
A30: 26 | B30: 46079 | E30: 18.4694 | F30: 66.4363 | G30: =IF(OR(B30="",NOT(ISERROR(SEARCH("KPI",$A$2))),NOT(ISERROR(SEARCH("Полиом",$A$2)))),0,IF(70-F30<=0,0,70-F30)) -> 3.5637 | L30: =SUM(K30*240) -> 0 | M30: =SUM(D30*120) -> 0 | N30: =SUM(E30*120) -> 2216.328 | O30: =SUM(F30*54) -> 3587.5602 | P30: =SUM(G30*54) -> 192.4398 | Q30: =SUM(H30*120) -> 0 | R30: =SUM(I30*1000) -> 0 | S30: =SUM(J30*140) -> 0 | T30: =SUM(L30:S30) -> 5996.328
A31: 27 | B31: 46080 | E31: 6.0693 | F31: 60.367 | G31: =IF(OR(B31="",NOT(ISERROR(SEARCH("KPI",$A$2))),NOT(ISERROR(SEARCH("Полиом",$A$2)))),0,IF(70-F31<=0,0,70-F31)) -> 9.633 | L31: =SUM(K31*240) -> 0 | M31: =SUM(D31*120) -> 0 | N31: =SUM(E31*120) -> 728.316 | O31: =SUM(F31*54) -> 3259.818 | P31: =SUM(G31*54) -> 520.182 | Q31: =SUM(H31*120) -> 0 | R31: =SUM(I31*1000) -> 0 | S31: =SUM(J31*140) -> 0 | T31: =SUM(L31:S31) -> 4508.316
A32: 28 | B32: 46081 | F32: 60.367 | G32: =IF(OR(B32="",NOT(ISERROR(SEARCH("KPI",$A$2))),NOT(ISERROR(SEARCH("Полиом",$A$2)))),0,IF(70-F32<=0,0,70-F32)) -> 9.633 | L32: =SUM(K32*240) -> 0 | M32: =SUM(D32*120) -> 0 | N32: =SUM(E32*120) -> 0 | O32: =SUM(F32*54) -> 3259.818 | P32: =SUM(G32*54) -> 520.182 | Q32: =SUM(H32*120) -> 0 | R32: =SUM(I32*1000) -> 0 | S32: =SUM(J32*140) -> 0 | T32: =SUM(L32:S32) -> 3780
A33: 29 | G33: =IF(OR(B33="",NOT(ISERROR(SEARCH("KPI",$A$2))),NOT(ISERROR(SEARCH("Полиом",$A$2)))),0,IF(70-F33<=0,0,70-F33)) -> 0 | L33: =SUM(K33*240) -> 0 | M33: =SUM(D33*120) -> 0 | N33: =SUM(E33*120) -> 0 | O33: =SUM(F33*54) -> 0 | P33: =SUM(G33*54) -> 0 | Q33: =SUM(H33*120) -> 0 | R33: =SUM(I33*1000) -> 0 | S33: =SUM(J33*140) -> 0 | T33: =SUM(L33:S33) -> 0
A34: 30 | G34: =IF(OR(B34="",NOT(ISERROR(SEARCH("KPI",$A$2))),NOT(ISERROR(SEARCH("Полиом",$A$2)))),0,IF(70-F34<=0,0,70-F34)) -> 0 | L34: =SUM(K34*240) -> 0 | M34: =SUM(D34*120) -> 0 | N34: =SUM(E34*120) -> 0 | O34: =SUM(F34*54) -> 0 | P34: =SUM(G34*54) -> 0 | Q34: =SUM(H34*120) -> 0 | R34: =SUM(I34*1000) -> 0 | S34: =SUM(J34*140) -> 0 | T34: =SUM(L34:S34) -> 0
G35: =IF(OR(B35="",NOT(ISERROR(SEARCH("KPI",$A$2))),NOT(ISERROR(SEARCH("Полиом",$A$2)))),0,IF(70-F35<=0,0,70-F35)) -> 0 | L35: =SUM(K35*240) -> 0 | M35: =SUM(D35*120) -> 0 | N35: =SUM(E35*120) -> 0 | O35: =SUM(F35*54) -> 0 | P35: =SUM(G35*54) -> 0 | Q35: =SUM(H35*120) -> 0 | R35: =SUM(I35*1000) -> 0 | S35: =SUM(J35*140) -> 0 | T35: =SUM(L35:S35) -> 0
F36: =SUM(F5:F35) -> 2724.4847 | G36: =SUM(G5:G35) -> 22.8297 | H36: =SUM(H5:H35) -> 0 | I36: =SUM(I5:I35) -> 0 | J36: =SUM(J5:J35) -> 0 | K36: =SUM(K5:K35) -> 0 | L36: =SUM(L5:L35) -> 0 | M36: =SUM(M5:M35) -> 8341.896 | ... T36: =SUM(T5:T35) -> 172355.73
T37: =T36*1.22 -> 210273.99

Sheet ИТОГО
A1: =G16 -> 1.3740576e+08
I2: ТОП
A3: Склад | B3: Сибур | C3: Завод | D3: Русвинил | E3: Клиенты сибура | F3: Остальные | G3: Итого | I3: Нижнекамск завод | J3: 53929177
A4: Баумана | B4: =INDEX($M$45:$M$54,MATCH(A4,$A$45:$A$54,0),1) -> 6966332.6 | C4: 0 | D4: =INDEX($B$57:$B$73,MATCH(A4,$A$57:$A$73,0),1) -> 427719.95 | E4: =SUMIF($F$19:$F$42,A4,$G$19:$G$42) -> 0 | F4: =SUMIF($B$19:$B$27,A4,$C$19:$C$27) -> 38511.2 | G4: =SUM(B4:F4) -> 7432563.8 | I4: Казань_Автосервисная | J4: 18532327
A5: Новикова-Прибоя | B5: =INDEX($M$45:$M$54,MATCH(A5,$A$45:$A$54,0),1) -> 10394917 | C5: 0 | D5: =INDEX($B$57:$B$73,MATCH(A5,$A$57:$A$73,0),1) -> 1025950.5 | E5: =SUMIF($F$19:$F$42,A5,$G$19:$G$42) -> 0 | F5: =SUMIF($B$19:$B$27,A5,$C$19:$C$27) -> 6648 | G5: =SUM(B5:F5) -> 11427516 | I5: Новикова-Прибоя | J5: 11427516
A6: Екатеринбург | B6: =INDEX($M$45:$M$54,MATCH(A6,$A$45:$A$54,0),1) -> 9888337.3 | C6: 0 | D6: =INDEX($B$57:$B$73,MATCH(A6,$A$57:$A$73,0),1) -> 0 | E6: =SUMIF($F$19:$F$42,A6,$G$19:$G$42) -> 0 | F6: =SUMIF($B$19:$B$27,A6,$C$19:$C$27) -> 0 | G6: =SUM(B6:F6) -> 9888337.3 | I6: Екатеринбург | J6: 9888337.3
A7: Новосибирск | B7: =INDEX($M$45:$M$54,MATCH(A7,$A$45:$A$54,0),1) -> 6087106.4 | C7: 0 | D7: =INDEX($B$57:$B$73,MATCH(A7,$A$57:$A$73,0),1) -> 0 | E7: =SUMIF($F$19:$F$42,A7,$G$19:$G$42) -> 210273.99 | F7: =SUMIF($B$19:$B$27,A7,$C$19:$C$27) -> 0 | G7: =SUM(B7:F7) -> 6297380.4 | I7: Казань_Приволжская | J7: 8384342
A8: Новосибирск_Пасечная | B8: =INDEX($M$45:$M$54,MATCH(A8,$A$45:$A$54,0),1) -> 5588857.3 | C8: 0 | D8: =INDEX($B$57:$B$73,MATCH(A8,$A$57:$A$73,0),1) -> 0 | E8: =SUMIF($F$19:$F$42,A8,$G$19:$G$42) -> 0 | F8: =SUMIF($B$19:$B$27,A8,$C$19:$C$27) -> 0 | G8: =SUM(B8:F8) -> 5588857.3 | I8: Зеленодольск | J8: 8120245.7
A9: Казань_Автосервисная | B9: =INDEX($M$45:$M$54,MATCH(A9,$A$45:$A$54,0),1) -> 18532327 | C9: 0 | D9: =INDEX($B$57:$B$73,MATCH(A9,$A$57:$A$73,0),1) -> 0 | E9: =SUMIF($F$19:$F$42,A9,$G$19:$G$42) -> 0 | F9: =SUMIF($B$19:$B$27,A9,$C$19:$C$27) -> 0 | G9: =SUM(B9:F9) -> 18532327 | I9: Баумана | J9: 7432563.8
A10: Казань_Приволжская | B10: =INDEX($M$45:$M$54,MATCH(A10,$A$45:$A$54,0),1) -> 8384342 | C10: 0 | D10: =INDEX($B$57:$B$73,MATCH(A10,$A$57:$A$73,0),1) -> 0 | E10: =SUMIF($F$19:$F$42,A10,$G$19:$G$42) -> 0 | F10: =SUMIF($B$19:$B$27,A10,$C$19:$C$27) -> 0 | G10: =SUM(B10:F10) -> 8384342 | I10: Новосибирск | J10: 6297380.4
A11: Зеленодольск | B11: =INDEX($M$45:$M$54,MATCH(A11,$A$45:$A$54,0),1) -> 7400248.4 | C11: 0 | D11: =INDEX($B$57:$B$73,MATCH(A11,$A$57:$A$73,0),1) -> 0 | E11: =SUMIF($F$19:$F$42,A11,$G$19:$G$42) -> 719997.26 | F11: =SUMIF($B$19:$B$27,A11,$C$19:$C$27) -> 0 | G11: =SUM(B11:F11) -> 8120245.7 | I11: Новосибирск_Пасечная | J11: 5588857.3
A12: Нижнекамск | B12: =INDEX($M$45:$M$54,MATCH(A12,$A$45:$A$54,0),1) -> 3607135.2 | C12: 0 | D12: =INDEX($B$57:$B$73,MATCH(A12,$A$57:$A$73,0),1) -> 0 | E12: =SUMIF($F$19:$F$42,A12,$G$19:$G$42) -> 0 | F12: =SUMIF($B$19:$B$27,A12,$C$19:$C$27) -> 0 | G12: =SUM(B12:F12) -> 3607135.2 | I12: Березовая Пойма | J12: 4197882
A13: Нижнекамск завод | B13: 0 | C13: =C29+C37 -> 53929177 | D13: =INDEX($B$57:$B$73,MATCH(A13,$A$57:$A$73,0),1) -> 0 | E13: =SUMIF($F$19:$F$42,A13,$G$19:$G$42) -> 0 | F13: =SUMIF($B$19:$B$27,A13,$C$19:$C$27) -> 0 | G13: =SUM(B13:F13) -> 53929177 | I13: Нижнекамск | J13: 3607135.2
A14: Монастырка | B14: 0 | C14: 0 | D14: =INDEX($B$57:$B$73,MATCH(A14,$A$57:$A$73,0),1) -> 0 | E14: =SUMIF($F$19:$F$42,A14,$G$19:$G$42) -> 0 | F14: =SUMIF($B$19:$B$27,A14,$C$19:$C$27) -> 0 | G14: =SUM(B14:F14) -> 0 | I14: Монастырка | J14: 0
A15: Березовая Пойма | B15: =INDEX($M$45:$M$54,MATCH(A15,$A$45:$A$54,0),1) -> 0 | C15: 0 | D15: =INDEX($B$57:$B$73,MATCH(A15,$A$57:$A$73,0),1) -> 4197882 | E15: =SUMIF($F$19:$F$42,A15,$G$19:$G$42) -> 0 | F15: =SUMIF($B$19:$B$27,A15,$C$19:$C$27) -> 0 | G15: =SUM(B15:F15) -> 4197882
B16: =SUM(B4:B15) -> 76849603 | C16: =SUM(C4:C15) -> 53929177 | D16: =SUM(D4:D15) -> 5651552.5 | E16: =SUM(E4:E15) -> 930271.25 | F16: =SUM(F4:F15) -> 45159.2 | G16: =SUM(G4:G15) -> 1.3740576e+08
A18: Остальные клиенты | C18: =SUM(C19:C27) -> 45159.2 | E18: Клиенты сибура | G18: =SUM(G19:G41) -> 930271.25
A19: Стройтех | B19: Баумана | C19: {=IFERROR(INDIRECT("'" & A19 & "'!A1"),)} -> 21478 | E19: Приоритет | F19: Баумана | G19: {=IFERROR(INDIRECT("'" & E19 & " " & F19 & "'!A1"),0)} -> 0
A20: Ергарда | B20: Баумана | C20: {=IFERROR(INDIRECT("'" & A20 & "'!A1"),)} -> 8064 | E20: Фармпласт | F20: Баумана | G20: {=IFERROR(INDIRECT("'" & E20 & " " & F20 & "'!A1"),0)} -> 0
A21: Литейные решения | B21: Баумана | C21: {=IFERROR(INDIRECT("'" & A21 & "'!A1"),)} -> 7786 | E21: Юг Полимер | F21: Баумана | G21: {=IFERROR(INDIRECT("'" & E21 & " " & F21 & "'!A1"),0)} -> 0
A22: Сандекс | B22: Баумана | C22: {=IFERROR(INDIRECT("'" & A22 & "'!A1"),)} -> 578.4 | E22: Центрополимер | F22: Екатеринбург | G22: {=IFERROR(INDIRECT("'" & E22 & " " & F22 & "'!A1"),0)} -> 0
A23: ЛС-Техномет | B23: Баумана | C23: {=IFERROR(INDIRECT("'" & A23 & "'!A1"),)} -> 604.8 | E23: Приоритет | F23: Екатеринбург | G23: {=IFERROR(INDIRECT("'" & E23 & " " & F23 & "'!A1"),0)} -> 0
A24: РусДжам | B24: ГАЗ | C24: {=IFERROR(INDIRECT("'" & A24 & "'!A1"),)} -> 0 | E24: Фармпласт | F24: Екатеринбург | G24: {=IFERROR(INDIRECT("'" & E24 & " " & F24 & "'!A1"),0)} -> 0
A25: Виго | B25: Новикова-Прибоя | C25: {=IFERROR(INDIRECT("'" & A25 & "'!A1"),)} -> 0 | E25: Приоритет | F25: Зеленодольск | G25: {=IFERROR(INDIRECT("'" & E25 & " " & F25 & "'!A1"),0)} -> 0
A26: Доктор Франк | B26: Новикова-Прибоя | C26: {=IFERROR(INDIRECT("'" & A26 & "'!A1"),)} -> 6648 | E26: Данафлекс | F26: Зеленодольск | G26: {=IFERROR(INDIRECT("'" & E26 & " " & F26 & "'!t37"),0)} -> 719997.26
A27: Нефтезол | B27: Новикова-Прибоя | C27: {=IFERROR(INDIRECT("'" & A27 & "'!A1"),)} -> 0 | E27: ИП Ксендз | F27: Нижнекамск | G27: {=IFERROR(INDIRECT("'" & E27 & " " & F27 & "'!A1"),0)} -> 0
E28: Фармпласт | F28: Новикова-Прибоя | G28: {=IFERROR(INDIRECT("'" & E28 & " " & F28 & "'!A1"),0)} -> 0
A29: Нижнекамск завод | C29: =SUM(C30:C35) -> 43767745 | E29: Центрополимер | F29: Новикова-Прибоя | G29: {=IFERROR(INDIRECT("'" & E29 & " " & F29 & "'!A1"),0)} -> 0
A30: ПРР | C30: {=INDIRECT("'" & A29 & "'!F17")} -> 16167490 | E30: Юг Полимер | F30: Новикова-Прибоя | G30: {=IFERROR(INDIRECT("'" & E30 & " " & F30 & "'!A1"),0)} -> 0
A31: Кладовки | C31: {=INDIRECT("'" & A29 & "'!F16")} -> 0 | E31: Приоритет | F31: Новикова-Прибоя | G31: {=IFERROR(INDIRECT("'" & E31 & " " & F31 & "'!A1"),0)} -> 0
A32: Стропальщики | C32: {=INDIRECT("'" & A29 & "'!F18")} -> 762500 | E32: Биаксплен | F32: Новосибирск | G32: {=IFERROR(INDIRECT("'" & E32 & " " & F32 & "'!A1"),0)} -> 210273.99
A33: Мойка контейнеров | C33: {=INDIRECT("'" & A29 & "'!F19")} -> 1668332 | E33: Центрополимер | F33: Новосибирск | G33: {=IFERROR(INDIRECT("'" & E33 & " " & F33 & "'!A1"),0)} -> 0
A34: МТО | C34: {=INDIRECT("'" & A29 & "'!F20")} -> 18346015 | E34: Фармпласт | F34: Новосибирск | G34: {=IFERROR(INDIRECT("'" & E34 & " " & F34 & "'!A1"),0)} -> 0
A35: МТО 2520 | C35: {=INDIRECT("'" & A29 & "'!F21")} -> 6823408
E36: Юг Полимер | F36: Зеленодольск | G36: {=IFERROR(INDIRECT("'" & E36 & " " & F36 & "'!A1"),0)} -> 0
A37: Контейнерные площадки | C37: =SUM(C38:C42) -> 10161432 | E37: Фармпласт | F37: Казань_Автосервисная | G37: {=IFERROR(INDIRECT("'" & E37 & " " & F37 & "'!A1"),0)} -> 0
A38: КОС | C38: =3097212 -> 3097212 | E38: Приоритет | F38: Казань_Приволжская | G38: {=IFERROR(INDIRECT("'" & E38 & " " & F38 & "'!A1"),0)} -> 0
A39: Нижнекамск | C39: 7064220 | E39: Центрополимер | F39: Баумана | G39: {=IFERROR(INDIRECT("'" & E39 & " " & F39 & "'!A1"),0)} -> 0
E40: Приоритет | F40: Казань_Автосервисная | G40: {=IFERROR(INDIRECT("'" & E40 & " " & F40 & "'!A1"),0)} -> 0
E41: Оникс | F41: Нижнекамск | G41: {=IFERROR(INDIRECT("'" & E41 & " " & F41 & "'!A1"),0)} -> 0
...

Sheet Сводка
A1: KPI | B1: Баумана | C1: =INDEX(ИТОГО!$B$45:$L$54,MATCH(Сводка!B1,ИТОГО!$A$45:$A$54,0),MATCH(Сводка!A1,ИТОГО!$B$44:$L$44,0)) -> 53220.88
A2: Полиом | B2: Баумана | C2: =INDEX(ИТОГО!$B$45:$L$54,MATCH(Сводка!B2,ИТОГО!$A$45:$A$54,0),MATCH(Сводка!A2,ИТОГО!$B$44:$L$44,0)) -> 217933.19
A3: Полимеры | B3: Баумана | C3: =INDEX(ИТОГО!$B$45:$L$54,MATCH(Сводка!B3,ИТОГО!$A$45:$A$54,0),MATCH(Сводка!A3,ИТОГО!$B$44:$L$44,0)) -> 6668338.6
A4: Каучук | B4: Баумана | C4: =INDEX(ИТОГО!$B$45:$L$54,MATCH(Сводка!B4,ИТОГО!$A$45:$A$54,0),MATCH(Сводка!A4,ИТОГО!$B$44:$L$44,0)) -> 0
A5: ПСОН | B5: Баумана | C5: =INDEX(ИТОГО!$B$45:$L$54,MATCH(Сводка!B5,ИТОГО!$A$45:$A$54,0),MATCH(Сводка!A5,ИТОГО!$B$44:$L$44,0)) -> 0
A6: Полиэфир | B6: Баумана | C6: =INDEX(ИТОГО!$B$45:$L$54,MATCH(Сводка!B6,ИТОГО!$A$45:$A$54,0),MATCH(Сводка!A6,ИТОГО!$B$44:$L$44,0)) -> 0
A7: СБС | B7: Баумана | C7: =INDEX(ИТОГО!$B$45:$L$54,MATCH(Сводка!B7,ИТОГО!$A$45:$A$54,0),MATCH(Сводка!A7,ИТОГО!$B$44:$L$44,0)) -> 0
A8: Порошок | B8: Баумана | C8: =INDEX(ИТОГО!$B$45:$L$54,MATCH(Сводка!B8,ИТОГО!$A$45:$A$54,0),MATCH(Сводка!A8,ИТОГО!$B$44:$L$44,0)) -> 0
A9: НПЭГ | B9: Баумана | C9: =INDEX(ИТОГО!$B$45:$L$54,MATCH(Сводка!B9,ИТОГО!$A$45:$A$54,0),MATCH(Сводка!A9,ИТОГО!$B$44:$L$44,0)) -> 0
A10: Экспорт | B10: Баумана | C10: =INDEX(ИТОГО!$B$45:$L$54,MATCH(Сводка!B10,ИТОГО!$A$45:$A$54,0),MATCH(Сводка!A10,ИТОГО!$B$44:$L$44,0)) -> 26840
A11: Доп услуги | B11: Баумана | C11: =INDEX(ИТОГО!$B$45:$L$54,MATCH(Сводка!B11,ИТОГО!$A$45:$A$54,0),MATCH(Сводка!A11,ИТОГО!$B$44:$L$44,0)) -> 0
A12: KPI | B12: Новикова-Прибоя | C12: =INDEX(ИТОГО!$B$45:$L$54,MATCH(Сводка!B12,ИТОГО!$A$45:$A$54,0),MATCH(Сводка!A12,ИТОГО!$B$44:$L$44,0)) -> 41717.38
... A99: Доп услуги | B99: Казань_Приволжская | C99: =INDEX(ИТОГО!$B$45:$L$54,MATCH(Сводка!B99,ИТОГО!$A$45:$A$54,0),MATCH(Сводка!A99,ИТОГО!$B$44:$L$44,0)) -> 0
A100: Русвинил | B100: Баумана | C100: =ИТОГО!B57 -> 427719.95
A101: Русвинил | B101: Новикова-Прибоя | C101: =ИТОГО!B58 -> 1025950.5
A102: Русвинил | B102: Березовая Пойма | C102: =ИТОГО!B67 -> 4197882
A103: ПРР | B103: Нижнекамск завод | C103: =ИТОГО!C30 -> 16167490
A104: Кладовки | B104: Нижнекамск завод | C104: =ИТОГО!C31 -> 0
A105: Стропальщики | B105: Нижнекамск завод | C105: =ИТОГО!C32 -> 762500
A106: Мойка контейнеров | B106: Нижнекамск завод | C106: =ИТОГО!C33 -> 1668332
A107: МТО | B107: Нижнекамск завод | C107: =ИТОГО!C34 -> 18346015
A108: МТО 2520 | B108: Нижнекамск завод | C108: =ИТОГО!C35 -> 6823408
A109: КП КОС | B109: Нижнекамск завод | C109: =ИТОГО!C38 -> 3097212
A110: КП Нижнекамск | B110: Нижнекамск завод | C110: =ИТОГО!C39 -> 7064220
A111: Стройтех | B111: Баумана | C111: =ИТОГО!C19 -> 21478
A112: Ергарда | B112: Баумана | C112: =ИТОГО!C20 -> 8064
A113: Литейные решения | B113: Баумана | C113: =ИТОГО!C21 -> 7786
A114: Сандекс | B114: Баумана | C114: =ИТОГО!C22 -> 578.4
A115: ЛС-Техномет | B115: Баумана | C115: =ИТОГО!C23 -> 604.8
A116: Приоритет | B116: Баумана | C116: =ИТОГО!G19 -> 0
A117: Фармпласт | B117: Баумана | C117: =ИТОГО!G20 -> 0
A118: Юг Полимер | B118: Баумана | C118: =ИТОГО!G21 -> 0
A119: Центрополимер | B119: Екатеринбург | C119: =ИТОГО!G22 -> 0
A120: Приоритет | B120: Екатеринбург | C120: =ИТОГО!G23 -> 0
A121: Фармпласт | B121: Екатеринбург | C121: =ИТОГО!G24 -> 0
A122: Приоритет | B122: Зеленодольск | C122: =ИТОГО!G25 -> 0
A123: Данафлекс | B123: Зеленодольск | C123: =ИТОГО!G26 -> 719997.26
A124: ИП Ксендз | B124: Нижнекамск | C124: =ИТОГО!G27 -> 0
A125: Фармпласт | B125: Новикова-Прибоя | C125: =ИТОГО!G28 -> 0
A126: Центрополимер | B126: Новикова-Прибоя | C126: =ИТОГО!G29 -> 0
...

Sheet Другое

Sheet Нижнекамск завод
A9: № | B9: Наименование услуг (работ) | C9: Ед. изм. | D9: Количество | E9: Цена | F9: Сумма
A14: Итого: | F14: =SUM(F10:F13) -> 0
A15: Без налога (НДС) | F15: =SUM(F14) -> 0
A16: Всего (с учетом НДС) | F16: =SUM(F15)*1.2 -> 0
A17: Вышеперечисленные услуги (работы) выполнены полностью. | E17: ПРР | F17: 16167490
A18: ПОКЛАЖЕДАТЕЛЬ претензий по объему, качеству и срокам оказания услуг претензий не имеет. | E18: Стропальщики | F18: 762500
E19: Контейнеры | F19: 1668332
E20: МТО | F20: 18346015
E21: МТО 2520 | F21: 6823408
A22: ООО "ДТМ" | D22: ПАО "Нижнекамскнефтехим"
A24: ____________________Молькова Т.Ю. | B24: Расстегаев Д.О. | D24: ____________________

Sheet Резерв
A3: ="Отчет по резерву хранению товара РВ " & TEXT(A6,"ММММ ") & YEAR(A6) & "" -> Отчет по резерву хранению товара РВ Февраль 2026
A4: дата | C4: Хранение Баумана | D4: Хранение Новикова | E4: Хранение Березовая Пойма | F4: Общее хранение | G4: Резерв 8000 т | H4: стоимость резерва | I4: итого
A6: 46054 | C6: ='[1]РВ Баумана'!G6 -> 801.35 | D6: ='[1]РВ Новикова-Прибоя'!G6 -> 1345.04 | E6: ='[1]РВ Березовая Пойма'!G6 -> 4865.205 | F6: =SUM(C6:E6) -> 7011.595 | G6: =IF(A6<>"",IF(8000-F6<0,0,8000-F6),0) -> 988.405 | H6: =G6*15 -> 14826.075 | I6: =SUM(H6:H6) -> 14826.075 | J6: =IF(OR(WEEKDAY(A6)=1,WEEKDAY(A6)=7,NOT(ISERROR(MATCH(A6,[1]Праздники!A:A,0)))),"Выходной","Рабочий") -> Выходной
A7: 46055 | C7: ='[1]РВ Баумана'!G7 -> 801.35 | D7: ='[1]РВ Новикова-Прибоя'!G7 -> 1345.04 | E7: ='[1]РВ Березовая Пойма'!G7 -> 5198.655 | F7: =SUM(C7:E7) -> 7345.045 | G7: =IF(A7<>"",IF(8000-F7<0,0,8000-F7),0) -> 654.955 | H7: =G7*15 -> 9824.325 | I7: =SUM(H7:H7) -> 9824.325 | J7: =IF(OR(WEEKDAY(A7)=1,WEEKDAY(A7)=7,NOT(ISERROR(MATCH(A7,[1]Праздники!A:A,0)))),"Выходной","Рабочий") -> Рабочий
A8: 46056 | C8: ='[1]РВ Баумана'!G8 -> 801.35 | D8: ='[1]РВ Новикова-Прибоя'!G8 -> 1345.04 | E8: ='[1]РВ Березовая Пойма'!G8 -> 5663.615 | F8: =SUM(C8:E8) -> 7810.005 | G8: =IF(A8<>"",IF(8000-F8<0,0,8000-F8),0) -> 189.995 | H8: =G8*15 -> 2849.925 | I8: =SUM(H8:H8) -> 2849.925 | J8: =IF(OR(WEEKDAY(A8)=1,WEEKDAY(A8)=7,NOT(ISERROR(MATCH(A8,[1]Праздники!A:A,0)))),"Выходной","Рабочий") -> Рабочий
A9: 46057 | C9: ='[1]РВ Баумана'!G9 -> 801.35 | D9: ='[1]РВ Новикова-Прибоя'!G9 -> 1345.04 | E9: ='[1]РВ Березовая Пойма'!G9 -> 5839.615 | F9: =SUM(C9:E9) -> 7986.005 | G9: =IF(A9<>"",IF(8000-F9<0,0,8000-F9),0) -> 13.995 | H9: =G9*15 -> 209.925 | I9: =SUM(H9:H9) -> 209.925 | J9: =IF(OR(WEEKDAY(A9)=1,WEEKDAY(A9)=7,NOT(ISERROR(MATCH(A9,[1]Праздники!A:A,0)))),"Выходной","Рабочий") -> Рабочий
A10: 46058 | C10: ='[1]РВ Баумана'!G10 -> 801.35 | D10: ='[1]РВ Новикова-Прибоя'!G10 -> 1478.42 | E10: ='[1]РВ Березовая Пойма'!G10 -> 5773.385 | F10: =SUM(C10:E10) -> 8053.155 | G10: =IF(A10<>"",IF(8000-F10<0,0,8000-F10),0) -> 0 | H10: =G10*15 -> 0 | I10: =SUM(H10:H10) -> 0 | J10: =IF(OR(WEEKDAY(A10)=1,WEEKDAY(A10)=7,NOT(ISERROR(MATCH(A10,[1]Праздники!A:A,0)))),"Выходной","Рабочий") -> Рабочий
A11: 46059 | C11: ='[1]РВ Баумана'!G11 -> 801.35 | D11: ='[1]РВ Новикова-Прибоя'!G11 -> 1545.38 | E11: ='[1]РВ Березовая Пойма'!G11 -> 5360.835 | F11: =SUM(C11:E11) -> 7707.565 | G11: =IF(A11<>"",IF(8000-F11<0,0,8000-F11),0) -> 292.435 | H11: =G11*15 -> 4386.525 | I11: =SUM(H11:H11) -> 4386.525 | J11: =IF(OR(WEEKDAY(A11)=1,WEEKDAY(A11)=7,NOT(ISERROR(MATCH(A11,[1]Праздники!A:A,0)))),"Выходной","Рабочий") -> Рабочий
A12: 46060 | C12: ='[1]РВ Баумана'!G12 -> 801.35 | D12: ='[1]РВ Новикова-Прибоя'!G12 -> 1567.38 | E12: ='[1]РВ Березовая Пойма'!G12 -> 5336.085 | F12: =SUM(C12:E12) -> 7704.815 | G12: =IF(A12<>"",IF(8000-F12<0,0,8000-F12),0) -> 295.185 | H12: =G12*15 -> 4427.775 | I12: =SUM(H12:H12) -> 4427.775 | J12: =IF(OR(WEEKDAY(A12)=1,WEEKDAY(A12)=7,NOT(ISERROR(MATCH(A12,[1]Праздники!A:A,0)))),"Выходной","Рабочий") -> Выходной
A13: 46061 | C13: ='[1]РВ Баумана'!G13 -> 801.35 | D13: ='[1]РВ Новикова-Прибоя'!G13 -> 1567.38 | E13: ='[1]РВ Березовая Пойма'!G13 -> 5423.165 | F13: =SUM(C13:E13) -> 7791.895 | G13: =IF(A13<>"",IF(8000-F13<0,0,8000-F13),0) -> 208.105 | H13: =G13*15 -> 3121.575 | I13: =SUM(H13:H13) -> 3121.575 | J13: =IF(OR(WEEKDAY(A13)=1,WEEKDAY(A13)=7,NOT(ISERROR(MATCH(A13,[1]Праздники!A:A,0)))),"Выходной","Рабочий") -> Выходной
A14: 46062 | C14: ='[1]РВ Баумана'!G14 -> 801.35 | D14: ='[1]РВ Новикова-Прибоя'!G14 -> 1545.38 | E14: ='[1]РВ Березовая Пойма'!G14 -> 5465.325 | F14: =SUM(C14:E14) -> 7812.055 | G14: =IF(A14<>"",IF(8000-F14<0,0,8000-F14),0) -> 187.945 | H14: =G14*15 -> 2819.175 | I14: =SUM(H14:H14) -> 2819.175 | J14: =IF(OR(WEEKDAY(A14)=1,WEEKDAY(A14)=7,NOT(ISERROR(MATCH(A14,[1]Праздники!A:A,0)))),"Выходной","Рабочий") -> Рабочий
A15: 46063 | C15: ='[1]РВ Баумана'!G15 -> 757.35 | D15: ='[1]РВ Новикова-Прибоя'!G15 -> 1523.38 | E15: ='[1]РВ Березовая Пойма'!G15 -> 5554.475 | F15: =SUM(C15:E15) -> 7835.205 | G15: =IF(A15<>"",IF(8000-F15<0,0,8000-F15),0) -> 164.795 | H15: =G15*15 -> 2471.925 | I15: =SUM(H15:H15) -> 2471.925 | J15: =IF(OR(WEEKDAY(A15)=1,WEEKDAY(A15)=7,NOT(ISERROR(MATCH(A15,[1]Праздники!A:A,0)))),"Выходной","Рабочий") -> Рабочий
A16: 46064 | C16: ='[1]РВ Баумана'!G16 -> 746.35 | D16: ='[1]РВ Новикова-Прибоя'!G16 -> 1523.38 | E16: ='[1]РВ Березовая Пойма'!G16 -> 5674.975 | F16: =SUM(C16:E16) -> 7944.705 | G16: =IF(A16<>"",IF(8000-F16<0,0,8000-F16),0) -> 55.295 | H16: =G16*15 -> 829.425 | I16: =SUM(H16:H16) -> 829.425 | J16: =IF(OR(WEEKDAY(A16)=1,WEEKDAY(A16)=7,NOT(ISERROR(MATCH(A16,[1]Праздники!A:A,0)))),"Выходной","Рабочий") -> Рабочий
A17: 46065 | C17: ='[1]РВ Баумана'!G17 -> 742.25 | D17: ='[1]РВ Новикова-Прибоя'!G17 -> 1523.38 | E17: ='[1]РВ Березовая Пойма'!G17 -> 5652.975 | F17: =SUM(C17:E17) -> 7918.605 | G17: =IF(A17<>"",IF(8000-F17<0,0,8000-F17),0) -> 81.395 | H17: =G17*15 -> 1220.925 | I17: =SUM(H17:H17) -> 1220.925 | J17: =IF(OR(WEEKDAY(A17)=1,WEEKDAY(A17)=7,NOT(ISERROR(MATCH(A17,[1]Праздники!A:A,0)))),"Выходной","Рабочий") -> Рабочий
... A33: 46081 | C33: ='[1]РВ Баумана'!G33 -> 641.525 | D33: ='[1]РВ Новикова-Прибоя'!G33 -> 464.63 | E33: ='[1]РВ Березовая Пойма'!G33 -> 4253 | F33: =SUM(C33:E33) -> 5359.155 | G33: =IF(A33<>"",IF(8000-F33<0,0,8000-F33),0) -> 2640.845 | H33: =G33*15 -> 39612.675 | I33: =SUM(H33:H33) -> 39612.675 | J33: =IF(OR(WEEKDAY(A33)=1,WEEKDAY(A33)=7,NOT(ISERROR(MATCH(A33,[1]Праздники!A:A,0)))),"Выходной","Рабочий") -> Выходной
C34: ='[1]РВ Баумана'!G34 -> 0 | D34: ='[1]РВ Новикова-Прибоя'!G34 -> 0 | E34: ='[1]РВ Березовая Пойма'!G34 -> 0 | F34: =SUM(C34:E34) -> 0 | G34: =IF(A34<>"",IF(8000-F34<0,0,8000-F34),0) -> 0 | H34: =G34*15 -> 0 | I34: =SUM(H34:H34) -> 0 | J34: =IF(OR(WEEKDAY(A34)=1,WEEKDAY(A34)=7,NOT(ISERROR(MATCH(A34,[1]Праздники!A:A,0)))),"Выходной","Рабочий") -> Выходной
C35: ='[1]РВ Баумана'!G35 -> 0 | D35: ='[1]РВ Новикова-Прибоя'!G35 -> 0 | E35: ='[1]РВ Березовая Пойма'!G35 -> 0 | F35: =SUM(C35:E35) -> 0 | G35: =IF(A35<>"",IF(8000-F35<0,0,8000-F35),0) -> 0 | H35: =G35*15 -> 0 | I35: =SUM(H35:H35) -> 0 | J35: =IF(OR(WEEKDAY(A35)=1,WEEKDAY(A35)=7,NOT(ISERROR(MATCH(A35,[1]Праздники!A:A,0)))),"Выходной","Рабочий") -> Выходной
C36: ='[1]РВ Баумана'!G36 -> 0 | D36: ='[1]РВ Новикова-Прибоя'!G36 -> 0 | E36: ='[1]РВ Березовая Пойма'!G36 -> 0 | F36: =SUM(C36:E36) -> 0 | G36: =IF(A36<>"",IF(8000-F36<0,0,8000-F36),0) -> 0 | H36: =G36*15 -> 0 | I36: =SUM(H36:H36) -> 0 | J36: =IF(OR(WEEKDAY(A36)=1,WEEKDAY(A36)=7,NOT(ISERROR(MATCH(A36,[1]Праздники!A:A,0)))),"Выходной","Рабочий") -> Выходной
C37: =SUM(C6:C36) -> 21155.675 | D37: =SUM(D6:D36) -> 35879.32 | E37: =SUM(E6:E36) -> 147197.03 | G37: =SUM(G6:G36) -> 19821.13 | H37: =SUM(H6:H36) -> 297316.95 | I37: =SUM(I6:I36) -> 297316.95
I38: =I37*1.22 -> 362726.68

Sheet РВ Баумана
R1: Выходной | S1: Рабочий
Q2: Выгрузка | R2: =SUMIF($P$6:$P$36,R$1,$C6:$C36) -> 0 | S2: =SUMIF($P$6:$P$36,S$1,$C6:$C36) -> 0
A3: ="Отчет по хранению товара РВ " & TEXT(A6,"ММММ ") & YEAR(A6) & " Баумана" -> Отчет по хранению товара РВ Февраль 2026 Баумана | Q3: Отгрузка | R3: =SUMIF($P$6:$P$36,R$1,$D6:$D36) -> 41.25 | S3: =SUMIF($P$6:$P$36,S$1,$D6:$D36) -> 159.825
A4: дата | C4: Выгрузка кол-во тонн | D4: Загрузка кол-во тонн | E4: Выгрузка после 20:00 | F4: Загрузка после 20:00 | G4: Хранение | H4: переконсолидация (тонн) | I4: стоимость выгрузки | J4: стоимость загрузки | K4: Стоимость выгрузки после 20:00 | L4: Стоимость загрузки после 20:00 | M4: стоимость хранения | N4: стоимость переконс. | O4: итого
G5: (кол-во тонн)
A6: 46054 | C6: 0 | D6: 0 | G6: 801.35 | I6: =IF(P6="Выходной",SUM(C6*150)*1.5,SUM(C6*150)) -> 0 | J6: =IF(P6="Выходной",SUM(D6*150)*1.5,SUM(D6*150)) -> 0 | K6: =IF(OR(WEEKDAY(A6)=1,WEEKDAY(A6)=7,NOT(ISERROR(MATCH(A6,[1]Праздники!A:A,0)))),SUM(E6*225)*1.5,SUM(E6*225)) -> 0 | L6: =IF(OR(WEEKDAY(A6)=1,WEEKDAY(A6)=7,NOT(ISERROR(MATCH(A6,[1]Праздники!A:A,0)))),SUM(F6*225)*1.5,SUM(F6*225)) -> 0 | M6: =SUM(G6*15) -> 12020.25 | N6: =SUM(H6)*750 -> 0 | O6: =SUM(I6:N6) -> 12020.25 | P6: =IF(OR(WEEKDAY(A6)=1,WEEKDAY(A6)=7,NOT(ISERROR(MATCH(A6,[1]Праздники!A:A,0)))),"Выходной","Рабочий") -> Выходной
A7: 46055 | C7: 0 | D7: 0 | G7: =IF(A7 ="",0,G6+C7+E7-D6-F6) -> 801.35 | I7: =IF(P7="Выходной",SUM(C7*150)*1.5,SUM(C7*150)) -> 0 | J7: =IF(P7="Выходной",SUM(D7*150)*1.5,SUM(D7*150)) -> 0 | K7: =IF(OR(WEEKDAY(A7)=1,WEEKDAY(A7)=7,NOT(ISERROR(MATCH(A7,[1]Праздники!A:A,0)))),SUM(E7*225)*1.5,SUM(E7*225)) -> 0 | L7: =IF(OR(WEEKDAY(A7)=1,WEEKDAY(A7)=7,NOT(ISERROR(MATCH(A7,[1]Праздники!A:A,0)))),SUM(F7*225)*1.5,SUM(F7*225)) -> 0 | M7: =SUM(G7*15) -> 12020.25 | N7: =SUM(H7)*750 -> 0 | O7: =SUM(I7:N7) -> 12020.25 | P7: =IF(OR(WEEKDAY(A7)=1,WEEKDAY(A7)=7,NOT(ISERROR(MATCH(A7,[1]Праздники!A:A,0)))),"Выходной","Рабочий") -> Рабочий
A8: 46056 | C8: 0 | D8: 0 | G8: =IF(A8 ="",0,G7+C8+E8-D7-F7) -> 801.35 | I8: =IF(P8="Выходной",SUM(C8*150)*1.5,SUM(C8*150)) -> 0 | J8: =IF(P8="Выходной",SUM(D8*150)*1.5,SUM(D8*150)) -> 0 | K8: =IF(OR(WEEKDAY(A8)=1,WEEKDAY(A8)=7,NOT(ISERROR(MATCH(A8,[1]Праздники!A:A,0)))),SUM(E8*225)*1.5,SUM(E8*225)) -> 0 | L8: =IF(OR(WEEKDAY(A8)=1,WEEKDAY(A8)=7,NOT(ISERROR(MATCH(A8,[1]Праздники!A:A,0)))),SUM(F8*225)*1.5,SUM(F8*225)) -> 0 | M8: =SUM(G8*15) -> 12020.25 | N8: =SUM(H8)*750 -> 0 | O8: =SUM(I8:N8) -> 12020.25 | P8: =IF(OR(WEEKDAY(A8)=1,WEEKDAY(A8)=7,NOT(ISERROR(MATCH(A8,[1]Праздники!A:A,0)))),"Выходной","Рабочий") -> Рабочий
A9: 46057 | C9: 0 | D9: 0 | G9: =IF(A9 ="",0,G8+C9+E9-D8-F8) -> 801.35 | I9: =IF(P9="Выходной",SUM(C9*150)*1.5,SUM(C9*150)) -> 0 | J9: =IF(P9="Выходной",SUM(D9*150)*1.5,SUM(D9*150)) -> 0 | K9: =IF(OR(WEEKDAY(A9)=1,WEEKDAY(A9)=7,NOT(ISERROR(MATCH(A9,[1]Праздники!A:A,0)))),SUM(E9*225)*1.5,SUM(E9*225)) -> 0 | L9: =IF(OR(WEEKDAY(A9)=1,WEEKDAY(A9)=7,NOT(ISERROR(MATCH(A9,[1]Праздники!A:A,0)))),SUM(F9*225)*1.5,SUM(F9*225)) -> 0 | M9: =SUM(G9*15) -> 12020.25 | N9: =SUM(H9)*750 -> 0 | O9: =SUM(I9:N9) -> 12020.25 | P9: =IF(OR(WEEKDAY(A9)=1,WEEKDAY(A9)=7,NOT(ISERROR(MATCH(A9,[1]Праздники!A:A,0)))),"Выходной","Рабочий") -> Рабочий
A10: 46058 | C10: 0 | D10: 0 | G10: =IF(A10 ="",0,G9+C10+E10-D9-F9) -> 801.35 | I10: =IF(P10="Выходной",SUM(C10*150)*1.5,SUM(C10*150)) -> 0 | J10: =IF(P10="Выходной",SUM(D10*150)*1.5,SUM(D10*150)) -> 0 | K10: =IF(OR(WEEKDAY(A10)=1,WEEKDAY(A10)=7,NOT(ISERROR(MATCH(A10,[1]Праздники!A:A,0)))),SUM(E10*225)*1.5,SUM(E10*225)) -> 0 | L10: =IF(OR(WEEKDAY(A10)=1,WEEKDAY(A10)=7,NOT(ISERROR(MATCH(A10,[1]Праздники!A:A,0)))),SUM(F10*225)*1.5,SUM(F10*225)) -> 0 | M10: =SUM(G10*15) -> 12020.25 | N10: =SUM(H10)*750 -> 0 | O10: =SUM(I10:N10) -> 12020.25 | P10: =IF(OR(WEEKDAY(A10)=1,WEEKDAY(A10)=7,NOT(ISERROR(MATCH(A10,[1]Праздники!A:A,0)))),"Выходной","Рабочий") -> Рабочий
A11: 46059 | C11: 0 | D11: 0 | G11: =IF(A11 ="",0,G10+C11+E11-D10-F10) -> 801.35 | I11: =IF(P11="Выходной",SUM(C11*150)*1.5,SUM(C11*150)) -> 0 | J11: =IF(P11="Выходной",SUM(D11*150)*1.5,SUM(D11*150)) -> 0 | K11: =IF(OR(WEEKDAY(A11)=1,WEEKDAY(A11)=7,NOT(ISERROR(MATCH(A11,[1]Праздники!A:A,0)))),SUM(E11*225)*1.5,SUM(E11*225)) -> 0 | L11: =IF(OR(WEEKDAY(A11)=1,WEEKDAY(A11)=7,NOT(ISERROR(MATCH(A11,[1]Праздники!A:A,0)))),SUM(F11*225)*1.5,SUM(F11*225)) -> 0 | M11: =SUM(G11*15) -> 12020.25 | N11: =SUM(H11)*750 -> 0 | O11: =SUM(I11:N11) -> 12020.25 | P11: =IF(OR(WEEKDAY(A11)=1,WEEKDAY(A11)=7,NOT(ISERROR(MATCH(A11,[1]Праздники!A:A,0)))),"Выходной","Рабочий") -> Рабочий
A12: 46060 | C12: 0 | D12: 0 | G12: =IF(A12 ="",0,G11+C12+E12-D11-F11) -> 801.35 | I12: =IF(P12="Выходной",SUM(C12*150)*1.5,SUM(C12*150)) -> 0 | J12: =IF(P12="Выходной",SUM(D12*150)*1.5,SUM(D12*150)) -> 0 | K12: =IF(OR(WEEKDAY(A12)=1,WEEKDAY(A12)=7,NOT(ISERROR(MATCH(A12,[1]Праздники!A:A,0)))),SUM(E12*225)*1.5,SUM(E12*225)) -> 0 | L12: =IF(OR(WEEKDAY(A12)=1,WEEKDAY(A12)=7,NOT(ISERROR(MATCH(A12,[1]Праздники!A:A,0)))),SUM(F12*225)*1.5,SUM(F12*225)) -> 0 | M12: =SUM(G12*15) -> 12020.25 | N12: =SUM(H12)*750 -> 0 | O12: =SUM(I12:N12) -> 12020.25 | P12: =IF(OR(WEEKDAY(A12)=1,WEEKDAY(A12)=7,NOT(ISERROR(MATCH(A12,[1]Праздники!A:A,0)))),"Выходной","Рабочий") -> Выходной
A13: 46061 | C13: 0 | D13: 0 | G13: =IF(A13 ="",0,G12+C13+E13-D12-F12) -> 801.35 | I13: =IF(P13="Выходной",SUM(C13*150)*1.5,SUM(C13*150)) -> 0 | J13: =IF(P13="Выходной",SUM(D13*150)*1.5,SUM(D13*150)) -> 0 | K13: =IF(OR(WEEKDAY(A13)=1,WEEKDAY(A13)=7,NOT(ISERROR(MATCH(A13,[1]Праздники!A:A,0)))),SUM(E13*225)*1.5,SUM(E13*225)) -> 0 | L13: =IF(OR(WEEKDAY(A13)=1,WEEKDAY(A13)=7,NOT(ISERROR(MATCH(A13,[1]Праздники!A:A,0)))),SUM(F13*225)*1.5,SUM(F13*225)) -> 0 | M13: =SUM(G13*15) -> 12020.25 | N13: =SUM(H13)*750 -> 0 | O13: =SUM(I13:N13) -> 12020.25 | P13: =IF(OR(WEEKDAY(A13)=1,WEEKDAY(A13)=7,NOT(ISERROR(MATCH(A13,[1]Праздники!A:A,0)))),"Выходной","Рабочий") -> Выходной
A14: 46062 | C14: 0 | D14: 44 | G14: =IF(A14 ="",0,G13+C14+E14-D13-F13) -> 801.35 | I14: =IF(P14="Выходной",SUM(C14*150)*1.5,SUM(C14*150)) -> 0 | J14: =IF(P14="Выходной",SUM(D14*150)*1.5,SUM(D14*150)) -> 6600 | K14: =IF(OR(WEEKDAY(A14)=1,WEEKDAY(A14)=7,NOT(ISERROR(MATCH(A14,[1]Праздники!A:A,0)))),SUM(E14*225)*1.5,SUM(E14*225)) -> 0 | L14: =IF(OR(WEEKDAY(A14)=1,WEEKDAY(A14)=7,NOT(ISERROR(MATCH(A14,[1]Праздники!A:A,0)))),SUM(F14*225)*1.5,SUM(F14*225)) -> 0 | M14: =SUM(G14*15) -> 12020.25 | N14: =SUM(H14)*750 -> 0 | O14: =SUM(I14:N14) -> 18620.25 | P14: =IF(OR(WEEKDAY(A14)=1,WEEKDAY(A14)=7,NOT(ISERROR(MATCH(A14,[1]Праздники!A:A,0)))),"Выходной","Рабочий") -> Рабочий
A15: 46063 | C15: 0 | D15: 11 | G15: =IF(A15 ="",0,G14+C15+E15-D14-F14) -> 757.35 | I15: =IF(P15="Выходной",SUM(C15*150)*1.5,SUM(C15*150)) -> 0 | J15: =IF(P15="Выходной",SUM(D15*150)*1.5,SUM(D15*150)) -> 1650 | K15: =IF(OR(WEEKDAY(A15)=1,WEEKDAY(A15)=7,NOT(ISERROR(MATCH(A15,[1]Праздники!A:A,0)))),SUM(E15*225)*1.5,SUM(E15*225)) -> 0 | L15: =IF(OR(WEEKDAY(A15)=1,WEEKDAY(A15)=7,NOT(ISERROR(MATCH(A15,[1]Праздники!A:A,0)))),SUM(F15*225)*1.5,SUM(F15*225)) -> 0 | M15: =SUM(G15*15) -> 11360.25 | N15: =SUM(H15)*750 -> 0 | O15: =SUM(I15:N15) -> 13010.25 | P15: =IF(OR(WEEKDAY(A15)=1,WEEKDAY(A15)=7,NOT(ISERROR(MATCH(A15,[1]Праздники!A:A,0)))),"Выходной","Рабочий") -> Рабочий
A16: 46064 | C16: 0 | D16: 4.1 | G16: =IF(A16 ="",0,G15+C16+E16-D15-F15) -> 746.35 | I16: =IF(P16="Выходной",SUM(C16*150)*1.5,SUM(C16*150)) -> 0 | J16: =IF(P16="Выходной",SUM(D16*150)*1.5,SUM(D16*150)) -> 615 | K16: =IF(OR(WEEKDAY(A16)=1,WEEKDAY(A16)=7,NOT(ISERROR(MATCH(A16,[1]Праздники!A:A,0)))),SUM(E16*225)*1.5,SUM(E16*225)) -> 0 | L16: =IF(OR(WEEKDAY(A16)=1,WEEKDAY(A16)=7,NOT(ISERROR(MATCH(A16,[1]Праздники!A:A,0)))),SUM(F16*225)*1.5,SUM(F16*225)) -> 0 | M16: =SUM(G16*15) -> 11195.25 | N16: =SUM(H16)*750 -> 0 | O16: =SUM(I16:N16) -> 11810.25 | P16: =IF(OR(WEEKDAY(A16)=1,WEEKDAY(A16)=7,NOT(ISERROR(MATCH(A16,[1]Праздники!A:A,0)))),"Выходной","Рабочий") -> Рабочий
A17: 46065 | C17: 0 | D17: 0 | G17: =IF(A17 ="",0,G16+C17+E17-D16-F16) -> 742.25 | I17: =IF(P17="Выходной",SUM(C17*150)*1.5,SUM(C17*150)) -> 0 | J17: =IF(P17="Выходной",SUM(D17*150)*1.5,SUM(D17*150)) -> 0 | K17: =IF(OR(WEEKDAY(A17)=1,WEEKDAY(A17)=7,NOT(ISERROR(MATCH(A17,[1]Праздники!A:A,0)))),SUM(E17*225)*1.5,SUM(E17*225)) -> 0 | L17: =IF(OR(WEEKDAY(A17)=1,WEEKDAY(A17)=7,NOT(ISERROR(MATCH(A17,[1]Праздники!A:A,0)))),SUM(F17*225)*1.5,SUM(F17*225)) -> 0 | M17: =SUM(G17*15) -> 11133.75 | N17: =SUM(H17)*750 -> 0 | O17: =SUM(I17:N17) -> 11133.75 | P17: =IF(OR(WEEKDAY(A17)=1,WEEKDAY(A17)=7,NOT(ISERROR(MATCH(A17,[1]Праздники!A:A,0)))),"Выходной","Рабочий") -> Рабочий
A18: 46066 | C18: 0 | D18: 0 | G18: =IF(A18 ="",0,G17+C18+E18-D17-F17) -> 742.25 | I18: =IF(P18="Выходной",SUM(C18*150)*1.5,SUM(C18*150)) -> 0 | J18: =IF(P18="Выходной",SUM(D18*150)*1.5,SUM(D18*150)) -> 0 | K18: =IF(OR(WEEKDAY(A18)=1,WEEKDAY(A18)=7,NOT(ISERROR(MATCH(A18,[1]Праздники!A:A,0)))),SUM(E18*225)*1.5,SUM(E18*225)) -> 0 | L18: =IF(OR(WEEKDAY(A18)=1,WEEKDAY(A18)=7,NOT(ISERROR(MATCH(A18,[1]Праздники!A:A,0)))),SUM(F18*225)*1.5,SUM(F18*225)) -> 0 | M18: =SUM(G18*15) -> 11133.75 | N18: =SUM(H18)*750 -> 0 | O18: =SUM(I18:N18) -> 11133.75 | P18: =IF(OR(WEEKDAY(A18)=1,WEEKDAY(A18)=7,NOT(ISERROR(MATCH(A18,[1]Праздники!A:A,0)))),"Выходной","Рабочий") -> Рабочий
... A33: 46081 | C33: 0 | D33: 41.25 | G33: =IF(A33 ="",0,G32+C33+E33-D32-F32) -> 641.525 | I33: =IF(P33="Выходной",SUM(C33*150)*1.5,SUM(C33*150)) -> 0 | J33: =IF(P33="Выходной",SUM(D33*150)*1.5,SUM(D33*150)) -> 9281.25 | K33: =IF(OR(WEEKDAY(A33)=1,WEEKDAY(A33)=7,NOT(ISERROR(MATCH(A33,[1]Праздники!A:A,0)))),SUM(E33*225)*1.5,SUM(E33*225)) -> 0 | L33: =IF(OR(WEEKDAY(A33)=1,WEEKDAY(A33)=7,NOT(ISERROR(MATCH(A33,[1]Праздники!A:A,0)))),SUM(F33*225)*1.5,SUM(F33*225)) -> 0 | M33: =SUM(G33*15) -> 9622.875 | N33: =SUM(H33)*750 -> 0 | O33: =SUM(I33:N33) -> 18904.125 | P33: =IF(OR(WEEKDAY(A33)=1,WEEKDAY(A33)=7,NOT(ISERROR(MATCH(A33,[1]Праздники!A:A,0)))),"Выходной","Рабочий") -> Выходной
C34: 0 | D34: 0 | G34: =IF(A34 ="",0,G33+C34+E34-D33-F33) -> 0 | I34: =IF(P34="Выходной",SUM(C34*150)*1.5,SUM(C34*150)) -> 0 | J34: =IF(P34="Выходной",SUM(D34*150)*1.5,SUM(D34*150)) -> 0 | K34: =IF(OR(WEEKDAY(A34)=1,WEEKDAY(A34)=7,NOT(ISERROR(MATCH(A34,[1]Праздники!A:A,0)))),SUM(E34*225)*1.5,SUM(E34*225)) -> 0 | L34: =IF(OR(WEEKDAY(A34)=1,WEEKDAY(A34)=7,NOT(ISERROR(MATCH(A34,[1]Праздники!A:A,0)))),SUM(F34*225)*1.5,SUM(F34*225)) -> 0 | M34: =SUM(G34*15) -> 0 | N34: =SUM(H34)*750 -> 0 | O34: =SUM(I34:N34) -> 0 | P34: =IF(OR(WEEKDAY(A34)=1,WEEKDAY(A34)=7,NOT(ISERROR(MATCH(A34,[1]Праздники!A:A,0)))),"Выходной","Рабочий") -> Выходной
C35: 0 | D35: 0 | G35: =IF(A35 ="",0,G34+C35+E35-D34-F34) -> 0 | I35: =IF(P35="Выходной",SUM(C35*150)*1.5,SUM(C35*150)) -> 0 | J35: =IF(P35="Выходной",SUM(D35*150)*1.5,SUM(D35*150)) -> 0 | K35: =IF(OR(WEEKDAY(A35)=1,WEEKDAY(A35)=7,NOT(ISERROR(MATCH(A35,[1]Праздники!A:A,0)))),SUM(E35*225)*1.5,SUM(E35*225)) -> 0 | L35: =IF(OR(WEEKDAY(A35)=1,WEEKDAY(A35)=7,NOT(ISERROR(MATCH(A35,[1]Праздники!A:A,0)))),SUM(F35*225)*1.5,SUM(F35*225)) -> 0 | M35: =SUM(G35*15) -> 0 | N35: =SUM(H35)*750 -> 0 | O35: =SUM(I35:N35) -> 0 | P35: =IF(OR(WEEKDAY(A35)=1,WEEKDAY(A35)=7,NOT(ISERROR(MATCH(A35,[1]Праздники!A:A,0)))),"Выходной","Рабочий") -> Выходной
C36: 0 | D36: 0 | G36: =IF(A36 ="",0,G35+C36+E36-D35-F35) -> 0 | I36: =IF(P36="Выходной",SUM(C36*150)*1.5,SUM(C36*150)) -> 0 | J36: =IF(P36="Выходной",SUM(D36*150)*1.5,SUM(D36*150)) -> 0 | K36: =IF(OR(WEEKDAY(A36)=1,WEEKDAY(A36)=7,NOT(ISERROR(MATCH(A36,[1]Праздники!A:A,0)))),SUM(E36*225)*1.5,SUM(E36*225)) -> 0 | L36: =IF(OR(WEEKDAY(A36)=1,WEEKDAY(A36)=7,NOT(ISERROR(MATCH(A36,[1]Праздники!A:A,0)))),SUM(F36*225)*1.5,SUM(F36*225)) -> 0 | M36: =SUM(G36*15) -> 0 | N36: =SUM(H36)*750 -> 0 | O36: =SUM(I36:N36) -> 0 | P36: =IF(OR(WEEKDAY(A36)=1,WEEKDAY(A36)=7,NOT(ISERROR(MATCH(A36,[1]Праздники!A:A,0)))),"Выходной","Рабочий") -> Выходной
C37: =SUM(C6:C36) -> 0 | D37: =SUM(D6:D36) -> 201.075 | E37: =SUM(E6:E36) -> 0 | F37: =SUM(F6:F36) -> 0 | G37: =SUM(G6:G36) -> 21155.675 | H37: =SUM(H6:H36) -> 0 | I37: =SUM(I6:I36) -> 0 | J37: =SUM(J6:J36) -> 33255 | ... O37: =SUM(O6:O36) -> 350590.12
N38: С НДС; | O38: =O37*1.22 -> 427719.95

Sheet РВ Березовая Пойма
R1: Выходной | S1: Рабочий
Q2: Выгрузка | R2: =SUMIF($P$6:$P$36,R$1,$C6:$C36) -> 731.29 | S2: =SUMIF($P$6:$P$36,S$1,$C6:$C36) -> 1702.71
A3: ="Отчет по хранению товара РВ " & TEXT(A6,"ММММ ") & YEAR(A6) & " Березовая Пойма" -> Отчет по хранению товара РВ Февраль 2026 Березовая Пойма | Q3: Отгрузка | R3: =SUMIF($P$6:$P$36,R$1,$D6:$D36) -> 877.59 | S3: =SUMIF($P$6:$P$36,S$1,$D6:$D36) -> 2121.4
A4: дата | C4: Выгрузка кол-во тонн | D4: Загрузка кол-во тонн | E4: Выгрузка после 20:00 | F4: Загрузка после 20:00 | G4: Хранение | H4: переконсолидация (тонн) | I4: стоимость выгрузки | J4: стоимость загрузки | K4: Стоимость выгрузки после 20:00 | L4: Стоимость загрузки после 20:00 | M4: стоимость хранения | N4: стоимость переконс. | O4: итого
G5: (кол-во тонн)
A6: 46054 | C6: 288.99 | D6: 0 | G6: 4865.205 | I6: =IF(P6="Выходной",SUM(C6*150)*1.5,SUM(C6*150)) -> 65022.75 | J6: =IF(P6="Выходной",SUM(D6*150)*1.5,SUM(D6*150)) -> 0 | K6: =IF(OR(WEEKDAY(A6)=1,WEEKDAY(A6)=7,NOT(ISERROR(MATCH(A6,[1]Праздники!A:A,0)))),SUM(E6*225)*1.5,SUM(E6*225)) -> 0 | L6: =IF(OR(WEEKDAY(A6)=1,WEEKDAY(A6)=7,NOT(ISERROR(MATCH(A6,[1]Праздники!A:A,0)))),SUM(F6*225)*1.5,SUM(F6*225)) -> 0 | M6: =SUM(G6*15) -> 72978.075 | N6: =SUM(H6)*750 -> 0 | O6: =SUM(I6:N6) -> 138000.83 | P6: =IF(OR(WEEKDAY(A6)=1,WEEKDAY(A6)=7,NOT(ISERROR(MATCH(A6,[1]Праздники!A:A,0)))),"Выходной","Рабочий") -> Выходной
A7: 46055 | C7: 333.45 | D7: 22 | G7: =IF(A7 ="",0,G6+C7+E7-D6-F6) -> 5198.655 | I7: =IF(P7="Выходной",SUM(C7*150)*1.5,SUM(C7*150)) -> 50017.5 | J7: =IF(P7="Выходной",SUM(D7*150)*1.5,SUM(D7*150)) -> 3300 | K7: =IF(OR(WEEKDAY(A7)=1,WEEKDAY(A7)=7,NOT(ISERROR(MATCH(A7,[1]Праздники!A:A,0)))),SUM(E7*225)*1.5,SUM(E7*225)) -> 0 | L7: =IF(OR(WEEKDAY(A7)=1,WEEKDAY(A7)=7,NOT(ISERROR(MATCH(A7,[1]Праздники!A:A,0)))),SUM(F7*225)*1.5,SUM(F7*225)) -> 0 | M7: =SUM(G7*15) -> 77979.825 | N7: =SUM(H7)*750 -> 0 | O7: =SUM(I7:N7) -> 131297.33 | P7: =IF(OR(WEEKDAY(A7)=1,WEEKDAY(A7)=7,NOT(ISERROR(MATCH(A7,[1]Праздники!A:A,0)))),"Выходной","Рабочий") -> Рабочий
A8: 46056 | C8: 486.96 | D8: 44 | G8: =IF(A8 ="",0,G7+C8+E8-D7-F7) -> 5663.615 | I8: =IF(P8="Выходной",SUM(C8*150)*1.5,SUM(C8*150)) -> 73044 | J8: =IF(P8="Выходной",SUM(D8*150)*1.5,SUM(D8*150)) -> 6600 | K8: =IF(OR(WEEKDAY(A8)=1,WEEKDAY(A8)=7,NOT(ISERROR(MATCH(A8,[1]Праздники!A:A,0)))),SUM(E8*225)*1.5,SUM(E8*225)) -> 0 | L8: =IF(OR(WEEKDAY(A8)=1,WEEKDAY(A8)=7,NOT(ISERROR(MATCH(A8,[1]Праздники!A:A,0)))),SUM(F8*225)*1.5,SUM(F8*225)) -> 0 | M8: =SUM(G8*15) -> 84954.225 | N8: =SUM(H8)*750 -> 0 | O8: =SUM(I8:N8) -> 164598.22 | P8: =IF(OR(WEEKDAY(A8)=1,WEEKDAY(A8)=7,NOT(ISERROR(MATCH(A8,[1]Праздники!A:A,0)))),"Выходной","Рабочий") -> Рабочий
A9: 46057 | C9: 220 | D9: 66.23 | G9: =IF(A9 ="",0,G8+C9+E9-D8-F8) -> 5839.615 | I9: =IF(P9="Выходной",SUM(C9*150)*1.5,SUM(C9*150)) -> 33000 | J9: =IF(P9="Выходной",SUM(D9*150)*1.5,SUM(D9*150)) -> 9934.5 | K9: =IF(OR(WEEKDAY(A9)=1,WEEKDAY(A9)=7,NOT(ISERROR(MATCH(A9,[1]Праздники!A:A,0)))),SUM(E9*225)*1.5,SUM(E9*225)) -> 0 | L9: =IF(OR(WEEKDAY(A9)=1,WEEKDAY(A9)=7,NOT(ISERROR(MATCH(A9,[1]Праздники!A:A,0)))),SUM(F9*225)*1.5,SUM(F9*225)) -> 0 | M9: =SUM(G9*15) -> 87594.225 | N9: =SUM(H9)*750 -> 0 | O9: =SUM(I9:N9) -> 130528.72 | P9: =IF(OR(WEEKDAY(A9)=1,WEEKDAY(A9)=7,NOT(ISERROR(MATCH(A9,[1]Праздники!A:A,0)))),"Выходной","Рабочий") -> Рабочий
A10: 46058 | C10: 0 | D10: 412.55 | G10: =IF(A10 ="",0,G9+C10+E10-D9-F9) -> 5773.385 | I10: =IF(P10="Выходной",SUM(C10*150)*1.5,SUM(C10*150)) -> 0 | J10: =IF(P10="Выходной",SUM(D10*150)*1.5,SUM(D10*150)) -> 61882.5 | K10: =IF(OR(WEEKDAY(A10)=1,WEEKDAY(A10)=7,NOT(ISERROR(MATCH(A10,[1]Праздники!A:A,0)))),SUM(E10*225)*1.5,SUM(E10*225)) -> 0 | L10: =IF(OR(WEEKDAY(A10)=1,WEEKDAY(A10)=7,NOT(ISERROR(MATCH(A10,[1]Праздники!A:A,0)))),SUM(F10*225)*1.5,SUM(F10*225)) -> 0 | M10: =SUM(G10*15) -> 86600.775 | N10: =SUM(H10)*750 -> 0 | O10: =SUM(I10:N10) -> 148483.28 | P10: =IF(OR(WEEKDAY(A10)=1,WEEKDAY(A10)=7,NOT(ISERROR(MATCH(A10,[1]Праздники!A:A,0)))),"Выходной","Рабочий") -> Рабочий
A11: 46059 | C11: 0 | D11: 247.05 | G11: =IF(A11 ="",0,G10+C11+E11-D10-F10) -> 5360.835 | I11: =IF(P11="Выходной",SUM(C11*150)*1.5,SUM(C11*150)) -> 0 | J11: =IF(P11="Выходной",SUM(D11*150)*1.5,SUM(D11*150)) -> 37057.5 | K11: =IF(OR(WEEKDAY(A11)=1,WEEKDAY(A11)=7,NOT(ISERROR(MATCH(A11,[1]Праздники!A:A,0)))),SUM(E11*225)*1.5,SUM(E11*225)) -> 0 | L11: =IF(OR(WEEKDAY(A11)=1,WEEKDAY(A11)=7,NOT(ISERROR(MATCH(A11,[1]Праздники!A:A,0)))),SUM(F11*225)*1.5,SUM(F11*225)) -> 0 | M11: =SUM(G11*15) -> 80412.525 | N11: =SUM(H11)*750 -> 0 | O11: =SUM(I11:N11) -> 117470.02 | P11: =IF(OR(WEEKDAY(A11)=1,WEEKDAY(A11)=7,NOT(ISERROR(MATCH(A11,[1]Праздники!A:A,0)))),"Выходной","Рабочий") -> Рабочий
A12: 46060 | C12: 222.3 | D12: 132.92 | G12: =IF(A12 ="",0,G11+C12+E12-D11-F11) -> 5336.085 | I12: =IF(P12="Выходной",SUM(C12*150)*1.5,SUM(C12*150)) -> 50017.5 | J12: =IF(P12="Выходной",SUM(D12*150)*1.5,SUM(D12*150)) -> 29907 | K12: =IF(OR(WEEKDAY(A12)=1,WEEKDAY(A12)=7,NOT(ISERROR(MATCH(A12,[1]Праздники!A:A,0)))),SUM(E12*225)*1.5,SUM(E12*225)) -> 0 | L12: =IF(OR(WEEKDAY(A12)=1,WEEKDAY(A12)=7,NOT(ISERROR(MATCH(A12,[1]Праздники!A:A,0)))),SUM(F12*225)*1.5,SUM(F12*225)) -> 0 | M12: =SUM(G12*15) -> 80041.275 | N12: =SUM(H12)*750 -> 0 | O12: =SUM(I12:N12) -> 159965.77 | P12: =IF(OR(WEEKDAY(A12)=1,WEEKDAY(A12)=7,NOT(ISERROR(MATCH(A12,[1]Праздники!A:A,0)))),"Выходной","Рабочий") -> Выходной
A13: 46061 | C13: 220 | D13: 177.84 | G13: =IF(A13 ="",0,G12+C13+E13-D12-F12) -> 5423.165 | I13: =IF(P13="Выходной",SUM(C13*150)*1.5,SUM(C13*150)) -> 49500 | J13: =IF(P13="Выходной",SUM(D13*150)*1.5,SUM(D13*150)) -> 40014 | K13: =IF(OR(WEEKDAY(A13)=1,WEEKDAY(A13)=7,NOT(ISERROR(MATCH(A13,[1]Праздники!A:A,0)))),SUM(E13*225)*1.5,SUM(E13*225)) -> 0 | L13: =IF(OR(WEEKDAY(A13)=1,WEEKDAY(A13)=7,NOT(ISERROR(MATCH(A13,[1]Праздники!A:A,0)))),SUM(F13*225)*1.5,SUM(F13*225)) -> 0 | M13: =SUM(G13*15) -> 81347.475 | N13: =SUM(H13)*750 -> 0 | O13: =SUM(I13:N13) -> 170861.48 | P13: =IF(OR(WEEKDAY(A13)=1,WEEKDAY(A13)=7,NOT(ISERROR(MATCH(A13,[1]Праздники!A:A,0)))),"Выходной","Рабочий") -> Выходной
A14: 46062 | C14: 220 | D14: 133.15 | G14: =IF(A14 ="",0,G13+C14+E14-D13-F13) -> 5465.325 | I14: =IF(P14="Выходной",SUM(C14*150)*1.5,SUM(C14*150)) -> 33000 | J14: =IF(P14="Выходной",SUM(D14*150)*1.5,SUM(D14*150)) -> 19972.5 | K14: =IF(OR(WEEKDAY(A14)=1,WEEKDAY(A14)=7,NOT(ISERROR(MATCH(A14,[1]Праздники!A:A,0)))),SUM(E14*225)*1.5,SUM(E14*225)) -> 0 | L14: =IF(OR(WEEKDAY(A14)=1,WEEKDAY(A14)=7,NOT(ISERROR(MATCH(A14,[1]Праздники!A:A,0)))),SUM(F14*225)*1.5,SUM(F14*225)) -> 0 | M14: =SUM(G14*15) -> 81979.875 | N14: =SUM(H14)*750 -> 0 | O14: =SUM(I14:N14) -> 134952.38 | P14: =IF(OR(WEEKDAY(A14)=1,WEEKDAY(A14)=7,NOT(ISERROR(MATCH(A14,[1]Праздники!A:A,0)))),"Выходной","Рабочий") -> Рабочий
A15: 46063 | C15: 222.3 | D15: 99.5 | G15: =IF(A15 ="",0,G14+C15+E15-D14-F14) -> 5554.475 | I15: =IF(P15="Выходной",SUM(C15*150)*1.5,SUM(C15*150)) -> 33345 | J15: =IF(P15="Выходной",SUM(D15*150)*1.5,SUM(D15*150)) -> 14925 | K15: =IF(OR(WEEKDAY(A15)=1,WEEKDAY(A15)=7,NOT(ISERROR(MATCH(A15,[1]Праздники!A:A,0)))),SUM(E15*225)*1.5,SUM(E15*225)) -> 0 | L15: =IF(OR(WEEKDAY(A15)=1,WEEKDAY(A15)=7,NOT(ISERROR(MATCH(A15,[1]Праздники!A:A,0)))),SUM(F15*225)*1.5,SUM(F15*225)) -> 0 | M15: =SUM(G15*15) -> 83317.125 | N15: =SUM(H15)*750 -> 0 | O15: =SUM(I15:N15) -> 131587.12 | P15: =IF(OR(WEEKDAY(A15)=1,WEEKDAY(A15)=7,NOT(ISERROR(MATCH(A15,[1]Праздники!A:A,0)))),"Выходной","Рабочий") -> Рабочий
A16: 46064 | C16: 220 | D16: 22 | G16: =IF(A16 ="",0,G15+C16+E16-D15-F15) -> 5674.975 | I16: =IF(P16="Выходной",SUM(C16*150)*1.5,SUM(C16*150)) -> 33000 | J16: =IF(P16="Выходной",SUM(D16*150)*1.5,SUM(D16*150)) -> 3300 | K16: =IF(OR(WEEKDAY(A16)=1,WEEKDAY(A16)=7,NOT(ISERROR(MATCH(A16,[1]Праздники!A:A,0)))),SUM(E16*225)*1.5,SUM(E16*225)) -> 0 | L16: =IF(OR(WEEKDAY(A16)=1,WEEKDAY(A16)=7,NOT(ISERROR(MATCH(A16,[1]Праздники!A:A,0)))),SUM(F16*225)*1.5,SUM(F16*225)) -> 0 | M16: =SUM(G16*15) -> 85124.625 | N16: =SUM(H16)*750 -> 0 | O16: =SUM(I16:N16) -> 121424.62 | P16: =IF(OR(WEEKDAY(A16)=1,WEEKDAY(A16)=7,NOT(ISERROR(MATCH(A16,[1]Праздники!A:A,0)))),"Выходной","Рабочий") -> Рабочий
A17: 46065 | C17: 0 | D17: 88.5 | G17: =IF(A17 ="",0,G16+C17+E17-D16-F16) -> 5652.975 | I17: =IF(P17="Выходной",SUM(C17*150)*1.5,SUM(C17*150)) -> 0 | J17: =IF(P17="Выходной",SUM(D17*150)*1.5,SUM(D17*150)) -> 13275 | K17: =IF(OR(WEEKDAY(A17)=1,WEEKDAY(A17)=7,NOT(ISERROR(MATCH(A17,[1]Праздники!A:A,0)))),SUM(E17*225)*1.5,SUM(E17*225)) -> 0 | L17: =IF(OR(WEEKDAY(A17)=1,WEEKDAY(A17)=7,NOT(ISERROR(MATCH(A17,[1]Праздники!A:A,0)))),SUM(F17*225)*1.5,SUM(F17*225)) -> 0 | M17: =SUM(G17*15) -> 84794.625 | N17: =SUM(H17)*750 -> 0 | O17: =SUM(I17:N17) -> 98069.625 | P17: =IF(OR(WEEKDAY(A17)=1,WEEKDAY(A17)=7,NOT(ISERROR(MATCH(A17,[1]Праздники!A:A,0)))),"Выходной","Рабочий") -> Рабочий
A18: 46066 | C18: 0 | D18: 44 | G18: =IF(A18 ="",0,G17+C18+E18-D17-F17) -> 5564.475 | I18: =IF(P18="Выходной",SUM(C18*150)*1.5,SUM(C18*150)) -> 0 | J18: =IF(P18="Выходной",SUM(D18*150)*1.5,SUM(D18*150)) -> 6600 | K18: =IF(OR(WEEKDAY(A18)=1,WEEKDAY(A18)=7,NOT(ISERROR(MATCH(A18,[1]Праздники!A:A,0)))),SUM(E18*225)*1.5,SUM(E18*225)) -> 0 | L18: =IF(OR(WEEKDAY(A18)=1,WEEKDAY(A18)=7,NOT(ISERROR(MATCH(A18,[1]Праздники!A:A,0)))),SUM(F18*225)*1.5,SUM(F18*225)) -> 0 | M18: =SUM(G18*15) -> 83467.125 | N18: =SUM(H18)*750 -> 0 | O18: =SUM(I18:N18) -> 90067.125 | P18: =IF(OR(WEEKDAY(A18)=1,WEEKDAY(A18)=7,NOT(ISERROR(MATCH(A18,[1]Праздники!A:A,0)))),"Выходной","Рабочий") -> Рабочий
... A33: 46081 | C33: 0 | D33: 241.775 | G33: =IF(A33 ="",0,G32+C33+E33-D32-F32) -> 4253 | I33: =IF(P33="Выходной",SUM(C33*150)*1.5,SUM(C33*150)) -> 0 | J33: =IF(P33="Выходной",SUM(D33*150)*1.5,SUM(D33*150)) -> 54399.375 | K33: =IF(OR(WEEKDAY(A33)=1,WEEKDAY(A33)=7,NOT(ISERROR(MATCH(A33,[1]Праздники!A:A,0)))),SUM(E33*225)*1.5,SUM(E33*225)) -> 0 | L33: =IF(OR(WEEKDAY(A33)=1,WEEKDAY(A33)=7,NOT(ISERROR(MATCH(A33,[1]Праздники!A:A,0)))),SUM(F33*225)*1.5,SUM(F33*225)) -> 0 | M33: =SUM(G33*15) -> 63795 | N33: =SUM(H33)*750 -> 0 | O33: =SUM(I33:N33) -> 118194.38 | P33: =IF(OR(WEEKDAY(A33)=1,WEEKDAY(A33)=7,NOT(ISERROR(MATCH(A33,[1]Праздники!A:A,0)))),"Выходной","Рабочий") -> Выходной
C34: 0 | D34: 0 | G34: =IF(A34 ="",0,G33+C34+E34-D33-F33) -> 0 | I34: =IF(P34="Выходной",SUM(C34*150)*1.5,SUM(C34*150)) -> 0 | J34: =IF(P34="Выходной",SUM(D34*150)*1.5,SUM(D34*150)) -> 0 | K34: =IF(OR(WEEKDAY(A34)=1,WEEKDAY(A34)=7,NOT(ISERROR(MATCH(A34,[1]Праздники!A:A,0)))),SUM(E34*225)*1.5,SUM(E34*225)) -> 0 | L34: =IF(OR(WEEKDAY(A34)=1,WEEKDAY(A34)=7,NOT(ISERROR(MATCH(A34,[1]Праздники!A:A,0)))),SUM(F34*225)*1.5,SUM(F34*225)) -> 0 | M34: =SUM(G34*15) -> 0 | N34: =SUM(H34)*750 -> 0 | O34: =SUM(I34:N34) -> 0 | P34: =IF(OR(WEEKDAY(A34)=1,WEEKDAY(A34)=7,NOT(ISERROR(MATCH(A34,[1]Праздники!A:A,0)))),"Выходной","Рабочий") -> Выходной
C35: 0 | D35: 0 | G35: =IF(A35 ="",0,G34+C35+E35-D34-F34) -> 0 | I35: =IF(P35="Выходной",SUM(C35*150)*1.5,SUM(C35*150)) -> 0 | J35: =IF(P35="Выходной",SUM(D35*150)*1.5,SUM(D35*150)) -> 0 | K35: =IF(OR(WEEKDAY(A35)=1,WEEKDAY(A35)=7,NOT(ISERROR(MATCH(A35,[1]Праздники!A:A,0)))),SUM(E35*225)*1.5,SUM(E35*225)) -> 0 | L35: =IF(OR(WEEKDAY(A35)=1,WEEKDAY(A35)=7,NOT(ISERROR(MATCH(A35,[1]Праздники!A:A,0)))),SUM(F35*225)*1.5,SUM(F35*225)) -> 0 | M35: =SUM(G35*15) -> 0 | N35: =SUM(H35)*750 -> 0 | O35: =SUM(I35:N35) -> 0 | P35: =IF(OR(WEEKDAY(A35)=1,WEEKDAY(A35)=7,NOT(ISERROR(MATCH(A35,[1]Праздники!A:A,0)))),"Выходной","Рабочий") -> Выходной
C36: 0 | D36: 0 | G36: =IF(A36 ="",0,G35+C36+E36-D35-F35) -> 0 | I36: =IF(P36="Выходной",SUM(C36*150)*1.5,SUM(C36*150)) -> 0 | J36: =IF(P36="Выходной",SUM(D36*150)*1.5,SUM(D36*150)) -> 0 | K36: =IF(OR(WEEKDAY(A36)=1,WEEKDAY(A36)=7,NOT(ISERROR(MATCH(A36,[1]Праздники!A:A,0)))),SUM(E36*225)*1.5,SUM(E36*225)) -> 0 | L36: =IF(OR(WEEKDAY(A36)=1,WEEKDAY(A36)=7,NOT(ISERROR(MATCH(A36,[1]Праздники!A:A,0)))),SUM(F36*225)*1.5,SUM(F36*225)) -> 0 | M36: =SUM(G36*15) -> 0 | N36: =SUM(H36)*750 -> 0 | O36: =SUM(I36:N36) -> 0 | P36: =IF(OR(WEEKDAY(A36)=1,WEEKDAY(A36)=7,NOT(ISERROR(MATCH(A36,[1]Праздники!A:A,0)))),"Выходной","Рабочий") -> Выходной
C37: =SUM(C6:C36) -> 2434 | D37: =SUM(D6:D36) -> 2998.99 | E37: =SUM(E6:E36) -> 0 | F37: =SUM(F6:F36) -> 0 | G37: =SUM(G6:G36) -> 147197.03 | H37: =SUM(H6:H36) -> 0 | I37: =SUM(I6:I36) -> 419946.75 | J37: =SUM(J6:J36) -> 515667.75 | ... O37: =SUM(O6:O36) -> 3143570
N38: С НДС; | O38: =O37*1.22 -> 3835155.3

Sheet РВ Новикова-Прибоя
R1: Выходной | S1: Рабочий
Q2: Выгрузка | R2: =SUMIF($P$6:$P$36,R$1,$C6:$C36) -> 22 | S2: =SUMIF($P$6:$P$36,S$1,$C6:$C36) -> 420.3
A3: ="Отчет по хранению товара РВ " & TEXT(A6,"ММММ ") & YEAR(A6) & " Новикова" -> Отчет по хранению товара РВ Февраль 2026 Новикова | Q3: Отгрузка | R3: =SUMIF($P$6:$P$36,R$1,$D6:$D36) -> 396.23 | S3: =SUMIF($P$6:$P$36,S$1,$D6:$D36) -> 970.71
A4: дата | C4: Выгрузка кол-во тонн | D4: Загрузка кол-во тонн | E4: Выгрузка после 20:00 | F4: Загрузка после 20:00 | G4: Хранение | H4: переконсолидация (тонн) | I4: стоимость выгрузки | J4: стоимость загрузки | K4: Стоимость выгрузки после 20:00 | L4: Стоимость загрузки после 20:00 | M4: стоимость хранения | N4: стоимость переконс. | O4: итого
G5: (кол-во тонн)
A6: 46054 | C6: 0 | D6: 0 | G6: 1345.04 | I6: =IF(P6="Выходной",SUM(C6*150)*1.5,SUM(C6*150)) -> 0 | J6: =IF(P6="Выходной",SUM(D6*150)*1.5,SUM(D6*150)) -> 0 | K6: =IF(OR(WEEKDAY(A6)=1,WEEKDAY(A6)=7,NOT(ISERROR(MATCH(A6,[1]Праздники!A:A,0)))),SUM(E6*225)*1.5,SUM(E6*225)) -> 0 | L6: =IF(OR(WEEKDAY(A6)=1,WEEKDAY(A6)=7,NOT(ISERROR(MATCH(A6,[1]Праздники!A:A,0)))),SUM(F6*225)*1.5,SUM(F6*225)) -> 0 | M6: =SUM(G6*15) -> 20175.6 | N6: =SUM(H6)*750 -> 0 | O6: =SUM(I6:N6) -> 20175.6 | P6: =IF(OR(WEEKDAY(A6)=1,WEEKDAY(A6)=7,NOT(ISERROR(MATCH(A6,[1]Праздники!A:A,0)))),"Выходной","Рабочий") -> Выходной
A7: 46055 | C7: 0 | D7: 0 | G7: =IF(A7 ="",0,G6+C7+E7-D6-F6) -> 1345.04 | I7: =IF(P7="Выходной",SUM(C7*150)*1.5,SUM(C7*150)) -> 0 | J7: =IF(P7="Выходной",SUM(D7*150)*1.5,SUM(D7*150)) -> 0 | K7: =IF(OR(WEEKDAY(A7)=1,WEEKDAY(A7)=7,NOT(ISERROR(MATCH(A7,[1]Праздники!A:A,0)))),SUM(E7*225)*1.5,SUM(E7*225)) -> 0 | L7: =IF(OR(WEEKDAY(A7)=1,WEEKDAY(A7)=7,NOT(ISERROR(MATCH(A7,[1]Праздники!A:A,0)))),SUM(F7*225)*1.5,SUM(F7*225)) -> 0 | M7: =SUM(G7*15) -> 20175.6 | N7: =SUM(H7)*750 -> 0 | O7: =SUM(I7:N7) -> 20175.6 | P7: =IF(OR(WEEKDAY(A7)=1,WEEKDAY(A7)=7,NOT(ISERROR(MATCH(A7,[1]Праздники!A:A,0)))),"Выходной","Рабочий") -> Рабочий
A8: 46056 | C8: 0 | D8: 0 | G8: =IF(A8 ="",0,G7+C8+E8-D7-F7) -> 1345.04 | I8: =IF(P8="Выходной",SUM(C8*150)*1.5,SUM(C8*150)) -> 0 | J8: =IF(P8="Выходной",SUM(D8*150)*1.5,SUM(D8*150)) -> 0 | K8: =IF(OR(WEEKDAY(A8)=1,WEEKDAY(A8)=7,NOT(ISERROR(MATCH(A8,[1]Праздники!A:A,0)))),SUM(E8*225)*1.5,SUM(E8*225)) -> 0 | L8: =IF(OR(WEEKDAY(A8)=1,WEEKDAY(A8)=7,NOT(ISERROR(MATCH(A8,[1]Праздники!A:A,0)))),SUM(F8*225)*1.5,SUM(F8*225)) -> 0 | M8: =SUM(G8*15) -> 20175.6 | N8: =SUM(H8)*750 -> 0 | O8: =SUM(I8:N8) -> 20175.6 | P8: =IF(OR(WEEKDAY(A8)=1,WEEKDAY(A8)=7,NOT(ISERROR(MATCH(A8,[1]Праздники!A:A,0)))),"Выходной","Рабочий") -> Рабочий
